Workbook

Sheet Sheet2
A3: Cty | B3: CPC
A4: Cty | B4: Far Eastern
A5: Cty | B5: Nhóm Trung Quốc

Sheet GAP
B3: BẢNG TÍNH GIÁ MUA CHAI, VẢY TỪ CÁC TRẠM
J4: Giá B0 | K4: Giá B0
I5: ĐVT: đồng/ký | J5: 9500 | K5: 10000
B6: Nhóm chai PET | C6: Thành phần chai PET sau phân loại | D6: Giá B0 | E6: Hao hụt | G6: Gap (đảm bảo chi phí và lợi nhuận) | H6: Giá mua theo công thức | I6: Giá mua đề xuất
E7: Tỷ lệ | F7: Quy ra tiền
B8: A. Giá mua Chai
B9: Chai PET nhóm 1 | C9: B1.1 + B1.2 + B1.3 + B2.1 + B3 + B6.1 | D9: 9500 | E9: 0.11 | F9: =D9*E9 -> 1045 | G9: 3500 | H9: =D9+F9+G9 -> 14045 | I9: 14500 | J9: =I9-D9 -> 5000 | K9: 5000 | L9: =J9-K9 -> 0
B10: Chai PET nhóm 2 | C10: B4 + B5 | D10: 9500 | E10: 0.11 | F10: =D10*E10 -> 1045 | G10: 500 | H10: =D10+F10+G10 -> 11045 | I10: 11500 | J10: =I10-D10 -> 2000 | K10: 2000 | L10: =J10-K10 -> 0
B11: Chai PET nhóm 3 | C11: B2.2 + B6.2 | D11: 9500 | E11: 0.11 | F11: =D11*E11 -> 1045 | G11: 2000 | H11: =D11+F11+G11 -> 12545 | I11: 13000 | J11: =I11-D11 -> 3500 | K11: 3500 | L11: =J11-K11 -> 0
B12: Chai PET nhóm 4 | C12: Nắp HD Ép, cổ chai, PP (quai) | D12: 9500 | E12: 0.11 | F12: =D12*E12 -> 1045 | G12: -5000 | H12: =D12+F12+G12 -> 5545 | I12: 6000 | J12: =I12-D12 -> -3500 | K12: -3500 | L12: =J12-K12 -> 0
B13: B. Giá mua Vảy | L13: =J13-K13 -> 0
B14: Nhóm 1 | C14: Vảy B6.2 | D14: =I11 -> 13000 | E14: 0.08 | F14: =D14*E14 -> 1040 | G14: 2000 | H14: =D14+F14+G14 -> 16040 | I14: 16000 | J14: =I14-D14 -> 3000 | K14: 3000 | L14: =J14-K14 -> 0
B16: BẢNG COPY QUA TỜ TRÌNH DUYỆT
B17: Mã SAP | C17: Tên Chai | D17: Giá đề xuất
C18: Chai PET B1.1 | D18: =$I$9 -> 14500
C19: Chai PET B1 KPL (B1.2) | D19: =D18-500 -> 14000
C20: Chai PET B1.3 | D20: =$I$9 -> 14500
B21: 150000004 | C21: Chai PET B2.1 | D21: =$I$9 -> 14500
B22: 150000050 | C22: Chai PET B2.2 | D22: =$I$11 -> 13000
B23: 150000005 | C23: Chai PET B3 | D23: =$I$9 -> 14500
B24: 150000014 | C24: Chai PET B4 | D24: =$I$10 -> 11500
B25: 150000015 | C25: Chai PET B5 | D25: =$I$10 -> 11500
B26: 150000016 | C26: Chai PET B6.1 | D26: =$I$9 -> 14500
B27: 150000114 | C27: Chai PET B6.2 | D27: =$I$11 -> 13000
C28: Nắp HD Ép, cổ chai | D28: =$I$12 -> 6000
C29: PP (quai) | D29: =$I$12 -> 6000
B30: 150000061 | C30: Vảy PET B6.2_A6 | D30: =I14 -> 16000

Sheet Giá mua Chai-Vảy
A2: 2026
A3: 2
B6: Giá chai B0 | C6: 9500
B7: Chi phí phân loại | C7: 3000
B8: Tỷ lệ hao hụt thực tế | C8: 0.11
B9: Tổng chi phí | C9: =SUM(C6:C7) -> 12500
B10: Chi phí hao hụt | C10: =C9*C8/(1-C8) -> 1544.9438
B11: Giá bán hòa vốn đơn vị | C11: =+C9/(1-C8) -> 14044.944 | X11: So giá mua BO
B12: Chai | S12: Check với SAP | V12: TT | W12: BOM | X12: TT | Y12: BOM
A13: STT | B13: Tên vật tư | C13: Cơ cấu thành phẩm theo BOM | E13: Giá bán chai 3 trạm về DTR | F13: Cơ cấu nguyên vật liệu BOM (gram) | G13: Cơ cấu thành phẩm thực tế | H13: Tỷ trọng giá trị | I13: Phân bổ giá B0 | J13: Phân bổ chi phí phân loại | K13: Chi phí sau phân loại | L13: Doanh thu đơn vị | M13: Lợi nhuận đơn vị | N13: Giá thành 1kg sau phân loại | O13: Giá bán chai 3 trạm về DTR | P13: Diff | R13: Giá BO sau phân loại | S13: BOM SAP | T13: Diff | U13: %Diff | V13: Tỷ 3 cấp chất lượng | W13: Tỷ 3 cấp chất lượng | X13: Tỷ 3 cấp chất lượng | Y13: Tỷ 3 cấp chất lượng | Z13: Cơ cấu giá trừ chất lượng | AA13: GAP so BO | AC13: Giá mua theo phân loại | AD13: Chi phí Băm Vảy | AE13: Vảy
A14: 1 | B14: Chai PET B1 | C14: 0.54 | E14: 15000 | F14: =C14*1000 -> 540 | G14: =F14/1000/(1-$C$8) -> 0.60674157 | H14: =E14*G14/SUMPRODUCT($E$14:$E$20,$G$14:$G$20) -> 0.63804647 | I14: =$C$6*H14 -> 6061.4415 | J14: =($C$7+$C$10)*H14 -> 2899.8854 | K14: =I14+J14 -> 8961.3269 | L14: =E14*G14 -> 9101.1236 | M14: =L14-K14 -> 139.7967 | N14: =K14/(F14/(1-$C$8))*1000 -> 14769.594 | O14: 15000 | P14: =O14-N14 -> 230.40567 | Q14: =P14/E14 -> 0.015360378 | R14: =I14/F14*1000 -> 11224.892 | S14: ='[1]BOM (Long)'!$P$7 -> 11536.632 | T14: =R14-S14 -> -311.74009 | U14: =T14/S14 -> -0.02702176 | V14: =R14/R$16 -> 1.25 | W14: =S14/S$16 -> 1.25 | X14: =S14/C$6 -> 1.2143823 | Y14: =S14/C$6 -> 1.2143823 | Z14: 9700 | AC14: 12500 | AE14: =AC14+AD14 -> 12500
A15: 5 | B15: Chai PET B2.2 | C15: 0.03 | E15: 13500 | F15: =C15*1000 -> 30 | G15: =F15/1000/(1-$C$8) -> 0.033707865 | H15: =E15*G15/SUMPRODUCT($E$14:$E$20,$G$14:$G$20) -> 0.031902324 | I15: =$C$6*H15 -> 303.07208 | J15: =($C$7+$C$10)*H15 -> 144.99427 | K15: =I15+J15 -> 448.06634 | L15: =E15*G15 -> 455.05618 | M15: =L15-K15 -> 6.989835 | N15: =K15/(F15/(1-$C$8))*1000 -> 13292.635 | O15: 13500 | P15: =O15-N15 -> 207.3651 | Q15: =P15/E15 -> 0.015360378 | R15: =I15/F15*1000 -> 10102.403 | S15: ='[1]BOM (Long)'!$P$9 -> 10152.236 | T15: =R15-S15 -> -49.833445 | U15: =T15/S15 -> -0.0049086177 | V15: =R15/R$16 -> 1.125 | W15: =S15/S$16 -> 1.1 | X15: =S15/C$6 -> 1.0686564 | Y15: =S15/C$6 -> 1.0686564 | Z15: =Z14/$Y$15 -> 9076.8182 | AA15: =Z15-$Z$14 -> -623.18182 | AB15: =Z15-Z14 -> -623.18182 | AC15: 10000
A16: 7 | B16: Chai PET B4 | C16: 0.02 | E16: 12000 | F16: =C16*1000 -> 20 | G16: =F16/1000/(1-$C$8) -> 0.02247191 | H16: =E16*G16/SUMPRODUCT($E$14:$E$20,$G$14:$G$20) -> 0.018905081 | I16: =$C$6*H16 -> 179.59827 | J16: =($C$7+$C$10)*H16 -> 85.92253 | K16: =I16+J16 -> 265.5208 | L16: =E16*G16 -> 269.66292 | M16: =L16-K16 -> 4.1421244 | N16: =K16/(F16/(1-$C$8))*1000 -> 11815.675 | O16: 12000 | P16: =O16-N16 -> 184.32454 | Q16: =P16/E16 -> 0.015360378 | R16: =I16/F16*1000 -> 8979.9134 | S16: ='[1]BOM (Long)'!$P$10 -> 9229.3054 | T16: =R16-S16 -> -249.39207 | U16: =T16/S16 -> -0.02702176 | V16: =R16/R$16 -> 1 | W16: =S16/S$16 -> 1 | X16: =S16/C$6 -> 0.97150583 | Y16: =S16/C$6 -> 0.97150583 | Z16: =Z15/$Y$15 -> 8493.673 | AA16: =Z16-$Z$14 -> -1206.327 | AB16: =Z16-Z15 -> -583.14516 | AC16: 9000
A17: 8 | B17: Chai PET B5 | C17: 0.02 | E17: 12000 | F17: =C17*1000 -> 20 | G17: =F17/1000/(1-$C$8) -> 0.02247191 | H17: =E17*G17/SUMPRODUCT($E$14:$E$20,$G$14:$G$20) -> 0.018905081 | I17: =$C$6*H17 -> 179.59827 | J17: =($C$7+$C$10)*H17 -> 85.92253 | K17: =I17+J17 -> 265.5208 | L17: =E17*G17 -> 269.66292 | M17: =L17-K17 -> 4.1421244 | N17: =K17/(F17/(1-$C$8))*1000 -> 11815.675 | O17: 12000 | P17: =O17-N17 -> 184.32454 | Q17: =P17/E17 -> 0.015360378 | R17: =I17/F17*1000 -> 8979.9134 | S17: ='[1]BOM (Long)'!$P$11 -> 9229.3054 | T17: =R17-S17 -> -249.39207 | U17: =T17/S17 -> -0.02702176 | V17: =R17/R$16 -> 1 | W17: =S17/S$16 -> 1 | X17: =S17/C$6 -> 0.97150583 | Y17: =S17/C$6 -> 0.97150583 | Z17: =Z16/$Y$15 -> 7947.9923 | AA17: =Z17-$Z$14 -> -1752.0077 | AB17: =Z17-Z16 -> -545.68068 | AC17: 9000
A18: 10 | B18: Chai PET B6.2 | C18: 0.27 | E18: 13500 | F18: =C18*1000 -> 270 | G18: =F18/1000/(1-$C$8) -> 0.30337079 | H18: =E18*G18/SUMPRODUCT($E$14:$E$20,$G$14:$G$20) -> 0.28712091 | I18: =$C$6*H18 -> 2727.6487 | J18: =($C$7+$C$10)*H18 -> 1304.9484 | K18: =I18+J18 -> 4032.5971 | L18: =E18*G18 -> 4095.5056 | M18: =L18-K18 -> 62.908515 | N18: =K18/(F18/(1-$C$8))*1000 -> 13292.635 | O18: 13500 | P18: =O18-N18 -> 207.3651 | Q18: =P18/E18 -> 0.015360378 | R18: =I18/F18*1000 -> 10102.403 | S18: ='[1]BOM (Long)'!$P$13 -> 10152.236 | T18: =R18-S18 -> -49.833445 | U18: =T18/S18 -> -0.0049086177 | V18: =R18/R$16 -> 1.125 | W18: =S18/S$16 -> 1.1 | X18: =S18/C$6 -> 1.0686564 | Y18: =S18/C$6 -> 1.0686564 | Z18: =Z17/$Y$15 -> 7437.3692 | AA18: =Z18-$Z$14 -> -2262.6308 | AB18: =Z18-Z17 -> -510.62313 | AC18: 10000 | AD18: ='[2]CP Công đoạn (3)'!$CJ$6 -> 2321.031 | AE18: =AC18+AD18 -> 12321.031
A19: 11 | B19: Nắp HD ép, cổ chai | C19: 0.01 | E19: 6500 | F19: =C19*1000 -> 10 | G19: =F19/1000/(1-$C$8) -> 0.011235955 | H19: =E19*G19/SUMPRODUCT($E$14:$E$20,$G$14:$G$20) -> 0.005120126 | I19: =$C$6*H19 -> 48.641197 | J19: =($C$7+$C$10)*H19 -> 23.270685 | K19: =I19+J19 -> 71.911882 | L19: =E19*G19 -> 73.033708 | M19: =L19-K19 -> 1.1218254 | N19: =K19/(F19/(1-$C$8))*1000 -> 6400.1575 | O19: 6500 | P19: =O19-N19 -> 99.842458 | Q19: =P19/E19 -> 0.015360378 | R19: =I19/F19*1000 -> 4864.1197 | S19: ='[1]BOM (Long)'!$P$14 -> 5537.5833 | T19: =R19-S19 -> -673.46352 | U19: =T19/S19 -> -0.12161687 | V19: =R19/R$16 -> 0.54166667 | W19: =S19/S$16 -> 0.6 | X19: =S19/C$6 -> 0.5829035 | Y19: =S19/C$6 -> 0.5829035 | Z19: =Z18/$Y$15 -> 6959.5514 | AA19: =Z19-$Z$14 -> -2740.4486 | AB19: =Z19-Z18 -> -477.81786 | AC19: 5000
F20: =C20*1000 -> 0 | G20: =F20/1000/(1-$C$8) -> 0 | H20: =E20*G20/SUMPRODUCT($E$14:$E$20,$G$14:$G$20) -> 0 | I20: =$C$6*H20 -> 0 | J20: =($C$7+$C$10)*H20 -> 0 | K20: =I20+J20 -> 0 | L20: =E20*G20 -> 0 | M20: =L20-K20 -> 0 | N20: =K20/(F20/(1-$C$8))*1000 -> #DIV/0! | P20: =O20-N20 -> #DIV/0! | Q20: =P20/E20 -> #DIV/0!
B21: Thành phẩm thu được sau lựa | C21: =SUM(C14:C20) -> 0.89 | F21: =SUM(F14:F20) -> 890 | G21: =SUM(G14:G20) -> 1 | H21: =SUM(H14:H20) -> 1 | I21: =SUM(I14:I20) -> 9500 | J21: =SUM(J14:J20) -> 4544.9438 | K21: =SUM(K14:K20) -> 14044.944 | L21: =SUM(L14:L20) -> 14264.045 | M21: =SUM(M14:M20) -> 219.10112
B22: Hao hụt (%) | C22: =100%-C21 -> 0.11
B23: Hao hụt (gram_BOM) | F23: =1000-F21 -> 110
B26: Giá chai BX mix sau phân loại | C26: =C11 -> 14044.944
B27: Chi phí phân loại | C27: 1500
B28: Tỷ lệ hao hụt thực tế | C28: 0.06
B29: Tổng chi phí | C29: =SUM(C26:C27) -> 15544.944
B30: Chi phí hao hụt | C30: =C29*C28/(1-C28) -> 992.23046
B31: Giá bán hòa vốn đơn vị | C31: =+C29/(1-C28) -> 16537.174
X32: So giá mua BO
B33: Vảy | S33: Check với SAP | V33: TT | W33: BOM | X33: TT | Y33: BOM
A34: STT | B34: Tên vật tư | C34: Cơ cấu thành phẩm theo BOM | E34: Giá bán thành chai trước băm | F34: Cơ cấu nguyên vật liệu BOM (gram) | G34: Cơ cấu thành phẩm thực tế | H34: Tỷ trọng giá trị | I34: Phân bổ giá chai băm | J34: Chi phí băm | K34: Giá thành sau băm | L34: Doanh thu đơn vị | M34: Lợi nhuận đơn vị | N34: Giá thành 1kg sau Băm | O34: Giá bán vảy 3 trạm về DTR | P34: Diff | R34: Giá BO sau phân loại | S34: BOM SAP | T34: Diff | U34: %Diff | V34: Tỷ 3 cấp chất lượng | W34: Tỷ 3 cấp chất lượng | X34: Tỷ 3 cấp chất lượng | Y34: Tỷ 3 cấp chất lượng | Z34: Cơ cấu giá trừ chất lượng | AA34: GAP so BO
A35: 1 | B35: Vảy_ Chai PET B1 | C35: 0.54 | E35: =N14 -> 14769.594 | F35: =C35*1000 -> 540 | G35: =F35/1000/(1-$C$28) -> 0.57446809 | H35: =E35*G35/SUMPRODUCT($E$35:$E$40,$G$35:$G$40) -> 0.63804647 | I35: =$C$26*H35 -> 8961.3269 | J35: =$C$27+$C$30 -> 2492.2305 | K35: =N14+J35 -> 17261.825 | L35: =O35 -> 16500 | M35: =L35-K35 -> -761.82479 | N35: =K35 -> 17261.825 | O35: 16500 | P35: =O35-N35 -> -761.82479 | Q35: =P35/E35 -> -0.051580617 | R35: =I35/F35*1000 -> 16595.05 | S35: ='[1]BOM (Long)'!$P$7 -> 11536.632 | T35: =R35-S35 -> 5058.418 | U35: =T35/S35 -> 0.43846576 | V35: =R35/R$16 -> 1.8480189 | W35: =S35/S$16 -> 1.25 | X35: =S35/C$6 -> 1.2143823 | Y35: =S35/C$6 -> 1.2143823 | Z35: 9700
A36: 5 | B36: Vảy_Chai PET B2.2 | C36: 0.03 | E36: =N15 -> 13292.635 | F36: =C36*1000 -> 30 | G36: =F36/1000/(1-$C$28) -> 0.031914894 | H36: =E36*G36/SUMPRODUCT($E$35:$E$40,$G$35:$G$40) -> 0.031902324 | I36: =$C$26*H36 -> 448.06634 | J36: =$C$27+$C$30 -> 2492.2305 | K36: =N15+J36 -> 15784.865 | L36: =O36 -> 15000 | M36: =L36-K36 -> -784.86535 | N36: =K36 -> 15784.865 | O36: 15000 | P36: =O36-N36 -> -784.86535 | Q36: =P36/E36 -> -0.05904513 | R36: =I36/F36*1000 -> 14935.545 | S36: ='[1]BOM (Long)'!$P$9 -> 10152.236 | T36: =R36-S36 -> 4783.3089 | U36: =T36/S36 -> 0.47115816 | V36: =R36/R$16 -> 1.663217 | W36: =S36/S$16 -> 1.1 | X36: =S36/C$6 -> 1.0686564 | Y36: =S36/C$6 -> 1.0686564 | Z36: =Z35/$Y$15 -> 9076.8182 | AA36: =Z36-$Z$14 -> -623.18182 | AB36: =Z36-Z35 -> -623.18182
A37: 7 | B37: Vảy_Chai PET B4 | C37: 0.02 | E37: =N16 -> 11815.675 | F37: =C37*1000 -> 20 | G37: =F37/1000/(1-$C$28) -> 0.021276596 | H37: =E37*G37/SUMPRODUCT($E$35:$E$40,$G$35:$G$40) -> 0.018905081 | I37: =$C$26*H37 -> 265.5208 | J37: =$C$27+$C$30 -> 2492.2305 | K37: =N16+J37 -> 14307.906 | L37: =O37 -> 13500 | M37: =L37-K37 -> -807.90592 | N37: =K37 -> 14307.906 | O37: 13500 | P37: =O37-N37 -> -807.90592 | Q37: =P37/E37 -> -0.068375771 | R37: =I37/F37*1000 -> 13276.04 | S37: ='[1]BOM (Long)'!$P$10 -> 9229.3054 | T37: =R37-S37 -> 4046.7344 | U37: =T37/S37 -> 0.43846576 | V37: =R37/R$16 -> 1.4784151 | W37: =S37/S$16 -> 1 | X37: =S37/C$6 -> 0.97150583 | Y37: =S37/C$6 -> 0.97150583 | Z37: =Z36/$Y$15 -> 8493.673 | AA37: =Z37-$Z$14 -> -1206.327 | AB37: =Z37-Z36 -> -583.14516
A38: 8 | B38: Vảy_Chai PET B5 | C38: 0.02 | E38: =N17 -> 11815.675 | F38: =C38*1000 -> 20 | G38: =F38/1000/(1-$C$28) -> 0.021276596 | H38: =E38*G38/SUMPRODUCT($E$35:$E$40,$G$35:$G$40) -> 0.018905081 | I38: =$C$26*H38 -> 265.5208 | J38: =$C$27+$C$30 -> 2492.2305 | K38: =N17+J38 -> 14307.906 | L38: =O38 -> 13500 | M38: =L38-K38 -> -807.90592 | N38: =K38 -> 14307.906 | O38: 13500 | P38: =O38-N38 -> -807.90592 | Q38: =P38/E38 -> -0.068375771 | R38: =I38/F38*1000 -> 13276.04 | S38: ='[1]BOM (Long)'!$P$11 -> 9229.3054 | T38: =R38-S38 -> 4046.7344 | U38: =T38/S38 -> 0.43846576 | V38: =R38/R$16 -> 1.4784151 | W38: =S38/S$16 -> 1 | X38: =S38/C$6 -> 0.97150583 | Y38: =S38/C$6 -> 0.97150583 | Z38: =Z37/$Y$15 -> 7947.9923 | AA38: =Z38-$Z$14 -> -1752.0077 | AB38: =Z38-Z37 -> -545.68068
A39: 10 | B39: Vảy_Chai PET B6.2 | C39: 0.27 | E39: =N18 -> 13292.635 | F39: =C39*1000 -> 270 | G39: =F39/1000/(1-$C$28) -> 0.28723404 | H39: =E39*G39/SUMPRODUCT($E$35:$E$40,$G$35:$G$40) -> 0.28712091 | I39: =$C$26*H39 -> 4032.5971 | J39: =$C$27+$C$30 -> 2492.2305 | K39: =N18+J39 -> 15784.865 | L39: =O39 -> 15000 | M39: =L39-K39 -> -784.86535 | N39: =K39 -> 15784.865 | O39: 15000 | P39: =O39-N39 -> -784.86535 | Q39: =P39/E39 -> -0.05904513 | R39: =I39/F39*1000 -> 14935.545 | S39: ='[1]BOM (Long)'!$P$13 -> 10152.236 | T39: =R39-S39 -> 4783.3089 | U39: =T39/S39 -> 0.47115816 | V39: =R39/R$16 -> 1.663217 | W39: =S39/S$16 -> 1.1 | X39: =S39/C$6 -> 1.0686564 | Y39: =S39/C$6 -> 1.0686564 | Z39: =Z38/$Y$15 -> 7437.3692 | AA39: =Z39-$Z$14 -> -2262.6308 | AB39: =Z39-Z38 -> -510.62313
A40: 11 | B40: Vảy_Nắp HD ép, cổ chai | C40: 0.01 | E40: =N19 -> 6400.1575 | F40: =C40*1000 -> 10 | G40: =F40/1000/(1-$C$28) -> 0.010638298 | H40: =E40*G40/SUMPRODUCT($E$35:$E$40,$G$35:$G$40) -> 0.005120126 | I40: =$C$26*H40 -> 71.911882 | J40: =$C$27+$C$30 -> 2492.2305 | K40: =N19+J40 -> 8892.388 | L40: =O40 -> 8000 | M40: =L40-K40 -> -892.388 | N40: =K40 -> 8892.388 | O40: 8000 | P40: =O40-N40 -> -892.388 | Q40: =P40/E40 -> -0.13943219 | R40: =I40/F40*1000 -> 7191.1882 | S40: ='[1]BOM (Long)'!$P$14 -> 5537.5833 | T40: =R40-S40 -> 1653.605 | U40: =T40/S40 -> 0.29861492 | V40: =R40/R$16 -> 0.8008082 | W40: =S40/S$16 -> 0.6 | X40: =S40/C$6 -> 0.5829035 | Y40: =S40/C$6 -> 0.5829035 | Z40: =Z39/$Y$15 -> 6959.5514 | AA40: =Z40-$Z$14 -> -2740.4486 | AB40: =Z40-Z39 -> -477.81786
F41: =C41*1000 -> 0 | G41: =F41/1000/(1-$C$8) -> 0 | H41: =E41*G41/SUMPRODUCT($E$14:$E$20,$G$14:$G$20) -> 0 | I41: =$C$6*H41 -> 0 | J41: =($C$7+$C$10)*H41 -> 0 | K41: =I41+J41 -> 0 | L41: =E41*G41 -> 0 | M41: =L41-K41 -> 0 | N41: =K41/(F41/(1-$C$8))*1000 -> #DIV/0! | P41: =O41-N41 -> #DIV/0! | Q41: =P41/E41 -> #DIV/0!
B42: Thành phẩm thu được sau lựa | C42: =SUM(C35:C41) -> 0.89 | F42: =SUM(F35:F41) -> 890 | G42: =SUM(G35:G41) -> 0.94680851 | H42: =SUM(H35:H41) -> 1 | I42: =SUM(I35:I41) -> 14044.944 | J42: =SUM(J35:J41) -> 14953.383 | K42: =SUM(K35:K41) -> 86339.755 | L42: =SUM(L35:L41) -> 81500 | M42: =SUM(M35:M41) -> -4839.7553
B43: Hao hụt (%) | C43: =100%-C42 -> 0.11
B44: Hao hụt (gram_BOM) | F44: =1000-F42 -> 110

Sheet Giá mua Chai-Vảy (Giá giảm)
A2: 2026
A3: 2
B6: Giá chai B0 | C6: 9500
B7: Chi phí phân loại | C7: 3000
B8: Tỷ lệ hao hụt thực tế | C8: 0.11
B9: Tổng chi phí | C9: =SUM(C6:C7) -> 12500
B10: Chi phí hao hụt | C10: =C9*C8/(1-C8) -> 1544.9438
B11: Giá bán hòa vốn đơn vị | C11: =+C9/(1-C8) -> 14044.944 | X11: So giá mua BO
B12: Chai | E12: 500 | S12: Check với SAP | V12: TT | W12: BOM | X12: TT | Y12: BOM
A13: STT | B13: Tên vật tư | C13: Cơ cấu thành phẩm theo BOM | E13: Giá bán chai 3 trạm về DTR | F13: Cơ cấu nguyên vật liệu BOM (gram) | G13: Cơ cấu thành phẩm thực tế | H13: Tỷ trọng giá trị | I13: Phân bổ giá B0 | J13: Phân bổ chi phí phân loại | K13: Chi phí sau phân loại | L13: Doanh thu đơn vị | M13: Lợi nhuận đơn vị | N13: Giá thành 1kg sau phân loại | O13: Giá bán chai 3 trạm về DTR | P13: Diff | R13: Giá BO sau phân loại | S13: BOM SAP | T13: Diff | U13: %Diff | V13: Tỷ 3 cấp chất lượng | W13: Tỷ 3 cấp chất lượng | X13: Tỷ 3 cấp chất lượng | Y13: Tỷ 3 cấp chất lượng | Z13: Cơ cấu giá trừ chất lượng | AA13: GAP so BO | AC13: Giá mua theo phân loại | AD13: Chi phí Băm Vảy | AE13: Vảy
A14: 1 | B14: Chai PET B1 | C14: 0.54 | E14: ='Giá mua Chai-Vảy'!E14-$E$12 -> 14500 | F14: =C14*1000 -> 540 | G14: =F14/1000/(1-$C$8) -> 0.60674157 | H14: =E14*G14/SUMPRODUCT($E$14:$E$20,$G$14:$G$20) -> 0.63918367 | I14: =$C$6*H14 -> 6072.2449 | J14: =($C$7+$C$10)*H14 -> 2905.0539 | K14: =I14+J14 -> 8977.2988 | L14: =E14*G14 -> 8797.7528 | M14: =L14-K14 -> -179.54598 | N14: =K14/(F14/(1-$C$8))*1000 -> 14795.918 | O14: 15000 | P14: =O14-N14 -> 204.08163 | Q14: =P14/E14 -> 0.014074595 | R14: =I14/F14*1000 -> 11244.898 | S14: ='[1]BOM (Long)'!$P$7 -> 11536.632 | T14: =R14-S14 -> -291.73382 | U14: =T14/S14 -> -0.025287608 | V14: =R14/R$16 -> 1.2608696 | W14: =S14/S$16 -> 1.25 | X14: =S14/C$6 -> 1.2143823 | Y14: =S14/C$6 -> 1.2143823 | Z14: 9700 | AC14: 12500 | AE14: =AC14+AD14 -> 12500
A15: 5 | B15: Chai PET B2.2 | C15: 0.03 | E15: ='Giá mua Chai-Vảy'!E15-$E$12 -> 13000 | F15: =C15*1000 -> 30 | G15: =F15/1000/(1-$C$8) -> 0.033707865 | H15: =E15*G15/SUMPRODUCT($E$14:$E$20,$G$14:$G$20) -> 0.031836735 | I15: =$C$6*H15 -> 302.44898 | J15: =($C$7+$C$10)*H15 -> 144.69617 | K15: =I15+J15 -> 447.14515 | L15: =E15*G15 -> 438.20225 | M15: =L15-K15 -> -8.942903 | N15: =K15/(F15/(1-$C$8))*1000 -> 13265.306 | O15: 13500 | P15: =O15-N15 -> 234.69388 | Q15: =P15/E15 -> 0.018053375 | R15: =I15/F15*1000 -> 10081.633 | S15: ='[1]BOM (Long)'!$P$9 -> 10152.236 | T15: =R15-S15 -> -70.603313 | U15: =T15/S15 -> -0.0069544594 | V15: =R15/R$16 -> 1.1304348 | W15: =S15/S$16 -> 1.1 | X15: =S15/C$6 -> 1.0686564 | Y15: =S15/C$6 -> 1.0686564 | Z15: =Z14/$Y$15 -> 9076.8182 | AA15: =Z15-$Z$14 -> -623.18182 | AB15: =Z15-Z14 -> -623.18182 | AC15: 10000
A16: 7 | B16: Chai PET B4 | C16: 0.02 | E16: ='Giá mua Chai-Vảy'!E16-$E$12 -> 11500 | F16: =C16*1000 -> 20 | G16: =F16/1000/(1-$C$8) -> 0.02247191 | H16: =E16*G16/SUMPRODUCT($E$14:$E$20,$G$14:$G$20) -> 0.01877551 | I16: =$C$6*H16 -> 178.36735 | J16: =($C$7+$C$10)*H16 -> 85.333639 | K16: =I16+J16 -> 263.70099 | L16: =E16*G16 -> 258.42697 | M16: =L16-K16 -> -5.2740197 | N16: =K16/(F16/(1-$C$8))*1000 -> 11734.694 | O16: 12000 | P16: =O16-N16 -> 265.30612 | Q16: =P16/E16 -> 0.023070098 | R16: =I16/F16*1000 -> 8918.3673 | S16: ='[1]BOM (Long)'!$P$10 -> 9229.3054 | T16: =R16-S16 -> -310.93808 | U16: =T16/S16 -> -0.033690301 | V16: =R16/R$16 -> 1 | W16: =S16/S$16 -> 1 | X16: =S16/C$6 -> 0.97150583 | Y16: =S16/C$6 -> 0.97150583 | Z16: =Z15/$Y$15 -> 8493.673 | AA16: =Z16-$Z$14 -> -1206.327 | AB16: =Z16-Z15 -> -583.14516 | AC16: 9000
A17: 8 | B17: Chai PET B5 | C17: 0.02 | E17: ='Giá mua Chai-Vảy'!E17-$E$12 -> 11500 | F17: =C17*1000 -> 20 | G17: =F17/1000/(1-$C$8) -> 0.02247191 | H17: =E17*G17/SUMPRODUCT($E$14:$E$20,$G$14:$G$20) -> 0.01877551 | I17: =$C$6*H17 -> 178.36735 | J17: =($C$7+$C$10)*H17 -> 85.333639 | K17: =I17+J17 -> 263.70099 | L17: =E17*G17 -> 258.42697 | M17: =L17-K17 -> -5.2740197 | N17: =K17/(F17/(1-$C$8))*1000 -> 11734.694 | O17: 12000 | P17: =O17-N17 -> 265.30612 | Q17: =P17/E17 -> 0.023070098 | R17: =I17/F17*1000 -> 8918.3673 | S17: ='[1]BOM (Long)'!$P$11 -> 9229.3054 | T17: =R17-S17 -> -310.93808 | U17: =T17/S17 -> -0.033690301 | V17: =R17/R$16 -> 1 | W17: =S17/S$16 -> 1 | X17: =S17/C$6 -> 0.97150583 | Y17: =S17/C$6 -> 0.97150583 | Z17: =Z16/$Y$15 -> 7947.9923 | AA17: =Z17-$Z$14 -> -1752.0077 | AB17: =Z17-Z16 -> -545.68068 | AC17: 9000
A18: 10 | B18: Chai PET B6.2 | C18: 0.27 | E18: ='Giá mua Chai-Vảy'!E18-$E$12 -> 13000 | F18: =C18*1000 -> 270 | G18: =F18/1000/(1-$C$8) -> 0.30337079 | H18: =E18*G18/SUMPRODUCT($E$14:$E$20,$G$14:$G$20) -> 0.28653061 | I18: =$C$6*H18 -> 2722.0408 | J18: =($C$7+$C$10)*H18 -> 1302.2655 | K18: =I18+J18 -> 4024.3064 | L18: =E18*G18 -> 3943.8202 | M18: =L18-K18 -> -80.486127 | N18: =K18/(F18/(1-$C$8))*1000 -> 13265.306 | O18: 13500 | P18: =O18-N18 -> 234.69388 | Q18: =P18/E18 -> 0.018053375 | R18: =I18/F18*1000 -> 10081.633 | S18: ='[1]BOM (Long)'!$P$13 -> 10152.236 | T18: =R18-S18 -> -70.603313 | U18: =T18/S18 -> -0.0069544594 | V18: =R18/R$16 -> 1.1304348 | W18: =S18/S$16 -> 1.1 | X18: =S18/C$6 -> 1.0686564 | Y18: =S18/C$6 -> 1.0686564 | Z18: =Z17/$Y$15 -> 7437.3692 | AA18: =Z18-$Z$14 -> -2262.6308 | AB18: =Z18-Z17 -> -510.62313 | AC18: 10000 | AD18: ='[2]CP Công đoạn (3)'!$CJ$6 -> 2321.031 | AE18: =AC18+AD18 -> 12321.031
A19: 11 | B19: Nắp HD ép, cổ chai | C19: 0.01 | E19: ='Giá mua Chai-Vảy'!E19-$E$12 -> 6000 | F19: =C19*1000 -> 10 | G19: =F19/1000/(1-$C$8) -> 0.011235955 | H19: =E19*G19/SUMPRODUCT($E$14:$E$20,$G$14:$G$20) -> 0.0048979592 | I19: =$C$6*H19 -> 46.530612 | J19: =($C$7+$C$10)*H19 -> 22.260949 | K19: =I19+J19 -> 68.791562 | L19: =E19*G19 -> 67.41573 | M19: =L19-K19 -> -1.3758312 | N19: =K19/(F19/(1-$C$8))*1000 -> 6122.449 | O19: 6500 | P19: =O19-N19 -> 377.55102 | Q19: =P19/E19 -> 0.06292517 | R19: =I19/F19*1000 -> 4653.0612 | S19: ='[1]BOM (Long)'!$P$14 -> 5537.5833 | T19: =R19-S19 -> -884.52203 | U19: =T19/S19 -> -0.1597307 | V19: =R19/R$16 -> 0.52173913 | W19: =S19/S$16 -> 0.6 | X19: =S19/C$6 -> 0.5829035 | Y19: =S19/C$6 -> 0.5829035 | Z19: =Z18/$Y$15 -> 6959.5514 | AA19: =Z19-$Z$14 -> -2740.4486 | AB19: =Z19-Z18 -> -477.81786 | AC19: 5000
F20: =C20*1000 -> 0 | G20: =F20/1000/(1-$C$8) -> 0 | H20: =E20*G20/SUMPRODUCT($E$14:$E$20,$G$14:$G$20) -> 0 | I20: =$C$6*H20 -> 0 | J20: =($C$7+$C$10)*H20 -> 0 | K20: =I20+J20 -> 0 | L20: =E20*G20 -> 0 | M20: =L20-K20 -> 0 | N20: =K20/(F20/(1-$C$8))*1000 -> #DIV/0! | P20: =O20-N20 -> #DIV/0! | Q20: =P20/E20 -> #DIV/0!
B21: Thành phẩm thu được sau lựa | C21: =SUM(C14:C20) -> 0.89 | F21: =SUM(F14:F20) -> 890 | G21: =SUM(G14:G20) -> 1 | H21: =SUM(H14:H20) -> 1 | I21: =SUM(I14:I20) -> 9500 | J21: =SUM(J14:J20) -> 4544.9438 | K21: =SUM(K14:K20) -> 14044.944 | L21: =SUM(L14:L20) -> 13764.045 | M21: =SUM(M14:M20) -> -280.89888
B22: Hao hụt (%) | C22: =100%-C21 -> 0.11
B23: Hao hụt (gram_BOM) | F23: =1000-F21 -> 110
B26: Giá chai BX mix sau phân loại | C26: =C11 -> 14044.944
B27: Chi phí phân loại | C27: 1500
B28: Tỷ lệ hao hụt thực tế | C28: 0.06
B29: Tổng chi phí | C29: =SUM(C26:C27) -> 15544.944
B30: Chi phí hao hụt | C30: =C29*C28/(1-C28) -> 992.23046
B31: Giá bán hòa vốn đơn vị | C31: =+C29/(1-C28) -> 16537.174
X32: So giá mua BO
B33: Vảy | S33: Check với SAP | V33: TT | W33: BOM | X33: TT | Y33: BOM
A34: STT | B34: Tên vật tư | C34: Cơ cấu thành phẩm theo BOM | E34: Giá bán thành chai trước băm | F34: Cơ cấu nguyên vật liệu BOM (gram) | G34: Cơ cấu thành phẩm thực tế | H34: Tỷ trọng giá trị | I34: Phân bổ giá chai băm | J34: Chi phí băm | K34: Giá thành sau băm | L34: Doanh thu đơn vị | M34: Lợi nhuận đơn vị | N34: Giá thành 1kg sau Băm | O34: Giá bán vảy 3 trạm về DTR | P34: Diff | R34: Giá BO sau phân loại | S34: BOM SAP | T34: Diff | U34: %Diff | V34: Tỷ 3 cấp chất lượng | W34: Tỷ 3 cấp chất lượng | X34: Tỷ 3 cấp chất lượng | Y34: Tỷ 3 cấp chất lượng | Z34: Cơ cấu giá trừ chất lượng | AA34: GAP so BO
A35: 1 | B35: Vảy_ Chai PET B1 | C35: 0.54 | E35: =N14 -> 14795.918 | F35: =C35*1000 -> 540 | G35: =F35/1000/(1-$C$28) -> 0.57446809 | H35: =E35*G35/SUMPRODUCT($E$35:$E$40,$G$35:$G$40) -> 0.63918367 | I35: =$C$26*H35 -> 8977.2988 | J35: =$C$27+$C$30 -> 2492.2305 | K35: =N14+J35 -> 17288.149 | L35: =O35 -> 16500 | M35: =L35-K35 -> -788.14882 | N35: =K35 -> 17288.149 | O35: 16500 | P35: =O35-N35 -> -788.14882 | Q35: =P35/E35 -> -0.053267989 | R35: =I35/F35*1000 -> 16624.627 | S35: ='[1]BOM (Long)'!$P$7 -> 11536.632 | T35: =R35-S35 -> 5087.9956 | U35: =T35/S35 -> 0.44102956 | V35: =R35/R$16 -> 1.8640887 | W35: =S35/S$16 -> 1.25 | X35: =S35/C$6 -> 1.2143823 | Y35: =S35/C$6 -> 1.2143823 | Z35: 9700
A36: 5 | B36: Vảy_Chai PET B2.2 | C36: 0.03 | E36: =N15 -> 13265.306 | F36: =C36*1000 -> 30 | G36: =F36/1000/(1-$C$28) -> 0.031914894 | H36: =E36*G36/SUMPRODUCT($E$35:$E$40,$G$35:$G$40) -> 0.031836735 | I36: =$C$26*H36 -> 447.14515 | J36: =$C$27+$C$30 -> 2492.2305 | K36: =N15+J36 -> 15757.537 | L36: =O36 -> 15000 | M36: =L36-K36 -> -757.53658 | N36: =K36 -> 15757.537 | O36: 15000 | P36: =O36-N36 -> -757.53658 | Q36: =P36/E36 -> -0.057106604 | R36: =I36/F36*1000 -> 14904.838 | S36: ='[1]BOM (Long)'!$P$9 -> 10152.236 | T36: =R36-S36 -> 4752.6024 | U36: =T36/S36 -> 0.46813356 | V36: =R36/R$16 -> 1.6712519 | W36: =S36/S$16 -> 1.1 | X36: =S36/C$6 -> 1.0686564 | Y36: =S36/C$6 -> 1.0686564 | Z36: =Z35/$Y$15 -> 9076.8182 | AA36: =Z36-$Z$14 -> -623.18182 | AB36: =Z36-Z35 -> -623.18182
A37: 7 | B37: Vảy_Chai PET B4 | C37: 0.02 | E37: =N16 -> 11734.694 | F37: =C37*1000 -> 20 | G37: =F37/1000/(1-$C$28) -> 0.021276596 | H37: =E37*G37/SUMPRODUCT($E$35:$E$40,$G$35:$G$40) -> 0.01877551 | I37: =$C$26*H37 -> 263.70099 | J37: =$C$27+$C$30 -> 2492.2305 | K37: =N16+J37 -> 14226.924 | L37: =O37 -> 13500 | M37: =L37-K37 -> -726.92433 | N37: =K37 -> 14226.924 | O37: 13500 | P37: =O37-N37 -> -726.92433 | Q37: =P37/E37 -> -0.061946595 | R37: =I37/F37*1000 -> 13185.049 | S37: ='[1]BOM (Long)'!$P$10 -> 9229.3054 | T37: =R37-S37 -> 3955.7439 | U37: =T37/S37 -> 0.42860689 | V37: =R37/R$16 -> 1.4784151 | W37: =S37/S$16 -> 1 | X37: =S37/C$6 -> 0.97150583 | Y37: =S37/C$6 -> 0.97150583 | Z37: =Z36/$Y$15 -> 8493.673 | AA37: =Z37-$Z$14 -> -1206.327 | AB37: =Z37-Z36 -> -583.14516
A38: 8 | B38: Vảy_Chai PET B5 | C38: 0.02 | E38: =N17 -> 11734.694 | F38: =C38*1000 -> 20 | G38: =F38/1000/(1-$C$28) -> 0.021276596 | H38: =E38*G38/SUMPRODUCT($E$35:$E$40,$G$35:$G$40) -> 0.01877551 | I38: =$C$26*H38 -> 263.70099 | J38: =$C$27+$C$30 -> 2492.2305 | K38: =N17+J38 -> 14226.924 | L38: =O38 -> 13500 | M38: =L38-K38 -> -726.92433 | N38: =K38 -> 14226.924 | O38: 13500 | P38: =O38-N38 -> -726.92433 | Q38: =P38/E38 -> -0.061946595 | R38: =I38/F38*1000 -> 13185.049 | S38: ='[1]BOM (Long)'!$P$11 -> 9229.3054 | T38: =R38-S38 -> 3955.7439 | U38: =T38/S38 -> 0.42860689 | V38: =R38/R$16 -> 1.4784151 | W38: =S38/S$16 -> 1 | X38: =S38/C$6 -> 0.97150583 | Y38: =S38/C$6 -> 0.97150583 | Z38: =Z37/$Y$15 -> 7947.9923 | AA38: =Z38-$Z$14 -> -1752.0077 | AB38: =Z38-Z37 -> -545.68068
A39: 10 | B39: Vảy_Chai PET B6.2 | C39: 0.27 | E39: =N18 -> 13265.306 | F39: =C39*1000 -> 270 | G39: =F39/1000/(1-$C$28) -> 0.28723404 | H39: =E39*G39/SUMPRODUCT($E$35:$E$40,$G$35:$G$40) -> 0.28653061 | I39: =$C$26*H39 -> 4024.3064 | J39: =$C$27+$C$30 -> 2492.2305 | K39: =N18+J39 -> 15757.537 | L39: =O39 -> 15000 | M39: =L39-K39 -> -757.53658 | N39: =K39 -> 15757.537 | O39: 15000 | P39: =O39-N39 -> -757.53658 | Q39: =P39/E39 -> -0.057106604 | R39: =I39/F39*1000 -> 14904.838 | S39: ='[1]BOM (Long)'!$P$13 -> 10152.236 | T39: =R39-S39 -> 4752.6024 | U39: =T39/S39 -> 0.46813356 | V39: =R39/R$16 -> 1.6712519 | W39: =S39/S$16 -> 1.1 | X39: =S39/C$6 -> 1.0686564 | Y39: =S39/C$6 -> 1.0686564 | Z39: =Z38/$Y$15 -> 7437.3692 | AA39: =Z39-$Z$14 -> -2262.6308 | AB39: =Z39-Z38 -> -510.62313
A40: 11 | B40: Vảy_Nắp HD ép, cổ chai | C40: 0.01 | E40: =N19 -> 6122.449 | F40: =C40*1000 -> 10 | G40: =F40/1000/(1-$C$28) -> 0.010638298 | H40: =E40*G40/SUMPRODUCT($E$35:$E$40,$G$35:$G$40) -> 0.0048979592 | I40: =$C$26*H40 -> 68.791562 | J40: =$C$27+$C$30 -> 2492.2305 | K40: =N19+J40 -> 8614.6794 | L40: =O40 -> 8000 | M40: =L40-K40 -> -614.67944 | N40: =K40 -> 8614.6794 | O40: 8000 | P40: =O40-N40 -> -614.67944 | Q40: =P40/E40 -> -0.10039764 | R40: =I40/F40*1000 -> 6879.1562 | S40: ='[1]BOM (Long)'!$P$14 -> 5537.5833 | T40: =R40-S40 -> 1341.5729 | U40: =T40/S40 -> 0.24226686 | V40: =R40/R$16 -> 0.77134703 | W40: =S40/S$16 -> 0.6 | X40: =S40/C$6 -> 0.5829035 | Y40: =S40/C$6 -> 0.5829035 | Z40: =Z39/$Y$15 -> 6959.5514 | AA40: =Z40-$Z$14 -> -2740.4486 | AB40: =Z40-Z39 -> -477.81786
F41: =C41*1000 -> 0 | G41: =F41/1000/(1-$C$8) -> 0 | H41: =E41*G41/SUMPRODUCT($E$14:$E$20,$G$14:$G$20) -> 0 | I41: =$C$6*H41 -> 0 | J41: =($C$7+$C$10)*H41 -> 0 | K41: =I41+J41 -> 0 | L41: =E41*G41 -> 0 | M41: =L41-K41 -> 0 | N41: =K41/(F41/(1-$C$8))*1000 -> #DIV/0! | P41: =O41-N41 -> #DIV/0! | Q41: =P41/E41 -> #DIV/0!
B42: Thành phẩm thu được sau lựa | C42: =SUM(C35:C41) -> 0.89 | F42: =SUM(F35:F41) -> 890 | G42: =SUM(G35:G41) -> 0.94680851 | H42: =SUM(H35:H41) -> 1 | I42: =SUM(I35:I41) -> 14044.944 | J42: =SUM(J35:J41) -> 14953.383 | K42: =SUM(K35:K41) -> 85871.75 | L42: =SUM(L35:L41) -> 81500 | M42: =SUM(M35:M41) -> -4371.7501
B43: Hao hụt (%) | C43: =100%-C42 -> 0.11
B44: Hao hụt (gram_BOM) | F44: =1000-F42 -> 110

Sheet Hảo_R&D
B1: Sơ đồ khối dòng nguyên liệu-sản phẩm hiện tại của DTR. | Z1: Giá chai | AC1: ='[2]10. 100% chai->hạt WSS01-iSS01'!$H$9 -> 15000 | AD1: =AC3-AC1-AD3 -> 1249.9477
B2: Với phân bố và định hướng sản phẩm như hiện nay, một số nguyên liệu đầu vào (B2.2/B4/B5) đang gặp khó khăn về giá, do gánh chung dòng chảy với chỉ khoảng 53% nguyên liệu chính B1.1. | Z2: Vảy (Mua ngoài) | AC2: ='[2]12. 100% vảy->hạt WSS01-iSS01'!$I$30 -> 17636.978 | AD2: ='[2]12. 100% vảy->hạt WSS01-iSS01'!$I$10 -> 1636.9775
Z3: Giá thành vảy (SX) => | AC3: ='[2]10. 100% chai->hạt WSS01-iSS01'!$I$60 -> 20966.591 | AD3: ='[2]10. 100% chai->hạt WSS01-iSS01'!$I$21+'[2]10. 100% chai->hạt WSS01-iSS01'!$I$37 -> 4716.6433 | AO3: Giá bán Hạt | AP3: Exw
Z4: Tên TP | AA4: Loại vảy 1 | AC4: Loại vảy 2 | AE4: Loại vảy 3 | AG4: Loại vảy 4 | AI4: Loại vảy 5 | AK4: Loại vảy 6 | AM4: Cộng | AO4: 26500
AA5: B6.2 | AB5: VND | AC5: B1 | AD5: VND | AE5: B2.2 | AF5: VND | AG5: B5 | AH5: VND | AI5: B7 | AJ5: VND | AK5: B4 | AL5: VND | AN5: VND | AO5: VND | AP5: USD
Z6: Chai B6.2 | AM6: 0.3
Z7: Hạt WSS01G-Nia | AA7: 0.1 | AB7: =AA7*$AA$3 -> 0 | AC7: 0.9 | AD7: =AC7*$AC$3 -> 18869.932 | AF7: =AE7*$AE$3 -> 0 | AH7: =AG7*$AG$3 -> 0 | AJ7: =AI7*$AI$3 -> 0 | AL7: =AK7*$AK$3 -> 0 | AM7: =AA7+AC7+AE7+AG7+AI7+AK7 -> 1 | AN7: =AB7+AD7+AF7+AH7+AJ7+AL7 -> 18869.932 | AO7: =$AO$4*AP7 -> 30740000 | AP7: 1160
Z8: Hạt iSS01G-Out | AA8: 0.3 | AB8: =AA8*$AA$3 -> 0 | AC8: 0.7 | AD8: =AC8*$AC$3 -> 14676.614 | AF8: =AE8*$AE$3 -> 0 | AH8: =AG8*$AG$3 -> 0 | AJ8: =AI8*$AI$3 -> 0 | AL8: =AK8*$AK$3 -> 0 | AM8: =AA8+AC8+AE8+AG8+AI8+AK8 -> 1 | AN8: =AB8+AD8+AF8+AH8+AJ8+AL8 -> 14676.614 | AO8: =$AO$4*AP8 -> 31535000 | AP8: =AP7+30 -> 1190
Z9: Hạt WSS03G-PW | AA9: 0.55 | AB9: =AA9*$AA$3 -> 0 | AC9: 0.3 | AD9: =AC9*$AC$3 -> 6289.9773 | AE9: 0.15 | AF9: =AE9*$AE$3 -> 0 | AH9: =AG9*$AG$3 -> 0 | AJ9: =AI9*$AI$3 -> 0 | AL9: =AK9*$AK$3 -> 0 | AM9: =AA9+AC9+AE9+AG9+AI9+AK9 -> 1 | AN9: =AB9+AD9+AF9+AH9+AJ9+AL9 -> 6289.9773 | AO9: =$AO$4*AP9 -> 28885000 | AP9: =AP7-70 -> 1090
Z10: Hạt WSS05SB (sợi ngắn) | AA10: 0.95 | AB10: =AA10*$AA$3 -> 0 | AD10: =AC10*$AC$3 -> 0 | AF10: =AE10*$AE$3 -> 0 | AG10: 0.05 | AH10: =AG10*$AG$3 -> 0 | AJ10: =AI10*$AI$3 -> 0 | AL10: =AK10*$AK$3 -> 0 | AM10: =AA10+AC10+AE10+AG10+AI10+AK10 -> 1 | AN10: =AB10+AD10+AF10+AH10+AJ10+AL10 -> 0 | AO10: =$AO$4*AP10 -> 19080000 | AP10: 720
Z11: Vảy FPET201-Out | AA11: 0.65 | AB11: =AA11*$AA$3 -> 0 | AC11: 0.15 | AD11: =AC11*$AC$3 -> 3144.9887 | AF11: =AE11*$AE$3 -> 0 | AG11: 0.2 | AH11: =AG11*$AG$3 -> 0 | AJ11: =AI11*$AI$3 -> 0 | AL11: =AK11*$AK$3 -> 0 | AM11: =AA11+AC11+AE11+AG11+AI11+AK11 -> 1 | AN11: =AB11+AD11+AF11+AH11+AJ11+AL11 -> 3144.9887 | AO11: =$AO$4*AP11 -> 0
Z14: Chai B1.1 | AC14: B1.1 | AM14: 0.53
Z15: Hạt WSS01G | AB15: =AA15*$AA$3 -> 0 | AC15: 1 | AD15: =AC15*$AC$3 -> 20966.591 | AF15: =AE15*$AE$3 -> 0 | AH15: =AG15*$AG$3 -> 0 | AJ15: =AI15*$AI$3 -> 0 | AL15: =AK15*$AK$3 -> 0 | AM15: =AA15+AC15+AE15+AG15+AI15+AK15 -> 1 | AN15: =AB15+AD15+AF15+AH15+AJ15+AL15 -> 20966.591 | AO15: =$AO$4*AP15 -> 30740000 | AP15: =AP7 -> 1160
Z16: Hạt iSS01G | AB16: =AA16*$AA$3 -> 0 | AC16: 1 | AD16: =AC16*$AC$3 -> 20966.591 | AF16: =AE16*$AE$3 -> 0 | AH16: =AG16*$AG$3 -> 0 | AJ16: =AI16*$AI$3 -> 0 | AL16: =AK16*$AK$3 -> 0 | AM16: =AA16+AC16+AE16+AG16+AI16+AK16 -> 1 | AN16: =AB16+AD16+AF16+AH16+AJ16+AL16 -> 20966.591 | AO16: =$AO$4*AP16 -> 31535000 | AP16: =AP7+30 -> 1190
Z17: Hạt iSS01084G | AB17: =AA17*$AA$3 -> 0 | AC17: 1 | AD17: =AC17*$AC$3 -> 20966.591 | AF17: =AE17*$AE$3 -> 0 | AH17: =AG17*$AG$3 -> 0 | AJ17: =AI17*$AI$3 -> 0 | AL17: =AK17*$AK$3 -> 0 | AM17: =AA17+AC17+AE17+AG17+AI17+AK17 -> 1 | AN17: =AB17+AD17+AF17+AH17+AJ17+AL17 -> 20966.591 | AO17: =$AO$4*AP17 -> 33125000 | AP17: =AP7+90 -> 1250
Z18: Hạt WSS03G | AB18: =AA18*$AA$3 -> 0 | AC18: 1 | AD18: =AC18*$AC$3 -> 20966.591 | AF18: =AE18*$AE$3 -> 0 | AH18: =AG18*$AG$3 -> 0 | AJ18: =AI18*$AI$3 -> 0 | AL18: =AK18*$AK$3 -> 0 | AM18: =AA18+AC18+AE18+AG18+AI18+AK18 -> 1 | AN18: =AB18+AD18+AF18+AH18+AJ18+AL18 -> 20966.591 | AO18: =$AO$4*AP18 -> 29945000 | AP18: =AP7-30 -> 1130
Z24: Chai B2.2 +B5 | AM24: 0.05
Z25: Hạt WSS01G-Nia | AB25: =AA25*$AA$3 -> 0 | AC25: 0.9 | AD25: =AC25*$AC$3 -> 18869.932 | AE25: 0.1 | AF25: =AE25*$AE$3 -> 0 | AH25: =AG25*$AG$3 -> 0 | AJ25: =AI25*$AI$3 -> 0 | AL25: =AK25*$AK$3 -> 0 | AM25: =AA25+AC25+AE25+AG25+AI25+AK25 -> 1 | AN25: =AB25+AD25+AF25+AH25+AJ25+AL25 -> 18869.932 | AO25: =$AO$4*AP25 -> 30740000 | AP25: =AP7 -> 1160
Z26: Hạt WSS03G-PW | AA26: 0.55 | AB26: =AA26*$AA$3 -> 0 | AC26: 0.3 | AD26: =AC26*$AC$3 -> 6289.9773 | AE26: 0.15 | AF26: =AE26*$AE$3 -> 0 | AH26: =AG26*$AG$3 -> 0 | AJ26: =AI26*$AI$3 -> 0 | AL26: =AK26*$AK$3 -> 0 | AM26: =AA26+AC26+AE26+AG26+AI26+AK26 -> 1 | AN26: =AB26+AD26+AF26+AH26+AJ26+AL26 -> 6289.9773 | AO26: =$AO$4*AP26 -> 28885000 | AP26: =AP7-70 -> 1090
Z27: Hạt WSS01S | AB27: =AA27*$AA$3 -> 0 | AC27: 0.4 | AD27: =AC27*$AC$3 -> 8386.6364 | AF27: =AE27*$AE$3 -> 0 | AG27: 0.5 | AH27: =AG27*$AG$3 -> 0 | AI27: 0.1 | AJ27: =AI27*$AI$3 -> 0 | AL27: =AK27*$AK$3 -> 0 | AM27: =AA27+AC27+AE27+AG27+AI27+AK27 -> 1 | AN27: =AB27+AD27+AF27+AH27+AJ27+AL27 -> 8386.6364 | AO27: =$AO$4*AP27 -> 30740000 | AP27: =AP7 -> 1160
Z28: Hạt WSS05SB (sợi ngắn) | AA28: 0.95 | AB28: =AA28*$AA$3 -> 0 | AD28: =AC28*$AC$3 -> 0 | AF28: =AE28*$AE$3 -> 0 | AG28: 0.05 | AH28: =AG28*$AG$3 -> 0 | AJ28: =AI28*$AI$3 -> 0 | AL28: =AK28*$AK$3 -> 0 | AM28: =AA28+AC28+AE28+AG28+AI28+AK28 -> 1 | AN28: =AB28+AD28+AF28+AH28+AJ28+AL28 -> 0 | AO28: =$AO$4*AP28 -> 19080000 | AP28: =AP10 -> 720
Z29: Vảy FPET201-Out | AA29: 0.65 | AB29: =AA29*$AA$3 -> 0 | AC29: 0.15 | AD29: =AC29*$AC$3 -> 3144.9887 | AF29: =AE29*$AE$3 -> 0 | AG29: 0.2 | AH29: =AG29*$AG$3 -> 0 | AJ29: =AI29*$AI$3 -> 0 | AL29: =AK29*$AK$3 -> 0 | AM29: =AA29+AC29+AE29+AG29+AI29+AK29 -> 1 | AN29: =AB29+AD29+AF29+AH29+AJ29+AL29 -> 3144.9887 | AO29: =$AO$4*AP29 -> 0
Z32: Chai B4 | AM32: 0.02
Z33: Dây Đai | AB33: =AA33*$AA$3 -> 0 | AD33: =AC33*$AC$3 -> 0 | AF33: =AE33*$AE$3 -> 0 | AJ33: =AI33*$AI$3 -> 0 | AK33: 1 | AM33: =AA33+AC33+AE33+AG33+AI33+AK33 -> 1 | AN33: =AB33+AD33+AF33+AH33+AJ33+AL33 -> 0 | AO33: =$AO$4*AP33 -> 19000500 | AP33: 717
AK35: ='Giá mua Chai-Vảy'!O40 -> 8000
Z36: Vảy_Nắp HD ép, cổ chai | AM36: 0.01
Z37: rHDPE ép | AB37: =AA37*$AA$3 -> 0 | AD37: =AC37*$AC$3 -> 0 | AF37: =AE37*$AE$3 -> 0 | AJ37: =AI37*$AI$3 -> 0 | AK37: 1 | AL37: =AK37*$AK$35 -> 8000 | AM37: =AA37+AC37+AE37+AG37+AI37+AK37 -> 1 | AN37: =AB37+AD37+AF37+AH37+AJ37+AL37 -> 8000 | AO37: =AO$1+AN37 -> 8000 | AP37: =AP$1+AO37 -> 8000

Sheet Hảo_R&D (Vảy sạch)
B1: Sơ đồ khối dòng nguyên liệu-sản phẩm hiện tại của DTR. | T1: Giá chai mua vào | U1: ='Giá mua Chai-Vảy'!E18 -> 13500 | W1: ='[2]10. 100% chai->hạt WSS01-iSS01'!$H$9 -> 15000 | X1: =W3-W1-X3 -> 1249.9477 | Y1: ='Giá mua Chai-Vảy'!E15 -> 13500 | AA1: ='[2]18. Vảy B5'!$I$9 -> 12000 | AB1: ='[2]18. Vảy B5'!$I$10 -> 411.6804 | AC1: ='[2]16.1 Rửa vảy B7'!$I$9 -> 7971.0145 | AD1: ='[2]16.1 Rửa vảy B7'!$I$10 -> 84.555435 | AE1: ='Giá mua Chai-Vảy'!E16 -> 12000 | AL1: =AL2/$AR$2 -> 0.31333333 | AM1: =AM2/$AR$2 -> 0.52 | AN1: =AN2/$AR$2 -> 0.026666667 | AO1: =AO2/$AR$2 -> 0.066666667 | AP1: =AP2/$AR$2 -> 0.0066666667 | AQ1: =AQ2/$AR$2 -> 0.066666667 | AR1: =AR2/$AR$2 -> 1
B2: Với phân bố và định hướng sản phẩm như hiện nay, một số nguyên liệu đầu vào (B2.2/B4/B5) đang gặp khó khăn về giá, do gánh chung dòng chảy với chỉ khoảng 53% nguyên liệu chính B1.1. | T2: Giá thành vảy sạch => từ vảy mua ngoài | W2: ='[2]12. 100% vảy->hạt WSS01-iSS01'!$I$30 -> 17636.978 | X2: ='[2]12. 100% vảy->hạt WSS01-iSS01'!$I$10 -> 1636.9775 | AL2: =AL6+AL14+AL24+AL33 -> 4.7 | AM2: =AM6+AM14+AM24+AM33 -> 7.8 | AN2: =AN6+AN14+AN24+AN33 -> 0.4 | AO2: =AO6+AO14+AO24+AO33 -> 1 | AP2: =AP6+AP14+AP24+AP33 -> 0.1 | AQ2: =AQ6+AQ14+AQ24+AQ33 -> 1 | AR2: =AR6+AR14+AR24+AR33 -> 15
T3: Giá thành vảy sạch => từ chai | U3: =U1+X3 -> 18216.643 | W3: ='[2]10. 100% chai->hạt WSS01-iSS01'!$I$60 -> 20966.591 | X3: ='[2]10. 100% chai->hạt WSS01-iSS01'!$I$21+'[2]10. 100% chai->hạt WSS01-iSS01'!$I$37 -> 4716.6433 | Y3: =Y1+X3 -> 18216.643 | AA3: ='[2]18. Vảy B5'!$I$58 -> 16916.835 | AB3: ='[2]18. Vảy B5'!$I$21+'[2]18. Vảy B5'!$I$37 -> 4505.1542 | AC3: ='[2]16.1 Rửa vảy B7'!$I$48 -> 14341.25 | AD3: ='[2]16.1 Rửa vảy B7'!$I$11+'[2]16.1 Rửa vảy B7'!$I$27 -> 6285.6803 | AE3: =AE1+AB3 -> 16505.154 | AG3: Giá thành vảy sạch | AI3: Giá bán Hạt | AJ3: Exw | AL3: Tổng hợp Các loại chai
T4: Tên TP | U4: Loại vảy 1 | W4: Loại vảy 2 | Y4: Loại vảy 3 | AA4: Loại vảy 4 | AC4: Loại vảy 5 | AE4: Loại vảy 6 | AG4: Cộng | AI4: 26500
U5: B6.2 | V5: VND | W5: B1 | X5: VND | Y5: B2.2 | Z5: VND | AA5: B5 | AB5: VND | AC5: B7 | AD5: VND | AE5: B4 | AF5: VND | AH5: VND | AI5: VND | AJ5: USD | AL5: =U5 -> B6.2 | AM5: =W5 -> B1 | AN5: =Y5 -> B2.2 | AO5: =AA5 -> B5 | AP5: =AC5 -> B7 | AQ5: =AE5 -> B4 | AT5: =AL5 -> B6.2 | AU5: =AM5 -> B1 | AV5: =AN5 -> B2.2 | AW5: =AO5 -> B5 | AX5: =AP5 -> B7 | AY5: =AQ5 -> B4 | AZ5: =AR5 -> 0
T6: Chai B6.2 | AG6: 0.3 | AL6: =SUM(AL7:AL11) -> 2.55 | AM6: =SUM(AM7:AM11) -> 2.05 | AN6: =SUM(AN7:AN11) -> 0.15 | AO6: =SUM(AO7:AO11) -> 0.25 | AP6: =SUM(AP7:AP11) -> 0 | AQ6: =SUM(AQ7:AQ11) -> 0 | AR6: =SUM(AR7:AR11) -> 5 | AT6: =AL6/AL$2 -> 0.54255319 | AU6: =AM6/AM$2 -> 0.26282051 | AV6: =AN6/AN$2 -> 0.375 | AW6: =AO6/AO$2 -> 0.25 | AX6: =AP6/AP$2 -> 0 | AY6: =AQ6/AQ$2 -> 0 | AZ6: =AR6/AR$2 -> 0.33333333
T7: Hạt WSS01G-Nia | U7: 0.1 | V7: =U7*$U$3 -> 1821.6643 | W7: 0.9 | X7: =W7*$W$3 -> 18869.932 | Z7: =Y7*$Y$3 -> 0 | AB7: =AA7*$AA$3 -> 0 | AD7: =AC7*$AC$3 -> 0 | AF7: =AE7*$AE$3 -> 0 | AG7: =U7+W7+Y7+AA7+AC7+AE7 -> 1 | AH7: =V7+X7+Z7+AB7+AD7+AF7 -> 20691.596 | AI7: =$AI$4*AJ7 -> 30740000 | AJ7: 1160 | AL7: =U7 -> 0.1 | AM7: =W7 -> 0.9 | AN7: =Y7 -> 0 | AO7: =AA7 -> 0 | AP7: =AC7 -> 0 | AQ7: =AE7 -> 0 | AR7: =SUM(AL7:AQ7) -> 1 | AT7: =AL7/AL$2 -> 0.021276596 | AU7: =AM7/AM$2 -> 0.11538462 | AV7: =AN7/AN$2 -> 0 | AW7: =AO7/AO$2 -> 0 | AX7: =AP7/AP$2 -> 0 | AY7: =AQ7/AQ$2 -> 0 | AZ7: =AR7/AR$2 -> 0.066666667
T8: Hạt iSS01G-Out | U8: 0.3 | V8: =U8*$U$3 -> 5464.993 | W8: 0.7 | X8: =W8*$W$3 -> 14676.614 | Z8: =Y8*$Y$3 -> 0 | AB8: =AA8*$AA$3 -> 0 | AD8: =AC8*$AC$3 -> 0 | AF8: =AE8*$AE$3 -> 0 | AG8: =U8+W8+Y8+AA8+AC8+AE8 -> 1 | AH8: =V8+X8+Z8+AB8+AD8+AF8 -> 20141.607 | AI8: =$AI$4*AJ8 -> 31535000 | AJ8: =AJ7+30 -> 1190 | AL8: =U8 -> 0.3 | AM8: =W8 -> 0.7 | AN8: =Y8 -> 0 | AO8: =AA8 -> 0 | AP8: =AC8 -> 0 | AQ8: =AE8 -> 0 | AR8: =SUM(AL8:AQ8) -> 1 | AT8: =AL8/AL$2 -> 0.063829787 | AU8: =AM8/AM$2 -> 0.08974359 | AV8: =AN8/AN$2 -> 0 | AW8: =AO8/AO$2 -> 0 | AX8: =AP8/AP$2 -> 0 | AY8: =AQ8/AQ$2 -> 0 | AZ8: =AR8/AR$2 -> 0.066666667
T9: Hạt WSS03G-PW | U9: 0.55 | V9: =U9*$U$3 -> 10019.154 | W9: 0.3 | X9: =W9*$W$3 -> 6289.9773 | Y9: 0.15 | Z9: =Y9*$Y$3 -> 2732.4965 | AB9: =AA9*$AA$3 -> 0 | AD9: =AC9*$AC$3 -> 0 | AF9: =AE9*$AE$3 -> 0 | AG9: =U9+W9+Y9+AA9+AC9+AE9 -> 1 | AH9: =V9+X9+Z9+AB9+AD9+AF9 -> 19041.628 | AI9: =$AI$4*AJ9 -> 28885000 | AJ9: =AJ7-70 -> 1090 | AL9: =U9 -> 0.55 | AM9: =W9 -> 0.3 | AN9: =Y9 -> 0.15 | AO9: =AA9 -> 0 | AP9: =AC9 -> 0 | AQ9: =AE9 -> 0 | AR9: =SUM(AL9:AQ9) -> 1 | AT9: =AL9/AL$2 -> 0.11702128 | AU9: =AM9/AM$2 -> 0.038461538 | AV9: =AN9/AN$2 -> 0.375 | AW9: =AO9/AO$2 -> 0 | AX9: =AP9/AP$2 -> 0 | AY9: =AQ9/AQ$2 -> 0 | AZ9: =AR9/AR$2 -> 0.066666667
T10: Hạt WSS05SB (sợi ngắn) | U10: 0.95 | V10: =U10*$U$3 -> 17305.811 | X10: =W10*$W$3 -> 0 | Z10: =Y10*$Y$3 -> 0 | AA10: 0.05 | AB10: =AA10*$AA$3 -> 845.84173 | AD10: =AC10*$AC$3 -> 0 | AF10: =AE10*$AE$3 -> 0 | AG10: =U10+W10+Y10+AA10+AC10+AE10 -> 1 | AH10: =V10+X10+Z10+AB10+AD10+AF10 -> 18151.653 | AI10: =$AI$4*AJ10 -> 19080000 | AJ10: 720 | AL10: =U10 -> 0.95 | AM10: =W10 -> 0 | AN10: =Y10 -> 0 | AO10: =AA10 -> 0.05 | AP10: =AC10 -> 0 | AQ10: =AE10 -> 0 | AR10: =SUM(AL10:AQ10) -> 1 | AT10: =AL10/AL$2 -> 0.20212766 | AU10: =AM10/AM$2 -> 0 | AV10: =AN10/AN$2 -> 0 | AW10: =AO10/AO$2 -> 0.05 | AX10: =AP10/AP$2 -> 0 | AY10: =AQ10/AQ$2 -> 0 | AZ10: =AR10/AR$2 -> 0.066666667
T11: Vảy FPET201-Out | U11: 0.65 | V11: =U11*$U$3 -> 11840.818 | W11: 0.15 | X11: =W11*$W$3 -> 3144.9887 | Z11: =Y11*$Y$3 -> 0 | AA11: 0.2 | AB11: =AA11*$AA$3 -> 3383.3669 | AD11: =AC11*$AC$3 -> 0 | AF11: =AE11*$AE$3 -> 0 | AG11: =U11+W11+Y11+AA11+AC11+AE11 -> 1 | AH11: =V11+X11+Z11+AB11+AD11+AF11 -> 18369.174 | AI11: =$AI$4*AJ11 -> 0 | AL11: =U11 -> 0.65 | AM11: =W11 -> 0.15 | AN11: =Y11 -> 0 | AO11: =AA11 -> 0.2 | AP11: =AC11 -> 0 | AQ11: =AE11 -> 0 | AR11: =SUM(AL11:AQ11) -> 1 | AT11: =AL11/AL$2 -> 0.13829787 | AU11: =AM11/AM$2 -> 0.019230769 | AV11: =AN11/AN$2 -> 0 | AW11: =AO11/AO$2 -> 0.2 | AX11: =AP11/AP$2 -> 0 | AY11: =AQ11/AQ$2 -> 0 | AZ11: =AR11/AR$2 -> 0.066666667
T14: Chai B1.1 | W14: B1.1 | AG14: 0.53 | AL14: =SUM(AL15:AL18) -> 0 | AM14: =SUM(AM15:AM18) -> 4 | AN14: =SUM(AN15:AN18) -> 0 | AO14: =SUM(AO15:AO18) -> 0 | AP14: =SUM(AP15:AP18) -> 0 | AQ14: =SUM(AQ15:AQ18) -> 0 | AR14: =SUM(AR15:AR18) -> 4 | AT14: =AL14/AL$2 -> 0 | AU14: =AM14/AM$2 -> 0.51282051 | AV14: =AN14/AN$2 -> 0 | AW14: =AO14/AO$2 -> 0 | AX14: =AP14/AP$2 -> 0 | AY14: =AQ14/AQ$2 -> 0 | AZ14: =AR14/AR$2 -> 0.26666667
T15: Hạt WSS01G | V15: =U15*$U$3 -> 0 | W15: 1 | X15: =W15*$W$3 -> 20966.591 | Z15: =Y15*$Y$3 -> 0 | AB15: =AA15*$AA$3 -> 0 | AD15: =AC15*$AC$3 -> 0 | AF15: =AE15*$AE$3 -> 0 | AG15: =U15+W15+Y15+AA15+AC15+AE15 -> 1 | AH15: =V15+X15+Z15+AB15+AD15+AF15 -> 20966.591 | AI15: =$AI$4*AJ15 -> 30740000 | AJ15: =AJ7 -> 1160 | AL15: =U15 -> 0 | AM15: =W15 -> 1 | AN15: =Y15 -> 0 | AO15: =AA15 -> 0 | AP15: =AC15 -> 0 | AQ15: =AE15 -> 0 | AR15: =SUM(AL15:AQ15) -> 1 | AT15: =AL15/AL$2 -> 0 | AU15: =AM15/AM$2 -> 0.12820513 | AV15: =AN15/AN$2 -> 0 | AW15: =AO15/AO$2 -> 0 | AX15: =AP15/AP$2 -> 0 | AY15: =AQ15/AQ$2 -> 0 | AZ15: =AR15/AR$2 -> 0.066666667
T16: Hạt iSS01G | V16: =U16*$U$3 -> 0 | W16: 1 | X16: =W16*$W$3 -> 20966.591 | Z16: =Y16*$Y$3 -> 0 | AB16: =AA16*$AA$3 -> 0 | AD16: =AC16*$AC$3 -> 0 | AF16: =AE16*$AE$3 -> 0 | AG16: =U16+W16+Y16+AA16+AC16+AE16 -> 1 | AH16: =V16+X16+Z16+AB16+AD16+AF16 -> 20966.591 | AI16: =$AI$4*AJ16 -> 31535000 | AJ16: =AJ7+30 -> 1190 | AL16: =U16 -> 0 | AM16: =W16 -> 1 | AN16: =Y16 -> 0 | AO16: =AA16 -> 0 | AP16: =AC16 -> 0 | AQ16: =AE16 -> 0 | AR16: =SUM(AL16:AQ16) -> 1 | AT16: =AL16/AL$2 -> 0 | AU16: =AM16/AM$2 -> 0.12820513 | AV16: =AN16/AN$2 -> 0 | AW16: =AO16/AO$2 -> 0 | AX16: =AP16/AP$2 -> 0 | AY16: =AQ16/AQ$2 -> 0 | AZ16: =AR16/AR$2 -> 0.066666667
T17: Hạt iSS01084G | V17: =U17*$U$3 -> 0 | W17: 1 | X17: =W17*$W$3 -> 20966.591 | Z17: =Y17*$Y$3 -> 0 | AB17: =AA17*$AA$3 -> 0 | AD17: =AC17*$AC$3 -> 0 | AF17: =AE17*$AE$3 -> 0 | AG17: =U17+W17+Y17+AA17+AC17+AE17 -> 1 | AH17: =V17+X17+Z17+AB17+AD17+AF17 -> 20966.591 | AI17: =$AI$4*AJ17 -> 33125000 | AJ17: =AJ7+90 -> 1250 | AL17: =U17 -> 0 | AM17: =W17 -> 1 | AN17: =Y17 -> 0 | AO17: =AA17 -> 0 | AP17: =AC17 -> 0 | AQ17: =AE17 -> 0 | AR17: =SUM(AL17:AQ17) -> 1 | AT17: =AL17/AL$2 -> 0 | AU17: =AM17/AM$2 -> 0.12820513 | AV17: =AN17/AN$2 -> 0 | AW17: =AO17/AO$2 -> 0 | AX17: =AP17/AP$2 -> 0 | AY17: =AQ17/AQ$2 -> 0 | AZ17: =AR17/AR$2 -> 0.066666667
T18: Hạt WSS03G | V18: =U18*$U$3 -> 0 | W18: 1 | X18: =W18*$W$3 -> 20966.591 | Z18: =Y18*$Y$3 -> 0 | AB18: =AA18*$AA$3 -> 0 | AD18: =AC18*$AC$3 -> 0 | AF18: =AE18*$AE$3 -> 0 | AG18: =U18+W18+Y18+AA18+AC18+AE18 -> 1 | AH18: =V18+X18+Z18+AB18+AD18+AF18 -> 20966.591 | AI18: =$AI$4*AJ18 -> 29945000 | AJ18: =AJ7-30 -> 1130 | AL18: =U18 -> 0 | AM18: =W18 -> 1 | AN18: =Y18 -> 0 | AO18: =AA18 -> 0 | AP18: =AC18 -> 0 | AQ18: =AE18 -> 0 | AR18: =SUM(AL18:AQ18) -> 1 | AT18: =AL18/AL$2 -> 0 | AU18: =AM18/AM$2 -> 0.12820513 | AV18: =AN18/AN$2 -> 0 | AW18: =AO18/AO$2 -> 0 | AX18: =AP18/AP$2 -> 0 | AY18: =AQ18/AQ$2 -> 0 | AZ18: =AR18/AR$2 -> 0.066666667
T24: Chai B2.2 +B5 | AG24: 0.05 | AL24: =SUM(AL25:AL29) -> 2.15 | AM24: =SUM(AM25:AM29) -> 1.75 | AN24: =SUM(AN25:AN29) -> 0.25 | AO24: =SUM(AO25:AO29) -> 0.75 | AP24: =SUM(AP25:AP29) -> 0.1 | AQ24: =SUM(AQ25:AQ29) -> 0 | AR24: =SUM(AR25:AR29) -> 5 | AT24: =AL24/AL$2 -> 0.45744681 | AU24: =AM24/AM$2 -> 0.22435897 | AV24: =AN24/AN$2 -> 0.625 | AW24: =AO24/AO$2 -> 0.75 | AX24: =AP24/AP$2 -> 1 | AY24: =AQ24/AQ$2 -> 0 | AZ24: =AR24/AR$2 -> 0.33333333
T25: Hạt WSS01G-Nia | V25: =U25*$U$3 -> 0 | W25: 0.9 | X25: =W25*$W$3 -> 18869.932 | Y25: 0.1 | Z25: =Y25*$Y$3 -> 1821.6643 | AB25: =AA25*$AA$3 -> 0 | AD25: =AC25*$AC$3 -> 0 | AF25: =AE25*$AE$3 -> 0 | AG25: =U25+W25+Y25+AA25+AC25+AE25 -> 1 | AH25: =V25+X25+Z25+AB25+AD25+AF25 -> 20691.596 | AI25: =$AI$4*AJ25 -> 30740000 | AJ25: =AJ7 -> 1160 | AL25: =U25 -> 0 | AM25: =W25 -> 0.9 | AN25: =Y25 -> 0.1 | AO25: =AA25 -> 0 | AP25: =AC25 -> 0 | AQ25: =AE25 -> 0 | AR25: =SUM(AL25:AQ25) -> 1 | AT25: =AL25/AL$2 -> 0 | AU25: =AM25/AM$2 -> 0.11538462 | AV25: =AN25/AN$2 -> 0.25 | AW25: =AO25/AO$2 -> 0 | AX25: =AP25/AP$2 -> 0 | AY25: =AQ25/AQ$2 -> 0 | AZ25: =AR25/AR$2 -> 0.066666667
T26: Hạt WSS03G-PW | U26: 0.55 | V26: =U26*$U$3 -> 10019.154 | W26: 0.3 | X26: =W26*$W$3 -> 6289.9773 | Y26: 0.15 | Z26: =Y26*$Y$3 -> 2732.4965 | AB26: =AA26*$AA$3 -> 0 | AD26: =AC26*$AC$3 -> 0 | AF26: =AE26*$AE$3 -> 0 | AG26: =U26+W26+Y26+AA26+AC26+AE26 -> 1 | AH26: =V26+X26+Z26+AB26+AD26+AF26 -> 19041.628 | AI26: =$AI$4*AJ26 -> 28885000 | AJ26: =AJ7-70 -> 1090 | AL26: =U26 -> 0.55 | AM26: =W26 -> 0.3 | AN26: =Y26 -> 0.15 | AO26: =AA26 -> 0 | AP26: =AC26 -> 0 | AQ26: =AE26 -> 0 | AR26: =SUM(AL26:AQ26) -> 1 | AT26: =AL26/AL$2 -> 0.11702128 | AU26: =AM26/AM$2 -> 0.038461538 | AV26: =AN26/AN$2 -> 0.375 | AW26: =AO26/AO$2 -> 0 | AX26: =AP26/AP$2 -> 0 | AY26: =AQ26/AQ$2 -> 0 | AZ26: =AR26/AR$2 -> 0.066666667
T27: Hạt WSS01S | V27: =U27*$U$3 -> 0 | W27: 0.4 | X27: =W27*$W$3 -> 8386.6364 | Z27: =Y27*$Y$3 -> 0 | AA27: 0.5 | AB27: =AA27*$AA$3 -> 8458.4173 | AC27: 0.1 | AD27: =AC27*$AC$3 -> 1434.125 | AF27: =AE27*$AE$3 -> 0 | AG27: =U27+W27+Y27+AA27+AC27+AE27 -> 1 | AH27: =V27+X27+Z27+AB27+AD27+AF27 -> 18279.179 | AI27: =$AI$4*AJ27 -> 30740000 | AJ27: =AJ7 -> 1160 | AL27: =U27 -> 0 | AM27: =W27 -> 0.4 | AN27: =Y27 -> 0 | AO27: =AA27 -> 0.5 | AP27: =AC27 -> 0.1 | AQ27: =AE27 -> 0 | AR27: =SUM(AL27:AQ27) -> 1 | AT27: =AL27/AL$2 -> 0 | AU27: =AM27/AM$2 -> 0.051282051 | AV27: =AN27/AN$2 -> 0 | AW27: =AO27/AO$2 -> 0.5 | AX27: =AP27/AP$2 -> 1 | AY27: =AQ27/AQ$2 -> 0 | AZ27: =AR27/AR$2 -> 0.066666667
T28: Hạt WSS05SB (sợi ngắn) | U28: 0.95 | V28: =U28*$U$3 -> 17305.811 | X28: =W28*$W$3 -> 0 | Z28: =Y28*$Y$3 -> 0 | AA28: 0.05 | AB28: =AA28*$AA$3 -> 845.84173 | AD28: =AC28*$AC$3 -> 0 | AF28: =AE28*$AE$3 -> 0 | AG28: =U28+W28+Y28+AA28+AC28+AE28 -> 1 | AH28: =V28+X28+Z28+AB28+AD28+AF28 -> 18151.653 | AI28: =$AI$4*AJ28 -> 19080000 | AJ28: =AJ10 -> 720 | AL28: =U28 -> 0.95 | AM28: =W28 -> 0 | AN28: =Y28 -> 0 | AO28: =AA28 -> 0.05 | AP28: =AC28 -> 0 | AQ28: =AE28 -> 0 | AR28: =SUM(AL28:AQ28) -> 1 | AT28: =AL28/AL$2 -> 0.20212766 | AU28: =AM28/AM$2 -> 0 | AV28: =AN28/AN$2 -> 0 | AW28: =AO28/AO$2 -> 0.05 | AX28: =AP28/AP$2 -> 0 | AY28: =AQ28/AQ$2 -> 0 | AZ28: =AR28/AR$2 -> 0.066666667
T29: Vảy FPET201-Out | U29: 0.65 | V29: =U29*$U$3 -> 11840.818 | W29: 0.15 | X29: =W29*$W$3 -> 3144.9887 | Z29: =Y29*$Y$3 -> 0 | AA29: 0.2 | AB29: =AA29*$AA$3 -> 3383.3669 | AD29: =AC29*$AC$3 -> 0 | AF29: =AE29*$AE$3 -> 0 | AG29: =U29+W29+Y29+AA29+AC29+AE29 -> 1 | AH29: =V29+X29+Z29+AB29+AD29+AF29 -> 18369.174 | AI29: =$AI$4*AJ29 -> 0 | AL29: =U29 -> 0.65 | AM29: =W29 -> 0.15 | AN29: =Y29 -> 0 | AO29: =AA29 -> 0.2 | AP29: =AC29 -> 0 | AQ29: =AE29 -> 0 | AR29: =SUM(AL29:AQ29) -> 1 | AT29: =AL29/AL$2 -> 0.13829787 | AU29: =AM29/AM$2 -> 0.019230769 | AV29: =AN29/AN$2 -> 0 | AW29: =AO29/AO$2 -> 0.2 | AX29: =AP29/AP$2 -> 0 | AY29: =AQ29/AQ$2 -> 0 | AZ29: =AR29/AR$2 -> 0.066666667
T32: Chai B4 | AG32: 0.02
T33: Dây Đai | V33: =U33*$U$3 -> 0 | X33: =W33*$W$3 -> 0 | Z33: =Y33*$Y$3 -> 0 | AD33: =AC33*$AC$3 -> 0 | AE33: 1 | AF33: =AE33*$AE$3 -> 16505.154 | AG33: =U33+W33+Y33+AA33+AC33+AE33 -> 1 | AH33: =V33+X33+Z33+AB33+AD33+AF33 -> 16505.154 | AI33: =$AI$4*AJ33 -> 19000500 | AJ33: 717 | AL33: =U33 -> 0 | AM33: =W33 -> 0 | AN33: =Y33 -> 0 | AO33: =AA33 -> 0 | AP33: =AC33 -> 0 | AQ33: =AE33 -> 1 | AR33: =SUM(AL33:AQ33) -> 1 | AT33: =AL33/AL$2 -> 0 | AU33: =AM33/AM$2 -> 0 | AV33: =AN33/AN$2 -> 0 | AW33: =AO33/AO$2 -> 0 | AX33: =AP33/AP$2 -> 0 | AY33: =AQ33/AQ$2 -> 1 | AZ33: =AR33/AR$2 -> 0.066666667
AE35: ='Giá mua Chai-Vảy'!O40 -> 8000
T36: Vảy_Nắp HD ép, cổ chai | AG36: 0.01
T37: rHDPE ép | V37: =U37*$U$3 -> 0 | X37: =W37*$W$3 -> 0 | Z37: =Y37*$Y$3 -> 0 | AD37: =AC37*$AC$3 -> 0 | AE37: 1 | AF37: =AE37*$AE$35 -> 8000 | AG37: =U37+W37+Y37+AA37+AC37+AE37 -> 1 | AH37: =V37+X37+Z37+AB37+AD37+AF37 -> 8000 | AI37: =$AI$4*AJ37 -> 19500000 | AJ37: =19500000/26500 -> 735.84906 | AK37: =AK$1+$W$2 -> 17636.978 | AL37: =AL$1+AK37*$AK$2+AJ37*$AJ$2 -> 0.31333333 | AM37: =AL37+$AM$1 -> 0.83333333 | AN37: =AL37+$AN$1 -> 0.34 | AO37: =AM37 -> 0.83333333 | AP37: =$AP$4*AQ37/1000 -> 0 | AQ37: =AE37 -> 1 | AR37: =SUM(AL37:AQ37) -> 3.32

Sheet Hảo_R&D (Vảy sạch) (giảm giá)
B1: Sơ đồ khối dòng nguyên liệu-sản phẩm hiện tại của DTR. | T1: Giá chai mua vào | U1: ='Giá mua Chai-Vảy (Giá giảm)'!E18 -> 13000 | W1: ='Giá mua Chai-Vảy (Giá giảm)'!E14 -> 14500 | X1: =W3-W1-X3 -> 1749.9477 | Y1: ='Giá mua Chai-Vảy (Giá giảm)'!E15 -> 13000 | AA1: ='Giá mua Chai-Vảy (Giá giảm)'!E17 -> 11500 | AB1: ='[2]18. Vảy B5'!$I$10 -> 411.6804 | AC1: ='[2]16.1 Rửa vảy B7'!$I$9 -> 7971.0145 | AD1: ='[2]16.1 Rửa vảy B7'!$I$10 -> 84.555435 | AE1: ='Giá mua Chai-Vảy (Giá giảm)'!E16 -> 11500
B2: Với phân bố và định hướng sản phẩm như hiện nay, một số nguyên liệu đầu vào (B2.2/B4/B5) đang gặp khó khăn về giá, do gánh chung dòng chảy với chỉ khoảng 53% nguyên liệu chính B1.1. | T2: Giá thành vảy sạch => từ vảy mua ngoài | W2: ='[2]12. 100% vảy->hạt WSS01-iSS01'!$I$30 -> 17636.978 | X2: ='[2]12. 100% vảy->hạt WSS01-iSS01'!$I$10 -> 1636.9775
T3: Giá thành vảy sạch => từ chai | U3: =U1+X3 -> 17716.643 | W3: ='[2]10. 100% chai->hạt WSS01-iSS01'!$I$60 -> 20966.591 | X3: ='[2]10. 100% chai->hạt WSS01-iSS01'!$I$21+'[2]10. 100% chai->hạt WSS01-iSS01'!$I$37 -> 4716.6433 | Y3: =Y1+X3 -> 17716.643 | AA3: ='[2]18. Vảy B5'!$I$58 -> 16916.835 | AB3: ='[2]18. Vảy B5'!$I$21+'[2]18. Vảy B5'!$I$37 -> 4505.1542 | AC3: ='[2]16.1 Rửa vảy B7'!$I$48 -> 14341.25 | AD3: ='[2]16.1 Rửa vảy B7'!$I$11+'[2]16.1 Rửa vảy B7'!$I$27 -> 6285.6803 | AE3: =AE1+AB3 -> 16005.154 | AG3: Giá thành vảy sạch | AI3: Giá bán Hạt | AJ3: Exw | AL3: Giá thành vảy sạch
T4: Tên TP | U4: Loại vảy 1 | W4: Loại vảy 2 | Y4: Loại vảy 3 | AA4: Loại vảy 4 | AC4: Loại vảy 5 | AE4: Loại vảy 6 | AG4: Cộng | AI4: 26500
U5: B6.2 | V5: VND | W5: B1 | X5: VND | Y5: B2.2 | Z5: VND | AA5: B5 | AB5: VND | AC5: B7 | AD5: VND | AE5: B4 | AF5: VND | AH5: VND | AI5: VND | AJ5: USD
T6: Chai B6.2 | AG6: 0.3
T7: Hạt WSS01G-Nia | U7: 0.1 | V7: =U7*$U$3 -> 1771.6643 | W7: 0.9 | X7: =W7*$W$3 -> 18869.932 | Z7: =Y7*$Y$3 -> 0 | AB7: =AA7*$AA$3 -> 0 | AD7: =AC7*$AC$3 -> 0 | AF7: =AE7*$AE$3 -> 0 | AG7: =U7+W7+Y7+AA7+AC7+AE7 -> 1 | AH7: =V7+X7+Z7+AB7+AD7+AF7 -> 20641.596 | AI7: =$AI$4*AJ7 -> 30740000 | AJ7: 1160 | AL7: =AH7/$AI$4*1000 -> 778.92816
T8: Hạt iSS01G-Out | U8: 0.3 | V8: =U8*$U$3 -> 5314.993 | W8: 0.7 | X8: =W8*$W$3 -> 14676.614 | Z8: =Y8*$Y$3 -> 0 | AB8: =AA8*$AA$3 -> 0 | AD8: =AC8*$AC$3 -> 0 | AF8: =AE8*$AE$3 -> 0 | AG8: =U8+W8+Y8+AA8+AC8+AE8 -> 1 | AH8: =V8+X8+Z8+AB8+AD8+AF8 -> 19991.607 | AI8: =$AI$4*AJ8 -> 31535000 | AJ8: =AJ7+30 -> 1190 | AL8: =AH8/$AI$4*1000 -> 754.40025
T9: Hạt WSS03G-PW | U9: 0.55 | V9: =U9*$U$3 -> 9744.1538 | W9: 0.3 | X9: =W9*$W$3 -> 6289.9773 | Y9: 0.15 | Z9: =Y9*$Y$3 -> 2657.4965 | AB9: =AA9*$AA$3 -> 0 | AD9: =AC9*$AC$3 -> 0 | AF9: =AE9*$AE$3 -> 0 | AG9: =U9+W9+Y9+AA9+AC9+AE9 -> 1 | AH9: =V9+X9+Z9+AB9+AD9+AF9 -> 18691.628 | AI9: =$AI$4*AJ9 -> 28885000 | AJ9: =AJ7-70 -> 1090 | AL9: =AH9/$AI$4*1000 -> 705.34444
T10: Hạt WSS05SB (sợi ngắn) | U10: 0.95 | V10: =U10*$U$3 -> 16830.811 | X10: =W10*$W$3 -> 0 | Z10: =Y10*$Y$3 -> 0 | AA10: 0.05 | AB10: =AA10*$AA$3 -> 845.84173 | AD10: =AC10*$AC$3 -> 0 | AF10: =AE10*$AE$3 -> 0 | AG10: =U10+W10+Y10+AA10+AC10+AE10 -> 1 | AH10: =V10+X10+Z10+AB10+AD10+AF10 -> 17676.653 | AI10: =$AI$4*AJ10 -> 19080000 | AJ10: 720 | AL10: =AH10/$AI$4*1000 -> 667.0435
T11: Vảy FPET201-Out | U11: 0.65 | V11: =U11*$U$3 -> 11515.818 | W11: 0.15 | X11: =W11*$W$3 -> 3144.9887 | Z11: =Y11*$Y$3 -> 0 | AA11: 0.2 | AB11: =AA11*$AA$3 -> 3383.3669 | AD11: =AC11*$AC$3 -> 0 | AF11: =AE11*$AE$3 -> 0 | AG11: =U11+W11+Y11+AA11+AC11+AE11 -> 1 | AH11: =V11+X11+Z11+AB11+AD11+AF11 -> 18044.174 | AI11: =$AI$4*AJ11 -> 16032500 | AJ11: 605 | AL11: =AH11/$AI$4*1000 -> 680.91222
T14: Chai B1.1 | W14: B1.1 | AG14: 0.53
T15: Hạt WSS01G | V15: =U15*$U$3 -> 0 | W15: 1 | X15: =W15*$W$3 -> 20966.591 | Z15: =Y15*$Y$3 -> 0 | AB15: =AA15*$AA$3 -> 0 | AD15: =AC15*$AC$3 -> 0 | AF15: =AE15*$AE$3 -> 0 | AG15: =U15+W15+Y15+AA15+AC15+AE15 -> 1 | AH15: =V15+X15+Z15+AB15+AD15+AF15 -> 20966.591 | AI15: =$AI$4*AJ15 -> 30740000 | AJ15: =AJ7 -> 1160 | AL15: =AH15/$AI$4*1000 -> 791.19211
T16: Hạt iSS01G | V16: =U16*$U$3 -> 0 | W16: 1 | X16: =W16*$W$3 -> 20966.591 | Z16: =Y16*$Y$3 -> 0 | AB16: =AA16*$AA$3 -> 0 | AD16: =AC16*$AC$3 -> 0 | AF16: =AE16*$AE$3 -> 0 | AG16: =U16+W16+Y16+AA16+AC16+AE16 -> 1 | AH16: =V16+X16+Z16+AB16+AD16+AF16 -> 20966.591 | AI16: =$AI$4*AJ16 -> 31535000 | AJ16: =AJ7+30 -> 1190 | AL16: =AH16/$AI$4*1000 -> 791.19211
T17: Hạt iSS01084G | V17: =U17*$U$3 -> 0 | W17: 1 | X17: =W17*$W$3 -> 20966.591 | Z17: =Y17*$Y$3 -> 0 | AB17: =AA17*$AA$3 -> 0 | AD17: =AC17*$AC$3 -> 0 | AF17: =AE17*$AE$3 -> 0 | AG17: =U17+W17+Y17+AA17+AC17+AE17 -> 1 | AH17: =V17+X17+Z17+AB17+AD17+AF17 -> 20966.591 | AI17: =$AI$4*AJ17 -> 33125000 | AJ17: =AJ7+90 -> 1250 | AL17: =AH17/$AI$4*1000 -> 791.19211
T18: Hạt WSS03G | V18: =U18*$U$3 -> 0 | W18: 1 | X18: =W18*$W$3 -> 20966.591 | Z18: =Y18*$Y$3 -> 0 | AB18: =AA18*$AA$3 -> 0 | AD18: =AC18*$AC$3 -> 0 | AF18: =AE18*$AE$3 -> 0 | AG18: =U18+W18+Y18+AA18+AC18+AE18 -> 1 | AH18: =V18+X18+Z18+AB18+AD18+AF18 -> 20966.591 | AI18: =$AI$4*AJ18 -> 29945000 | AJ18: =AJ7-30 -> 1130 | AL18: =AH18/$AI$4*1000 -> 791.19211
T24: Chai B2.2 +B5 | AG24: 0.05
T25: Hạt WSS01G-Nia | V25: =U25*$U$3 -> 0 | W25: 0.9 | X25: =W25*$W$3 -> 18869.932 | Y25: 0.1 | Z25: =Y25*$Y$3 -> 1771.6643 | AB25: =AA25*$AA$3 -> 0 | AD25: =AC25*$AC$3 -> 0 | AF25: =AE25*$AE$3 -> 0 | AG25: =U25+W25+Y25+AA25+AC25+AE25 -> 1 | AH25: =V25+X25+Z25+AB25+AD25+AF25 -> 20641.596 | AI25: =$AI$4*AJ25 -> 30740000 | AJ25: =AJ7 -> 1160 | AL25: =AH25/$AI$4*1000 -> 778.92816
T26: Hạt WSS03G-PW | U26: 0.55 | V26: =U26*$U$3 -> 9744.1538 | W26: 0.3 | X26: =W26*$W$3 -> 6289.9773 | Y26: 0.15 | Z26: =Y26*$Y$3 -> 2657.4965 | AB26: =AA26*$AA$3 -> 0 | AD26: =AC26*$AC$3 -> 0 | AF26: =AE26*$AE$3 -> 0 | AG26: =U26+W26+Y26+AA26+AC26+AE26 -> 1 | AH26: =V26+X26+Z26+AB26+AD26+AF26 -> 18691.628 | AI26: =$AI$4*AJ26 -> 28885000 | AJ26: =AJ7-70 -> 1090 | AL26: =AH26/$AI$4*1000 -> 705.34444
T27: Hạt WSS01S | V27: =U27*$U$3 -> 0 | W27: 0.4 | X27: =W27*$W$3 -> 8386.6364 | Z27: =Y27*$Y$3 -> 0 | AA27: 0.5 | AB27: =AA27*$AA$3 -> 8458.4173 | AC27: 0.1 | AD27: =AC27*$AC$3 -> 1434.125 | AF27: =AE27*$AE$3 -> 0 | AG27: =U27+W27+Y27+AA27+AC27+AE27 -> 1 | AH27: =V27+X27+Z27+AB27+AD27+AF27 -> 18279.179 | AI27: =$AI$4*AJ27 -> 30740000 | AJ27: =AJ7 -> 1160 | AL27: =AH27/$AI$4*1000 -> 689.78033
T28: Hạt WSS05SB (sợi ngắn) | U28: 0.95 | V28: =U28*$U$3 -> 16830.811 | X28: =W28*$W$3 -> 0 | Z28: =Y28*$Y$3 -> 0 | AA28: 0.05 | AB28: =AA28*$AA$3 -> 845.84173 | AD28: =AC28*$AC$3 -> 0 | AF28: =AE28*$AE$3 -> 0 | AG28: =U28+W28+Y28+AA28+AC28+AE28 -> 1 | AH28: =V28+X28+Z28+AB28+AD28+AF28 -> 17676.653 | AI28: =$AI$4*AJ28 -> 19080000 | AJ28: =AJ10 -> 720 | AL28: =AH28/$AI$4*1000 -> 667.0435
T29: Vảy FPET201-Out | U29: 0.65 | V29: =U29*$U$3 -> 11515.818 | W29: 0.15 | X29: =W29*$W$3 -> 3144.9887 | Z29: =Y29*$Y$3 -> 0 | AA29: 0.2 | AB29: =AA29*$AA$3 -> 3383.3669 | AD29: =AC29*$AC$3 -> 0 | AF29: =AE29*$AE$3 -> 0 | AG29: =U29+W29+Y29+AA29+AC29+AE29 -> 1 | AH29: =V29+X29+Z29+AB29+AD29+AF29 -> 18044.174 | AI29: =$AI$4*AJ29 -> 16032500 | AJ29: 605 | AL29: =AH29/$AI$4*1000 -> 680.91222
T32: Chai B4 | AG32: 0.02
T33: Dây Đai | V33: =U33*$U$3 -> 0 | X33: =W33*$W$3 -> 0 | Z33: =Y33*$Y$3 -> 0 | AD33: =AC33*$AC$3 -> 0 | AE33: 1 | AF33: =AE33*$AE$3 -> 16005.154 | AG33: =U33+W33+Y33+AA33+AC33+AE33 -> 1 | AH33: =V33+X33+Z33+AB33+AD33+AF33 -> 16005.154 | AI33: =$AI$4*AJ33 -> 19000500 | AJ33: 717 | AL33: =AH33/$AI$4*1000 -> 603.96808
AE35: ='Giá mua Chai-Vảy'!O40 -> 8000
T36: Vảy_Nắp HD ép, cổ chai | AG36: 0.01
T37: rHDPE ép | V37: =U37*$U$3 -> 0 | X37: =W37*$W$3 -> 0 | Z37: =Y37*$Y$3 -> 0 | AD37: =AC37*$AC$3 -> 0 | AE37: 1 | AF37: =AE37*$AE$35 -> 8000 | AG37: =U37+W37+Y37+AA37+AC37+AE37 -> 1 | AH37: =V37+X37+Z37+AB37+AD37+AF37 -> 8000 | AI37: =$AI$4*AJ37 -> 19500000 | AJ37: =19500000/26500 -> 735.84906 | AK37: =AK$1+$W$2 -> 17636.978 | AL37: =AL$1+AK37*$AK$2+AJ37*$AJ$2 -> 0 | AM37: =AL37+$AM$1 -> 0 | AN37: =AL37+$AN$1 -> 0 | AO37: =AM37 -> 0 | AP37: =$AP$4*AQ37/1000 -> 0

Sheet Hảo_R&D (Hạt)
B1: Sơ đồ khối dòng nguyên liệu-sản phẩm hiện tại của DTR. | T1: Giá chai mua vào | U1: ='Giá mua Chai-Vảy'!E18 -> 13500 | W1: ='[2]10. 100% chai->hạt WSS01-iSS01'!$H$9 -> 15000 | X1: =W3-W1-X3 -> 1249.9477 | Y1: ='Giá mua Chai-Vảy'!E15 -> 13500 | AA1: ='[2]18. Vảy B5'!$I$9 -> 12000 | AB1: ='[2]18. Vảy B5'!$I$10 -> 411.6804 | AC1: ='[2]16.1 Rửa vảy B7'!$I$9 -> 7971.0145 | AD1: ='[2]16.1 Rửa vảy B7'!$I$10 -> 84.555435 | AE1: ='Giá mua Chai-Vảy'!E16 -> 12000 | AI1: ='[2]10. 100% chai->hạt WSS01-iSS01'!$I$61 -> 3384.4942 | AJ1: ='[2]10. 100% chai->hạt WSS01-iSS01'!$I$83 -> 1901.1244 | AK1: ='[2]11. 100% chai->hạt iSS01084G'!$I$83 -> 2331.8861
B2: Với phân bố và định hướng sản phẩm như hiện nay, một số nguyên liệu đầu vào (B2.2/B4/B5) đang gặp khó khăn về giá, do gánh chung dòng chảy với chỉ khoảng 53% nguyên liệu chính B1.1. | T2: Giá thành vảy sạch => từ vảy mua ngoài | W2: ='[2]12. 100% vảy->hạt WSS01-iSS01'!$I$30 -> 17636.978 | X2: ='[2]12. 100% vảy->hạt WSS01-iSS01'!$I$10 -> 1636.9775
T3: Giá thành vảy sạch => từ chai | U3: =U1+X3 -> 18216.643 | W3: ='[2]10. 100% chai->hạt WSS01-iSS01'!$I$60 -> 20966.591 | X3: ='[2]10. 100% chai->hạt WSS01-iSS01'!$I$21+'[2]10. 100% chai->hạt WSS01-iSS01'!$I$37 -> 4716.6433 | Y3: =Y1+X3 -> 18216.643 | AA3: ='[2]18. Vảy B5'!$I$58 -> 16916.835 | AB3: ='[2]18. Vảy B5'!$I$21+'[2]18. Vảy B5'!$I$37 -> 4505.1542 | AC3: ='[2]16.1 Rửa vảy B7'!$I$48 -> 14341.25 | AD3: ='[2]16.1 Rửa vảy B7'!$I$11+'[2]16.1 Rửa vảy B7'!$I$27 -> 6285.6803 | AE3: =AE1+AB3 -> 16505.154 | AG3: Giá thành vảy sạch | AI3: Chi phi tạo hạt | AJ3: Chi phí nâng IV (8 tiếng) | AK3: Chi phí nâng IV (10 tiếng) | AL3: Giá thành hạt (IV8) | AM3: Giá bán Hạt | AN3: Exw | AO3: LG | AP3: % | AQ3: Chi phí quản lý | AR3: Giá bán vảy
T4: Tên TP | U4: Loại vảy 1 | W4: Loại vảy 2 | Y4: Loại vảy 3 | AA4: Loại vảy 4 | AC4: Loại vảy 5 | AE4: Loại vảy 6 | AG4: Cộng | AM4: 26500
U5: B6.2 | V5: VND | W5: B1 | X5: VND | Y5: B2.2 | Z5: VND | AA5: B5 | AB5: VND | AC5: B7 | AD5: VND | AE5: B4 | AF5: VND | AH5: VND | AM5: VND | AN5: USD
T6: Chai B6.2 | AG6: 0.3
