Workbook
Name \A: #REF!
Name \M: #REF!
Name ___ATS98: #REF!
Name ___BGT02: #REF!
Name ___CHF98: #REF!
Name ___CHX2002: #REF!
Name ___CHX2003: #REF!
Name ___CHX2004: #REF!
Name ___CHX2005: #REF!
Name ___DTB2003: #REF!
Name ___DTB2004: #REF!
Name ___LY01: #REF!
Name ___Mkt1: #REF!
Name ___VAR1: #REF!
Name ___VAR2: #REF!
Name ___var22: #REF!
Name ___VAR3: #REF!
Name ___VAR4: #REF!
Name ___VAR5: #REF!
Name ___VAR6: #REF!
Name ___VAR7: #REF!
Name __ATS98: #REF!
Name __BGT02: #REF!
Name __CHF98: #REF!
Name __CHX2002: #REF!
Name __CHX2003: #REF!
Name __CHX2004: #REF!
Name __CHX2005: #REF!
Name __DAT1: #REF!
Name __DAT10: #REF!
Name __DAT11: #REF!
Name __DAT12: #REF!
Name __DAT13: #REF!
Name __DAT14: #REF!
Name __DAT15: #REF!
Name __DAT16: #REF!
Name __DAT17: #REF!
Name __DAT18: #REF!
Name __DAT19: #REF!
Name __DAT2: #REF!
Name __DAT20: #REF!
Name __DAT21: #REF!
Name __DAT22: #REF!
Name __DAT23: #REF!
Name __DAT24: #REF!
Name __DAT25: #REF!
Name __DAT26: #REF!
Name __DAT27: #REF!
Name __DAT28: #REF!
Name __DAT29: #REF!
Name __DAT3: #REF!
Name __DAT30: #REF!
Name __DAT31: #REF!
Name __DAT32: #REF!
Name __DAT33: #REF!
Name __DAT34: #REF!
Name __DAT35: #REF!
Name __DAT36: #REF!
Name __DAT37: #REF!
Name __DAT38: #REF!

Sheet 4.DOANH THU
BG1: Đơn vị tính: triệu đồng
B2: DUYTAN TÁI CHẾ
B3: KẾ HOẠCH KINH DOANH & NGÂN SÁCH NĂM 2025
B4: DOANH THU | AT4: tự động, không điền số | AX4: tự động, không điền số | BC4: tự động, không điền số
B5: STT | D5: 2023 | R5: 2024 | AF5: 2025 | AT5: Năm | AX5: Biến động | BC5: Tỉ lệ %/Doanh thu | BG5: Giải trình
C6: Nội dung | D6: 01 | E6: 02 | F6: 03 | G6: 04 | H6: 05 | I6: 06 | J6: 07 | K6: 08 | L6: 09 | M6: 10 | N6: 11 | O6: 12 | P6: 2023 | R6: 01 | S6: 02 | T6: 03 | U6: 04 | V6: 05 | W6: 06 | X6: 07 | Y6: 08 | Z6: 09 | AA6: 10 | AB6: 11 | AC6: 12 | AD6: 2024 | AF6: 01 | AG6: 02 | AH6: 03 | AI6: 04 | AJ6: 05 | AK6: 06 | AL6: 07 | AM6: 08 | AN6: 09 | AO6: 10 | AP6: 11 | AQ6: 12 | AR6: 2025 | AT6: =P6 -> 2023 | AU6: =AD6 -> 2024 | AV6: =AR6 -> 2025 | AX6: 24 sv 23 | AY6: % | AZ6: 25 sv 24 | BA6: % | BC6: =AT6 -> 2023 | BD6: =AU6 -> 2024 | BE6: =AV6 -> 2025
B7: 1 | C7: SẢN LƯỢNG (tấn) | D7: =SUM(D8:D17) -> 651.8 | E7: =SUM(E8:E17) -> 653.075 | F7: =SUM(F8:F17) -> 1860.64 | G7: =SUM(G8:G17) -> 1792.575 | H7: =SUM(H8:H17) -> 1632.875 | I7: =SUM(I8:I17) -> 1573.975 | J7: =SUM(J8:J17) -> 1591.575 | K7: =SUM(K8:K17) -> 2445.175 | ... AR7: =SUM(AR8:AR17) -> #REF! | AT7: =P7 -> 21482.69 | AU7: =AD7 -> 45118.917 | AV7: =AR7 -> #REF! | AX7: =AU7-AT7 -> 23636.227 | AY7: =IFERROR(AX7/AT7,"") -> 1.1002452 | AZ7: =AV7-AU7 -> #REF! | BA7: =IFERROR(AZ7/AU7,"")
B8: 1.1 | C8: rPET | D8: 591.8 | E8: 546.775 | F8: 1734.14 | G8: 1712.85 | H8: 1466.4 | I8: 1412.6 | J8: 1477.45 | K8: 2318.6 | L8: 1561 | M8: 2096.9 | N8: 1926.425 | O8: 3138.4 | P8: =SUM(D8:O8) -> 19983.34 | R8: =SUMIFS('511'!$Q:$Q,'511'!$R:$R,'4.DOANH THU'!$C8,'511'!$A:$A,'4.DOANH THU'!R$6)/1000 -> 1901.95 | S8: =SUMIFS('511'!$Q:$Q,'511'!$R:$R,'4.DOANH THU'!$C8,'511'!$A:$A,'4.DOANH THU'!S$6)/1000 -> 1962.4 | T8: =SUMIFS('511'!$Q:$Q,'511'!$R:$R,'4.DOANH THU'!$C8,'511'!$A:$A,'4.DOANH THU'!T$6)/1000 -> 2680.425 | U8: =SUMIFS('511'!$Q:$Q,'511'!$R:$R,'4.DOANH THU'!$C8,'511'!$A:$A,'4.DOANH THU'!U$6)/1000 -> 2733.725 | V8: =SUMIFS('511'!$Q:$Q,'511'!$R:$R,'4.DOANH THU'!$C8,'511'!$A:$A,'4.DOANH THU'!V$6)/1000 -> 2891.725 | W8: =SUMIFS('511'!$Q:$Q,'511'!$R:$R,'4.DOANH THU'!$C8,'511'!$A:$A,'4.DOANH THU'!W$6)/1000 -> 1564.1 | X8: =SUMIFS('511'!$Q:$Q,'511'!$R:$R,'4.DOANH THU'!$C8,'511'!$A:$A,'4.DOANH THU'!X$6)/1000 -> 1508 | Y8: =SUMIFS('511'!$Q:$Q,'511'!$R:$R,'4.DOANH THU'!$C8,'511'!$A:$A,'4.DOANH THU'!Y$6)/1000 -> 4752.5829 | ... AA8: =SUMIFS('511'!$Q:$Q,'511'!$R:$R,'4.DOANH THU'!$C8,'511'!$A:$A,'4.DOANH THU'!AA$6)/1000 -> 3247.4 | AB8: 3514.7 | AC8: 6712 | AD8: =SUM(R8:AC8) -> 38046.708 | AF8: =SUMIFS('KH 2026'!N:N,'KH 2026'!$K:$K,'4.DOANH THU'!$C8) -> 3754.6359 | AG8: =SUMIFS('KH 2026'!O:O,'KH 2026'!$K:$K,'4.DOANH THU'!$C8) -> 3654.7276 | AH8: =SUMIFS('KH 2026'!P:P,'KH 2026'!$K:$K,'4.DOANH THU'!$C8) -> 3872.9704 | AI8: =SUMIFS('KH 2026'!Q:Q,'KH 2026'!$K:$K,'4.DOANH THU'!$C8) -> 3773.6445 | AJ8: =SUMIFS('KH 2026'!R:R,'KH 2026'!$K:$K,'4.DOANH THU'!$C8) -> 4033.8495 | AK8: =SUMIFS('KH 2026'!S:S,'KH 2026'!$K:$K,'4.DOANH THU'!$C8) -> 3849.3652 | AL8: =SUMIFS('KH 2026'!T:T,'KH 2026'!$K:$K,'4.DOANH THU'!$C8) -> 4007.8355 | AM8: =SUMIFS('KH 2026'!U:U,'KH 2026'!$K:$K,'4.DOANH THU'!$C8) -> 3868.2625 | AN8: =SUMIFS('KH 2026'!V:V,'KH 2026'!$K:$K,'4.DOANH THU'!$C8) -> 3873.0361 | AO8: =SUMIFS('KH 2026'!W:W,'KH 2026'!$K:$K,'4.DOANH THU'!$C8) -> 3750.0393 | AP8: =SUMIFS('KH 2026'!X:X,'KH 2026'!$K:$K,'4.DOANH THU'!$C8) -> 4016.6561 | AQ8: =SUMIFS('KH 2026'!Y:Y,'KH 2026'!$K:$K,'4.DOANH THU'!$C8) -> 3891.9334 | AR8: =SUM(AF8:AQ8) -> 46346.956 | AT8: =P8 -> 19983.34 | AU8: =AD8 -> 38046.708 | AV8: =AR8 -> 46346.956 | AX8: =AU8-AT8 -> 18063.368 | AY8: =IFERROR(AX8/AT8,"") -> 0.90392136 | AZ8: =AV8-AU8 -> 8300.2483 | BA8: =IFERROR(AZ8/AU8,"") -> 0.21815944
B9: 1.2 | C9: rHDPE | D9: 60 | E9: 106.3 | F9: 126.5 | G9: 79.725 | H9: 166.35 | I9: 161.375 | J9: 114.125 | K9: 126.5 | L9: 85.875 | M9: 162.625 | N9: 182.375 | O9: 127.4 | P9: =SUM(D9:O9) -> 1499.15 | R9: =SUMIFS('511'!$Q:$Q,'511'!$R:$R,'4.DOANH THU'!$C9,'511'!$A:$A,'4.DOANH THU'!R$6)/1000 -> 214.375 | S9: =SUMIFS('511'!$Q:$Q,'511'!$R:$R,'4.DOANH THU'!$C9,'511'!$A:$A,'4.DOANH THU'!S$6)/1000 -> 136.95 | T9: =SUMIFS('511'!$Q:$Q,'511'!$R:$R,'4.DOANH THU'!$C9,'511'!$A:$A,'4.DOANH THU'!T$6)/1000 -> 171.9 | U9: =SUMIFS('511'!$Q:$Q,'511'!$R:$R,'4.DOANH THU'!$C9,'511'!$A:$A,'4.DOANH THU'!U$6)/1000 -> 211.025 | V9: =SUMIFS('511'!$Q:$Q,'511'!$R:$R,'4.DOANH THU'!$C9,'511'!$A:$A,'4.DOANH THU'!V$6)/1000 -> 195.9 | W9: =SUMIFS('511'!$Q:$Q,'511'!$R:$R,'4.DOANH THU'!$C9,'511'!$A:$A,'4.DOANH THU'!W$6)/1000 -> 126.5 | X9: =SUMIFS('511'!$Q:$Q,'511'!$R:$R,'4.DOANH THU'!$C9,'511'!$A:$A,'4.DOANH THU'!X$6)/1000 -> 110.925 | Y9: =SUMIFS('511'!$Q:$Q,'511'!$R:$R,'4.DOANH THU'!$C9,'511'!$A:$A,'4.DOANH THU'!Y$6)/1000 -> 141.125 | ... AA9: =SUMIFS('511'!$Q:$Q,'511'!$R:$R,'4.DOANH THU'!$C9,'511'!$A:$A,'4.DOANH THU'!AA$6)/1000 -> 235.5 | AB9: 140 | AC9: 300.25 | AD9: =SUM(R9:AC9) -> 2127.725 | AF9: =SUMIFS('KH 2026'!N:N,'KH 2026'!$K:$K,'4.DOANH THU'!$C9) -> 0 | AG9: =SUMIFS('KH 2026'!O:O,'KH 2026'!$K:$K,'4.DOANH THU'!$C9) -> 0 | AH9: =SUMIFS('KH 2026'!P:P,'KH 2026'!$K:$K,'4.DOANH THU'!$C9) -> 0 | AI9: =SUMIFS('KH 2026'!Q:Q,'KH 2026'!$K:$K,'4.DOANH THU'!$C9) -> 0 | AJ9: =SUMIFS('KH 2026'!R:R,'KH 2026'!$K:$K,'4.DOANH THU'!$C9) -> 0 | AK9: =SUMIFS('KH 2026'!S:S,'KH 2026'!$K:$K,'4.DOANH THU'!$C9) -> 0 | AL9: =SUMIFS('KH 2026'!T:T,'KH 2026'!$K:$K,'4.DOANH THU'!$C9) -> 0 | AM9: =SUMIFS('KH 2026'!U:U,'KH 2026'!$K:$K,'4.DOANH THU'!$C9) -> 0 | AN9: =SUMIFS('KH 2026'!V:V,'KH 2026'!$K:$K,'4.DOANH THU'!$C9) -> 0 | AO9: =SUMIFS('KH 2026'!W:W,'KH 2026'!$K:$K,'4.DOANH THU'!$C9) -> 0 | AP9: =SUMIFS('KH 2026'!X:X,'KH 2026'!$K:$K,'4.DOANH THU'!$C9) -> 0 | AQ9: =SUMIFS('KH 2026'!Y:Y,'KH 2026'!$K:$K,'4.DOANH THU'!$C9) -> 0 | AR9: =SUM(AF9:AQ9) -> 0 | AT9: =P9 -> 1499.15 | AU9: =AD9 -> 2127.725 | AV9: =AR9 -> 0 | AX9: =AU9-AT9 -> 628.575 | AY9: =IFERROR(AX9/AT9,"") -> 0.4192876 | AZ9: =AV9-AU9 -> -2127.725 | BA9: =IFERROR(AZ9/AU9,"") -> -1
B10: 1.3 | C10: rPP | H10: 0.125 | K10: 0.075 | P10: =SUM(D10:O10) -> 0.2 | R10: =SUMIFS('511'!$Q:$Q,'511'!$R:$R,'4.DOANH THU'!$C10,'511'!$A:$A,'4.DOANH THU'!R$6)/1000 -> 15 | S10: =SUMIFS('511'!$Q:$Q,'511'!$R:$R,'4.DOANH THU'!$C10,'511'!$A:$A,'4.DOANH THU'!S$6)/1000 -> 15 | T10: =SUMIFS('511'!$Q:$Q,'511'!$R:$R,'4.DOANH THU'!$C10,'511'!$A:$A,'4.DOANH THU'!T$6)/1000 -> 56 | U10: =SUMIFS('511'!$Q:$Q,'511'!$R:$R,'4.DOANH THU'!$C10,'511'!$A:$A,'4.DOANH THU'!U$6)/1000 -> 30.5 | V10: =SUMIFS('511'!$Q:$Q,'511'!$R:$R,'4.DOANH THU'!$C10,'511'!$A:$A,'4.DOANH THU'!V$6)/1000 -> 35.25 | W10: =SUMIFS('511'!$Q:$Q,'511'!$R:$R,'4.DOANH THU'!$C10,'511'!$A:$A,'4.DOANH THU'!W$6)/1000 -> 5.25 | X10: =SUMIFS('511'!$Q:$Q,'511'!$R:$R,'4.DOANH THU'!$C10,'511'!$A:$A,'4.DOANH THU'!X$6)/1000 -> 0.3 | Y10: =SUMIFS('511'!$Q:$Q,'511'!$R:$R,'4.DOANH THU'!$C10,'511'!$A:$A,'4.DOANH THU'!Y$6)/1000 -> 41.675 | ... AA10: =SUMIFS('511'!$Q:$Q,'511'!$R:$R,'4.DOANH THU'!$C10,'511'!$A:$A,'4.DOANH THU'!AA$6)/1000 -> 18.025 | AB10: 20 | AC10: 20 | AD10: =SUM(R10:AC10) -> 257.025 | AF10: =SUMIFS('KH 2026'!N:N,'KH 2026'!$K:$K,'4.DOANH THU'!$C10) -> 72 | AG10: =SUMIFS('KH 2026'!O:O,'KH 2026'!$K:$K,'4.DOANH THU'!$C10) -> 63 | AH10: =SUMIFS('KH 2026'!P:P,'KH 2026'!$K:$K,'4.DOANH THU'!$C10) -> 72 | AI10: =SUMIFS('KH 2026'!Q:Q,'KH 2026'!$K:$K,'4.DOANH THU'!$C10) -> 63 | AJ10: =SUMIFS('KH 2026'!R:R,'KH 2026'!$K:$K,'4.DOANH THU'!$C10) -> 72 | AK10: =SUMIFS('KH 2026'!S:S,'KH 2026'!$K:$K,'4.DOANH THU'!$C10) -> 87 | AL10: =SUMIFS('KH 2026'!T:T,'KH 2026'!$K:$K,'4.DOANH THU'!$C10) -> 72 | AM10: =SUMIFS('KH 2026'!U:U,'KH 2026'!$K:$K,'4.DOANH THU'!$C10) -> 63 | AN10: =SUMIFS('KH 2026'!V:V,'KH 2026'!$K:$K,'4.DOANH THU'!$C10) -> 72 | AO10: =SUMIFS('KH 2026'!W:W,'KH 2026'!$K:$K,'4.DOANH THU'!$C10) -> 87 | AP10: =SUMIFS('KH 2026'!X:X,'KH 2026'!$K:$K,'4.DOANH THU'!$C10) -> 72 | AQ10: =SUMIFS('KH 2026'!Y:Y,'KH 2026'!$K:$K,'4.DOANH THU'!$C10) -> 63 | AR10: =SUM(AF10:AQ10) -> 858 | AT10: =P10 -> 0.2 | AU10: =AD10 -> 257.025 | AV10: =AR10 -> 858 | AX10: =AU10-AT10 -> 256.825 | AZ10: =AV10-AU10 -> 600.975 | BA10: =IFERROR(AZ10/AU10,"") -> 2.3381967
B11: 1.4 | C11: Xơ sợi | P11: =SUM(D11:O11) -> 0 | R11: =SUMIFS('511'!$Q:$Q,'511'!$R:$R,'4.DOANH THU'!$C11,'511'!$A:$A,'4.DOANH THU'!R$6)/1000 -> 22 | S11: =SUMIFS('511'!$Q:$Q,'511'!$R:$R,'4.DOANH THU'!$C11,'511'!$A:$A,'4.DOANH THU'!S$6)/1000 -> 50.025 | T11: =SUMIFS('511'!$Q:$Q,'511'!$R:$R,'4.DOANH THU'!$C11,'511'!$A:$A,'4.DOANH THU'!T$6)/1000 -> 0.075 | U11: =SUMIFS('511'!$Q:$Q,'511'!$R:$R,'4.DOANH THU'!$C11,'511'!$A:$A,'4.DOANH THU'!U$6)/1000 -> 225.5 | V11: =SUMIFS('511'!$Q:$Q,'511'!$R:$R,'4.DOANH THU'!$C11,'511'!$A:$A,'4.DOANH THU'!V$6)/1000 -> 82.55 | W11: =SUMIFS('511'!$Q:$Q,'511'!$R:$R,'4.DOANH THU'!$C11,'511'!$A:$A,'4.DOANH THU'!W$6)/1000 -> 185.9 | X11: =SUMIFS('511'!$Q:$Q,'511'!$R:$R,'4.DOANH THU'!$C11,'511'!$A:$A,'4.DOANH THU'!X$6)/1000 -> 165 | Y11: =SUMIFS('511'!$Q:$Q,'511'!$R:$R,'4.DOANH THU'!$C11,'511'!$A:$A,'4.DOANH THU'!Y$6)/1000 -> 0 | ... AA11: =SUMIFS('511'!$Q:$Q,'511'!$R:$R,'4.DOANH THU'!$C11,'511'!$A:$A,'4.DOANH THU'!AA$6)/1000 -> 231 | AB11: 33 | AC11: 220 | AD11: =SUM(R11:AC11) -> 1435.05 | AF11: =SUMIFS('KH 2026'!N:N,'KH 2026'!$K:$K,'4.DOANH THU'!$C11) -> 86.586983 | AG11: =SUMIFS('KH 2026'!O:O,'KH 2026'!$K:$K,'4.DOANH THU'!$C11) -> 86.586983 | AH11: =SUMIFS('KH 2026'!P:P,'KH 2026'!$K:$K,'4.DOANH THU'!$C11) -> 86.586983 | AI11: =SUMIFS('KH 2026'!Q:Q,'KH 2026'!$K:$K,'4.DOANH THU'!$C11) -> 86.586983 | AJ11: =SUMIFS('KH 2026'!R:R,'KH 2026'!$K:$K,'4.DOANH THU'!$C11) -> 86.586983 | AK11: =SUMIFS('KH 2026'!S:S,'KH 2026'!$K:$K,'4.DOANH THU'!$C11) -> 86.586983 | AL11: =SUMIFS('KH 2026'!T:T,'KH 2026'!$K:$K,'4.DOANH THU'!$C11) -> 86.586983 | AM11: =SUMIFS('KH 2026'!U:U,'KH 2026'!$K:$K,'4.DOANH THU'!$C11) -> 86.586983 | AN11: =SUMIFS('KH 2026'!V:V,'KH 2026'!$K:$K,'4.DOANH THU'!$C11) -> 86.586983 | AO11: =SUMIFS('KH 2026'!W:W,'KH 2026'!$K:$K,'4.DOANH THU'!$C11) -> 86.586983 | AP11: =SUMIFS('KH 2026'!X:X,'KH 2026'!$K:$K,'4.DOANH THU'!$C11) -> 86.586983 | AQ11: =SUMIFS('KH 2026'!Y:Y,'KH 2026'!$K:$K,'4.DOANH THU'!$C11) -> 86.586983 | AR11: =SUM(AF11:AQ11) -> 1039.0438 | AT11: =P11 -> 0 | AU11: =AD11 -> 1435.05 | AV11: =AR11 -> 1039.0438 | AX11: =AU11-AT11 -> 1435.05 | AY11: =IFERROR(AX11/AT11,"") | AZ11: =AV11-AU11 -> -396.0062 | BA11: =IFERROR(AZ11/AU11,"") -> -0.27595289
B12: 1.5 | C12: Khác (phó sản, phế liệu) | P12: =SUM(D12:O12) -> 0 | R12: =SUMIFS('511'!$Q:$Q,'511'!$R:$R,'4.DOANH THU'!$C12,'511'!$A:$A,'4.DOANH THU'!R$6)/1000 -> 246.83 | S12: =SUMIFS('511'!$Q:$Q,'511'!$R:$R,'4.DOANH THU'!$C12,'511'!$A:$A,'4.DOANH THU'!S$6)/1000 -> 55.676 | T12: =SUMIFS('511'!$Q:$Q,'511'!$R:$R,'4.DOANH THU'!$C12,'511'!$A:$A,'4.DOANH THU'!T$6)/1000 -> 5.668 | U12: =SUMIFS('511'!$Q:$Q,'511'!$R:$R,'4.DOANH THU'!$C12,'511'!$A:$A,'4.DOANH THU'!U$6)/1000 -> 2.002 | V12: =SUMIFS('511'!$Q:$Q,'511'!$R:$R,'4.DOANH THU'!$C12,'511'!$A:$A,'4.DOANH THU'!V$6)/1000 -> 37.269 | W12: =SUMIFS('511'!$Q:$Q,'511'!$R:$R,'4.DOANH THU'!$C12,'511'!$A:$A,'4.DOANH THU'!W$6)/1000 -> 39.315 | X12: =SUMIFS('511'!$Q:$Q,'511'!$R:$R,'4.DOANH THU'!$C12,'511'!$A:$A,'4.DOANH THU'!X$6)/1000 -> 22.628 | Y12: =SUMIFS('511'!$Q:$Q,'511'!$R:$R,'4.DOANH THU'!$C12,'511'!$A:$A,'4.DOANH THU'!Y$6)/1000 -> 193.176 | ... AA12: =SUMIFS('511'!$Q:$Q,'511'!$R:$R,'4.DOANH THU'!$C12,'511'!$A:$A,'4.DOANH THU'!AA$6)/1000 -> 219.938 | AB12: 200 | AC12: 200 | AD12: =SUM(R12:AC12) -> 1471.409 | AF12: =SUMIFS('KH 2026'!N:N,'KH 2026'!$K:$K,'4.DOANH THU'!$C12) -> 0 | AG12: =SUMIFS('KH 2026'!O:O,'KH 2026'!$K:$K,'4.DOANH THU'!$C12) -> 0 | AH12: =SUMIFS('KH 2026'!P:P,'KH 2026'!$K:$K,'4.DOANH THU'!$C12) -> 0 | AI12: =SUMIFS('KH 2026'!Q:Q,'KH 2026'!$K:$K,'4.DOANH THU'!$C12) -> 0 | AJ12: =SUMIFS('KH 2026'!R:R,'KH 2026'!$K:$K,'4.DOANH THU'!$C12) -> 0 | AK12: =SUMIFS('KH 2026'!S:S,'KH 2026'!$K:$K,'4.DOANH THU'!$C12) -> 0 | AL12: =SUMIFS('KH 2026'!T:T,'KH 2026'!$K:$K,'4.DOANH THU'!$C12) -> 0 | AM12: =SUMIFS('KH 2026'!U:U,'KH 2026'!$K:$K,'4.DOANH THU'!$C12) -> 0 | AN12: =SUMIFS('KH 2026'!V:V,'KH 2026'!$K:$K,'4.DOANH THU'!$C12) -> 0 | AO12: =SUMIFS('KH 2026'!W:W,'KH 2026'!$K:$K,'4.DOANH THU'!$C12) -> 0 | AP12: =SUMIFS('KH 2026'!X:X,'KH 2026'!$K:$K,'4.DOANH THU'!$C12) -> 0 | AQ12: =SUMIFS('KH 2026'!Y:Y,'KH 2026'!$K:$K,'4.DOANH THU'!$C12) -> 0 | AR12: =SUM(AF12:AQ12) -> 0 | AT12: =P12 -> 0 | AU12: =AD12 -> 1471.409 | AV12: =AR12 -> 0 | AX12: =AU12-AT12 -> 1471.409 | AY12: =IFERROR(AX12/AT12,"") | AZ12: =AV12-AU12 -> -1471.409
B13: 1.6 | C13: Khác (tài trợ) | P13: =SUM(D13:O13) -> 0 | R13: =SUMIFS('511'!$Q:$Q,'511'!$R:$R,'4.DOANH THU'!$C13,'511'!$A:$A,'4.DOANH THU'!R$6)/1000 -> 0 | S13: =SUMIFS('511'!$Q:$Q,'511'!$R:$R,'4.DOANH THU'!$C13,'511'!$A:$A,'4.DOANH THU'!S$6)/1000 -> 0 | T13: =SUMIFS('511'!$Q:$Q,'511'!$R:$R,'4.DOANH THU'!$C13,'511'!$A:$A,'4.DOANH THU'!T$6)/1000 -> 0 | U13: =SUMIFS('511'!$Q:$Q,'511'!$R:$R,'4.DOANH THU'!$C13,'511'!$A:$A,'4.DOANH THU'!U$6)/1000 -> 0 | V13: =SUMIFS('511'!$Q:$Q,'511'!$R:$R,'4.DOANH THU'!$C13,'511'!$A:$A,'4.DOANH THU'!V$6)/1000 -> 0 | W13: =SUMIFS('511'!$Q:$Q,'511'!$R:$R,'4.DOANH THU'!$C13,'511'!$A:$A,'4.DOANH THU'!W$6)/1000 -> 0 | X13: =SUMIFS('511'!$Q:$Q,'511'!$R:$R,'4.DOANH THU'!$C13,'511'!$A:$A,'4.DOANH THU'!X$6)/1000 -> 0 | Y13: =SUMIFS('511'!$Q:$Q,'511'!$R:$R,'4.DOANH THU'!$C13,'511'!$A:$A,'4.DOANH THU'!Y$6)/1000 -> 0 | ... AA13: =SUMIFS('511'!$Q:$Q,'511'!$R:$R,'4.DOANH THU'!$C13,'511'!$A:$A,'4.DOANH THU'!AA$6)/1000 -> 0 | AD13: =SUM(R13:AC13) -> 0 | AF13: =SUMIFS('KH 2026'!N:N,'KH 2026'!$K:$K,'4.DOANH THU'!$C13) -> 0 | AG13: =SUMIFS('KH 2026'!O:O,'KH 2026'!$K:$K,'4.DOANH THU'!$C13) -> 0 | AH13: =SUMIFS('KH 2026'!P:P,'KH 2026'!$K:$K,'4.DOANH THU'!$C13) -> 0 | AI13: =SUMIFS('KH 2026'!Q:Q,'KH 2026'!$K:$K,'4.DOANH THU'!$C13) -> 0 | AJ13: =SUMIFS('KH 2026'!R:R,'KH 2026'!$K:$K,'4.DOANH THU'!$C13) -> 0 | AK13: =SUMIFS('KH 2026'!S:S,'KH 2026'!$K:$K,'4.DOANH THU'!$C13) -> 0 | AL13: =SUMIFS('KH 2026'!T:T,'KH 2026'!$K:$K,'4.DOANH THU'!$C13) -> 0 | AM13: =SUMIFS('KH 2026'!U:U,'KH 2026'!$K:$K,'4.DOANH THU'!$C13) -> 0 | AN13: =SUMIFS('KH 2026'!V:V,'KH 2026'!$K:$K,'4.DOANH THU'!$C13) -> 0 | AO13: =SUMIFS('KH 2026'!W:W,'KH 2026'!$K:$K,'4.DOANH THU'!$C13) -> 0 | AP13: =SUMIFS('KH 2026'!X:X,'KH 2026'!$K:$K,'4.DOANH THU'!$C13) -> 0 | AQ13: =SUMIFS('KH 2026'!Y:Y,'KH 2026'!$K:$K,'4.DOANH THU'!$C13) -> 0 | AR13: =SUM(AF13:AQ13) -> 0 | AT13: =P13 -> 0 | AU13: =AD13 -> 0 | AV13: =AR13 -> 0 | AX13: =AU13-AT13 -> 0 | AY13: =IFERROR(AX13/AT13,"") | AZ13: =AV13-AU13 -> 0 | BA13: =IFERROR(AZ13/AU13,"")
B14: 1.7 | C14: Dây đai | P14: =SUM(D14:O14) -> 0 | R14: =SUMIFS('511'!$Q:$Q,'511'!$R:$R,'4.DOANH THU'!$C14,'511'!$A:$A,'4.DOANH THU'!R$6)/1000 -> 0 | S14: =SUMIFS('511'!$Q:$Q,'511'!$R:$R,'4.DOANH THU'!$C14,'511'!$A:$A,'4.DOANH THU'!S$6)/1000 -> 165 | T14: =SUMIFS('511'!$Q:$Q,'511'!$R:$R,'4.DOANH THU'!$C14,'511'!$A:$A,'4.DOANH THU'!T$6)/1000 -> 58 | U14: =SUMIFS('511'!$Q:$Q,'511'!$R:$R,'4.DOANH THU'!$C14,'511'!$A:$A,'4.DOANH THU'!U$6)/1000 -> 0 | V14: =SUMIFS('511'!$Q:$Q,'511'!$R:$R,'4.DOANH THU'!$C14,'511'!$A:$A,'4.DOANH THU'!V$6)/1000 -> 222 | W14: =SUMIFS('511'!$Q:$Q,'511'!$R:$R,'4.DOANH THU'!$C14,'511'!$A:$A,'4.DOANH THU'!W$6)/1000 -> 511.26 | X14: =SUMIFS('511'!$Q:$Q,'511'!$R:$R,'4.DOANH THU'!$C14,'511'!$A:$A,'4.DOANH THU'!X$6)/1000 -> 180 | Y14: =SUMIFS('511'!$Q:$Q,'511'!$R:$R,'4.DOANH THU'!$C14,'511'!$A:$A,'4.DOANH THU'!Y$6)/1000 -> 380 | ... AA14: =SUMIFS('511'!$Q:$Q,'511'!$R:$R,'4.DOANH THU'!$C14,'511'!$A:$A,'4.DOANH THU'!AA$6)/1000 -> 264.74 | AD14: =SUM(R14:AC14) -> 1781 | AF14: =#REF! -> #REF! | AG14: =#REF! -> #REF! | AH14: =#REF! -> #REF! | AI14: =#REF! -> #REF! | AJ14: =#REF! -> #REF! | AK14: =#REF! -> #REF! | AL14: =#REF! -> #REF! | AM14: =#REF! -> #REF! | ... AQ14: =#REF! -> #REF! | AR14: =SUM(AF14:AQ14) -> #REF! | AT14: =P14 -> 0 | AU14: =AD14 -> 1781 | AV14: =AR14 -> #REF! | AX14: =AU14-AT14 -> 1781 | AY14: =IFERROR(AX14/AT14,"") | AZ14: =AV14-AU14 -> #REF! | BA14: =IFERROR(AZ14/AU14,"")
B15: 1.8 | C15: Chi phí xuất khẩu | P15: =SUM(D15:O15) -> 0 | AR15: =SUM(AF15:AQ15) -> 0 | AT15: =P15 -> 0 | AU15: =AD15 -> 0 | AV15: =AR15 -> 0 | AX15: =AU15-AT15 -> 0 | AY15: =IFERROR(AX15/AT15,"") | AZ15: =AV15-AU15 -> 0 | BA15: =IFERROR(AZ15/AV15,"")
B16: 1.9 | C16: XX | AT16: =P16 -> 0 | AU16: =AD16 -> 0 | AV16: =AR16 -> 0 | AX16: =AU16-AT16 -> 0 | AY16: =IFERROR(AX16/AT16,"") | AZ16: =AV16-AU16 -> 0 | BA16: =IFERROR(AZ16/AV16,"")
B17: 1.10 | C17: XX | AT17: =P17 -> 0 | AU17: =AD17 -> 0 | AV17: =AR17 -> 0 | AX17: =AU17-AT17 -> 0 | AY17: =IFERROR(AX17/AT17,"") | AZ17: =AV17-AU17 -> 0 | BA17: =IFERROR(AZ17/AV17,"")
B18: 2 | C18: DOANH THU (Trđ) | D18: =SUM(D19:D28) -> #REF! | E18: =SUM(E19:E28) -> #REF! | F18: =SUM(F19:F28) -> #REF! | G18: =SUM(G19:G28) -> #REF! | H18: =SUM(H19:H28) -> #REF! | I18: =SUM(I19:I28) -> #REF! | J18: =SUM(J19:J28) -> #REF! | K18: =SUM(K19:K28) -> #REF! | ... AR18: =SUM(AR19:AR28) -> #REF! | AT18: =P18 -> #REF! | AU18: =AD18 -> 1359355.2 | AV18: =AR18 -> #REF! | AX18: =AU18-AT18 -> #REF! | AY18: =IFERROR(AX18/AT18,"") | AZ18: =AV18-AU18 -> #REF! | BA18: =IFERROR(AZ18/AU18,"") | BC18: =IFERROR(AT18/AT$18,"") | BD18: =IFERROR(AU18/AU$18,"") -> 1 | BE18: =IFERROR(AV18/AV$18,"")
B19: 2.1 | C19: =C30 -> rPET | D19: =19396.48348-D26 -> #REF! | E19: =18963.976457-E26 -> #REF! | F19: =53172.37105-F26 -> #REF! | G19: =51252.84836-G26 -> #REF! | H19: =45718.90666-H26 -> #REF! | I19: =44053.037287-I26 -> #REF! | J19: =46420.304964-J26 -> #REF! | K19: =71532.069455-K26 -> #REF! | L19: =50880.777704-L26 -> #REF! | M19: =72547.856348-M26 -> #REF! | N19: =55659.174905-N26 -> #REF! | O19: =91608.39445-O26 -> #REF! | P19: =SUM(D19:O19) -> #REF! | R19: 56566.322 | S19: 59696.552 | T19: 80807.5 | U19: 82629.115 | V19: 88373.996 | W19: 49159.51 | X19: 45482.549 | Y19: 134002.49 | Z19: 129683.46 | AA19: 94810.295 | AB19: 114153.01 | AC19: 215813.18 | AD19: =SUM(R19:AC19) -> 1151178 | AF19: =SUMIFS('KH 2026'!AU:AU,'KH 2026'!$K:$K,'4.DOANH THU'!$C19)/10^6 -> 112067.22 | AG19: =SUMIFS('KH 2026'!AV:AV,'KH 2026'!$K:$K,'4.DOANH THU'!$C19)/10^6 -> 109088.86 | AH19: =SUMIFS('KH 2026'!AW:AW,'KH 2026'!$K:$K,'4.DOANH THU'!$C19)/10^6 -> 115750.31 | AI19: =SUMIFS('KH 2026'!AX:AX,'KH 2026'!$K:$K,'4.DOANH THU'!$C19)/10^6 -> 112741.82 | AJ19: =SUMIFS('KH 2026'!AY:AY,'KH 2026'!$K:$K,'4.DOANH THU'!$C19)/10^6 -> 120771.28 | AK19: =SUMIFS('KH 2026'!AZ:AZ,'KH 2026'!$K:$K,'4.DOANH THU'!$C19)/10^6 -> 115158.11 | AL19: =SUMIFS('KH 2026'!BA:BA,'KH 2026'!$K:$K,'4.DOANH THU'!$C19)/10^6 -> 120001.74 | AM19: =SUMIFS('KH 2026'!BB:BB,'KH 2026'!$K:$K,'4.DOANH THU'!$C19)/10^6 -> 115666.61 | AN19: =SUMIFS('KH 2026'!BC:BC,'KH 2026'!$K:$K,'4.DOANH THU'!$C19)/10^6 -> 115941.48 | AO19: =SUMIFS('KH 2026'!BD:BD,'KH 2026'!$K:$K,'4.DOANH THU'!$C19)/10^6 -> 112161.28 | AP19: =SUMIFS('KH 2026'!BE:BE,'KH 2026'!$K:$K,'4.DOANH THU'!$C19)/10^6 -> 120283.49 | AQ19: =SUMIFS('KH 2026'!BF:BF,'KH 2026'!$K:$K,'4.DOANH THU'!$C19)/10^6 -> 116438.31 | AR19: =SUM(AF19:AQ19) -> 1386070.5 | AT19: =P19 -> #REF! | AU19: =AD19 -> 1151178 | AV19: =AR19 -> 1386070.5 | AX19: =AU19-AT19 -> #REF! | AY19: =IFERROR(AX19/AT19,"") | AZ19: =AV19-AU19 -> 234892.53 | BA19: =IFERROR(AZ19/AU19,"") -> 0.20404537 | BC19: =IFERROR(AT19/AT$18,"") | BD19: =IFERROR(AU19/AU$18,"") -> 0.84685591 | BE19: =IFERROR(AV19/AV$18,"")
B20: 2.2 | C20: =C31 -> rHDPE | D20: 2257.566 | E20: 4028.86 | F20: 4803.979 | G20: 2931.0628 | H20: 5846.4744 | I20: 5804.2415 | J20: 4174.3171 | K20: 4419.8895 | L20: 3133.9969 | M20: 5728.2765 | N20: 6625.3224 | O20: 3773.6758 | P20: =SUM(D20:O20) -> 53527.662 | R20: 7433.9118 | S20: 4453.7879 | T20: 6059.9371 | U20: 7065.9947 | V20: 6289.2351 | W20: 4270.794 | X20: 3836.6409 | Y20: 4644.4584 | Z20: 4834.7957 | AA20: 7221.6201 | AB20: 4673.9388 | AC20: 10248.05 | AD20: =SUM(R20:AC20) -> 71033.165 | AF20: =SUMIFS('KH 2026'!AU:AU,'KH 2026'!$K:$K,'4.DOANH THU'!$C20)/10^6 -> 0 | AG20: =SUMIFS('KH 2026'!AV:AV,'KH 2026'!$K:$K,'4.DOANH THU'!$C20)/10^6 -> 0 | AH20: =SUMIFS('KH 2026'!AW:AW,'KH 2026'!$K:$K,'4.DOANH THU'!$C20)/10^6 -> 0 | AI20: =SUMIFS('KH 2026'!AX:AX,'KH 2026'!$K:$K,'4.DOANH THU'!$C20)/10^6 -> 0 | AJ20: =SUMIFS('KH 2026'!AY:AY,'KH 2026'!$K:$K,'4.DOANH THU'!$C20)/10^6 -> 0 | AK20: =SUMIFS('KH 2026'!AZ:AZ,'KH 2026'!$K:$K,'4.DOANH THU'!$C20)/10^6 -> 0 | AL20: =SUMIFS('KH 2026'!BA:BA,'KH 2026'!$K:$K,'4.DOANH THU'!$C20)/10^6 -> 0 | AM20: =SUMIFS('KH 2026'!BB:BB,'KH 2026'!$K:$K,'4.DOANH THU'!$C20)/10^6 -> 0 | AN20: =SUMIFS('KH 2026'!BC:BC,'KH 2026'!$K:$K,'4.DOANH THU'!$C20)/10^6 -> 0 | AO20: =SUMIFS('KH 2026'!BD:BD,'KH 2026'!$K:$K,'4.DOANH THU'!$C20)/10^6 -> 0 | AP20: =SUMIFS('KH 2026'!BE:BE,'KH 2026'!$K:$K,'4.DOANH THU'!$C20)/10^6 -> 0 | AQ20: =SUMIFS('KH 2026'!BF:BF,'KH 2026'!$K:$K,'4.DOANH THU'!$C20)/10^6 -> 0 | AR20: =SUM(AF20:AQ20) -> 0 | AT20: =P20 -> 53527.662 | AU20: =AD20 -> 71033.165 | AV20: =AR20 -> 0 | AX20: =AU20-AT20 -> 17505.503 | AY20: =IFERROR(AX20/AT20,"") -> 0.32703657 | AZ20: =AV20-AU20 -> -71033.165 | BA20: =IFERROR(AZ20/AU20,"") -> -1 | BC20: =IFERROR(AT20/AT$18,"") | BD20: =IFERROR(AU20/AU$18,"") -> 0.052255044 | BE20: =IFERROR(AV20/AV$18,"")
B21: 2.3 | C21: =C32 -> rPP | H21: 3.7808 | K21: 1.900845 | P21: =SUM(D21:O21) -> 5.681645 | R21: =-SUMIFS('511'!$J:$J,'511'!$R:$R,'4.DOANH THU'!$C21,'511'!$A:$A,'4.DOANH THU'!R$6)/10^6 -> 298.605 | S21: =-SUMIFS('511'!$J:$J,'511'!$R:$R,'4.DOANH THU'!$C21,'511'!$A:$A,'4.DOANH THU'!S$6)/10^6 -> 298.605 | T21: =-SUMIFS('511'!$J:$J,'511'!$R:$R,'4.DOANH THU'!$C21,'511'!$A:$A,'4.DOANH THU'!T$6)/10^6 -> 1256.87 | U21: =-SUMIFS('511'!$J:$J,'511'!$R:$R,'4.DOANH THU'!$C21,'511'!$A:$A,'4.DOANH THU'!U$6)/10^6 -> 674.3855 | V21: =-SUMIFS('511'!$J:$J,'511'!$R:$R,'4.DOANH THU'!$C21,'511'!$A:$A,'4.DOANH THU'!V$6)/10^6 -> 779.41275 | W21: =-SUMIFS('511'!$J:$J,'511'!$R:$R,'4.DOANH THU'!$C21,'511'!$A:$A,'4.DOANH THU'!W$6)/10^6 -> 116.08275 | X21: =-SUMIFS('511'!$J:$J,'511'!$R:$R,'4.DOANH THU'!$C21,'511'!$A:$A,'4.DOANH THU'!X$6)/10^6 -> 7.31759 | Y21: =-SUMIFS('511'!$J:$J,'511'!$R:$R,'4.DOANH THU'!$C21,'511'!$A:$A,'4.DOANH THU'!Y$6)/10^6 -> 1081.5932 | ... AA21: =-SUMIFS('511'!$J:$J,'511'!$R:$R,'4.DOANH THU'!$C21,'511'!$A:$A,'4.DOANH THU'!AA$6)/10^6 -> 402.43134 | AB21: 446.93568 | AC21: 500 | AD21: =SUM(R21:AC21) -> 5862.8571 | AF21: =SUMIFS('KH 2026'!AU:AU,'KH 2026'!$K:$K,'4.DOANH THU'!$C21)/10^6 -> 1319.7 | AG21: =SUMIFS('KH 2026'!AV:AV,'KH 2026'!$K:$K,'4.DOANH THU'!$C21)/10^6 -> 1168.65 | AH21: =SUMIFS('KH 2026'!AW:AW,'KH 2026'!$K:$K,'4.DOANH THU'!$C21)/10^6 -> 1319.7 | AI21: =SUMIFS('KH 2026'!AX:AX,'KH 2026'!$K:$K,'4.DOANH THU'!$C21)/10^6 -> 1168.65 | AJ21: =SUMIFS('KH 2026'!AY:AY,'KH 2026'!$K:$K,'4.DOANH THU'!$C21)/10^6 -> 1319.7 | AK21: =SUMIFS('KH 2026'!AZ:AZ,'KH 2026'!$K:$K,'4.DOANH THU'!$C21)/10^6 -> 1613.85 | AL21: =SUMIFS('KH 2026'!BA:BA,'KH 2026'!$K:$K,'4.DOANH THU'!$C21)/10^6 -> 1319.7 | AM21: =SUMIFS('KH 2026'!BB:BB,'KH 2026'!$K:$K,'4.DOANH THU'!$C21)/10^6 -> 1168.65 | AN21: =SUMIFS('KH 2026'!BC:BC,'KH 2026'!$K:$K,'4.DOANH THU'!$C21)/10^6 -> 1319.7 | AO21: =SUMIFS('KH 2026'!BD:BD,'KH 2026'!$K:$K,'4.DOANH THU'!$C21)/10^6 -> 1613.85 | AP21: =SUMIFS('KH 2026'!BE:BE,'KH 2026'!$K:$K,'4.DOANH THU'!$C21)/10^6 -> 1319.7 | AQ21: =SUMIFS('KH 2026'!BF:BF,'KH 2026'!$K:$K,'4.DOANH THU'!$C21)/10^6 -> 1168.65 | AR21: =SUM(AF21:AQ21) -> 15820.5 | AT21: =P21 -> 5.681645 | AU21: =AD21 -> 5862.8571 | AV21: =AR21 -> 15820.5 | AX21: =AU21-AT21 -> 5857.1755 | AY21: =IFERROR(AX21/AT21,"") -> 1030.8943 | AZ21: =AV21-AU21 -> 9957.6429 | BA21: =IFERROR(AZ21/AU21,"") -> 1.6984284 | BC21: =IFERROR(AT21/AT$18,"") | BD21: =IFERROR(AU21/AU$18,"") -> 0.0043129692 | BE21: =IFERROR(AV21/AV$18,"")
B22: 2.4 | C22: =C33 -> Xơ sợi | P22: =SUM(D22:O22) -> 0 | R22: 503.20754 | S22: -1165.4441 | T22: 2.18207 | U22: 3832.5869 | V22: 1635.1653 | W22: 3122.5766 | X22: 2722.5 | Y22: 0 | Z22: 3892.252 | AA22: 4251.2669 | AB22: 660 | AC22: 3861 | AD22: =SUM(R22:AC22) -> 23317.293 | AF22: =SUMIFS('KH 2026'!AU:AU,'KH 2026'!$K:$K,'4.DOANH THU'!$C22)/10^6 -> 1468.5152 | AG22: =SUMIFS('KH 2026'!AV:AV,'KH 2026'!$K:$K,'4.DOANH THU'!$C22)/10^6 -> 1450.1588 | AH22: =SUMIFS('KH 2026'!AW:AW,'KH 2026'!$K:$K,'4.DOANH THU'!$C22)/10^6 -> 1431.8024 | AI22: =SUMIFS('KH 2026'!AX:AX,'KH 2026'!$K:$K,'4.DOANH THU'!$C22)/10^6 -> 1413.4459 | AJ22: =SUMIFS('KH 2026'!AY:AY,'KH 2026'!$K:$K,'4.DOANH THU'!$C22)/10^6 -> 1395.0895 | AK22: =SUMIFS('KH 2026'!AZ:AZ,'KH 2026'!$K:$K,'4.DOANH THU'!$C22)/10^6 -> 1376.733 | AL22: =SUMIFS('KH 2026'!BA:BA,'KH 2026'!$K:$K,'4.DOANH THU'!$C22)/10^6 -> 1358.3766 | AM22: =SUMIFS('KH 2026'!BB:BB,'KH 2026'!$K:$K,'4.DOANH THU'!$C22)/10^6 -> 1340.0202 | AN22: =SUMIFS('KH 2026'!BC:BC,'KH 2026'!$K:$K,'4.DOANH THU'!$C22)/10^6 -> 1321.6637 | AO22: =SUMIFS('KH 2026'!BD:BD,'KH 2026'!$K:$K,'4.DOANH THU'!$C22)/10^6 -> 1303.3073 | AP22: =SUMIFS('KH 2026'!BE:BE,'KH 2026'!$K:$K,'4.DOANH THU'!$C22)/10^6 -> 1284.9508 | AQ22: =SUMIFS('KH 2026'!BF:BF,'KH 2026'!$K:$K,'4.DOANH THU'!$C22)/10^6 -> 1266.5944 | AR22: =SUM(AF22:AQ22) -> 16410.658 | AT22: =P22 -> 0 | AU22: =AD22 -> 23317.293 | AV22: =AR22 -> 16410.658 | AX22: =AU22-AT22 -> 23317.293 | AY22: =IFERROR(AX22/AT22,"") | AZ22: =AV22-AU22 -> -6906.6355 | BA22: =IFERROR(AZ22/AU22,"") -> -0.29620228 | BC22: =IFERROR(AT22/AT$18,"") | BD22: =IFERROR(AU22/AU$18,"") -> 0.017153201 | BE22: =IFERROR(AV22/AV$18,"")
B23: 2.5 | C23: =C34 -> Khác (phó sản, phế liệu) | D23: 87.445683 | E23: 49.482552 | F23: 1236.1834 | G23: 103.13109 | H23: 1680.7844 | I23: 1046.4194 | J23: 2931.7051 | K23: 2328.6038 | L23: 9390.6439 | M23: 5347.8269 | N23: 618.54416 | O23: 898.54197 | P23: =SUM(D23:O23) -> 25719.312 | R23: =-SUMIFS('511'!$J:$J,'511'!$R:$R,'4.DOANH THU'!$C23,'511'!$A:$A,'4.DOANH THU'!R$6)/10^6 -> 1757.8884 | S23: =-SUMIFS('511'!$J:$J,'511'!$R:$R,'4.DOANH THU'!$C23,'511'!$A:$A,'4.DOANH THU'!S$6)/10^6 -> 1219.8437 | T23: =-SUMIFS('511'!$J:$J,'511'!$R:$R,'4.DOANH THU'!$C23,'511'!$A:$A,'4.DOANH THU'!T$6)/10^6 -> 195.53848 | U23: =-SUMIFS('511'!$J:$J,'511'!$R:$R,'4.DOANH THU'!$C23,'511'!$A:$A,'4.DOANH THU'!U$6)/10^6 -> 140.73871 | V23: =-SUMIFS('511'!$J:$J,'511'!$R:$R,'4.DOANH THU'!$C23,'511'!$A:$A,'4.DOANH THU'!V$6)/10^6 -> 928.72836 | W23: =-SUMIFS('511'!$J:$J,'511'!$R:$R,'4.DOANH THU'!$C23,'511'!$A:$A,'4.DOANH THU'!W$6)/10^6 -> 867.30228 | X23: =-SUMIFS('511'!$J:$J,'511'!$R:$R,'4.DOANH THU'!$C23,'511'!$A:$A,'4.DOANH THU'!X$6)/10^6 -> 473.44707 | Y23: =-SUMIFS('511'!$J:$J,'511'!$R:$R,'4.DOANH THU'!$C23,'511'!$A:$A,'4.DOANH THU'!Y$6)/10^6 -> 1235.337 | ... AA23: =-SUMIFS('511'!$J:$J,'511'!$R:$R,'4.DOANH THU'!$C23,'511'!$A:$A,'4.DOANH THU'!AA$6)/10^6 -> 1886.9294 | AB23: 1000 | AC23: 1000 | AD23: =SUM(R23:AC23) -> 12163.244 | AR23: =SUM(AF23:AQ23) -> 0 | AT23: =P23 -> 25719.312 | AU23: =AD23 -> 12163.244 | AV23: =AR23 -> 0 | AX23: =AU23-AT23 -> -13556.068 | AY23: =IFERROR(AX23/AT23,"") -> -0.5270774 | AZ23: =AV23-AU23 -> -12163.244 | BA23: =IFERROR(AZ23/AV23,"") | BC23: =IFERROR(AT23/AT$18,"") | BD23: =IFERROR(AU23/AU$18,"") -> 0.0089478043 | BE23: =IFERROR(AV23/AV$18,"")
B24: 2.6 | C24: Khác (tài trợ) | D24: 3243.9601 | H24: 4382.0385 | L24: 1510.7581 | M24: 1047.5693 | O24: 3275.3815 | P24: =SUM(D24:O24) -> 13459.708 | R24: =-SUMIFS('511'!$J:$J,'511'!$R:$R,'4.DOANH THU'!$C24,'511'!$A:$A,'4.DOANH THU'!R$6)/10^6 -> 0 | S24: =-SUMIFS('511'!$J:$J,'511'!$R:$R,'4.DOANH THU'!$C24,'511'!$A:$A,'4.DOANH THU'!S$6)/10^6 -> 1016.6853 | T24: =-SUMIFS('511'!$J:$J,'511'!$R:$R,'4.DOANH THU'!$C24,'511'!$A:$A,'4.DOANH THU'!T$6)/10^6 -> 0 | U24: =-SUMIFS('511'!$J:$J,'511'!$R:$R,'4.DOANH THU'!$C24,'511'!$A:$A,'4.DOANH THU'!U$6)/10^6 -> 0 | V24: =-SUMIFS('511'!$J:$J,'511'!$R:$R,'4.DOANH THU'!$C24,'511'!$A:$A,'4.DOANH THU'!V$6)/10^6 -> 0 | W24: =-SUMIFS('511'!$J:$J,'511'!$R:$R,'4.DOANH THU'!$C24,'511'!$A:$A,'4.DOANH THU'!W$6)/10^6 -> 586 | X24: =-SUMIFS('511'!$J:$J,'511'!$R:$R,'4.DOANH THU'!$C24,'511'!$A:$A,'4.DOANH THU'!X$6)/10^6 -> 0 | Y24: =-SUMIFS('511'!$J:$J,'511'!$R:$R,'4.DOANH THU'!$C24,'511'!$A:$A,'4.DOANH THU'!Y$6)/10^6 -> 0 | ... AA24: =-SUMIFS('511'!$J:$J,'511'!$R:$R,'4.DOANH THU'!$C24,'511'!$A:$A,'4.DOANH THU'!AA$6)/10^6 -> 0 | AB24: 5722.2246 | AC24: 12261.9 | AD24: =SUM(R24:AC24) -> 31048.921 | AF24: 0 | AG24: 0 | AH24: 0 | AI24: 4832.301 | AJ24: 2876.02 | AK24: 3228.282 | AL24: 3459.806 | AM24: 3254.188 | AN24: 3254.188 | AO24: 3487.71 | AP24: 3408.55 | AQ24: 3271.999 | AR24: =SUM(AF24:AQ24) -> 31073.044 | AT24: =P24 -> 13459.708 | AU24: =AD24 -> 31048.921 | AV24: =AR24 -> 31073.044 | AX24: =AU24-AT24 -> 17589.213 | AY24: =IFERROR(AX24/AT24,"") -> 1.306805 | AZ24: =AV24-AU24 -> 24.123415 | BA24: =IFERROR(AZ24/AU24,"") -> 0.00077694859 | BC24: =IFERROR(AT24/AT$18,"") | BD24: =IFERROR(AU24/AU$18,"") -> 0.022840918 | BE24: =IFERROR(AV24/AV$18,"") | BG24: Quý 1 MKT tập trung đi kiếm hợp đồng tài trợ, dự kiến bắt đầu quý 2 mới bắt đầu phát sinh tài trợ
B25: 2.7 | C25: =C36 -> Dây đai | P25: =SUM(D25:O25) -> 0 | R25: =-SUMIFS('511'!$J:$J,'511'!$R:$R,'4.DOANH THU'!$C25,'511'!$A:$A,'4.DOANH THU'!R$6)/10^6 -> 0 | S25: =-SUMIFS('511'!$J:$J,'511'!$R:$R,'4.DOANH THU'!$C25,'511'!$A:$A,'4.DOANH THU'!S$6)/10^6 -> 2881.5 | T25: =-SUMIFS('511'!$J:$J,'511'!$R:$R,'4.DOANH THU'!$C25,'511'!$A:$A,'4.DOANH THU'!T$6)/10^6 -> 1017.5 | U25: =-SUMIFS('511'!$J:$J,'511'!$R:$R,'4.DOANH THU'!$C25,'511'!$A:$A,'4.DOANH THU'!U$6)/10^6 -> 0 | V25: =-SUMIFS('511'!$J:$J,'511'!$R:$R,'4.DOANH THU'!$C25,'511'!$A:$A,'4.DOANH THU'!V$6)/10^6 -> 4012.5 | W25: =-SUMIFS('511'!$J:$J,'511'!$R:$R,'4.DOANH THU'!$C25,'511'!$A:$A,'4.DOANH THU'!W$6)/10^6 -> 9377.9199 | X25: =-SUMIFS('511'!$J:$J,'511'!$R:$R,'4.DOANH THU'!$C25,'511'!$A:$A,'4.DOANH THU'!X$6)/10^6 -> 3288 | Y25: =-SUMIFS('511'!$J:$J,'511'!$R:$R,'4.DOANH THU'!$C25,'511'!$A:$A,'4.DOANH THU'!Y$6)/10^6 -> 7215 | ... AA25: =-SUMIFS('511'!$J:$J,'511'!$R:$R,'4.DOANH THU'!$C25,'511'!$A:$A,'4.DOANH THU'!AA$6)/10^6 -> 5119.58 | AB25: 0 | AC25: 0 | AD25: =SUM(R25:AC25) -> 32912 | AF25: =#REF! -> #REF! | AG25: =#REF! -> #REF! | AH25: =#REF! -> #REF! | AI25: =#REF! -> #REF! | AJ25: =#REF! -> #REF! | AK25: =#REF! -> #REF! | AL25: =#REF! -> #REF! | AM25: =#REF! -> #REF! | ... AQ25: =#REF! -> #REF! | AR25: =SUM(AF25:AQ25) -> #REF! | AT25: =P25 -> 0 | AU25: =AD25 -> 32912 | AV25: =AR25 -> #REF! | AX25: =AU25-AT25 -> 32912 | AY25: =IFERROR(AX25/AT25,"") | AZ25: =AV25-AU25 -> #REF! | BA25: =IFERROR(AZ25/AU25,"") | BC25: =IFERROR(AT25/AT$18,"") | BD25: =IFERROR(AU25/AU$18,"") -> 0.024211479 | BE25: =IFERROR(AV25/AV$18,"")
B26: 2.8 | C26: =C37 -> Chi phí xuất khẩu | D26: =#REF! -> #REF! | E26: =#REF! -> #REF! | F26: =#REF! -> #REF! | G26: =#REF! -> #REF! | H26: =#REF! -> #REF! | I26: =#REF! -> #REF! | J26: =#REF! -> #REF! | K26: =#REF! -> #REF! | ... O26: =#REF! -> #REF! | P26: =SUM(D26:O26) -> #REF! | R26: 1002.3327 | S26: 538.21769 | T26: 2778.0748 | U26: 3138.1782 | V26: 345.96043 | W26: 514.65757 | X26: 719.07051 | Y26: 5848.9901 | Z26: 5499.1743 | AA26: 2715.4764 | AB26: 3002.8883 | AC26: 5736.708 | AD26: =SUM(R26:AC26) -> 31839.729 | AF26: =#REF!/10^6 -> #REF! | AG26: =#REF!/10^6 -> #REF! | AH26: =#REF!/10^6 -> #REF! | AI26: =#REF!/10^6 -> #REF! | AJ26: =#REF!/10^6 -> #REF! | AK26: =#REF!/10^6 -> #REF! | AL26: =#REF!/10^6 -> #REF! | AM26: =#REF!/10^6 -> #REF! | ... AQ26: =#REF!/10^6 -> #REF! | AR26: =SUM(AF26:AQ26) -> #REF! | AT26: =P26 -> #REF! | AU26: =AD26 -> 31839.729 | AV26: =AR26 -> #REF! | AX26: =AU26-AT26 -> #REF! | AY26: =IFERROR(AX26/AT26,"") | AZ26: =AV26-AU26 -> #REF! | BA26: =IFERROR(AZ26/AU26,"") | BC26: =IFERROR(AT26/AT$18,"") | BD26: =IFERROR(AU26/AU$18,"") -> 0.023422671 | BE26: =IFERROR(AV26/AV$18,"") | BG26: - 2024 không bán giá DDP, năm 2025 bán 3.569 tấn * 524 usd/ tấn => tăng ~ 46,7 tỷ - 2025 bán giá CIF: 8.112 tấn , 2024 bán giá CIF: 4.180 tấn => tăng 3.932 tấn ~ 25 tỷ
B27: 2.9 | C27: =C38 -> XX | AD27: =SUM(R27:AC27) -> 0 | AT27: =P27 -> 0 | AU27: =AD27 -> 0 | AV27: =AR27 -> 0 | AX27: =AU27-AT27 -> 0 | AY27: =IFERROR(AX27/AT27,"") | AZ27: =AV27-AU27 -> 0 | BA27: =IFERROR(AZ27/AV27,"") | BC27: =IFERROR(AT27/AT$18,"") | BD27: =IFERROR(AU27/AU$18,"") -> 0 | BE27: =IFERROR(AV27/AV$18,"")
B28: 2.10 | C28: =C39 -> XX | AT28: =P28 -> 0 | AU28: =AD28 -> 0 | AV28: =AR28 -> 0 | AX28: =AU28-AT28 -> 0 | AY28: =IFERROR(AX28/AT28,"") | AZ28: =AV28-AU28 -> 0 | BA28: =IFERROR(AZ28/AV28,"") | BC28: =IFERROR(AT28/AT$18,"") | BD28: =IFERROR(AU28/AU$18,"") -> 0 | BE28: =IFERROR(AV28/AV$18,"")
B29: 3 | C29: ĐƠN GIÁ BÁN (VNĐ) | Q29: =SUM(Q30:Q39) -> 0 | AE29: =SUM(AE30:AE39) -> 0 | AY29: =IFERROR(AX29/AT29,"") | BA29: =IFERROR(AZ29/AV29,"")
B30: 3.1 | C30: =C8 -> rPET | D30: =IFERROR(D19/D8*1000,0) -> 0 | E30: =IFERROR(E19/E8*1000,0) -> 0 | F30: =IFERROR(F19/F8*1000,0) -> 0 | G30: =IFERROR(G19/G8*1000,0) -> 0 | H30: =IFERROR(H19/H8*1000,0) -> 0 | I30: =IFERROR(I19/I8*1000,0) -> 0 | J30: =IFERROR(J19/J8*1000,0) -> 0 | K30: =IFERROR(K19/K8*1000,0) -> 0 | ... P30: =IFERROR(P19/P8*1000,0) -> 0 | R30: =IFERROR(R19/R8*1000,0) -> 29741.225 | S30: =IFERROR(S19/S8*1000,0) -> 30420.175 | T30: =IFERROR(T19/T8*1000,0) -> 30147.271 | U30: =IFERROR(U19/U8*1000,0) -> 30225.833 | V30: =IFERROR(V19/V8*1000,0) -> 30560.996 | W30: =IFERROR(W19/W8*1000,0) -> 31429.902 | X30: =IFERROR(X19/X8*1000,0) -> 30160.841 | Y30: =IFERROR(Y19/Y8*1000,0) -> 28195.718 | ... AD30: =IFERROR(AD19/AD8*1000,0) -> 30256.967 | AF30: =IFERROR(AF19/AF8*1000,0) -> 29847.694 | AG30: =IFERROR(AG19/AG8*1000,0) -> 29848.698 | AH30: =IFERROR(AH19/AH8*1000,0) -> 29886.702 | AI30: =IFERROR(AI19/AI8*1000,0) -> 29876.109 | AJ30: =IFERROR(AJ19/AJ8*1000,0) -> 29939.463 | AK30: =IFERROR(AK19/AK8*1000,0) -> 29916.131 | AL30: =IFERROR(AL19/AL8*1000,0) -> 29941.782 | AM30: =IFERROR(AM19/AM8*1000,0) -> 29901.437 | ... AR30: =IFERROR(AR19/AR8*1000,0) -> 29906.398 | AT30: =P30 -> 0 | AU30: =AD30 -> 30256.967 | AV30: =AR30 -> 29906.398 | AX30: =AU30-AT30 -> 30256.967 | AY30: =IFERROR(AX30/AT30,"") | AZ30: =AV30-AU30 -> -350.56896 | BA30: =IFERROR(AZ30/AU30,"") -> -0.011586388
B31: 3.2 | C31: =C9 -> rHDPE | D31: =IFERROR(D20/D9*1000,0) -> 37626.1 | E31: =IFERROR(E20/E9*1000,0) -> 37900.847 | F31: =IFERROR(F20/F9*1000,0) -> 37976.119 | G31: =IFERROR(G20/G9*1000,0) -> 36764.663 | H31: =IFERROR(H20/H9*1000,0) -> 35145.623 | I31: =IFERROR(I20/I9*1000,0) -> 35967.415 | J31: =IFERROR(J20/J9*1000,0) -> 36576.711 | K31: =IFERROR(K20/K9*1000,0) -> 34939.838 | ... P31: =IFERROR(P20/P9*1000,0) -> 35705.341 | R31: =IFERROR(R20/R9*1000,0) -> 34677.14 | S31: =IFERROR(S20/S9*1000,0) -> 32521.27 | T31: =IFERROR(T20/T9*1000,0) -> 35252.688 | U31: =IFERROR(U20/U9*1000,0) -> 33484.159 | V31: =IFERROR(V20/V9*1000,0) -> 32104.314 | W31: =IFERROR(W20/W9*1000,0) -> 33761.217 | X31: =IFERROR(X20/X9*1000,0) -> 34587.703 | Y31: =IFERROR(Y20/Y9*1000,0) -> 32910.245 | ... AD31: =IFERROR(AD20/AD9*1000,0) -> 33384.561 | AF31: =IFERROR(AF20/AF9*1000,0) -> 0 | AG31: =IFERROR(AG20/AG9*1000,0) -> 0 | AH31: =IFERROR(AH20/AH9*1000,0) -> 0 | AI31: =IFERROR(AI20/AI9*1000,0) -> 0 | AJ31: =IFERROR(AJ20/AJ9*1000,0) -> 0 | AK31: =IFERROR(AK20/AK9*1000,0) -> 0 | AL31: =IFERROR(AL20/AL9*1000,0) -> 0 | AM31: =IFERROR(AM20/AM9*1000,0) -> 0 | ... AR31: =IFERROR(AR20/AR9*1000,0) -> 0 | AT31: =P31 -> 35705.341 | AU31: =AD31 -> 33384.561 | AV31: =AR31 -> 0 | AX31: =AU31-AT31 -> -2320.7802 | AY31: =IFERROR(AX31/AT31,"") -> -0.064998124 | AZ31: =AV31-AU31 -> -33384.561 | BA31: =IFERROR(AZ31/AU31,"") -> -1
B32: 3.3 | C32: =C10 -> rPP | D32: =IFERROR(D21/D10*1000," -") -> - | E32: =IFERROR(E21/E10*1000," -") -> - | F32: =IFERROR(F21/F10*1000," -") -> - | G32: =IFERROR(G21/G10*1000," -") -> - | H32: =IFERROR(H21/H10*1000," -") -> 30246.4 | I32: =IFERROR(I21/I10*1000," -") -> - | J32: =IFERROR(J21/J10*1000," -") -> - | K32: =IFERROR(K21/K10*1000," -") -> 25344.6 | ... P32: =IFERROR(P21/P10*1000," -") -> 28408.225 | R32: =IFERROR(R21/R10*1000,0) -> 19907 | S32: =IFERROR(S21/S10*1000,0) -> 19907 | T32: =IFERROR(T21/T10*1000,0) -> 22444.107 | U32: =IFERROR(U21/U10*1000,0) -> 22111 | V32: =IFERROR(V21/V10*1000,0) -> 22111 | W32: =IFERROR(W21/W10*1000,0) -> 22111 | X32: =IFERROR(X21/X10*1000,0) -> 24391.967 | Y32: =IFERROR(Y21/Y10*1000,0) -> 25953.047 | ... AD32: =IFERROR(AD21/AD10*1000,0) -> 22810.455 | AF32: =IFERROR(AF21/AF10*1000,0) -> 18329.167 | AG32: =IFERROR(AG21/AG10*1000,0) -> 18550 | AH32: =IFERROR(AH21/AH10*1000,0) -> 18329.167 | AI32: =IFERROR(AI21/AI10*1000,0) -> 18550 | AJ32: =IFERROR(AJ21/AJ10*1000,0) -> 18329.167 | AK32: =IFERROR(AK21/AK10*1000,0) -> 18550 | AL32: =IFERROR(AL21/AL10*1000,0) -> 18329.167 | AM32: =IFERROR(AM21/AM10*1000,0) -> 18550 | ... AR32: =IFERROR(AR21/AR10*1000,0) -> 18438.811 | AT32: =P32 -> 28408.225 | AU32: =AD32 -> 22810.455 | AV32: =AR32 -> 18438.811 | AX32: =AU32-AT32 -> -5597.7703 | AY32: =IFERROR(AX32/AT32,"") -> -0.19704752 | AZ32: =AV32-AU32 -> -4371.6435 | BA32: =IFERROR(AZ32/AU32,"") -> -0.19165087
B33: 3.4 | C33: =C11 -> Xơ sợi | R33: =IFERROR(R22/R11*1000,0) -> 22873.07 | S33: =IFERROR(S22/S11*1000,0) -> -23297.233 | T33: =IFERROR(T22/T11*1000,0) -> 29094.267 | U33: =IFERROR(U22/U11*1000,0) -> 16995.951 | V33: =IFERROR(V22/V11*1000,0) -> 19808.181 | W33: =IFERROR(W22/W11*1000,0) -> 16797.077 | X33: =IFERROR(X22/X11*1000,0) -> 16500 | Y33: =IFERROR(Y22/Y11*1000,0) -> 0 | ... AD33: =IFERROR(AD22/AD11*1000,0) -> 16248.419 | AF33: =IFERROR(AF22/AF11*1000,0) -> 16960 | AG33: =IFERROR(AG22/AG11*1000,0) -> 16748 | AH33: =IFERROR(AH22/AH11*1000,0) -> 16536 | AI33: =IFERROR(AI22/AI11*1000,0) -> 16324 | AJ33: =IFERROR(AJ22/AJ11*1000,0) -> 16112 | AK33: =IFERROR(AK22/AK11*1000,0) -> 15900 | AL33: =IFERROR(AL22/AL11*1000,0) -> 15688 | AM33: =IFERROR(AM22/AM11*1000,0) -> 15476 | ... AR33: =IFERROR(AR22/AR11*1000,0) -> 15794 | AT33: =P33 -> 0 | AU33: =AD33 -> 16248.419 | AV33: =AR33 -> 15794 | AY33: =IFERROR(AX33/AT33,"") | AZ33: =AV33-AU33 -> -454.41869 | BA33: =IFERROR(AZ33/AU33,"") -> -0.027966948 | BG33: Kinh doanh đề xuất tăng giá WSS05SB lên 800usd/ tấn cho năm 2025
B34: 3.5 | C34: =C12 -> Khác (phó sản, phế liệu) | R34: =IFERROR(R23/R12*1000,0) -> 7121.8589 | S34: =IFERROR(S23/S12*1000,0) -> 21909.686 | T34: =IFERROR(T23/T12*1000,0) -> 34498.674 | U34: =IFERROR(U23/U12*1000,0) -> 70299.057 | V34: =IFERROR(V23/V12*1000,0) -> 24919.594 | W34: =IFERROR(W23/W12*1000,0) -> 22060.34 | X34: =IFERROR(X23/X12*1000,0) -> 20923.063 | Y34: =IFERROR(Y23/Y12*1000,0) -> 6394.8783 | ... AD34: =IFERROR(AD23/AD12*1000,0) -> 8266.3924 | AT34: =P34 -> 0 | AU34: =AD34 -> 8266.3924 | AV34: =AR34 -> 0 | AY34: =IFERROR(AX34/AT34,"") | BA34: =IFERROR(AZ34/AV34,"")
B35: 3.6 | C35: =C13 -> Khác (tài trợ) | AD35: =SUM(R35:AC35) -> 0 | AT35: =P35 -> 0 | AU35: =AD35 -> 0 | AV35: =AR35 -> 0 | AX35: =AU35-AT35 -> 0 | AY35: =IFERROR(AX35/AT35,"") | AZ35: =AV35-AU35 -> 0 | BA35: =IFERROR(AZ35/AV35,"")
B36: 3.7 | C36: =C14 -> Dây đai | R36: =IFERROR(R25/R14*1000,0) -> 0 | S36: =IFERROR(S25/S14*1000,0) -> 17463.636 | T36: =IFERROR(T25/T14*1000,0) -> 17543.103 | U36: =IFERROR(U25/U14*1000,0) -> 0 | V36: =IFERROR(V25/V14*1000,0) -> 18074.324 | W36: =IFERROR(W25/W14*1000,0) -> 18342.761 | X36: =IFERROR(X25/X14*1000,0) -> 18266.667 | Y36: =IFERROR(Y25/Y14*1000,0) -> 18986.842 | ... AD36: =IFERROR(AD25/AD14*1000,0) -> 18479.506 | AF36: =IFERROR(AF25/AF14*1000,0) -> 0 | AG36: =IFERROR(AG25/AG14*1000,0) -> 0 | AH36: =IFERROR(AH25/AH14*1000,0) -> 0 | AI36: =IFERROR(AI25/AI14*1000,0) -> 0 | AJ36: =IFERROR(AJ25/AJ14*1000,0) -> 0 | AK36: =IFERROR(AK25/AK14*1000,0) -> 0 | AL36: =IFERROR(AL25/AL14*1000,0) -> 0 | AM36: =IFERROR(AM25/AM14*1000,0) -> 0 | ... AR36: =IFERROR(AR25/AR14*1000,0) -> 0 | AT36: =P36 -> 0 | AU36: =AD36 -> 18479.506 | AV36: =AR36 -> 0 | AX36: =AU36-AT36 -> 18479.506 | AY36: =IFERROR(AX36/AT36,"") | AZ36: =AV36-AU36 -> -18479.506 | BA36: =IFERROR(AZ36/AU36,"") -> -1 | BG36: Theo hợp đồng sắp ký
B37: 3.8 | C37: =C15 -> Chi phí xuất khẩu | AR37: =IFERROR(AR26/AR15*1000,0) -> 0 | AT37: =P37 -> 0 | AU37: =AD37 -> 0 | AV37: =AR37 -> 0 | AX37: =AU37-AT37 -> 0 | AY37: =IFERROR(AX37/AT37,"") | AZ37: =AV37-AU37 -> 0 | BA37: =IFERROR(AZ37/AV37,"")
B38: 3.9 | C38: =C16 -> XX | AT38: =P38 -> 0 | AU38: =AD38 -> 0 | AV38: =AR38 -> 0 | AX38: =AU38-AT38 -> 0 | AY38: =IFERROR(AX38/AT38,"") | AZ38: =AV38-AU38 -> 0 | BA38: =IFERROR(AZ38/AV38,"")
B39: 3.10 | C39: =C17 -> XX | AT39: =P39 -> 0 | AU39: =AD39 -> 0 | AV39: =AR39 -> 0 | AX39: =AU39-AT39 -> 0 | AY39: =IFERROR(AX39/AT39,"") | AZ39: =AV39-AU39 -> 0 | BA39: =IFERROR(AZ39/AV39,"")
B40: 4 | C40: NHÓM KHÁCH HÀNG (Trđ) | D40: =SUM(D41:D50) -> #REF! | E40: =SUM(E41:E50) -> #REF! | F40: =SUM(F41:F50) -> #REF! | G40: =SUM(G41:G50) -> #REF! | H40: =SUM(H41:H50) -> #REF! | I40: =SUM(I41:I50) -> #REF! | J40: =SUM(J41:J50) -> #REF! | K40: =SUM(K41:K50) -> #REF! | ... AR40: =SUM(AR41:AR50) -> #REF! | AT40: =P40 -> #REF! | AU40: =AD40 -> 1283231 | AV40: =AR40 -> #REF! | AX40: =AU40-AT40 -> #REF! | AY40: =IFERROR(AX40/AT40,"") | AZ40: =AV40-AU40 -> #REF! | BC40: =IFERROR(AT40/AT$18,"") | BD40: =IFERROR(AU40/AU$18,"") -> 0.9439998 | BE40: =IFERROR(AV40/AV$18,"")
...

Sheet 4.DOANH THU (USD)
BG1: Đơn vị tính: triệu đồng
B2: DUYTAN TÁI CHẾ
B3: KẾ HOẠCH KINH DOANH & NGÂN SÁCH NĂM 2025
B4: DOANH THU | AT4: tự động, không điền số | AX4: tự động, không điền số | BC4: tự động, không điền số
B5: STT | D5: 2023 | R5: 2024 | AF5: 2025 | AT5: Năm | AX5: Biến động | BC5: Tỉ lệ %/Doanh thu | BG5: Giải trình
C6: Nội dung | D6: 01 | E6: 02 | F6: 03 | G6: 04 | H6: 05 | I6: 06 | J6: 07 | K6: 08 | L6: 09 | M6: 10 | N6: 11 | O6: 12 | P6: 2023 | R6: 01 | S6: 02 | T6: 03 | U6: 04 | V6: 05 | W6: 06 | X6: 07 | Y6: 08 | Z6: 09 | AA6: 10 | AB6: 11 | AC6: 12 | AD6: 2024 | AF6: 01 | AG6: 02 | AH6: 03 | AI6: 04 | AJ6: 05 | AK6: 06 | AL6: 07 | AM6: 08 | AN6: 09 | AO6: 10 | AP6: 11 | AQ6: 12 | AR6: 2025 | AT6: =P6 -> 2023 | AU6: =AD6 -> 2024 | AV6: =AR6 -> 2025 | AX6: 24 sv 23 | AY6: % | AZ6: 25 sv 24 | BA6: % | BC6: =AT6 -> 2023 | BD6: =AU6 -> 2024 | BE6: =AV6 -> 2025
B7: 1 | C7: SẢN LƯỢNG (tấn) | D7: =SUM(D8:D17) -> 651.8 | E7: =SUM(E8:E17) -> 653.075 | F7: =SUM(F8:F17) -> 1860.64 | G7: =SUM(G8:G17) -> 1792.575 | H7: =SUM(H8:H17) -> 1632.875 | I7: =SUM(I8:I17) -> 1573.975 | J7: =SUM(J8:J17) -> 1591.575 | K7: =SUM(K8:K17) -> 2445.175 | ... AR7: =SUM(AR8:AR17) -> #REF! | AT7: =P7 -> 21482.69 | AU7: =AD7 -> 41154.767 | AV7: =AR7 -> #REF! | AX7: =AU7-AT7 -> 19672.077 | AY7: =IFERROR(AX7/AT7,"") -> 0.91571758 | AZ7: =AV7-AU7 -> #REF! | BA7: =IFERROR(AZ7/AV7,"")
B8: 1.1 | C8: rPET | D8: 591.8 | E8: 546.775 | F8: 1734.14 | G8: 1712.85 | H8: 1466.4 | I8: 1412.6 | J8: 1477.45 | K8: 2318.6 | L8: 1561 | M8: 2096.9 | N8: 1926.425 | O8: 3138.4 | P8: =SUM(D8:O8) -> 19983.34 | R8: =SUMIFS('511'!$Q:$Q,'511'!$R:$R,'4.DOANH THU (USD)'!$C8,'511'!$A:$A,'4.DOANH THU (USD)'!R$6)/1000 -> 1901.95 | S8: =SUMIFS('511'!$Q:$Q,'511'!$R:$R,'4.DOANH THU (USD)'!$C8,'511'!$A:$A,'4.DOANH THU (USD)'!S$6)/1000 -> 1962.4 | T8: =SUMIFS('511'!$Q:$Q,'511'!$R:$R,'4.DOANH THU (USD)'!$C8,'511'!$A:$A,'4.DOANH THU (USD)'!T$6)/1000 -> 2680.425 | U8: =SUMIFS('511'!$Q:$Q,'511'!$R:$R,'4.DOANH THU (USD)'!$C8,'511'!$A:$A,'4.DOANH THU (USD)'!U$6)/1000 -> 2733.725 | V8: =SUMIFS('511'!$Q:$Q,'511'!$R:$R,'4.DOANH THU (USD)'!$C8,'511'!$A:$A,'4.DOANH THU (USD)'!V$6)/1000 -> 2891.725 | W8: =SUMIFS('511'!$Q:$Q,'511'!$R:$R,'4.DOANH THU (USD)'!$C8,'511'!$A:$A,'4.DOANH THU (USD)'!W$6)/1000 -> 1564.1 | X8: =SUMIFS('511'!$Q:$Q,'511'!$R:$R,'4.DOANH THU (USD)'!$C8,'511'!$A:$A,'4.DOANH THU (USD)'!X$6)/1000 -> 1508 | Y8: =SUMIFS('511'!$Q:$Q,'511'!$R:$R,'4.DOANH THU (USD)'!$C8,'511'!$A:$A,'4.DOANH THU (USD)'!Y$6)/1000 -> 4752.5829 | ... AA8: =SUMIFS('511'!$Q:$Q,'511'!$R:$R,'4.DOANH THU (USD)'!$C8,'511'!$A:$A,'4.DOANH THU (USD)'!AA$6)/1000 -> 3247.4 | AB8: 2875.3 | AC8: 3444 | AD8: =SUM(R8:AC8) -> 34139.308 | AF8: =SUMIFS('KH 2026'!N:N,'KH 2026'!$K:$K,'4.DOANH THU (USD)'!$C8) -> 3754.6359 | AG8: =SUMIFS('KH 2026'!O:O,'KH 2026'!$K:$K,'4.DOANH THU (USD)'!$C8) -> 3654.7276 | AH8: =SUMIFS('KH 2026'!P:P,'KH 2026'!$K:$K,'4.DOANH THU (USD)'!$C8) -> 3872.9704 | AI8: =SUMIFS('KH 2026'!Q:Q,'KH 2026'!$K:$K,'4.DOANH THU (USD)'!$C8) -> 3773.6445 | AJ8: =SUMIFS('KH 2026'!R:R,'KH 2026'!$K:$K,'4.DOANH THU (USD)'!$C8) -> 4033.8495 | AK8: =SUMIFS('KH 2026'!S:S,'KH 2026'!$K:$K,'4.DOANH THU (USD)'!$C8) -> 3849.3652 | AL8: =SUMIFS('KH 2026'!T:T,'KH 2026'!$K:$K,'4.DOANH THU (USD)'!$C8) -> 4007.8355 | AM8: =SUMIFS('KH 2026'!U:U,'KH 2026'!$K:$K,'4.DOANH THU (USD)'!$C8) -> 3868.2625 | AN8: =SUMIFS('KH 2026'!V:V,'KH 2026'!$K:$K,'4.DOANH THU (USD)'!$C8) -> 3873.0361 | AO8: =SUMIFS('KH 2026'!W:W,'KH 2026'!$K:$K,'4.DOANH THU (USD)'!$C8) -> 3750.0393 | AP8: =SUMIFS('KH 2026'!X:X,'KH 2026'!$K:$K,'4.DOANH THU (USD)'!$C8) -> 4016.6561 | AQ8: =SUMIFS('KH 2026'!Y:Y,'KH 2026'!$K:$K,'4.DOANH THU (USD)'!$C8) -> 3891.9334 | AR8: =SUM(AF8:AQ8) -> 46346.956 | AT8: =P8 -> 19983.34 | AU8: =AD8 -> 34139.308 | AV8: =AR8 -> 46346.956 | AX8: =AU8-AT8 -> 14155.968 | AY8: =IFERROR(AX8/AT8,"") -> 0.70838848 | AZ8: =AV8-AU8 -> 12207.648 | BA8: =IFERROR(AZ8/AV8,"") -> 0.26339698
B9: 1.2 | C9: rHDPE | D9: 60 | E9: 106.3 | F9: 126.5 | G9: 79.725 | H9: 166.35 | I9: 161.375 | J9: 114.125 | K9: 126.5 | L9: 85.875 | M9: 162.625 | N9: 182.375 | O9: 127.4 | P9: =SUM(D9:O9) -> 1499.15 | R9: =SUMIFS('511'!$Q:$Q,'511'!$R:$R,'4.DOANH THU (USD)'!$C9,'511'!$A:$A,'4.DOANH THU (USD)'!R$6)/1000 -> 214.375 | S9: =SUMIFS('511'!$Q:$Q,'511'!$R:$R,'4.DOANH THU (USD)'!$C9,'511'!$A:$A,'4.DOANH THU (USD)'!S$6)/1000 -> 136.95 | T9: =SUMIFS('511'!$Q:$Q,'511'!$R:$R,'4.DOANH THU (USD)'!$C9,'511'!$A:$A,'4.DOANH THU (USD)'!T$6)/1000 -> 171.9 | U9: =SUMIFS('511'!$Q:$Q,'511'!$R:$R,'4.DOANH THU (USD)'!$C9,'511'!$A:$A,'4.DOANH THU (USD)'!U$6)/1000 -> 211.025 | V9: =SUMIFS('511'!$Q:$Q,'511'!$R:$R,'4.DOANH THU (USD)'!$C9,'511'!$A:$A,'4.DOANH THU (USD)'!V$6)/1000 -> 195.9 | W9: =SUMIFS('511'!$Q:$Q,'511'!$R:$R,'4.DOANH THU (USD)'!$C9,'511'!$A:$A,'4.DOANH THU (USD)'!W$6)/1000 -> 126.5 | X9: =SUMIFS('511'!$Q:$Q,'511'!$R:$R,'4.DOANH THU (USD)'!$C9,'511'!$A:$A,'4.DOANH THU (USD)'!X$6)/1000 -> 110.925 | Y9: =SUMIFS('511'!$Q:$Q,'511'!$R:$R,'4.DOANH THU (USD)'!$C9,'511'!$A:$A,'4.DOANH THU (USD)'!Y$6)/1000 -> 141.125 | ... AA9: =SUMIFS('511'!$Q:$Q,'511'!$R:$R,'4.DOANH THU (USD)'!$C9,'511'!$A:$A,'4.DOANH THU (USD)'!AA$6)/1000 -> 235.5 | AB9: 302 | AC9: 352.5 | AD9: =SUM(R9:AC9) -> 2341.975 | AF9: =SUMIFS('KH 2026'!N:N,'KH 2026'!$K:$K,'4.DOANH THU (USD)'!$C9) -> 0 | AG9: =SUMIFS('KH 2026'!O:O,'KH 2026'!$K:$K,'4.DOANH THU (USD)'!$C9) -> 0 | AH9: =SUMIFS('KH 2026'!P:P,'KH 2026'!$K:$K,'4.DOANH THU (USD)'!$C9) -> 0 | AI9: =SUMIFS('KH 2026'!Q:Q,'KH 2026'!$K:$K,'4.DOANH THU (USD)'!$C9) -> 0 | AJ9: =SUMIFS('KH 2026'!R:R,'KH 2026'!$K:$K,'4.DOANH THU (USD)'!$C9) -> 0 | AK9: =SUMIFS('KH 2026'!S:S,'KH 2026'!$K:$K,'4.DOANH THU (USD)'!$C9) -> 0 | AL9: =SUMIFS('KH 2026'!T:T,'KH 2026'!$K:$K,'4.DOANH THU (USD)'!$C9) -> 0 | AM9: =SUMIFS('KH 2026'!U:U,'KH 2026'!$K:$K,'4.DOANH THU (USD)'!$C9) -> 0 | AN9: =SUMIFS('KH 2026'!V:V,'KH 2026'!$K:$K,'4.DOANH THU (USD)'!$C9) -> 0 | AO9: =SUMIFS('KH 2026'!W:W,'KH 2026'!$K:$K,'4.DOANH THU (USD)'!$C9) -> 0 | AP9: =SUMIFS('KH 2026'!X:X,'KH 2026'!$K:$K,'4.DOANH THU (USD)'!$C9) -> 0 | AQ9: =SUMIFS('KH 2026'!Y:Y,'KH 2026'!$K:$K,'4.DOANH THU (USD)'!$C9) -> 0 | AR9: =SUM(AF9:AQ9) -> 0 | AT9: =P9 -> 1499.15 | AU9: =AD9 -> 2341.975 | AV9: =AR9 -> 0 | AX9: =AU9-AT9 -> 842.825 | AY9: =IFERROR(AX9/AT9,"") -> 0.56220191 | AZ9: =AV9-AU9 -> -2341.975 | BA9: =IFERROR(AZ9/AV9,"")
B10: 1.3 | C10: rPP | D10: 0 | E10: 0 | F10: 0 | G10: 0 | H10: 0.125 | I10: 0 | J10: 0 | K10: 0.075 | L10: 0 | M10: 0 | N10: 0 | O10: 0 | P10: =SUM(D10:O10) -> 0.2 | R10: =SUMIFS('511'!$Q:$Q,'511'!$R:$R,'4.DOANH THU (USD)'!$C10,'511'!$A:$A,'4.DOANH THU (USD)'!R$6)/1000 -> 15 | S10: =SUMIFS('511'!$Q:$Q,'511'!$R:$R,'4.DOANH THU (USD)'!$C10,'511'!$A:$A,'4.DOANH THU (USD)'!S$6)/1000 -> 15 | T10: =SUMIFS('511'!$Q:$Q,'511'!$R:$R,'4.DOANH THU (USD)'!$C10,'511'!$A:$A,'4.DOANH THU (USD)'!T$6)/1000 -> 56 | U10: =SUMIFS('511'!$Q:$Q,'511'!$R:$R,'4.DOANH THU (USD)'!$C10,'511'!$A:$A,'4.DOANH THU (USD)'!U$6)/1000 -> 30.5 | V10: =SUMIFS('511'!$Q:$Q,'511'!$R:$R,'4.DOANH THU (USD)'!$C10,'511'!$A:$A,'4.DOANH THU (USD)'!V$6)/1000 -> 35.25 | W10: =SUMIFS('511'!$Q:$Q,'511'!$R:$R,'4.DOANH THU (USD)'!$C10,'511'!$A:$A,'4.DOANH THU (USD)'!W$6)/1000 -> 5.25 | X10: =SUMIFS('511'!$Q:$Q,'511'!$R:$R,'4.DOANH THU (USD)'!$C10,'511'!$A:$A,'4.DOANH THU (USD)'!X$6)/1000 -> 0.3 | Y10: =SUMIFS('511'!$Q:$Q,'511'!$R:$R,'4.DOANH THU (USD)'!$C10,'511'!$A:$A,'4.DOANH THU (USD)'!Y$6)/1000 -> 41.675 | ... AA10: =SUMIFS('511'!$Q:$Q,'511'!$R:$R,'4.DOANH THU (USD)'!$C10,'511'!$A:$A,'4.DOANH THU (USD)'!AA$6)/1000 -> 18.025 | AB10: 41.1 | AC10: 50.9 | AD10: =SUM(R10:AC10) -> 309.025 | AF10: =SUMIFS('KH 2026'!N:N,'KH 2026'!$K:$K,'4.DOANH THU (USD)'!$C10) -> 72 | AG10: =SUMIFS('KH 2026'!O:O,'KH 2026'!$K:$K,'4.DOANH THU (USD)'!$C10) -> 63 | AH10: =SUMIFS('KH 2026'!P:P,'KH 2026'!$K:$K,'4.DOANH THU (USD)'!$C10) -> 72 | AI10: =SUMIFS('KH 2026'!Q:Q,'KH 2026'!$K:$K,'4.DOANH THU (USD)'!$C10) -> 63 | AJ10: =SUMIFS('KH 2026'!R:R,'KH 2026'!$K:$K,'4.DOANH THU (USD)'!$C10) -> 72 | AK10: =SUMIFS('KH 2026'!S:S,'KH 2026'!$K:$K,'4.DOANH THU (USD)'!$C10) -> 87 | AL10: =SUMIFS('KH 2026'!T:T,'KH 2026'!$K:$K,'4.DOANH THU (USD)'!$C10) -> 72 | AM10: =SUMIFS('KH 2026'!U:U,'KH 2026'!$K:$K,'4.DOANH THU (USD)'!$C10) -> 63 | AN10: =SUMIFS('KH 2026'!V:V,'KH 2026'!$K:$K,'4.DOANH THU (USD)'!$C10) -> 72 | AO10: =SUMIFS('KH 2026'!W:W,'KH 2026'!$K:$K,'4.DOANH THU (USD)'!$C10) -> 87 | AP10: =SUMIFS('KH 2026'!X:X,'KH 2026'!$K:$K,'4.DOANH THU (USD)'!$C10) -> 72 | AQ10: =SUMIFS('KH 2026'!Y:Y,'KH 2026'!$K:$K,'4.DOANH THU (USD)'!$C10) -> 63 | AR10: =SUM(AF10:AQ10) -> 858 | AT10: =P10 -> 0.2 | AU10: =AD10 -> 309.025 | AV10: =AR10 -> 858 | AX10: =AU10-AT10 -> 308.825 | AZ10: =AV10-AU10 -> 548.975 | BA10: =IFERROR(AZ10/AV10,"") -> 0.639831
B11: 1.4 | C11: Xơ sợi | P11: =SUM(D11:O11) -> 0 | R11: =SUMIFS('511'!$Q:$Q,'511'!$R:$R,'4.DOANH THU (USD)'!$C11,'511'!$A:$A,'4.DOANH THU (USD)'!R$6)/1000 -> 22 | S11: =SUMIFS('511'!$Q:$Q,'511'!$R:$R,'4.DOANH THU (USD)'!$C11,'511'!$A:$A,'4.DOANH THU (USD)'!S$6)/1000 -> 50.025 | T11: =SUMIFS('511'!$Q:$Q,'511'!$R:$R,'4.DOANH THU (USD)'!$C11,'511'!$A:$A,'4.DOANH THU (USD)'!T$6)/1000 -> 0.075 | U11: =SUMIFS('511'!$Q:$Q,'511'!$R:$R,'4.DOANH THU (USD)'!$C11,'511'!$A:$A,'4.DOANH THU (USD)'!U$6)/1000 -> 225.5 | V11: =SUMIFS('511'!$Q:$Q,'511'!$R:$R,'4.DOANH THU (USD)'!$C11,'511'!$A:$A,'4.DOANH THU (USD)'!V$6)/1000 -> 82.55 | W11: =SUMIFS('511'!$Q:$Q,'511'!$R:$R,'4.DOANH THU (USD)'!$C11,'511'!$A:$A,'4.DOANH THU (USD)'!W$6)/1000 -> 185.9 | X11: =SUMIFS('511'!$Q:$Q,'511'!$R:$R,'4.DOANH THU (USD)'!$C11,'511'!$A:$A,'4.DOANH THU (USD)'!X$6)/1000 -> 165 | Y11: =SUMIFS('511'!$Q:$Q,'511'!$R:$R,'4.DOANH THU (USD)'!$C11,'511'!$A:$A,'4.DOANH THU (USD)'!Y$6)/1000 -> 0 | ... AA11: =SUMIFS('511'!$Q:$Q,'511'!$R:$R,'4.DOANH THU (USD)'!$C11,'511'!$A:$A,'4.DOANH THU (USD)'!AA$6)/1000 -> 231 | AB11: 66 | AC11: 264 | AD11: =SUM(R11:AC11) -> 1512.05 | AF11: =SUMIFS('KH 2026'!N:N,'KH 2026'!$K:$K,'4.DOANH THU (USD)'!$C11) -> 86.586983 | AG11: =SUMIFS('KH 2026'!O:O,'KH 2026'!$K:$K,'4.DOANH THU (USD)'!$C11) -> 86.586983 | AH11: =SUMIFS('KH 2026'!P:P,'KH 2026'!$K:$K,'4.DOANH THU (USD)'!$C11) -> 86.586983 | AI11: =SUMIFS('KH 2026'!Q:Q,'KH 2026'!$K:$K,'4.DOANH THU (USD)'!$C11) -> 86.586983 | AJ11: =SUMIFS('KH 2026'!R:R,'KH 2026'!$K:$K,'4.DOANH THU (USD)'!$C11) -> 86.586983 | AK11: =SUMIFS('KH 2026'!S:S,'KH 2026'!$K:$K,'4.DOANH THU (USD)'!$C11) -> 86.586983 | AL11: =SUMIFS('KH 2026'!T:T,'KH 2026'!$K:$K,'4.DOANH THU (USD)'!$C11) -> 86.586983 | AM11: =SUMIFS('KH 2026'!U:U,'KH 2026'!$K:$K,'4.DOANH THU (USD)'!$C11) -> 86.586983 | AN11: =SUMIFS('KH 2026'!V:V,'KH 2026'!$K:$K,'4.DOANH THU (USD)'!$C11) -> 86.586983 | AO11: =SUMIFS('KH 2026'!W:W,'KH 2026'!$K:$K,'4.DOANH THU (USD)'!$C11) -> 86.586983 | AP11: =SUMIFS('KH 2026'!X:X,'KH 2026'!$K:$K,'4.DOANH THU (USD)'!$C11) -> 86.586983 | AQ11: =SUMIFS('KH 2026'!Y:Y,'KH 2026'!$K:$K,'4.DOANH THU (USD)'!$C11) -> 86.586983 | AR11: =SUM(AF11:AQ11) -> 1039.0438 | AT11: =P11 -> 0 | AU11: =AD11 -> 1512.05 | AV11: =AR11 -> 1039.0438 | AX11: =AU11-AT11 -> 1512.05 | AY11: =IFERROR(AX11/AT11,"") | AZ11: =AV11-AU11 -> -473.0062 | BA11: =IFERROR(AZ11/AV11,"") -> -0.4552322
B12: 1.5 | C12: Khác (phó sản, phế liệu) | P12: =SUM(D12:O12) -> 0 | R12: =SUMIFS('511'!$Q:$Q,'511'!$R:$R,'4.DOANH THU (USD)'!$C12,'511'!$A:$A,'4.DOANH THU (USD)'!R$6)/1000 -> 246.83 | S12: =SUMIFS('511'!$Q:$Q,'511'!$R:$R,'4.DOANH THU (USD)'!$C12,'511'!$A:$A,'4.DOANH THU (USD)'!S$6)/1000 -> 55.676 | T12: =SUMIFS('511'!$Q:$Q,'511'!$R:$R,'4.DOANH THU (USD)'!$C12,'511'!$A:$A,'4.DOANH THU (USD)'!T$6)/1000 -> 5.668 | U12: =SUMIFS('511'!$Q:$Q,'511'!$R:$R,'4.DOANH THU (USD)'!$C12,'511'!$A:$A,'4.DOANH THU (USD)'!U$6)/1000 -> 2.002 | V12: =SUMIFS('511'!$Q:$Q,'511'!$R:$R,'4.DOANH THU (USD)'!$C12,'511'!$A:$A,'4.DOANH THU (USD)'!V$6)/1000 -> 37.269 | W12: =SUMIFS('511'!$Q:$Q,'511'!$R:$R,'4.DOANH THU (USD)'!$C12,'511'!$A:$A,'4.DOANH THU (USD)'!W$6)/1000 -> 39.315 | X12: =SUMIFS('511'!$Q:$Q,'511'!$R:$R,'4.DOANH THU (USD)'!$C12,'511'!$A:$A,'4.DOANH THU (USD)'!X$6)/1000 -> 22.628 | Y12: =SUMIFS('511'!$Q:$Q,'511'!$R:$R,'4.DOANH THU (USD)'!$C12,'511'!$A:$A,'4.DOANH THU (USD)'!Y$6)/1000 -> 193.176 | ... AA12: =SUMIFS('511'!$Q:$Q,'511'!$R:$R,'4.DOANH THU (USD)'!$C12,'511'!$A:$A,'4.DOANH THU (USD)'!AA$6)/1000 -> 219.938 | AD12: =SUM(R12:AC12) -> 1071.409 | AF12: =SUMIFS('KH 2026'!N:N,'KH 2026'!$K:$K,'4.DOANH THU (USD)'!$C12) -> 0 | AG12: =SUMIFS('KH 2026'!O:O,'KH 2026'!$K:$K,'4.DOANH THU (USD)'!$C12) -> 0 | AH12: =SUMIFS('KH 2026'!P:P,'KH 2026'!$K:$K,'4.DOANH THU (USD)'!$C12) -> 0 | AI12: =SUMIFS('KH 2026'!Q:Q,'KH 2026'!$K:$K,'4.DOANH THU (USD)'!$C12) -> 0 | AJ12: =SUMIFS('KH 2026'!R:R,'KH 2026'!$K:$K,'4.DOANH THU (USD)'!$C12) -> 0 | AK12: =SUMIFS('KH 2026'!S:S,'KH 2026'!$K:$K,'4.DOANH THU (USD)'!$C12) -> 0 | AL12: =SUMIFS('KH 2026'!T:T,'KH 2026'!$K:$K,'4.DOANH THU (USD)'!$C12) -> 0 | AM12: =SUMIFS('KH 2026'!U:U,'KH 2026'!$K:$K,'4.DOANH THU (USD)'!$C12) -> 0 | AN12: =SUMIFS('KH 2026'!V:V,'KH 2026'!$K:$K,'4.DOANH THU (USD)'!$C12) -> 0 | AO12: =SUMIFS('KH 2026'!W:W,'KH 2026'!$K:$K,'4.DOANH THU (USD)'!$C12) -> 0 | AP12: =SUMIFS('KH 2026'!X:X,'KH 2026'!$K:$K,'4.DOANH THU (USD)'!$C12) -> 0 | AQ12: =SUMIFS('KH 2026'!Y:Y,'KH 2026'!$K:$K,'4.DOANH THU (USD)'!$C12) -> 0 | AR12: =SUM(AF12:AQ12) -> 0 | AT12: =P12 -> 0 | AU12: =AD12 -> 1071.409 | AV12: =AR12 -> 0 | AX12: =AU12-AT12 -> 1071.409 | AY12: =IFERROR(AX12/AT12,"") | AZ12: =AV12-AU12 -> -1071.409 | BA12: =IFERROR(AZ12/AV12,"")
B13: 1.6 | C13: Khác (tài trợ) | P13: =SUM(D13:O13) -> 0 | R13: =SUMIFS('511'!$Q:$Q,'511'!$R:$R,'4.DOANH THU (USD)'!$C13,'511'!$A:$A,'4.DOANH THU (USD)'!R$6)/1000 -> 0 | S13: =SUMIFS('511'!$Q:$Q,'511'!$R:$R,'4.DOANH THU (USD)'!$C13,'511'!$A:$A,'4.DOANH THU (USD)'!S$6)/1000 -> 0 | T13: =SUMIFS('511'!$Q:$Q,'511'!$R:$R,'4.DOANH THU (USD)'!$C13,'511'!$A:$A,'4.DOANH THU (USD)'!T$6)/1000 -> 0 | U13: =SUMIFS('511'!$Q:$Q,'511'!$R:$R,'4.DOANH THU (USD)'!$C13,'511'!$A:$A,'4.DOANH THU (USD)'!U$6)/1000 -> 0 | V13: =SUMIFS('511'!$Q:$Q,'511'!$R:$R,'4.DOANH THU (USD)'!$C13,'511'!$A:$A,'4.DOANH THU (USD)'!V$6)/1000 -> 0 | W13: =SUMIFS('511'!$Q:$Q,'511'!$R:$R,'4.DOANH THU (USD)'!$C13,'511'!$A:$A,'4.DOANH THU (USD)'!W$6)/1000 -> 0 | X13: =SUMIFS('511'!$Q:$Q,'511'!$R:$R,'4.DOANH THU (USD)'!$C13,'511'!$A:$A,'4.DOANH THU (USD)'!X$6)/1000 -> 0 | Y13: =SUMIFS('511'!$Q:$Q,'511'!$R:$R,'4.DOANH THU (USD)'!$C13,'511'!$A:$A,'4.DOANH THU (USD)'!Y$6)/1000 -> 0 | ... AA13: =SUMIFS('511'!$Q:$Q,'511'!$R:$R,'4.DOANH THU (USD)'!$C13,'511'!$A:$A,'4.DOANH THU (USD)'!AA$6)/1000 -> 0 | AD13: =SUM(R13:AC13) -> 0 | AF13: =SUMIFS('KH 2026'!N:N,'KH 2026'!$K:$K,'4.DOANH THU (USD)'!$C13) -> 0 | AG13: =SUMIFS('KH 2026'!O:O,'KH 2026'!$K:$K,'4.DOANH THU (USD)'!$C13) -> 0 | AH13: =SUMIFS('KH 2026'!P:P,'KH 2026'!$K:$K,'4.DOANH THU (USD)'!$C13) -> 0 | AI13: =SUMIFS('KH 2026'!Q:Q,'KH 2026'!$K:$K,'4.DOANH THU (USD)'!$C13) -> 0 | AJ13: =SUMIFS('KH 2026'!R:R,'KH 2026'!$K:$K,'4.DOANH THU (USD)'!$C13) -> 0 | AK13: =SUMIFS('KH 2026'!S:S,'KH 2026'!$K:$K,'4.DOANH THU (USD)'!$C13) -> 0 | AL13: =SUMIFS('KH 2026'!T:T,'KH 2026'!$K:$K,'4.DOANH THU (USD)'!$C13) -> 0 | AM13: =SUMIFS('KH 2026'!U:U,'KH 2026'!$K:$K,'4.DOANH THU (USD)'!$C13) -> 0 | AN13: =SUMIFS('KH 2026'!V:V,'KH 2026'!$K:$K,'4.DOANH THU (USD)'!$C13) -> 0 | AO13: =SUMIFS('KH 2026'!W:W,'KH 2026'!$K:$K,'4.DOANH THU (USD)'!$C13) -> 0 | AP13: =SUMIFS('KH 2026'!X:X,'KH 2026'!$K:$K,'4.DOANH THU (USD)'!$C13) -> 0 | AQ13: =SUMIFS('KH 2026'!Y:Y,'KH 2026'!$K:$K,'4.DOANH THU (USD)'!$C13) -> 0 | AR13: =SUM(AF13:AQ13) -> 0 | AT13: =P13 -> 0 | AU13: =AD13 -> 0 | AV13: =AR13 -> 0 | AX13: =AU13-AT13 -> 0 | AY13: =IFERROR(AX13/AT13,"") | AZ13: =AV13-AU13 -> 0 | BA13: =IFERROR(AZ13/AV13,"")
B14: 1.7 | C14: Dây đai | P14: =SUM(D14:O14) -> 0 | R14: =SUMIFS('511'!$Q:$Q,'511'!$R:$R,'4.DOANH THU (USD)'!$C14,'511'!$A:$A,'4.DOANH THU (USD)'!R$6)/1000 -> 0 | S14: =SUMIFS('511'!$Q:$Q,'511'!$R:$R,'4.DOANH THU (USD)'!$C14,'511'!$A:$A,'4.DOANH THU (USD)'!S$6)/1000 -> 165 | T14: =SUMIFS('511'!$Q:$Q,'511'!$R:$R,'4.DOANH THU (USD)'!$C14,'511'!$A:$A,'4.DOANH THU (USD)'!T$6)/1000 -> 58 | U14: =SUMIFS('511'!$Q:$Q,'511'!$R:$R,'4.DOANH THU (USD)'!$C14,'511'!$A:$A,'4.DOANH THU (USD)'!U$6)/1000 -> 0 | V14: =SUMIFS('511'!$Q:$Q,'511'!$R:$R,'4.DOANH THU (USD)'!$C14,'511'!$A:$A,'4.DOANH THU (USD)'!V$6)/1000 -> 222 | W14: =SUMIFS('511'!$Q:$Q,'511'!$R:$R,'4.DOANH THU (USD)'!$C14,'511'!$A:$A,'4.DOANH THU (USD)'!W$6)/1000 -> 511.26 | X14: =SUMIFS('511'!$Q:$Q,'511'!$R:$R,'4.DOANH THU (USD)'!$C14,'511'!$A:$A,'4.DOANH THU (USD)'!X$6)/1000 -> 180 | Y14: =SUMIFS('511'!$Q:$Q,'511'!$R:$R,'4.DOANH THU (USD)'!$C14,'511'!$A:$A,'4.DOANH THU (USD)'!Y$6)/1000 -> 380 | ... AA14: =SUMIFS('511'!$Q:$Q,'511'!$R:$R,'4.DOANH THU (USD)'!$C14,'511'!$A:$A,'4.DOANH THU (USD)'!AA$6)/1000 -> 264.74 | AD14: =SUM(R14:AC14) -> 1781 | AF14: =#REF! -> #REF! | AG14: =#REF! -> #REF! | AH14: =#REF! -> #REF! | AI14: =#REF! -> #REF! | AJ14: =#REF! -> #REF! | AK14: =#REF! -> #REF! | AL14: =#REF! -> #REF! | AM14: =#REF! -> #REF! | ... AQ14: =#REF! -> #REF! | AR14: =SUM(AF14:AQ14) -> #REF! | AT14: =P14 -> 0 | AU14: =AD14 -> 1781 | AV14: =AR14 -> #REF! | AX14: =AU14-AT14 -> 1781 | AY14: =IFERROR(AX14/AT14,"") | AZ14: =AV14-AU14 -> #REF! | BA14: =IFERROR(AZ14/AV14,"")
B15: 1.8 | C15: Chi phí xuất khẩu | P15: =SUM(D15:O15) -> 0 | AT15: =P15 -> 0 | AU15: =AD15 -> 0 | AV15: =AR15 -> 0 | AX15: =AU15-AT15 -> 0 | AY15: =IFERROR(AX15/AT15,"") | AZ15: =AV15-AU15 -> 0 | BA15: =IFERROR(AZ15/AV15,"")
B16: 1.9 | C16: XX | AT16: =P16 -> 0 | AU16: =AD16 -> 0 | AV16: =AR16 -> 0 | AX16: =AU16-AT16 -> 0 | AY16: =IFERROR(AX16/AT16,"") | AZ16: =AV16-AU16 -> 0 | BA16: =IFERROR(AZ16/AV16,"")
B17: 1.10 | C17: XX | AT17: =P17 -> 0 | AU17: =AD17 -> 0 | AV17: =AR17 -> 0 | AX17: =AU17-AT17 -> 0 | AY17: =IFERROR(AX17/AT17,"") | AZ17: =AV17-AU17 -> 0 | BA17: =IFERROR(AZ17/AV17,"")
