Workbook
Name EXR: Asm.!$B$2

Sheet Ghi chú
A1: MỘT SỐ LƯU Ý
A3: STT | B3: Ghi chú màu các ô | C3: Ghi chú
A4: 1 | C4: Droplist: lựa chọn các kết quả định sẵn. Nếu như danh sách chưa đủ, đề nghị phòng ban liên hệ lại với kế toán quản trị phụ trách để cập nhật thêm
A5: 2 | C5: Điền thông tin vào các ô
A6: 3 | C6: Không cần điền
A7: 4 | C7: Các ô trống là đã có gán công thức
A17: THỐNG NHẤT CÁCH ĐẶT TÊN SẢN PHẨM MỚI, KHÁCH HÀNG MỚI
A19: Cách đặt mã sản phẩm mới:
A20: Ví dụ:
B21: NS26-PET-001
B22: NS26-HDTHOI-001
B23: NS26-HDTHOI-002
B24: NS26-HDTHOI-003
B25: NS26-PP-003
B26: NS26-HDEP-001
B27: NS26-XOSOI-001
A29: Cách đặt khách hàng mới:
A30: Ví dụ:
B31: 1-NS26-NEWCUS-001
B32: 2-NS26-NEWCUS-002
A33: Số 1 ở đầu là nội địa
A34: Số 2 là xuất khẩu

Sheet ĐGVC
A3: Tên Khách-Rút gọn | B3: Kênh bán hàng | C3: Địa điểm đến | D3: Nước đến | E3: Incoterm | G3: ĐƠN GIÁ VẬN CHUYỂN NỘI ĐỊA - BAO GỒM KÊNH XUẤT KHẨU | O3: Quy ra VND | Q3: ĐƠN GIÁ CƯỚC TÀU | Y3: Quy ra VND
G4: Cont 20' | K4: ĐG (VND/tấn) USD/tấn-XK | O4: KH26 | Q4: Cont 20' | U4: ĐG (VND/tấn) | Y4: KH26
G5: TT25 | H5: KH26 | I5: VND/USD | K5: TT25 | L5: KH26 | M5: VND/USD | Q5: TT25 | R5: KH26 | S5: VND/USD | U5: TT25 | V5: KH26 | W5: VND/USD
A6: Công ty TNHH La Vie | B6: Nội địa | C6: Tây Ninh | D6: Việt Nam | E6: EXW | K6: =G6/22 -> 0 | L6: =H6/22 -> 0 | M6: =I6 -> 0 | O6: =IF(M6="USD",L6*EXR,L6) -> 0 | U6: =Q6/22 -> 0 | V6: =R6/22 -> 0 | W6: =S6 -> 0 | Y6: =IF(W6="USD",V6*EXR,V6) -> 0
A7: Quang Chí Bảo | B7: Nội địa | C7: Hồ Chí Minh | D7: Việt Nam | E7: EXW | K7: =G7/22 -> 0 | L7: =H7/22 -> 0 | M7: =I7 -> 0 | O7: =IF(M7="USD",L7*EXR,L7) -> 0 | U7: =Q7/22 -> 0 | V7: =R7/22 -> 0 | W7: =S7 -> 0 | Y7: =IF(W7="USD",V7*EXR,V7) -> 0
A8: Nhựa Đạt Hòa | B8: Nội địa | C8: Hồ Chí Minh | D8: Việt Nam | E8: DDP | K8: =G8/22 -> 0 | L8: =H8/22 -> 0 | M8: =I8 -> 0 | O8: =IF(M8="USD",L8*EXR,L8) -> 0 | U8: =Q8/22 -> 0 | V8: =R8/22 -> 0 | W8: =S8 -> 0 | Y8: =IF(W8="USD",V8*EXR,V8) -> 0
A9: Công ty trách nhiệm hữu hạn Uy Kiệt | B9: Nội địa | C9: Bình Dương | D9: Việt Nam | E9: DDP | G9: 4840000 | H9: 4840000 | I9: VND | K9: =G9/22 -> 220000 | L9: =H9/22 -> 220000 | M9: =I9 -> VND | O9: =IF(M9="USD",L9*EXR,L9) -> 220000 | U9: =Q9/22 -> 0 | V9: =R9/22 -> 0 | W9: =S9 -> 0 | Y9: =IF(W9="USD",V9*EXR,V9) -> 0
A10: Plascene- DTP | B10: Nội địa | C10: Tây Ninh | D10: Việt Nam | E10: DDP | K10: =G10/22 -> 0 | L10: =H10/22 -> 0 | M10: =I10 -> 0 | O10: =IF(M10="USD",L10*EXR,L10) -> 0 | U10: =Q10/22 -> 0 | V10: =R10/22 -> 0 | W10: =S10 -> 0 | Y10: =IF(W10="USD",V10*EXR,V10) -> 0
A11: CÔNG TY TNHH HƯNG DỤ | B11: Nội địa | C11: Bình Dương | D11: Việt Nam | E11: DDP | G11: 3800000 | H11: 3800000 | I11: VND | K11: =G11/22 -> 172727.27 | L11: =H11/22 -> 172727.27 | M11: =I11 -> VND | O11: =IF(M11="USD",L11*EXR,L11) -> 172727.27 | U11: =Q11/22 -> 0 | V11: =R11/22 -> 0 | W11: =S11 -> 0 | Y11: =IF(W11="USD",V11*EXR,V11) -> 0
A12: New Developments - Hạt HDPE - NĐ | B12: Nội địa | C12: Việt Nam | D12: Việt Nam | E12: EXW | K12: =G12/22 -> 0 | L12: =H12/22 -> 0 | M12: =I12 -> 0 | O12: =IF(M12="USD",L12*EXR,L12) -> 0 | U12: =Q12/22 -> 0 | V12: =R12/22 -> 0 | W12: =S12 -> 0 | Y12: =IF(W12="USD",V12*EXR,V12) -> 0
A13: Motul -DTP | B13: Nội địa | C13: Tây Ninh | D13: Việt Nam | E13: DDP | K13: =G13/22 -> 0 | L13: =H13/22 -> 0 | M13: =I13 -> 0 | O13: =IF(M13="USD",L13*EXR,L13) -> 0 | U13: =Q13/22 -> 0 | V13: =R13/22 -> 0 | W13: =S13 -> 0 | Y13: =IF(W13="USD",V13*EXR,V13) -> 0
A14: MTVN Plastic | B14: Nội địa | C14: Đồng Nai | D14: Việt Nam | E14: EXW | K14: =G14/22 -> 0 | L14: =H14/22 -> 0 | M14: =I14 -> 0 | O14: =IF(M14="USD",L14*EXR,L14) -> 0 | U14: =Q14/22 -> 0 | V14: =R14/22 -> 0 | W14: =S14 -> 0 | Y14: =IF(W14="USD",V14*EXR,V14) -> 0
A15: New Developments - Hạt PP - NĐ | B15: Nội địa | C15: Việt Nam | D15: Việt Nam | E15: EXW | K15: =G15/22 -> 0 | L15: =H15/22 -> 0 | M15: =I15 -> 0 | O15: =IF(M15="USD",L15*EXR,L15) -> 0 | U15: =Q15/22 -> 0 | V15: =R15/22 -> 0 | W15: =S15 -> 0 | Y15: =IF(W15="USD",V15*EXR,V15) -> 0
A16: NHỰA ĐỒNG NAI | B16: Nội địa | C16: Đồng Nai | D16: Việt Nam | E16: DDP | K16: =G16/22 -> 0 | L16: =H16/22 -> 0 | M16: =I16 -> 0 | O16: =IF(M16="USD",L16*EXR,L16) -> 0 | U16: =Q16/22 -> 0 | V16: =R16/22 -> 0 | W16: =S16 -> 0 | Y16: =IF(W16="USD",V16*EXR,V16) -> 0
A17: CN COCA-COLA VN - LONG AN | B17: Nội địa | C17: Tây Ninh | D17: Việt Nam | E17: DDP | G17: 4400000 | H17: 4400000 | I17: VND | K17: =G17/22 -> 200000 | L17: =H17/22 -> 200000 | M17: =I17 -> VND | O17: =IF(M17="USD",L17*EXR,L17) -> 200000 | U17: =Q17/22 -> 0 | V17: =R17/22 -> 0 | W17: =S17 -> 0 | Y17: =IF(W17="USD",V17*EXR,V17) -> 0
A18: LƯỚI BẢO NÔNG | B18: Nội địa | C18: Tây Ninh | D18: Việt Nam | E18: EXW | K18: =G18/22 -> 0 | L18: =H18/22 -> 0 | M18: =I18 -> 0 | O18: =IF(M18="USD",L18*EXR,L18) -> 0 | U18: =Q18/22 -> 0 | V18: =R18/22 -> 0 | W18: =S18 -> 0 | Y18: =IF(W18="USD",V18*EXR,V18) -> 0
A19: HUY THÀNH | B19: Nội địa | C19: Tây Ninh | D19: Việt Nam | E19: DDP | K19: =G19/22 -> 0 | L19: =H19/22 -> 0 | M19: =I19 -> 0 | O19: =IF(M19="USD",L19*EXR,L19) -> 0 | U19: =Q19/22 -> 0 | V19: =R19/22 -> 0 | W19: =S19 -> 0 | Y19: =IF(W19="USD",V19*EXR,V19) -> 0
A20: MTV MILKIWAY SOLUTION | B20: Nội địa | C20: Hồ Chí Minh | D20: Việt Nam | E20: DDP | K20: =G20/22 -> 0 | L20: =H20/22 -> 0 | M20: =I20 -> 0 | O20: =IF(M20="USD",L20*EXR,L20) -> 0 | U20: =Q20/22 -> 0 | V20: =R20/22 -> 0 | W20: =S20 -> 0 | Y20: =IF(W20="USD",V20*EXR,V20) -> 0
A21: ĐẠI LỤC | B21: Nội địa | C21: Hồ Chí Minh | D21: Việt Nam | E21: DDP | K21: =G21/22 -> 0 | L21: =H21/22 -> 0 | M21: =I21 -> 0 | O21: =IF(M21="USD",L21*EXR,L21) -> 0 | U21: =Q21/22 -> 0 | V21: =R21/22 -> 0 | W21: =S21 -> 0 | Y21: =IF(W21="USD",V21*EXR,V21) -> 0
A22: THẠC HƯƠNG | B22: Nội địa | C22: Đồng Nai | D22: Việt Nam | E22: EXW | K22: =G22/22 -> 0 | L22: =H22/22 -> 0 | M22: =I22 -> 0 | O22: =IF(M22="USD",L22*EXR,L22) -> 0 | U22: =Q22/22 -> 0 | V22: =R22/22 -> 0 | W22: =S22 -> 0 | Y22: =IF(W22="USD",V22*EXR,V22) -> 0
A23: NHỰA LỘC PHÁT | B23: Nội địa | C23: Hồ Chí Minh | D23: Việt Nam | E23: DDP | K23: =G23/22 -> 0 | L23: =H23/22 -> 0 | M23: =I23 -> 0 | O23: =IF(M23="USD",L23*EXR,L23) -> 0 | U23: =Q23/22 -> 0 | V23: =R23/22 -> 0 | W23: =S23 -> 0 | Y23: =IF(W23="USD",V23*EXR,V23) -> 0
A24: CPSX Nhựa Duy Tân | B24: Nội địa | C24: Tây Ninh | D24: Việt Nam | E24: DDP | K24: =G24/22 -> 0 | L24: =H24/22 -> 0 | M24: =I24 -> 0 | O24: =IF(M24="USD",L24*EXR,L24) -> 0 | U24: =Q24/22 -> 0 | V24: =R24/22 -> 0 | W24: =S24 -> 0 | Y24: =IF(W24="USD",V24*EXR,V24) -> 0
A25: MONDELEZ-VIỆT THÀNH | B25: Nội địa | C25: Tây Ninh | D25: Việt Nam | E25: EXW | K25: =G25/22 -> 0 | L25: =H25/22 -> 0 | M25: =I25 -> 0 | O25: =IF(M25="USD",L25*EXR,L25) -> 0 | U25: =Q25/22 -> 0 | V25: =R25/22 -> 0 | W25: =S25 -> 0 | Y25: =IF(W25="USD",V25*EXR,V25) -> 0
A26: Hồng Kim Long An | B26: Nội địa | C26: Tây Ninh | D26: Việt Nam | E26: DDP | K26: =G26/22 -> 0 | L26: =H26/22 -> 0 | M26: =I26 -> 0 | O26: =IF(M26="USD",L26*EXR,L26) -> 0 | U26: =Q26/22 -> 0 | V26: =R26/22 -> 0 | W26: =S26 -> 0 | Y26: =IF(W26="USD",V26*EXR,V26) -> 0
A27: ĐÔ THÀNH | B27: Nội địa | C27: Hồ Chí Minh | D27: Việt Nam | E27: DDP | K27: =G27/22 -> 0 | L27: =H27/22 -> 0 | M27: =I27 -> 0 | O27: =IF(M27="USD",L27*EXR,L27) -> 0 | U27: =Q27/22 -> 0 | V27: =R27/22 -> 0 | W27: =S27 -> 0 | Y27: =IF(W27="USD",V27*EXR,V27) -> 0
A28: NHỰA TRƯỜNG AN | B28: Nội địa | C28: Tây Ninh | D28: Việt Nam | E28: DDP | K28: =G28/22 -> 0 | L28: =H28/22 -> 0 | M28: =I28 -> 0 | O28: =IF(M28="USD",L28*EXR,L28) -> 0 | U28: =Q28/22 -> 0 | V28: =R28/22 -> 0 | W28: =S28 -> 0 | Y28: =IF(W28="USD",V28*EXR,V28) -> 0
A29: LINH CHI | B29: Nội địa | C29: Hồ Chí Minh | D29: Việt Nam | E29: EXW | K29: =G29/22 -> 0 | L29: =H29/22 -> 0 | M29: =I29 -> 0 | O29: =IF(M29="USD",L29*EXR,L29) -> 0 | U29: =Q29/22 -> 0 | V29: =R29/22 -> 0 | W29: =S29 -> 0 | Y29: =IF(W29="USD",V29*EXR,V29) -> 0
... A52: NHỰA TC 2050 | B52: Nội địa | C52: Đà Nẵng | D52: Việt Nam | E52: DDP | K52: =G52/22 -> 0 | L52: =H52/22 -> 0 | M52: =I52 -> 0 | O52: =IF(M52="USD",L52*EXR,L52) -> 0 | U52: =Q52/22 -> 0 | V52: =R52/22 -> 0 | W52: =S52 -> 0 | Y52: =IF(W52="USD",V52*EXR,V52) -> 0
A53: Niagara Bottling, LLC | B53: Xuất khẩu | C53: Mỹ | D53: Mỹ | E53: FOB | G53: 440 | H53: 484 | I53: USD | K53: =G53/22 -> 20 | L53: 20 | M53: =I53 -> USD | O53: =IF(M53="USD",L53*EXR,L53) -> 530000 | U53: =Q53/22 -> 0 | V53: =R53/22 -> 0 | W53: =S53 -> 0 | Y53: =IF(W53="USD",V53*EXR,V53) -> 0
A54: Niagara Bottling, LLC | B54: Xuất khẩu | C54: Shepley | D54: UK | E54: FOB | G54: 440 | H54: 484 | I54: USD | K54: =G54/22 -> 20 | L54: 20 | M54: =I54 -> USD | O54: =IF(M54="USD",L54*EXR,L54) -> 530000 | U54: =Q54/22 -> 0 | V54: =R54/22 -> 0 | W54: =S54 -> 0 | Y54: =IF(W54="USD",V54*EXR,V54) -> 0
A55: OUTEIRINHO TURISMO E INDUSTRIA SA | B55: Xuất khẩu | C55: Lisbon | D55: Bồ Đào Nha | E55: FOB | G55: 440 | H55: 484 | I55: USD | K55: =G55/22 -> 20 | L55: 20 | M55: =I55 -> USD | O55: =IF(M55="USD",L55*EXR,L55) -> 530000 | U55: =Q55/22 -> 0 | V55: =R55/22 -> 0 | W55: =S55 -> 0 | Y55: =IF(W55="USD",V55*EXR,V55) -> 0
A56: SHARPAK AYLESHAM LTD | B56: Xuất khẩu | C56: Felixstowe | D56: UK | E56: CIF | G56: 440 | H56: 484 | I56: USD | K56: =G56/22 -> 20 | L56: 20 | M56: =I56 -> USD | O56: =IF(M56="USD",L56*EXR,L56) -> 530000 | Q56: 2695 | R56: 1800 | S56: USD | U56: =Q56/22 -> 122.5 | V56: =R56/22 -> 81.818182 | W56: =S56 -> USD | Y56: =IF(W56="USD",V56*EXR,V56) -> 2168181.8
A57: New Developments - Vảy PET - XK | B57: Xuất Khẩu | C57: Mỹ | D57: Unknown | E57: FOB | G57: 440 | H57: 484 | I57: USD | K57: =G57/22 -> 20 | L57: 20 | M57: =I57 -> USD | O57: =IF(M57="USD",L57*EXR,L57) -> 530000 | U57: =Q57/22 -> 0 | V57: =R57/22 -> 0 | W57: =S57 -> 0 | Y57: =IF(W57="USD",V57*EXR,V57) -> 0
A58: New Developments - Hạt PET - XK | B58: Xuất Khẩu | C58: Mỹ | D58: Unknown | E58: FOB | G58: 440 | H58: 484 | I58: USD | K58: =G58/22 -> 20 | L58: 20 | M58: =I58 -> USD | O58: =IF(M58="USD",L58*EXR,L58) -> 530000 | U58: =Q58/22 -> 0 | V58: =R58/22 -> 0 | W58: =S58 -> 0 | Y58: =IF(W58="USD",V58*EXR,V58) -> 0
A59: MHE ENTERPRISE | B59: Xuất khẩu | C59: Tema | D59: Ghana | E59: CIF | G59: 440 | H59: 484 | I59: USD | K59: =G59/22 -> 20 | L59: 20 | M59: =I59 -> USD | O59: =IF(M59="USD",L59*EXR,L59) -> 530000 | Q59: 3600 | R59: 4000 | S59: USD | U59: =Q59/22 -> 163.63636 | V59: =R59/22 -> 181.81818 | W59: =S59 -> USD | Y59: =IF(W59="USD",V59*EXR,V59) -> 4818181.8
A60: Vinmar International | B60: Xuất khẩu | C60: Mỹ | D60: Mỹ | E60: FOB | G60: 440 | H60: 484 | I60: USD | K60: =G60/22 -> 20 | L60: 20 | M60: =I60 -> USD | O60: =IF(M60="USD",L60*EXR,L60) -> 530000 | U60: =Q60/22 -> 0 | V60: =R60/22 -> 0 | W60: =S60 -> 0 | Y60: =IF(W60="USD",V60*EXR,V60) -> 0
A61: Svepol Americas Inc. | B61: Xuất khẩu | C61: Mỹ | D61: Mỹ | E61: FOB | G61: 440 | H61: 484 | I61: USD | K61: =G61/22 -> 20 | L61: 20 | M61: =I61 -> USD | O61: =IF(M61="USD",L61*EXR,L61) -> 530000 | U61: =Q61/22 -> 0 | V61: =R61/22 -> 0 | W61: =S61 -> 0 | Y61: =IF(W61="USD",V61*EXR,V61) -> 0
A62: Serioplast | B62: Xuất Khẩu | C62: Ý | D62: Ý | E62: FOB | G62: 440 | H62: 484 | I62: USD | K62: =G62/22 -> 20 | L62: 20 | M62: =I62 -> USD | O62: =IF(M62="USD",L62*EXR,L62) -> 530000 | U62: =Q62/22 -> 0 | V62: =R62/22 -> 0 | W62: =S62 -> 0 | Y62: =IF(W62="USD",V62*EXR,V62) -> 0
A63: KORYFES SA | B63: Xuất khẩu | C63: Varna | D63: Bulgaria | E63: CFR | G63: 440 | H63: 484 | I63: USD | K63: =G63/22 -> 20 | L63: 20 | M63: =I63 -> USD | O63: =IF(M63="USD",L63*EXR,L63) -> 530000 | Q63: 2000 | R63: 2700 | S63: USD | U63: =Q63/22 -> 90.909091 | V63: =R63/22 -> 122.72727 | W63: =S63 -> USD | Y63: =IF(W63="USD",V63*EXR,V63) -> 3252272.7
A64: Plascene, Inc. | B64: Xuất khẩu | C64: Mỹ | D64: Mỹ | E64: FOB | G64: 440 | H64: 484 | I64: USD | K64: =G64/22 -> 20 | L64: 20 | M64: =I64 -> USD | O64: =IF(M64="USD",L64*EXR,L64) -> 530000 | U64: =Q64/22 -> 0 | V64: =R64/22 -> 0 | W64: =S64 -> 0 | Y64: =IF(W64="USD",V64*EXR,V64) -> 0
...

Sheet Source_VC
A1: Địa điểm đến | B1: Nước đến | C1: Khu vực | D1: Incoterm | E1: Check
A2: {=_xlfn._xlws.SORT(_xlfn.UNIQUE(#REF!),,-1,FALSE)} -> #REF! | E2: {=IF(A2<>"",OR(_xlfn.TEXTJOIN("",FALSE,A2:D2)=ĐGVC!$B$6:$B$201&ĐGVC!$C$6:$C$201&ĐGVC!$D$6:$D$201&ĐGVC!$E$6:$E$201),"")} -> #REF!
E3: {=IF(A3<>"",OR(_xlfn.TEXTJOIN("",FALSE,A3:D3)=ĐGVC!$B$6:$B$201&ĐGVC!$C$6:$C$201&ĐGVC!$D$6:$D$201&ĐGVC!$E$6:$E$201),"")}
E4: {=IF(A4<>"",OR(_xlfn.TEXTJOIN("",FALSE,A4:D4)=ĐGVC!$B$6:$B$201&ĐGVC!$C$6:$C$201&ĐGVC!$D$6:$D$201&ĐGVC!$E$6:$E$201),"")}
E5: {=IF(A5<>"",OR(_xlfn.TEXTJOIN("",FALSE,A5:D5)=ĐGVC!$B$6:$B$201&ĐGVC!$C$6:$C$201&ĐGVC!$D$6:$D$201&ĐGVC!$E$6:$E$201),"")}
E6: {=IF(A6<>"",OR(_xlfn.TEXTJOIN("",FALSE,A6:D6)=ĐGVC!$B$6:$B$201&ĐGVC!$C$6:$C$201&ĐGVC!$D$6:$D$201&ĐGVC!$E$6:$E$201),"")}
E7: {=IF(A7<>"",OR(_xlfn.TEXTJOIN("",FALSE,A7:D7)=ĐGVC!$B$6:$B$201&ĐGVC!$C$6:$C$201&ĐGVC!$D$6:$D$201&ĐGVC!$E$6:$E$201),"")}
E8: {=IF(A8<>"",OR(_xlfn.TEXTJOIN("",FALSE,A8:D8)=ĐGVC!$B$6:$B$201&ĐGVC!$C$6:$C$201&ĐGVC!$D$6:$D$201&ĐGVC!$E$6:$E$201),"")}
E9: {=IF(A9<>"",OR(_xlfn.TEXTJOIN("",FALSE,A9:D9)=ĐGVC!$B$6:$B$201&ĐGVC!$C$6:$C$201&ĐGVC!$D$6:$D$201&ĐGVC!$E$6:$E$201),"")}
E10: {=IF(A10<>"",OR(_xlfn.TEXTJOIN("",FALSE,A10:D10)=ĐGVC!$B$6:$B$201&ĐGVC!$C$6:$C$201&ĐGVC!$D$6:$D$201&ĐGVC!$E$6:$E$201),"")}
E11: {=IF(A11<>"",OR(_xlfn.TEXTJOIN("",FALSE,A11:D11)=ĐGVC!$B$6:$B$201&ĐGVC!$C$6:$C$201&ĐGVC!$D$6:$D$201&ĐGVC!$E$6:$E$201),"")}
E12: {=IF(A12<>"",OR(_xlfn.TEXTJOIN("",FALSE,A12:D12)=ĐGVC!$B$6:$B$201&ĐGVC!$C$6:$C$201&ĐGVC!$D$6:$D$201&ĐGVC!$E$6:$E$201),"")}
E13: {=IF(A13<>"",OR(_xlfn.TEXTJOIN("",FALSE,A13:D13)=ĐGVC!$B$6:$B$201&ĐGVC!$C$6:$C$201&ĐGVC!$D$6:$D$201&ĐGVC!$E$6:$E$201),"")}
E14: {=IF(A14<>"",OR(_xlfn.TEXTJOIN("",FALSE,A14:D14)=ĐGVC!$B$6:$B$201&ĐGVC!$C$6:$C$201&ĐGVC!$D$6:$D$201&ĐGVC!$E$6:$E$201),"")}
... E200: {=IF(A200<>"",OR(_xlfn.TEXTJOIN("",FALSE,A200:D200)=ĐGVC!$B$6:$B$201&ĐGVC!$C$6:$C$201&ĐGVC!$D$6:$D$201&ĐGVC!$E$6:$E$201),"")}

Sheet Sheet1
A1: IV/IM | B1: (All) | E1: Application | F1: (Multiple Items) | H1: Ngành hàng | I1: rHDPE thổi
A2: Application | B2: (Multiple Items) | H2: Phân loại sản phẩm | I2: (All)
E3: Row Labels | F3: Sum of SL-KH26
A4: Row Labels | B4: Sum of SL-KH26 | E4: rPET | F4: 46346.956 | H4: Row Labels | I4: Sum of SL-KH26
A5: rPET | B5: 46346.956 | E5: 0.70 ± 0.02 | F5: 6358.1562 | H5: THỔI CHAI | I5: 5844
A6: rHDPE thổi | B6: 6624 | E6: 0.78 ± 0.02 | F6: 19336.9 | H6: THỔI ỐNG | I6: 780
A7: Xơ sợi | B7: 1039.0438 | E7: 0.80 ± 0.02 | F7: 10794.9 | H7: Grand Total | I7: 6624
A8: rPP | B8: 858 | E8: 0.84 ± 0.03 | F8: 9857
A9: Phó sản | B9: 132 | E9: Xơ sợi | F9: 1039.0438
A10: rHDPE ép | B10: 0 | E10: 0.55 ± 0.05 | F10: 1039.0438
A11: Grand Total | B11: 55000 | E11: 0.65 ± 0.03 | F11: 0
E12: Grand Total | F12: 47386
E14: Application | F14: (Multiple Items)
E15: IV/IM | F15: 0.78 ± 0.02
E17: Row Labels | F17: Sum of SL-KH26
E18: rPET | F18: 19336.9
E19: Niagara Bottling, LLC | F19: 13200 | G19: =GETPIVOTDATA("SL-KH26",$E$17,"Parent Account","Niagara Bottling, LLC","Ngành hàng","rPET")/GETPIVOTDATA("SL-KH26",$E$17,"Ngành hàng","rPET") -> 0.68263269 | H19: =GETPIVOTDATA("SL-KH26",$E$17,"Parent Account","Niagara Bottling, LLC","Ngành hàng","rPET")/GETPIVOTDATA("SL-KH26",$E$3) -> 0.27856329
E20: Unilever | F20: 3300
E21: Lavie | F21: 1320
E22: Plascene, Inc. | F22: 482.9
E23: Plascene | F23: 286
E24: PIA | F24: 264
E25: DTP | F25: 132
E26: Tân Lập Thành | F26: 132
E27: TRICON | F27: 132
E28: ĐÔ THÀNH | F28: 77
E29: AN NHẬT | F29: 11
E30: Muji- DTP | F30: 0
E31: Nhựa Âu Lạc | F31: 0
... E33: Grand Total | F33: 19336.9

Sheet KH 2026_OPT6
H1: -7200 | W1: 0.9 | AP1: 1203 | AQ1: 1184 | AR1: 1165 | AS1: 1146 | AT1: 1127 | AU1: 1108 | AV1: 1089 | AW1: 1070 | AX1: 1051 | BP1: =BP2*EXR -> 373028177500000
W2: =SUBTOTAL(9,KH_26_OPT4_KTQT_v4[SL-01]) -> 0 | X2: =SUBTOTAL(9,KH_26_OPT4_KTQT_v4[SL-02]) -> 0 | Y2: =SUBTOTAL(9,KH_26_OPT4_KTQT_v4[SL-03]) -> 44 | Z2: =SUBTOTAL(9,KH_26_OPT4_KTQT_v4[SL-04]) -> 44 | AA2: =SUBTOTAL(9,KH_26_OPT4_KTQT_v4[SL-05]) -> 88 | AB2: =SUBTOTAL(9,KH_26_OPT4_KTQT_v4[SL-06]) -> 44 | AC2: =SUBTOTAL(9,KH_26_OPT4_KTQT_v4[SL-07]) -> 64.9 | AD2: =SUBTOTAL(9,KH_26_OPT4_KTQT_v4[SL-08]) -> 66 | AE2: =SUBTOTAL(9,KH_26_OPT4_KTQT_v4[SL-09]) -> 0 | AF2: =SUBTOTAL(9,KH_26_OPT4_KTQT_v4[SL-10]) -> 0 | AG2: =SUBTOTAL(9,KH_26_OPT4_KTQT_v4[SL-11]) -> 66 | AH2: =SUBTOTAL(9,KH_26_OPT4_KTQT_v4[SL-12]) -> 66 | AI2: =SUBTOTAL(9,KH_26_OPT4_KTQT_v4[SL-KH26]) -> 482.9 | AJ2: =SUBTOTAL(9,KH_26_OPT4_KTQT_v4[SL-DB25]) -> 482.9 | AK2: =AI2-AJ2 -> 0 | BP2: =SUBTOTAL(9,KH_26_OPT4_KTQT_v4[DT-EXW-KH26]) -> 14076535000 | BQ2: =SUBTOTAL(9,KH_26_OPT4_KTQT_v4[DT-EXW-DB25]) -> 1.1150621e+10 | BR2: =BP2-BQ2 -> 2.9259135e+09 | BW2: =SUBTOTAL(9,KH_26_OPT4_KTQT_v4[CPHH-01]) -> 0 | BX2: =SUBTOTAL(9,KH_26_OPT4_KTQT_v4[CPHH-02]) -> 0 | BY2: =SUBTOTAL(9,KH_26_OPT4_KTQT_v4[CPHH-03]) -> 0 | BZ2: =SUBTOTAL(9,KH_26_OPT4_KTQT_v4[CPHH-04]) -> 0 | CA2: =SUBTOTAL(9,KH_26_OPT4_KTQT_v4[CPHH-05]) -> 0 | CB2: =SUBTOTAL(9,KH_26_OPT4_KTQT_v4[CPHH-06]) -> 0 | CC2: =SUBTOTAL(9,KH_26_OPT4_KTQT_v4[CPHH-07]) -> 0 | CD2: =SUBTOTAL(9,KH_26_OPT4_KTQT_v4[CPHH-08]) -> 0 | CE2: =SUBTOTAL(9,KH_26_OPT4_KTQT_v4[CPHH-09]) -> 0 | CF2: =SUBTOTAL(9,KH_26_OPT4_KTQT_v4[CPHH-10]) -> 0 | CG2: =SUBTOTAL(9,KH_26_OPT4_KTQT_v4[CPHH-11]) -> 0 | CH2: =SUBTOTAL(9,KH_26_OPT4_KTQT_v4[CPHH-12]) -> 0 | CI2: =SUBTOTAL(9,KH_26_OPT4_KTQT_v4[CPHH-KH26]) -> 0 | CJ2: Kinh doanh không cần quan tâm | CK2: Kinh doanh không cần quan tâm | CL2: Kinh doanh không cần quan tâm | CM2: Kinh doanh không cần quan tâm | CN2: =SUBTOTAL(9,KH_26_OPT4_KTQT_v4[CPVC-01]) -> 0 | CO2: =SUBTOTAL(9,KH_26_OPT4_KTQT_v4[CPVC-02]) -> 0 | CP2: =SUBTOTAL(9,KH_26_OPT4_KTQT_v4[CPVC-03]) -> 23320000 | CQ2: =SUBTOTAL(9,KH_26_OPT4_KTQT_v4[CPVC-04]) -> 23320000 | CR2: =SUBTOTAL(9,KH_26_OPT4_KTQT_v4[CPVC-05]) -> 46640000 | CS2: =SUBTOTAL(9,KH_26_OPT4_KTQT_v4[CPVC-06]) -> 23320000 | CT2: =SUBTOTAL(9,KH_26_OPT4_KTQT_v4[CPVC-07]) -> 34397000 | CU2: =SUBTOTAL(9,KH_26_OPT4_KTQT_v4[CPVC-08]) -> 34980000 | CV2: =SUBTOTAL(9,KH_26_OPT4_KTQT_v4[CPVC-09]) -> 0 | CW2: =SUBTOTAL(9,KH_26_OPT4_KTQT_v4[CPVC-10]) -> 0 | CX2: =SUBTOTAL(9,KH_26_OPT4_KTQT_v4[CPVC-11]) -> 34980000 | CY2: =SUBTOTAL(9,KH_26_OPT4_KTQT_v4[CPVC-12]) -> 34980000 | CZ2: =SUBTOTAL(9,KH_26_OPT4_KTQT_v4[CPVC-KH26]) -> 255937000 | DA2: Kinh doanh không cần quan tâm | DB2: Kinh doanh không cần quan tâm | DC2: Kinh doanh không cần quan tâm | DD2: Kinh doanh không cần quan tâm | DE2: Kinh doanh không cần quan tâm | DF2: Kinh doanh không cần quan tâm | DG2: Kinh doanh không cần quan tâm | DH2: Kinh doanh không cần quan tâm | DI2: Kinh doanh không cần quan tâm | DJ2: Kinh doanh không cần quan tâm | DK2: Kinh doanh không cần quan tâm | DL2: Kinh doanh không cần quan tâm | DM2: =SUBTOTAL(9,KH_26_OPT4_KTQT_v4[DT-KH26]) -> 14332472000 | DN2: Kinh doanh không cần quan tâm | DO2: Kinh doanh không cần quan tâm | DP2: Kinh doanh không cần quan tâm | DR2: =SUBTOTAL(9,DR6:DR1048576) -> 0 | DS2: =SUBTOTAL(9,DS6:DS1048576) -> 0 | DT2: =SUBTOTAL(9,DT6:DT1048576) -> 0 | DU2: =SUBTOTAL(9,DU6:DU1048576) -> 0 | DV2: =SUBTOTAL(9,DV6:DV1048576) -> 0 | DW2: =SUBTOTAL(9,DW6:DW1048576) -> 0 | DX2: =SUBTOTAL(9,DX6:DX1048576) -> 0 | DY2: =SUBTOTAL(9,DY6:DY1048576) -> 0 | ... EC2: =SUBTOTAL(9,EC6:EC1048576) -> 0 | ED2: =SUBTOTAL(9,KH_26_OPT4_KTQT_v4[CPDP-KH26]) -> 0
A3: STT | B3: Salesman | C3: Sales Manager | D3: Mã khách | E3: Parent Account | F3: Tên khách-Rút gọn | G3: Phân loại khách | H3: Kênh bán hàng | I3: Địa điểm đến | J3: Nước đến | K3: Khu vực | L3: Incoterm | M3: Mã sản phẩm | N3: Tên sản phẩm-Rút gọn | O3: Ngành hàng | P3: Nhóm sản phẩm | Q3: IV/IM | R3: Application | S3: Phân loại sản phẩm | T3: Phân loại KH | V3: Mức độ khả thi | W3: SỐ LƯỢNG BÁN - 2026 (tấn) | AI3: KH 2026 | AJ3: DB 2025 | AK3: +/- | AL3: %+/- | AM3: GIÁ BÁN EXW - 2026 (USD/tấn) - CHƯA LOẠI TRỪ EPR | AY3: KH 2026 | AZ3: DB 2025 | BA3: +/- | BB3: %+/- | BD3: DOANH THU EXW (VND) | BP3: KH 2026 | BQ3: DB 2025 | BR3: +/- | BS3: %+/- | BT3: CHI PHÍ HOA HỒNG | CI3: KH 26 | CJ3: ĐƠN GIÁ VC KÊNH NỘI ĐỊA | CK3: ĐƠN GIÁ VC KÊNH XUẤT KHẨU | CL3: ĐƠN GIÁ VC NỘI ĐỊA- KÊNH XUẤT KHẨU | CM3: CƯỚC TÀU | CN3: CHI PHÍ VẬN CHUYỂN | CZ3: KH 2026 | DA3: DOANH THU KẾ TOÁN (VND) | DM3: KH 2026 | DN3: DB 2025 | DO3: +/- | DP3: %+/- | DQ3: CHI PHÍ DỰ PHÒNG | ED3: KH 2026
T4: Price scheme | W4: SL-01 | X4: SL-02 | Y4: SL-03 | Z4: SL-04 | AA4: SL-05 | AB4: SL-06 | AC4: SL-07 | AD4: SL-08 | AE4: SL-09 | AF4: SL-10 | AG4: SL-11 | AH4: SL-12 | AM4: GB-01 | AN4: GB-02 | AO4: GB-03 | AP4: GB-04 | AQ4: GB-05 | AR4: GB-06 | AS4: GB-07 | AT4: GB-08 | AU4: GB-09 | AV4: GB-10 | AW4: GB-11 | AX4: GB-12 | BD4: DT-EXW-01 | BE4: DT-EXW-02 | BF4: DT-EXW-03 | BG4: DT-EXW-04 | BH4: DT-EXW-05 | BI4: DT-EXW-06 | BJ4: DT-EXW-07 | BK4: DT-EXW-08 | BL4: DT-EXW-09 | BM4: DT-EXW-10 | BN4: DT-EXW-11 | BO4: DT-EXW-12 | BT4: %CPHH | BU4: %CPHH | BV4: CPHH-SL | BW4: CPHH-01 | BX4: CPHH-02 | BY4: CPHH-03 | BZ4: CPHH-04 | CA4: CPHH-05 | CB4: CPHH-06 | CC4: CPHH-07 | CD4: CPHH-08 | CE4: CPHH-09 | CF4: CPHH-10 | CG4: CPHH-11 | CH4: CPHH-12 | CN4: CPVC-01 | CO4: CPVC-02 | CP4: CPVC-03 | CQ4: CPVC-04 | CR4: CPVC-05 | CS4: CPVC-06 | CT4: CPVC-07 | CU4: CPVC-08 | CV4: CPVC-09 | CW4: CPVC-10 | CX4: CPVC-11 | CY4: CPVC-12 | DA4: DT-01 | DB4: DT-02 | DC4: DT-03 | DD4: DT-04 | DE4: DT-05 | DF4: DT-06 | DG4: DT-07 | DH4: DT-08 | DI4: DT-09 | DJ4: DT-10 | DK4: DT-11 | DL4: DT-12 | DQ4: %DP | DR4: CPDP-01 | DS4: CPDP-02 | DT4: CPDP-03 | DU4: CPDP-04 | DV4: CPDP-05 | DW4: CPDP-06 | DX4: CPDP-07 | DY4: CPDP-08 | DZ4: CPDP-09 | EA4: CPDP-10 | EB4: CPDP-11 | EC4: CPDP-12
A5: STT | B5: Salesman | C5: SalesManager | D5: Mã khách | E5: Parent Account | F5: Tên khách | G5: Phân loại khách | H5: Kênh bán hàng | I5: Địa điểm đến | J5: Nước đến | K5: Khu vực | L5: Incoterm | M5: Mã sản phẩm | N5: Tên sản phẩm | O5: Ngành hàng | P5: Nhóm sản phẩm | Q5: IV/IM | R5: Application | S5: Phân loại sản phẩm | T5: Price_Sheme | U5: Lấy | V5: Mức độ khả thi | W5: SL-01 | X5: SL-02 | Y5: SL-03 | Z5: SL-04 | AA5: SL-05 | AB5: SL-06 | AC5: SL-07 | AD5: SL-08 | AE5: SL-09 | AF5: SL-10 | AG5: SL-11 | AH5: SL-12 | AI5: SL-KH26 | AJ5: SL-DB25 | AK5: SL-+/- | AL5: SL-%+/- | AM5: GB-01 | AN5: GB-02 | AO5: GB-03 | AP5: GB-04 | AQ5: GB-05 | AR5: GB-06 | AS5: GB-07 | AT5: GB-08 | AU5: GB-09 | AV5: GB-10 | AW5: GB-11 | AX5: GB-12 | AY5: GB-DB25 | AZ5: GB-KH25 | BA5: GB-+/- | BB5: GB-%+/- | BC5: Ghi chú | BD5: DT-EXW-01 | BE5: DT-EXW-02 | BF5: DT-EXW-03 | BG5: DT-EXW-04 | BH5: DT-EXW-05 | BI5: DT-EXW-06 | BJ5: DT-EXW-07 | BK5: DT-EXW-08 | BL5: DT-EXW-09 | BM5: DT-EXW-10 | BN5: DT-EXW-11 | BO5: DT-EXW-12 | BP5: DT-EXW-KH26 | BQ5: DT-EXW-DB25 | BR5: DT-EXW-+/- | BS5: DT-EXW-%+/- | BT5: CPHH-%-SL | BU5: %HH | BV5: HH-SL | BW5: CPHH-01 | BX5: CPHH-02 | BY5: CPHH-03 | BZ5: CPHH-04 | CA5: CPHH-05 | CB5: CPHH-06 | CC5: CPHH-07 | CD5: CPHH-08 | CE5: CPHH-09 | CF5: CPHH-10 | CG5: CPHH-11 | CH5: CPHH-12 | CI5: CPHH-KH26 | CJ5: ĐGVC-KNĐ | CK5: ĐGVC-KXK | CL5: ĐGVCNĐ-KXK | CM5: ĐGVCCT-KXK | CN5: CPVC-01 | CO5: CPVC-02 | CP5: CPVC-03 | CQ5: CPVC-04 | CR5: CPVC-05 | CS5: CPVC-06 | CT5: CPVC-07 | CU5: CPVC-08 | CV5: CPVC-09 | CW5: CPVC-10 | CX5: CPVC-11 | CY5: CPVC-12 | CZ5: CPVC-KH26 | DA5: DT-01 | DB5: DT-02 | DC5: DT-03 | DD5: DT-04 | DE5: DT-05 | DF5: DT-06 | DG5: DT-07 | DH5: DT-08 | DI5: DT-09 | DJ5: DT-10 | DK5: DT-11 | DL5: DT-12 | DM5: DT-KH26 | DN5: DT-DB25 | DO5: DT-+/- | DP5: DT-%+/- | DQ5: %CPDP | DR5: CPDP-01 | DS5: CPDP-02 | DT5: CPDP-03 | DU5: CPDP-04 | DV5: CPDP-05 | DW5: CPDP-06 | DX5: CPDP-07 | DY5: CPDP-08 | DZ5: CPDP-09 | EA5: CPDP-10 | EB5: CPDP-11 | EC5: CPDP-12 | ED5: CPDP-KH26
A6: 1 | B6: Quốc Anh | C6: =IFERROR(_xlfn.XLOOKUP(KH_26_OPT4_KTQT_v4[[#This Row],[Salesman]],MD_Salesman[Salesman],MD_Salesman[SalesManager]),"") -> Quốc Anh | D6: =IFERROR(INDEX(MD_Customer[Mã khách],MATCH(KH_26_OPT4_KTQT_v4[[#This Row],[Tên khách]],MD_Customer[Tên khách-rút gọn],0)),"") -> 200319 | E6: =IFERROR(INDEX(MD_Customer[Parent Account],MATCH(KH_26_OPT4_KTQT_v4[[#This Row],[Tên khách]],MD_Customer[Tên khách-rút gọn],0)),"") -> Niagara Bottling, LLC | F6: Niagara Bottling, LLC | G6: =IFERROR(INDEX(MD_Customer[Phân loại],MATCH(KH_26_OPT4_KTQT_v4[[#This Row],[Tên khách]],MD_Customer[Tên khách-rút gọn],0)),"") -> Hiện hữu | H6: =IFERROR(INDEX(MD_Customer[Kênh bán hàng],MATCH(KH_26_OPT4_KTQT_v4[[#This Row],[Tên khách]],MD_Customer[Tên khách-rút gọn],0)),"") -> Xuất khẩu | I6: Mỹ | J6: =IFERROR(INDEX(MD_Destination[Nước],MATCH(KH_26_OPT4_KTQT_v4[[#This Row],[Địa điểm đến]],MD_Destination[Địa điểm đến],0)),"") -> Mỹ | K6: =IFERROR(INDEX(MD_Destination[Khu vực],MATCH(KH_26_OPT4_KTQT_v4[[#This Row],[Địa điểm đến]],MD_Destination[Địa điểm đến],0)),"") -> Châu Mỹ | L6: FOB | M6: =IFERROR(INDEX(MD_SKU[Mã SKU],MATCH(KH_26_OPT4_KTQT_v4[[#This Row],[Tên sản phẩm]],MD_SKU[Tên SKU-rút gọn],0)),"") -> 110000354 | N6: WSS01G 1 | O6: =IFERROR(INDEX(MD_SKU[Ngành hàng],MATCH(KH_26_OPT4_KTQT_v4[[#This Row],[Tên sản phẩm]],MD_SKU[Tên SKU-rút gọn],0)),"") -> rPET | P6: =IFERROR(INDEX(MD_SKU[Nhóm ngành],MATCH(KH_26_OPT4_KTQT_v4[[#This Row],[Tên sản phẩm]],MD_SKU[Tên SKU-rút gọn],0)),"") -> Hạt PET | Q6: =IFERROR( IF(INDEX(MD_SKU[IV/IM],MATCH(KH_26_OPT4_KTQT_v4[[#This Row],[Tên sản phẩm]],MD_SKU[Tên SKU-rút gọn],0))=0, "", INDEX(MD_SKU[IV/IM],MATCH(KH_26_OPT4_KTQT_v4[[#This Row],[Tên sản phẩm]],MD_SKU[Tên SKU-rút gọn],0)) ), "") -> 0.78 ± 0.02 | R6: =IFERROR(INDEX(MD_SKU[Application],MATCH(KH_26_OPT4_KTQT_v4[[#This Row],[Tên sản phẩm]],MD_SKU[Tên SKU-rút gọn],0)),"") -> 0 | S6: =IFERROR(INDEX(MD_SKU[Phân loại],MATCH(KH_26_OPT4_KTQT_v4[[#This Row],[Tên sản phẩm]],MD_SKU[Tên SKU-rút gọn],0)),"") -> Cũ | T6: Niagara Bottling, LLC | U6: x | V6: 0.8 | W6: 660 | X6: 660 | Y6: 660 | Z6: 660 | AA6: 660 | AB6: 660 | AC6: 660 | AD6: 660 | AE6: 660 | AF6: 660 | AG6: 660 | AH6: 660 | AI6: =SUM(KH_26_OPT4_KTQT_v4[[#This Row],[SL-01]:[SL-12]]) -> 7920 | AJ6: =SUMIFS(DB_25[SL-DB25],DB_25[Mã khách],KH_26_OPT4_KTQT_v4[[#This Row],[Mã khách]],DB_25[Mã sản phẩm],KH_26_OPT4_KTQT_v4[[#This Row],[Mã sản phẩm]]) -> 13002 | AK6: =KH_26_OPT4_KTQT_v4[[#This Row],[SL-KH26]]-KH_26_OPT4_KTQT_v4[[#This Row],[SL-DB25]] -> -5082 | AL6: =IFERROR(KH_26_OPT4_KTQT_v4[[#This Row],[SL-+/-]]/KH_26_OPT4_KTQT_v4[[#This Row],[SL-DB25]],0) -> -0.39086294 | AM6: 1044 | AN6: 1044 | AO6: 1044 | AP6: 1044 | AQ6: 1044 | AR6: 1044 | AS6: 1044 | AT6: 1044 | AU6: 1044 | AV6: 1044 | AW6: 1044 | AX6: 1044 | AY6: 1080 | BA6: =KH_26_OPT4_KTQT_v4[[#This Row],[GB-DB25]]-KH_26_OPT4_KTQT_v4[[#This Row],[GB-KH25]] -> 1080 | BB6: =IFERROR(KH_26_OPT4_KTQT_v4[[#This Row],[GB-+/-]]/KH_26_OPT4_KTQT_v4[[#This Row],[GB-KH25]],0) -> 0 | BC6: Đã bao gồm chi phí hỗ trợ tối đa 10% (giá sau hỗ trợ là 1060) | BD6: =KH_26_OPT4_KTQT_v4[[#This Row],[SL-01]]*KH_26_OPT4_KTQT_v4[[#This Row],[GB-01]]*EXR -> 18259560000 | BE6: =KH_26_OPT4_KTQT_v4[[#This Row],[SL-02]]*KH_26_OPT4_KTQT_v4[[#This Row],[GB-02]]*EXR -> 18259560000 | BF6: =KH_26_OPT4_KTQT_v4[[#This Row],[SL-03]]*KH_26_OPT4_KTQT_v4[[#This Row],[GB-03]]*EXR -> 18259560000 | BG6: =KH_26_OPT4_KTQT_v4[[#This Row],[SL-04]]*KH_26_OPT4_KTQT_v4[[#This Row],[GB-04]]*EXR -> 18259560000 | BH6: =KH_26_OPT4_KTQT_v4[[#This Row],[SL-05]]*KH_26_OPT4_KTQT_v4[[#This Row],[GB-05]]*EXR -> 18259560000 | BI6: =KH_26_OPT4_KTQT_v4[[#This Row],[SL-06]]*KH_26_OPT4_KTQT_v4[[#This Row],[GB-06]]*EXR -> 18259560000 | BJ6: =KH_26_OPT4_KTQT_v4[[#This Row],[SL-07]]*KH_26_OPT4_KTQT_v4[[#This Row],[GB-07]]*EXR -> 18259560000 | BK6: =KH_26_OPT4_KTQT_v4[[#This Row],[SL-08]]*KH_26_OPT4_KTQT_v4[[#This Row],[GB-08]]*EXR -> 18259560000 | BL6: =KH_26_OPT4_KTQT_v4[[#This Row],[SL-09]]*KH_26_OPT4_KTQT_v4[[#This Row],[GB-09]]*EXR -> 18259560000 | BM6: =KH_26_OPT4_KTQT_v4[[#This Row],[SL-10]]*KH_26_OPT4_KTQT_v4[[#This Row],[GB-10]]*EXR -> 18259560000 | BN6: =KH_26_OPT4_KTQT_v4[[#This Row],[SL-11]]*KH_26_OPT4_KTQT_v4[[#This Row],[GB-11]]*EXR -> 18259560000 | BO6: =KH_26_OPT4_KTQT_v4[[#This Row],[SL-12]]*KH_26_OPT4_KTQT_v4[[#This Row],[GB-12]]*EXR -> 18259560000 | BP6: =SUM(KH_26_OPT4_KTQT_v4[[#This Row],[DT-EXW-01]:[DT-EXW-12]]) -> 219114720000 | BQ6: =SUMIFS(DB_25[DT-DB25],DB_25[Mã khách],KH_26_OPT4_KTQT_v4[[#This Row],[Mã khách]],DB_25[Mã sản phẩm],KH_26_OPT4_KTQT_v4[[#This Row],[Mã sản phẩm]]) -> 3.6959011e+11 | BR6: =KH_26_OPT4_KTQT_v4[[#This Row],[DT-EXW-KH26]]-KH_26_OPT4_KTQT_v4[[#This Row],[DT-EXW-DB25]] -> -1.5047539e+11 | BS6: =IFERROR(KH_26_OPT4_KTQT_v4[[#This Row],[DT-EXW-+/-]]/KH_26_OPT4_KTQT_v4[[#This Row],[DT-EXW-DB25]],0) -> -0.40714128 | BT6: Dthu | BU6: 0.015 | BW6: =IF(KH_26_OPT4_KTQT_v4[[#This Row],[CPHH-%-SL]]="Dthu",KH_26_OPT4_KTQT_v4[[#This Row],[%HH]]*KH_26_OPT4_KTQT_v4[[#This Row],[DT-EXW-01]],KH_26_OPT4_KTQT_v4[[#This Row],[HH-SL]]*KH_26_OPT4_KTQT_v4[[#This Row],[SL-01]]) -> 273893400 | BX6: =IF(KH_26_OPT4_KTQT_v4[[#This Row],[CPHH-%-SL]]="Dthu",KH_26_OPT4_KTQT_v4[[#This Row],[%HH]]*KH_26_OPT4_KTQT_v4[[#This Row],[DT-EXW-02]],KH_26_OPT4_KTQT_v4[[#This Row],[HH-SL]]*KH_26_OPT4_KTQT_v4[[#This Row],[SL-02]]) -> 273893400 | BY6: =IF(KH_26_OPT4_KTQT_v4[[#This Row],[CPHH-%-SL]]="Dthu",KH_26_OPT4_KTQT_v4[[#This Row],[%HH]]*KH_26_OPT4_KTQT_v4[[#This Row],[DT-EXW-03]],KH_26_OPT4_KTQT_v4[[#This Row],[HH-SL]]*KH_26_OPT4_KTQT_v4[[#This Row],[SL-03]]) -> 273893400 | BZ6: =IF(KH_26_OPT4_KTQT_v4[[#This Row],[CPHH-%-SL]]="Dthu",KH_26_OPT4_KTQT_v4[[#This Row],[%HH]]*KH_26_OPT4_KTQT_v4[[#This Row],[DT-EXW-04]],KH_26_OPT4_KTQT_v4[[#This Row],[HH-SL]]*KH_26_OPT4_KTQT_v4[[#This Row],[SL-04]]) -> 273893400 | CA6: =IF(KH_26_OPT4_KTQT_v4[[#This Row],[CPHH-%-SL]]="Dthu",KH_26_OPT4_KTQT_v4[[#This Row],[%HH]]*KH_26_OPT4_KTQT_v4[[#This Row],[DT-EXW-05]],KH_26_OPT4_KTQT_v4[[#This Row],[HH-SL]]*KH_26_OPT4_KTQT_v4[[#This Row],[SL-05]]) -> 273893400 | CB6: =IF(KH_26_OPT4_KTQT_v4[[#This Row],[CPHH-%-SL]]="Dthu",KH_26_OPT4_KTQT_v4[[#This Row],[%HH]]*KH_26_OPT4_KTQT_v4[[#This Row],[DT-EXW-06]],KH_26_OPT4_KTQT_v4[[#This Row],[HH-SL]]*KH_26_OPT4_KTQT_v4[[#This Row],[SL-06]]) -> 273893400 | CC6: =IF(KH_26_OPT4_KTQT_v4[[#This Row],[CPHH-%-SL]]="Dthu",KH_26_OPT4_KTQT_v4[[#This Row],[%HH]]*KH_26_OPT4_KTQT_v4[[#This Row],[DT-EXW-07]],KH_26_OPT4_KTQT_v4[[#This Row],[HH-SL]]*KH_26_OPT4_KTQT_v4[[#This Row],[SL-07]]) -> 273893400 | CD6: =IF(KH_26_OPT4_KTQT_v4[[#This Row],[CPHH-%-SL]]="Dthu",KH_26_OPT4_KTQT_v4[[#This Row],[%HH]]*KH_26_OPT4_KTQT_v4[[#This Row],[DT-EXW-08]],KH_26_OPT4_KTQT_v4[[#This Row],[HH-SL]]*KH_26_OPT4_KTQT_v4[[#This Row],[SL-08]]) -> 273893400 | CE6: =IF(KH_26_OPT4_KTQT_v4[[#This Row],[CPHH-%-SL]]="Dthu",KH_26_OPT4_KTQT_v4[[#This Row],[%HH]]*KH_26_OPT4_KTQT_v4[[#This Row],[DT-EXW-09]],KH_26_OPT4_KTQT_v4[[#This Row],[HH-SL]]*KH_26_OPT4_KTQT_v4[[#This Row],[SL-09]]) -> 273893400 | CF6: =IF(KH_26_OPT4_KTQT_v4[[#This Row],[CPHH-%-SL]]="Dthu",KH_26_OPT4_KTQT_v4[[#This Row],[%HH]]*KH_26_OPT4_KTQT_v4[[#This Row],[DT-EXW-10]],KH_26_OPT4_KTQT_v4[[#This Row],[HH-SL]]*KH_26_OPT4_KTQT_v4[[#This Row],[SL-10]]) -> 273893400 | CG6: =IF(KH_26_OPT4_KTQT_v4[[#This Row],[CPHH-%-SL]]="Dthu",KH_26_OPT4_KTQT_v4[[#This Row],[%HH]]*KH_26_OPT4_KTQT_v4[[#This Row],[DT-EXW-11]],KH_26_OPT4_KTQT_v4[[#This Row],[HH-SL]]*KH_26_OPT4_KTQT_v4[[#This Row],[SL-11]]) -> 273893400 | CH6: =IF(KH_26_OPT4_KTQT_v4[[#This Row],[CPHH-%-SL]]="Dthu",KH_26_OPT4_KTQT_v4[[#This Row],[%HH]]*KH_26_OPT4_KTQT_v4[[#This Row],[DT-EXW-12]],KH_26_OPT4_KTQT_v4[[#This Row],[HH-SL]]*KH_26_OPT4_KTQT_v4[[#This Row],[SL-12]]) -> 273893400 | CI6: =SUM(KH_26_OPT4_KTQT_v4[[#This Row],[CPHH-01]:[CPHH-12]]) -> 3286720800 | CJ6: {=IFERROR(IF(KH_26_OPT4_KTQT_v4[[#This Row],[Kênh bán hàng]]="Nội địa",_xlfn.XLOOKUP(KH_26_OPT4_KTQT_v4[[#This Row],[Tên khách]]&KH_26_OPT4_KTQT_v4[[#This Row],[Kênh bán hàng]]&KH_26_OPT4_KTQT_v4[[#This Row],[Địa điểm đến]]&KH_26_OPT4_KTQT_v4[[#This Row],[Nước đến]]&KH_26_OPT4_KTQT_v4[[#This Row],[Incoterm]],ĐGVC!$A$6:$A$201&ĐGVC!$B$6:$B$201&ĐGVC!$C$6:$C$201&ĐGVC!$D$6:$D$201&ĐGVC!$E$6:$E$201,ĐGVC!$O$6:$O$201),0),0)} -> 0 | CK6: =SUM(KH_26_OPT4_KTQT_v4[[#This Row],[ĐGVCNĐ-KXK]:[ĐGVCCT-KXK]]) -> 530000 | CL6: {=IFERROR(IF(KH_26_OPT4_KTQT_v4[[#This Row],[Kênh bán hàng]]="xuất khẩu",_xlfn.XLOOKUP(KH_26_OPT4_KTQT_v4[[#This Row],[Tên khách]]&KH_26_OPT4_KTQT_v4[[#This Row],[Kênh bán hàng]]&KH_26_OPT4_KTQT_v4[[#This Row],[Địa điểm đến]]&KH_26_OPT4_KTQT_v4[[#This Row],[Nước đến]]&KH_26_OPT4_KTQT_v4[[#This Row],[Incoterm]],ĐGVC!$A$6:$A$201&ĐGVC!$B$6:$B$201&ĐGVC!$C$6:$C$201&ĐGVC!$D$6:$D$201&ĐGVC!$E$6:$E$201,ĐGVC!$O$6:$O$201),0),0)} -> 530000 | CM6: {=IFERROR(_xlfn.XLOOKUP(KH_26_OPT4_KTQT_v4[[#This Row],[Tên khách]]&KH_26_OPT4_KTQT_v4[[#This Row],[Kênh bán hàng]]&KH_26_OPT4_KTQT_v4[[#This Row],[Địa điểm đến]]&KH_26_OPT4_KTQT_v4[[#This Row],[Nước đến]]&KH_26_OPT4_KTQT_v4[[#This Row],[Incoterm]],ĐGVC!$A$6:$A$201&ĐGVC!$B$6:$B$201&ĐGVC!$C$6:$C$201&ĐGVC!$D$6:$D$201&ĐGVC!$E$6:$E$201,ĐGVC!$Y$6:$Y$201),0)} -> 0 | CN6: =(KH_26_OPT4_KTQT_v4[[#This Row],[ĐGVC-KNĐ]]+KH_26_OPT4_KTQT_v4[[#This Row],[ĐGVC-KXK]])*KH_26_OPT4_KTQT_v4[[#This Row],[SL-01]] -> 349800000 | CO6: =(KH_26_OPT4_KTQT_v4[[#This Row],[ĐGVC-KNĐ]]+KH_26_OPT4_KTQT_v4[[#This Row],[ĐGVC-KXK]])*KH_26_OPT4_KTQT_v4[[#This Row],[SL-02]] -> 349800000 | CP6: =(KH_26_OPT4_KTQT_v4[[#This Row],[ĐGVC-KNĐ]]+KH_26_OPT4_KTQT_v4[[#This Row],[ĐGVC-KXK]])*KH_26_OPT4_KTQT_v4[[#This Row],[SL-03]] -> 349800000 | CQ6: =(KH_26_OPT4_KTQT_v4[[#This Row],[ĐGVC-KNĐ]]+KH_26_OPT4_KTQT_v4[[#This Row],[ĐGVC-KXK]])*KH_26_OPT4_KTQT_v4[[#This Row],[SL-04]] -> 349800000 | CR6: =(KH_26_OPT4_KTQT_v4[[#This Row],[ĐGVC-KNĐ]]+KH_26_OPT4_KTQT_v4[[#This Row],[ĐGVC-KXK]])*KH_26_OPT4_KTQT_v4[[#This Row],[SL-05]] -> 349800000 | CS6: =(KH_26_OPT4_KTQT_v4[[#This Row],[ĐGVC-KNĐ]]+KH_26_OPT4_KTQT_v4[[#This Row],[ĐGVC-KXK]])*KH_26_OPT4_KTQT_v4[[#This Row],[SL-06]] -> 349800000 | CT6: =(KH_26_OPT4_KTQT_v4[[#This Row],[ĐGVC-KNĐ]]+KH_26_OPT4_KTQT_v4[[#This Row],[ĐGVC-KXK]])*KH_26_OPT4_KTQT_v4[[#This Row],[SL-07]] -> 349800000 | CU6: =(KH_26_OPT4_KTQT_v4[[#This Row],[ĐGVC-KNĐ]]+KH_26_OPT4_KTQT_v4[[#This Row],[ĐGVC-KXK]])*KH_26_OPT4_KTQT_v4[[#This Row],[SL-08]] -> 349800000 | CV6: =(KH_26_OPT4_KTQT_v4[[#This Row],[ĐGVC-KNĐ]]+KH_26_OPT4_KTQT_v4[[#This Row],[ĐGVC-KXK]])*KH_26_OPT4_KTQT_v4[[#This Row],[SL-09]] -> 349800000 | CW6: =(KH_26_OPT4_KTQT_v4[[#This Row],[ĐGVC-KNĐ]]+KH_26_OPT4_KTQT_v4[[#This Row],[ĐGVC-KXK]])*KH_26_OPT4_KTQT_v4[[#This Row],[SL-10]] -> 349800000 | CX6: =(KH_26_OPT4_KTQT_v4[[#This Row],[ĐGVC-KNĐ]]+KH_26_OPT4_KTQT_v4[[#This Row],[ĐGVC-KXK]])*KH_26_OPT4_KTQT_v4[[#This Row],[SL-11]] -> 349800000 | CY6: =(KH_26_OPT4_KTQT_v4[[#This Row],[ĐGVC-KNĐ]]+KH_26_OPT4_KTQT_v4[[#This Row],[ĐGVC-KXK]])*KH_26_OPT4_KTQT_v4[[#This Row],[SL-12]] -> 349800000 | CZ6: =SUM(KH_26_OPT4_KTQT_v4[[#This Row],[CPVC-01]:[CPVC-12]]) -> 4197600000 | DA6: =KH_26_OPT4_KTQT_v4[[#This Row],[DT-EXW-01]]+KH_26_OPT4_KTQT_v4[[#This Row],[CPVC-01]]+KH_26_OPT4_KTQT_v4[[#This Row],[CPHH-01]] -> 18883253400 | DB6: =KH_26_OPT4_KTQT_v4[[#This Row],[DT-EXW-02]]+KH_26_OPT4_KTQT_v4[[#This Row],[CPVC-02]]+KH_26_OPT4_KTQT_v4[[#This Row],[CPHH-02]] -> 18883253400 | DC6: =KH_26_OPT4_KTQT_v4[[#This Row],[DT-EXW-03]]+KH_26_OPT4_KTQT_v4[[#This Row],[CPVC-03]]+KH_26_OPT4_KTQT_v4[[#This Row],[CPHH-03]] -> 18883253400 | DD6: =KH_26_OPT4_KTQT_v4[[#This Row],[DT-EXW-04]]+KH_26_OPT4_KTQT_v4[[#This Row],[CPVC-04]]+KH_26_OPT4_KTQT_v4[[#This Row],[CPHH-04]] -> 18883253400 | DE6: =KH_26_OPT4_KTQT_v4[[#This Row],[DT-EXW-05]]+KH_26_OPT4_KTQT_v4[[#This Row],[CPVC-05]]+KH_26_OPT4_KTQT_v4[[#This Row],[CPHH-05]] -> 18883253400 | DF6: =KH_26_OPT4_KTQT_v4[[#This Row],[DT-EXW-06]]+KH_26_OPT4_KTQT_v4[[#This Row],[CPVC-06]]+KH_26_OPT4_KTQT_v4[[#This Row],[CPHH-06]] -> 18883253400 | DG6: =KH_26_OPT4_KTQT_v4[[#This Row],[DT-EXW-07]]+KH_26_OPT4_KTQT_v4[[#This Row],[CPVC-07]]+KH_26_OPT4_KTQT_v4[[#This Row],[CPHH-07]] -> 18883253400 | DH6: =KH_26_OPT4_KTQT_v4[[#This Row],[DT-EXW-08]]+KH_26_OPT4_KTQT_v4[[#This Row],[CPVC-08]]+KH_26_OPT4_KTQT_v4[[#This Row],[CPHH-08]] -> 18883253400 | DI6: =KH_26_OPT4_KTQT_v4[[#This Row],[DT-EXW-09]]+KH_26_OPT4_KTQT_v4[[#This Row],[CPVC-09]]+KH_26_OPT4_KTQT_v4[[#This Row],[CPHH-09]] -> 18883253400 | DJ6: =KH_26_OPT4_KTQT_v4[[#This Row],[DT-EXW-10]]+KH_26_OPT4_KTQT_v4[[#This Row],[CPVC-10]]+KH_26_OPT4_KTQT_v4[[#This Row],[CPHH-10]] -> 18883253400 | DK6: =KH_26_OPT4_KTQT_v4[[#This Row],[DT-EXW-11]]+KH_26_OPT4_KTQT_v4[[#This Row],[CPVC-11]]+KH_26_OPT4_KTQT_v4[[#This Row],[CPHH-11]] -> 18883253400 | DL6: =KH_26_OPT4_KTQT_v4[[#This Row],[DT-EXW-12]]+KH_26_OPT4_KTQT_v4[[#This Row],[CPVC-12]]+KH_26_OPT4_KTQT_v4[[#This Row],[CPHH-12]] -> 18883253400 | DM6: =SUM(KH_26_OPT4_KTQT_v4[[#This Row],[DT-01]:[DT-12]]) -> 226599040800 | DR6: =IFERROR(KH_26_OPT4_KTQT_v4[[#This Row],[DT-EXW-01]]*KH_26_OPT4_KTQT_v4[[#This Row],[%CPDP]],0) -> 0 | DS6: =IFERROR(KH_26_OPT4_KTQT_v4[[#This Row],[DT-EXW-02]]*KH_26_OPT4_KTQT_v4[[#This Row],[%CPDP]],0) -> 0 | DT6: =IFERROR(KH_26_OPT4_KTQT_v4[[#This Row],[DT-EXW-03]]*KH_26_OPT4_KTQT_v4[[#This Row],[%CPDP]],0) -> 0 | DU6: =IFERROR(KH_26_OPT4_KTQT_v4[[#This Row],[DT-EXW-04]]*KH_26_OPT4_KTQT_v4[[#This Row],[%CPDP]],0) -> 0 | DV6: =IFERROR(KH_26_OPT4_KTQT_v4[[#This Row],[DT-EXW-05]]*KH_26_OPT4_KTQT_v4[[#This Row],[%CPDP]],0) -> 0 | DW6: =IFERROR(KH_26_OPT4_KTQT_v4[[#This Row],[DT-EXW-06]]*KH_26_OPT4_KTQT_v4[[#This Row],[%CPDP]],0) -> 0 | DX6: =IFERROR(KH_26_OPT4_KTQT_v4[[#This Row],[DT-EXW-07]]*KH_26_OPT4_KTQT_v4[[#This Row],[%CPDP]],0) -> 0 | DY6: =IFERROR(KH_26_OPT4_KTQT_v4[[#This Row],[DT-EXW-08]]*KH_26_OPT4_KTQT_v4[[#This Row],[%CPDP]],0) -> 0 | DZ6: =IFERROR(KH_26_OPT4_KTQT_v4[[#This Row],[DT-EXW-09]]*KH_26_OPT4_KTQT_v4[[#This Row],[%CPDP]],0) -> 0 | EA6: =IFERROR(KH_26_OPT4_KTQT_v4[[#This Row],[DT-EXW-10]]*KH_26_OPT4_KTQT_v4[[#This Row],[%CPDP]],0) -> 0 | EB6: =IFERROR(KH_26_OPT4_KTQT_v4[[#This Row],[DT-EXW-11]]*KH_26_OPT4_KTQT_v4[[#This Row],[%CPDP]],0) -> 0 | EC6: =IFERROR(KH_26_OPT4_KTQT_v4[[#This Row],[DT-EXW-12]]*KH_26_OPT4_KTQT_v4[[#This Row],[%CPDP]],0) -> 0 | ED6: =SUM(KH_26_OPT4_KTQT_v4[[#This Row],[CPDP-01]:[CPDP-12]]) -> 0
A7: 2 | B7: Quốc Anh | C7: =IFERROR(_xlfn.XLOOKUP(KH_26_OPT4_KTQT_v4[[#This Row],[Salesman]],MD_Salesman[Salesman],MD_Salesman[SalesManager]),"") -> Quốc Anh | D7: =IFERROR(INDEX(MD_Customer[Mã khách],MATCH(KH_26_OPT4_KTQT_v4[[#This Row],[Tên khách]],MD_Customer[Tên khách-rút gọn],0)),"") -> 200319 | E7: =IFERROR(INDEX(MD_Customer[Parent Account],MATCH(KH_26_OPT4_KTQT_v4[[#This Row],[Tên khách]],MD_Customer[Tên khách-rút gọn],0)),"") -> Niagara Bottling, LLC | F7: Niagara Bottling, LLC | G7: =IFERROR(INDEX(MD_Customer[Phân loại],MATCH(KH_26_OPT4_KTQT_v4[[#This Row],[Tên khách]],MD_Customer[Tên khách-rút gọn],0)),"") -> Hiện hữu | H7: =IFERROR(INDEX(MD_Customer[Kênh bán hàng],MATCH(KH_26_OPT4_KTQT_v4[[#This Row],[Tên khách]],MD_Customer[Tên khách-rút gọn],0)),"") -> Xuất khẩu | I7: Shepley | J7: =IFERROR(INDEX(MD_Destination[Nước],MATCH(KH_26_OPT4_KTQT_v4[[#This Row],[Địa điểm đến]],MD_Destination[Địa điểm đến],0)),"") -> UK | K7: =IFERROR(INDEX(MD_Destination[Khu vực],MATCH(KH_26_OPT4_KTQT_v4[[#This Row],[Địa điểm đến]],MD_Destination[Địa điểm đến],0)),"") -> Châu Âu | L7: FOB | M7: =IFERROR(INDEX(MD_SKU[Mã SKU],MATCH(KH_26_OPT4_KTQT_v4[[#This Row],[Tên sản phẩm]],MD_SKU[Tên SKU-rút gọn],0)),"") -> 110000354 | N7: WSS01G 1 | O7: =IFERROR(INDEX(MD_SKU[Ngành hàng],MATCH(KH_26_OPT4_KTQT_v4[[#This Row],[Tên sản phẩm]],MD_SKU[Tên SKU-rút gọn],0)),"") -> rPET | P7: =IFERROR(INDEX(MD_SKU[Nhóm ngành],MATCH(KH_26_OPT4_KTQT_v4[[#This Row],[Tên sản phẩm]],MD_SKU[Tên SKU-rút gọn],0)),"") -> Hạt PET | Q7: =IFERROR( IF(INDEX(MD_SKU[IV/IM],MATCH(KH_26_OPT4_KTQT_v4[[#This Row],[Tên sản phẩm]],MD_SKU[Tên SKU-rút gọn],0))=0, "", INDEX(MD_SKU[IV/IM],MATCH(KH_26_OPT4_KTQT_v4[[#This Row],[Tên sản phẩm]],MD_SKU[Tên SKU-rút gọn],0)) ), "") -> 0.78 ± 0.02 | R7: =IFERROR(INDEX(MD_SKU[Application],MATCH(KH_26_OPT4_KTQT_v4[[#This Row],[Tên sản phẩm]],MD_SKU[Tên SKU-rút gọn],0)),"") -> 0 | S7: =IFERROR(INDEX(MD_SKU[Phân loại],MATCH(KH_26_OPT4_KTQT_v4[[#This Row],[Tên sản phẩm]],MD_SKU[Tên SKU-rút gọn],0)),"") -> Cũ | T7: Niagara Bottling, LLC | U7: x | V7: 0.8 | W7: 440 | X7: 440 | Y7: 440 | Z7: 440 | AA7: 440 | AB7: 440 | AC7: 440 | AD7: 440 | AE7: 440 | AF7: 440 | AG7: 440 | AH7: 440 | AI7: =SUM(KH_26_OPT4_KTQT_v4[[#This Row],[SL-01]:[SL-12]]) -> 5280 | AJ7: =SUMIFS(DB_25[SL-DB25],DB_25[Mã khách],KH_26_OPT4_KTQT_v4[[#This Row],[Mã khách]],DB_25[Mã sản phẩm],KH_26_OPT4_KTQT_v4[[#This Row],[Mã sản phẩm]]) -> 13002 | AK7: =KH_26_OPT4_KTQT_v4[[#This Row],[SL-KH26]]-KH_26_OPT4_KTQT_v4[[#This Row],[SL-DB25]] -> -7722 | AL7: =IFERROR(KH_26_OPT4_KTQT_v4[[#This Row],[SL-+/-]]/KH_26_OPT4_KTQT_v4[[#This Row],[SL-DB25]],0) -> -0.59390863 | AM7: 1084 | AN7: 1084 | AO7: 1084 | AP7: 1084 | AQ7: 1084 | AR7: 1084 | AS7: 1084 | AT7: 1084 | AU7: 1084 | AV7: 1084 | AW7: 1084 | AX7: 1084 | AY7: 1150 | BA7: =KH_26_OPT4_KTQT_v4[[#This Row],[GB-DB25]]-KH_26_OPT4_KTQT_v4[[#This Row],[GB-KH25]] -> 1150 | BB7: =IFERROR(KH_26_OPT4_KTQT_v4[[#This Row],[GB-+/-]]/KH_26_OPT4_KTQT_v4[[#This Row],[GB-KH25]],0) -> 0 | BD7: =KH_26_OPT4_KTQT_v4[[#This Row],[SL-01]]*KH_26_OPT4_KTQT_v4[[#This Row],[GB-01]]*EXR -> 12639440000 | BE7: =KH_26_OPT4_KTQT_v4[[#This Row],[SL-02]]*KH_26_OPT4_KTQT_v4[[#This Row],[GB-02]]*EXR -> 12639440000 | BF7: =KH_26_OPT4_KTQT_v4[[#This Row],[SL-03]]*KH_26_OPT4_KTQT_v4[[#This Row],[GB-03]]*EXR -> 12639440000 | BG7: =KH_26_OPT4_KTQT_v4[[#This Row],[SL-04]]*KH_26_OPT4_KTQT_v4[[#This Row],[GB-04]]*EXR -> 12639440000 | BH7: =KH_26_OPT4_KTQT_v4[[#This Row],[SL-05]]*KH_26_OPT4_KTQT_v4[[#This Row],[GB-05]]*EXR -> 12639440000 | BI7: =KH_26_OPT4_KTQT_v4[[#This Row],[SL-06]]*KH_26_OPT4_KTQT_v4[[#This Row],[GB-06]]*EXR -> 12639440000 | BJ7: =KH_26_OPT4_KTQT_v4[[#This Row],[SL-07]]*KH_26_OPT4_KTQT_v4[[#This Row],[GB-07]]*EXR -> 12639440000 | BK7: =KH_26_OPT4_KTQT_v4[[#This Row],[SL-08]]*KH_26_OPT4_KTQT_v4[[#This Row],[GB-08]]*EXR -> 12639440000 | BL7: =KH_26_OPT4_KTQT_v4[[#This Row],[SL-09]]*KH_26_OPT4_KTQT_v4[[#This Row],[GB-09]]*EXR -> 12639440000 | BM7: =KH_26_OPT4_KTQT_v4[[#This Row],[SL-10]]*KH_26_OPT4_KTQT_v4[[#This Row],[GB-10]]*EXR -> 12639440000 | BN7: =KH_26_OPT4_KTQT_v4[[#This Row],[SL-11]]*KH_26_OPT4_KTQT_v4[[#This Row],[GB-11]]*EXR -> 12639440000 | BO7: =KH_26_OPT4_KTQT_v4[[#This Row],[SL-12]]*KH_26_OPT4_KTQT_v4[[#This Row],[GB-12]]*EXR -> 12639440000 | BP7: =SUM(KH_26_OPT4_KTQT_v4[[#This Row],[DT-EXW-01]:[DT-EXW-12]]) -> 151673280000 | BQ7: =SUMIFS(DB_25[DT-DB25],DB_25[Mã khách],KH_26_OPT4_KTQT_v4[[#This Row],[Mã khách]],DB_25[Mã sản phẩm],KH_26_OPT4_KTQT_v4[[#This Row],[Mã sản phẩm]]) -> 3.6959011e+11 | BR7: =KH_26_OPT4_KTQT_v4[[#This Row],[DT-EXW-KH26]]-KH_26_OPT4_KTQT_v4[[#This Row],[DT-EXW-DB25]] -> -2.1791683e+11 | BS7: =IFERROR(KH_26_OPT4_KTQT_v4[[#This Row],[DT-EXW-+/-]]/KH_26_OPT4_KTQT_v4[[#This Row],[DT-EXW-DB25]],0) -> -0.58961759 | BT7: Dthu | BU7: 0.015 | BW7: =IF(KH_26_OPT4_KTQT_v4[[#This Row],[CPHH-%-SL]]="Dthu",KH_26_OPT4_KTQT_v4[[#This Row],[%HH]]*KH_26_OPT4_KTQT_v4[[#This Row],[DT-EXW-01]],KH_26_OPT4_KTQT_v4[[#This Row],[HH-SL]]*KH_26_OPT4_KTQT_v4[[#This Row],[SL-01]]) -> 189591600 | BX7: =IF(KH_26_OPT4_KTQT_v4[[#This Row],[CPHH-%-SL]]="Dthu",KH_26_OPT4_KTQT_v4[[#This Row],[%HH]]*KH_26_OPT4_KTQT_v4[[#This Row],[DT-EXW-02]],KH_26_OPT4_KTQT_v4[[#This Row],[HH-SL]]*KH_26_OPT4_KTQT_v4[[#This Row],[SL-02]]) -> 189591600 | BY7: =IF(KH_26_OPT4_KTQT_v4[[#This Row],[CPHH-%-SL]]="Dthu",KH_26_OPT4_KTQT_v4[[#This Row],[%HH]]*KH_26_OPT4_KTQT_v4[[#This Row],[DT-EXW-03]],KH_26_OPT4_KTQT_v4[[#This Row],[HH-SL]]*KH_26_OPT4_KTQT_v4[[#This Row],[SL-03]]) -> 189591600 | BZ7: =IF(KH_26_OPT4_KTQT_v4[[#This Row],[CPHH-%-SL]]="Dthu",KH_26_OPT4_KTQT_v4[[#This Row],[%HH]]*KH_26_OPT4_KTQT_v4[[#This Row],[DT-EXW-04]],KH_26_OPT4_KTQT_v4[[#This Row],[HH-SL]]*KH_26_OPT4_KTQT_v4[[#This Row],[SL-04]]) -> 189591600 | CA7: =IF(KH_26_OPT4_KTQT_v4[[#This Row],[CPHH-%-SL]]="Dthu",KH_26_OPT4_KTQT_v4[[#This Row],[%HH]]*KH_26_OPT4_KTQT_v4[[#This Row],[DT-EXW-05]],KH_26_OPT4_KTQT_v4[[#This Row],[HH-SL]]*KH_26_OPT4_KTQT_v4[[#This Row],[SL-05]]) -> 189591600 | CB7: =IF(KH_26_OPT4_KTQT_v4[[#This Row],[CPHH-%-SL]]="Dthu",KH_26_OPT4_KTQT_v4[[#This Row],[%HH]]*KH_26_OPT4_KTQT_v4[[#This Row],[DT-EXW-06]],KH_26_OPT4_KTQT_v4[[#This Row],[HH-SL]]*KH_26_OPT4_KTQT_v4[[#This Row],[SL-06]]) -> 189591600 | CC7: =IF(KH_26_OPT4_KTQT_v4[[#This Row],[CPHH-%-SL]]="Dthu",KH_26_OPT4_KTQT_v4[[#This Row],[%HH]]*KH_26_OPT4_KTQT_v4[[#This Row],[DT-EXW-07]],KH_26_OPT4_KTQT_v4[[#This Row],[HH-SL]]*KH_26_OPT4_KTQT_v4[[#This Row],[SL-07]]) -> 189591600 | CD7: =IF(KH_26_OPT4_KTQT_v4[[#This Row],[CPHH-%-SL]]="Dthu",KH_26_OPT4_KTQT_v4[[#This Row],[%HH]]*KH_26_OPT4_KTQT_v4[[#This Row],[DT-EXW-08]],KH_26_OPT4_KTQT_v4[[#This Row],[HH-SL]]*KH_26_OPT4_KTQT_v4[[#This Row],[SL-08]]) -> 189591600 | CE7: =IF(KH_26_OPT4_KTQT_v4[[#This Row],[CPHH-%-SL]]="Dthu",KH_26_OPT4_KTQT_v4[[#This Row],[%HH]]*KH_26_OPT4_KTQT_v4[[#This Row],[DT-EXW-09]],KH_26_OPT4_KTQT_v4[[#This Row],[HH-SL]]*KH_26_OPT4_KTQT_v4[[#This Row],[SL-09]]) -> 189591600 | CF7: =IF(KH_26_OPT4_KTQT_v4[[#This Row],[CPHH-%-SL]]="Dthu",KH_26_OPT4_KTQT_v4[[#This Row],[%HH]]*KH_26_OPT4_KTQT_v4[[#This Row],[DT-EXW-10]],KH_26_OPT4_KTQT_v4[[#This Row],[HH-SL]]*KH_26_OPT4_KTQT_v4[[#This Row],[SL-10]]) -> 189591600 | CG7: =IF(KH_26_OPT4_KTQT_v4[[#This Row],[CPHH-%-SL]]="Dthu",KH_26_OPT4_KTQT_v4[[#This Row],[%HH]]*KH_26_OPT4_KTQT_v4[[#This Row],[DT-EXW-11]],KH_26_OPT4_KTQT_v4[[#This Row],[HH-SL]]*KH_26_OPT4_KTQT_v4[[#This Row],[SL-11]]) -> 189591600 | CH7: =IF(KH_26_OPT4_KTQT_v4[[#This Row],[CPHH-%-SL]]="Dthu",KH_26_OPT4_KTQT_v4[[#This Row],[%HH]]*KH_26_OPT4_KTQT_v4[[#This Row],[DT-EXW-12]],KH_26_OPT4_KTQT_v4[[#This Row],[HH-SL]]*KH_26_OPT4_KTQT_v4[[#This Row],[SL-12]]) -> 189591600 | CI7: =SUM(KH_26_OPT4_KTQT_v4[[#This Row],[CPHH-01]:[CPHH-12]]) -> 2275099200 | CJ7: {=IFERROR(IF(KH_26_OPT4_KTQT_v4[[#This Row],[Kênh bán hàng]]="Nội địa",_xlfn.XLOOKUP(KH_26_OPT4_KTQT_v4[[#This Row],[Tên khách]]&KH_26_OPT4_KTQT_v4[[#This Row],[Kênh bán hàng]]&KH_26_OPT4_KTQT_v4[[#This Row],[Địa điểm đến]]&KH_26_OPT4_KTQT_v4[[#This Row],[Nước đến]]&KH_26_OPT4_KTQT_v4[[#This Row],[Incoterm]],ĐGVC!$A$6:$A$201&ĐGVC!$B$6:$B$201&ĐGVC!$C$6:$C$201&ĐGVC!$D$6:$D$201&ĐGVC!$E$6:$E$201,ĐGVC!$O$6:$O$201),0),0)} -> 0 | CK7: =SUM(KH_26_OPT4_KTQT_v4[[#This Row],[ĐGVCNĐ-KXK]:[ĐGVCCT-KXK]]) -> 530000 | CL7: {=IFERROR(IF(KH_26_OPT4_KTQT_v4[[#This Row],[Kênh bán hàng]]="xuất khẩu",_xlfn.XLOOKUP(KH_26_OPT4_KTQT_v4[[#This Row],[Tên khách]]&KH_26_OPT4_KTQT_v4[[#This Row],[Kênh bán hàng]]&KH_26_OPT4_KTQT_v4[[#This Row],[Địa điểm đến]]&KH_26_OPT4_KTQT_v4[[#This Row],[Nước đến]]&KH_26_OPT4_KTQT_v4[[#This Row],[Incoterm]],ĐGVC!$A$6:$A$201&ĐGVC!$B$6:$B$201&ĐGVC!$C$6:$C$201&ĐGVC!$D$6:$D$201&ĐGVC!$E$6:$E$201,ĐGVC!$O$6:$O$201),0),0)} -> 530000 | CM7: {=IFERROR(_xlfn.XLOOKUP(KH_26_OPT4_KTQT_v4[[#This Row],[Tên khách]]&KH_26_OPT4_KTQT_v4[[#This Row],[Kênh bán hàng]]&KH_26_OPT4_KTQT_v4[[#This Row],[Địa điểm đến]]&KH_26_OPT4_KTQT_v4[[#This Row],[Nước đến]]&KH_26_OPT4_KTQT_v4[[#This Row],[Incoterm]],ĐGVC!$A$6:$A$201&ĐGVC!$B$6:$B$201&ĐGVC!$C$6:$C$201&ĐGVC!$D$6:$D$201&ĐGVC!$E$6:$E$201,ĐGVC!$Y$6:$Y$201),0)} -> 0 | CN7: =(KH_26_OPT4_KTQT_v4[[#This Row],[ĐGVC-KNĐ]]+KH_26_OPT4_KTQT_v4[[#This Row],[ĐGVC-KXK]])*KH_26_OPT4_KTQT_v4[[#This Row],[SL-01]] -> 233200000 | CO7: =(KH_26_OPT4_KTQT_v4[[#This Row],[ĐGVC-KNĐ]]+KH_26_OPT4_KTQT_v4[[#This Row],[ĐGVC-KXK]])*KH_26_OPT4_KTQT_v4[[#This Row],[SL-02]] -> 233200000 | CP7: =(KH_26_OPT4_KTQT_v4[[#This Row],[ĐGVC-KNĐ]]+KH_26_OPT4_KTQT_v4[[#This Row],[ĐGVC-KXK]])*KH_26_OPT4_KTQT_v4[[#This Row],[SL-03]] -> 233200000 | CQ7: =(KH_26_OPT4_KTQT_v4[[#This Row],[ĐGVC-KNĐ]]+KH_26_OPT4_KTQT_v4[[#This Row],[ĐGVC-KXK]])*KH_26_OPT4_KTQT_v4[[#This Row],[SL-04]] -> 233200000 | CR7: =(KH_26_OPT4_KTQT_v4[[#This Row],[ĐGVC-KNĐ]]+KH_26_OPT4_KTQT_v4[[#This Row],[ĐGVC-KXK]])*KH_26_OPT4_KTQT_v4[[#This Row],[SL-05]] -> 233200000 | CS7: =(KH_26_OPT4_KTQT_v4[[#This Row],[ĐGVC-KNĐ]]+KH_26_OPT4_KTQT_v4[[#This Row],[ĐGVC-KXK]])*KH_26_OPT4_KTQT_v4[[#This Row],[SL-06]] -> 233200000 | CT7: =(KH_26_OPT4_KTQT_v4[[#This Row],[ĐGVC-KNĐ]]+KH_26_OPT4_KTQT_v4[[#This Row],[ĐGVC-KXK]])*KH_26_OPT4_KTQT_v4[[#This Row],[SL-07]] -> 233200000 | CU7: =(KH_26_OPT4_KTQT_v4[[#This Row],[ĐGVC-KNĐ]]+KH_26_OPT4_KTQT_v4[[#This Row],[ĐGVC-KXK]])*KH_26_OPT4_KTQT_v4[[#This Row],[SL-08]] -> 233200000 | CV7: =(KH_26_OPT4_KTQT_v4[[#This Row],[ĐGVC-KNĐ]]+KH_26_OPT4_KTQT_v4[[#This Row],[ĐGVC-KXK]])*KH_26_OPT4_KTQT_v4[[#This Row],[SL-09]] -> 233200000 | CW7: =(KH_26_OPT4_KTQT_v4[[#This Row],[ĐGVC-KNĐ]]+KH_26_OPT4_KTQT_v4[[#This Row],[ĐGVC-KXK]])*KH_26_OPT4_KTQT_v4[[#This Row],[SL-10]] -> 233200000 | CX7: =(KH_26_OPT4_KTQT_v4[[#This Row],[ĐGVC-KNĐ]]+KH_26_OPT4_KTQT_v4[[#This Row],[ĐGVC-KXK]])*KH_26_OPT4_KTQT_v4[[#This Row],[SL-11]] -> 233200000 | CY7: =(KH_26_OPT4_KTQT_v4[[#This Row],[ĐGVC-KNĐ]]+KH_26_OPT4_KTQT_v4[[#This Row],[ĐGVC-KXK]])*KH_26_OPT4_KTQT_v4[[#This Row],[SL-12]] -> 233200000 | CZ7: =SUM(KH_26_OPT4_KTQT_v4[[#This Row],[CPVC-01]:[CPVC-12]]) -> 2798400000 | DA7: =KH_26_OPT4_KTQT_v4[[#This Row],[DT-EXW-01]]+KH_26_OPT4_KTQT_v4[[#This Row],[CPVC-01]]+KH_26_OPT4_KTQT_v4[[#This Row],[CPHH-01]] -> 13062231600 | DB7: =KH_26_OPT4_KTQT_v4[[#This Row],[DT-EXW-02]]+KH_26_OPT4_KTQT_v4[[#This Row],[CPVC-02]]+KH_26_OPT4_KTQT_v4[[#This Row],[CPHH-02]] -> 13062231600 | DC7: =KH_26_OPT4_KTQT_v4[[#This Row],[DT-EXW-03]]+KH_26_OPT4_KTQT_v4[[#This Row],[CPVC-03]]+KH_26_OPT4_KTQT_v4[[#This Row],[CPHH-03]] -> 13062231600 | DD7: =KH_26_OPT4_KTQT_v4[[#This Row],[DT-EXW-04]]+KH_26_OPT4_KTQT_v4[[#This Row],[CPVC-04]]+KH_26_OPT4_KTQT_v4[[#This Row],[CPHH-04]] -> 13062231600 | DE7: =KH_26_OPT4_KTQT_v4[[#This Row],[DT-EXW-05]]+KH_26_OPT4_KTQT_v4[[#This Row],[CPVC-05]]+KH_26_OPT4_KTQT_v4[[#This Row],[CPHH-05]] -> 13062231600 | DF7: =KH_26_OPT4_KTQT_v4[[#This Row],[DT-EXW-06]]+KH_26_OPT4_KTQT_v4[[#This Row],[CPVC-06]]+KH_26_OPT4_KTQT_v4[[#This Row],[CPHH-06]] -> 13062231600 | DG7: =KH_26_OPT4_KTQT_v4[[#This Row],[DT-EXW-07]]+KH_26_OPT4_KTQT_v4[[#This Row],[CPVC-07]]+KH_26_OPT4_KTQT_v4[[#This Row],[CPHH-07]] -> 13062231600 | DH7: =KH_26_OPT4_KTQT_v4[[#This Row],[DT-EXW-08]]+KH_26_OPT4_KTQT_v4[[#This Row],[CPVC-08]]+KH_26_OPT4_KTQT_v4[[#This Row],[CPHH-08]] -> 13062231600 | DI7: =KH_26_OPT4_KTQT_v4[[#This Row],[DT-EXW-09]]+KH_26_OPT4_KTQT_v4[[#This Row],[CPVC-09]]+KH_26_OPT4_KTQT_v4[[#This Row],[CPHH-09]] -> 13062231600 | DJ7: =KH_26_OPT4_KTQT_v4[[#This Row],[DT-EXW-10]]+KH_26_OPT4_KTQT_v4[[#This Row],[CPVC-10]]+KH_26_OPT4_KTQT_v4[[#This Row],[CPHH-10]] -> 13062231600 | DK7: =KH_26_OPT4_KTQT_v4[[#This Row],[DT-EXW-11]]+KH_26_OPT4_KTQT_v4[[#This Row],[CPVC-11]]+KH_26_OPT4_KTQT_v4[[#This Row],[CPHH-11]] -> 13062231600 | DL7: =KH_26_OPT4_KTQT_v4[[#This Row],[DT-EXW-12]]+KH_26_OPT4_KTQT_v4[[#This Row],[CPVC-12]]+KH_26_OPT4_KTQT_v4[[#This Row],[CPHH-12]] -> 13062231600 | DM7: =SUM(KH_26_OPT4_KTQT_v4[[#This Row],[DT-01]:[DT-12]]) -> 156746779200 | DR7: =IFERROR(KH_26_OPT4_KTQT_v4[[#This Row],[DT-EXW-01]]*KH_26_OPT4_KTQT_v4[[#This Row],[%CPDP]],0) -> 0 | DS7: =IFERROR(KH_26_OPT4_KTQT_v4[[#This Row],[DT-EXW-02]]*KH_26_OPT4_KTQT_v4[[#This Row],[%CPDP]],0) -> 0 | DT7: =IFERROR(KH_26_OPT4_KTQT_v4[[#This Row],[DT-EXW-03]]*KH_26_OPT4_KTQT_v4[[#This Row],[%CPDP]],0) -> 0 | DU7: =IFERROR(KH_26_OPT4_KTQT_v4[[#This Row],[DT-EXW-04]]*KH_26_OPT4_KTQT_v4[[#This Row],[%CPDP]],0) -> 0 | DV7: =IFERROR(KH_26_OPT4_KTQT_v4[[#This Row],[DT-EXW-05]]*KH_26_OPT4_KTQT_v4[[#This Row],[%CPDP]],0) -> 0 | DW7: =IFERROR(KH_26_OPT4_KTQT_v4[[#This Row],[DT-EXW-06]]*KH_26_OPT4_KTQT_v4[[#This Row],[%CPDP]],0) -> 0 | DX7: =IFERROR(KH_26_OPT4_KTQT_v4[[#This Row],[DT-EXW-07]]*KH_26_OPT4_KTQT_v4[[#This Row],[%CPDP]],0) -> 0 | DY7: =IFERROR(KH_26_OPT4_KTQT_v4[[#This Row],[DT-EXW-08]]*KH_26_OPT4_KTQT_v4[[#This Row],[%CPDP]],0) -> 0 | DZ7: =IFERROR(KH_26_OPT4_KTQT_v4[[#This Row],[DT-EXW-09]]*KH_26_OPT4_KTQT_v4[[#This Row],[%CPDP]],0) -> 0 | EA7: =IFERROR(KH_26_OPT4_KTQT_v4[[#This Row],[DT-EXW-10]]*KH_26_OPT4_KTQT_v4[[#This Row],[%CPDP]],0) -> 0 | EB7: =IFERROR(KH_26_OPT4_KTQT_v4[[#This Row],[DT-EXW-11]]*KH_26_OPT4_KTQT_v4[[#This Row],[%CPDP]],0) -> 0 | EC7: =IFERROR(KH_26_OPT4_KTQT_v4[[#This Row],[DT-EXW-12]]*KH_26_OPT4_KTQT_v4[[#This Row],[%CPDP]],0) -> 0 | ED7: =SUM(KH_26_OPT4_KTQT_v4[[#This Row],[CPDP-01]:[CPDP-12]]) -> 0
