Workbook

Sheet Cover
C10: KHỐI TÁI CHẾ
C18: THẨM QUYỀN PHÊ DUYỆT (DOA)

Sheet Cấp bậc
B4: Hội đồng Quản trị | D4: Duy Tân Group | F4: Công ty Nhựa Tái chế Duy Tân | H4: Trạm Vận Hành
B5: HĐQT | C5: Hội đồng Quản trị | D5: GĐĐH-TC | E5: Giám đốc Điều hành Tài chính | F5: PTGĐ | G5: Phó Tổng Giám đốc | H5: GĐT/TT | I5: Giám đốc Trạm/Trưởng Trạm
B6: CT HĐQT | C6: Chủ Tịch Hội đồng Quản trị | D6: GĐĐH-NS | E6: Giám đốc Điều hành Nhân sự | F6: GĐĐH | G6: Giám đốc Điều hành | H6: KTT | I6: Kế toán trưởng
D7: GĐĐH-SX | E7: Giám đốc Điều hành Sản xuất | F7: GĐTC | G7: Giám đốc Tài chính | H7: TPNS | I7: Trưởng phòng Hành chánh Nhân sự
D8: GĐĐH-CCU | E8: Giám đốc Điều hành Chuỗi Cung Ứng | F8: GĐPTKD | G8: Giám đốc Phát triển Kinh doanh | H8: QLSX | I8: Quản lý sản xuất
D9: GĐĐH-KD | E9: Giám đốc Điều hành Kinh Doanh | F9: GĐNS | G9: Giám đốc Nhân sự | H9: TTKT | I9: Tổ trưởng Kỹ thuật
D10: GĐPC | E10: Giám đốc Pháp chế | F10: GĐKT | G10: Giám đốc Kỹ thuật | H10: QLCL | I10: Nhân viên chuyên trách Quản lý Chất lượng
D11: GĐCNTT | E11: Giám đốc Công nghệ Thông tin | F11: GĐSX | G11: Giám đốc Sản xuất | H11: QLK | I11: Quản lý kho
D12: GĐPTBV | E12: Giám đốc Phát triển Bền Vững | F12: GĐCCƯ | G12: Giám Đốc Chuỗi Cung Ứng | H12: MH | I12: Nhân viên chuyên trách Mua hàng
D13: PGĐDA | E13: Phó Giám đốc dự án XDCB | F13: GĐCLCCƯ | G13: Giám Đốc Chiến lược Chuỗi Cung Ứng | H13: VHCN | I13: Vận hành Chức năng
D14: GĐKSNB | E14: Giám đốc Kiểm soát Nội bộ | F14: GĐQLCL | G14: Giám đốc Quản lý Chất lượng
D15: GĐHCQT | E15: Giám đốc Hành chánh Quản trị | F15: GĐR&D | G15: Giám đốc R&D
F16: GĐĐH-T | G16: Giám đốc Điều hành Trạm
F17: PGĐ | G17: Phó Giám đốc Chức năng
F18: KTT | G18: Kế Toán Trưởng
F19: TP | G19: Trưởng Phòng Chức năng
F20: PP | G20: Phó Phòng Chức năng

Sheet RASCI
A1: MA TRẬN PHÂN CÔNG TRÁCH NHIỆM: MÔ HÌNH RASCI
C3: Vai trò | D3: Trách nhiệm | E3: Quyền
B4: R: | C4: Người đề xuất, thực hiện triển khai, chịu trách nhiệm ngân sách, tiến độ, chất lượng công việc | D4: Tinh thần “Tự làm, tự chịu trách nhiệm” | E4: Có quyền tiếp tục trình hồ sơ nếu “S”, “C” giữ hồ sơ không có lý do khi quá thời gian tiêu chuẩn
D5: KPI đo lường kết quả công việc trực tiếp
B6: S: | C6: Người kiểm tra, xem xét, cho ý kiến góp ý trên lĩnh vực có trách nhiệm chuyên môn | D6: Trách nhiệm liên đới khi “Thiếu trách nhiệm, cẩu thả góp ý chuyên môn” | E6: Có quyền chọn 1 trong 3 quyền cho ý kiến:
D7: KPI đo lường kết quả công việc góp ý | E7: q Đồng ý hoàn toàn
E8: q Đồng ý một phần
E9: q Từ chối hoàn toàn
B10: C: | C10: Người rà soát có trách nhiệm xem xét, kiểm tra tổng thể và có quyền chỉ định lấy ý kiến chuyên môn của các giám đốc theo yêu cầu kiểm tra nội nghiệp | D10: Trách nhiệm liên đới khi “Thiếu trách nhiệm, cẩu thả kiểm tra tổng thể ” | E10: Có quyền yêu cầu “R” cung cấp chi tiết, giải thích cặn kẽ
D11: KPI đo lường kết quả công việc kiểm tra
B12: A1: | C12: Ký nháy | D12: Ký duyệt
C13: Người có quyền phê duyệt (các hồ sơ có yêu cầu chữ ký pháp nhân) | D13: Điều chỉnh hồ sơ trình lại
D14: Từ chối phê duyệt
B15: A: | C15: Ký pháp nhân | D15: Ký duyệt chính thức trên hồ sơ sau khi có A1 phê duyệt; hoặc
C16: Người ký trên hồ sơ | D16: Ký duyệt chính thức trên hồ sơ nội bộ hoặc hồ sơ có yêu cầu ký pháp nhân mà A là người duyệt có pháp nhân/giấy ủy quyền pháp lý
B17: I: | C17: Người nhận thông tin, báo cáo | D17: § Báo cáo TGD/CT HĐQT
D18: § Thông báo các phần hành chức năng
B19: * | C19: A*: Đồng duyệt, A1*: đồng ký nháy
C20: (*): Ghi chú khác có giải thích theo từng trường hợp cụ thể

Sheet MỤC LỤC
C2: MỤC LỤC
B3: A | C3: Quản trị Công ty
B4: B | C4: Nhân sự
B5: C | C5: Ngân sách
B6: D | C6: Tài chính
B7: E | C7: Đầu tư (Capex) & Mua hàng(Opex) -PR
B8: F | C8: Hợp đồng/PO Mua hàng
B9: G | C9: Thủ tục thanh toán
B10: H | C10: XNK & Thuế
B11: I | C11: Kinh doanh Bán hàng-Hợp đồng
B12: J | C12: Thủ tục hành chính và vận hành
B13: K | C13: Quản lý chất lượng
B14: L | C14: Tiếp thị & Truyền thông
... B26: X | C26: An toàn

Sheet A.QUẢN TRỊ CTY
B2: Ký hiệu | C2: NỘI DUNG | D2: Giá trị _vnđ | E2: THẨM QUYỀN PHÊ DUYỆT | AQ2: Ghi chú
E3: HĐQT | G3: DUY TÂN GROUP | R3: CTY TNHH NHỰA TÁI CHẾ DUY TÂN | AH3: TRẠM VẬN HÀNH
E4: =+'Cấp bậc'!B5 -> HĐQT | F4: =+'Cấp bậc'!B6 -> CT HĐQT | G4: =+'Cấp bậc'!D5 -> GĐĐH-TC | H4: =+'Cấp bậc'!D6 -> GĐĐH-NS | I4: =+'Cấp bậc'!D7 -> GĐĐH-SX | J4: =+'Cấp bậc'!D8 -> GĐĐH-CCU | K4: =+'Cấp bậc'!D9 -> GĐĐH-KD | L4: =+'Cấp bậc'!D10 -> GĐPC | M4: =+'Cấp bậc'!D11 -> GĐCNTT | N4: =+'Cấp bậc'!D12 -> GĐPTBV | O4: =+'Cấp bậc'!D13 -> PGĐDA | P4: =+'Cấp bậc'!D14 -> GĐKSNB | Q4: =+'Cấp bậc'!D15 -> GĐHCQT | R4: =+'Cấp bậc'!F5 -> PTGĐ | S4: =+'Cấp bậc'!F6 -> GĐĐH | T4: =+'Cấp bậc'!F7 -> GĐTC | U4: =+'Cấp bậc'!F8 -> GĐPTKD | V4: =+'Cấp bậc'!F9 -> GĐNS | W4: =+'Cấp bậc'!F10 -> GĐKT | X4: =+'Cấp bậc'!F11 -> GĐSX | Y4: =+'Cấp bậc'!F12 -> GĐCCƯ | Z4: =+'Cấp bậc'!F13 -> GĐCLCCƯ | AA4: =+'Cấp bậc'!F14 -> GĐQLCL | AB4: =+'Cấp bậc'!F15 -> GĐR&D | AC4: =+'Cấp bậc'!F16 -> GĐĐH-T | AD4: =+'Cấp bậc'!F17 -> PGĐ | AE4: =+'Cấp bậc'!F18 -> KTT | AF4: =+'Cấp bậc'!F19 -> TP | AG4: =+'Cấp bậc'!F20 -> PP | AH4: =+'Cấp bậc'!H5 -> GĐT/TT | AI4: =+'Cấp bậc'!H6 -> KTT | AJ4: =+'Cấp bậc'!H7 -> TPNS | AK4: =+'Cấp bậc'!H8 -> QLSX | AL4: =+'Cấp bậc'!H9 -> TTKT | AM4: =+'Cấp bậc'!H10 -> QLCL | AN4: =+'Cấp bậc'!H11 -> QLK | AO4: =+'Cấp bậc'!H12 -> MH | AP4: =+'Cấp bậc'!H13 -> VHCN
E5: 1 | F5: =+E5+1 -> 2 | G5: =+F5+1 -> 3 | H5: =+G5+1 -> 4 | I5: =+H5+1 -> 5 | J5: =+I5+1 -> 6 | K5: =+J5+1 -> 7 | L5: =+K5+1 -> 8 | M5: =+L5+1 -> 9 | ... AP5: =+AO5+1 -> 38
B6: A | C6: QUẢN CÔNG TY
B7: A1 | C7: Chiến lược kinh doanh và kế hoạch phát triển
B8: A1.1 | C8: Chiến lược dài hạn (5 năm)
B9: A1.2 | C9: Kế hoạch kinh doanh hàng năm
B10: A1.3 | C10: Đánh giá lại chiến lược dài hạn
B11: A1.4 | C11: Thay đổi kế hoạch kinh doanh hàng năm
B12: A2 | C12: KPIs Công ty Thành viên
B13: A2.1 | C13: Thiết lập KPIs
C14: Bảng phân bổ KPI
B15: A2.2 | C15: Báo cáo kết quả, đánh giá KPIs
B16: A2.3 | C16: Hiệu chỉnh KPI
B17: A2.3.1 | C17: Hiệu chỉnh KPIs cấp Giám đốc/Phó giám đốc
B18: A2.3.2 | C18: Hiệu chỉnh KPIs cấp Trưởng, Phó phòng
B19: A2.3.3 | C19: Hiệu chỉnh KPIs cấp dưới ca61o Phó phòng

Sheet B.NHÂN SỰ
B2: Ký hiệu | C2: NỘI DUNG | D2: Giá trị _vnđ | E2: THẨM QUYỀN PHÊ DUYỆT | AQ2: Ghi chú
E3: HĐQT | G3: DUY TÂN GROUP | R3: CTY TNHH NHỰA TÁI CHẾ DUY TÂN | AH3: TRẠM VẬN HÀNH
E4: =+'Cấp bậc'!B5 -> HĐQT | F4: =+'Cấp bậc'!B6 -> CT HĐQT | G4: =+'Cấp bậc'!D5 -> GĐĐH-TC | H4: =+'Cấp bậc'!D6 -> GĐĐH-NS | I4: =+'Cấp bậc'!D7 -> GĐĐH-SX | J4: =+'Cấp bậc'!D8 -> GĐĐH-CCU | K4: =+'Cấp bậc'!D9 -> GĐĐH-KD | L4: =+'Cấp bậc'!D10 -> GĐPC | M4: =+'Cấp bậc'!D11 -> GĐCNTT | N4: =+'Cấp bậc'!D12 -> GĐPTBV | O4: =+'Cấp bậc'!D13 -> PGĐDA | P4: =+'Cấp bậc'!D14 -> GĐKSNB | Q4: =+'Cấp bậc'!D15 -> GĐHCQT | R4: =+'Cấp bậc'!F5 -> PTGĐ | S4: =+'Cấp bậc'!F6 -> GĐĐH | T4: =+'Cấp bậc'!F7 -> GĐTC | U4: =+'Cấp bậc'!F8 -> GĐPTKD | V4: =+'Cấp bậc'!F9 -> GĐNS | W4: =+'Cấp bậc'!F10 -> GĐKT | X4: =+'Cấp bậc'!F11 -> GĐSX | Y4: =+'Cấp bậc'!F12 -> GĐCCƯ | Z4: =+'Cấp bậc'!F13 -> GĐCLCCƯ | AA4: =+'Cấp bậc'!F14 -> GĐQLCL | AB4: =+'Cấp bậc'!F15 -> GĐR&D | AC4: =+'Cấp bậc'!F16 -> GĐĐH-T | AD4: =+'Cấp bậc'!F17 -> PGĐ | AE4: =+'Cấp bậc'!F18 -> KTT | AF4: =+'Cấp bậc'!F19 -> TP | AG4: =+'Cấp bậc'!F20 -> PP | AH4: =+'Cấp bậc'!H5 -> GĐT/TT | AI4: =+'Cấp bậc'!H6 -> KTT | AJ4: =+'Cấp bậc'!H7 -> TPNS | AK4: =+'Cấp bậc'!H8 -> QLSX | AL4: =+'Cấp bậc'!H9 -> TTKT | AM4: =+'Cấp bậc'!H10 -> QLCL | AN4: =+'Cấp bậc'!H11 -> QLK | AO4: =+'Cấp bậc'!H12 -> MH | AP4: =+'Cấp bậc'!H13 -> VHCN
E5: 1 | F5: =+E5+1 -> 2 | G5: =+F5+1 -> 3 | H5: =+G5+1 -> 4 | I5: =+H5+1 -> 5 | J5: =+I5+1 -> 6 | K5: =+J5+1 -> 7 | L5: =+K5+1 -> 8 | M5: =+L5+1 -> 9 | ... AP5: =+AO5+1 -> 38
B6: B | C6: NHÂN SỰ
B7: B1 | C7: Thiết lập quy chế, chính sách
B8: B1.1 | C8: Phê duyệt định hướng chiến lược nhân sự & chính sách phúc lợi tổng thể
B9: B1.2 | C9: Ban hành điều lệ, quy chế, 3Q nội bộ(nội quy lao động, tuyển dụng, quy trình tiếp nhận – kỷ luật – nghỉ việc, nhân tài...)
B10: B1.3 | C10: Chính sách tổng thể về nhân sự, tiền lương, thưởng, phúc lợi
B11: B1.4 | C11: Xây dựng và điều chỉnh hệ thống chức danh, thang bảng lương
B12: B2 | C12: Cơ cấu tổ chức & mô tả công việc
B13: B2.1 | C13: Sơ đồ tổ chức, cấp công ty, cấp phòng ban, bản mô tả chức năng (SOW) cho các phòng ban/đơn vị
B14: B2.2 | C14: Ban hành bản mô tả công việc (JD) cho từng vị trí
B15: B3 | C15: Quản trị nhân sự & ngân sách
B16: B3.1 | C16: Kế hoạch định biên nhân sự hàng năm
B17: B3.2 | C17: Ngân sách tăng lương, thưởng hàng năm, đào tạo, tuyển dụng, phúc lợi
... B28: B5 | C28: Tuyển dụng & tiếp nhận nhân sự
C29: Tuyển dụng nhân sự mới TRONG định biên đã duyệt đầu năm)
B30: B5.1 | C30: Tuyển dụng nhân sự mới NGOÀI định biên đã duyệt đầu năm)
B31: B5.2 | C31: Tuyển dụng nhân sự mới/thay thế ( cấp Giám đốc trở lên)
B32: B5.3 | C32: Ký kết Hợp đồng & các thỏa thuận khác giữa Công ty với Người lao động
B33: B6 | C33: Đào tạo & phát triển
B34: B6.1 | C34: Kế hoạch đào tạo năm
B35: B6.2 | C35: Tổ chức chương trình đào tạo kỹ năng mềm & năng lực chung
B36: B6.3 | C36: Chương trình đào tạo khác do giảng viên nội bộ thực hiện hoặc thuê ngoài
B37: B6.4 | C37: Các kế hoạch triển khai chương trình phát triển nhân tài & kế thừa (talent, succession…) hàng năm
B38: B7 | C38: Quản trị tuân thủ & rủi ro nhân sự
B39: B7.1 | C39: Xử lý vi phạm, kỷ luật, chấm dứt hợp đồng lao động
B40: B7.2 | C40: Làm việc với cơ quan nhà nước, kiểm toán, thanh tra & đối tác bên ngoài

Sheet C.NGÂN SÁCH
B2: Ký hiệu | C2: NỘI DUNG | D2: Giá trị _vnđ | E2: THẨM QUYỀN PHÊ DUYỆT | AQ2: Ghi chú
E3: HĐQT | G3: DUY TÂN GROUP | R3: CTY TNHH NHỰA TÁI CHẾ DUY TÂN | AH3: TRẠM VẬN HÀNH
E4: =+'Cấp bậc'!B5 -> HĐQT | F4: =+'Cấp bậc'!B6 -> CT HĐQT | G4: =+'Cấp bậc'!D5 -> GĐĐH-TC | H4: =+'Cấp bậc'!D6 -> GĐĐH-NS | I4: =+'Cấp bậc'!D7 -> GĐĐH-SX | J4: =+'Cấp bậc'!D8 -> GĐĐH-CCU | K4: =+'Cấp bậc'!D9 -> GĐĐH-KD | L4: =+'Cấp bậc'!D10 -> GĐPC | M4: =+'Cấp bậc'!D11 -> GĐCNTT | N4: =+'Cấp bậc'!D12 -> GĐPTBV | O4: =+'Cấp bậc'!D13 -> PGĐDA | P4: =+'Cấp bậc'!D14 -> GĐKSNB | Q4: =+'Cấp bậc'!D15 -> GĐHCQT | R4: =+'Cấp bậc'!F5 -> PTGĐ | S4: =+'Cấp bậc'!F6 -> GĐĐH | T4: =+'Cấp bậc'!F7 -> GĐTC | U4: =+'Cấp bậc'!F8 -> GĐPTKD | V4: =+'Cấp bậc'!F9 -> GĐNS | W4: =+'Cấp bậc'!F10 -> GĐKT | X4: =+'Cấp bậc'!F11 -> GĐSX | Y4: =+'Cấp bậc'!F12 -> GĐCCƯ | Z4: =+'Cấp bậc'!F13 -> GĐCLCCƯ | AA4: =+'Cấp bậc'!F14 -> GĐQLCL | AB4: =+'Cấp bậc'!F15 -> GĐR&D | AC4: =+'Cấp bậc'!F16 -> GĐĐH-T | AD4: =+'Cấp bậc'!F17 -> PGĐ | AE4: =+'Cấp bậc'!F18 -> KTT | AF4: =+'Cấp bậc'!F19 -> TP | AG4: =+'Cấp bậc'!F20 -> PP | AH4: =+'Cấp bậc'!H5 -> GĐT/TT | AI4: =+'Cấp bậc'!H6 -> KTT | AJ4: =+'Cấp bậc'!H7 -> TPNS | AK4: =+'Cấp bậc'!H8 -> QLSX | AL4: =+'Cấp bậc'!H9 -> TTKT | AM4: =+'Cấp bậc'!H10 -> QLCL | AN4: =+'Cấp bậc'!H11 -> QLK | AO4: =+'Cấp bậc'!H12 -> MH | AP4: =+'Cấp bậc'!H13 -> VHCN
E5: 1 | F5: =+E5+1 -> 2 | G5: =+F5+1 -> 3 | H5: =+G5+1 -> 4 | I5: =+H5+1 -> 5 | J5: =+I5+1 -> 6 | K5: =+J5+1 -> 7 | L5: =+K5+1 -> 8 | M5: =+L5+1 -> 9 | ... AP5: =+AO5+1 -> 38
B6: C1 | C6: Ngân sách hàng năm
B7: C1.1 | C7: Duyệt Ngân sách hàng năm (Capex & Opex) | E7: I | F7: A | G7: C | S7: C | T7: R | AE7: R | AF7: R
B8: C1.2 | C8: Duyệt TĂNG ngân sách (giá trị % tăng/năm so với tổng Ngân sách Chi phí vận hành (Opex)) đã được duyệt | D8: > 1 % | F8: A
B9: C1.3 | D9: < 1% | F9: I | G9: A | S9: C | T9: R | AE9: R | AF9: R
B10: C1.4 | C10: Duyệt TĂNG/bổ sung ngân sách Capex từ đầu tư/dự án đã được duyệt hoặc chưa phát sinh trong năm (chưa trình duyệt) | F10: A | G10: C | S10: C | T10: R
B11: C1.5 | C11: Duyệt giảm ngân sách | G11: I | S11: A | T11: C | AE11: I | AF11: R
B12: C1.6 | C12: Thay đổi phân bổ ngân sách +/-20% (tổng ngân sách không thay đổi) | G12: I | S12: A | T12: C | AE12: I | AF12: R
B13: C1.7 | C13: Duyệt chuyển ngân sách mua sắm tài sản qua năm tài chính kế tiếp | F13: A | G13: C | S13: C | T13: R

Sheet D.TAI CHÍNH
B2: Ký hiệu | C2: NỘI DUNG | D2: Giá trị _vnđ | E2: THẨM QUYỀN PHÊ DUYỆT | AQ2: Ghi chú
E3: HĐQT | G3: DUY TÂN GROUP | R3: CTY TNHH NHỰA TÁI CHẾ DUY TÂN | AH3: TRẠM VẬN HÀNH
E4: =+'Cấp bậc'!B5 -> HĐQT | F4: =+'Cấp bậc'!B6 -> CT HĐQT | G4: =+'Cấp bậc'!D5 -> GĐĐH-TC | H4: =+'Cấp bậc'!D6 -> GĐĐH-NS | I4: =+'Cấp bậc'!D7 -> GĐĐH-SX | J4: =+'Cấp bậc'!D8 -> GĐĐH-CCU | K4: =+'Cấp bậc'!D9 -> GĐĐH-KD | L4: =+'Cấp bậc'!D10 -> GĐPC | M4: =+'Cấp bậc'!D11 -> GĐCNTT | N4: =+'Cấp bậc'!D12 -> GĐPTBV | O4: =+'Cấp bậc'!D13 -> PGĐDA | P4: =+'Cấp bậc'!D14 -> GĐKSNB | Q4: =+'Cấp bậc'!D15 -> GĐHCQT | R4: =+'Cấp bậc'!F5 -> PTGĐ | S4: =+'Cấp bậc'!F6 -> GĐĐH | T4: =+'Cấp bậc'!F7 -> GĐTC | U4: =+'Cấp bậc'!F8 -> GĐPTKD | V4: =+'Cấp bậc'!F9 -> GĐNS | W4: =+'Cấp bậc'!F10 -> GĐKT | X4: =+'Cấp bậc'!F11 -> GĐSX | Y4: =+'Cấp bậc'!F12 -> GĐCCƯ | Z4: =+'Cấp bậc'!F13 -> GĐCLCCƯ | AA4: =+'Cấp bậc'!F14 -> GĐQLCL | AB4: =+'Cấp bậc'!F15 -> GĐR&D | AC4: =+'Cấp bậc'!F16 -> GĐĐH-T | AD4: =+'Cấp bậc'!F17 -> PGĐ | AE4: =+'Cấp bậc'!F18 -> KTT | AF4: =+'Cấp bậc'!F19 -> TP | AG4: =+'Cấp bậc'!F20 -> PP | AH4: =+'Cấp bậc'!H5 -> GĐT/TT | AI4: =+'Cấp bậc'!H6 -> KTT | AJ4: =+'Cấp bậc'!H7 -> TPNS | AK4: =+'Cấp bậc'!H8 -> QLSX | AL4: =+'Cấp bậc'!H9 -> TTKT | AM4: =+'Cấp bậc'!H10 -> QLCL | AN4: =+'Cấp bậc'!H11 -> QLK | AO4: =+'Cấp bậc'!H12 -> MH | AP4: =+'Cấp bậc'!H13 -> VHCN
E5: 1 | F5: =+E5+1 -> 2 | G5: =+F5+1 -> 3 | H5: =+G5+1 -> 4 | I5: =+H5+1 -> 5 | J5: =+I5+1 -> 6 | K5: =+J5+1 -> 7 | L5: =+K5+1 -> 8 | M5: =+L5+1 -> 9 | ... P5: =+O5+1 -> 12 | R5: =+P5+1 -> 13 | S5: =+R5+1 -> 14 | T5: =+S5+1 -> 15 | U5: =+T5+1 -> 16 | V5: =+U5+1 -> 17 | W5: =+V5+1 -> 18 | X5: =+W5+1 -> 19 | Y5: =+X5+1 -> 20 | Z5: =+Y5+1 -> 21 | ... AP5: =+AO5+1 -> 37
B6: D | C6: TÀI CHÍNH KẾ TOÁN
B7: D1 | C7: Những vấn đề Tài chính & các chính sách
B8: D1.1 | C8: Duyệt kiểm toán hàng năm & chọn đơn vị kiểm toán | G8: A | T8: S
B9: D1.2 | C9: Thay đổi cấu trúc vốn | F9: A
B10: D1.3 | C10: Thay đổi vốn điều lệ | F10: A
B11: D1.4 | C11: Chính sách phân chia lợi nhuận | F11: A
B12: D1.5 | C12: Quyết định việc mở các tài khoản Ngân hàng | G12: A
B13: D1.6 | C13: Thực hiện, ký kết hồ sơ mở tài khoản Ngân hàng | S13: A | T13: C | AE13: S
B14: D1.7 | C14: Các chính sách liên quan đến việc vay Ngân hàng và thế chấp, bảo lãnh Ngân hàng | G14: A
B15: D1.8 | C15: Bảo lãnh (Bank Guatantee) và Thư Tín dụng (LC) | S15: A | T15: C | AE15: S
B16: D1.9 | C16: Các chính sách kế toán và các chính sách Tài chính | G16: A
B17: D1.10 | C17: Đánh giá lại tài sản cố định | G17: A
B18: D1.11 | C18: Vay vốn, thế chấp tài sản tại các tổ chức tín dụng | G18: A
B19: D1.12 | C19: Gửi tiền tiền nhàn rỗi (dòng tiền chưa dùng ngay) | G19: A
B20: D2 | C20: Giao dịch Mua bán và sáp nhập
B21: D2.1 | C21: Tất cả các thương vụ sáp nhập, liên doanh, mua lại và thoái vốn tài sản hoặc cổ phần trong bất kỳ giao dịch nào | F21: A
B22: D2.2 | C22: Quyết định tiến hành đầu tư phát triển khi cơ hội mở ra nhiều triển vọng | F22: A
B23: D2.3 | C23: Chọn Ngân hàng đầu tư/ hợp tác | F23: A
B24: D2.4 | C24: Chọn đơn vị tư vấn M&A | F24: A
B25: D2.5 | C25: Duyệt đầu tư/ Từ bỏ đầu tư/ hợp tác | F25: A
B26: D2.6 | C26: Ký kết hợp đồng Mua và Bán (M&A - Mergers & Acquisitions) | F26: A
B27: D2.7 | C27: Ký thư chỉ định (LOI - Letter of Intent) | F27: A
B28: D2.8 | C28: Ký kết Bảng ghi nhớ MOU (Memorandum Of Understanding) | F28: A
B29: D3 | C29: Các điều chỉnh kế toán
B30: D3.1 | C30: Điều chỉnh chênh lệch tồn kho, Điều chỉnh tổn thất/ hao hụt/ tổn thất khác | D30: > 1 tỷ | G30: A | T30: C | AC30: C | AH30: C | AI30: R
D31: < 1 tỷ | S31: A | T31: C | AE31: C
B32: D3.3 | C32: Giảm giá hàng tồn kho (nguyên vật liệu, thành phẩm, bán thành phẩm, công cụ dụng cụ, hóa chất…) | D32: > 500 tr | G32: A | T32: C | AC32: C | AH32: C | AI32: R
D33: < 500 tr | S33: A | T33: C | AE33: C
B34: D4 | C34: Dự Phòng và Thanh lý tài sản cố định và tài sản/ hàng hóa
B35: D4.1 | C35: Lập Dự phòng
B36: D4.1.1 | C36: Dự phòng nợ khó đòi | T36: A | AH36: C | AI36: R
B37: D4.1.2 | C37: Dự phòng khác | T37: A | AH37: C | AI37: R
B38: 4.2 | C38: Thanh lý
B39: D4.2.1 | C39: Thanh lý tài sản cố định & tài sản khác | F39: A | G39: C | S39: C | T39: S
B40: D4.2.2 | C40: Thanh lý phế liệu | S40: A | T40: C | X40: C | AE40: C
B41: D4.2.3 | C41: Thanh lý hàng tồn kho | D41: > 200 tr | F41: A | T41: C
...

Sheet E.ĐẦU TƯ-MUA HÀNG(PR)
B2: Ký hiệu | C2: NỘI DUNG | D2: Giá trị _vnđ | E2: THẨM QUYỀN PHÊ DUYỆT | AQ2: Ghi chú
E3: HĐQT | G3: DUY TÂN GROUP | R3: CTY TNHH NHỰA TÁI CHẾ DUY TÂN | AH3: TRẠM VẬN HÀNH
E4: =+'Cấp bậc'!B5 -> HĐQT | F4: =+'Cấp bậc'!B6 -> CT HĐQT | G4: =+'Cấp bậc'!D5 -> GĐĐH-TC | H4: =+'Cấp bậc'!D6 -> GĐĐH-NS | I4: =+'Cấp bậc'!D7 -> GĐĐH-SX | J4: =+'Cấp bậc'!D8 -> GĐĐH-CCU | K4: =+'Cấp bậc'!D9 -> GĐĐH-KD | L4: =+'Cấp bậc'!D10 -> GĐPC | M4: =+'Cấp bậc'!D11 -> GĐCNTT | N4: =+'Cấp bậc'!D12 -> GĐPTBV | O4: =+'Cấp bậc'!D13 -> PGĐDA | P4: =+'Cấp bậc'!D14 -> GĐKSNB | Q4: =+'Cấp bậc'!D15 -> GĐHCQT | R4: =+'Cấp bậc'!F5 -> PTGĐ | S4: =+'Cấp bậc'!F6 -> GĐĐH | T4: =+'Cấp bậc'!F7 -> GĐTC | U4: =+'Cấp bậc'!F8 -> GĐPTKD | V4: =+'Cấp bậc'!F9 -> GĐNS | W4: =+'Cấp bậc'!F10 -> GĐKT | X4: =+'Cấp bậc'!F11 -> GĐSX | Y4: =+'Cấp bậc'!F12 -> GĐCCƯ | Z4: =+'Cấp bậc'!F13 -> GĐCLCCƯ | AA4: =+'Cấp bậc'!F14 -> GĐQLCL | AB4: =+'Cấp bậc'!F15 -> GĐR&D | AC4: =+'Cấp bậc'!F16 -> GĐĐH-T | AD4: =+'Cấp bậc'!F17 -> PGĐ | AE4: =+'Cấp bậc'!F18 -> KTT | AF4: =+'Cấp bậc'!F19 -> TP | AG4: =+'Cấp bậc'!F20 -> PP | AH4: =+'Cấp bậc'!H5 -> GĐT/TT | AI4: =+'Cấp bậc'!H6 -> KTT | AJ4: =+'Cấp bậc'!H7 -> TPNS | AK4: =+'Cấp bậc'!H8 -> QLSX | AL4: =+'Cấp bậc'!H9 -> TTKT | AM4: =+'Cấp bậc'!H10 -> QLCL | AN4: =+'Cấp bậc'!H11 -> QLK | AO4: =+'Cấp bậc'!H12 -> MH | AP4: =+'Cấp bậc'!H13 -> VHCN
E5: 1 | F5: =+E5+1 -> 2 | G5: =+F5+1 -> 3 | H5: =+G5+1 -> 4 | I5: =+H5+1 -> 5 | J5: =+I5+1 -> 6 | K5: =+J5+1 -> 7 | L5: =+K5+1 -> 8 | M5: =+L5+1 -> 9 | ... AP5: =+AO5+1 -> 38
B6: E | C6: THỦ TỤC ĐỀ NGHỊ DẦU TƯ (CAPEX) & ĐỀ NGHỊ MUA HÀNG HÓA, DỊCH VỤ(OPEX) & THỦ TỤC DUYỆT GIÁ
B7: E1 | C7: Đề nghị Đầu tư máy móc thiết bị, xây dựng Cơ bản, Công nghệ Thông tin - Capex
B8: E1.1 | C8: Đề nghị đầu tư máy móc thiết bị trong ngân sách và ngoài ngân sách | F8: A | G8: C | I8: S | S8: C | T8: C | V8: R | W8: R | X8: R | Y8: R | AA8: R | AB8: R
B9: E1.2 | C9: Đề nghị đầu tư Xây dựng Cơ bản trong ngân sách và ngoài ngân sách | F9: A | G9: C | O9: S | S9: C | T9: C | AE9: C
B10: E1.3 | C10: Đề nghị đầu tư Công nghệ Thông tin (giải pháp vận hành CNTT, hạ tầng, thiết bị…) trong ngân sách và ngoài ngân sách | F10: A | G10: C | M10: S | S10: C | T10: C | AE10: C
B11: E2 | C11: Duyệt giá đầu tư máy móc thiết bị, Xây dựng cơ bản, CNTT (Capex) & nguyên vật liệu, hàng hóa, dịch vụ (Opex)
B12: E2.1 | C12: Duyệt giá đầu tư máy móc thiết bị, xây dựng Cơ bản, Công nghệ Thông tin - Capex | F12: A | T12: C | W12: S
B13: E2.2 | C13: Duyệt giá mua Nguyên vật liệu chính/bán thành phẩm vảy, rác thải nhựa phục vụ sản xuất-Opex | F13: A | S13: I | Z13: C
B14: E2.3 | C14: Duyệt giá mua vật liệu phụ, hàng hóa, công cụ dụng cụ, dịch vụ….Opex | S14: A
B15: E3 | C15: Đề nghị mua hóa, dịch vụ phục vụ sản xuất kinh doanh theo kế hoạch sản xuất đã được duyệt - Opex
B16: E3.1 | C16: Đề nghị mua Nguyên vật liệu chính: rác thải nhựa, vảy phục vụ sản xuất kinh doanh khối Tái chế trong kế hoạch sản xuất đã được duyệt | S16: A | T16: C | Y16: C | AF16: R
B17: E3.2 | C17: Đề nghị mua Nguyên vật liệu chính: rác thải nhựa, vảy phục vụ sản xuất kinh doanh khối Tái chế vượt kế hoạch sản xuất đã được duyệt | S17: A | T17: C | Y17: C | AF17: R
B18: E3.3 | C18: Đề nghị mua Nguyên vật liệu, hàng hóa, công cụ dụng cụ, gia công lắp ráp, dịch vụ lắp đặt các hệ thống PCCC, nước, điện, điện lạnh, thiết bị vi tính ngoại vi, và các loại dịch vụ khác…phục vụ sản xuất kinh doanh | D18: Giá trị>10 tỷ | F18: A
D19: Giá trị<10 tỷ | G19: A
D20: Giá trị<5 tỷ | S20: A | T20: C
B21: E3.5 | C21: Đề nghị dịch vụ tư vấn, thiết kế, khoa học kỹ thuật, dịch vụ kiểm định, Marketing, tài trợ, các khoản bồi thường, các khoản phạt và các loại dịch vụ khác… | D21: Giá trị>10 tỷ | F21: A
D22: Giá trị<10 tỷ | G22: A
D23: Giá trị<5 tỷ | S23: A | T23: C | AE23: C

Sheet F.HỢP ĐỒNG-PO 
B2: Ký hiệu | C2: NỘI DUNG | D2: Giá trị _vnđ | E2: THẨM QUYỀN PHÊ DUYỆT | AQ2: Ghi chú
E3: HĐQT | G3: DUY TÂN GROUP | R3: CTY TNHH NHỰA TÁI CHẾ DUY TÂN | AH3: TRẠM VẬN HÀNH
E4: =+'Cấp bậc'!B5 -> HĐQT | F4: =+'Cấp bậc'!B6 -> CT HĐQT | G4: =+'Cấp bậc'!D5 -> GĐĐH-TC | H4: =+'Cấp bậc'!D6 -> GĐĐH-NS | I4: =+'Cấp bậc'!D7 -> GĐĐH-SX | J4: =+'Cấp bậc'!D8 -> GĐĐH-CCU | K4: =+'Cấp bậc'!D9 -> GĐĐH-KD | L4: =+'Cấp bậc'!D10 -> GĐPC | M4: =+'Cấp bậc'!D11 -> GĐCNTT | N4: =+'Cấp bậc'!D12 -> GĐPTBV | O4: =+'Cấp bậc'!D13 -> PGĐDA | P4: =+'Cấp bậc'!D14 -> GĐKSNB | Q4: =+'Cấp bậc'!D15 -> GĐHCQT | R4: =+'Cấp bậc'!F5 -> PTGĐ | S4: =+'Cấp bậc'!F6 -> GĐĐH | T4: =+'Cấp bậc'!F7 -> GĐTC | U4: =+'Cấp bậc'!F8 -> GĐPTKD | V4: =+'Cấp bậc'!F9 -> GĐNS | W4: =+'Cấp bậc'!F10 -> GĐKT | X4: =+'Cấp bậc'!F11 -> GĐSX | Y4: =+'Cấp bậc'!F12 -> GĐCCƯ | Z4: =+'Cấp bậc'!F13 -> GĐCLCCƯ | AA4: =+'Cấp bậc'!F14 -> GĐQLCL | AB4: =+'Cấp bậc'!F15 -> GĐR&D | AC4: =+'Cấp bậc'!F16 -> GĐĐH-T | AD4: =+'Cấp bậc'!F17 -> PGĐ | AE4: =+'Cấp bậc'!F18 -> KTT | AF4: =+'Cấp bậc'!F19 -> TP | AG4: =+'Cấp bậc'!F20 -> PP | AH4: =+'Cấp bậc'!H5 -> GĐT/TT | AI4: =+'Cấp bậc'!H6 -> KTT | AJ4: =+'Cấp bậc'!H7 -> TPNS | AK4: =+'Cấp bậc'!H8 -> QLSX | AL4: =+'Cấp bậc'!H9 -> TTKT | AM4: =+'Cấp bậc'!H10 -> QLCL | AN4: =+'Cấp bậc'!H11 -> QLK | AO4: =+'Cấp bậc'!H12 -> MH | AP4: =+'Cấp bậc'!H13 -> VHCN
E5: 1 | F5: =+E5+1 -> 2 | G5: =+F5+1 -> 3 | H5: =+G5+1 -> 4 | I5: =+H5+1 -> 5 | J5: =+I5+1 -> 6 | K5: =+J5+1 -> 7 | L5: =+K5+1 -> 8 | M5: =+L5+1 -> 9 | ... AP5: =+AO5+1 -> 38
B6: F | C6: THỦ TỤC ĐỀ NGHỊ DẦU TƯ, DUYỆT GIÁ, MUA HÀNG VÀ HỢP ĐỒNG/PO
B7: F1 | C7: Hợp đồng/PO mua hàng hóa, dịch vụ với Nhà Cung Cấp nước ngoài & nội địa (sau khi đề nghị đầu tư (Capex) mua hàng hóa, dịch vụ (Opex) đã được duyệt)
B8: F1.1 | C8: Ký kết hợp đồng/PO Công trình Xây dựng Cơ bản với Nhà cung cấp nước ngoài và nội địa | O8: A1 | S8: A | AH8: A | AI8: C | AQ8: A:Ký HĐ theo DTR/Trạm
B9: F1.2 | C9: Ký kết hợp đồng/PO mua sắm Công nghệ Thông tin (giải pháp vận hành CNTT, hạ tầng, thiết bị…) với Nhà cung cấp nước ngoài và nội địa | M9: A1 | S9: A | AH9: A | AI9: C | AQ9: A:Ký HĐ theo DTR/Trạm
B10: F1.3 | C10: Ký kết hợp đồng/PO mua sắm máy móc thiết bị, linh kiện, phụ kiện với Nhà cung cấp nước ngoài và nội địa | I10: A1 | S10: A | AH10: A | AI10: C | AQ10: A:Ký HĐ theo DTR/Trạm
B11: F1.4 | C11: Ký kết hợp đồng/PO mua Nguyên vật liệu chính, bán thành phẩm, gia công, nguyên liệu phụ, linh kiện, công cụ dụng cụ,...phục vụ sản xuất kinh doanh với Nhà cung cấp nước ngoài và nội địa | S11: A | AH11: A | AI11: C | AQ11: A:Ký HĐ theo DTR/Trạm
B12: F2 | C12: Hợp đồng/PO liên quan hành chính và vận hành (sau khi đề nghị được duyệt) | AQ12: A:Ký HĐ theo DTR/Trạm
B13: F2.1 | C13: Ký kết hợp đồng/PO liên quan đến lĩnh vực hành chánh nhân sự | S13: A | AH13: A | AQ13: A:Ký HĐ theo DTR/Trạm
B14: F2.2 | C14: Ký kết hợp đồng/PO thuê đất và/hoặc thuê văn phòng/kho | S14: A | T14: C | AH14: A | AQ14: A:Ký HĐ theo DTR/Trạm
B15: F2.3 | C15: Ký kết hợp đồng chuyển nhượng tài sản trí tuệ | F15: A | AH15: A | AQ15: A:Ký HĐ theo DTR/Trạm
B16: F2.4 | C16: Ký kết hợp đồng vay tài sản, vay Ngân hàng | S16: A | T16: C | AH16: A | AQ16: A:Ký HĐ theo DTR/Trạm
B17: F3 | C17: Ký kết hợp đồng lao động sau khi các thủ tục liên quan đến tuyển dụng đã được duyệt | AQ17: A:Ký HĐ theo DTR/Trạm
B18: F3.1 | C18: Ban giám đốc | AH18: A | AI18: R | AQ18: A:Ký HĐ theo DTR/Trạm
B19: F3.2 | C19: Cán bộ nhân viên cấp Trưởng phó phòng | AH19: A | AI19: R | AQ19: A:Ký HĐ theo DTR/Trạm
B20: F3.3 | C20: Cán bộ nhân viên dưới cấp Phó phòng | AH20: A | AI20: R | AQ20: A:Ký HĐ theo DTR/Trạm
B21: F3.4 | C21: Các loại Hợp đồng khác có liên quan đến Người Lao động: hợp đồng Bảo hiểm (tai nạn cho nhân viên), sức khỏe (cho cấp quản lý) | AH21: A | AI21: R | AQ21: A:Ký HĐ theo DTR/Trạm
C23: Hợp đồng mua hàng phải có ý kiến tham vấn của Phòng Tài chính DTR nhằm đảm bảo tính hợp lệ, hợp lý về mặt tài chính và kiểm soát rủi ro tài chính trước khi ký hợp đồng mua hàng

Sheet G.THU TUC THANH TOÁN
B2: Ký hiệu | C2: NỘI DUNG | D2: Giá trị _vnđ | E2: THẨM QUYỀN PHÊ DUYỆT | AQ2: Ghi chú
E3: HĐQT | G3: DUY TÂN GROUP | R3: CTY TNHH NHỰA TÁI CHẾ DUY TÂN | AH3: TRẠM VẬN HÀNH
E4: =+'Cấp bậc'!B5 -> HĐQT | F4: =+'Cấp bậc'!B6 -> CT HĐQT | G4: =+'Cấp bậc'!D5 -> GĐĐH-TC | H4: =+'Cấp bậc'!D6 -> GĐĐH-NS | I4: =+'Cấp bậc'!D7 -> GĐĐH-SX | J4: =+'Cấp bậc'!D8 -> GĐĐH-CCU | K4: =+'Cấp bậc'!D9 -> GĐĐH-KD | L4: =+'Cấp bậc'!D10 -> GĐPC | M4: =+'Cấp bậc'!D11 -> GĐCNTT | N4: =+'Cấp bậc'!D12 -> GĐPTBV | O4: =+'Cấp bậc'!D13 -> PGĐDA | P4: =+'Cấp bậc'!D14 -> GĐKSNB | Q4: =+'Cấp bậc'!D15 -> GĐHCQT | R4: =+'Cấp bậc'!F5 -> PTGĐ | S4: =+'Cấp bậc'!F6 -> GĐĐH | T4: =+'Cấp bậc'!F7 -> GĐTC | U4: =+'Cấp bậc'!F8 -> GĐPTKD | V4: =+'Cấp bậc'!F9 -> GĐNS | W4: =+'Cấp bậc'!F10 -> GĐKT | X4: =+'Cấp bậc'!F11 -> GĐSX | Y4: =+'Cấp bậc'!F12 -> GĐCCƯ | Z4: =+'Cấp bậc'!F13 -> GĐCLCCƯ | AA4: =+'Cấp bậc'!F14 -> GĐQLCL | AB4: =+'Cấp bậc'!F15 -> GĐR&D | AC4: =+'Cấp bậc'!F16 -> GĐĐH-T | AD4: =+'Cấp bậc'!F17 -> PGĐ | AE4: =+'Cấp bậc'!F18 -> KTT | AF4: =+'Cấp bậc'!F19 -> TP | AG4: =+'Cấp bậc'!F20 -> PP | AH4: =+'Cấp bậc'!H5 -> GĐT/TT | AI4: =+'Cấp bậc'!H6 -> KTT | AJ4: =+'Cấp bậc'!H7 -> TPNS | AK4: =+'Cấp bậc'!H8 -> QLSX | AL4: =+'Cấp bậc'!H9 -> TTKT | AM4: =+'Cấp bậc'!H10 -> QLCL | AN4: =+'Cấp bậc'!H11 -> QLK | AO4: =+'Cấp bậc'!H12 -> MH | AP4: =+'Cấp bậc'!H13 -> VHCN
E5: 1 | F5: =+E5+1 -> 2 | G5: =+F5+1 -> 3 | H5: =+G5+1 -> 4 | I5: =+H5+1 -> 5 | J5: =+I5+1 -> 6 | K5: =+J5+1 -> 7 | L5: =+K5+1 -> 8 | M5: =+L5+1 -> 9 | ... AP5: =+AO5+1 -> 38
B6: G | C6: THỦ TỤC ĐỀ NGHỊ THANH TOÁN & PHIẾU CHI THANH TOÁN (Sau khi Đề nghị đầu tư (Capex), Đề nghị mua hàng (Opex), Hợp đồng/PO đã được ký duyệt
B7: G1 | C7: Đề nghị thanh toán các khoản liên quan đến Đầu tư máy móc thiết bị, Công nghệ Thông tin - Capex | S7: A | T7: C | AE7: C
B8: G2 | C8: Đề nghị thanh toán các khoản liên quan đến Đầu tư công trình Xây dựng Cơ bản - Capex | S8: A | T8: C | AE8: C
B9: G3 | C9: Đề nghị thanh toán các khoản liên quan đến Chi phí vận hành sản xuất kinh doanh (Chi phí trực tiếp & gián tiếp) - Opex | S9: A | T9: C | AE9: C
B10: G4 | C10: Phiếu chi Thanh toán sau khi đề nghị Thanh toán được các cấp thẩm quyền duyệt | S10: A | T10: C | AE10: C

Sheet H.XNK & THUẾ
B2: Ký hiệu | C2: NỘI DUNG | D2: Giá trị _vnđ | E2: THẨM QUYỀN PHÊ DUYỆT | AQ2: Ghi chú
E3: HĐQT | G3: DUY TÂN GROUP | R3: CTY TNHH NHỰA TÁI CHẾ DUY TÂN | AH3: TRẠM VẬN HÀNH
E4: =+'Cấp bậc'!B5 -> HĐQT | F4: =+'Cấp bậc'!B6 -> CT HĐQT | G4: =+'Cấp bậc'!D5 -> GĐĐH-TC | H4: =+'Cấp bậc'!D6 -> GĐĐH-NS | I4: =+'Cấp bậc'!D7 -> GĐĐH-SX | J4: =+'Cấp bậc'!D8 -> GĐĐH-CCU | K4: =+'Cấp bậc'!D9 -> GĐĐH-KD | L4: =+'Cấp bậc'!D10 -> GĐPC | M4: =+'Cấp bậc'!D11 -> GĐCNTT | N4: =+'Cấp bậc'!D12 -> GĐPTBV | O4: =+'Cấp bậc'!D13 -> PGĐDA | P4: =+'Cấp bậc'!D14 -> GĐKSNB | Q4: =+'Cấp bậc'!D15 -> GĐHCQT | R4: =+'Cấp bậc'!F5 -> PTGĐ | S4: =+'Cấp bậc'!F6 -> GĐĐH | T4: =+'Cấp bậc'!F7 -> GĐTC | U4: =+'Cấp bậc'!F8 -> GĐPTKD | V4: =+'Cấp bậc'!F9 -> GĐNS | W4: =+'Cấp bậc'!F10 -> GĐKT | X4: =+'Cấp bậc'!F11 -> GĐSX | Y4: =+'Cấp bậc'!F12 -> GĐCCƯ | Z4: =+'Cấp bậc'!F13 -> GĐCLCCƯ | AA4: =+'Cấp bậc'!F14 -> GĐQLCL | AB4: =+'Cấp bậc'!F15 -> GĐR&D | AC4: =+'Cấp bậc'!F16 -> GĐĐH-T | AD4: =+'Cấp bậc'!F17 -> PGĐ | AE4: =+'Cấp bậc'!F18 -> KTT | AF4: =+'Cấp bậc'!F19 -> TP | AG4: =+'Cấp bậc'!F20 -> PP | AH4: =+'Cấp bậc'!H5 -> GĐT/TT | AI4: =+'Cấp bậc'!H6 -> KTT | AJ4: =+'Cấp bậc'!H7 -> TPNS | AK4: =+'Cấp bậc'!H8 -> QLSX | AL4: =+'Cấp bậc'!H9 -> TTKT | AM4: =+'Cấp bậc'!H10 -> QLCL | AN4: =+'Cấp bậc'!H11 -> QLK | AO4: =+'Cấp bậc'!H12 -> MH | AP4: =+'Cấp bậc'!H13 -> VHCN
E5: 1 | F5: =+E5+1 -> 2 | G5: =+F5+1 -> 3 | H5: =+G5+1 -> 4 | I5: =+H5+1 -> 5 | J5: =+I5+1 -> 6 | K5: =+J5+1 -> 7 | L5: =+K5+1 -> 8 | M5: =+L5+1 -> 9 | ... AP5: =+AO5+1 -> 38
B6: H | C6: THU TỤC XUẤT NHẬP KHẨU & THUẾ,HÓA ĐƠN
B7: H1 | C7: Thủ tục xuất khẩu
B8: H1.1 | C8: Ký các loại tờ khai Hải quan và các chứng từ, hồ sơ liên quan đến thủ tục xuất khẩu
B9: H2 | C9: Thủ tục nhập khẩu
B10: H2.1 | C10: Ký các loại tờ khai Hải quan và các chứng từ, hồ sơ liên quan đến thủ tục nhập khẩu
B11: H2.2 | C11: Ký sao y các loại chứng từ liên quan đến thủ tục xuất, nhập khẩu
B12: H3 | C12: Thủ tục liên quan đến Thuế, hóa đơn
B13: H3.1 | C13: Các tờ khai thuế Công ty: GTGT, Thu nhập doanh nghiệp, Thuế tài nguyên, sử dụng đất phi nông nghiệp | AE13: A
B14: H3.2 | C14: Các tờ khai thuế, phí và lệ phí khác của Công ty theo quy định pháp luật | AE14: A
B15: H3.3 | C15: Ký hóa đơn, biên bản điều chỉnh, hủy, mất hóa đơn, báo cáo tình hình sử dụng hóa đơn, các thủ tục liên quan đến hóa đơn | AE15: A
B16: H3.4 | C16: Bảng kê hàng hóa, đối chiếu công nợ (khách hàng/ NCC) | AE16: A

Sheet I.  KINH DOANH BH-HDONG
B2: Ký hiệu | C2: NỘI DUNG | D2: Giá trị _vnđ | E2: THẨM QUYỀN PHÊ DUYỆT | AQ2: Ghi chú
E3: HĐQT | G3: DUY TÂN GROUP | R3: CTY TNHH NHỰA TÁI CHẾ DUY TÂN | AH3: TRẠM VẬN HÀNH
E4: =+'Cấp bậc'!B5 -> HĐQT | F4: =+'Cấp bậc'!B6 -> CT HĐQT | G4: =+'Cấp bậc'!D5 -> GĐĐH-TC | H4: =+'Cấp bậc'!D6 -> GĐĐH-NS | I4: =+'Cấp bậc'!D7 -> GĐĐH-SX | J4: =+'Cấp bậc'!D8 -> GĐĐH-CCU | K4: =+'Cấp bậc'!D9 -> GĐĐH-KD | L4: =+'Cấp bậc'!D10 -> GĐPC | M4: =+'Cấp bậc'!D11 -> GĐCNTT | N4: =+'Cấp bậc'!D12 -> GĐPTBV | O4: =+'Cấp bậc'!D13 -> PGĐDA | P4: =+'Cấp bậc'!D14 -> GĐKSNB | Q4: =+'Cấp bậc'!D15 -> GĐHCQT | R4: =+'Cấp bậc'!F5 -> PTGĐ | S4: =+'Cấp bậc'!F6 -> GĐĐH | T4: =+'Cấp bậc'!F7 -> GĐTC | U4: =+'Cấp bậc'!F8 -> GĐPTKD | V4: =+'Cấp bậc'!F9 -> GĐNS | W4: =+'Cấp bậc'!F10 -> GĐKT | X4: =+'Cấp bậc'!F11 -> GĐSX | Y4: =+'Cấp bậc'!F12 -> GĐCCƯ | Z4: =+'Cấp bậc'!F13 -> GĐCLCCƯ | AA4: =+'Cấp bậc'!F14 -> GĐQLCL | AB4: =+'Cấp bậc'!F15 -> GĐR&D | AC4: =+'Cấp bậc'!F16 -> GĐĐH-T | AD4: =+'Cấp bậc'!F17 -> PGĐ | AE4: =+'Cấp bậc'!F18 -> KTT | AF4: =+'Cấp bậc'!F19 -> TP | AG4: =+'Cấp bậc'!F20 -> PP | AH4: =+'Cấp bậc'!H5 -> GĐT/TT | AI4: =+'Cấp bậc'!H6 -> KTT | AJ4: =+'Cấp bậc'!H7 -> TPNS | AK4: =+'Cấp bậc'!H8 -> QLSX | AL4: =+'Cấp bậc'!H9 -> TTKT | AM4: =+'Cấp bậc'!H10 -> QLCL | AN4: =+'Cấp bậc'!H11 -> QLK | AO4: =+'Cấp bậc'!H12 -> MH | AP4: =+'Cấp bậc'!H13 -> VHCN
E5: 1 | F5: =+E5+1 -> 2 | G5: =+F5+1 -> 3 | H5: =+G5+1 -> 4 | I5: =+H5+1 -> 5 | J5: =+I5+1 -> 6 | K5: =+J5+1 -> 7 | L5: =+K5+1 -> 8 | M5: =+L5+1 -> 9 | ... AP5: =+AO5+1 -> 38
B6: I | C6: KINH DOANH BÁN HÀNG
B7: I1 | C7: Kinh doanh bán hàng
B8: I1.1 | C8: Duyệt kế hoạch kinh doanh bán hàng năm
B9: I1.2 | C9: Duyệt bán hàng vượt hạn mức tín dụng (Credit Limit (CL))
B10: I1.3 | C10: Duyệt thay đổi tên, địa chỉ, tình trạng pháp lý của khách hàng trước khi điều chỉnh dữ liệu kinh doanh khách hàng
B11: I1.4 | C11: Duyệt bán hàng nợ có đảm bảo công nợ (Bank guarantee, thế chấp …)
B12: I1.5 | C12: Thiết lập/thay đổi tỷ lệ chiết khấu
B13: I1.6 | C13: Duyệt hoàn trả/bồi thường hàng hóa
B14: I2 | C14: Thủ tục duyệt giá bán & Hợp đồng Kinh doanh bán hàng
B15: I2.1 | C15: Phê duyệt giá bán
B16: I2.1.1 | C16: Duyệt bảng giá bán thành phẩm Nhựa Tái chế Duy Tân | F16: A
B17: I2.1.2 | C17: Duyệt bảng giá bán thành phẩm (hàng tháng) Nhựa Tái chế Duy Tân: chênh lệch +/- 10% so với giá bán đã được duyệt | F17: A
B18: I2.1.3 | C18: Duyệt giá bán thành phẩm Trạm vận hành Tái chế | F18: A | AQ18: GĐĐH-T & GĐT/TT tham vấn giá bán
B19: I2.1.4 | C19: Duyệt giá bán phó sản & các loại hàng hóa thanh lý khác | F19: A
B20: I3 | C20: Ký kết hợp đồng kinh doanh bán hàng | F20: A
B21: I3.1 | C21: Ký kết hợp đồng kinh doanh bán hàng nước ngoài (sau khi giá bán đã được duyệt) | D21: Giá trị>10 tỷ
D22: Giá trị<10 tỷ | F22: A, A1(*) | AC22: A1 | AH22: A | AQ22: A1(*): Ký nháy HĐ Trạm
D23: Giá trị<5 tỷ | G23: A1 | S23: A | AC23: A1 | AH23: A
B24: I3.2 | C24: Ký kết hợp đồng kinh doanh bán hàng nội địa (sau khi giá bán đã được duyệt) | D24: Giá trị>10 tỷ | AH24: A
D25: Giá trị<10 tỷ | F25: A, A1(*) | AH25: A | AQ25: A1(*): Ký nháy HĐ Trạm
D26: Giá trị<5 tỷ | G26: A1 | S26: A | AC26: A1 | AH26: A
B27: I3.3 | C27: Ký kết hợp đồng nguyên tắc không giá trị - nước ngoài và nội địa (tham chiếu Quy chế duyệt Hợp đồng của Pháp chế) | AH27: A
B28: I3.4 | C28: Ký kết hợp đồng bán hàng khác | D28: Giá trị>10 tỷ | F28: A, A1(*) | AQ28: A1(*): Ký nháy HĐ Trạm
D29: Giá trị<10 tỷ | G29: A1 | S29: A
D30: Giá trị<5 tỷ | S30: A | AC30: A1 | AH30: A
C32: Hợp đồng kinh doanh phải có ý kiến tham vấn của Phòng Tài chính DTR nhằm đảm bảo tính hợp lệ, hợp lý về mặt tài chính và kiểm soát rủi ro tài chính trước khi ký hợp đồng kinh doanh

Sheet J.TT HÀNH CHÍNH & VẬN HÀNH
B2: Ký hiệu | C2: NỘI DUNG | D2: Giá trị _vnđ | E2: THẨM QUYỀN PHÊ DUYỆT | AQ2: Ghi chú
E3: HĐQT | G3: DUY TÂN GROUP | R3: CTY TNHH NHỰA TÁI CHẾ DUY TÂN | AH3: TRẠM VẬN HÀNH
E4: =+'Cấp bậc'!B5 -> HĐQT | F4: =+'Cấp bậc'!B6 -> CT HĐQT | G4: =+'Cấp bậc'!D5 -> GĐĐH-TC | H4: =+'Cấp bậc'!D6 -> GĐĐH-NS | I4: =+'Cấp bậc'!D7 -> GĐĐH-SX | J4: =+'Cấp bậc'!D8 -> GĐĐH-CCU | K4: =+'Cấp bậc'!D9 -> GĐĐH-KD | L4: =+'Cấp bậc'!D10 -> GĐPC | M4: =+'Cấp bậc'!D11 -> GĐCNTT | N4: =+'Cấp bậc'!D12 -> GĐPTBV | O4: =+'Cấp bậc'!D13 -> PGĐDA | P4: =+'Cấp bậc'!D14 -> GĐKSNB | Q4: =+'Cấp bậc'!D15 -> GĐHCQT | R4: =+'Cấp bậc'!F5 -> PTGĐ | S4: =+'Cấp bậc'!F6 -> GĐĐH | T4: =+'Cấp bậc'!F7 -> GĐTC | U4: =+'Cấp bậc'!F8 -> GĐPTKD | V4: =+'Cấp bậc'!F9 -> GĐNS | W4: =+'Cấp bậc'!F10 -> GĐKT | X4: =+'Cấp bậc'!F11 -> GĐSX | Y4: =+'Cấp bậc'!F12 -> GĐCCƯ | Z4: =+'Cấp bậc'!F13 -> GĐCLCCƯ | AA4: =+'Cấp bậc'!F14 -> GĐQLCL | AB4: =+'Cấp bậc'!F15 -> GĐR&D | AC4: =+'Cấp bậc'!F16 -> GĐĐH-T | AD4: =+'Cấp bậc'!F17 -> PGĐ | AE4: =+'Cấp bậc'!F18 -> KTT | AF4: =+'Cấp bậc'!F19 -> TP | AG4: =+'Cấp bậc'!F20 -> PP | AH4: =+'Cấp bậc'!H5 -> GĐT/TT | AI4: =+'Cấp bậc'!H6 -> KTT | AJ4: =+'Cấp bậc'!H7 -> TPNS | AK4: =+'Cấp bậc'!H8 -> QLSX | AL4: =+'Cấp bậc'!H9 -> TTKT | AM4: =+'Cấp bậc'!H10 -> QLCL | AN4: =+'Cấp bậc'!H11 -> QLK | AO4: =+'Cấp bậc'!H12 -> MH | AP4: =+'Cấp bậc'!H13 -> VHCN
E5: 1 | F5: =+E5+1 -> 2 | G5: =+F5+1 -> 3 | H5: =+G5+1 -> 4 | I5: =+H5+1 -> 5 | J5: =+I5+1 -> 6 | K5: =+J5+1 -> 7 | L5: =+K5+1 -> 8 | M5: =+L5+1 -> 9 | ... AP5: =+AO5+1 -> 38
B6: J | C6: THỦ TỤC HÀNH CHÍNH & VẬN HÀNH
B7: J1 | C7: Quy trình vận hành 3Q: Quy trình, Quy định, Quy chế, Chính sách, Sổ tay, Cẩm nang
B8: J1.1 | C8: Quy trình vận hành 3Q do Duy Tân Group ban hành và các đơn vị thực hiện (căn cứ vào Quy định kiểm soát tài liệu) | H8: A
B9: J1.2 | C9: Quy trình vận hành 3Q do đơn vị ban hành và các phòng ban trong đơn vị thực hiện | AC9: A1 | AH9: A | AI9: S | AJ9: C | AK9: R | AL9: R | AM9: R | AN9: R | AO9: R | AP9: R
B10: J2 | C10: Quy trình soạn thảo và trình duyệt: Thẩm quyền phê duyệt-DOA
B11: J2.1 | C11: Quy trình soạn thảo và trình duyệt: Thẩm quyền phê duyệt-DOA: Chủ Tịch HĐQT/HĐTV/CSH phân quyền ký duyệt và điều hành cho các cập điều hành, quản lý các vận hành của các Công ty Thành viên theo Quy chế Quản lý Tập trung của DTG | F11: A
B12: J3 | C12: Các thủ tục, văn bản liên quan đến lĩnh vực HCNS & cơ quan hữu quan
B13: J3.1 | C13: Văn bản Công ty gửi các cơ quan Nhà nước & đối tác: thực hiện các quy định của Bộ Lao Động, BHXH & các quy định liên quan sử dụng lao động
B14: J3.2 | C14: Thông báo nội bộ Công ty, sao y bản chính chứng từ hành chính, văn bản hành chính nội bộ
B15: J3.3 | C15: Hồ sơ văn bản liên quan đến Người lao động: mở thẻ tại Ngân hàng, xác nhận mức lương, tờ khai thuế, thời gian công tác
B16: J3.4 | C16: Văn bản liên quan thủ tục Chuyên gia nhập cảnh, xuất cảnh, cách ly do dịch bệnh, lưu trú, di chuyển…
B17: J3.5 | C17: Văn bản của Công ty gửi các cơ quan Nhà nước, đối tác, tổ chức, cá nhân, khách hàng
B18: J3.6 | C18: Cung cấp các thông tin, tài liệu theo yêu cầu của các Cơ quan nhà nước có thẩm quyền và ký tên trên các văn bản có liên quan
B19: J3.7 | C19: Làm việc với bên ngoài (cơ quan nhà nước, đối tác, khách hàng…)
B20: J3.8 | C20: Điều chuyển tài sản, thiết bị, công cụ trừ máy móc phục vụ sản xuất cho đơn vị khác.
B21: J3.9 | C21: Cho phép bên ngoài thuê, mượn tài sản, thiết bị, dụng cụ trừ máy móc phục vụ sản xuất
B22: J3.10 | C22: Bảo trì các loại xe của công ty
B23: J4 | C23: Thủ tục liên quan công tác
... B38: J5.8 | C38: Các hồ sơ liên quan hoạt động đánh giá chứng nhận, audit khác

Sheet K. QL CHẤT LƯỢNG
B2: Ký hiệu | C2: NỘI DUNG | D2: Giá trị _vnđ | E2: THẨM QUYỀN PHÊ DUYỆT | AQ2: Ghi chú
E3: HĐQT | G3: DUY TÂN GROUP | R3: CTY TNHH NHỰA TÁI CHẾ DUY TÂN | AH3: TRẠM VẬN HÀNH
E4: =+'Cấp bậc'!B5 -> HĐQT | F4: =+'Cấp bậc'!B6 -> CT HĐQT | G4: =+'Cấp bậc'!D5 -> GĐĐH-TC | H4: =+'Cấp bậc'!D6 -> GĐĐH-NS | I4: =+'Cấp bậc'!D7 -> GĐĐH-SX | J4: =+'Cấp bậc'!D8 -> GĐĐH-CCU | K4: =+'Cấp bậc'!D9 -> GĐĐH-KD | L4: =+'Cấp bậc'!D10 -> GĐPC | M4: =+'Cấp bậc'!D11 -> GĐCNTT | N4: =+'Cấp bậc'!D12 -> GĐPTBV | O4: =+'Cấp bậc'!D13 -> PGĐDA | P4: =+'Cấp bậc'!D14 -> GĐKSNB | Q4: =+'Cấp bậc'!D15 -> GĐHCQT | R4: =+'Cấp bậc'!F5 -> PTGĐ | S4: =+'Cấp bậc'!F6 -> GĐĐH | T4: =+'Cấp bậc'!F7 -> GĐTC | U4: =+'Cấp bậc'!F8 -> GĐPTKD | V4: =+'Cấp bậc'!F9 -> GĐNS | W4: =+'Cấp bậc'!F10 -> GĐKT | X4: =+'Cấp bậc'!F11 -> GĐSX | Y4: =+'Cấp bậc'!F12 -> GĐCCƯ | Z4: =+'Cấp bậc'!F13 -> GĐCLCCƯ | AA4: =+'Cấp bậc'!F14 -> GĐQLCL | AB4: =+'Cấp bậc'!F15 -> GĐR&D | AC4: =+'Cấp bậc'!F16 -> GĐĐH-T | AD4: =+'Cấp bậc'!F17 -> PGĐ | AE4: =+'Cấp bậc'!F18 -> KTT | AF4: =+'Cấp bậc'!F19 -> TP | AG4: =+'Cấp bậc'!F20 -> PP | AH4: =+'Cấp bậc'!H5 -> GĐT/TT | AI4: =+'Cấp bậc'!H6 -> KTT | AJ4: =+'Cấp bậc'!H7 -> TPNS | AK4: =+'Cấp bậc'!H8 -> QLSX | AL4: =+'Cấp bậc'!H9 -> TTKT | AM4: =+'Cấp bậc'!H10 -> QLCL | AN4: =+'Cấp bậc'!H11 -> QLK | AO4: =+'Cấp bậc'!H12 -> MH | AP4: =+'Cấp bậc'!H13 -> VHCN
E5: 1 | F5: =+E5+1 -> 2 | G5: =+F5+1 -> 3 | H5: =+G5+1 -> 4 | I5: =+H5+1 -> 5 | J5: =+I5+1 -> 6 | K5: =+J5+1 -> 7 | L5: =+K5+1 -> 8 | M5: =+L5+1 -> 9 | ... AP5: =+AO5+1 -> 38
B6: K | C6: QUẢN LÝ CHẤT LƯỢNG
B7: K1 | C7: Thiết lập tiêu chuẩn chất lượng
B8: K1.1 | C8: Nguyên vật liệu/ phụ tùng
B9: K1.2 | C9: Sản phẩm.
B10: K2 | C10: Thiết lập thủ tục kiểm soát chất lượng và phương pháp kiểm tra mẫu sản phẩm và nguyên vật liệu sản xuất.
B11: K3 | C11: Phê duyệt kết quả kiểm tra chất lượng nguyên vật liệu/sản phẩm & vật tư liên quan đến Sản xuất
B12: K3.1 | C12: Chứng nhận chất lượng sản phẩm.
B13: K3.2 | C13: Cung cấp dịch vụ kiểm tra sản phẩm/vật tư
B14: K3.3 | C14: Báo cáo kết quả kiểm tra nguyên vật liệu.
B15: K4 | C15: Gửi sản phẩm/nguyên vật liệu kiểm tra ở tổ chức bên ngoài đơn vị
B16: K4.1 | C16: Trong DTG
B17: K4.2 | C17: Tổ chức trong nước.
... B19: K5 | C19: Phê duyệt cấp phát nguyên vật liệu thô/hóa chất/vật liệu sản xuất khác hay phụ tùng khác/ bán thành phẩm/ sản phẩm cho mục đích kiểm tra và kiểm soát chất lượng.

Sheet L.TIẾP THỊ & TRUYỀN THÔNG
B2: Ký hiệu | C2: NỘI DUNG | D2: Giá trị _vnđ | E2: THẨM QUYỀN PHÊ DUYỆT | AQ2: Ghi chú
E3: HĐQT | G3: DUY TÂN GROUP | R3: CTY TNHH NHỰA TÁI CHẾ DUY TÂN | AH3: TRẠM VẬN HÀNH
E4: =+'Cấp bậc'!B5 -> HĐQT | F4: =+'Cấp bậc'!B6 -> CT HĐQT | G4: =+'Cấp bậc'!D5 -> GĐĐH-TC | H4: =+'Cấp bậc'!D6 -> GĐĐH-NS | I4: =+'Cấp bậc'!D7 -> GĐĐH-SX | J4: =+'Cấp bậc'!D8 -> GĐĐH-CCU | K4: =+'Cấp bậc'!D9 -> GĐĐH-KD | L4: =+'Cấp bậc'!D10 -> GĐPC | M4: =+'Cấp bậc'!D11 -> GĐCNTT | N4: =+'Cấp bậc'!D12 -> GĐPTBV | O4: =+'Cấp bậc'!D13 -> PGĐDA | P4: =+'Cấp bậc'!D14 -> GĐKSNB | Q4: =+'Cấp bậc'!D15 -> GĐHCQT | R4: =+'Cấp bậc'!F5 -> PTGĐ | S4: =+'Cấp bậc'!F6 -> GĐĐH | T4: =+'Cấp bậc'!F7 -> GĐTC | U4: =+'Cấp bậc'!F8 -> GĐPTKD | V4: =+'Cấp bậc'!F9 -> GĐNS | W4: =+'Cấp bậc'!F10 -> GĐKT | X4: =+'Cấp bậc'!F11 -> GĐSX | Y4: =+'Cấp bậc'!F12 -> GĐCCƯ | Z4: =+'Cấp bậc'!F13 -> GĐCLCCƯ | AA4: =+'Cấp bậc'!F14 -> GĐQLCL | AB4: =+'Cấp bậc'!F15 -> GĐR&D | AC4: =+'Cấp bậc'!F16 -> GĐĐH-T | AD4: =+'Cấp bậc'!F17 -> PGĐ | AE4: =+'Cấp bậc'!F18 -> KTT | AF4: =+'Cấp bậc'!F19 -> TP | AG4: =+'Cấp bậc'!F20 -> PP | AH4: =+'Cấp bậc'!H5 -> GĐT/TT | AI4: =+'Cấp bậc'!H6 -> KTT | AJ4: =+'Cấp bậc'!H7 -> TPNS | AK4: =+'Cấp bậc'!H8 -> QLSX | AL4: =+'Cấp bậc'!H9 -> TTKT | AM4: =+'Cấp bậc'!H10 -> QLCL | AN4: =+'Cấp bậc'!H11 -> QLK | AO4: =+'Cấp bậc'!H12 -> MH | AP4: =+'Cấp bậc'!H13 -> VHCN
E5: 1 | F5: =+E5+1 -> 2 | G5: =+F5+1 -> 3 | H5: =+G5+1 -> 4 | I5: =+H5+1 -> 5 | J5: =+I5+1 -> 6 | K5: =+J5+1 -> 7 | L5: =+K5+1 -> 8 | M5: =+L5+1 -> 9 | ... AP5: =+AO5+1 -> 38
B6: L | C6: TRUYỀN THÔNG, TIẾP THỊ & NGHIÊN CỨU THỊ TRƯỜNG
B7: L1 | C7: Truyền Thông
B8: L1.1 | C8: Xây dựng Thương Hiệu: Biểu trưng (logo), Khẩu hiệu (slogan), Người phát ngôn
B9: L1.2 | C9: Định hướng truyền thông, Câu chuyện của thương hiệu, Định vị thương hiệu,
B10: L1.3 | C10: Thông cáo báo chí
B11: L1.4 | C11: Ra quyết định Xử lý khủng hoảng truyền thông
B12: L1.5 | C12: Thuê ngoài/ mua thông tin/ tin tức thị trường tại mỗi thời điểm
B13: L1.6 | C13: Đề xuất tiếp thị, quảng cảo/ truyền thông
B14: L2 | C14: Tiếp thị & nghiên cứu thị trường
B15: L2.1 | C15: Thực hiện triển lãm hàng hóa.
B16: L2.2 | C16: Thỏa thuận phí bản quyền
B17: L2.3 | C17: Nghiên cứu thị trường/ dịch vụ kỹ thuật, giá trị trong ngân sách.
... B19: L2.5 | C19: Đăng ký kinh doanh thương mại điện tử.

Sheet M.SẢN XUẤT
B2: Ký hiệu | C2: NỘI DUNG | D2: Giá trị _vnđ | E2: THẨM QUYỀN PHÊ DUYỆT | AQ2: Ghi chú
E3: HĐQT | G3: DUY TÂN GROUP | R3: CTY TNHH NHỰA TÁI CHẾ DUY TÂN | AH3: TRẠM VẬN HÀNH
E4: =+'Cấp bậc'!B5 -> HĐQT | F4: =+'Cấp bậc'!B6 -> CT HĐQT | G4: =+'Cấp bậc'!D5 -> GĐĐH-TC | H4: =+'Cấp bậc'!D6 -> GĐĐH-NS | I4: =+'Cấp bậc'!D7 -> GĐĐH-SX | J4: =+'Cấp bậc'!D8 -> GĐĐH-CCU | K4: =+'Cấp bậc'!D9 -> GĐĐH-KD | L4: =+'Cấp bậc'!D10 -> GĐPC | M4: =+'Cấp bậc'!D11 -> GĐCNTT | N4: =+'Cấp bậc'!D12 -> GĐPTBV | O4: =+'Cấp bậc'!D13 -> PGĐDA | P4: =+'Cấp bậc'!D14 -> GĐKSNB | Q4: =+'Cấp bậc'!D15 -> GĐHCQT | R4: =+'Cấp bậc'!F5 -> PTGĐ | S4: =+'Cấp bậc'!F6 -> GĐĐH | T4: =+'Cấp bậc'!F7 -> GĐTC | U4: =+'Cấp bậc'!F8 -> GĐPTKD | V4: =+'Cấp bậc'!F9 -> GĐNS | W4: =+'Cấp bậc'!F10 -> GĐKT | X4: =+'Cấp bậc'!F11 -> GĐSX | Y4: =+'Cấp bậc'!F12 -> GĐCCƯ | Z4: =+'Cấp bậc'!F13 -> GĐCLCCƯ | AA4: =+'Cấp bậc'!F14 -> GĐQLCL | AB4: =+'Cấp bậc'!F15 -> GĐR&D | AC4: =+'Cấp bậc'!F16 -> GĐĐH-T | AD4: =+'Cấp bậc'!F17 -> PGĐ | AE4: =+'Cấp bậc'!F18 -> KTT | AF4: =+'Cấp bậc'!F19 -> TP | AG4: =+'Cấp bậc'!F20 -> PP | AH4: =+'Cấp bậc'!H5 -> GĐT/TT | AI4: =+'Cấp bậc'!H6 -> KTT | AJ4: =+'Cấp bậc'!H7 -> TPNS | AK4: =+'Cấp bậc'!H8 -> QLSX | AL4: =+'Cấp bậc'!H9 -> TTKT | AM4: =+'Cấp bậc'!H10 -> QLCL | AN4: =+'Cấp bậc'!H11 -> QLK | AO4: =+'Cấp bậc'!H12 -> MH | AP4: =+'Cấp bậc'!H13 -> VHCN
E5: 1 | F5: =+E5+1 -> 2 | G5: =+F5+1 -> 3 | H5: =+G5+1 -> 4 | I5: =+H5+1 -> 5 | J5: =+I5+1 -> 6 | K5: =+J5+1 -> 7 | L5: =+K5+1 -> 8 | M5: =+L5+1 -> 9 | ... AP5: =+AO5+1 -> 38
B6: M | C6: SẢN XUẤT
B7: M1 | C7: Phê duyệt Kế hoạch sản xuất hàng năm
B8: M2 | C8: Thiết lập/thay đổi kế hoạch sản xuất bao gồm phê duyệt sản xuất | X8: S | AC8: C | AH8: A | AK8: R
B9: M3 | C9: Phê duyệt sản xuất | X9: S | AC9: C | AH9: A | AK9: R
B10: M4 | C10: Phê duyệt chất lượng sản xuất | Z10: S | AC10: C | AH10: A | AK10: R
B11: M5 | C11: Thông báo kiểm tra/điều chỉnh máy móc để cải tiến quy trình sản xuất | W11: S | AC11: C | AH11: A | AK11: R
B12: M6 | C12: Yêu cầu bắt đầu sản xuất hoặc ngưng sản xuất | X12: S | AC12: C | AH12: A | AK12: R
B13: M7 | C13: Phê duyệt xử lý nguyên vật liệu hao hụt trong sản xuất | X13: S | AC13: C | AH13: A | AK13: R
B14: M8 | C14: Phê duyệt cấp phát nguyên vật liệu/phụ tùng bán thành phẩm để sản xuất | AC14: C | AH14: A | AK14: R
B15: M9 | C15: Thiết lập chiêu chuẩn chất lượng cho tương ứng với tỷ lệ nguyên liệu | X15: S | AC15: C | AH15: A | AK15: R
B16: M10 | C16: Phê duyệt chứng từ sản xuất: thành phẩm | AH16: A | AK16: R
B17: M11 | C17: Phê duyệt chứng từ sản xuất: bán thành phẩm | AH17: A | AK17: R
B18: M12 | C18: Phê duyệt hao hụt trong quá trình sản xuất | AH18: A | AK18: R

Sheet N.QUẢN LÝ KHO
B2: Ký hiệu | C2: NỘI DUNG | D2: Giá trị _vnđ | E2: THẨM QUYỀN PHÊ DUYỆT | AQ2: Ghi chú
E3: HĐQT | G3: DUY TÂN GROUP | R3: CTY TNHH NHỰA TÁI CHẾ DUY TÂN | AH3: TRẠM VẬN HÀNH
E4: =+'Cấp bậc'!B5 -> HĐQT | F4: =+'Cấp bậc'!B6 -> CT HĐQT | G4: =+'Cấp bậc'!D5 -> GĐĐH-TC | H4: =+'Cấp bậc'!D6 -> GĐĐH-NS | I4: =+'Cấp bậc'!D7 -> GĐĐH-SX | J4: =+'Cấp bậc'!D8 -> GĐĐH-CCU | K4: =+'Cấp bậc'!D9 -> GĐĐH-KD | L4: =+'Cấp bậc'!D10 -> GĐPC | M4: =+'Cấp bậc'!D11 -> GĐCNTT | N4: =+'Cấp bậc'!D12 -> GĐPTBV | O4: =+'Cấp bậc'!D13 -> PGĐDA | P4: =+'Cấp bậc'!D14 -> GĐKSNB | Q4: =+'Cấp bậc'!D15 -> GĐHCQT | R4: =+'Cấp bậc'!F5 -> PTGĐ | S4: =+'Cấp bậc'!F6 -> GĐĐH | T4: =+'Cấp bậc'!F7 -> GĐTC | U4: =+'Cấp bậc'!F8 -> GĐPTKD | V4: =+'Cấp bậc'!F9 -> GĐNS | W4: =+'Cấp bậc'!F10 -> GĐKT | X4: =+'Cấp bậc'!F11 -> GĐSX | Y4: =+'Cấp bậc'!F12 -> GĐCCƯ | Z4: =+'Cấp bậc'!F13 -> GĐCLCCƯ | AA4: =+'Cấp bậc'!F14 -> GĐQLCL | AB4: =+'Cấp bậc'!F15 -> GĐR&D | AC4: =+'Cấp bậc'!F16 -> GĐĐH-T | AD4: =+'Cấp bậc'!F17 -> PGĐ | AE4: =+'Cấp bậc'!F18 -> KTT | AF4: =+'Cấp bậc'!F19 -> TP | AG4: =+'Cấp bậc'!F20 -> PP | AH4: =+'Cấp bậc'!H5 -> GĐT/TT | AI4: =+'Cấp bậc'!H6 -> KTT | AJ4: =+'Cấp bậc'!H7 -> TPNS | AK4: =+'Cấp bậc'!H8 -> QLSX | AL4: =+'Cấp bậc'!H9 -> TTKT | AM4: =+'Cấp bậc'!H10 -> QLCL | AN4: =+'Cấp bậc'!H11 -> QLK | AO4: =+'Cấp bậc'!H12 -> MH | AP4: =+'Cấp bậc'!H13 -> VHCN
E5: 1 | F5: =+E5+1 -> 2 | G5: =+F5+1 -> 3 | H5: =+G5+1 -> 4 | I5: =+H5+1 -> 5 | J5: =+I5+1 -> 6 | K5: =+J5+1 -> 7 | L5: =+K5+1 -> 8 | M5: =+L5+1 -> 9 | ... AP5: =+AO5+1 -> 38
B6: N | C6: QUẢN LÝ KHO
B7: N1 | C7: Quản trị vận hành kho
B8: N1.1 | C8: Duyệt mức tồn kho (stock level) các loại hàng hóa, nguyên vật liệu, thành phầm, bán thành phẩm, công cụ dụng cụ, bao bì….. | AH8: A | AK8: R
B9: N1.2 | C9: Duyệt chuyển kho hàng hóa (kho nội bộ & kho thuê) | AH9: A | AK9: R
B10: N1.3 | C10: Phê duyệt hàng hóa hư hỏng trong quá trình lưu kho, vận chuyển nội bộ, giao hàng bán khách hàng | AH10: A | AK10: R
B11: N1.4 | C11: Thiết lập/thay đổi sơ đồ bố trí kho, phương thức lưu trữ và bảo quản vật tư | AH11: A | AK11: R
B12: N1.5 | C12: Quyết định kiểm kê kho xưởng/kho kỹ thuật | AH12: A | AK12: R
B13: N1.6 | C13: Biên bản kiểm kê kho | AH13: A | AK13: R
B14: N1.7 | C14: Giải trình biên bản kiểm kê/điều chỉnh sau kiểm kê | AH14: A | AK14: R
B15: N1.8 | C15: Đề xuất chuyển mã lưu kho | AH15: A | AK15: R
B16: N2 | C16: Xuất kho
B17: N2.1 | C17: Xuất Nguyên Vật Liệu sản xuất
B18: N2.1.1 | C18: Xuất nguyên vật liệu chính/ Bán thành phẩm | AH18: A | AK18: R
B19: N2.1.2 | C19: Nguyên vật liệu sản xuất khác | AH19: A | AK19: R
B20: N2.1.3 | C20: Các hàng hoá khác (vật tư kỹ thuật, phụ tùng xe, công cụ dụng cụ,...) | AH20: A | AK20: R
B21: N2.1.4 | C21: Xuất hàng mua trực tiếp từ nhà cung cấp nội địa | AH21: A | AK21: R
B22: N2.1.5 | C22: Xuất nguyên vật liệu để kiểm tra chất lượng, mẫu/ gửi Nhà cung cấp | AH22: A | AK22: R
B23: N2.2 | C23: Xuất gia công (đơn vị thứ ba)
B24: N2.2.1 | C24: Xuất gia công của vật tư sản xuất | AH24: A | AK24: R
B25: N2.2.2 | C25: Xuất gia công khác | AH25: A | AK25: R
B26: N2.3 | C26: Thành phẩm
B27: N2.3.1 | C27: Xuất kho thành phẩm bán/ Xuất kho thành phẩm vận chuyển nội bộ | AH27: A | AK27: R
B28: N2.3.2 | C28: Xuất kho thành phẩm làm hàng mẫu | AH28: A | AK28: R
B29: N2.3.3 | C29: Xuất kho thành phẩm hàng biếu | AH29: A | AK29: R
B30: N2.4 | C30: Xuất nhiên liệu cho dịch vụ
B31: N2.4.1 | C31: Cấp phát xăng dầu cho vận tải phục vụ sản xuất | AH31: A | AK31: R
B32: N2.4.2 | C32: Cấp phát xăng dầu cho dịch vụ xe du lịch | AH32: A | AK32: R
B33: N2.5 | C33: Xuất khác
B34: N2.5.1 | C34: Các hàng hoá khác (vật tư kỹ thuật, phụ tùng xe, công cụ dụng cụ,...) | AH34: A | AK34: R
B35: N2.5.2 | C35: Xuất hàng mua trực tiếp từ nhà cung cấp nội địa | AH35: A | AK35: R
B36: N2.5.3 | C36: Xuất kho hàng mẫu gửi khách hàng trong ngân sách được duyệt | AH36: A | AK36: R

Sheet O. CUNG ỨNG-MUA HÀNG
B2: Ký hiệu | C2: NỘI DUNG | D2: Giá trị _vnđ | E2: THẨM QUYỀN PHÊ DUYỆT | AQ2: Ghi chú
E3: HĐQT | G3: DUY TÂN GROUP | R3: CTY TNHH NHỰA TÁI CHẾ DUY TÂN | AH3: TRẠM VẬN HÀNH
E4: =+'Cấp bậc'!B5 -> HĐQT | F4: =+'Cấp bậc'!B6 -> CT HĐQT | G4: =+'Cấp bậc'!D5 -> GĐĐH-TC | H4: =+'Cấp bậc'!D6 -> GĐĐH-NS | I4: =+'Cấp bậc'!D7 -> GĐĐH-SX | J4: =+'Cấp bậc'!D8 -> GĐĐH-CCU | K4: =+'Cấp bậc'!D9 -> GĐĐH-KD | L4: =+'Cấp bậc'!D10 -> GĐPC | M4: =+'Cấp bậc'!D11 -> GĐCNTT | N4: =+'Cấp bậc'!D12 -> GĐPTBV | O4: =+'Cấp bậc'!D13 -> PGĐDA | P4: =+'Cấp bậc'!D14 -> GĐKSNB | Q4: =+'Cấp bậc'!D15 -> GĐHCQT | R4: =+'Cấp bậc'!F5 -> PTGĐ | S4: =+'Cấp bậc'!F6 -> GĐĐH | T4: =+'Cấp bậc'!F7 -> GĐTC | U4: =+'Cấp bậc'!F8 -> GĐPTKD | V4: =+'Cấp bậc'!F9 -> GĐNS | W4: =+'Cấp bậc'!F10 -> GĐKT | X4: =+'Cấp bậc'!F11 -> GĐSX | Y4: =+'Cấp bậc'!F12 -> GĐCCƯ | Z4: =+'Cấp bậc'!F13 -> GĐCLCCƯ | AA4: =+'Cấp bậc'!F14 -> GĐQLCL | AB4: =+'Cấp bậc'!F15 -> GĐR&D | AC4: =+'Cấp bậc'!F16 -> GĐĐH-T | AD4: =+'Cấp bậc'!F17 -> PGĐ | AE4: =+'Cấp bậc'!F18 -> KTT | AF4: =+'Cấp bậc'!F19 -> TP | AG4: =+'Cấp bậc'!F20 -> PP | AH4: =+'Cấp bậc'!H5 -> GĐT/TT | AI4: =+'Cấp bậc'!H6 -> KTT | AJ4: =+'Cấp bậc'!H7 -> TPNS | AK4: =+'Cấp bậc'!H8 -> QLSX | AL4: =+'Cấp bậc'!H9 -> TTKT | AM4: =+'Cấp bậc'!H10 -> QLCL | AN4: =+'Cấp bậc'!H11 -> QLK | AO4: =+'Cấp bậc'!H12 -> MH | AP4: =+'Cấp bậc'!H13 -> VHCN
E5: 1 | F5: =+E5+1 -> 2 | G5: =+F5+1 -> 3 | H5: =+G5+1 -> 4 | I5: =+H5+1 -> 5 | J5: =+I5+1 -> 6 | K5: =+J5+1 -> 7 | L5: =+K5+1 -> 8 | M5: =+L5+1 -> 9 | ... AP5: =+AO5+1 -> 38
B6: O | C6: CUNG ỨNG & MUA HÀNG HÓA DỊCH VỤ
B7: O1 | C7: Cung Ứng Nguyên vật liệu
B8: O1.1 | C8: Duyệt mở đơn vị cung ứng nguyên vật liệu rác thải nhựa | Z8: A | AC8: I | AH8: I
B9: O1.2 | C9: Duyệt thời hạn nợ (nhà cung cấp) | Z9: A | AC9: I | AH9: I
B10: O1.3 | C10: Duyệt chỉ tiêu mua hàng | Z10: A | AC10: I | AH10: I
B11: O1.3.1 | C11: Chỉ tiêu mua hàng NCC | Z11: A | AC11: I | AH11: I
B12: O1.3.2 | C12: Chỉ tiêu NCC cung ứng nguyên liệu rác thải nhựa | Z12: A | AC12: I | AH12: I
B13: O1.4 | C13: Phiếu đánh giá Nhà Cung Cấp định kỳ và theo dõi Nhà Cung cấp mới | Z13: I | AC13: S | AH13: A
B14: O2 | C14: Mua hàng hóa dịch vụ
B15: O2.1 | C15: Duyệt báo giá & lựa chọn Nhà cung cấp | AF15: A
B16: O2.2 | C16: Duyệt đơn hàng (PO) | AC16: I | AF16: C | AH16: A
B17: O2.3 | C17: Hủy/điều chỉnh Đơn Đặt Hàng (P/O) đã được thực hiện | AC17: I | AF17: C | AH17: A
B18: O2.4 | C18: Duyệt thời hạn nợ (nhà cung cấp) | AF18: A
B19: O2.5 | C19: Đánh giá Nhà Cung Cấp định kỳ và theo dõi Nhà Cung cấp mới | AF19: A1 | AH19: A

Sheet P.VẬN HÀNH SALES
B2: Ký hiệu | C2: NỘI DUNG | D2: Giá trị _vnđ | E2: THẨM QUYỀN PHÊ DUYỆT | AQ2: Ghi chú
E3: HĐQT | G3: DUY TÂN GROUP | R3: CTY TNHH NHỰA TÁI CHẾ DUY TÂN | AH3: TRẠM VẬN HÀNH
E4: =+'Cấp bậc'!B5 -> HĐQT | F4: =+'Cấp bậc'!B6 -> CT HĐQT | G4: =+'Cấp bậc'!D5 -> GĐĐH-TC | H4: =+'Cấp bậc'!D6 -> GĐĐH-NS | I4: =+'Cấp bậc'!D7 -> GĐĐH-SX | J4: =+'Cấp bậc'!D8 -> GĐĐH-CCU | K4: =+'Cấp bậc'!D9 -> GĐĐH-KD | L4: =+'Cấp bậc'!D10 -> GĐPC | M4: =+'Cấp bậc'!D11 -> GĐCNTT | N4: =+'Cấp bậc'!D12 -> GĐPTBV | O4: =+'Cấp bậc'!D13 -> PGĐDA | P4: =+'Cấp bậc'!D14 -> GĐKSNB | Q4: =+'Cấp bậc'!D15 -> GĐHCQT | R4: =+'Cấp bậc'!F5 -> PTGĐ | S4: =+'Cấp bậc'!F6 -> GĐĐH | T4: =+'Cấp bậc'!F7 -> GĐTC | U4: =+'Cấp bậc'!F8 -> GĐPTKD | V4: =+'Cấp bậc'!F9 -> GĐNS | W4: =+'Cấp bậc'!F10 -> GĐKT | X4: =+'Cấp bậc'!F11 -> GĐSX | Y4: =+'Cấp bậc'!F12 -> GĐCCƯ | Z4: =+'Cấp bậc'!F13 -> GĐCLCCƯ | AA4: =+'Cấp bậc'!F14 -> GĐQLCL | AB4: =+'Cấp bậc'!F15 -> GĐR&D | AC4: =+'Cấp bậc'!F16 -> GĐĐH-T | AD4: =+'Cấp bậc'!F17 -> PGĐ | AE4: =+'Cấp bậc'!F18 -> KTT | AF4: =+'Cấp bậc'!F19 -> TP | AG4: =+'Cấp bậc'!F20 -> PP | AH4: =+'Cấp bậc'!H5 -> GĐT/TT | AI4: =+'Cấp bậc'!H6 -> KTT | AJ4: =+'Cấp bậc'!H7 -> TPNS | AK4: =+'Cấp bậc'!H8 -> QLSX | AL4: =+'Cấp bậc'!H9 -> TTKT | AM4: =+'Cấp bậc'!H10 -> QLCL | AN4: =+'Cấp bậc'!H11 -> QLK | AO4: =+'Cấp bậc'!H12 -> MH | AP4: =+'Cấp bậc'!H13 -> VHCN
E5: 1 | F5: =+E5+1 -> 2 | G5: =+F5+1 -> 3 | H5: =+G5+1 -> 4 | I5: =+H5+1 -> 5 | J5: =+I5+1 -> 6 | K5: =+J5+1 -> 7 | L5: =+K5+1 -> 8 | M5: =+L5+1 -> 9 | ... AP5: =+AO5+1 -> 38
B6: P | C6: THỦ TỤC VẬN HÀNH BÁN HÀNG
B7: P1 | C7: Kế hoạch bán hàng
B8: P1.1 | C8: Duyệt kế hoạch bán hàng hàng năm
B9: P1.2 | C9: Hiệu chỉnh kế hoạch bàn hàng hàng năm
B10: P2 | C10: Tín dụng & Chiết khấu
B11: P2.1 | C11: Duyệt thay đổi hạn mức tín dụng
B12: P2.2 | C12: Duyệt bán hàng vượt hạn mức tín dụng ngoại trừ khách hàng loại
B13: P2.3 | C13: Duyệt thay đổi tài sản thế chấp khách hàng đảm bảo hạn mức tín dụng
B14: P2.4 | C14: Thiết lập điều kiện bán hàng, điều kiện trả hàng, phương thức thanh toán
B15: P2.5 | C15: Duyệt chiết khấu
B16: P3 | C16: Vận hành kinh doanh bán hàng
B17: P3.1 | C17: Hoa hồng bán hàng: thiết lập mức hóa hồng bán hàng
... B25: P4.5 | C25: Duyệt mở Nhà phân phối

Sheet Q.R&D
B2: Ký hiệu | C2: NỘI DUNG | D2: Giá trị _vnđ | E2: THẨM QUYỀN PHÊ DUYỆT | AQ2: Ghi chú
E3: HĐQT | G3: DUY TÂN GROUP | R3: CTY TNHH NHỰA TÁI CHẾ DUY TÂN | AH3: TRẠM VẬN HÀNH
E4: =+'Cấp bậc'!B5 -> HĐQT | F4: =+'Cấp bậc'!B6 -> CT HĐQT | G4: =+'Cấp bậc'!D5 -> GĐĐH-TC | H4: =+'Cấp bậc'!D6 -> GĐĐH-NS | I4: =+'Cấp bậc'!D7 -> GĐĐH-SX | J4: =+'Cấp bậc'!D8 -> GĐĐH-CCU | K4: =+'Cấp bậc'!D9 -> GĐĐH-KD | L4: =+'Cấp bậc'!D10 -> GĐPC | M4: =+'Cấp bậc'!D11 -> GĐCNTT | N4: =+'Cấp bậc'!D12 -> GĐPTBV | O4: =+'Cấp bậc'!D13 -> PGĐDA | P4: =+'Cấp bậc'!D14 -> GĐKSNB | Q4: =+'Cấp bậc'!D15 -> GĐHCQT | R4: =+'Cấp bậc'!F5 -> PTGĐ | S4: =+'Cấp bậc'!F6 -> GĐĐH | T4: =+'Cấp bậc'!F7 -> GĐTC | U4: =+'Cấp bậc'!F8 -> GĐPTKD | V4: =+'Cấp bậc'!F9 -> GĐNS | W4: =+'Cấp bậc'!F10 -> GĐKT | X4: =+'Cấp bậc'!F11 -> GĐSX | Y4: =+'Cấp bậc'!F12 -> GĐCCƯ | Z4: =+'Cấp bậc'!F13 -> GĐCLCCƯ | AA4: =+'Cấp bậc'!F14 -> GĐQLCL | AB4: =+'Cấp bậc'!F15 -> GĐR&D | AC4: =+'Cấp bậc'!F16 -> GĐĐH-T | AD4: =+'Cấp bậc'!F17 -> PGĐ | AE4: =+'Cấp bậc'!F18 -> KTT | AF4: =+'Cấp bậc'!F19 -> TP | AG4: =+'Cấp bậc'!F20 -> PP | AH4: =+'Cấp bậc'!H5 -> GĐT/TT | AI4: =+'Cấp bậc'!H6 -> KTT | AJ4: =+'Cấp bậc'!H7 -> TPNS | AK4: =+'Cấp bậc'!H8 -> QLSX | AL4: =+'Cấp bậc'!H9 -> TTKT | AM4: =+'Cấp bậc'!H10 -> QLCL | AN4: =+'Cấp bậc'!H11 -> QLK | AO4: =+'Cấp bậc'!H12 -> MH | AP4: =+'Cấp bậc'!H13 -> VHCN
E5: 1 | F5: =+E5+1 -> 2 | G5: =+F5+1 -> 3 | H5: =+G5+1 -> 4 | I5: =+H5+1 -> 5 | J5: =+I5+1 -> 6 | K5: =+J5+1 -> 7 | L5: =+K5+1 -> 8 | M5: =+L5+1 -> 9 | ... AP5: =+AO5+1 -> 38
B6: Q | C6: NGHIÊN CỨU & PHÁT TRIỂN R&D
B7: Q1 | C7: Phê duyệt dự án nghiên cứu và Phát triển (nội bộ)
B8: Q1.1 | C8: Dự án kéo dài liên tục hơn 1 năm.
B9: Q1.2 | C9: Dự án sẽ hoàn thành trong vòng 1 năm.
B10: Q2 | C10: Phê duyệt dự án nghiên cứu và Phát triển (thuê ngoài)
B11: Q2.1 | C11: Dự án kéo dài liên tục hơn 1 năm.
B12: Q2.2 | C12: Dự án sẽ hoàn thành trong vòng 1 năm.
B13: Q3 | C13: Thủ tục vận hành R&D
B14: Q3.1 | C14: Tiêu chuẩn tên gọi nguyên liệu, thành phẩm,…
B15: Q3.2 | C15: Tiêu chuẩn kỹ thuật vảy nguyên liệu, bán thành phẩm, thành phẩm,…
B16: Q3.3 | C16: Tiêu chuẩn kỹ thuật nguyên vật liệu mua vào
B17: Q3.4 | C17: Hướng dẫn đo, kiểm tra…liên quan chất lượng sản phẩm
... B23: Q3.10 | C23: Văn bản cam kết bảo mật

Sheet R.CNTT
B2: Ký hiệu | C2: NỘI DUNG | D2: Giá trị _vnđ | E2: THẨM QUYỀN PHÊ DUYỆT | AQ2: Ghi chú
E3: HĐQT | G3: DUY TÂN GROUP | R3: CTY TNHH NHỰA TÁI CHẾ DUY TÂN | AH3: TRẠM VẬN HÀNH
E4: =+'Cấp bậc'!B5 -> HĐQT | F4: =+'Cấp bậc'!B6 -> CT HĐQT | G4: =+'Cấp bậc'!D5 -> GĐĐH-TC | H4: =+'Cấp bậc'!D6 -> GĐĐH-NS | I4: =+'Cấp bậc'!D7 -> GĐĐH-SX | J4: =+'Cấp bậc'!D8 -> GĐĐH-CCU | K4: =+'Cấp bậc'!D9 -> GĐĐH-KD | L4: =+'Cấp bậc'!D10 -> GĐPC | M4: =+'Cấp bậc'!D11 -> GĐCNTT | N4: =+'Cấp bậc'!D12 -> GĐPTBV | O4: =+'Cấp bậc'!D13 -> PGĐDA | P4: =+'Cấp bậc'!D14 -> GĐKSNB | Q4: =+'Cấp bậc'!D15 -> GĐHCQT | R4: =+'Cấp bậc'!F5 -> PTGĐ | S4: =+'Cấp bậc'!F6 -> GĐĐH | T4: =+'Cấp bậc'!F7 -> GĐTC | U4: =+'Cấp bậc'!F8 -> GĐPTKD | V4: =+'Cấp bậc'!F9 -> GĐNS | W4: =+'Cấp bậc'!F10 -> GĐKT | X4: =+'Cấp bậc'!F11 -> GĐSX | Y4: =+'Cấp bậc'!F12 -> GĐCCƯ | Z4: =+'Cấp bậc'!F13 -> GĐCLCCƯ | AA4: =+'Cấp bậc'!F14 -> GĐQLCL | AB4: =+'Cấp bậc'!F15 -> GĐR&D | AC4: =+'Cấp bậc'!F16 -> GĐĐH-T | AD4: =+'Cấp bậc'!F17 -> PGĐ | AE4: =+'Cấp bậc'!F18 -> KTT | AF4: =+'Cấp bậc'!F19 -> TP | AG4: =+'Cấp bậc'!F20 -> PP | AH4: =+'Cấp bậc'!H5 -> GĐT/TT | AI4: =+'Cấp bậc'!H6 -> KTT | AJ4: =+'Cấp bậc'!H7 -> TPNS | AK4: =+'Cấp bậc'!H8 -> QLSX | AL4: =+'Cấp bậc'!H9 -> TTKT | AM4: =+'Cấp bậc'!H10 -> QLCL | AN4: =+'Cấp bậc'!H11 -> QLK | AO4: =+'Cấp bậc'!H12 -> MH | AP4: =+'Cấp bậc'!H13 -> VHCN
E5: 1 | F5: =+E5+1 -> 2 | G5: =+F5+1 -> 3 | H5: =+G5+1 -> 4 | I5: =+H5+1 -> 5 | J5: =+I5+1 -> 6 | K5: =+J5+1 -> 7 | L5: =+K5+1 -> 8 | M5: =+L5+1 -> 9 | ... AP5: =+AO5+1 -> 38
B6: R | C6: CÔNG NGHỆ THÔNG TIN (CNTT)
B7: R1 | C7: Quản lý Công Nghệ Thông Tin
B8: R1.1 | C8: Chiến lược CNTT, kế hoạch CNTT hằng năm, ngân sách CNTT hàng năm
B9: R1.2 | C9: Chính sách CNTT (bao gồm các lĩnh vực an toàn bảo mật, hạ tầng máy chủ, sao lưu, hệ thống và thiết bị mạng, quyền quản trị hệ thống, quản lý người dùng, hệ thống hỗ trợ người dủng, triển khai dự án, phát triển ứng dụng, ...)
B10: R1.3 | C10: Kiến trúc tổng thể hệ thống CNTT, danh sách các hệ thống ứng dụng
B11: R1.4 | C11: Quyền quản trị hệ thống hạ tầng, hệ thống mạng, hệ thống an toàn bảo mật, hệ thống ứng dụng lõi (Microsoft 365, SAP, Salesforce, HRM, Văn phòng số)
B12: R1.5 | C12: Quyền quản trị các ứng dụng chuyên dụng đặc thù tại mỗi công ty thành viên
B13: R1.6 | C13: Thỏa thuận bảo mật thông tin (nhà cung cấp tiềm năng, tổ chức/cá nhân tư vấn bên ngoài tồ chức) tuân thủ theo mẫu đã ban hành
B14: R1.7 | C14: Thỏa thuận bảo mật thông tin (nhà cung cấp tiềm năng, tổ chức/cá nhân tư vấn bên ngoài tồ chức) hiện chỉnh so với mẫu đã ban hành
B15: R2 | C15: Bản quyền (bao gồm mua mới và gia hạn)
B16: R2.1 | C16: Tờ trình đề xuất mua mới, mua gia hạn bản quyền hệ thống hạ tầng, hệ thống mạng, hệ thống an toàn bảo mật, hệ thống ứng dụng lõi (Microsoft 365, SAP, Salesforce, HRM, Văn phòng số), các hệ thống sử dụng xuyên suốt tại nhiều công ty thành viên
B17: R2.2 | C17: Tờ trình đề xuất mua mới, mua gia hạn bản quyền các ứng dụng chuyên dụng đặc thù tại mỗi công ty
... B42: R8 | C42: Phê duyệt Ma trận phân quyền từng cấp bậc sử dụng các hệ thống/ứng dụng trong đơn vị

Sheet S.KỸ THUẬT & BẢO TRÌ
B2: Ký hiệu | C2: NỘI DUNG | D2: Giá trị _vnđ | E2: THẨM QUYỀN PHÊ DUYỆT | AQ2: Ghi chú
E3: HĐQT | G3: DUY TÂN GROUP | R3: CTY TNHH NHỰA TÁI CHẾ DUY TÂN | AH3: TRẠM VẬN HÀNH
E4: =+'Cấp bậc'!B5 -> HĐQT | F4: =+'Cấp bậc'!B6 -> CT HĐQT | G4: =+'Cấp bậc'!D5 -> GĐĐH-TC | H4: =+'Cấp bậc'!D6 -> GĐĐH-NS | I4: =+'Cấp bậc'!D7 -> GĐĐH-SX | J4: =+'Cấp bậc'!D8 -> GĐĐH-CCU | K4: =+'Cấp bậc'!D9 -> GĐĐH-KD | L4: =+'Cấp bậc'!D10 -> GĐPC | M4: =+'Cấp bậc'!D11 -> GĐCNTT | N4: =+'Cấp bậc'!D12 -> GĐPTBV | O4: =+'Cấp bậc'!D13 -> PGĐDA | P4: =+'Cấp bậc'!D14 -> GĐKSNB | Q4: =+'Cấp bậc'!D15 -> GĐHCQT | R4: =+'Cấp bậc'!F5 -> PTGĐ | S4: =+'Cấp bậc'!F6 -> GĐĐH | T4: =+'Cấp bậc'!F7 -> GĐTC | U4: =+'Cấp bậc'!F8 -> GĐPTKD | V4: =+'Cấp bậc'!F9 -> GĐNS | W4: =+'Cấp bậc'!F10 -> GĐKT | X4: =+'Cấp bậc'!F11 -> GĐSX | Y4: =+'Cấp bậc'!F12 -> GĐCCƯ | Z4: =+'Cấp bậc'!F13 -> GĐCLCCƯ | AA4: =+'Cấp bậc'!F14 -> GĐQLCL | AB4: =+'Cấp bậc'!F15 -> GĐR&D | AC4: =+'Cấp bậc'!F16 -> GĐĐH-T | AD4: =+'Cấp bậc'!F17 -> PGĐ | AE4: =+'Cấp bậc'!F18 -> KTT | AF4: =+'Cấp bậc'!F19 -> TP | AG4: =+'Cấp bậc'!F20 -> PP | AH4: =+'Cấp bậc'!H5 -> GĐT/TT | AI4: =+'Cấp bậc'!H6 -> KTT | AJ4: =+'Cấp bậc'!H7 -> TPNS | AK4: =+'Cấp bậc'!H8 -> QLSX | AL4: =+'Cấp bậc'!H9 -> TTKT | AM4: =+'Cấp bậc'!H10 -> QLCL | AN4: =+'Cấp bậc'!H11 -> QLK | AO4: =+'Cấp bậc'!H12 -> MH | AP4: =+'Cấp bậc'!H13 -> VHCN
E5: 1 | F5: =+E5+1 -> 2 | G5: =+F5+1 -> 3 | H5: =+G5+1 -> 4 | I5: =+H5+1 -> 5 | J5: =+I5+1 -> 6 | K5: =+J5+1 -> 7 | L5: =+K5+1 -> 8 | M5: =+L5+1 -> 9 | ... AP5: =+AO5+1 -> 38
B6: S | C6: KỸ THUẬT & BẢO TRÌ
B7: S1 | C7: Kỹ thuật
B8: S1.1 | C8: Phê duyệt thiết kế bản vẽ máy móc, thiết bị.
B9: S1.1.1 | C9: Thay đổi bổ sung.
B10: S1.1.12 | C10: Không thay đổi so với trước
B11: S1.2 | C11: Thực hiện đặt hàng cho các phụ tùng, công cụ dụng cụ
B12: S1.3 | C12: Duyệt kết quả đấu thầu khi mua sắm máy móc thiết bị
B13: S2 | C13: Thủ tục liên quan đến kiểm định & nghiệm thu & mua bán điện
B14: S2.1 | C14: Ký các thủ tục kiểm định máy móc thiết bị, vật tư, đo điện trở tại Trung Tâm kiểm định kỹ thuật an toàn
B15: S2.2 | C15: Thủ tục đo điện trở đất kim chống sét
B16: S2.3 | C16: Thủ tục bảo trì, nghiệm thu máy móc thiết bị
B17: S2.4 | C17: Thủ tục đăng ký mới cầu trục
... B26: S3.4 | C26: Triển khai sửa chữa/bảo trì máy móc, công cụ, thiết bị theo kế hoạch & báo giá đã được duyệt

Sheet T.XDCB
B2: Ký hiệu | C2: NỘI DUNG | D2: Giá trị _vnđ | E2: THẨM QUYỀN PHÊ DUYỆT | AQ2: Ghi chú
