Workbook
Name _1: #REF!
Name _2: #REF!
Name _3: #REF!
Name _4: #REF!
Name _5: #REF!
Name a: #REF!
Name Accounts: #REF!
Name Activity_Reports: #REF!
Name ADM: #REF!
Name Application: [6]!Table6[Application]
Name B: #REF!
Name back: #REF!
Name Calendar: #REF!
Name Catalogue_xls: #REF!
Name CompanyCode: [11]CompanyCode!$A$2:$A$5
Name Contractingdiv: #REF!
Name corporate_affairs: #REF!
Name CTY: '[12]0.CTY'!$D:$D
Name Data_Values: '[16]Single Measure Analysis'!$B$29:$M$30
Name DATA13: '[17]2.1Raw material_details'!#REF!
Name DATA14: '[17]2.1Raw material_details'!#REF!
Name DATA15: '[17]2.1Raw material_details'!#REF!
Name DATA16: '[17]2.1Raw material_details'!#REF!
Name DATA17: '[17]2.1Raw material_details'!#REF!
Name DATA18: '[17]2.1Raw material_details'!#REF!
Name DATA19: '[17]2.1Raw material_details'!#REF!
Name DATA20: '[17]2.1Raw material_details'!#REF!
Name DATA21: '[17]2.1Raw material_details'!#REF!
Name DATA22: '[17]2.1Raw material_details'!#REF!
Name DATA23: '[17]2.1Raw material_details'!#REF!
Name DATA24: '[17]2.1Raw material_details'!#REF!
Name DATA25: '[17]2.1Raw material_details'!#REF!
Name DATA26: '[17]2.1Raw material_details'!#REF!
Name DATA27: '[17]2.1Raw material_details'!#REF!
Name DATA28: '[17]2.1Raw material_details'!#REF!
Name DATA29: '[17]2.1Raw material_details'!#REF!
Name DATA30: '[17]2.1Raw material_details'!#REF!
Name DATA31: '[17]2.1Raw material_details'!#REF!
Name DATA32: '[17]2.1Raw material_details'!#REF!
Name DATA33: '[17]2.1Raw material_details'!#REF!
Name DATA34: '[17]2.1Raw material_details'!#REF!
Name DATA35: '[17]2.1Raw material_details'!#REF!
Name DATA36: '[17]2.1Raw material_details'!#REF!
Name DATA37: '[17]2.1Raw material_details'!#REF!
Name Date_of_separation: #REF!
Name DeptCode: #REF!
Name dinhbien2021: #REF!
Name DivisionCode: #REF!
Name dow: #REF!
Name DT: #REF!
Name ERP: #REF!
Name Excise: #REF!
Name Expectations: #REF!
Name EXR: [19]Asm.!$B$2
Name EXR: #REF!
Name fdg: [20]!MeasureList
Name Finanacialsys: #REF!
Name Financialsys: #REF!
Name GENERAL: #REF!,#REF!,#REF!,#REF!,#REF!,#REF!,#REF!
Name GrossUp: #REF!

Sheet Timeline & PIC
B1: DUY TAN GROUP
B2: =IF(B3="EN","Schedule Annual Plan 2025","Lịch lập NGÂN SÁCH năm 2026") -> Lịch lập NGÂN SÁCH năm 2026 | D2: =IF(B3="EN","Start:","Bắt đầu:") -> Bắt đầu: | E2: 45915
B3: ='[28]Overview-BC Tongquan'!B2 -> VN | D3: =IF(B3="EN","Finish:","Kết thúc:") -> Kết thúc: | E3: =G22 -> 45990 | G3: =E3-E2 -> 75
D4: =IF(B3="en","SENDER","Đơn vị gửi") -> Đơn vị gửi | E4: =IF(B3="EN","RECEIVER","Đơn vị nhận") -> Đơn vị nhận | G4: Deadline | H4: THÁNG 09 | AM4: THÁNG 10 | BR4: THÁNG 11
B5: No. | C5: =IF(B3="EN","PROCESS","TRÌNH TỰ THỰC HIỆN") -> TRÌNH TỰ THỰC HIỆN | F5: Thời gian | H5: 1 | I5: 2 | J5: 3 | K5: 4 | L5: 5 | M5: 6 | N5: 7 | O5: 8 | P5: 9 | Q5: 10 | R5: 11 | S5: 12 | T5: 13 | U5: 14 | V5: 15 | W5: 16 | X5: 17 | Y5: 18 | Z5: 19 | AA5: 20 | AB5: 21 | AC5: 22 | AD5: 23 | AE5: 24 | AF5: 25 | AG5: 26 | AH5: 27 | AI5: 28 | AJ5: 29 | AK5: 30 | AL5: 31 | AM5: 1 | AN5: 2 | AO5: 3 | AP5: 4 | AQ5: 5 | AR5: 6 | AS5: 7 | AT5: 8 | AU5: 9 | AV5: 10 | AW5: 11 | AX5: 12 | AY5: 13 | AZ5: 14 | BA5: 15 | BB5: 16 | BC5: 17 | BD5: 18 | BE5: 19 | BF5: 20 | BG5: 21 | BH5: 22 | BI5: 23 | BJ5: 24 | BK5: 25 | BL5: 26 | BM5: 27 | BN5: 28 | BO5: 29 | BP5: 30 | BQ5: 31 | BR5: 1 | BS5: =BR5+1 -> 2 | BT5: =BS5+1 -> 3 | BU5: =BT5+1 -> 4 | BV5: =BU5+1 -> 5 | BW5: =BV5+1 -> 6 | BX5: =BW5+1 -> 7 | BY5: =BX5+1 -> 8 | BZ5: =BY5+1 -> 9 | ... CT5: =CS5+1 -> 29 | CU5: 30
F6: (Ngày) | H6: M | I6: T | J6: W | K6: TH | L6: F | M6: Sa | N6: Su | O6: M | P6: T | Q6: W | R6: TH | S6: F | T6: Sa | U6: Su | V6: M | W6: T | X6: W | Y6: TH | Z6: F | AA6: Sa | AB6: Su | AC6: M | AD6: T | AE6: W | AF6: TH | AG6: F | AH6: Sa | AI6: Su | AJ6: M | AK6: T | AL6: W | AM6: TH | AN6: F | AO6: Sa | AP6: Su | AQ6: M | AR6: T | AS6: W | AT6: TH | AU6: F | AV6: Sa | AW6: Su | AX6: M | AY6: T | AZ6: W | BA6: TH | BB6: F | BC6: Sa | BD6: Su | BE6: M | BF6: T | BG6: W | BH6: TH | BI6: F | BJ6: Sa | BK6: Su | BL6: M | BM6: T | BN6: W | BO6: TH | BP6: F | BQ6: Sa | BR6: Su | BS6: M | BT6: T | BU6: W | BV6: TH | BW6: F | BX6: Sa | BY6: Su | BZ6: M | CA6: T | CB6: W | CC6: TH | CD6: F | CE6: Sa | CF6: Su | CG6: M | CH6: T | CI6: W | CJ6: TH | CK6: F | CL6: Sa | CM6: Su | CN6: M | CO6: T | CP6: W | CQ6: TH | CR6: F | CS6: Sa | CT6: Su | CU6: M
B7: 1 | C7: Khởi động | D7: GĐTC holding | E7: =IF(B3="EN","All","Tất cả") -> Tất cả | G7: =E2 -> 45915
B8: 2 | C8: Kế hoạch Doanh thu / Sản lượng | D8: =IF(B3="EN","Sales team","Phòng kinh doanh") -> Phòng kinh doanh | E8: =IF(B3="EN","Acct.","Kế toán") -> Kế toán | F8: 15 | G8: =F8+$G$7 -> 45930
B9: 3 | C9: Kế hoạch giá cả nguyên vật liệu | D9: =IF(B2="EN","Supply chain","Chuỗi cung ứng") -> Chuỗi cung ứng | E9: =E8 -> Kế toán | F9: 15 | G9: =F9+$G$7 -> 45930
B10: =B9+1 -> 4 | C10: Kế hoạch chi phí vận chuyển, cước xuất khẩu,... | D10: =IF(B3="EN","Supply chain","Chuổi cung ứng") -> Chuổi cung ứng | E10: =E9 -> Kế toán | F10: 15 | G10: =F10+$G$7 -> 45930
B11: =B10+1 -> 5 | C11: Kế hoạch sản xuất | D11: =IF(B3="EN","Production","Bộ phận sản xuất") -> Bộ phận sản xuất | E11: =E10 -> Kế toán | F11: 20 | G11: =F11+$G$7 -> 45935
B12: =B11+1 -> 6 | C12: Kế hoạch biến phí sản xuất | D12: =E12 -> Kế toán | E12: =E11 -> Kế toán | F12: 20 | G12: =F12+$G$7 -> 45935
B13: =B12+1 -> 7 | C13: Kế hoạch nhân sự (số lượng nhân sự, quỹ lương, chi phí đào tạo,...) | D13: =IF(B3="EN","HR","Phòng nhân sự") -> Phòng nhân sự | E13: =E12 -> Kế toán | F13: 30 | G13: =F13+$G$7 -> 45945
B14: =B13+1 -> 8 | C14: Ngân sách đầu tư | D14: =E7 -> Tất cả | E14: =E13 -> Kế toán | F14: 30 | G14: =F14+$G$7 -> 45945
B15: =B14+1 -> 9 | C15: Ngân sách chi phí sản xuất (không bao gồm lương) | D15: =D11 -> Bộ phận sản xuất | E15: =E14 -> Kế toán | F15: 30 | G15: =F15+$G$7 -> 45945
B16: =B15+1 -> 10 | C16: Ngân sách chi phí bán hàng & chí phí quản lý (không bao gồm lương) | D16: =D14 -> Tất cả | E16: =E15 -> Kế toán | F16: 30 | G16: =F16+$G$7 -> 45945
B17: =B16+1 -> 11 | C17: Tổng hợp kết quả ngân sách mỗi công ty | D17: Kế toán quản trị | E17: KTT/GĐTC | F17: 45 | G17: =F17+$G$7 -> 45960
B18: 12 | C18: Trình bày kết quả ngân sách của mỗi công ty đến TGĐ (Bottom up) | D18: KTT/GĐTC | E18: TGĐ | F18: 50 | G18: =F18+$G$7 -> 45965
B19: 13 | C19: Trình bày kết quả ngân sách của mỗi công ty đến TGĐ (Top down) | D19: KTT/GĐTC | E19: TGĐ | F19: 55 | G19: =F19+$G$7 -> 45970
B20: 14 | C20: Trình bày kết quả ngân sách của mỗi công ty đến TGĐ (Chính thức) | D20: KTT/GĐTC | E20: TGĐ | F20: 62 | G20: =F20+$G$7 -> 45977
B21: 15 | C21: Hợp nhất ngân sách cho toàn bộ DT Group | D21: KTQT holding | E21: GĐTC holding | F21: 70 | G21: =F21+$G$7 -> 45985
B22: 16 | C22: Trình bày kết quả ngân sách hợp nhất cho toàn bộ DT Group | D22: GĐTC holding | E22: TGĐ | F22: 75 | G22: =F22+$G$7 -> 45990

Sheet Thongtin
B2: STT | C2: Nội dung | D2: Nguồn cung cấp dữ liệu | E2: Nguồn thông tin liên quan | F2: Thời gian cần dữ liệu | H2: STT | I2: Màu sheet | J2: Thông tin
B3: 1 | C3: Ban hành Nhóm-Loại NVL Trạm thu mua | D3: GĐĐH Trạm - DTR | E3: 1. BGĐ DTR 2. Phòng cung ứng DTR | F3: 45940 | H3: 1 | J3: Kết quả kinh doanh tổng hợp
B4: 2 | C4: Ban hành Sản lượng Trạm thu mua | D4: GĐĐH Trạm - DTR | E4: 1. BGĐ DTR 2. Phòng cung ứng DTR | F4: 45940 | H4: 2 | J4: Kết quả kinh doanh PET và HD
B5: 3 | C5: Ban hành đơn giá MUA từng loại NVL | D5: GĐĐH Trạm - DTR | E5: 1. Phòng cung ứng DTR đề xuất KH năm 2026 (Dữ liệu theo từng tháng) 2. KTT các trạm cung cấp đơn giá bình quân thực tế mua theo từng tháng ( Dữ liệu năm 2023-2024-2025) 3. Đơn giá BGĐ-DTR duyệt mua trong năm 2025 (Dữ liệu theo từng tháng) | F5: 45940 | H5: 3 | J5: Kết quả kinh doanh PET và HD
B6: 4 | C6: Ban hành đơn giá BÁN từng loại thành phẩm | D6: GĐĐH Trạm - DTR | E6: 1. BGĐ DTR 2. Phòng cung ứng DTR | F6: 45940 | H6: 4 | J6: Ban hành Định mức về Công suất MMTB - Định mức về CP phục vụ sản xuất - Định biên Nhân sự
B7: 5 | C7: Kế hoạch đầu tư CAPEX tại Trạm => Ảnh hưởng đến Sản phẩm và TCKT Trạm cung cấp đến DTR | D7: GĐĐH Trạm - DTR | E7: 1. BGĐ DTR 2. Phòng kỹ thuật DTR 3. Phòng mua hàng DTR | F7: 45940 | H7: 5 | J7: Ban hành sản lượng - đơn giá - Cơ cấu về: NVL - Thành phẩm - Hao hụt - Bán hàng
H8: 6 | J8: Nhóm Chi phí:CP Sản xuất - CP Bán hàng - CP Quản lý (Công thức từ: Định mức - Lương - PB_TSCD - PB_CPTT - nhóm NVL - Phát sinh trực tiếp)
H9: 7 | J9: Cập nhật TSCĐ - CPTT năm trước chuyển sang và Capex 2026
H10: 8 | I10: … | J10: Thông tin khác

Sheet KH hanh dong
A3: KẾ HOẠCH KINH DOANH 2026
A4: Nguồn yêu cầu: GĐTC-DTR
A5: STT | B5: Nhóm công việc | C5: Kế hoạch hành động | D5: Người thực hiện | E5: Thời gian hoàn thành tính toán và xác lập mục tiêu 2026 | F5: Hiện trạng / vướng mắt / giải pháp (tại thời điểm tháng 10/2025) | G5: Mục tiêu 2026 (rolling hàng tháng) | U5: KHNS 2026 | V5: Thực hiện 2025 | W5: Tăng/giảm vs KHNS 2026
G6: Đánh giá KQ đạt được (cập nhật đến thời điểm báo cáo) | H6: Mục tiêu T1 | I6: Mục tiêu T2 | J6: Mục tiêu T3 | K6: Mục tiêu T4 | L6: Mục tiêu T5 | M6: Mục tiêu T6 | N6: Mục tiêu T7 | O6: Mục tiêu T8 | P6: Mục tiêu T9 | Q6: Mục tiêu T10 | R6: Mục tiêu T11 | S6: Mục tiêu T12 | T6: Dự báo KQ 2026 | W6: Theo số tiền phát sinh | X6: Theo mức độ hoạt động | Y6: %
A7: A | B7: HOẠT ĐỘNG MUA HÀNG
A8: 1 | B8: Đáp ứng sản lượng mua cho Trạm | C8: Lập mục tiêu sản lượng mua để Trạm đạt hòa vốn và có lãi.
C9: Xây dựng các trạm vệ tinh để tăng lượng chai về Trạm.
C10: Phát triển thêm các NCC liên kết ở tỉnh.
C11: Đàm phán tăng sản lượng mua từ các NCC đang giao dịch.
A12: 2 | B12: Cải thiện dịch vụ khách hàng | C12: Cải thiện thời gian nhận hàng
C13: Thanh toán trong ngày và cuối tuần
A14: B | B14: HOẠT ĐỘNG BÁN HÀNG
A15: 1 | B15: Giá bán về DTR | C15: Áp dụng cơ cấu giá mới từ Tháng 9/2025
A16: 2 | B16: Kiểm soát tồn kho thành phẩm | C16: Lập KH giao hàng về DTR hàng ngày, ngày cuối tháng không để tồn kho và xuất hóa đơn 100%
A17: 3 | B17: Chi phí thuê xe vận chuyển | C17: - Đàm phán giảm giá, đề nghị NCC sử dụng phương tiện vận chuyển hiệu quả. - Tìm NCC mới cạnh tranh.
A18: C | B18: HOẠT ĐỘNG CẢI TIẾN CHI PHÍ
A19: I | B19: Chi phí nguyên vật liệu
A20: 1 | B20: Kiểm soát lượng mua, giá mua | C20: - Lập mục tiêu tồn kho tối thiểu 10 ngày sản xuất và phối hợp P.Cung ứng lập KH mua hàng theo tuần. - Kiểm soát giá mua tương ứng với từng mức chất lượng chai.
A21: 2 | B21: Kiểm soát chất lượng NVL, hao hụt | C21: Kiểm soát chất lượng chai (tỷ lệ chai nguyên liệu - Chai xá/xô tuyển, thành phần chai sau phân loại, tỷ lệ tạp chất).
A22: 3 | B22: Kiểm soát định mức vật tư sản xuất (hóa chất, dây đai, vật tư kỹ thuật …) | C22: - Thống kê và thực hiện cải tiến tiêu hao. - Mua tập trung tại P.Mua hàng DTR.
A23: 4 | B23: Xử lý phế liệu, phó sản thu hồi | C23: Phân loại phế liệu thành 2 nhóm: - Nhóm hàng hóa (nhãn, bao jumbo, kim loại,…): tìm đơn vị thu mua giá cao - Nhóm rác thải công nghiệp (bùn, hỗn hợp tạp chất): thuê thu gom
A24: II | B24: Chi phí nhân công
A25: 1 | B25: Định mức NCTT | C25: - Kiểm soát định mức NCTT theo chuyền/công đoạn. - Thực hiện tiêu chuẩn hóa/tự động hóa MMTB để giảm nhân công, tăng năng suất. - Tăng số lượng lao động thời vụ. - Tính toán phương án trả lương/ thưởng theo sản lượng.
A26: 2 | B26: Năng suất lao động | C26: - Lập mục tiêu tăng thời gian sản xuất từ 8 giờ/ngày -> 12 giờ -> 16 giờ -> 24 giờ.
A27: III | B27: Chi phí sản xuất chung
A28: 1 | B28: Chi phí điện | C28: - Phối hợp kỹ thuật bảo trì MMTB đảm bảo hoạt động liên tục -> tăng hiệu quả sử dụng điện và tăng năng suất lao động.
A29: 2 | B29: Chi phí xe nâng | C29: - Chuyển dần xe nâng dầu từ DTR về các Trạm (các xe của trạm sửa chữa nhiều sẽ thanh lý)
A30: 3 | B30: Chi phí khấu hao TSCĐ, CCDC, chi phí phân bổ khác | C30: - Thống kê, đánh giá lại hiệu quả sử dụng tất cả TS. - Tách chi phí khấu hao/phân bổ không phục vụ trực tiếp hoạt động để đánh giá hiệu quả KD thực của trạm.
A31: 4 | B31: Chi phí thuê xưởng | C31: - Tìm vị trí và đề xuất phương án di dời nhà máy để giảm tiền thu, tăng hiệu quả thu mua.
A32: IV | B32: Chi phí quản lý
A33: 1 | B33: Chi phí lương (gồm gián tiếp SX) | C33: Soát xét định biên và kế hoạch tuyển dụng, lập mục tiêu giảm định biên đến cuối 2026
A34: 2 | B34: Chi phí theo mục phí (ngoài chi phí lương) | C34: - Lập danh mục chi phí dịch vụ thuê/mua trả tiền định kỳ (nhóm dịch vụ/phòng ban quản lý, tên NCC, hợp đồng mới nhất, tiền trả định kỳ tháng/quý/năm, thời hạn công nợ) -> đàm phán từng NC giảm giá và tìm NCC mới cạnh tranh - XD định mức chi phí cho các khoản mục có thể xác lập định mức - Phân tích chi phí, nguyên nhân tăng/giảm và giải pháp cải tiến.
A35: V | B35: Mục tiêu lợi nhuận
A36: 1 | B36: Lợi nhuận kế hoạch đến cuối năm 2026 | C36: Sau khi đánh giá, xác lập các mục tiêu bên trên, tính toán lợi nhuận kế hoạch đến cuối năm 2026

Sheet KQKD Tong hop
B3: MỤC TIÊU KẾT QUẢ KINH DOANH NĂM 2026 | S3: ĐVT: Triệu đồng
B4: STT | C4: Mục phí | D4: Thực tế năm 2023 | E4: Thực tế năm 2024 | F4: KQKD 2025 | G4: T1 | H4: T2 | I4: T3 | J4: T4 | K4: T5 | L4: T6 | M4: T7 | N4: T8 | O4: T9 | P4: T10 | Q4: T11 | R4: T12 | S4: Kế hoạch 2026 | U4: KQKD 2025 | V4: KH 2026 | X4: KQKD 2025 | Y4: KH 2026
B5: 1 | C5: SẢN LƯỢNG BÁN (TẤN) | D5: ='KQKD PET'!D5 -> 5652770.5 | E5: ='KQKD PET'!E5 -> 4895018.4 | F5: ='KQKD PET'!F5 -> 5879799 | G5: =G6+G7+G8 -> 533700 | H5: =H6+H7+H8 -> 400275 | I5: =I6+I7+I8 -> 578175 | J5: =J6+J7+J8 -> 622650 | K5: =K6+K7+K8 -> 622650 | L5: =L6+L7+L8 -> 622650 | M5: =M6+M7+M8 -> 622650 | N5: =N6+N7+N8 -> 622650 | ... R5: =R6+R7+R8 -> 622650 | S5: =SUM(G5:R5) -> 7116000 | V5: =S5/F5 -> 1.2102455
B6: 1.1 | C6: Chai PET | D6: ='KQKD PET'!D6 -> 5652770.5 | E6: ='KQKD PET'!E6 -> 4895018.4 | F6: ='KQKD PET'!F6 -> 5879799 | G6: ='KQKD PET'!G6+'KQKD HD'!F6 -> 533700 | H6: ='KQKD PET'!H6+'KQKD HD'!G6 -> 400275 | I6: ='KQKD PET'!I6+'KQKD HD'!H6 -> 578175 | J6: ='KQKD PET'!J6+'KQKD HD'!I6 -> 622650 | K6: ='KQKD PET'!K6+'KQKD HD'!J6 -> 622650 | L6: ='KQKD PET'!L6+'KQKD HD'!K6 -> 622650 | M6: ='KQKD PET'!M6+'KQKD HD'!L6 -> 622650 | N6: ='KQKD PET'!N6+'KQKD HD'!M6 -> 622650 | ... R6: ='KQKD PET'!R6+'KQKD HD'!Q6 -> 622650 | S6: =SUM(G6:R6) -> 7116000 | U6: =S6/F6 -> 1.2102455 | V6: =S6/F6 -> 1.2102455
B7: 1.2 | C7: Vảy PET | D7: ='KQKD PET'!D7 -> 0 | E7: ='KQKD PET'!E7 -> 0 | F7: ='KQKD PET'!F7 -> 0 | G7: ='KQKD PET'!G7+'KQKD HD'!F7 -> 0 | H7: ='KQKD PET'!H7+'KQKD HD'!G7 -> 0 | I7: ='KQKD PET'!I7+'KQKD HD'!H7 -> 0 | J7: ='KQKD PET'!J7+'KQKD HD'!I7 -> 0 | K7: ='KQKD PET'!K7+'KQKD HD'!J7 -> 0 | L7: ='KQKD PET'!L7+'KQKD HD'!K7 -> 0 | M7: ='KQKD PET'!M7+'KQKD HD'!L7 -> 0 | N7: ='KQKD PET'!N7+'KQKD HD'!M7 -> 0 | ... R7: ='KQKD PET'!R7+'KQKD HD'!Q7 -> 0 | S7: =SUM(G7:R7) -> 0
B8: 1.3 | C8: Vảy HD | D8: ='KQKD PET'!D8 -> 0 | E8: ='KQKD PET'!E8 -> 0 | F8: ='KQKD PET'!F8 -> 0 | G8: ='KQKD PET'!G8+'KQKD HD'!F8 -> 0 | H8: ='KQKD PET'!H8+'KQKD HD'!G8 -> 0 | I8: ='KQKD PET'!I8+'KQKD HD'!H8 -> 0 | J8: ='KQKD PET'!J8+'KQKD HD'!I8 -> 0 | K8: ='KQKD PET'!K8+'KQKD HD'!J8 -> 0 | L8: ='KQKD PET'!L8+'KQKD HD'!K8 -> 0 | M8: ='KQKD PET'!M8+'KQKD HD'!L8 -> 0 | N8: ='KQKD PET'!N8+'KQKD HD'!M8 -> 0 | ... R8: ='KQKD PET'!R8+'KQKD HD'!Q8 -> 0 | S8: =SUM(G8:R8) -> 0
B9: 2 | C9: DOANH THU | D9: ='KQKD PET'!D9 -> 78915665269 | E9: ='KQKD PET'!E9 -> 74523104085 | F9: ='KQKD PET'!F9 -> 97725917198 | G9: =G10+G11+G12+G13 -> 7469550000 | H9: =H10+H11+H12+H13 -> 5602162500 | I9: =I10+I11+I12+I13 -> 8092012500 | J9: =J10+J11+J12+J13 -> 8714475000 | K9: =K10+K11+K12+K13 -> 8714475000 | L9: =L10+L11+L12+L13 -> 8714475000 | M9: =M10+M11+M12+M13 -> 8714475000 | N9: =N10+N11+N12+N13 -> 8714475000 | ... R9: =R10+R11+R12+R13 -> 8714475000 | S9: =SUM(G9:R9) -> 99594000000 | U9: =F9/F$9 -> 1 | V9: =S9/S$9 -> 1 | X9: =F9/F5 -> 16620.622 | Y9: =S9/S5 -> 13995.784 | Z9: =Y9-X9 -> -2624.838
B10: 2.1 | C10: Chai PET | D10: ='KQKD PET'!D10 -> 78915665269 | E10: ='KQKD PET'!E10 -> 74523104085 | F10: ='KQKD PET'!F10 -> 97725917198 | G10: ='KQKD PET'!G10+'KQKD HD'!F10 -> 7469550000 | H10: ='KQKD PET'!H10+'KQKD HD'!G10 -> 5602162500 | I10: ='KQKD PET'!I10+'KQKD HD'!H10 -> 8092012500 | J10: ='KQKD PET'!J10+'KQKD HD'!I10 -> 8714475000 | K10: ='KQKD PET'!K10+'KQKD HD'!J10 -> 8714475000 | L10: ='KQKD PET'!L10+'KQKD HD'!K10 -> 8714475000 | M10: ='KQKD PET'!M10+'KQKD HD'!L10 -> 8714475000 | N10: ='KQKD PET'!N10+'KQKD HD'!M10 -> 8714475000 | ... R10: ='KQKD PET'!R10+'KQKD HD'!Q10 -> 8714475000 | S10: =SUM(G10:R10) -> 99594000000 | U10: =F10/F$9 -> 1 | V10: =S10/S$9 -> 1
B11: 2.2 | C11: Vảy PET | D11: ='KQKD PET'!D11 -> 0 | E11: ='KQKD PET'!E11 -> 0 | F11: ='KQKD PET'!F11 -> 0 | G11: ='KQKD PET'!G11+'KQKD HD'!F11 -> 0 | H11: ='KQKD PET'!H11+'KQKD HD'!G11 -> 0 | I11: ='KQKD PET'!I11+'KQKD HD'!H11 -> 0 | J11: ='KQKD PET'!J11+'KQKD HD'!I11 -> 0 | K11: ='KQKD PET'!K11+'KQKD HD'!J11 -> 0 | L11: ='KQKD PET'!L11+'KQKD HD'!K11 -> 0 | M11: ='KQKD PET'!M11+'KQKD HD'!L11 -> 0 | N11: ='KQKD PET'!N11+'KQKD HD'!M11 -> 0 | ... R11: ='KQKD PET'!R11+'KQKD HD'!Q11 -> 0 | S11: =SUM(G11:R11) -> 0 | U11: =F11/F$9 -> 0 | V11: =S11/S$9 -> 0
B12: 2.3 | C12: Vảy HD | D12: ='KQKD PET'!D12 -> 0 | E12: ='KQKD PET'!E12 -> 0 | F12: ='KQKD PET'!F12 -> 0 | G12: ='KQKD PET'!G12+'KQKD HD'!F12 -> 0 | H12: ='KQKD PET'!H12+'KQKD HD'!G12 -> 0 | I12: ='KQKD PET'!I12+'KQKD HD'!H12 -> 0 | J12: ='KQKD PET'!J12+'KQKD HD'!I12 -> 0 | K12: ='KQKD PET'!K12+'KQKD HD'!J12 -> 0 | L12: ='KQKD PET'!L12+'KQKD HD'!K12 -> 0 | M12: ='KQKD PET'!M12+'KQKD HD'!L12 -> 0 | N12: ='KQKD PET'!N12+'KQKD HD'!M12 -> 0 | ... R12: ='KQKD PET'!R12+'KQKD HD'!Q12 -> 0 | S12: =SUM(G12:R12) -> 0 | U12: =F12/F$9 -> 0 | V12: =S12/S$9 -> 0
B13: 2.4 | C13: Khác | D13: ='KQKD PET'!D13 -> 0 | E13: ='KQKD PET'!E13 -> 0 | F13: ='KQKD PET'!F13 -> 0 | G13: ='KQKD PET'!G13+'KQKD HD'!F13 -> 0 | H13: ='KQKD PET'!H13+'KQKD HD'!G13 -> 0 | I13: ='KQKD PET'!I13+'KQKD HD'!H13 -> 0 | J13: ='KQKD PET'!J13+'KQKD HD'!I13 -> 0 | K13: ='KQKD PET'!K13+'KQKD HD'!J13 -> 0 | L13: ='KQKD PET'!L13+'KQKD HD'!K13 -> 0 | M13: ='KQKD PET'!M13+'KQKD HD'!L13 -> 0 | N13: ='KQKD PET'!N13+'KQKD HD'!M13 -> 0 | ... R13: ='KQKD PET'!R13+'KQKD HD'!Q13 -> 0 | S13: =SUM(G13:R13) -> 0 | U13: =F13/F$9 -> 0 | V13: =S13/S$9 -> 0
B14: 3 | C14: BIẾN PHÍ | D14: ='KQKD PET'!D14 -> 7.4913898e+10 | E14: ='KQKD PET'!E14 -> 70945682854 | F14: ='KQKD PET'!F14 -> 8.7040525e+10 | G14: =G15+G23 -> 6.6989855e+09 | H14: =H15+H23 -> 5.1345336e+09 | I14: =I15+I23 -> 7.2126164e+09 | J14: =J15+J23 -> 7.7629387e+09 | K14: =K15+K23 -> 7.7380763e+09 | L14: =L15+L23 -> 7.7567254e+09 | M14: =M15+M23 -> 7.7882538e+09 | N14: =N15+N23 -> 7.8002203e+09 | ... R14: =R15+R23 -> 7.7463711e+09 | S14: =SUM(G14:R14) -> 8.8930411e+10 | U14: =F14/F$9 -> 0.89065959 | V14: =S14/S$9 -> 0.89292941
B15: 3.1 | C15: BIẾN PHÍ SẢN XUẤT | D15: ='KQKD PET'!D15 -> 7.3435299e+10 | E15: ='KQKD PET'!E15 -> 69651631026 | F15: ='KQKD PET'!F15 -> 8.5723904e+10 | G15: =G16+G20+G21+G22 -> 6.5846212e+09 | H15: =H16+H20+H21+H22 -> 5.0487604e+09 | I15: =I16+I20+I21+I22 -> 7.0887217e+09 | J15: =J16+J20+J21+J22 -> 7.6295137e+09 | K15: =K16+K20+K21+K22 -> 7.6046513e+09 | L15: =L16+L20+L21+L22 -> 7.6233004e+09 | M15: =M16+M20+M21+M22 -> 7.6548288e+09 | N15: =N16+N20+N21+N22 -> 7.6667953e+09 | ... R15: =R16+R20+R21+R22 -> 7.6129461e+09 | S15: =SUM(G15:R15) -> 8.7405554e+10 | U15: =F15/F$9 -> 0.877187 | V15: =S15/S$9 -> 0.87761868
B16: 3.1.1 | C16: Nguyên vật liệu chính (nhựa, gồm hao hụt) | D16: ='KQKD PET'!D16 -> 66674046263 | E16: ='KQKD PET'!E16 -> 64023356129 | F16: ='KQKD PET'!F16 -> 79307026326 | G16: ='KQKD PET'!G16+'KQKD HD'!F16 -> 6000000000 | H16: ='KQKD PET'!H16+'KQKD HD'!G16 -> 4500000000 | I16: ='KQKD PET'!I16+'KQKD HD'!H16 -> 6500000000 | J16: ='KQKD PET'!J16+'KQKD HD'!I16 -> 7000000000 | K16: ='KQKD PET'!K16+'KQKD HD'!J16 -> 7000000000 | L16: ='KQKD PET'!L16+'KQKD HD'!K16 -> 7000000000 | M16: ='KQKD PET'!M16+'KQKD HD'!L16 -> 7000000000 | N16: ='KQKD PET'!N16+'KQKD HD'!M16 -> 7000000000 | ... R16: ='KQKD PET'!R16+'KQKD HD'!Q16 -> 7000000000 | S16: =SUM(G16:R16) -> 80000000000 | U16: =F16/F$9 -> 0.81152501 | V16: =S16/S$9 -> 0.80326124
B17: 3.1.2 | C17: Trong đó: i/ Hao hụt CĐ phân loại chai | D17: ='KQKD PET'!D17 -> 4304680024 | E17: ='KQKD PET'!E17 -> 5823164953 | F17: ='KQKD PET'!F17 -> 8362915901 | G17: ='KQKD PET'!G17+'KQKD HD'!F17 -> 663000000 | H17: ='KQKD PET'!H17+'KQKD HD'!G17 -> 497250000 | I17: ='KQKD PET'!I17+'KQKD HD'!H17 -> 718250000 | J17: ='KQKD PET'!J17+'KQKD HD'!I17 -> 773500000 | K17: ='KQKD PET'!K17+'KQKD HD'!J17 -> 773500000 | L17: ='KQKD PET'!L17+'KQKD HD'!K17 -> 773500000 | M17: ='KQKD PET'!M17+'KQKD HD'!L17 -> 773500000 | N17: ='KQKD PET'!N17+'KQKD HD'!M17 -> 773500000 | ... R17: ='KQKD PET'!R17+'KQKD HD'!Q17 -> 773500000 | S17: =SUM(G17:R17) -> 8840000000 | U17: =F17/F$9 -> 0.08557521 | V17: =S17/S$9 -> 0.088760367
C18: ii/ Hao hụt CĐ băm vảy | D18: ='KQKD PET'!D18 -> 0 | E18: ='KQKD PET'!E18 -> 0 | F18: ='KQKD PET'!F18 -> 0 | G18: ='KQKD PET'!G18+'KQKD HD'!F18 -> 0 | H18: ='KQKD PET'!H18+'KQKD HD'!G18 -> 0 | I18: ='KQKD PET'!I18+'KQKD HD'!H18 -> 0 | J18: ='KQKD PET'!J18+'KQKD HD'!I18 -> 0 | K18: ='KQKD PET'!K18+'KQKD HD'!J18 -> 0 | L18: ='KQKD PET'!L18+'KQKD HD'!K18 -> 0 | M18: ='KQKD PET'!M18+'KQKD HD'!L18 -> 0 | N18: ='KQKD PET'!N18+'KQKD HD'!M18 -> 0 | ... R18: ='KQKD PET'!R18+'KQKD HD'!Q18 -> 0 | S18: =SUM(G18:R18) -> 0 | U18: =F18/F$9 -> 0 | V18: =S18/S$9 -> 0
B19: 3.1.3 | C19: % chi phí nguyên liệu/doanh thu | D19: ='KQKD PET'!D19 -> 0.8448772 | E19: ='KQKD PET'!E19 -> 0.85910748 | F19: ='KQKD PET'!F19 -> 0.81152501 | G19: =G16/G9 -> 0.80326124 | H19: =H16/H9 -> 0.80326124 | I19: =I16/I9 -> 0.80326124 | J19: =J16/J9 -> 0.80326124 | K19: =K16/K9 -> 0.80326124 | L19: =L16/L9 -> 0.80326124 | M19: =M16/M9 -> 0.80326124 | N19: =N16/N9 -> 0.80326124 | ... S19: =S16/S9 -> 0.80326124 | U19: =F19/F$9 -> 8.3040921e-12 | V19: =S19/S$9 -> 8.0653578e-12
B20: 3.1.4 | C20: Nguyên vật liệu phụ | D20: ='KQKD PET'!D20 -> 630817585 | E20: ='KQKD PET'!E20 -> 620417107 | F20: ='KQKD PET'!F20 -> 5.6441463e+08 | G20: ='KQKD PET'!G20+'KQKD HD'!F20 -> 1.2915839e+08 | H20: ='KQKD PET'!H20+'KQKD HD'!G20 -> 96868796 | I20: ='KQKD PET'!I20+'KQKD HD'!H20 -> 1.3992159e+08 | J20: ='KQKD PET'!J20+'KQKD HD'!I20 -> 1.5068479e+08 | K20: ='KQKD PET'!K20+'KQKD HD'!J20 -> 1.5068479e+08 | L20: ='KQKD PET'!L20+'KQKD HD'!K20 -> 1.5068479e+08 | M20: ='KQKD PET'!M20+'KQKD HD'!L20 -> 1.5068479e+08 | N20: ='KQKD PET'!N20+'KQKD HD'!M20 -> 1.5068479e+08 | ... R20: ='KQKD PET'!R20+'KQKD HD'!Q20 -> 1.5068479e+08 | S20: =SUM(G20:R20) -> 1.7221119e+09 | U20: =F20/F$9 -> 0.0057754857 | V20: =S20/S$9 -> 0.017291322
B21: 3.1.5 | C21: Điện sản xuất | D21: ='KQKD PET'!D21 -> 326356700 | E21: ='KQKD PET'!E21 -> 377182809 | F21: ='KQKD PET'!F21 -> 453250096 | G21: ='KQKD PET'!G21+'KQKD HD'!F21 -> 45584274 | H21: ='KQKD PET'!H21+'KQKD HD'!G21 -> 34188205 | I21: ='KQKD PET'!I21+'KQKD HD'!H21 -> 49382963 | J21: ='KQKD PET'!J21+'KQKD HD'!I21 -> 53181653 | K21: ='KQKD PET'!K21+'KQKD HD'!J21 -> 53181653 | L21: ='KQKD PET'!L21+'KQKD HD'!K21 -> 53181653 | M21: ='KQKD PET'!M21+'KQKD HD'!L21 -> 53181653 | N21: ='KQKD PET'!N21+'KQKD HD'!M21 -> 53181653 | ... R21: ='KQKD PET'!R21+'KQKD HD'!Q21 -> 53181653 | S21: =SUM(G21:R21) -> 6.0779032e+08 | U21: =F21/F$9 -> 0.0046379723 | V21: =S21/S$9 -> 0.00610268
B22: 3.1.6 | C22: Nhân công trực tiếp | D22: ='KQKD PET'!D22 -> 5.8040781e+09 | E22: ='KQKD PET'!E22 -> 4630674981 | F22: ='KQKD PET'!F22 -> 5.3992128e+09 | G22: ='KQKD PET'!G22+'KQKD HD'!F22 -> 4.0987858e+08 | H22: ='KQKD PET'!H22+'KQKD HD'!G22 -> 4.177034e+08 | I22: ='KQKD PET'!I22+'KQKD HD'!H22 -> 3.9941719e+08 | J22: ='KQKD PET'!J22+'KQKD HD'!I22 -> 4.256473e+08 | K22: ='KQKD PET'!K22+'KQKD HD'!J22 -> 4.0078483e+08 | L22: ='KQKD PET'!L22+'KQKD HD'!K22 -> 4.1943392e+08 | M22: ='KQKD PET'!M22+'KQKD HD'!L22 -> 4.5096237e+08 | N22: ='KQKD PET'!N22+'KQKD HD'!M22 -> 4.6292885e+08 | ... R22: ='KQKD PET'!R22+'KQKD HD'!Q22 -> 4.0907969e+08 | S22: =SUM(G22:R22) -> 5.0756521e+09 | U22: =F22/F$9 -> 0.055248525 | V22: =S22/S$9 -> 0.050963433
B23: 3.2 | C23: BIẾN PHÍ BÁN HÀNG | D23: ='KQKD PET'!D23 -> 1478599034 | E23: ='KQKD PET'!E23 -> 1294051828 | F23: ='KQKD PET'!F23 -> 1.3166214e+09 | G23: =G24 -> 1.1436429e+08 | H23: =H24 -> 85773214 | I23: =I24 -> 1.2389464e+08 | J23: =J24 -> 133425000 | K23: =K24 -> 133425000 | L23: =L24 -> 133425000 | M23: =M24 -> 133425000 | N23: =N24 -> 133425000 | ... R23: =R24 -> 133425000 | S23: =SUM(G23:R23) -> 1.5248571e+09 | U23: =F23/F$9 -> 0.013472592 | V23: =S23/S$9 -> 0.015310733
C24: Chi phí vận chuyển | D24: ='KQKD PET'!D24 -> 1478599034 | E24: ='KQKD PET'!E24 -> 1294051828 | F24: ='KQKD PET'!F24 -> 1.3166214e+09 | G24: ='KQKD PET'!G24+'KQKD HD'!F24 -> 1.1436429e+08 | H24: ='KQKD PET'!H24+'KQKD HD'!G24 -> 85773214 | I24: ='KQKD PET'!I24+'KQKD HD'!H24 -> 1.2389464e+08 | J24: ='KQKD PET'!J24+'KQKD HD'!I24 -> 133425000 | K24: ='KQKD PET'!K24+'KQKD HD'!J24 -> 133425000 | L24: ='KQKD PET'!L24+'KQKD HD'!K24 -> 133425000 | M24: ='KQKD PET'!M24+'KQKD HD'!L24 -> 133425000 | N24: ='KQKD PET'!N24+'KQKD HD'!M24 -> 133425000 | ... R24: ='KQKD PET'!R24+'KQKD HD'!Q24 -> 133425000 | S24: =SUM(G24:R24) -> 1.5248571e+09 | U24: =F24/F$9 -> 0.013472592 | V24: =S24/S$9 -> 0.015310733
B25: 4 | C25: LÃI SAU BIẾN PHÍ | D25: ='KQKD PET'!D25 -> 4.0017676e+09 | E25: ='KQKD PET'!E25 -> 3577421231 | F25: ='KQKD PET'!F25 -> 1.0685392e+10 | G25: =G9-G14 -> 7.7056447e+08 | H25: =H9-H14 -> 4.6762888e+08 | I25: =I9-I14 -> 8.7939612e+08 | J25: =J9-J14 -> 9.5153625e+08 | K25: =K9-K14 -> 9.7639873e+08 | L25: =L9-L14 -> 9.5774963e+08 | M25: =M9-M14 -> 9.2622118e+08 | N25: =N9-N14 -> 9.1425471e+08 | ... R25: =R9-R14 -> 9.6810387e+08 | S25: =SUM(G25:R25) -> 1.0663589e+10 | U25: =F25/F$9 -> 0.10934041 | V25: =S25/S$9 -> 0.10707059
B26: 4.1 | C26: % lãi biến phí/doanh thu | D26: ='KQKD PET'!D26 -> 0.05070942 | E26: ='KQKD PET'!E26 -> 0.04800419 | F26: ='KQKD PET'!F26 -> 0.013472592 | G26: =G25/G9 -> 0.10316076 | H26: =H25/H9 -> 0.083472924 | I26: =I25/I9 -> 0.10867459 | J26: =J25/J9 -> 0.10919031 | K26: =K25/K9 -> 0.11204332 | L26: =L25/L9 -> 0.10990331 | M26: =M25/M9 -> 0.10628537 | N26: =N25/N9 -> 0.1049122 | ... S26: =S25/S9 -> 0.10707059 | U26: =F26/F$9 -> 1.37861e-13 | V26: =S26/S$9 -> 1.0750707e-12
B27: 5 | C27: CHI PHÍ SẢN XUẤT CHUNG | D27: ='KQKD PET'!D27 -> 2.0941578e+09 | E27: ='KQKD PET'!E27 -> 2385196776 | F27: ='KQKD PET'!F27 -> 4.2048304e+09 | G27: =G28+G29+G30 -> 5.2485398e+08 | H27: =H28+H29+H30 -> 5.3468413e+08 | I27: =I28+I29+I30 -> 4.9822558e+08 | J27: =J28+J29+J30 -> 5.1694045e+08 | K27: =K28+K29+K30 -> 4.9801716e+08 | L27: =L28+L29+L30 -> 5.2597207e+08 | M27: =M28+M29+M30 -> 5.063536e+08 | N27: =N28+N29+N30 -> 5.1191977e+08 | ... R27: =R28+R29+R30 -> 5.1098676e+08 | S27: =SUM(G27:R27) -> 6.138579e+09 | U27: =F27/F$9 -> 0.043026768 | V27: =S27/S$9 -> 0.061636032
B28: 5.1 | C28: Lương gián tiếp Sản xuất | D28: ='KQKD PET'!D28 -> 3.1517286e+08 | E28: ='KQKD PET'!E28 -> 220439144 | F28: ='KQKD PET'!F28 -> 1.0162315e+09 | G28: ='KQKD PET'!G28+'KQKD HD'!F28 -> 2.0140792e+08 | H28: ='KQKD PET'!H28+'KQKD HD'!G28 -> 2.2291481e+08 | I28: ='KQKD PET'!I28+'KQKD HD'!H28 -> 1.9174351e+08 | J28: ='KQKD PET'!J28+'KQKD HD'!I28 -> 2.0729541e+08 | K28: ='KQKD PET'!K28+'KQKD HD'!J28 -> 197959424 | L28: ='KQKD PET'!L28+'KQKD HD'!K28 -> 2.0561971e+08 | M28: ='KQKD PET'!M28+'KQKD HD'!L28 -> 2.0558595e+08 | N28: ='KQKD PET'!N28+'KQKD HD'!M28 -> 2.0680673e+08 | ... R28: ='KQKD PET'!R28+'KQKD HD'!Q28 -> 2.0131325e+08 | S28: =SUM(G28:R28) -> 2.4550487e+09 | U28: =F28/F$9 -> 0.010398792 | V28: =S28/S$9 -> 0.024650568
B29: 5.2 | C29: Chi phí thuê xưởng | D29: ='KQKD PET'!D29 -> 1118310000 | E29: ='KQKD PET'!E29 -> 1557000000 | F29: ='KQKD PET'!F29 -> 1800000000 | G29: ='KQKD PET'!G29+'KQKD HD'!F29 -> 150000000 | H29: ='KQKD PET'!H29+'KQKD HD'!G29 -> 150000000 | I29: ='KQKD PET'!I29+'KQKD HD'!H29 -> 150000000 | J29: ='KQKD PET'!J29+'KQKD HD'!I29 -> 150000000 | K29: ='KQKD PET'!K29+'KQKD HD'!J29 -> 150000000 | L29: ='KQKD PET'!L29+'KQKD HD'!K29 -> 150000000 | M29: ='KQKD PET'!M29+'KQKD HD'!L29 -> 150000000 | N29: ='KQKD PET'!N29+'KQKD HD'!M29 -> 150000000 | ... R29: ='KQKD PET'!R29+'KQKD HD'!Q29 -> 150000000 | S29: =SUM(G29:R29) -> 1800000000 | U29: =F29/F$9 -> 0.01841886 | V29: =S29/S$9 -> 0.018073378
B30: 5.3 | C30: Chi phí sản xuất (Ngoài lương, BOM, thuê xưởng, khấu hao) | D30: ='KQKD PET'!D30 -> 660674936 | E30: ='KQKD PET'!E30 -> 607757632 | F30: ='KQKD PET'!F30 -> 1.3885989e+09 | G30: ='KQKD PET'!G30+'KQKD HD'!F30 -> 1.7344606e+08 | H30: ='KQKD PET'!H30+'KQKD HD'!G30 -> 1.6176933e+08 | I30: ='KQKD PET'!I30+'KQKD HD'!H30 -> 1.5648207e+08 | J30: ='KQKD PET'!J30+'KQKD HD'!I30 -> 1.5964503e+08 | K30: ='KQKD PET'!K30+'KQKD HD'!J30 -> 1.5005774e+08 | L30: ='KQKD PET'!L30+'KQKD HD'!K30 -> 1.7035236e+08 | M30: ='KQKD PET'!M30+'KQKD HD'!L30 -> 1.5076764e+08 | N30: ='KQKD PET'!N30+'KQKD HD'!M30 -> 1.5511304e+08 | ... R30: ='KQKD PET'!R30+'KQKD HD'!Q30 -> 1.5967352e+08 | S30: =SUM(G30:R30) -> 1.8835303e+09 | U30: =F30/F$9 -> 0.014209116 | V30: =S30/S$9 -> 0.018912086
B31: 6 | C31: CHI PHÍ KHẤU HAO | D31: ='KQKD PET'!D31 -> 1036408270 | E31: ='KQKD PET'!E31 -> 1382050356 | F31: ='KQKD PET'!F31 -> 1.9084998e+09 | G31: ='KQKD PET'!G31+'KQKD HD'!F31 -> 81327530 | H31: ='KQKD PET'!H31+'KQKD HD'!G31 -> 81327530 | I31: ='KQKD PET'!I31+'KQKD HD'!H31 -> 81327530 | J31: ='KQKD PET'!J31+'KQKD HD'!I31 -> 81327530 | K31: ='KQKD PET'!K31+'KQKD HD'!J31 -> 81327530 | L31: ='KQKD PET'!L31+'KQKD HD'!K31 -> 81327530 | M31: ='KQKD PET'!M31+'KQKD HD'!L31 -> 81327530 | N31: ='KQKD PET'!N31+'KQKD HD'!M31 -> 81327530 | ... R31: ='KQKD PET'!R31+'KQKD HD'!Q31 -> 81327530 | S31: =SUM(G31:R31) -> 9.7593036e+08 | U31: =F31/F$9 -> 0.019529106 | V31: =S31/S$9 -> 0.0097990879
B32: 7 | C32: LỢI NHUẬN GỘP | D32: ='KQKD PET'!D32 -> 871201538 | E32: ='KQKD PET'!E32 -> -189825901 | F32: ='KQKD PET'!F32 -> 4.5720617e+09 | G32: =G25-G27-G31 -> 1.6438296e+08 | H32: =H25-H27-H31 -> -1.4838278e+08 | I32: =I25-I27-I31 -> 2.9984301e+08 | J32: =J25-J27-J31 -> 3.5326827e+08 | K32: =K25-K27-K31 -> 3.9705403e+08 | L32: =L25-L27-L31 -> 3.5045003e+08 | M32: =M25-M27-M31 -> 3.3854005e+08 | N32: =N25-N27-N31 -> 3.2100741e+08 | ... R32: =R25-R27-R31 -> 3.7578957e+08 | S32: =SUM(G32:R32) -> 3.5490792e+09 | U32: =F32/F$9 -> 0.046784536 | V32: =S32/S$9 -> 0.035635472
B33: 7.1 | C33: % lãi gộp/doanh thu | D33: ='KQKD PET'!D33 -> 0.011039653 | E33: ='KQKD PET'!E33 -> -0.0025472087 | F33: ='KQKD PET'!F33 -> 0.046784536 | G33: =G32/G9 -> 0.022007077 | H33: =H32/H9 -> -0.026486697 | I33: =I32/I9 -> 0.037054195 | J33: =J32/J9 -> 0.040538102 | K33: =K32/K9 -> 0.045562588 | L33: =L32/L9 -> 0.040214704 | M33: =M32/M9 -> 0.038848015 | N33: =N32/N9 -> 0.036836116 | ... S33: =S32/S9 -> 0.035635472 | U33: =F33/F$9 -> 4.7873213e-13 | V33: =S33/S$9 -> 3.5780742e-13
B34: 8 | C34: CHI PHÍ BÁN HÀNG & MKT & R&D | D34: ='KQKD PET'!D34 -> 0 | E34: ='KQKD PET'!E34 -> 0 | F34: ='KQKD PET'!F34 -> 0 | G34: =G35+G36+G37 -> 0 | H34: =H35+H36+H37 -> 0 | I34: =I35+I36+I37 -> 0 | J34: =J35+J36+J37 -> 0 | K34: =K35+K36+K37 -> 0 | L34: =L35+L36+L37 -> 0 | M34: =M35+M36+M37 -> 0 | N34: =N35+N36+N37 -> 0 | ... R34: =R35+R36+R37 -> 0 | S34: =SUM(G34:R34) -> 0 | U34: =F34/F$9 -> 0 | V34: =S34/S$9 -> 0
B35: 8.1 | C35: Lương | D35: ='KQKD PET'!D35 -> 0 | E35: ='KQKD PET'!E35 -> 0 | F35: ='KQKD PET'!F35 -> 0 | G35: ='KQKD PET'!G35+'KQKD HD'!F35 -> 0 | H35: ='KQKD PET'!H35+'KQKD HD'!G35 -> 0 | I35: ='KQKD PET'!I35+'KQKD HD'!H35 -> 0 | J35: ='KQKD PET'!J35+'KQKD HD'!I35 -> 0 | K35: ='KQKD PET'!K35+'KQKD HD'!J35 -> 0 | L35: ='KQKD PET'!L35+'KQKD HD'!K35 -> 0 | M35: ='KQKD PET'!M35+'KQKD HD'!L35 -> 0 | N35: ='KQKD PET'!N35+'KQKD HD'!M35 -> 0 | ... R35: ='KQKD PET'!R35+'KQKD HD'!Q35 -> 0 | S35: =SUM(G35:R35) -> 0 | U35: =F35/F$9 -> 0 | V35: =S35/S$9 -> 0
B36: 8.2 | C36: Chi phí bán hàng (ngoài lương, khấu hao) | D36: ='KQKD PET'!D36 -> 0 | E36: ='KQKD PET'!E36 -> 0 | F36: ='KQKD PET'!F36 -> 0 | G36: ='KQKD PET'!G36+'KQKD HD'!F36 -> 0 | H36: ='KQKD PET'!H36+'KQKD HD'!G36 -> 0 | I36: ='KQKD PET'!I36+'KQKD HD'!H36 -> 0 | J36: ='KQKD PET'!J36+'KQKD HD'!I36 -> 0 | K36: ='KQKD PET'!K36+'KQKD HD'!J36 -> 0 | L36: ='KQKD PET'!L36+'KQKD HD'!K36 -> 0 | M36: ='KQKD PET'!M36+'KQKD HD'!L36 -> 0 | N36: ='KQKD PET'!N36+'KQKD HD'!M36 -> 0 | ... R36: ='KQKD PET'!R36+'KQKD HD'!Q36 -> 0 | S36: =SUM(G36:R36) -> 0 | U36: =F36/F$9 -> 0 | V36: =S36/S$9 -> 0
B37: 83 | C37: Khấu hao tài sản | D37: ='KQKD PET'!D37 -> 0 | E37: ='KQKD PET'!E37 -> 0 | F37: ='KQKD PET'!F37 -> 0 | G37: ='KQKD PET'!G37+'KQKD HD'!F37 -> 0 | H37: ='KQKD PET'!H37+'KQKD HD'!G37 -> 0 | I37: ='KQKD PET'!I37+'KQKD HD'!H37 -> 0 | J37: ='KQKD PET'!J37+'KQKD HD'!I37 -> 0 | K37: ='KQKD PET'!K37+'KQKD HD'!J37 -> 0 | L37: ='KQKD PET'!L37+'KQKD HD'!K37 -> 0 | M37: ='KQKD PET'!M37+'KQKD HD'!L37 -> 0 | N37: ='KQKD PET'!N37+'KQKD HD'!M37 -> 0 | ... R37: ='KQKD PET'!R37+'KQKD HD'!Q37 -> 0 | S37: =SUM(G37:R37) -> 0 | U37: =F37/F$9 -> 0 | V37: =S37/S$9 -> 0
B38: 9 | C38: CHI PHÍ QUẢN LÝ | D38: ='KQKD PET'!D38 -> 1414416772 | E38: ='KQKD PET'!E38 -> 2036034770 | F38: ='KQKD PET'!F38 -> 3.891071e+09 | G38: =G39+G40+G41 -> 4.7153661e+08 | H38: =H39+H40+H41 -> 4.996212e+08 | I38: =I39+I40+I41 -> 4.3800101e+08 | J38: =J39+J40+J41 -> 4.4143001e+08 | K38: =K39+K40+K41 -> 4.4099057e+08 | L38: =L39+L40+L41 -> 4.3789178e+08 | M38: =M39+M40+M41 -> 4.3766534e+08 | N38: =N39+N40+N41 -> 4.9357986e+08 | ... R38: =R39+R40+R41 -> 4.4120512e+08 | S38: =SUM(G38:R38) -> 5.4138202e+09 | U38: =F38/F$9 -> 0.039816162 | V38: =S38/S$9 -> 0.054358899
B39: 9.1 | C39: Lương | D39: ='KQKD PET'!D39 -> 1124385437 | E39: ='KQKD PET'!E39 -> 1412576558 | F39: ='KQKD PET'!F39 -> 2.8990944e+09 | G39: ='KQKD PET'!G39+'KQKD HD'!F39 -> 323945534 | H39: ='KQKD PET'!H39+'KQKD HD'!G39 -> 362007174 | I39: ='KQKD PET'!I39+'KQKD HD'!H39 -> 317132791 | J39: ='KQKD PET'!J39+'KQKD HD'!I39 -> 325999646 | K39: ='KQKD PET'!K39+'KQKD HD'!J39 -> 321392926 | L39: ='KQKD PET'!L39+'KQKD HD'!K39 -> 325999646 | M39: ='KQKD PET'!M39+'KQKD HD'!L39 -> 323044028 | N39: ='KQKD PET'!N39+'KQKD HD'!M39 -> 323044028 | ... R39: ='KQKD PET'!R39+'KQKD HD'!Q39 -> 323044028 | S39: =SUM(G39:R39) -> 3918100515 | U39: =F39/F$9 -> 0.029665563 | V39: =S39/S$9 -> 0.039340729
B40: 9.2 | C40: Chi phí quản lý (ngoài lương, khấu hao) | D40: ='KQKD PET'!D40 -> 290031335 | E40: ='KQKD PET'!E40 -> 609710270 | F40: ='KQKD PET'!F40 -> 902118544 | G40: ='KQKD PET'!G40+'KQKD HD'!F40 -> 1.3693526e+08 | H40: ='KQKD PET'!H40+'KQKD HD'!G40 -> 1.2695821e+08 | I40: ='KQKD PET'!I40+'KQKD HD'!H40 -> 1.102124e+08 | J40: ='KQKD PET'!J40+'KQKD HD'!I40 -> 1.0477454e+08 | K40: ='KQKD PET'!K40+'KQKD HD'!J40 -> 1.0894183e+08 | L40: ='KQKD PET'!L40+'KQKD HD'!K40 -> 1.0123631e+08 | M40: ='KQKD PET'!M40+'KQKD HD'!L40 -> 1.039655e+08 | N40: ='KQKD PET'!N40+'KQKD HD'!M40 -> 1.5988002e+08 | ... R40: ='KQKD PET'!R40+'KQKD HD'!Q40 -> 1.0750528e+08 | S40: =SUM(G40:R40) -> 1.3678499e+09 | U40: =F40/F$9 -> 0.0092311085 | V40: =S40/S$9 -> 0.01373426
B41: 9.3 | C41: Khấu hao tài sản | D41: ='KQKD PET'!D41 -> 0 | E41: ='KQKD PET'!E41 -> 13747942 | F41: ='KQKD PET'!F41 -> 89858023 | G41: ='KQKD PET'!G41+'KQKD HD'!F41 -> 10655817 | H41: ='KQKD PET'!H41+'KQKD HD'!G41 -> 10655817 | I41: ='KQKD PET'!I41+'KQKD HD'!H41 -> 10655817 | J41: ='KQKD PET'!J41+'KQKD HD'!I41 -> 10655817 | K41: ='KQKD PET'!K41+'KQKD HD'!J41 -> 10655817 | L41: ='KQKD PET'!L41+'KQKD HD'!K41 -> 10655817 | M41: ='KQKD PET'!M41+'KQKD HD'!L41 -> 10655817 | N41: ='KQKD PET'!N41+'KQKD HD'!M41 -> 10655817 | ... R41: ='KQKD PET'!R41+'KQKD HD'!Q41 -> 10655817 | S41: =SUM(G41:R41) -> 1.278698e+08 | U41: =F41/F$9 -> 0.0009194902 | V41: =S41/S$9 -> 0.0012839107
B42: 10 | C42: DOANH THU/CHI PHÍ KHÁC | D42: ='KQKD PET'!D42 -> 114814093 | E42: ='KQKD PET'!E42 -> -59489094 | F42: ='KQKD PET'!F42 -> 283673552 | G42: ='KQKD PET'!G42+'KQKD HD'!F42 -> 0 | H42: ='KQKD PET'!H42+'KQKD HD'!G42 -> 0 | I42: ='KQKD PET'!I42+'KQKD HD'!H42 -> 0 | J42: ='KQKD PET'!J42+'KQKD HD'!I42 -> 0 | K42: ='KQKD PET'!K42+'KQKD HD'!J42 -> 0 | L42: ='KQKD PET'!L42+'KQKD HD'!K42 -> 0 | M42: ='KQKD PET'!M42+'KQKD HD'!L42 -> 0 | N42: ='KQKD PET'!N42+'KQKD HD'!M42 -> 0 | ... R42: ='KQKD PET'!R42+'KQKD HD'!Q42 -> 0 | S42: =SUM(G42:R42) -> 0 | U42: =F42/F$9 -> 0.0029027464 | V42: =S42/S$9 -> 0
...

Sheet KQKD PET
B3: MỤC TIÊU KẾT QUẢ KINH DOANH NĂM 2026 | S3: ĐVT: Triệu đồng
B4: STT | C4: Mục phí | D4: Thực tế năm 2023 | E4: Thực tế năm 2024 | F4: KQKD 2025 | G4: T1 | H4: T2 | I4: T3 | J4: T4 | K4: T5 | L4: T6 | M4: T7 | N4: T8 | O4: T9 | P4: T10 | Q4: T11 | R4: T12 | S4: Kế hoạch 2026 | U4: Kiểm tra lại các sheet chi phí
B5: 1 | C5: SẢN LƯỢNG BÁN (TẤN) | D5: =D6+D7+D8 -> 5652770.5 | E5: =E6+E7+E8 -> 4895018.4 | F5: =F6+F7+F8 -> 5879799 | G5: =G6+G7+G8 -> 533700 | H5: =H6+H7+H8 -> 400275 | I5: =I6+I7+I8 -> 578175 | J5: =J6+J7+J8 -> 622650 | K5: =K6+K7+K8 -> 622650 | ... R5: =R6+R7+R8 -> 622650 | S5: =SUM(G5:R5) -> 7116000 | U5: ='3.Thanh pham'!$T$136+'3.Thanh pham'!$T$97 -> 7116000
B6: 1.1 | C6: Chai PET | D6: ='4.Doanh thu'!AJ22 -> 5652770.5 | E6: ='4.Doanh thu'!AH22 -> 4895018.4 | F6: ='4.Doanh thu'!AF22 -> 5879799 | G6: ='4.Doanh thu'!F22 -> 533700 | H6: ='4.Doanh thu'!G22 -> 400275 | I6: ='4.Doanh thu'!H22 -> 578175 | J6: ='4.Doanh thu'!I22 -> 622650 | K6: ='4.Doanh thu'!J22 -> 622650 | L6: ='4.Doanh thu'!K22 -> 622650 | M6: ='4.Doanh thu'!L22 -> 622650 | N6: ='4.Doanh thu'!M22 -> 622650 | ... R6: ='4.Doanh thu'!Q22 -> 622650 | S6: =SUM(G6:R6) -> 7116000
B7: 1.2 | C7: Vảy PET | D7: ='4.Doanh thu'!AJ80 -> 0 | E7: ='4.Doanh thu'!AH80 -> 0 | F7: ='4.Doanh thu'!AF80 -> 0 | G7: ='4.Doanh thu'!F80 -> 0 | H7: ='4.Doanh thu'!G80 -> 0 | I7: ='4.Doanh thu'!H80 -> 0 | J7: ='4.Doanh thu'!I80 -> 0 | K7: ='4.Doanh thu'!J80 -> 0 | L7: ='4.Doanh thu'!K80 -> 0 | M7: ='4.Doanh thu'!L80 -> 0 | N7: ='4.Doanh thu'!M80 -> 0 | ... R7: ='4.Doanh thu'!Q80 -> 0 | S7: =SUM(G7:R7) -> 0
B8: 1.3 | C8: Vảy HD | S8: =SUM(G8:R8) -> 0
B9: 2 | C9: DOANH THU | D9: =D10+D11+D12+D13 -> 78915665269 | E9: =E10+E11+E12+E13 -> 74523104085 | F9: =F10+F11+F12+F13 -> 97725917198 | G9: =G10+G11+G12+G13 -> 7469550000 | H9: =H10+H11+H12+H13 -> 5602162500 | I9: =I10+I11+I12+I13 -> 8092012500 | J9: =J10+J11+J12+J13 -> 8714475000 | K9: =K10+K11+K12+K13 -> 8714475000 | ... R9: =R10+R11+R12+R13 -> 8714475000 | S9: =SUM(G9:R9) -> 99594000000 | U9: ='4.Doanh thu'!$R$60+'4.Doanh thu'!$R$119 -> 99594000000
B10: 2.1 | C10: Chai PET | D10: ='4.Doanh thu'!AJ60 -> 78915665269 | E10: ='4.Doanh thu'!AH60 -> 74523104085 | F10: ='4.Doanh thu'!AF60 -> 97725917198 | G10: ='4.Doanh thu'!F60 -> 7469550000 | H10: ='4.Doanh thu'!G60 -> 5602162500 | I10: ='4.Doanh thu'!H60 -> 8092012500 | J10: ='4.Doanh thu'!I60 -> 8714475000 | K10: ='4.Doanh thu'!J60 -> 8714475000 | L10: ='4.Doanh thu'!K60 -> 8714475000 | M10: ='4.Doanh thu'!L60 -> 8714475000 | N10: ='4.Doanh thu'!M60 -> 8714475000 | ... R10: ='4.Doanh thu'!Q60 -> 8714475000 | S10: =SUM(G10:R10) -> 99594000000
B11: 2.2 | C11: Vảy PET | D11: ='4.Doanh thu'!AJ119 -> 0 | E11: ='4.Doanh thu'!AH119 -> 0 | F11: ='4.Doanh thu'!AF119 -> 0 | G11: ='4.Doanh thu'!F119 -> 0 | H11: ='4.Doanh thu'!G119 -> 0 | I11: ='4.Doanh thu'!H119 -> 0 | J11: ='4.Doanh thu'!I119 -> 0 | K11: ='4.Doanh thu'!J119 -> 0 | L11: ='4.Doanh thu'!K119 -> 0 | M11: ='4.Doanh thu'!L119 -> 0 | N11: ='4.Doanh thu'!M119 -> 0 | ... R11: ='4.Doanh thu'!Q119 -> 0 | S11: =SUM(G11:R11) -> 0
B12: 2.3 | C12: Vảy HD | S12: =SUM(G12:R12) -> 0
B13: 2.4 | C13: Khác | S13: =SUM(G13:R13) -> 0
B14: 3 | C14: BIẾN PHÍ | D14: =D15+D23 -> 7.4913898e+10 | E14: =E15+E23 -> 70945682854 | F14: =F15+F23 -> 8.7040525e+10 | G14: =G15+G23 -> 6.6989855e+09 | H14: =H15+H23 -> 5.1345336e+09 | I14: =I15+I23 -> 7.2126164e+09 | J14: =J15+J23 -> 7.7629387e+09 | K14: =K15+K23 -> 7.7380763e+09 | ... R14: =R15+R23 -> 7.7463711e+09 | S14: =SUM(G14:R14) -> 8.8930411e+10
B15: 3.1 | C15: BIẾN PHÍ SẢN XUẤT | D15: =D16+D20+D21+D22 -> 7.3435299e+10 | E15: =E16+E20+E21+E22 -> 69651631026 | F15: =F16+F20+F21+F22 -> 8.5723904e+10 | G15: =G16+G20+G21+G22 -> 6.5846212e+09 | H15: =H16+H20+H21+H22 -> 5.0487604e+09 | I15: =I16+I20+I21+I22 -> 7.0887217e+09 | J15: =J16+J20+J21+J22 -> 7.6295137e+09 | K15: =K16+K20+K21+K22 -> 7.6046513e+09 | ... R15: =R16+R20+R21+R22 -> 7.6129461e+09 | S15: =SUM(G15:R15) -> 8.7405554e+10
B16: 3.1.1 | C16: Nguyên vật liệu chính (nhựa, gồm hao hụt) | D16: =65387977661-414619518-4421623024+792534516+1021205404+3891200+D17 -> 66674046263 | E16: =58200191176+E17 -> 64023356129 | F16: =57301760425+13642350000+F17 -> 79307026326 | G16: ='1.NVL Chai'!H42 -> 6000000000 | H16: ='1.NVL Chai'!I42 -> 4500000000 | I16: ='1.NVL Chai'!J42 -> 6500000000 | J16: ='1.NVL Chai'!K42 -> 7000000000 | K16: ='1.NVL Chai'!L42 -> 7000000000 | L16: ='1.NVL Chai'!M42 -> 7000000000 | M16: ='1.NVL Chai'!N42 -> 7000000000 | N16: ='1.NVL Chai'!O42 -> 7000000000 | ... R16: ='1.NVL Chai'!S42 -> 7000000000 | S16: =SUM(G16:R16) -> 80000000000 | U16: ='3.Thanh pham'!T198 -> 80000000000
B17: 3.1.2 | C17: Trong đó: i/ Hao hụt CĐ phân loại chai | D17: =4421623024+172191089-312083318+201538626-178589397 -> 4304680024 | E17: 5823164953 | F17: =6555265901+1807650000 -> 8362915901 | G17: =SUM('3.Thanh pham'!H$187:H$189)*'1.NVL Chai'!H$34 -> 663000000 | H17: =SUM('3.Thanh pham'!I$187:I$189)*'1.NVL Chai'!I$34 -> 497250000 | I17: =SUM('3.Thanh pham'!J$187:J$189)*'1.NVL Chai'!J$34 -> 718250000 | J17: =SUM('3.Thanh pham'!K$187:K$189)*'1.NVL Chai'!K$34 -> 773500000 | K17: =SUM('3.Thanh pham'!L$187:L$189)*'1.NVL Chai'!L$34 -> 773500000 | L17: =SUM('3.Thanh pham'!M$187:M$189)*'1.NVL Chai'!M$34 -> 773500000 | M17: =SUM('3.Thanh pham'!N$187:N$189)*'1.NVL Chai'!N$34 -> 773500000 | N17: =SUM('3.Thanh pham'!O$187:O$189)*'1.NVL Chai'!O$34 -> 773500000 | ... R17: =SUM('3.Thanh pham'!S$187:S$189)*'1.NVL Chai'!S$34 -> 773500000 | S17: =SUM(G17:R17) -> 8840000000 | U17: ='3.Thanh pham'!T196 -> 8840000000
C18: ii/ Hao hụt CĐ băm vảy | G18: =('3.Thanh pham'!H$190*'1.NVL Chai'!H$34) -> 0 | H18: =('3.Thanh pham'!I$190*'1.NVL Chai'!I$34) -> 0 | I18: =('3.Thanh pham'!J$190*'1.NVL Chai'!J$34) -> 0 | J18: =('3.Thanh pham'!K$190*'1.NVL Chai'!K$34) -> 0 | K18: =('3.Thanh pham'!L$190*'1.NVL Chai'!L$34) -> 0 | L18: =('3.Thanh pham'!M$190*'1.NVL Chai'!M$34) -> 0 | M18: =('3.Thanh pham'!N$190*'1.NVL Chai'!N$34) -> 0 | N18: =('3.Thanh pham'!O$190*'1.NVL Chai'!O$34) -> 0 | ... R18: =('3.Thanh pham'!S$190*'1.NVL Chai'!S$34) -> 0 | S18: =SUM(G18:R18) -> 0 | U18: =U17-S17-S18 -> 0
B19: 3.1.3 | C19: % chi phí nguyên liệu/doanh thu | D19: =D16/D9 -> 0.8448772 | E19: =E16/E9 -> 0.85910748 | F19: =IFERROR(F16/$F$9,0) -> 0.81152501 | G19: =G16/G9 -> 0.80326124 | H19: =H16/H9 -> 0.80326124 | I19: =I16/I9 -> 0.80326124 | J19: =J16/J9 -> 0.80326124 | K19: =K16/K9 -> 0.80326124 | L19: =L16/L9 -> 0.80326124 | M19: =M16/M9 -> 0.80326124 | N19: =N16/N9 -> 0.80326124 | ... S19: =S16/S9 -> 0.80326124
B20: 3.1.4 | C20: Nguyên vật liệu phụ | D20: =SUM(CPSX!AO19:AO25) -> 630817585 | E20: =SUM(CPSX!AM19:AM25) -> 620417107 | F20: =SUM(CPSX!AK19:AK25) -> 5.6441463e+08 | G20: =SUM(CPSX!K19:K25) -> 1.2915839e+08 | H20: =SUM(CPSX!L19:L25) -> 96868796 | I20: =SUM(CPSX!M19:M25) -> 1.3992159e+08 | J20: =SUM(CPSX!N19:N25) -> 1.5068479e+08 | K20: =SUM(CPSX!O19:O25) -> 1.5068479e+08 | L20: =SUM(CPSX!P19:P25) -> 1.5068479e+08 | M20: =SUM(CPSX!Q19:Q25) -> 1.5068479e+08 | N20: =SUM(CPSX!R19:R25) -> 1.5068479e+08 | ... R20: =SUM(CPSX!V19:V25) -> 1.5068479e+08 | S20: =SUM(G20:R20) -> 1.7221119e+09 | U20: =SUM(CPSX!W19:W25) -> 1.7221119e+09
B21: 3.1.5 | C21: Điện sản xuất | D21: =CPSX!AO$18 -> 326356700 | E21: =CPSX!AM$18 -> 377182809 | F21: =CPSX!AK$18 -> 453250096 | G21: =CPSX!K$18 -> 45584274 | H21: =CPSX!L$18 -> 34188205 | I21: =CPSX!M$18 -> 49382963 | J21: =CPSX!N$18 -> 53181653 | K21: =CPSX!O$18 -> 53181653 | L21: =CPSX!P$18 -> 53181653 | M21: =CPSX!Q$18 -> 53181653 | N21: =CPSX!R$18 -> 53181653 | ... R21: =CPSX!V$18 -> 53181653 | S21: =SUM(G21:R21) -> 6.0779032e+08 | U21: =CPSX!W18 -> 6.0779032e+08
B22: 3.1.6 | C22: Nhân công trực tiếp | D22: =SUM(CPSX!AO6:AO16) -> 5.8040781e+09 | E22: =SUM(CPSX!AM6:AM16) -> 4630674981 | F22: =SUM(CPSX!AK6:AK16) -> 5.3992128e+09 | G22: =SUM(CPSX!K6:K16) -> 4.0987858e+08 | H22: =SUM(CPSX!L6:L16) -> 4.177034e+08 | I22: =SUM(CPSX!M6:M16) -> 3.9941719e+08 | J22: =SUM(CPSX!N6:N16) -> 4.256473e+08 | K22: =SUM(CPSX!O6:O16) -> 4.0078483e+08 | L22: =SUM(CPSX!P6:P16) -> 4.1943392e+08 | M22: =SUM(CPSX!Q6:Q16) -> 4.5096237e+08 | N22: =SUM(CPSX!R6:R16) -> 4.6292885e+08 | ... R22: =SUM(CPSX!V6:V16) -> 4.0907969e+08 | S22: =SUM(G22:R22) -> 5.0756521e+09 | U22: =SUM(CPSX!W6:W16) -> 5.0756521e+09
B23: 3.2 | C23: BIẾN PHÍ BÁN HÀNG | D23: =D24 -> 1478599034 | E23: =E24 -> 1294051828 | F23: =F24 -> 1.3166214e+09 | G23: =G24 -> 1.1436429e+08 | H23: =H24 -> 85773214 | I23: =I24 -> 1.2389464e+08 | J23: =J24 -> 133425000 | K23: =K24 -> 133425000 | ... R23: =R24 -> 133425000 | S23: =SUM(G23:R23) -> 1.5248571e+09 | U23: =CPBH!W8 -> 1.5248571e+09
C24: Chi phí vận chuyển | D24: =CPBH!AO$8 -> 1478599034 | E24: =CPBH!AM$8 -> 1294051828 | F24: =CPBH!AK$8 -> 1.3166214e+09 | G24: =CPBH!K$8 -> 1.1436429e+08 | H24: =CPBH!L$8 -> 85773214 | I24: =CPBH!M$8 -> 1.2389464e+08 | J24: =CPBH!N$8 -> 133425000 | K24: =CPBH!O$8 -> 133425000 | L24: =CPBH!P$8 -> 133425000 | M24: =CPBH!Q$8 -> 133425000 | N24: =CPBH!R$8 -> 133425000 | ... R24: =CPBH!V$8 -> 133425000 | S24: =SUM(G24:R24) -> 1.5248571e+09
B25: 4 | C25: LÃI SAU BIẾN PHÍ | D25: =D9-D14 -> 4.0017676e+09 | E25: =E9-E14 -> 3577421231 | F25: =F9-F14 -> 1.0685392e+10 | G25: =G9-G14 -> 7.7056447e+08 | H25: =H9-H14 -> 4.6762888e+08 | I25: =I9-I14 -> 8.7939612e+08 | J25: =J9-J14 -> 9.5153625e+08 | K25: =K9-K14 -> 9.7639873e+08 | ... R25: =R9-R14 -> 9.6810387e+08 | S25: =SUM(G25:R25) -> 1.0663589e+10
B26: 4.1 | C26: % lãi biến phí/doanh thu | D26: =D25/D9 -> 0.05070942 | E26: =E25/E9 -> 0.04800419 | F26: =IFERROR(F23/$F$9,0) -> 0.013472592 | G26: =G25/G9 -> 0.10316076 | H26: =H25/H9 -> 0.083472924 | I26: =I25/I9 -> 0.10867459 | J26: =J25/J9 -> 0.10919031 | K26: =K25/K9 -> 0.11204332 | L26: =L25/L9 -> 0.10990331 | M26: =M25/M9 -> 0.10628537 | N26: =N25/N9 -> 0.1049122 | ... S26: =S25/S9 -> 0.10707059
B27: 5 | C27: CHI PHÍ SẢN XUẤT CHUNG | D27: =D28+D29+D30 -> 2.0941578e+09 | E27: =E28+E29+E30 -> 2385196776 | F27: =F28+F29+F30 -> 4.2048304e+09 | G27: =G28+G29+G30 -> 5.2485398e+08 | H27: =H28+H29+H30 -> 5.3468413e+08 | I27: =I28+I29+I30 -> 4.9822558e+08 | J27: =J28+J29+J30 -> 5.1694045e+08 | K27: =K28+K29+K30 -> 4.9801716e+08 | ... R27: =R28+R29+R30 -> 5.1098676e+08 | S27: =SUM(G27:R27) -> 6.138579e+09
B28: 5.1 | C28: Lương gián tiếp Sản xuất | D28: =SUM(CPSX!AO$72:AO$81) -> 3.1517286e+08 | E28: =SUM(CPSX!AM$72:AM$81) -> 220439144 | F28: =SUM(CPSX!AK$72:AK$81) -> 1.0162315e+09 | G28: =SUM(CPSX!K$72:K$81) -> 2.0140792e+08 | H28: =SUM(CPSX!L$72:L$81) -> 2.2291481e+08 | I28: =SUM(CPSX!M$72:M$81) -> 1.9174351e+08 | J28: =SUM(CPSX!N$72:N$81) -> 2.0729541e+08 | K28: =SUM(CPSX!O$72:O$81) -> 197959424 | L28: =SUM(CPSX!P$72:P$81) -> 2.0561971e+08 | M28: =SUM(CPSX!Q$72:Q$81) -> 2.0558595e+08 | N28: =SUM(CPSX!R$72:R$81) -> 2.0680673e+08 | ... R28: =SUM(CPSX!V$72:V$81) -> 2.0131325e+08 | S28: =SUM(G28:R28) -> 2.4550487e+09
B29: 5.2 | C29: Chi phí thuê xưởng | D29: =CPSX!AO$88 -> 1118310000 | E29: =CPSX!AM$88 -> 1557000000 | F29: =CPSX!AK$88 -> 1800000000 | G29: =CPSX!K$88 -> 150000000 | H29: =CPSX!L$88 -> 150000000 | I29: =CPSX!M$88 -> 150000000 | J29: =CPSX!N$88 -> 150000000 | K29: =CPSX!O$88 -> 150000000 | L29: =CPSX!P$88 -> 150000000 | M29: =CPSX!Q$88 -> 150000000 | N29: =CPSX!R$88 -> 150000000 | ... R29: =CPSX!V$88 -> 150000000 | S29: =SUM(G29:R29) -> 1800000000
B30: 5.3 | C30: Chi phí sản xuất (Ngoài lương, BOM, thuê xưởng, khấu hao) | D30: =CPSX!AO17+SUM(CPSX!AO82:AO87)+SUM(CPSX!AO89:AO98) -> 660674936 | E30: =CPSX!AM17+SUM(CPSX!AM82:AM87)+SUM(CPSX!AM89:AM98) -> 607757632 | F30: =CPSX!AK17+SUM(CPSX!AK82:AK87)+SUM(CPSX!AK89:AK98) -> 1.3885989e+09 | G30: =CPSX!K17+SUM(CPSX!K82:K87)+SUM(CPSX!K89:K98) -> 1.7344606e+08 | H30: =CPSX!L17+SUM(CPSX!L82:L87)+SUM(CPSX!L89:L98) -> 1.6176933e+08 | I30: =CPSX!M17+SUM(CPSX!M82:M87)+SUM(CPSX!M89:M98) -> 1.5648207e+08 | J30: =CPSX!N17+SUM(CPSX!N82:N87)+SUM(CPSX!N89:N98) -> 1.5964503e+08 | K30: =CPSX!O17+SUM(CPSX!O82:O87)+SUM(CPSX!O89:O98) -> 1.5005774e+08 | L30: =CPSX!P17+SUM(CPSX!P82:P87)+SUM(CPSX!P89:P98) -> 1.7035236e+08 | M30: =CPSX!Q17+SUM(CPSX!Q82:Q87)+SUM(CPSX!Q89:Q98) -> 1.5076764e+08 | N30: =CPSX!R17+SUM(CPSX!R82:R87)+SUM(CPSX!R89:R98) -> 1.5511304e+08 | ... R30: =CPSX!V17+SUM(CPSX!V82:V87)+SUM(CPSX!V89:V98) -> 1.5967352e+08 | S30: =SUM(G30:R30) -> 1.8835303e+09
B31: 6 | C31: CHI PHÍ KHẤU HAO | D31: =CPSX!AO99 -> 1036408270 | E31: =CPSX!AM99 -> 1382050356 | F31: =CPSX!AK99 -> 1.9084998e+09 | G31: =SUM(CPSX!K100:K104) -> 81327530 | H31: =SUM(CPSX!L100:L104) -> 81327530 | I31: =SUM(CPSX!M100:M104) -> 81327530 | J31: =SUM(CPSX!N100:N104) -> 81327530 | K31: =SUM(CPSX!O100:O104) -> 81327530 | L31: =SUM(CPSX!P100:P104) -> 81327530 | M31: =SUM(CPSX!Q100:Q104) -> 81327530 | N31: =SUM(CPSX!R100:R104) -> 81327530 | ... R31: =SUM(CPSX!V100:V104) -> 81327530 | S31: =SUM(G31:R31) -> 9.7593036e+08
B32: 7 | C32: LỢI NHUẬN GỘP | D32: =D25-D27-D31 -> 871201538 | E32: =E25-E27-E31 -> -189825901 | F32: =F25-F27-F31 -> 4.5720617e+09 | G32: =G25-G27-G31 -> 1.6438296e+08 | H32: =H25-H27-H31 -> -1.4838278e+08 | I32: =I25-I27-I31 -> 2.9984301e+08 | J32: =J25-J27-J31 -> 3.5326827e+08 | K32: =K25-K27-K31 -> 3.9705403e+08 | ... R32: =R25-R27-R31 -> 3.7578957e+08 | S32: =SUM(G32:R32) -> 3.5490792e+09
B33: 7.1 | C33: % lãi gộp/doanh thu | D33: =D32/D9 -> 0.011039653 | E33: =E32/E9 -> -0.0025472087 | F33: =F32/F9 -> 0.046784536 | G33: =G32/G9 -> 0.022007077 | H33: =H32/H9 -> -0.026486697 | I33: =I32/I9 -> 0.037054195 | J33: =J32/J9 -> 0.040538102 | K33: =K32/K9 -> 0.045562588 | ... S33: =S32/S9 -> 0.035635472
B34: 8 | C34: CHI PHÍ BÁN HÀNG & MKT & R&D | D34: =D35+D36+D37 -> 0 | E34: =E35+E36+E37 -> 0 | F34: =F35+F36+F37 -> 0 | G34: =G35+G36+G37 -> 0 | H34: =H35+H36+H37 -> 0 | I34: =I35+I36+I37 -> 0 | J34: =J35+J36+J37 -> 0 | K34: =K35+K36+K37 -> 0 | ... R34: =R35+R36+R37 -> 0 | S34: =SUM(G34:R34) -> 0
B35: 8.1 | C35: Lương | S35: =SUM(G35:R35) -> 0
B36: 8.2 | C36: Chi phí bán hàng (ngoài lương, khấu hao) | S36: =SUM(G36:R36) -> 0
B37: 8.3 | C37: Khấu hao tài sản | S37: =SUM(G37:R37) -> 0
B38: 9 | C38: CHI PHÍ QUẢN LÝ | D38: =D39+D40+D41 -> 1414416772 | E38: =E39+E40+E41 -> 2036034770 | F38: =F39+F40+F41 -> 3.891071e+09 | G38: =G39+G40+G41 -> 4.7153661e+08 | H38: =H39+H40+H41 -> 4.996212e+08 | I38: =I39+I40+I41 -> 4.3800101e+08 | J38: =J39+J40+J41 -> 4.4143001e+08 | K38: =K39+K40+K41 -> 4.4099057e+08 | ... R38: =R39+R40+R41 -> 4.4120512e+08 | S38: =SUM(G38:R38) -> 5.4138202e+09
B39: 9.1 | C39: Lương | D39: =SUM(CPQL!AO5:AO14) -> 1124385437 | E39: =SUM(CPQL!AM5:AM14) -> 1412576558 | F39: =SUM(CPQL!AK5:AK14) -> 2.8990944e+09 | G39: =SUM(CPQL!K5:K14) -> 323945534 | H39: =SUM(CPQL!L5:L14) -> 362007174 | I39: =SUM(CPQL!M5:M14) -> 317132791 | J39: =SUM(CPQL!N5:N14) -> 325999646 | K39: =SUM(CPQL!O5:O14) -> 321392926 | L39: =SUM(CPQL!P5:P14) -> 325999646 | M39: =SUM(CPQL!Q5:Q14) -> 323044028 | N39: =SUM(CPQL!R5:R14) -> 323044028 | ... R39: =SUM(CPQL!V5:V14) -> 323044028 | S39: =SUM(G39:R39) -> 3918100515
B40: 9.2 | C40: Chi phí quản lý (ngoài lương, khấu hao) | D40: =SUM(CPQL!AO15:AO62) -> 290031335 | E40: =SUM(CPQL!AM15:AM62) -> 609710270 | F40: =SUM(CPQL!AK15:AK62) -> 902118544 | G40: =SUM(CPQL!K15:K62) -> 1.3693526e+08 | H40: =SUM(CPQL!L15:L62) -> 1.2695821e+08 | I40: =SUM(CPQL!M15:M62) -> 1.102124e+08 | J40: =SUM(CPQL!N15:N62) -> 1.0477454e+08 | K40: =SUM(CPQL!O15:O62) -> 1.0894183e+08 | L40: =SUM(CPQL!P15:P62) -> 1.0123631e+08 | M40: =SUM(CPQL!Q15:Q62) -> 1.039655e+08 | N40: =SUM(CPQL!R15:R62) -> 1.5988002e+08 | ... R40: =SUM(CPQL!V15:V62) -> 1.0750528e+08 | S40: =SUM(G40:R40) -> 1.3678499e+09
B41: 9.3 | C41: Khấu hao tài sản | D41: =CPQL!AO63 -> 0 | E41: =CPQL!AM63 -> 13747942 | F41: =CPQL!AK63 -> 89858023 | G41: =CPQL!K63 -> 10655817 | H41: =CPQL!L63 -> 10655817 | I41: =CPQL!M63 -> 10655817 | J41: =CPQL!N63 -> 10655817 | K41: =CPQL!O63 -> 10655817 | L41: =CPQL!P63 -> 10655817 | M41: =CPQL!Q63 -> 10655817 | N41: =CPQL!R63 -> 10655817 | ... R41: =CPQL!V63 -> 10655817 | S41: =SUM(G41:R41) -> 1.278698e+08
B42: 10 | C42: DOANH THU/CHI PHÍ KHÁC | D42: 114814093 | E42: =4158777-63647871 -> -59489094 | F42: 283673552 | S42: =SUM(G42:R42) -> 0 | U42: <= Nhập số liệu
...

Sheet KQKD HD
B3: MỤC TIÊU KẾT QUẢ KINH DOANH NĂM 2026 | R3: ĐVT: Triệu đồng
B4: STT | C4: Mục phí | D4: Thực tế năm 2024 | E4: KQKD 2025 | F4: T1 | G4: T2 | H4: T3 | I4: T4 | J4: T5 | K4: T6 | L4: T7 | M4: T8 | N4: T9 | O4: T10 | P4: T11 | Q4: T12 | R4: Kế hoạch 2026
B5: 1 | C5: SẢN LƯỢNG BÁN (TẤN) | E5: =E6+E7+E8 -> 0 | F5: =F6+F7+F8 -> 0 | G5: =G6+G7+G8 -> 0 | H5: =H6+H7+H8 -> 0 | I5: =I6+I7+I8 -> 0 | J5: =J6+J7+J8 -> 0 | K5: =K6+K7+K8 -> 0 | L5: =L6+L7+L8 -> 0 | ... Q5: =Q6+Q7+Q8 -> 0 | R5: =SUM(F5:Q5) -> 0
B6: 1.1 | C6: Chai PET | R6: =SUM(F6:Q6) -> 0
B7: 1.2 | C7: Vảy PET | R7: =SUM(F7:Q7) -> 0
B8: 1.3 | C8: Vảy HD | F8: ='4.Doanh thu'!F123 -> 0 | G8: ='4.Doanh thu'!G123 -> 0 | H8: ='4.Doanh thu'!H123 -> 0 | I8: ='4.Doanh thu'!I123 -> 0 | J8: ='4.Doanh thu'!J123 -> 0 | K8: ='4.Doanh thu'!K123 -> 0 | L8: ='4.Doanh thu'!L123 -> 0 | M8: ='4.Doanh thu'!M123 -> 0 | ... Q8: ='4.Doanh thu'!Q123 -> 0 | R8: =SUM(F8:Q8) -> 0
B9: 2 | C9: DOANH THU | E9: =E10+E11+E12+E13 -> 0 | F9: =F10+F11+F12+F13 -> 0 | G9: =G10+G11+G12+G13 -> 0 | H9: =H10+H11+H12+H13 -> 0 | I9: =I10+I11+I12+I13 -> 0 | J9: =J10+J11+J12+J13 -> 0 | K9: =K10+K11+K12+K13 -> 0 | L9: =L10+L11+L12+L13 -> 0 | ... Q9: =Q10+Q11+Q12+Q13 -> 0 | R9: =SUM(F9:Q9) -> 0
B10: 2.1 | C10: Chai PET | R10: =SUM(F10:Q10) -> 0
B11: 2.2 | C11: Vảy PET | R11: =SUM(F11:Q11) -> 0
B12: 2.3 | C12: Vảy HD | F12: ='4.Doanh thu'!F125 -> 0 | G12: ='4.Doanh thu'!G125 -> 0 | H12: ='4.Doanh thu'!H125 -> 0 | I12: ='4.Doanh thu'!I125 -> 0 | J12: ='4.Doanh thu'!J125 -> 0 | K12: ='4.Doanh thu'!K125 -> 0 | L12: ='4.Doanh thu'!L125 -> 0 | M12: ='4.Doanh thu'!M125 -> 0 | ... Q12: ='4.Doanh thu'!Q125 -> 0 | R12: =SUM(F12:Q12) -> 0
B13: 2.4 | C13: Khác | R13: =SUM(F13:Q13) -> 0
B14: 3 | C14: BIẾN PHÍ | E14: =E15+E23 -> 0 | F14: =F15+F23 -> 0 | G14: =G15+G23 -> 0 | H14: =H15+H23 -> 0 | I14: =I15+I23 -> 0 | J14: =J15+J23 -> 0 | K14: =K15+K23 -> 0 | L14: =L15+L23 -> 0 | ... Q14: =Q15+Q23 -> 0 | R14: =SUM(F14:Q14) -> 0
B15: 3.1 | C15: BIẾN PHÍ SẢN XUẤT | E15: =E16+E20+E21+E22 -> 0 | F15: =F16+F20+F21+F22 -> 0 | G15: =G16+G20+G21+G22 -> 0 | H15: =H16+H20+H21+H22 -> 0 | I15: =I16+I20+I21+I22 -> 0 | J15: =J16+J20+J21+J22 -> 0 | K15: =K16+K20+K21+K22 -> 0 | L15: =L16+L20+L21+L22 -> 0 | ... Q15: =Q16+Q20+Q21+Q22 -> 0 | R15: =SUM(F15:Q15) -> 0
B16: 3.1.1 | C16: Nguyên vật liệu chính (nhựa, gồm hao hụt) | F16: ='1.NVL Chai'!H21 -> 0 | G16: ='1.NVL Chai'!I21 -> 0 | H16: ='1.NVL Chai'!J21 -> 0 | I16: ='1.NVL Chai'!K21 -> 0 | J16: ='1.NVL Chai'!L21 -> 0 | K16: ='1.NVL Chai'!M21 -> 0 | L16: ='1.NVL Chai'!N21 -> 0 | M16: ='1.NVL Chai'!O21 -> 0 | ... Q16: ='1.NVL Chai'!S21 -> 0 | R16: =SUM(F16:Q16) -> 0
B17: 3.1.2 | C17: Trong đó: i/ Hao hụt CĐ phân loại chai | R17: =SUM(F17:Q17) -> 0
C18: ii/ Hao hụt CĐ băm vảy | F18: ='1.NVL Chai'!H21*'2.Hao hut & % chai '!F48 -> 0 | G18: ='1.NVL Chai'!I21*'2.Hao hut & % chai '!G48 -> 0 | H18: ='1.NVL Chai'!J21*'2.Hao hut & % chai '!H48 -> 0 | I18: ='1.NVL Chai'!K21*'2.Hao hut & % chai '!I48 -> 0 | J18: ='1.NVL Chai'!L21*'2.Hao hut & % chai '!J48 -> 0 | K18: ='1.NVL Chai'!M21*'2.Hao hut & % chai '!K48 -> 0 | L18: ='1.NVL Chai'!N21*'2.Hao hut & % chai '!L48 -> 0 | M18: ='1.NVL Chai'!O21*'2.Hao hut & % chai '!M48 -> 0 | ... Q18: ='1.NVL Chai'!S21*'2.Hao hut & % chai '!Q48 -> 0 | R18: =SUM(F18:Q18) -> 0
B19: 3.1.3 | C19: % chi phí nguyên liệu/doanh thu | E19: =IFERROR(E18/E$9,0) -> 0 | F19: =IFERROR(F18/F$9,0) -> 0 | G19: =IFERROR(G18/G$9,0) -> 0 | H19: =IFERROR(H18/H$9,0) -> 0 | I19: =IFERROR(I18/I$9,0) -> 0 | J19: =IFERROR(J18/J$9,0) -> 0 | K19: =IFERROR(K18/K$9,0) -> 0 | L19: =IFERROR(L18/L$9,0) -> 0 | ... R19: =IFERROR(R18/R$9,0) -> 0
B20: 3.1.4 | C20: Nguyên vật liệu phụ | R20: =SUM(F20:Q20) -> 0
B21: 3.1.5 | C21: Điện sản xuất | R21: =SUM(F21:Q21) -> 0
B22: 3.1.6 | C22: Nhân công trực tiếp | F22: =Luong_HCNS!G62 -> 0 | G22: =Luong_HCNS!H62 -> 0 | H22: =Luong_HCNS!I62 -> 0 | I22: =Luong_HCNS!J62 -> 0 | J22: =Luong_HCNS!K62 -> 0 | K22: =Luong_HCNS!L62 -> 0 | L22: =Luong_HCNS!M62 -> 0 | M22: =Luong_HCNS!N62 -> 0 | ... Q22: =Luong_HCNS!R62 -> 0 | R22: =SUM(F22:Q22) -> 0
B23: 3.2 | C23: BIẾN PHÍ BÁN HÀNG | E23: =E24 -> 0 | F23: =F24 -> 0 | G23: =G24 -> 0 | H23: =H24 -> 0 | I23: =I24 -> 0 | J23: =J24 -> 0 | K23: =K24 -> 0 | L23: =L24 -> 0 | ... Q23: =Q24 -> 0 | R23: =SUM(F23:Q23) -> 0
C24: Chi phí vận chuyển | F24: ='3.Thanh pham'!H141*'Dinh muc'!$G$48 -> 0 | G24: ='3.Thanh pham'!I141*'Dinh muc'!$G$48 -> 0 | H24: ='3.Thanh pham'!J141*'Dinh muc'!$G$48 -> 0 | I24: ='3.Thanh pham'!K141*'Dinh muc'!$G$48 -> 0 | J24: ='3.Thanh pham'!L141*'Dinh muc'!$G$48 -> 0 | K24: ='3.Thanh pham'!M141*'Dinh muc'!$G$48 -> 0 | L24: ='3.Thanh pham'!N141*'Dinh muc'!$G$48 -> 0 | M24: ='3.Thanh pham'!O141*'Dinh muc'!$G$48 -> 0 | ... Q24: ='3.Thanh pham'!S141*'Dinh muc'!$G$48 -> 0 | R24: =SUM(F24:Q24) -> 0
B25: 4 | C25: LÃI SAU BIẾN PHÍ | E25: =E9-E14 -> 0 | F25: =F9-F14 -> 0 | G25: =G9-G14 -> 0 | H25: =H9-H14 -> 0 | I25: =I9-I14 -> 0 | J25: =J9-J14 -> 0 | K25: =K9-K14 -> 0 | L25: =L9-L14 -> 0 | ... Q25: =Q9-Q14 -> 0 | R25: =SUM(F25:Q25) -> 0
B26: 4.1 | C26: % lãi biến phí/doanh thu | E26: =IFERROR(E25/E$9,0) -> 0 | F26: =IFERROR(F25/F$9,0) -> 0 | G26: =IFERROR(G25/G$9,0) -> 0 | H26: =IFERROR(H25/H$9,0) -> 0 | I26: =IFERROR(I25/I$9,0) -> 0 | J26: =IFERROR(J25/J$9,0) -> 0 | K26: =IFERROR(K25/K$9,0) -> 0 | L26: =IFERROR(L25/L$9,0) -> 0 | ... R26: =IFERROR(R25/R$9,0) -> 0
B27: 5 | C27: CHI PHÍ SẢN XUẤT CHUNG | E27: =E28+E29+E30 -> 0 | F27: =F28+F29+F30 -> 0 | G27: =G28+G29+G30 -> 0 | H27: =H28+H29+H30 -> 0 | I27: =I28+I29+I30 -> 0 | J27: =J28+J29+J30 -> 0 | K27: =K28+K29+K30 -> 0 | L27: =L28+L29+L30 -> 0 | ... Q27: =Q28+Q29+Q30 -> 0 | R27: =SUM(F27:Q27) -> 0
B28: 5.1 | C28: Lương gián tiếp Sản xuất | F28: =Luong_HCNS!G61 -> 0 | G28: =Luong_HCNS!H61 -> 0 | H28: =Luong_HCNS!I61 -> 0 | I28: =Luong_HCNS!J61 -> 0 | J28: =Luong_HCNS!K61 -> 0 | K28: =Luong_HCNS!L61 -> 0 | L28: =Luong_HCNS!M61 -> 0 | M28: =Luong_HCNS!N61 -> 0 | ... Q28: =Luong_HCNS!R61 -> 0 | R28: =SUM(F28:Q28) -> 0
B29: 5.2 | C29: Chi phí thuê xưởng | R29: =SUM(F29:Q29) -> 0
B30: 5.3 | C30: Chi phí sản xuất (Ngoài lương, BOM, thuê xưởng, khấu hao) | R30: =SUM(F30:Q30) -> 0
B31: 6 | C31: CHI PHÍ KHẤU HAO | R31: =SUM(F31:Q31) -> 0
B32: 7 | C32: LỢI NHUẬN GỘP | E32: =E25-E27-E31 -> 0 | F32: =F25-F27-F31 -> 0 | G32: =G25-G27-G31 -> 0 | H32: =H25-H27-H31 -> 0 | I32: =I25-I27-I31 -> 0 | J32: =J25-J27-J31 -> 0 | K32: =K25-K27-K31 -> 0 | L32: =L25-L27-L31 -> 0 | ... Q32: =Q25-Q27-Q31 -> 0 | R32: =SUM(F32:Q32) -> 0
B33: 7.1 | C33: % lãi gộp/doanh thu | E33: =IFERROR(E32/E$9,0) -> 0 | F33: =IFERROR(F32/F$9,0) -> 0 | G33: =IFERROR(G32/G$9,0) -> 0 | H33: =IFERROR(H32/H$9,0) -> 0 | I33: =IFERROR(I32/I$9,0) -> 0 | J33: =IFERROR(J32/J$9,0) -> 0 | K33: =IFERROR(K32/K$9,0) -> 0 | L33: =IFERROR(L32/L$9,0) -> 0 | ... R33: =IFERROR(R32/R$9,0) -> 0
B34: 8 | C34: CHI PHÍ BÁN HÀNG & MKT & R&D | E34: =E35+E36+E37 -> 0 | F34: =F35+F36+F37 -> 0 | G34: =G35+G36+G37 -> 0 | H34: =H35+H36+H37 -> 0 | I34: =I35+I36+I37 -> 0 | J34: =J35+J36+J37 -> 0 | K34: =K35+K36+K37 -> 0 | L34: =L35+L36+L37 -> 0 | ... Q34: =Q35+Q36+Q37 -> 0 | R34: =SUM(F34:Q34) -> 0
B35: 8.1 | C35: Lương | R35: =SUM(F35:Q35) -> 0
B36: 8.2 | C36: Chi phí bán hàng (ngoài lương, khấu hao) | R36: =SUM(F36:Q36) -> 0
B37: 83 | C37: Khấu hao tài sản | R37: =SUM(F37:Q37) -> 0
B38: 9 | C38: CHI PHÍ QUẢN LÝ | E38: =E39+E40+E41 -> 0 | F38: =F39+F40+F41 -> 0 | G38: =G39+G40+G41 -> 0 | H38: =H39+H40+H41 -> 0 | I38: =I39+I40+I41 -> 0 | J38: =J39+J40+J41 -> 0 | K38: =K39+K40+K41 -> 0 | L38: =L39+L40+L41 -> 0 | ... Q38: =Q39+Q40+Q41 -> 0 | R38: =SUM(F38:Q38) -> 0
B39: 9.1 | C39: Lương | R39: =SUM(F39:Q39) -> 0
