Workbook

Sheet BOM
B2: BẢNG TÍNH SETTLEMENT RULE BOM - ROUTING (co-product)
M3: Hide
B4: I. | C4: CÔNG ĐOẠN PHÂN LOẠI CHAI | D4: BOM - KẾ HOẠCH | F4: Sản lượng thành phẩm thực tế | G4: Hệ số quy đổi | H4: Sản lượng thành phẩm quy đổi | I4: Giá trị nguyên liệu phân bổ cho thành phẩm quy đổi | J4: Settlement rule - BOM | K4: Settlement rule - ROUTING | L4: Ghi chú | M4: Giá bán hiện tại | N4: Hệ số quy đổi giá bán | P4: GT NVL | Q4: CFSX | R4: GT SP Trạm | S4: LG | T4: %
D5: Số lượng | E5: Tỷ lệ | F5: (1) | G5: (2) | H5: (3)= (1)*(2) | I5: (4) | J5: Tỷ lệ | K5: Tỷ lệ
B6: 150000001 | C6: Chai PET xá | D6: 1000 | E6: =SUM(E7:E20) -> 1 | I6: =D6*10000 -> 10000000 | J6: =SUM(J7:J19) -> 1 | K6: =SUM(K7:K19) -> 1 | Q6: 3000
B7: 160000001 | C7: Chai PET B1.1 | D7: 540 | E7: 0.54 | F7: =D7 -> 540 | G7: 1.25 | H7: =F7*G7 -> 675 | I7: =$I$6/$H$21*H7 -> 6422454.8 | J7: =I7/$I$6 -> 0.64224548 | K7: =J7 -> 0.64224548 | L7: (4) = Tổng giá trị NVL /(Tổng số lượng TP quy đổi) * Sl Tp quy đổi. (5) = Giá trị nguyên liệu phân bổ cho thành phẩm quy đổi / Tổng giá trị nguyên liệu phân bổ cho thành phẩm quy đổi | M7: =ROUND(11000+11000*14%+4000,-2) -> 16500 | N7: =M7/$M$21 -> 1.2222222 | P7: =I7/F7 -> 11893.435 | Q7: =$Q$6*K7 -> 1926.7364 | R7: =P7+Q7 -> 13820.171 | S7: =M7-R7 -> 2679.8287 | T7: =S7/M7 -> 0.16241386
B8: 160000081 | C8: Chai PET B1.3 | F8: =D8 -> 0 | H8: =F8*G8 -> 0 | I8: =$I$6/$H$21*H8 -> 0 | J8: =I8/$I$6 -> 0 | K8: =J8 -> 0 | N8: =M8/$M$21 -> 0 | P8: =I8/F8 -> #DIV/0! | Q8: =$Q$6*K8 -> 0 | R8: =P8+Q8 -> #DIV/0! | S8: =M8-R8 -> #DIV/0! | T8: =S8/M8 -> #DIV/0!
B9: 160000002 | C9: Chai PET B2.2 | D9: 30 | E9: 0.03 | F9: =D9 -> 30 | G9: 1.1 | H9: =F9*G9 -> 33 | I9: =$I$6/$H$21*H9 -> 313986.68 | J9: =I9/$I$6 -> 0.031398668 | K9: =J9 -> 0.031398668 | M9: =ROUND(11000+11000*14%+2500,-2) -> 15000 | N9: =M9/$M$21 -> 1.1111111 | P9: =I9/F9 -> 10466.223 | Q9: =$Q$6*K9 -> 94.196004 | R9: =P9+Q9 -> 10560.419 | S9: =M9-R9 -> 4439.5814 | T9: =S9/M9 -> 0.29597209
B10: 160000063 | C10: Chai PET B4 | D10: 20 | E10: 0.02 | F10: =D10 -> 20 | G10: 1 | H10: =F10*G10 -> 20 | I10: =$I$6/$H$21*H10 -> 190294.96 | J10: =I10/$I$6 -> 0.019029496 | K10: =J10 -> 0.019029496 | M10: =ROUND(11000+11000*14%+1000,-2) -> 13500 | N10: =M10/$M$21 -> 1 | P10: =I10/F10 -> 9514.7479 | Q10: =$Q$6*K10 -> 57.088487 | R10: =P10+Q10 -> 9571.8363 | S10: =M10-R10 -> 3928.1637 | T10: =S10/M10 -> 0.29097509
B11: 160000004 | C11: Chai PET B5 | D11: 20 | E11: 0.02 | F11: =D11 -> 20 | G11: 1 | H11: =F11*G11 -> 20 | I11: =$I$6/$H$21*H11 -> 190294.96 | J11: =I11/$I$6 -> 0.019029496 | K11: =J11 -> 0.019029496 | M11: =ROUND(11000+11000*14%+1000,-2) -> 13500 | N11: =M11/$M$21 -> 1 | P11: =I11/F11 -> 9514.7479 | Q11: =$Q$6*K11 -> 57.088487 | R11: =P11+Q11 -> 9571.8363 | S11: =M11-R11 -> 3928.1637 | T11: =S11/M11 -> 0.29097509
C12: Chai PET B6.1 | F12: =D12 -> 0 | H12: =F12*G12 -> 0 | I12: =$I$6/$H$21*H12 -> 0 | J12: =I12/$I$6 -> 0 | K12: =J12 -> 0 | N12: =M12/$M$21 -> 0 | P12: =I12/F12 -> #DIV/0! | Q12: =$Q$6*K12 -> 0 | R12: =P12+Q12 -> #DIV/0! | S12: =M12-R12 -> #DIV/0! | T12: =S12/M12 -> #DIV/0!
B13: 160000005 | C13: Chai PET B6.2 | D13: 270 | E13: 0.27 | F13: =D13 -> 270 | G13: 1.1 | H13: =F13*G13 -> 297 | I13: =$I$6/$H$21*H13 -> 2825880.1 | J13: =I13/$I$6 -> 0.28258801 | K13: =J13 -> 0.28258801 | M13: =ROUND(11000+11000*14%+2500,-2) -> 15000 | N13: =M13/$M$21 -> 1.1111111 | P13: =I13/F13 -> 10466.223 | Q13: =$Q$6*K13 -> 847.76403 | R13: =P13+Q13 -> 11313.987 | S13: =M13-R13 -> 3686.0133 | T13: =S13/M13 -> 0.24573422
B14: 160000007 | C14: Nắp HD Ép Các Màu HDE-06 | D14: 10 | E14: 0.01 | F14: =D14 -> 10 | G14: 0.6 | H14: =F14*G14 -> 6 | I14: =$I$6/$H$21*H14 -> 57088.487 | J14: =I14/$I$6 -> 0.0057088487 | K14: =J14 -> 0.0057088487 | M14: =ROUND(11000+11000*14%-5000,-2) -> 7500 | N14: =M14/$M$21 -> 0.55555556 | P14: =I14/F14 -> 5708.8487 | Q14: =$Q$6*K14 -> 17.126546 | R14: =P14+Q14 -> 5725.9753 | S14: =M14-R14 -> 1774.0247 | T14: =S14/M14 -> 0.23653663
C15: Chai PET B7.1 | E15: 0 | N15: =M15/$M$21 -> 0 | P15: =I15/F15 -> #DIV/0! | Q15: =$Q$6*K15 -> 0 | R15: =P15+Q15 -> #DIV/0! | S15: =M15-R15 -> #DIV/0! | T15: =S15/M15 -> #DIV/0!
B16: 160000084 | C16: Chai PET B7.2 | E16: 0 | N16: =M16/$M$21 -> 0 | P16: =I16/F16 -> #DIV/0! | Q16: =$Q$6*K16 -> 0 | R16: =P16+Q16 -> #DIV/0! | S16: =M16-R16 -> #DIV/0! | T16: =S16/M16 -> #DIV/0!
B17: 160000062 | C17: Cổ Chai PET | E17: 0 | N17: =M17/$M$21 -> 0 | P17: =I17/F17 -> #DIV/0! | Q17: =$Q$6*K17 -> 0 | R17: =P17+Q17 -> #DIV/0! | S17: =M17-R17 -> #DIV/0! | T17: =S17/M17 -> #DIV/0!
B18: 160000006 | C18: Hao Hụt - Tạp chất | D18: 10 | E18: 0.01 | P18: =I18/F18 -> #DIV/0! | Q18: =$Q$6*K18 -> 0 | R18: =P18+Q18 -> #DIV/0! | S18: =M18-R18 -> #DIV/0! | T18: =S18/M18 -> #DIV/0!
B19: 800000006 | C19: Hao hụt - nhãn chai PET | D19: 60 | E19: 0.06 | P19: =I19/F19 -> #DIV/0! | Q19: =$Q$6*K19 -> 0 | R19: =P19+Q19 -> #DIV/0! | S19: =M19-R19 -> #DIV/0! | T19: =S19/M19 -> #DIV/0!
C20: Hao hụt vô hình | D20: =D6-SUM(D7:D19) -> 40 | E20: 0.04 | P20: =I20/F20 -> #DIV/0! | Q20: =$Q$6*K20 -> 0 | R20: =P20+Q20 -> #DIV/0! | S20: =M20-R20 -> #DIV/0! | T20: =S20/M20 -> #DIV/0!
C21: TỔNG | D21: =SUM(D7:D20) -> 1000 | E21: =SUM(E7:E20) -> 1 | F21: =SUM(F7:F20) -> 890 | G21: =SUM(G7:G20) -> 6.05 | H21: =SUM(H7:H20) -> 1051 | I21: =SUM(I7:I20) -> 10000000 | M21: =AVERAGE(M7:M19) -> 13500 | P21: =I21/F21 -> 11235.955 | T21: =S21/M21 -> 0
P22: =10000/(F21/1000)-P21 -> 0
B24: II. | C24: CÔNG ĐOẠN BĂM CHAI B6.2 | D24: BOM - KẾ HOẠCH | F24: Sản lượng thành phẩm thực tế | G24: Hệ số quy đổi | H24: Sản lượng thành phẩm quy đổi | I24: Giá trị nguyên liệu phân bổ cho thành phẩm quy đổi | J24: Settlement rule - BOM | K24: Settlement rule - ROUTING | L24: Ghi chú | M24: Giá bán hiện tại | N24: Hệ số quy đổi giá bán
D25: Số lượng | E25: Tỷ lệ | F25: (1) | G25: (2) | H25: (3)= (1)*(2) | I25: (4) | J25: Tỷ lệ | K25: Tỷ lệ
B26: 160000005 | C26: Chai PET B6.2 | D26: 600 | F26: =SUM(F27:F31) -> 1080 | G26: =SUM(G27:G31) -> 4.1 | I26: =I13/F13*D26 -> 6279733.6
B27: 160000027 | C27: Vảy PET B6.2_A6 | D27: =D26*E27 -> 510 | E27: 0.85 | F27: =D27 -> 510 | G27: 1.35 | H27: =F27*G27 -> 688.5 | I27: =$I$26/$H$31*H27 -> 6093864.1 | J27: =I27/$I$26 -> 0.97040169 | K27: =J27 -> 0.97040169 | L27: (4) = Tổng giá trị NVL /(Tổng số lượng TP quy đổi) * Sl Tp quy đổi. (5) = Giá trị nguyên liệu phân bổ cho thành phẩm quy đổi / Tổng giá trị nguyên liệu phân bổ cho thành phẩm quy đổi | M27: 18500 | N27: =M27/$M$31 -> 1.3214286
B28: 160000059 | C28: Vảy nắp hỗn hợp B6.2 | D28: =D26*E28 -> 30 | E28: 0.05 | F28: =D28 -> 30 | G28: 0.7 | H28: =F28*G28 -> 21 | I28: =$I$26/$H$31*H28 -> 185869.49 | J28: =I28/$I$26 -> 0.029598309 | K28: =J28 -> 0.029598309 | M28: 9500 | N28: =M28/$M$31 -> 0.67857143
C29: Phó sản bụi cám | D29: =D26*5% -> 30
C30: Hao hụt vô hình | D30: =D26*5% -> 30
C31: TỔNG | D31: =SUM(D27:D30) -> 600 | F31: =SUM(F27:F30) -> 540 | G31: =SUM(G27:G30) -> 2.05 | H31: =SUM(H27:H30) -> 709.5 | M31: =AVERAGE(M27:M30) -> 14000

Sheet ROUTING
G2: 1H sx
E3: ROUTING HIỆN TẠI | G3: SOÁT XÉT LẠI BOM SAU 3 THÁNG CHẠY THỬ | I3: Settlement rule - BOM | J3: Settlement rule - ROUTING
B4: 1000445 | C4: Tròn | D4: Đvt | E4: Số lượng | F4: Tỷ lệ | G4: Số lượng | H4: Tỷ lệ | I4: Tỷ lệ | J4: Tỷ lệ
B5: 150000001 | C5: Chai PET B0 | E5: 1000 | G5: 1400 | I5: =SUM(I6:I13) -> 1 | J5: 0.98
B6: LAB01 | C6: Nhân công trực tiếp | D6: h | F6: =E6/$E$5 -> 0 | G6: 15 | I6: 0.95 | J6: 0.97
B7: LAB03 | C7: Nhân công gián tiếp | D7: h | F7: =E7/$E$5 -> 0 | G7: 1 | I7: 0 | J7: 0
B8: ELE01 | C8: Điện | D8: Kw/h | F8: =E8/$E$5 -> 0 | G8: 35 | I8: 0.02 | J8: 0.01
B9: DEP01 | C9: Khấu hao | D9: h | F9: =E9/$E$5 -> 0 | G9: 1 | I9: 0 | J9: 0
B10: OTHE01 | C10: Sản xuất chung | D10: h | F10: =E10/$E$5 -> 0 | G10: 1 | I10: 0.02 | J10: 0.01
F11: =E11/$E$5 -> 0 | I11: 0.01 | J11: 0
F12: =E12/$E$5 -> 0 | I12: 0 | J12: 0.01
F13: =E13/$E$5 -> 0 | I13: 0 | J13: 0
B14: 1000446 | C14: Ép kiện | D14: TB | E14: Số lượng | F14: Tỷ lệ | G14: Số lượng | H14: Tỷ lệ | I14: Tỷ lệ | J14: Tỷ lệ
B15: 150000003 | C15: Chai PET (ép kiện) | D15: =#REF!/#REF! -> #REF! | E15: 1000 | G15: 1300 | I15: =SUM(I16:I24) -> 1 | J15: =SUM(J16:J24) -> 1
B16: LAB01 | C16: Nhân công trực tiếp | E16: 700 | F16: =E16/$E$15 -> 0.7 | G16: 14 | I16: 0.8 | J16: 0.97
B17: LAB03 | C17: Nhân công gián tiếp | E17: 10 | F17: =E17/$E$15 -> 0.01 | G17: 1 | I17: 0 | J17: 0
B18: ELE01 | C18: Điện | E18: 80 | F18: =E18/$E$15 -> 0.08 | G18: 40 | I18: 0.15 | J18: 0
B19: DEP01 | C19: Khấu hao | F19: =E19/$E$15 -> 0 | G19: 1 | I19: 0 | J19: 0
B20: OTHE01 | C20: Sản xuất chung | E20: 15 | F20: =E20/$E$15 -> 0.015 | G20: 1 | I20: 0.02 | J20: 0.01
E21: 25 | F21: =E21/$E$15 -> 0.025 | I21: 0.02 | J21: 0.01
E22: 20 | F22: =E22/$E$15 -> 0.02 | I22: 0.01 | J22: 0
E23: 40 | F23: =E23/$E$15 -> 0.04 | I23: 0 | J23: 0.01
E24: 70 | F24: =E24/$E$15 -> 0.07 | I24: 0 | J24: 0
B25: 1000448 | C25: Tuyển | D25: TB | E25: Số lượng | F25: Tỷ lệ | G25: Số lượng | H25: Tỷ lệ | I25: Tỷ lệ | J25: Tỷ lệ
B26: 152000009 | C26: Chai PET B1 Không Phân Loại | D26: =#REF!/#REF! -> #REF! | E26: 1000 | G26: 2000 | I26: =SUM(I27:I32) -> 1.12 | J26: =SUM(J27:J32) -> 1
B27: LAB01 | C27: Nhân công trực tiếp | F27: =E27/E$26 -> 0 | G27: 9 | I27: 0.92 | J27: 1
B28: LAB03 | C28: Nhân công gián tiếp | F28: =E28/E$26 -> 0 | G28: 1 | I28: 0.06 | J28: 0
B29: ELE01 | C29: Điện | F29: =E29/E$26 -> 0 | G29: 30 | I29: 0.06 | J29: 0
B30: DEP01 | C30: Khấu hao | F30: =E30/E$26 -> 0 | G30: 1 | I30: 0.06 | J30: 0
B31: OTHE01 | C31: Sản xuất chung | F31: =E31/E$26 -> 0 | G31: 1 | J31: 0
F32: =E32/E$26 -> 0 | I32: 0.02 | J32: 0

Sheet BOM (2)
B2: BẢNG TÍNH SETTLEMENT RULE BOM - ROUTING (co-product)
M3: Hide
B4: I. | C4: CÔNG ĐOẠN PHÂN LOẠI CHAI | D4: BOM - KẾ HOẠCH | F4: Sản lượng thành phẩm thực tế | G4: Hệ số quy đổi | H4: Sản lượng thành phẩm quy đổi | I4: Giá trị nguyên liệu phân bổ cho thành phẩm quy đổi | J4: Settlement rule - BOM | K4: Settlement rule - ROUTING | L4: Ghi chú | M4: Giá bán hiện tại | N4: Hệ số quy đổi giá bán | O4: Gap (đảm bảo chi phí và lợi nhuận) | P4: GT NVL | Q4: CFSX | R4: GT SP Trạm | S4: LG | T4: % | V4: Đlộc | X4: KN | Z4: ĐLâm | AB4: Giá thị trường
D5: Số lượng | E5: Tỷ lệ | F5: (1) | G5: (2) | H5: (3)= (1)*(2) | I5: (4) | J5: Tỷ lệ | K5: Tỷ lệ | M5: =MAX(V5,X5,Z5) -> 0.10667325 | U5: Hao hụt | V5: ='[1]1. Đại Lộc'!$O$334 -> 0.10096034 | X5: ='[1]2. Khánh Nga'!$O$39 -> 0.097733527 | Z5: ='[1]3. Đồng Lâm'!$O$344 -> 0.10667325
B6: 150000001 | C6: Chai PET xá | D6: 1000 | E6: =SUM(E7:E20) -> 1 | I6: =D6*10000 -> 10000000 | J6: =SUM(J7:J19) -> 1 | K6: =SUM(K7:K19) -> 1 | Q6: 3000 | V6: ='[3]3.CP_TAN'!$Q$78 -> 3684.4011 | X6: ='[3]3.CP_TAN'!$R$78 -> 2894.8843 | Z6: ='[3]3.CP_TAN'!$S$78 -> 2609.6553 | AB6: 10000
B7: 160000001 | C7: Chai PET B1.1 | D7: 540 | E7: 0.54 | F7: =D7 -> 540 | G7: 1.25 | H7: =F7*G7 -> 675 | I7: =$I$6/$H$21*H7 -> 6422454.8 | J7: =I7/$I$6 -> 0.64224548 | K7: =J7 -> 0.64224548 | L7: (4) = Tổng giá trị NVL /(Tổng số lượng TP quy đổi) * Sl Tp quy đổi. (5) = Giá trị nguyên liệu phân bổ cho thành phẩm quy đổi / Tổng giá trị nguyên liệu phân bổ cho thành phẩm quy đổi | M7: =ROUND(10000+10000*$M$5+O7,-2) -> 14600 | N7: =M7/$M$21 -> 1.2604317 | O7: 3500 | P7: =I7/F7 -> 11893.435 | Q7: =$Q$6*K7 -> 1926.7364 | R7: =P7+Q7 -> 13820.171 | S7: =M7-R7 -> 779.82873 | T7: =S7/M7 -> 0.053412927 | U7: ='[1]1. Đại Lộc'!B327 -> % Chai B1 | V7: ='[1]1. Đại Lộc'!O327 -> 0.65050165 | W7: ='[1]2. Khánh Nga'!B32 -> % Chai B1 | X7: ='[1]2. Khánh Nga'!O32 -> 0.5258354 | Y7: ='[1]3. Đồng Lâm'!B337 -> % Chai B1 | Z7: ='[1]3. Đồng Lâm'!O337 -> 0.50053443 | AB7: 14500 | AC7: 11200 | AE7: =T7*V7 -> 0.034745197
B8: 160000081 | C8: Chai PET B1.3 | F8: =D8 -> 0 | H8: =F8*G8 -> 0 | I8: =$I$6/$H$21*H8 -> 0 | J8: =I8/$I$6 -> 0 | K8: =J8 -> 0 | N8: =M8/$M$21 -> 0 | O8: =O7 -> 3500 | P8: =I8/F8 -> #DIV/0! | Q8: =$Q$6*K8 -> 0 | R8: =P8+Q8 -> #DIV/0! | S8: =M8-R8 -> #DIV/0! | T8: =S8/M8 -> #DIV/0! | AE8: =T8*V8 -> #DIV/0!
B9: 160000002 | C9: Chai PET B2.2 | D9: 30 | E9: 0.03 | F9: =D9 -> 30 | G9: 1.1 | H9: =F9*G9 -> 33 | I9: =$I$6/$H$21*H9 -> 313986.68 | J9: =I9/$I$6 -> 0.031398668 | K9: =J9 -> 0.031398668 | M9: =ROUND(10000+10000*$M$5%+2000,-2) -> 12000 | N9: =M9/$M$21 -> 1.0359712 | O9: 2000 | P9: =I9/F9 -> 10466.223 | Q9: =$Q$6*K9 -> 94.196004 | R9: =P9+Q9 -> 10560.419 | S9: =M9-R9 -> 1439.5814 | T9: =S9/M9 -> 0.11996511 | U9: ='[1]1. Đại Lộc'!B328 -> % Chai B2.2 | V9: ='[1]1. Đại Lộc'!O328 -> 0.0053561787 | W9: ='[1]2. Khánh Nga'!B33 -> % Chai B2.2 | X9: ='[1]2. Khánh Nga'!O33 -> 0.078724377 | Y9: ='[1]3. Đồng Lâm'!B338 -> % Chai B2.2 | Z9: ='[1]3. Đồng Lâm'!O338 -> 0.08356034 | AE9: =T9*V9 -> 0.00064255458
B10: 160000063 | C10: Chai PET B4 | D10: 20 | E10: 0.02 | F10: =D10 -> 20 | G10: 1 | H10: =F10*G10 -> 20 | I10: =$I$6/$H$21*H10 -> 190294.96 | J10: =I10/$I$6 -> 0.019029496 | K10: =J10 -> 0.019029496 | M10: =ROUND(10000+10000*$M$5+500,-2) -> 11600 | N10: =M10/$M$21 -> 1.0014388 | O10: 500 | P10: =I10/F10 -> 9514.7479 | Q10: =$Q$6*K10 -> 57.088487 | R10: =P10+Q10 -> 9571.8363 | S10: =M10-R10 -> 2028.1637 | T10: =S10/M10 -> 0.17484169 | U10: ='[1]2. Khánh Nga'!B35 -> % Chai B4 | V10: ='[1]2. Khánh Nga'!O35 -> 0.014912634 | W10: ='[1]2. Khánh Nga'!B35 -> % Chai B4 | X10: ='[1]2. Khánh Nga'!O35 -> 0.014912634 | Y10: ='[1]3. Đồng Lâm'!B340 -> % Chai B4 | Z10: ='[1]3. Đồng Lâm'!O340 -> 0.019139602 | AE10: =T10*V10 -> 0.0026073502
B11: 160000004 | C11: Chai PET B5 | D11: 20 | E11: 0.02 | F11: =D11 -> 20 | G11: 1 | H11: =F11*G11 -> 20 | I11: =$I$6/$H$21*H11 -> 190294.96 | J11: =I11/$I$6 -> 0.019029496 | K11: =J11 -> 0.019029496 | M11: =ROUND(10000+10000*$M$5+500,-2) -> 11600 | N11: =M11/$M$21 -> 1.0014388 | O11: =O10 -> 500 | P11: =I11/F11 -> 9514.7479 | Q11: =$Q$6*K11 -> 57.088487 | R11: =P11+Q11 -> 9571.8363 | S11: =M11-R11 -> 2028.1637 | T11: =S11/M11 -> 0.17484169 | U11: ='[1]2. Khánh Nga'!B36 -> % Chai B5 | V11: ='[1]2. Khánh Nga'!O36 -> 0.019802359 | W11: ='[1]2. Khánh Nga'!B36 -> % Chai B5 | X11: ='[1]2. Khánh Nga'!O36 -> 0.019802359 | Y11: ='[1]3. Đồng Lâm'!B341 -> % Chai B5 | Z11: ='[1]3. Đồng Lâm'!O341 -> 0.010656982 | AE11: =T11*V11 -> 0.0034622779
C12: Chai PET B6.1 | F12: =D12 -> 0 | H12: =F12*G12 -> 0 | I12: =$I$6/$H$21*H12 -> 0 | J12: =I12/$I$6 -> 0 | K12: =J12 -> 0 | N12: =M12/$M$21 -> 0 | O12: =O8 -> 3500 | P12: =I12/F12 -> #DIV/0! | Q12: =$Q$6*K12 -> 0 | R12: =P12+Q12 -> #DIV/0! | S12: =M12-R12 -> #DIV/0! | T12: =S12/M12 -> #DIV/0! | AE12: =T12*V12 -> #DIV/0!
B13: 160000005 | C13: Chai PET B6.2 | D13: 270 | E13: 0.27 | F13: =D13 -> 270 | G13: 1.1 | H13: =F13*G13 -> 297 | I13: =$I$6/$H$21*H13 -> 2825880.1 | J13: =I13/$I$6 -> 0.28258801 | K13: =J13 -> 0.28258801 | M13: =ROUND(10000+10000*$M$5+2500,-2) -> 13600 | N13: =M13/$M$21 -> 1.1741007 | O13: =O9 -> 2000 | P13: =I13/F13 -> 10466.223 | Q13: =$Q$6*K13 -> 847.76403 | R13: =P13+Q13 -> 11313.987 | S13: =M13-R13 -> 2286.0133 | T13: =S13/M13 -> 0.16808921 | U13: ='[1]1. Đại Lộc'!B329 -> % Chai B6.2 | V13: ='[1]1. Đại Lộc'!O329 -> 0.19170632 | W13: ='[1]2. Khánh Nga'!B34 -> % Chai B6.2 | X13: ='[1]2. Khánh Nga'!O34 -> 0.23118717 | Y13: ='[1]3. Đồng Lâm'!B339 -> % Chai B6.2 | Z13: ='[1]3. Đồng Lâm'!O339 -> 0.26757253 | AE13: =T13*V13 -> 0.032223765
B14: 160000007 | C14: Nắp HD Ép Các Màu HDE-06 | D14: 10 | E14: 0.01 | F14: =D14 -> 10 | G14: 0.6 | H14: =F14*G14 -> 6 | I14: =$I$6/$H$21*H14 -> 57088.487 | J14: =I14/$I$6 -> 0.0057088487 | K14: =J14 -> 0.0057088487 | M14: =ROUND(10000+10000*$M$5-5000,-2) -> 6100 | N14: =M14/$M$21 -> 0.52661871 | O14: -5000 | P14: =I14/F14 -> 5708.8487 | Q14: =$Q$6*K14 -> 17.126546 | R14: =P14+Q14 -> 5725.9753 | S14: =M14-R14 -> 374.02474 | T14: =S14/M14 -> 0.061315531 | U14: ='[1]2. Khánh Nga'!B37 -> % Nắp | V14: ='[1]2. Khánh Nga'!O37 -> 0.031786115 | W14: ='[1]2. Khánh Nga'!B37 -> % Nắp | X14: ='[1]2. Khánh Nga'!O37 -> 0.031786115 | Y14: ='[1]3. Đồng Lâm'!B342 -> % Nắp | Z14: ='[1]3. Đồng Lâm'!O342 -> 0.0029470813 | AE14: =T14*V14 -> 0.0019489825
C15: Chai PET B7.1 | E15: 0 | N15: =M15/$M$21 -> 0 | P15: =I15/F15 -> #DIV/0! | Q15: =$Q$6*K15 -> 0 | R15: =P15+Q15 -> #DIV/0! | S15: =M15-R15 -> #DIV/0! | T15: =S15/M15 -> #DIV/0! | AE15: =T15*V15 -> #DIV/0!
B16: 160000084 | C16: Chai PET B7.2 | E16: 0 | N16: =M16/$M$21 -> 0 | O16: -1000 | P16: =I16/F16 -> #DIV/0! | Q16: =$Q$6*K16 -> 0 | R16: =P16+Q16 -> #DIV/0! | S16: =M16-R16 -> #DIV/0! | T16: =S16/M16 -> #DIV/0! | U16: ='[1]2. Khánh Nga'!B38 -> % Chai B7.2 | V16: ='[1]2. Khánh Nga'!O38 -> 1.842727e-05 | W16: ='[1]2. Khánh Nga'!B38 -> % Chai B7.2 | X16: ='[1]2. Khánh Nga'!O38 -> 1.842727e-05 | Y16: ='[1]3. Đồng Lâm'!B343 -> % Phó sản | Z16: ='[1]3. Đồng Lâm'!O343 -> 0.0089157794
B17: 160000062 | C17: Cổ Chai PET | E17: 0 | N17: =M17/$M$21 -> 0 | O17: 2000 | P17: =I17/F17 -> #DIV/0! | Q17: =$Q$6*K17 -> 0 | R17: =P17+Q17 -> #DIV/0! | S17: =M17-R17 -> #DIV/0! | T17: =S17/M17 -> #DIV/0!
B18: 160000006 | C18: Hao Hụt - Tạp chất | D18: 10 | E18: 0.01 | P18: =I18/F18 -> #DIV/0! | Q18: =$Q$6*K18 -> 0 | R18: =P18+Q18 -> #DIV/0! | S18: =M18-R18 -> #DIV/0! | T18: =S18/M18 -> #DIV/0!
B19: 800000006 | C19: Hao hụt - nhãn chai PET | D19: 60 | E19: 0.06 | P19: =I19/F19 -> #DIV/0! | Q19: =$Q$6*K19 -> 0 | R19: =P19+Q19 -> #DIV/0! | S19: =M19-R19 -> #DIV/0! | T19: =S19/M19 -> #DIV/0!
C20: Hao hụt vô hình | D20: =D6-SUM(D7:D19) -> 40 | E20: 0.04 | P20: =I20/F20 -> #DIV/0! | Q20: =$Q$6*K20 -> 0 | R20: =P20+Q20 -> #DIV/0! | S20: =M20-R20 -> #DIV/0! | T20: =S20/M20 -> #DIV/0!
C21: TỔNG | D21: =SUM(D7:D20) -> 1000 | E21: =SUM(E7:E20) -> 1 | F21: =SUM(F7:F20) -> 890 | G21: =SUM(G7:G20) -> 6.05 | H21: =SUM(H7:H20) -> 1051 | I21: =SUM(I7:I20) -> 10000000 | M21: =AVERAGE(M7:M19) -> 11583.333 | P21: =I21/F21 -> 11235.955 | T21: =S21/M21 -> 0
P22: =10000/(F21/1000)-P21 -> 0
B24: II. | C24: CÔNG ĐOẠN BĂM CHAI B6.2 | D24: BOM - KẾ HOẠCH | F24: Sản lượng thành phẩm thực tế | G24: Hệ số quy đổi | H24: Sản lượng thành phẩm quy đổi | I24: Giá trị nguyên liệu phân bổ cho thành phẩm quy đổi | J24: Settlement rule - BOM | K24: Settlement rule - ROUTING | L24: Ghi chú | M24: Giá bán hiện tại | N24: Hệ số quy đổi giá bán
D25: Số lượng | E25: Tỷ lệ | F25: (1) | G25: (2) | H25: (3)= (1)*(2) | I25: (4) | J25: Tỷ lệ | K25: Tỷ lệ
B26: 160000005 | C26: Chai PET B6.2 | D26: 600 | F26: =SUM(F27:F31) -> 1080 | G26: =SUM(G27:G31) -> 4.1 | I26: =I13/F13*D26 -> 6279733.6
B27: 160000027 | C27: Vảy PET B6.2_A6 | D27: =D26*E27 -> 510 | E27: 0.85 | F27: =D27 -> 510 | G27: 1.35 | H27: =F27*G27 -> 688.5 | I27: =$I$26/$H$31*H27 -> 6093864.1 | J27: =I27/$I$26 -> 0.97040169 | K27: =J27 -> 0.97040169 | L27: (4) = Tổng giá trị NVL /(Tổng số lượng TP quy đổi) * Sl Tp quy đổi. (5) = Giá trị nguyên liệu phân bổ cho thành phẩm quy đổi / Tổng giá trị nguyên liệu phân bổ cho thành phẩm quy đổi | M27: 18500 | N27: =M27/$M$31 -> 1.3214286 | O27: =O9 -> 2000
B28: 160000059 | C28: Vảy nắp hỗn hợp B6.2 | D28: =D26*E28 -> 30 | E28: 0.05 | F28: =D28 -> 30 | G28: 0.7 | H28: =F28*G28 -> 21 | I28: =$I$26/$H$31*H28 -> 185869.49 | J28: =I28/$I$26 -> 0.029598309 | K28: =J28 -> 0.029598309 | M28: 9500 | N28: =M28/$M$31 -> 0.67857143
C29: Phó sản bụi cám | D29: =D26*5% -> 30
C30: Hao hụt vô hình | D30: =D26*5% -> 30
C31: TỔNG | D31: =SUM(D27:D30) -> 600 | F31: =SUM(F27:F30) -> 540 | G31: =SUM(G27:G30) -> 2.05 | H31: =SUM(H27:H30) -> 709.5 | M31: =AVERAGE(M27:M30) -> 14000
C33: Vảy PET_A5.1 mua ngoài | AB33: 16300

Sheet BOM (Long)
B2: BẢNG TÍNH SETTLEMENT RULE BOM - ROUTING (co-product)
M3: Hide | P3: Giá BO sau Phân loại
B4: I. | C4: CÔNG ĐOẠN PHÂN LOẠI CHAI | D4: BOM - KẾ HOẠCH | F4: Sản lượng thành phẩm thực tế | G4: Hệ số quy đổi | H4: Sản lượng thành phẩm quy đổi | I4: Giá trị nguyên liệu phân bổ cho thành phẩm quy đổi | J4: Settlement rule - BOM | K4: Settlement rule - ROUTING | L4: Ghi chú | M4: Giá bán hiện tại | N4: Hệ số quy đổi giá bán | O4: Gap (đảm bảo chi phí và lợi nhuận) | P4: GT NVL | Q4: CFSX | R4: GT SP Trạm | S4: LG | T4: % | V4: Đlộc | X4: KN | Z4: ĐLâm | AB4: Giá thị trường
D5: Số lượng | E5: Tỷ lệ | F5: (1) | G5: (2) | H5: (3)= (1)*(2) | I5: (4) | J5: Tỷ lệ | K5: Tỷ lệ | M5: =MAX(V5,X5,Z5) -> 0.10667325 | U5: Hao hụt | V5: ='[1]1. Đại Lộc'!$O$334 -> 0.10096034 | X5: ='[1]2. Khánh Nga'!$O$39 -> 0.097733527 | Z5: ='[1]3. Đồng Lâm'!$O$344 -> 0.10667325
B6: 150000001 | C6: Chai PET xá | D6: 1000 | E6: =SUM(E7:E20) -> 1 | I6: =D6*$M$6 -> 9700000 | J6: =SUM(J7:J19) -> 1 | K6: =SUM(K7:K19) -> 1 | M6: 9700 | Q6: 3000 | V6: ='[3]3.CP_TAN'!$Q$78 -> 3684.4011 | X6: ='[3]3.CP_TAN'!$R$78 -> 2894.8843 | Z6: ='[3]3.CP_TAN'!$S$78 -> 2609.6553 | AB6: 10000
B7: 160000001 | C7: Chai PET B1.1 | D7: 540 | E7: 0.54 | F7: =D7 -> 540 | G7: 1.25 | H7: =F7*G7 -> 675 | I7: =$I$6/$H$21*H7 -> 6229781.2 | J7: =I7/$I$6 -> 0.64224548 | K7: =J7 -> 0.64224548 | L7: (4) = Tổng giá trị NVL /(Tổng số lượng TP quy đổi) * Sl Tp quy đổi. (5) = Giá trị nguyên liệu phân bổ cho thành phẩm quy đổi / Tổng giá trị nguyên liệu phân bổ cho thành phẩm quy đổi | M7: =ROUND($M$6+$M$6*$M$5+O7,-2) -> 14600 | N7: =M7/$M$21 -> 1.2863436 | O7: 3900 | P7: =I7/F7 -> 11536.632 | Q7: =$Q$6*K7 -> 1926.7364 | R7: =P7+Q7 -> 13463.368 | S7: =M7-R7 -> 1136.6318 | T7: =S7/M7 -> 0.077851492 | U7: ='[1]1. Đại Lộc'!B327 -> % Chai B1 | V7: ='[1]1. Đại Lộc'!O327 -> 0.65050165 | W7: ='[1]2. Khánh Nga'!B32 -> % Chai B1 | X7: ='[1]2. Khánh Nga'!O32 -> 0.5258354 | Y7: ='[1]3. Đồng Lâm'!B337 -> % Chai B1 | Z7: ='[1]3. Đồng Lâm'!O337 -> 0.50053443 | AB7: 14500 | AC7: 11200 | AE7: =T7*V7 -> 0.050642524 | AF7: =ROUND($M$6+$M$6*$M$5,-2) -> 10700
B8: 160000081 | C8: Chai PET B1.3 | F8: =D8 -> 0 | H8: =F8*G8 -> 0 | I8: =$I$6/$H$21*H8 -> 0 | J8: =I8/$I$6 -> 0 | K8: =J8 -> 0 | N8: =M8/$M$21 -> 0 | O8: =O7 -> 3900 | P8: =I8/F8 -> #DIV/0! | Q8: =$Q$6*K8 -> 0 | R8: =P8+Q8 -> #DIV/0! | S8: =M8-R8 -> #DIV/0! | T8: =S8/M8 -> #DIV/0! | AE8: =T8*V8 -> #DIV/0!
B9: 160000002 | C9: Chai PET B2.2 | D9: 30 | E9: 0.03 | F9: =D9 -> 30 | G9: 1.1 | H9: =F9*G9 -> 33 | I9: =$I$6/$H$21*H9 -> 304567.08 | J9: =I9/$I$6 -> 0.031398668 | K9: =J9 -> 0.031398668 | M9: =ROUND($M$6+$M$6*$M$5+O9,-2) -> 12700 | N9: =M9/$M$21 -> 1.1189427 | O9: 2000 | P9: =I9/F9 -> 10152.236 | Q9: =$Q$6*K9 -> 94.196004 | R9: =P9+Q9 -> 10246.432 | S9: =M9-R9 -> 2453.568 | T9: =S9/M9 -> 0.19319433 | U9: ='[1]1. Đại Lộc'!B328 -> % Chai B2.2 | V9: ='[1]1. Đại Lộc'!O328 -> 0.0053561787 | W9: ='[1]2. Khánh Nga'!B33 -> % Chai B2.2 | X9: ='[1]2. Khánh Nga'!O33 -> 0.078724377 | Y9: ='[1]3. Đồng Lâm'!B338 -> % Chai B2.2 | Z9: ='[1]3. Đồng Lâm'!O338 -> 0.08356034 | AE9: =T9*V9 -> 0.0010347834
B10: 160000063 | C10: Chai PET B4 | D10: 20 | E10: 0.02 | F10: =D10 -> 20 | G10: 1 | H10: =F10*G10 -> 20 | I10: =$I$6/$H$21*H10 -> 184586.11 | J10: =I10/$I$6 -> 0.019029496 | K10: =J10 -> 0.019029496 | M10: =ROUND($M$6+$M$6*$M$5+O10,-2) -> 11200 | N10: =M10/$M$21 -> 0.98678414 | O10: 500 | P10: =I10/F10 -> 9229.3054 | Q10: =$Q$6*K10 -> 57.088487 | R10: =P10+Q10 -> 9286.3939 | S10: =M10-R10 -> 1913.6061 | T10: =S10/M10 -> 0.17085769 | U10: ='[1]2. Khánh Nga'!B35 -> % Chai B4 | V10: ='[1]2. Khánh Nga'!O35 -> 0.014912634 | W10: ='[1]2. Khánh Nga'!B35 -> % Chai B4 | X10: ='[1]2. Khánh Nga'!O35 -> 0.014912634 | Y10: ='[1]3. Đồng Lâm'!B340 -> % Chai B4 | Z10: ='[1]3. Đồng Lâm'!O340 -> 0.019139602 | AE10: =T10*V10 -> 0.0025479381
B11: 160000004 | C11: Chai PET B5 | D11: 20 | E11: 0.02 | F11: =D11 -> 20 | G11: 1 | H11: =F11*G11 -> 20 | I11: =$I$6/$H$21*H11 -> 184586.11 | J11: =I11/$I$6 -> 0.019029496 | K11: =J11 -> 0.019029496 | M11: =ROUND($M$6+$M$6*$M$5+O11,-2) -> 11200 | N11: =M11/$M$21 -> 0.98678414 | O11: =O10 -> 500 | P11: =I11/F11 -> 9229.3054 | Q11: =$Q$6*K11 -> 57.088487 | R11: =P11+Q11 -> 9286.3939 | S11: =M11-R11 -> 1913.6061 | T11: =S11/M11 -> 0.17085769 | U11: ='[1]2. Khánh Nga'!B36 -> % Chai B5 | V11: ='[1]2. Khánh Nga'!O36 -> 0.019802359 | W11: ='[1]2. Khánh Nga'!B36 -> % Chai B5 | X11: ='[1]2. Khánh Nga'!O36 -> 0.019802359 | Y11: ='[1]3. Đồng Lâm'!B341 -> % Chai B5 | Z11: ='[1]3. Đồng Lâm'!O341 -> 0.010656982 | AE11: =T11*V11 -> 0.0033833852
C12: Chai PET B6.1 | F12: =D12 -> 0 | H12: =F12*G12 -> 0 | I12: =$I$6/$H$21*H12 -> 0 | J12: =I12/$I$6 -> 0 | K12: =J12 -> 0 | N12: =M12/$M$21 -> 0 | O12: =O8 -> 3900 | P12: =I12/F12 -> #DIV/0! | Q12: =$Q$6*K12 -> 0 | R12: =P12+Q12 -> #DIV/0! | S12: =M12-R12 -> #DIV/0! | T12: =S12/M12 -> #DIV/0! | AE12: =T12*V12 -> #DIV/0!
B13: 160000005 | C13: Chai PET B6.2 | D13: 270 | E13: 0.27 | F13: =D13 -> 270 | G13: 1.1 | H13: =F13*G13 -> 297 | I13: =$I$6/$H$21*H13 -> 2741103.7 | J13: =I13/$I$6 -> 0.28258801 | K13: =J13 -> 0.28258801 | M13: =ROUND($M$6+$M$6*$M$5+O13,-2) -> 12700 | N13: =M13/$M$21 -> 1.1189427 | O13: =O9 -> 2000 | P13: =I13/F13 -> 10152.236 | Q13: =$Q$6*K13 -> 847.76403 | R13: =P13+Q13 -> 11000 | S13: =M13-R13 -> 1700 | T13: =S13/M13 -> 0.13385827 | U13: ='[1]1. Đại Lộc'!B329 -> % Chai B6.2 | V13: ='[1]1. Đại Lộc'!O329 -> 0.19170632 | W13: ='[1]2. Khánh Nga'!B34 -> % Chai B6.2 | X13: ='[1]2. Khánh Nga'!O34 -> 0.23118717 | Y13: ='[1]3. Đồng Lâm'!B339 -> % Chai B6.2 | Z13: ='[1]3. Đồng Lâm'!O339 -> 0.26757253 | AE13: =T13*V13 -> 0.025661476
B14: 160000007 | C14: Nắp HD Ép Các Màu HDE-06 | D14: 10 | E14: 0.01 | F14: =D14 -> 10 | G14: 0.6 | H14: =F14*G14 -> 6 | I14: =$I$6/$H$21*H14 -> 55375.833 | J14: =I14/$I$6 -> 0.0057088487 | K14: =J14 -> 0.0057088487 | M14: =ROUND($M$6+$M$6*$M$5+O14,-2) -> 5700 | N14: =M14/$M$21 -> 0.50220264 | O14: -5000 | P14: =I14/F14 -> 5537.5833 | Q14: =$Q$6*K14 -> 17.126546 | R14: =P14+Q14 -> 5554.7098 | S14: =M14-R14 -> 145.2902 | T14: =S14/M14 -> 0.025489509 | U14: ='[1]2. Khánh Nga'!B37 -> % Nắp | V14: ='[1]2. Khánh Nga'!O37 -> 0.031786115 | W14: ='[1]2. Khánh Nga'!B37 -> % Nắp | X14: ='[1]2. Khánh Nga'!O37 -> 0.031786115 | Y14: ='[1]3. Đồng Lâm'!B342 -> % Nắp | Z14: ='[1]3. Đồng Lâm'!O342 -> 0.0029470813 | AE14: =T14*V14 -> 0.00081021245
C15: Chai PET B7.1 | E15: 0 | N15: =M15/$M$21 -> 0 | P15: =I15/F15 -> #DIV/0! | Q15: =$Q$6*K15 -> 0 | R15: =P15+Q15 -> #DIV/0! | S15: =M15-R15 -> #DIV/0! | T15: =S15/M15 -> #DIV/0! | AE15: =T15*V15 -> #DIV/0!
B16: 160000084 | C16: Chai PET B7.2 | E16: 0 | N16: =M16/$M$21 -> 0 | O16: -1000 | P16: =I16/F16 -> #DIV/0! | Q16: =$Q$6*K16 -> 0 | R16: =P16+Q16 -> #DIV/0! | S16: =M16-R16 -> #DIV/0! | T16: =S16/M16 -> #DIV/0! | U16: ='[1]2. Khánh Nga'!B38 -> % Chai B7.2 | V16: ='[1]2. Khánh Nga'!O38 -> 1.842727e-05 | W16: ='[1]2. Khánh Nga'!B38 -> % Chai B7.2 | X16: ='[1]2. Khánh Nga'!O38 -> 1.842727e-05 | Y16: ='[1]3. Đồng Lâm'!B343 -> % Phó sản | Z16: ='[1]3. Đồng Lâm'!O343 -> 0.0089157794
B17: 160000062 | C17: Cổ Chai PET | E17: 0 | N17: =M17/$M$21 -> 0 | O17: 2000 | P17: =I17/F17 -> #DIV/0! | Q17: =$Q$6*K17 -> 0 | R17: =P17+Q17 -> #DIV/0! | S17: =M17-R17 -> #DIV/0! | T17: =S17/M17 -> #DIV/0!
B18: 160000006 | C18: Hao Hụt - Tạp chất | D18: 10 | E18: 0.01 | P18: =I18/F18 -> #DIV/0! | Q18: =$Q$6*K18 -> 0 | R18: =P18+Q18 -> #DIV/0! | S18: =M18-R18 -> #DIV/0! | T18: =S18/M18 -> #DIV/0!
B19: 800000006 | C19: Hao hụt - nhãn chai PET | D19: 60 | E19: 0.06 | P19: =I19/F19 -> #DIV/0! | Q19: =$Q$6*K19 -> 0 | R19: =P19+Q19 -> #DIV/0! | S19: =M19-R19 -> #DIV/0! | T19: =S19/M19 -> #DIV/0!
C20: Hao hụt vô hình | D20: =D6-SUM(D7:D19) -> 40 | E20: 0.04 | P20: =I20/F20 -> #DIV/0! | Q20: =$Q$6*K20 -> 0 | R20: =P20+Q20 -> #DIV/0! | S20: =M20-R20 -> #DIV/0! | T20: =S20/M20 -> #DIV/0!
C21: TỔNG | D21: =SUM(D7:D20) -> 1000 | E21: =SUM(E7:E20) -> 1 | F21: =SUM(F7:F20) -> 890 | G21: =SUM(G7:G20) -> 6.05 | H21: =SUM(H7:H20) -> 1051 | I21: =SUM(I7:I20) -> 9700000 | M21: =AVERAGE(M7:M19) -> 11350 | P21: =I21/F21 -> 10898.876 | T21: =S21/M21 -> 0
P22: =10000/(F21/1000)-P21 -> 337.07865
B24: II. | C24: CÔNG ĐOẠN BĂM CHAI B6.2 | D24: BOM - KẾ HOẠCH | F24: Sản lượng thành phẩm thực tế | G24: Hệ số quy đổi | H24: Sản lượng thành phẩm quy đổi | I24: Giá trị nguyên liệu phân bổ cho thành phẩm quy đổi | J24: Settlement rule - BOM | K24: Settlement rule - ROUTING | L24: Ghi chú | M24: Giá bán hiện tại | N24: Hệ số quy đổi giá bán
D25: Số lượng | E25: Tỷ lệ | F25: (1) | G25: (2) | H25: (3)= (1)*(2) | I25: (4) | J25: Tỷ lệ | K25: Tỷ lệ
B26: 160000005 | C26: Chai PET B6.2 | D26: 600 | F26: =SUM(F27:F31) -> 1080 | G26: =SUM(G27:G31) -> 4.1 | I26: =I13/F13*D26 -> 6091341.6
B27: 160000027 | C27: Vảy PET B6.2_A6 | D27: =D26*E27 -> 510 | E27: 0.85 | F27: =D27 -> 510 | G27: 1.35 | H27: =F27*G27 -> 688.5 | I27: =$I$26/$H$31*H27 -> 5911048.2 | J27: =I27/$I$26 -> 0.97040169 | K27: =J27 -> 0.97040169 | L27: (4) = Tổng giá trị NVL /(Tổng số lượng TP quy đổi) * Sl Tp quy đổi. (5) = Giá trị nguyên liệu phân bổ cho thành phẩm quy đổi / Tổng giá trị nguyên liệu phân bổ cho thành phẩm quy đổi | M27: =ROUND($M$13+O27,-2) -> 15200 | N27: =M27/$M$31 -> 1.2991453 | O27: =O9+500 -> 2500
B28: 160000059 | C28: Vảy nắp hỗn hợp B6.2 | D28: =D26*E28 -> 30 | E28: 0.05 | F28: =D28 -> 30 | G28: 0.7 | H28: =F28*G28 -> 21 | I28: =$I$26/$H$31*H28 -> 180293.41 | J28: =I28/$I$26 -> 0.029598309 | K28: =J28 -> 0.029598309 | M28: =ROUND($M$14+O28,-2) -> 8200 | N28: =M28/$M$31 -> 0.7008547 | O28: =O27 -> 2500
C29: Phó sản bụi cám | D29: =D26*5% -> 30
C30: Hao hụt vô hình | D30: =D26*5% -> 30
C31: TỔNG | D31: =SUM(D27:D30) -> 600 | F31: =SUM(F27:F30) -> 540 | G31: =SUM(G27:G30) -> 2.05 | H31: =SUM(H27:H30) -> 709.5 | M31: =AVERAGE(M27:M30) -> 11700
C33: Vảy PET_A5.1 mua ngoài | AB33: 16300

Sheet BOM (3NS26)
B2: BẢNG TÍNH SETTLEMENT RULE BOM - ROUTING (co-product)
M3: Hide
B4: I. | C4: CÔNG ĐOẠN PHÂN LOẠI CHAI | D4: BOM - KẾ HOẠCH | F4: Sản lượng thành phẩm thực tế | G4: Hệ số quy đổi | H4: Sản lượng thành phẩm quy đổi | I4: Giá trị nguyên liệu phân bổ cho thành phẩm quy đổi | J4: Settlement rule - BOM | K4: Settlement rule - ROUTING | L4: Ghi chú | M4: Giá bán hiện tại | N4: Hệ số quy đổi giá bán | O4: Gap (đảm bảo chi phí và lợi nhuận) | P4: GT NVL | Q4: CFSX | R4: GT SP Trạm | S4: LG | T4: % | V4: Đlộc | X4: KN | Z4: ĐLâm | AB4: Giá thị trường
D5: Số lượng | E5: Tỷ lệ | F5: (1) | G5: (2) | H5: (3)= (1)*(2) | I5: (4) | J5: Tỷ lệ | K5: Tỷ lệ | M5: =MAX(V5,X5,Z5) -> 0.10667325 | U5: Hao hụt | V5: ='[1]1. Đại Lộc'!$O$334 -> 0.10096034 | X5: ='[1]2. Khánh Nga'!$O$39 -> 0.097733527 | Z5: ='[1]3. Đồng Lâm'!$O$344 -> 0.10667325
B6: 150000001 | C6: Chai PET xá | D6: 1000 | E6: =SUM(E7:E20) -> 1 | I6: =D6*10000 -> 10000000 | J6: =SUM(J7:J19) -> 1 | K6: =SUM(K7:K19) -> 1 | Q6: 3000 | V6: ='[2]3.CP_TAN'!$Q$78*1000 -> 3684.4011 | X6: ='[2]3.CP_TAN'!$R$78*1000 -> 2894.8843 | Z6: ='[2]3.CP_TAN'!$S$78*1000 -> 2609.6553 | AB6: 10000
B7: 160000001 | C7: Chai PET B1.1 | D7: 540 | E7: 0.54 | F7: =D7 -> 540 | G7: 1.25 | H7: =F7*G7 -> 675 | I7: =$I$6/$H$21*H7 -> 6422454.8 | J7: =I7/$I$6 -> 0.64224548 | K7: =J7 -> 0.64224548 | L7: (4) = Tổng giá trị NVL /(Tổng số lượng TP quy đổi) * Sl Tp quy đổi. (5) = Giá trị nguyên liệu phân bổ cho thành phẩm quy đổi / Tổng giá trị nguyên liệu phân bổ cho thành phẩm quy đổi | M7: =ROUND(10000+10000*$M$5+O7,-2) -> 15000 | N7: =M7/$M$21 -> 1.2875536 | O7: 3900 | P7: =I7/F7 -> 11893.435 | Q7: =$Q$6*K7 -> 1926.7364 | R7: =P7+Q7 -> 13820.171 | S7: =M7-R7 -> 1179.8287 | T7: =S7/M7 -> 0.078655249 | U7: ='[1]1. Đại Lộc'!B327 -> % Chai B1 | V7: ='[1]1. Đại Lộc'!O327 -> 0.65050165 | W7: ='[1]2. Khánh Nga'!B32 -> % Chai B1 | X7: ='[1]2. Khánh Nga'!O32 -> 0.5258354 | Y7: ='[1]3. Đồng Lâm'!B337 -> % Chai B1 | Z7: ='[1]3. Đồng Lâm'!O337 -> 0.50053443 | AB7: 14500 | AC7: 11200 | AE7: =T7*V7 -> 0.051165369
B8: 160000081 | C8: Chai PET B1.3 | F8: =D8 -> 0 | H8: =F8*G8 -> 0 | I8: =$I$6/$H$21*H8 -> 0 | J8: =I8/$I$6 -> 0 | K8: =J8 -> 0 | N8: =M8/$M$21 -> 0 | O8: =O7 -> 3900 | P8: =I8/F8 -> #DIV/0! | Q8: =$Q$6*K8 -> 0 | R8: =P8+Q8 -> #DIV/0! | S8: =M8-R8 -> #DIV/0! | T8: =S8/M8 -> #DIV/0! | AE8: =T8*V8 -> #DIV/0!
B9: 160000002 | C9: Chai PET B2.2 | D9: 30 | E9: 0.03 | F9: =D9 -> 30 | G9: 1.1 | H9: =F9*G9 -> 33 | I9: =$I$6/$H$21*H9 -> 313986.68 | J9: =I9/$I$6 -> 0.031398668 | K9: =J9 -> 0.031398668 | M9: =ROUND(10000+10000*$M$5%+2000,-2) -> 12000 | N9: =M9/$M$21 -> 1.0300429 | O9: 2000 | P9: =I9/F9 -> 10466.223 | Q9: =$Q$6*K9 -> 94.196004 | R9: =P9+Q9 -> 10560.419 | S9: =M9-R9 -> 1439.5814 | T9: =S9/M9 -> 0.11996511 | U9: ='[1]1. Đại Lộc'!B328 -> % Chai B2.2 | V9: ='[1]1. Đại Lộc'!O328 -> 0.0053561787 | W9: ='[1]2. Khánh Nga'!B33 -> % Chai B2.2 | X9: ='[1]2. Khánh Nga'!O33 -> 0.078724377 | Y9: ='[1]3. Đồng Lâm'!B338 -> % Chai B2.2 | Z9: ='[1]3. Đồng Lâm'!O338 -> 0.08356034 | AE9: =T9*V9 -> 0.00064255458
B10: 160000063 | C10: Chai PET B4 | D10: 20 | E10: 0.02 | F10: =D10 -> 20 | G10: 1 | H10: =F10*G10 -> 20 | I10: =$I$6/$H$21*H10 -> 190294.96 | J10: =I10/$I$6 -> 0.019029496 | K10: =J10 -> 0.019029496 | M10: =ROUND(10000+10000*$M$5+500,-2) -> 11600 | N10: =M10/$M$21 -> 0.99570815 | O10: 500 | P10: =I10/F10 -> 9514.7479 | Q10: =$Q$6*K10 -> 57.088487 | R10: =P10+Q10 -> 9571.8363 | S10: =M10-R10 -> 2028.1637 | T10: =S10/M10 -> 0.17484169 | U10: ='[1]2. Khánh Nga'!B35 -> % Chai B4 | V10: ='[1]2. Khánh Nga'!O35 -> 0.014912634 | W10: ='[1]2. Khánh Nga'!B35 -> % Chai B4 | X10: ='[1]2. Khánh Nga'!O35 -> 0.014912634 | Y10: ='[1]3. Đồng Lâm'!B340 -> % Chai B4 | Z10: ='[1]3. Đồng Lâm'!O340 -> 0.019139602 | AE10: =T10*V10 -> 0.0026073502
B11: 160000004 | C11: Chai PET B5 | D11: 20 | E11: 0.02 | F11: =D11 -> 20 | G11: 1 | H11: =F11*G11 -> 20 | I11: =$I$6/$H$21*H11 -> 190294.96 | J11: =I11/$I$6 -> 0.019029496 | K11: =J11 -> 0.019029496 | M11: =ROUND(10000+10000*$M$5+500,-2) -> 11600 | N11: =M11/$M$21 -> 0.99570815 | O11: =O10 -> 500 | P11: =I11/F11 -> 9514.7479 | Q11: =$Q$6*K11 -> 57.088487 | R11: =P11+Q11 -> 9571.8363 | S11: =M11-R11 -> 2028.1637 | T11: =S11/M11 -> 0.17484169 | U11: ='[1]2. Khánh Nga'!B36 -> % Chai B5 | V11: ='[1]2. Khánh Nga'!O36 -> 0.019802359 | W11: ='[1]2. Khánh Nga'!B36 -> % Chai B5 | X11: ='[1]2. Khánh Nga'!O36 -> 0.019802359 | Y11: ='[1]3. Đồng Lâm'!B341 -> % Chai B5 | Z11: ='[1]3. Đồng Lâm'!O341 -> 0.010656982 | AE11: =T11*V11 -> 0.0034622779
C12: Chai PET B6.1 | F12: =D12 -> 0 | H12: =F12*G12 -> 0 | I12: =$I$6/$H$21*H12 -> 0 | J12: =I12/$I$6 -> 0 | K12: =J12 -> 0 | N12: =M12/$M$21 -> 0 | O12: =O8 -> 3900 | P12: =I12/F12 -> #DIV/0! | Q12: =$Q$6*K12 -> 0 | R12: =P12+Q12 -> #DIV/0! | S12: =M12-R12 -> #DIV/0! | T12: =S12/M12 -> #DIV/0! | AE12: =T12*V12 -> #DIV/0!
B13: 160000005 | C13: Chai PET B6.2 | D13: 270 | E13: 0.27 | F13: =D13 -> 270 | G13: 1.1 | H13: =F13*G13 -> 297 | I13: =$I$6/$H$21*H13 -> 2825880.1 | J13: =I13/$I$6 -> 0.28258801 | K13: =J13 -> 0.28258801 | M13: =ROUND(10000+10000*$M$5+2500,-2) -> 13600 | N13: =M13/$M$21 -> 1.167382 | O13: =O9 -> 2000 | P13: =I13/F13 -> 10466.223 | Q13: =$Q$6*K13 -> 847.76403 | R13: =P13+Q13 -> 11313.987 | S13: =M13-R13 -> 2286.0133 | T13: =S13/M13 -> 0.16808921 | U13: ='[1]1. Đại Lộc'!B329 -> % Chai B6.2 | V13: ='[1]1. Đại Lộc'!O329 -> 0.19170632 | W13: ='[1]2. Khánh Nga'!B34 -> % Chai B6.2 | X13: ='[1]2. Khánh Nga'!O34 -> 0.23118717 | Y13: ='[1]3. Đồng Lâm'!B339 -> % Chai B6.2 | Z13: ='[1]3. Đồng Lâm'!O339 -> 0.26757253 | AE13: =T13*V13 -> 0.032223765
B14: 160000007 | C14: Nắp HD Ép Các Màu HDE-06 | D14: 10 | E14: 0.01 | F14: =D14 -> 10 | G14: 0.6 | H14: =F14*G14 -> 6 | I14: =$I$6/$H$21*H14 -> 57088.487 | J14: =I14/$I$6 -> 0.0057088487 | K14: =J14 -> 0.0057088487 | M14: =ROUND(10000+10000*$M$5-5000,-2) -> 6100 | N14: =M14/$M$21 -> 0.52360515 | O14: -5000 | P14: =I14/F14 -> 5708.8487 | Q14: =$Q$6*K14 -> 17.126546 | R14: =P14+Q14 -> 5725.9753 | S14: =M14-R14 -> 374.02474 | T14: =S14/M14 -> 0.061315531 | U14: ='[1]2. Khánh Nga'!B37 -> % Nắp | V14: ='[1]2. Khánh Nga'!O37 -> 0.031786115 | W14: ='[1]2. Khánh Nga'!B37 -> % Nắp | X14: ='[1]2. Khánh Nga'!O37 -> 0.031786115 | Y14: ='[1]3. Đồng Lâm'!B342 -> % Nắp | Z14: ='[1]3. Đồng Lâm'!O342 -> 0.0029470813 | AE14: =T14*V14 -> 0.0019489825
C15: Chai PET B7.1 | E15: 0 | N15: =M15/$M$21 -> 0 | P15: =I15/F15 -> #DIV/0! | Q15: =$Q$6*K15 -> 0 | R15: =P15+Q15 -> #DIV/0! | S15: =M15-R15 -> #DIV/0! | T15: =S15/M15 -> #DIV/0! | AE15: =T15*V15 -> #DIV/0!
B16: 160000084 | C16: Chai PET B7.2 | E16: 0 | N16: =M16/$M$21 -> 0 | O16: -1000 | P16: =I16/F16 -> #DIV/0! | Q16: =$Q$6*K16 -> 0 | R16: =P16+Q16 -> #DIV/0! | S16: =M16-R16 -> #DIV/0! | T16: =S16/M16 -> #DIV/0! | U16: ='[1]2. Khánh Nga'!B38 -> % Chai B7.2 | V16: ='[1]2. Khánh Nga'!O38 -> 1.842727e-05 | W16: ='[1]2. Khánh Nga'!B38 -> % Chai B7.2 | X16: ='[1]2. Khánh Nga'!O38 -> 1.842727e-05 | Y16: ='[1]3. Đồng Lâm'!B343 -> % Phó sản | Z16: ='[1]3. Đồng Lâm'!O343 -> 0.0089157794
B17: 160000062 | C17: Cổ Chai PET | E17: 0 | N17: =M17/$M$21 -> 0 | O17: 2000 | P17: =I17/F17 -> #DIV/0! | Q17: =$Q$6*K17 -> 0 | R17: =P17+Q17 -> #DIV/0! | S17: =M17-R17 -> #DIV/0! | T17: =S17/M17 -> #DIV/0!
B18: 160000006 | C18: Hao Hụt - Tạp chất | D18: 10 | E18: 0.01 | P18: =I18/F18 -> #DIV/0! | Q18: =$Q$6*K18 -> 0 | R18: =P18+Q18 -> #DIV/0! | S18: =M18-R18 -> #DIV/0! | T18: =S18/M18 -> #DIV/0!
B19: 800000006 | C19: Hao hụt - nhãn chai PET | D19: 60 | E19: 0.06 | P19: =I19/F19 -> #DIV/0! | Q19: =$Q$6*K19 -> 0 | R19: =P19+Q19 -> #DIV/0! | S19: =M19-R19 -> #DIV/0! | T19: =S19/M19 -> #DIV/0!
C20: Hao hụt vô hình | D20: =D6-SUM(D7:D19) -> 40 | E20: 0.04 | P20: =I20/F20 -> #DIV/0! | Q20: =$Q$6*K20 -> 0 | R20: =P20+Q20 -> #DIV/0! | S20: =M20-R20 -> #DIV/0! | T20: =S20/M20 -> #DIV/0!
C21: TỔNG | D21: =SUM(D7:D20) -> 1000 | E21: =SUM(E7:E20) -> 1 | F21: =SUM(F7:F20) -> 890 | G21: =SUM(G7:G20) -> 6.05 | H21: =SUM(H7:H20) -> 1051 | I21: =SUM(I7:I20) -> 10000000 | M21: =AVERAGE(M7:M19) -> 11650 | P21: =I21/F21 -> 11235.955 | T21: =S21/M21 -> 0
P22: =10000/(F21/1000)-P21 -> 0
B24: II. | C24: CÔNG ĐOẠN BĂM CHAI B6.2 | D24: BOM - KẾ HOẠCH | F24: Sản lượng thành phẩm thực tế | G24: Hệ số quy đổi | H24: Sản lượng thành phẩm quy đổi | I24: Giá trị nguyên liệu phân bổ cho thành phẩm quy đổi | J24: Settlement rule - BOM | K24: Settlement rule - ROUTING | L24: Ghi chú | M24: Giá bán hiện tại | N24: Hệ số quy đổi giá bán
D25: Số lượng | E25: Tỷ lệ | F25: (1) | G25: (2) | H25: (3)= (1)*(2) | I25: (4) | J25: Tỷ lệ | K25: Tỷ lệ
B26: 160000005 | C26: Chai PET B6.2 | D26: 600 | F26: =SUM(F27:F31) -> 1080 | G26: =SUM(G27:G31) -> 4.1 | I26: =I13/F13*D26 -> 6279733.6
B27: 160000027 | C27: Vảy PET B6.2_A6 | D27: =D26*E27 -> 510 | E27: 0.85 | F27: =D27 -> 510 | G27: 1.35 | H27: =F27*G27 -> 688.5 | I27: =$I$26/$H$31*H27 -> 6093864.1 | J27: =I27/$I$26 -> 0.97040169 | K27: =J27 -> 0.97040169 | L27: (4) = Tổng giá trị NVL /(Tổng số lượng TP quy đổi) * Sl Tp quy đổi. (5) = Giá trị nguyên liệu phân bổ cho thành phẩm quy đổi / Tổng giá trị nguyên liệu phân bổ cho thành phẩm quy đổi | M27: =ROUND($M$13+O27,-2) -> 16100 | N27: =M27/$M$31 -> 1.3036437 | O27: =O9+500 -> 2500
B28: 160000059 | C28: Vảy nắp hỗn hợp B6.2 | D28: =D26*E28 -> 30 | E28: 0.05 | F28: =D28 -> 30 | G28: 0.7 | H28: =F28*G28 -> 21 | I28: =$I$26/$H$31*H28 -> 185869.49 | J28: =I28/$I$26 -> 0.029598309 | K28: =J28 -> 0.029598309 | M28: =ROUND($M$14+O28,-2) -> 8600 | N28: =M28/$M$31 -> 0.69635628 | O28: =O27 -> 2500
C29: Phó sản bụi cám | D29: =D26*5% -> 30
C30: Hao hụt vô hình | D30: =D26*5% -> 30
C31: TỔNG | D31: =SUM(D27:D30) -> 600 | F31: =SUM(F27:F30) -> 540 | G31: =SUM(G27:G30) -> 2.05 | H31: =SUM(H27:H30) -> 709.5 | M31: =AVERAGE(M27:M30) -> 12350
C33: Vảy PET_A5.1 mua ngoài | AB33: 16300

Sheet BOM (DLoc)
B2: BẢNG TÍNH SETTLEMENT RULE BOM - ROUTING (co-product)
M3: Hide
B4: I. | C4: CÔNG ĐOẠN PHÂN LOẠI CHAI | D4: BOM - KẾ HOẠCH | F4: Sản lượng thành phẩm thực tế | G4: Hệ số quy đổi | H4: Sản lượng thành phẩm quy đổi | I4: Giá trị nguyên liệu phân bổ cho thành phẩm quy đổi | J4: Settlement rule - BOM | K4: Settlement rule - ROUTING | L4: Ghi chú | M4: Giá bán hiện tại | N4: Hệ số quy đổi giá bán | O4: Gap (đảm bảo chi phí và lợi nhuận) | P4: GT NVL | Q4: CFSX | R4: GT SP Trạm | S4: LG | T4: % | V4: Đlộc | X4: KN | Z4: ĐLâm | AB4: Giá thị trường
D5: Số lượng | E5: Tỷ lệ | F5: (1) | G5: (2) | H5: (3)= (1)*(2) | I5: (4) | J5: Tỷ lệ | K5: Tỷ lệ | M5: =V5 -> 0.10096034 | U5: Hao hụt | V5: ='[1]1. Đại Lộc'!$O$334 -> 0.10096034 | X5: ='[1]2. Khánh Nga'!$O$39 -> 0.097733527 | Z5: ='[1]3. Đồng Lâm'!$O$344 -> 0.10667325
B6: 150000001 | C6: Chai PET xá | D6: 1000 | E6: =SUM(E7:E20) -> 1 | I6: =D6*9500 -> 9500000 | J6: =SUM(J7:J19) -> 1 | K6: =SUM(K7:K19) -> 1 | Q6: =V6 -> 3684.4011 | V6: ='[2]3.CP_TAN'!$Q$78*1000 -> 3684.4011 | X6: ='[2]3.CP_TAN'!$R$78*1000 -> 2894.8843 | Z6: ='[2]3.CP_TAN'!$S$78*1000 -> 2609.6553 | AB6: 10000
B7: 160000001 | C7: Chai PET B1.1 | D7: 540 | E7: 0.54 | F7: =D7 -> 540 | G7: 1.25 | H7: =F7*G7 -> 675 | I7: =$I$6/$H$21*H7 -> 6101332.1 | J7: =I7/$I$6 -> 0.64224548 | K7: =J7 -> 0.64224548 | L7: (4) = Tổng giá trị NVL /(Tổng số lượng TP quy đổi) * Sl Tp quy đổi. (5) = Giá trị nguyên liệu phân bổ cho thành phẩm quy đổi / Tổng giá trị nguyên liệu phân bổ cho thành phẩm quy đổi | M7: =ROUND(10000+10000*$M$5+O7,-2) -> 14500 | N7: =M7/$M$21 -> 1.2608696 | O7: 3500 | P7: =I7/F7 -> 11298.763 | Q7: =$Q$6*K7 -> 2366.2899 | R7: =P7+Q7 -> 13665.053 | S7: =M7-R7 -> 834.94697 | T7: =S7/M7 -> 0.05758255 | U7: ='[1]1. Đại Lộc'!B327 -> % Chai B1 | V7: ='[1]1. Đại Lộc'!O327 -> 0.65050165 | W7: ='[1]2. Khánh Nga'!B32 -> % Chai B1 | X7: ='[1]2. Khánh Nga'!O32 -> 0.5258354 | Y7: ='[1]3. Đồng Lâm'!B337 -> % Chai B1 | Z7: ='[1]3. Đồng Lâm'!O337 -> 0.50053443 | AB7: 14500 | AC7: 11200 | AE7: =T7*V7 -> 0.037457544
B8: 160000081 | C8: Chai PET B1.3 | F8: =D8 -> 0 | H8: =F8*G8 -> 0 | I8: =$I$6/$H$21*H8 -> 0 | J8: =I8/$I$6 -> 0 | K8: =J8 -> 0 | N8: =M8/$M$21 -> 0 | O8: =O7 -> 3500 | P8: =I8/F8 -> #DIV/0! | Q8: =$Q$6*K8 -> 0 | R8: =P8+Q8 -> #DIV/0! | S8: =M8-R8 -> #DIV/0! | T8: =S8/M8 -> #DIV/0! | AE8: =T8*V8 -> #DIV/0!
B9: 160000002 | C9: Chai PET B2.2 | D9: 30 | E9: 0.03 | F9: =D9 -> 30 | G9: 1.1 | H9: =F9*G9 -> 33 | I9: =$I$6/$H$21*H9 -> 298287.35 | J9: =I9/$I$6 -> 0.031398668 | K9: =J9 -> 0.031398668 | M9: =ROUND(10000+10000*$M$5%+2000,-2) -> 12000 | N9: =M9/$M$21 -> 1.0434783 | O9: 2000 | P9: =I9/F9 -> 9942.9115 | Q9: =$Q$6*K9 -> 115.68529 | R9: =P9+Q9 -> 10058.597 | S9: =M9-R9 -> 1941.4032 | T9: =S9/M9 -> 0.1617836 | U9: ='[1]1. Đại Lộc'!B328 -> % Chai B2.2 | V9: ='[1]1. Đại Lộc'!O328 -> 0.0053561787 | W9: ='[1]2. Khánh Nga'!B33 -> % Chai B2.2 | X9: ='[1]2. Khánh Nga'!O33 -> 0.078724377 | Y9: ='[1]3. Đồng Lâm'!B338 -> % Chai B2.2 | Z9: ='[1]3. Đồng Lâm'!O338 -> 0.08356034 | AE9: =T9*V9 -> 0.00086654187
B10: 160000063 | C10: Chai PET B4 | D10: 20 | E10: 0.02 | F10: =D10 -> 20 | G10: 1 | H10: =F10*G10 -> 20 | I10: =$I$6/$H$21*H10 -> 180780.21 | J10: =I10/$I$6 -> 0.019029496 | K10: =J10 -> 0.019029496 | M10: =ROUND(10000+10000*$M$5+500,-2) -> 11500 | N10: =M10/$M$21 -> 1 | O10: 500 | P10: =I10/F10 -> 9039.0105 | Q10: =$Q$6*K10 -> 70.112295 | R10: =P10+Q10 -> 9109.1228 | S10: =M10-R10 -> 2390.8772 | T10: =S10/M10 -> 0.20790237 | U10: ='[1]2. Khánh Nga'!B35 -> % Chai B4 | V10: ='[1]2. Khánh Nga'!O35 -> 0.014912634 | W10: ='[1]2. Khánh Nga'!B35 -> % Chai B4 | X10: ='[1]2. Khánh Nga'!O35 -> 0.014912634 | Y10: ='[1]3. Đồng Lâm'!B340 -> % Chai B4 | Z10: ='[1]3. Đồng Lâm'!O340 -> 0.019139602 | AE10: =T10*V10 -> 0.0031003719
B11: 160000004 | C11: Chai PET B5 | D11: 20 | E11: 0.02 | F11: =D11 -> 20 | G11: 1 | H11: =F11*G11 -> 20 | I11: =$I$6/$H$21*H11 -> 180780.21 | J11: =I11/$I$6 -> 0.019029496 | K11: =J11 -> 0.019029496 | M11: =ROUND(10000+10000*$M$5+500,-2) -> 11500 | N11: =M11/$M$21 -> 1 | O11: =O10 -> 500 | P11: =I11/F11 -> 9039.0105 | Q11: =$Q$6*K11 -> 70.112295 | R11: =P11+Q11 -> 9109.1228 | S11: =M11-R11 -> 2390.8772 | T11: =S11/M11 -> 0.20790237 | U11: ='[1]2. Khánh Nga'!B36 -> % Chai B5 | V11: ='[1]2. Khánh Nga'!O36 -> 0.019802359 | W11: ='[1]2. Khánh Nga'!B36 -> % Chai B5 | X11: ='[1]2. Khánh Nga'!O36 -> 0.019802359 | Y11: ='[1]3. Đồng Lâm'!B341 -> % Chai B5 | Z11: ='[1]3. Đồng Lâm'!O341 -> 0.010656982 | AE11: =T11*V11 -> 0.0041169573
C12: Chai PET B6.1 | F12: =D12 -> 0 | H12: =F12*G12 -> 0 | I12: =$I$6/$H$21*H12 -> 0 | J12: =I12/$I$6 -> 0 | K12: =J12 -> 0 | N12: =M12/$M$21 -> 0 | O12: =O8 -> 3500 | P12: =I12/F12 -> #DIV/0! | Q12: =$Q$6*K12 -> 0 | R12: =P12+Q12 -> #DIV/0! | S12: =M12-R12 -> #DIV/0! | T12: =S12/M12 -> #DIV/0! | AE12: =T12*V12 -> #DIV/0!
B13: 160000005 | C13: Chai PET B6.2 | D13: 270 | E13: 0.27 | F13: =D13 -> 270 | G13: 1.1 | H13: =F13*G13 -> 297 | I13: =$I$6/$H$21*H13 -> 2684586.1 | J13: =I13/$I$6 -> 0.28258801 | K13: =J13 -> 0.28258801 | M13: =ROUND(10000+10000*$M$5+2500,-2) -> 13500 | N13: =M13/$M$21 -> 1.173913 | O13: =O9 -> 2000 | P13: =I13/F13 -> 9942.9115 | Q13: =$Q$6*K13 -> 1041.1676 | R13: =P13+Q13 -> 10984.079 | S13: =M13-R13 -> 2515.9209 | T13: =S13/M13 -> 0.18636451 | U13: ='[1]1. Đại Lộc'!B329 -> % Chai B6.2 | V13: ='[1]1. Đại Lộc'!O329 -> 0.19170632 | W13: ='[1]2. Khánh Nga'!B34 -> % Chai B6.2 | X13: ='[1]2. Khánh Nga'!O34 -> 0.23118717 | Y13: ='[1]3. Đồng Lâm'!B339 -> % Chai B6.2 | Z13: ='[1]3. Đồng Lâm'!O339 -> 0.26757253 | AE13: =T13*V13 -> 0.035727255
B14: 160000007 | C14: Nắp HD Ép Các Màu HDE-06 | D14: 10 | E14: 0.01 | F14: =D14 -> 10 | G14: 0.6 | H14: =F14*G14 -> 6 | I14: =$I$6/$H$21*H14 -> 54234.063 | J14: =I14/$I$6 -> 0.0057088487 | K14: =J14 -> 0.0057088487 | M14: =ROUND(10000+10000*$M$5-5000,-2) -> 6000 | N14: =M14/$M$21 -> 0.52173913 | O14: -5000 | P14: =I14/F14 -> 5423.4063 | Q14: =$Q$6*K14 -> 21.033688 | R14: =P14+Q14 -> 5444.44 | S14: =M14-R14 -> 555.56003 | T14: =S14/M14 -> 0.092593339 | U14: ='[1]2. Khánh Nga'!B37 -> % Nắp | V14: ='[1]2. Khánh Nga'!O37 -> 0.031786115 | W14: ='[1]2. Khánh Nga'!B37 -> % Nắp | X14: ='[1]2. Khánh Nga'!O37 -> 0.031786115 | Y14: ='[1]3. Đồng Lâm'!B342 -> % Nắp | Z14: ='[1]3. Đồng Lâm'!O342 -> 0.0029470813 | AE14: =T14*V14 -> 0.0029431825
C15: Chai PET B7.1 | E15: 0 | N15: =M15/$M$21 -> 0 | P15: =I15/F15 -> #DIV/0! | Q15: =$Q$6*K15 -> 0 | R15: =P15+Q15 -> #DIV/0! | S15: =M15-R15 -> #DIV/0! | T15: =S15/M15 -> #DIV/0! | AE15: =T15*V15 -> #DIV/0!
B16: 160000084 | C16: Chai PET B7.2 | E16: 0 | N16: =M16/$M$21 -> 0 | O16: -1000 | P16: =I16/F16 -> #DIV/0! | Q16: =$Q$6*K16 -> 0 | R16: =P16+Q16 -> #DIV/0! | S16: =M16-R16 -> #DIV/0! | T16: =S16/M16 -> #DIV/0! | U16: ='[1]2. Khánh Nga'!B38 -> % Chai B7.2 | V16: ='[1]2. Khánh Nga'!O38 -> 1.842727e-05 | W16: ='[1]2. Khánh Nga'!B38 -> % Chai B7.2 | X16: ='[1]2. Khánh Nga'!O38 -> 1.842727e-05 | Y16: ='[1]3. Đồng Lâm'!B343 -> % Phó sản | Z16: ='[1]3. Đồng Lâm'!O343 -> 0.0089157794
B17: 160000062 | C17: Cổ Chai PET | E17: 0 | N17: =M17/$M$21 -> 0 | O17: 2000 | P17: =I17/F17 -> #DIV/0! | Q17: =$Q$6*K17 -> 0 | R17: =P17+Q17 -> #DIV/0! | S17: =M17-R17 -> #DIV/0! | T17: =S17/M17 -> #DIV/0!
B18: 160000006 | C18: Hao Hụt - Tạp chất | D18: 10 | E18: 0.01 | P18: =I18/F18 -> #DIV/0! | Q18: =$Q$6*K18 -> 0 | R18: =P18+Q18 -> #DIV/0! | S18: =M18-R18 -> #DIV/0! | T18: =S18/M18 -> #DIV/0!
B19: 800000006 | C19: Hao hụt - nhãn chai PET | D19: 60 | E19: 0.06 | P19: =I19/F19 -> #DIV/0! | Q19: =$Q$6*K19 -> 0 | R19: =P19+Q19 -> #DIV/0! | S19: =M19-R19 -> #DIV/0! | T19: =S19/M19 -> #DIV/0!
C20: Hao hụt vô hình | D20: =D6-SUM(D7:D19) -> 40 | E20: 0.04 | P20: =I20/F20 -> #DIV/0! | Q20: =$Q$6*K20 -> 0 | R20: =P20+Q20 -> #DIV/0! | S20: =M20-R20 -> #DIV/0! | T20: =S20/M20 -> #DIV/0!
C21: TỔNG | D21: =SUM(D7:D20) -> 1000 | E21: =SUM(E7:E20) -> 1 | F21: =SUM(F7:F20) -> 890 | G21: =SUM(G7:G20) -> 6.05 | H21: =SUM(H7:H20) -> 1051 | I21: =SUM(I7:I20) -> 9500000 | M21: =AVERAGE(M7:M19) -> 11500 | P21: =I21/F21 -> 10674.157 | T21: =S21/M21 -> 0
P22: =10000/(F21/1000)-P21 -> 561.79775
B24: II. | C24: CÔNG ĐOẠN BĂM CHAI B6.2 | D24: BOM - KẾ HOẠCH | F24: Sản lượng thành phẩm thực tế | G24: Hệ số quy đổi | H24: Sản lượng thành phẩm quy đổi | I24: Giá trị nguyên liệu phân bổ cho thành phẩm quy đổi | J24: Settlement rule - BOM | K24: Settlement rule - ROUTING | L24: Ghi chú | M24: Giá bán hiện tại | N24: Hệ số quy đổi giá bán
D25: Số lượng | E25: Tỷ lệ | F25: (1) | G25: (2) | H25: (3)= (1)*(2) | I25: (4) | J25: Tỷ lệ | K25: Tỷ lệ
B26: 160000005 | C26: Chai PET B6.2 | D26: 600 | F26: =SUM(F27:F31) -> 1080 | G26: =SUM(G27:G31) -> 4.1 | I26: =I13/F13*D26 -> 5965746.9
B27: 160000027 | C27: Vảy PET B6.2_A6 | D27: =D26*E27 -> 510 | E27: 0.85 | F27: =D27 -> 510 | G27: 1.35 | H27: =F27*G27 -> 688.5 | I27: =$I$26/$H$31*H27 -> 5789170.9 | J27: =I27/$I$26 -> 0.97040169 | K27: =J27 -> 0.97040169 | L27: (4) = Tổng giá trị NVL /(Tổng số lượng TP quy đổi) * Sl Tp quy đổi. (5) = Giá trị nguyên liệu phân bổ cho thành phẩm quy đổi / Tổng giá trị nguyên liệu phân bổ cho thành phẩm quy đổi | M27: =ROUND($M$13+O27,-2) -> 16000 | N27: =M27/$M$31 -> 1.3061224 | O27: =O9+500 -> 2500
B28: 160000059 | C28: Vảy nắp hỗn hợp B6.2 | D28: =D26*E28 -> 30 | E28: 0.05 | F28: =D28 -> 30 | G28: 0.7 | H28: =F28*G28 -> 21 | I28: =$I$26/$H$31*H28 -> 176576.02 | J28: =I28/$I$26 -> 0.029598309 | K28: =J28 -> 0.029598309 | M28: =ROUND($M$14+O28,-2) -> 8500 | N28: =M28/$M$31 -> 0.69387755 | O28: =O27 -> 2500
C29: Phó sản bụi cám | D29: =D26*5% -> 30
C30: Hao hụt vô hình | D30: =D26*5% -> 30
C31: TỔNG | D31: =SUM(D27:D30) -> 600 | F31: =SUM(F27:F30) -> 540 | G31: =SUM(G27:G30) -> 2.05 | H31: =SUM(H27:H30) -> 709.5 | M31: =AVERAGE(M27:M30) -> 12250
C33: Vảy PET_A5.1 mua ngoài | AB33: 16300

Sheet BOM (KN)
B2: BẢNG TÍNH SETTLEMENT RULE BOM - ROUTING (co-product)
M3: Hide
B4: I. | C4: CÔNG ĐOẠN PHÂN LOẠI CHAI | D4: BOM - KẾ HOẠCH | F4: Sản lượng thành phẩm thực tế | G4: Hệ số quy đổi | H4: Sản lượng thành phẩm quy đổi | I4: Giá trị nguyên liệu phân bổ cho thành phẩm quy đổi | J4: Settlement rule - BOM | K4: Settlement rule - ROUTING | L4: Ghi chú | M4: Giá bán hiện tại | N4: Hệ số quy đổi giá bán | O4: Gap (đảm bảo chi phí và lợi nhuận) | P4: GT NVL | Q4: CFSX | R4: GT SP Trạm | S4: LG | T4: % | V4: Đlộc | X4: KN | Z4: ĐLâm | AB4: Giá thị trường
D5: Số lượng | E5: Tỷ lệ | F5: (1) | G5: (2) | H5: (3)= (1)*(2) | I5: (4) | J5: Tỷ lệ | K5: Tỷ lệ | M5: =X5 -> 0.097733527 | U5: Hao hụt | V5: ='[1]1. Đại Lộc'!$O$334 -> 0.10096034 | X5: ='[1]2. Khánh Nga'!$O$39 -> 0.097733527 | Z5: ='[1]3. Đồng Lâm'!$O$344 -> 0.10667325
B6: 150000001 | C6: Chai PET xá | D6: 1000 | E6: =SUM(E7:E20) -> 1 | I6: =D6*9500 -> 9500000 | J6: =SUM(J7:J19) -> 1 | K6: =SUM(K7:K19) -> 1 | Q6: =X6 -> 2894.8843 | V6: ='[2]3.CP_TAN'!$Q$78*1000 -> 3684.4011 | X6: ='[2]3.CP_TAN'!$R$78*1000 -> 2894.8843 | Z6: ='[2]3.CP_TAN'!$S$78*1000 -> 2609.6553 | AB6: 10000
B7: 160000001 | C7: Chai PET B1.1 | D7: 540 | E7: 0.54 | F7: =D7 -> 540 | G7: 1.25 | H7: =F7*G7 -> 675 | I7: =$I$6/$H$21*H7 -> 6101332.1 | J7: =I7/$I$6 -> 0.64224548 | K7: =J7 -> 0.64224548 | L7: (4) = Tổng giá trị NVL /(Tổng số lượng TP quy đổi) * Sl Tp quy đổi. (5) = Giá trị nguyên liệu phân bổ cho thành phẩm quy đổi / Tổng giá trị nguyên liệu phân bổ cho thành phẩm quy đổi | M7: =ROUND(10000+10000*$M$5+O7,-2) -> 14500 | N7: =M7/$M$21 -> 1.2608696 | O7: 3500 | P7: =I7/F7 -> 11298.763 | Q7: =$Q$6*K7 -> 1859.2263 | R7: =P7+Q7 -> 13157.989 | S7: =M7-R7 -> 1342.0106 | T7: =S7/M7 -> 0.092552455 | U7: ='[1]1. Đại Lộc'!B327 -> % Chai B1 | V7: ='[1]1. Đại Lộc'!O327 -> 0.65050165 | W7: ='[1]2. Khánh Nga'!B32 -> % Chai B1 | X7: ='[1]2. Khánh Nga'!O32 -> 0.5258354 | Y7: ='[1]3. Đồng Lâm'!B337 -> % Chai B1 | Z7: ='[1]3. Đồng Lâm'!O337 -> 0.50053443 | AB7: 14500 | AC7: 11200 | AE7: =T7*V7 -> 0.060205525
B8: 160000081 | C8: Chai PET B1.3 | F8: =D8 -> 0 | H8: =F8*G8 -> 0 | I8: =$I$6/$H$21*H8 -> 0 | J8: =I8/$I$6 -> 0 | K8: =J8 -> 0 | N8: =M8/$M$21 -> 0 | O8: =O7 -> 3500 | P8: =I8/F8 -> #DIV/0! | Q8: =$Q$6*K8 -> 0 | R8: =P8+Q8 -> #DIV/0! | S8: =M8-R8 -> #DIV/0! | T8: =S8/M8 -> #DIV/0! | AE8: =T8*V8 -> #DIV/0!
B9: 160000002 | C9: Chai PET B2.2 | D9: 30 | E9: 0.03 | F9: =D9 -> 30 | G9: 1.1 | H9: =F9*G9 -> 33 | I9: =$I$6/$H$21*H9 -> 298287.35 | J9: =I9/$I$6 -> 0.031398668 | K9: =J9 -> 0.031398668 | M9: =ROUND(10000+10000*$M$5%+2000,-2) -> 12000 | N9: =M9/$M$21 -> 1.0434783 | O9: 2000 | P9: =I9/F9 -> 9942.9115 | Q9: =$Q$6*K9 -> 90.895509 | R9: =P9+Q9 -> 10033.807 | S9: =M9-R9 -> 1966.193 | T9: =S9/M9 -> 0.16384941 | U9: ='[1]1. Đại Lộc'!B328 -> % Chai B2.2 | V9: ='[1]1. Đại Lộc'!O328 -> 0.0053561787 | W9: ='[1]2. Khánh Nga'!B33 -> % Chai B2.2 | X9: ='[1]2. Khánh Nga'!O33 -> 0.078724377 | Y9: ='[1]3. Đồng Lâm'!B338 -> % Chai B2.2 | Z9: ='[1]3. Đồng Lâm'!O338 -> 0.08356034 | AE9: =T9*V9 -> 0.00087760675
B10: 160000063 | C10: Chai PET B4 | D10: 20 | E10: 0.02 | F10: =D10 -> 20 | G10: 1 | H10: =F10*G10 -> 20 | I10: =$I$6/$H$21*H10 -> 180780.21 | J10: =I10/$I$6 -> 0.019029496 | K10: =J10 -> 0.019029496 | M10: =ROUND(10000+10000*$M$5+500,-2) -> 11500 | N10: =M10/$M$21 -> 1 | O10: 500 | P10: =I10/F10 -> 9039.0105 | Q10: =$Q$6*K10 -> 55.088187 | R10: =P10+Q10 -> 9094.0987 | S10: =M10-R10 -> 2405.9013 | T10: =S10/M10 -> 0.20920881 | U10: ='[1]2. Khánh Nga'!B35 -> % Chai B4 | V10: ='[1]2. Khánh Nga'!O35 -> 0.014912634 | W10: ='[1]2. Khánh Nga'!B35 -> % Chai B4 | X10: ='[1]2. Khánh Nga'!O35 -> 0.014912634 | Y10: ='[1]3. Đồng Lâm'!B340 -> % Chai B4 | Z10: ='[1]3. Đồng Lâm'!O340 -> 0.019139602 | AE10: =T10*V10 -> 0.0031198544
B11: 160000004 | C11: Chai PET B5 | D11: 20 | E11: 0.02 | F11: =D11 -> 20 | G11: 1 | H11: =F11*G11 -> 20 | I11: =$I$6/$H$21*H11 -> 180780.21 | J11: =I11/$I$6 -> 0.019029496 | K11: =J11 -> 0.019029496 | M11: =ROUND(10000+10000*$M$5+500,-2) -> 11500 | N11: =M11/$M$21 -> 1 | O11: =O10 -> 500 | P11: =I11/F11 -> 9039.0105 | Q11: =$Q$6*K11 -> 55.088187 | R11: =P11+Q11 -> 9094.0987 | S11: =M11-R11 -> 2405.9013 | T11: =S11/M11 -> 0.20920881 | U11: ='[1]2. Khánh Nga'!B36 -> % Chai B5 | V11: ='[1]2. Khánh Nga'!O36 -> 0.019802359 | W11: ='[1]2. Khánh Nga'!B36 -> % Chai B5 | X11: ='[1]2. Khánh Nga'!O36 -> 0.019802359 | Y11: ='[1]3. Đồng Lâm'!B341 -> % Chai B5 | Z11: ='[1]3. Đồng Lâm'!O341 -> 0.010656982 | AE11: =T11*V11 -> 0.0041428279
C12: Chai PET B6.1 | F12: =D12 -> 0 | H12: =F12*G12 -> 0 | I12: =$I$6/$H$21*H12 -> 0 | J12: =I12/$I$6 -> 0 | K12: =J12 -> 0 | N12: =M12/$M$21 -> 0 | O12: =O8 -> 3500 | P12: =I12/F12 -> #DIV/0! | Q12: =$Q$6*K12 -> 0 | R12: =P12+Q12 -> #DIV/0! | S12: =M12-R12 -> #DIV/0! | T12: =S12/M12 -> #DIV/0! | AE12: =T12*V12 -> #DIV/0!
B13: 160000005 | C13: Chai PET B6.2 | D13: 270 | E13: 0.27 | F13: =D13 -> 270 | G13: 1.1 | H13: =F13*G13 -> 297 | I13: =$I$6/$H$21*H13 -> 2684586.1 | J13: =I13/$I$6 -> 0.28258801 | K13: =J13 -> 0.28258801 | M13: =ROUND(10000+10000*$M$5+2500,-2) -> 13500 | N13: =M13/$M$21 -> 1.173913 | O13: =O9 -> 2000 | P13: =I13/F13 -> 9942.9115 | Q13: =$Q$6*K13 -> 818.05958 | R13: =P13+Q13 -> 10760.971 | S13: =M13-R13 -> 2739.0289 | T13: =S13/M13 -> 0.20289103 | U13: ='[1]1. Đại Lộc'!B329 -> % Chai B6.2 | V13: ='[1]1. Đại Lộc'!O329 -> 0.19170632 | W13: ='[1]2. Khánh Nga'!B34 -> % Chai B6.2 | X13: ='[1]2. Khánh Nga'!O34 -> 0.23118717 | Y13: ='[1]3. Đồng Lâm'!B339 -> % Chai B6.2 | Z13: ='[1]3. Đồng Lâm'!O339 -> 0.26757253 | AE13: =T13*V13 -> 0.038895493
B14: 160000007 | C14: Nắp HD Ép Các Màu HDE-06 | D14: 10 | E14: 0.01 | F14: =D14 -> 10 | G14: 0.6 | H14: =F14*G14 -> 6 | I14: =$I$6/$H$21*H14 -> 54234.063 | J14: =I14/$I$6 -> 0.0057088487 | K14: =J14 -> 0.0057088487 | M14: =ROUND(10000+10000*$M$5-5000,-2) -> 6000 | N14: =M14/$M$21 -> 0.52173913 | O14: -5000 | P14: =I14/F14 -> 5423.4063 | Q14: =$Q$6*K14 -> 16.526456 | R14: =P14+Q14 -> 5439.9327 | S14: =M14-R14 -> 560.06726 | T14: =S14/M14 -> 0.093344544 | U14: ='[1]2. Khánh Nga'!B37 -> % Nắp | V14: ='[1]2. Khánh Nga'!O37 -> 0.031786115 | W14: ='[1]2. Khánh Nga'!B37 -> % Nắp | X14: ='[1]2. Khánh Nga'!O37 -> 0.031786115 | Y14: ='[1]3. Đồng Lâm'!B342 -> % Nắp | Z14: ='[1]3. Đồng Lâm'!O342 -> 0.0029470813 | AE14: =T14*V14 -> 0.0029670604
C15: Chai PET B7.1 | E15: 0 | N15: =M15/$M$21 -> 0 | P15: =I15/F15 -> #DIV/0! | Q15: =$Q$6*K15 -> 0 | R15: =P15+Q15 -> #DIV/0! | S15: =M15-R15 -> #DIV/0! | T15: =S15/M15 -> #DIV/0! | AE15: =T15*V15 -> #DIV/0!
B16: 160000084 | C16: Chai PET B7.2 | E16: 0 | N16: =M16/$M$21 -> 0 | O16: -1000 | P16: =I16/F16 -> #DIV/0! | Q16: =$Q$6*K16 -> 0 | R16: =P16+Q16 -> #DIV/0! | S16: =M16-R16 -> #DIV/0! | T16: =S16/M16 -> #DIV/0! | U16: ='[1]2. Khánh Nga'!B38 -> % Chai B7.2 | V16: ='[1]2. Khánh Nga'!O38 -> 1.842727e-05 | W16: ='[1]2. Khánh Nga'!B38 -> % Chai B7.2 | X16: ='[1]2. Khánh Nga'!O38 -> 1.842727e-05 | Y16: ='[1]3. Đồng Lâm'!B343 -> % Phó sản | Z16: ='[1]3. Đồng Lâm'!O343 -> 0.0089157794
B17: 160000062 | C17: Cổ Chai PET | E17: 0 | N17: =M17/$M$21 -> 0 | O17: 2000 | P17: =I17/F17 -> #DIV/0! | Q17: =$Q$6*K17 -> 0 | R17: =P17+Q17 -> #DIV/0! | S17: =M17-R17 -> #DIV/0! | T17: =S17/M17 -> #DIV/0!
B18: 160000006 | C18: Hao Hụt - Tạp chất | D18: 10 | E18: 0.01 | P18: =I18/F18 -> #DIV/0! | Q18: =$Q$6*K18 -> 0 | R18: =P18+Q18 -> #DIV/0! | S18: =M18-R18 -> #DIV/0! | T18: =S18/M18 -> #DIV/0!
B19: 800000006 | C19: Hao hụt - nhãn chai PET | D19: 60 | E19: 0.06 | P19: =I19/F19 -> #DIV/0! | Q19: =$Q$6*K19 -> 0 | R19: =P19+Q19 -> #DIV/0! | S19: =M19-R19 -> #DIV/0! | T19: =S19/M19 -> #DIV/0!
C20: Hao hụt vô hình | D20: =D6-SUM(D7:D19) -> 40 | E20: 0.04 | P20: =I20/F20 -> #DIV/0! | Q20: =$Q$6*K20 -> 0 | R20: =P20+Q20 -> #DIV/0! | S20: =M20-R20 -> #DIV/0! | T20: =S20/M20 -> #DIV/0!
C21: TỔNG | D21: =SUM(D7:D20) -> 1000 | E21: =SUM(E7:E20) -> 1 | F21: =SUM(F7:F20) -> 890 | G21: =SUM(G7:G20) -> 6.05 | H21: =SUM(H7:H20) -> 1051 | I21: =SUM(I7:I20) -> 9500000 | M21: =AVERAGE(M7:M19) -> 11500 | P21: =I21/F21 -> 10674.157 | T21: =S21/M21 -> 0
P22: =10000/(F21/1000)-P21 -> 561.79775
B24: II. | C24: CÔNG ĐOẠN BĂM CHAI B6.2 | D24: BOM - KẾ HOẠCH | F24: Sản lượng thành phẩm thực tế | G24: Hệ số quy đổi | H24: Sản lượng thành phẩm quy đổi | I24: Giá trị nguyên liệu phân bổ cho thành phẩm quy đổi | J24: Settlement rule - BOM | K24: Settlement rule - ROUTING | L24: Ghi chú | M24: Giá bán hiện tại | N24: Hệ số quy đổi giá bán
D25: Số lượng | E25: Tỷ lệ | F25: (1) | G25: (2) | H25: (3)= (1)*(2) | I25: (4) | J25: Tỷ lệ | K25: Tỷ lệ
B26: 160000005 | C26: Chai PET B6.2 | D26: 600 | F26: =SUM(F27:F31) -> 1080 | G26: =SUM(G27:G31) -> 4.1 | I26: =I13/F13*D26 -> 5965746.9
B27: 160000027 | C27: Vảy PET B6.2_A6 | D27: =D26*E27 -> 510 | E27: 0.85 | F27: =D27 -> 510 | G27: 1.35 | H27: =F27*G27 -> 688.5 | I27: =$I$26/$H$31*H27 -> 5789170.9 | J27: =I27/$I$26 -> 0.97040169 | K27: =J27 -> 0.97040169 | L27: (4) = Tổng giá trị NVL /(Tổng số lượng TP quy đổi) * Sl Tp quy đổi. (5) = Giá trị nguyên liệu phân bổ cho thành phẩm quy đổi / Tổng giá trị nguyên liệu phân bổ cho thành phẩm quy đổi | M27: =ROUND($M$13+O27,-2) -> 16000 | N27: =M27/$M$31 -> 1.3061224 | O27: =O9+500 -> 2500
B28: 160000059 | C28: Vảy nắp hỗn hợp B6.2 | D28: =D26*E28 -> 30 | E28: 0.05 | F28: =D28 -> 30 | G28: 0.7 | H28: =F28*G28 -> 21 | I28: =$I$26/$H$31*H28 -> 176576.02 | J28: =I28/$I$26 -> 0.029598309 | K28: =J28 -> 0.029598309 | M28: =ROUND($M$14+O28,-2) -> 8500 | N28: =M28/$M$31 -> 0.69387755 | O28: =O27 -> 2500
C29: Phó sản bụi cám | D29: =D26*5% -> 30
C30: Hao hụt vô hình | D30: =D26*5% -> 30
C31: TỔNG | D31: =SUM(D27:D30) -> 600 | F31: =SUM(F27:F30) -> 540 | G31: =SUM(G27:G30) -> 2.05 | H31: =SUM(H27:H30) -> 709.5 | M31: =AVERAGE(M27:M30) -> 12250
C33: Vảy PET_A5.1 mua ngoài | AB33: 16300

Sheet BOM (Dlam)
B2: BẢNG TÍNH SETTLEMENT RULE BOM - ROUTING (co-product)
M3: Hide
B4: I. | C4: CÔNG ĐOẠN PHÂN LOẠI CHAI | D4: BOM - KẾ HOẠCH | F4: Sản lượng thành phẩm thực tế | G4: Hệ số quy đổi | H4: Sản lượng thành phẩm quy đổi | I4: Giá trị nguyên liệu phân bổ cho thành phẩm quy đổi | J4: Settlement rule - BOM | K4: Settlement rule - ROUTING | L4: Ghi chú | M4: Giá bán hiện tại | N4: Hệ số quy đổi giá bán | O4: Gap (đảm bảo chi phí và lợi nhuận) | P4: GT NVL | Q4: CFSX | R4: GT SP Trạm | S4: LG | T4: % | V4: Đlộc | X4: KN | Z4: ĐLâm | AB4: Giá thị trường
D5: Số lượng | E5: Tỷ lệ | F5: (1) | G5: (2) | H5: (3)= (1)*(2) | I5: (4) | J5: Tỷ lệ | K5: Tỷ lệ | L5: Giá mua BO | M5: =Z5 -> 0.10667325 | U5: Hao hụt | V5: ='[1]1. Đại Lộc'!$O$334 -> 0.10096034 | X5: ='[1]2. Khánh Nga'!$O$39 -> 0.097733527 | Z5: ='[1]3. Đồng Lâm'!$O$344 -> 0.10667325
B6: 150000001 | C6: Chai PET xá | D6: 1000 | E6: =SUM(E7:E20) -> 1 | I6: =D6*$L$6 -> 9500000 | J6: =SUM(J7:J19) -> 1 | K6: =SUM(K7:K19) -> 1 | L6: 9500 | Q6: =Z6 -> 2609.6553 | V6: ='[2]3.CP_TAN'!$Q$78*1000 -> 3684.4011 | X6: ='[2]3.CP_TAN'!$R$78*1000 -> 2894.8843 | Z6: ='[2]3.CP_TAN'!$S$78*1000 -> 2609.6553 | AB6: 10000
