Workbook

Sheet Timeline & PIC
B1: DUY TAN GROUP
B2: =IF(B3="EN","Schedule Annual Plan 2025","Lịch lập NGÂN SÁCH năm 2026") -> Lịch lập NGÂN SÁCH năm 2026 | D2: =IF(B3="EN","Start:","Bắt đầu:") -> Bắt đầu: | E2: 45915
B3: VN | D3: =IF(B3="EN","Finish:","Kết thúc:") -> Kết thúc: | E3: =G22 -> 45990 | G3: =E3-E2 -> 75
D4: =IF(B3="en","SENDER","Đơn vị gửi") -> Đơn vị gửi | E4: =IF(B3="EN","RECEIVER","Đơn vị nhận") -> Đơn vị nhận | G4: Deadline | H4: THÁNG 09 | AM4: THÁNG 10 | BR4: THÁNG 11
B5: No. | C5: =IF(B3="EN","PROCESS","TRÌNH TỰ THỰC HIỆN") -> TRÌNH TỰ THỰC HIỆN | F5: Thời gian | H5: 1 | I5: 2 | J5: 3 | K5: 4 | L5: 5 | M5: 6 | N5: 7 | O5: 8 | P5: 9 | Q5: 10 | R5: 11 | S5: 12 | T5: 13 | U5: 14 | V5: 15 | W5: 16 | X5: 17 | Y5: 18 | Z5: 19 | AA5: 20 | AB5: 21 | AC5: 22 | AD5: 23 | AE5: 24 | AF5: 25 | AG5: 26 | AH5: 27 | AI5: 28 | AJ5: 29 | AK5: 30 | AL5: 31 | AM5: 1 | AN5: 2 | AO5: 3 | AP5: 4 | AQ5: 5 | AR5: 6 | AS5: 7 | AT5: 8 | AU5: 9 | AV5: 10 | AW5: 11 | AX5: 12 | AY5: 13 | AZ5: 14 | BA5: 15 | BB5: 16 | BC5: 17 | BD5: 18 | BE5: 19 | BF5: 20 | BG5: 21 | BH5: 22 | BI5: 23 | BJ5: 24 | BK5: 25 | BL5: 26 | BM5: 27 | BN5: 28 | BO5: 29 | BP5: 30 | BQ5: 31 | BR5: 1 | BS5: =BR5+1 -> 2 | BT5: =BS5+1 -> 3 | BU5: =BT5+1 -> 4 | BV5: =BU5+1 -> 5 | BW5: =BV5+1 -> 6 | BX5: =BW5+1 -> 7 | BY5: =BX5+1 -> 8 | BZ5: =BY5+1 -> 9 | ... CT5: =CS5+1 -> 29 | CU5: 30
F6: (Ngày) | H6: M | I6: T | J6: W | K6: TH | L6: F | M6: Sa | N6: Su | O6: M | P6: T | Q6: W | R6: TH | S6: F | T6: Sa | U6: Su | V6: M | W6: T | X6: W | Y6: TH | Z6: F | AA6: Sa | AB6: Su | AC6: M | AD6: T | AE6: W | AF6: TH | AG6: F | AH6: Sa | AI6: Su | AJ6: M | AK6: T | AL6: W | AM6: TH | AN6: F | AO6: Sa | AP6: Su | AQ6: M | AR6: T | AS6: W | AT6: TH | AU6: F | AV6: Sa | AW6: Su | AX6: M | AY6: T | AZ6: W | BA6: TH | BB6: F | BC6: Sa | BD6: Su | BE6: M | BF6: T | BG6: W | BH6: TH | BI6: F | BJ6: Sa | BK6: Su | BL6: M | BM6: T | BN6: W | BO6: TH | BP6: F | BQ6: Sa | BR6: Su | BS6: M | BT6: T | BU6: W | BV6: TH | BW6: F | BX6: Sa | BY6: Su | BZ6: M | CA6: T | CB6: W | CC6: TH | CD6: F | CE6: Sa | CF6: Su | CG6: M | CH6: T | CI6: W | CJ6: TH | CK6: F | CL6: Sa | CM6: Su | CN6: M | CO6: T | CP6: W | CQ6: TH | CR6: F | CS6: Sa | CT6: Su | CU6: M
B7: 1 | C7: Khởi động | D7: GĐTC holding | E7: =IF(B3="EN","All","Tất cả") -> Tất cả | G7: =E2 -> 45915
B8: 2 | C8: Kế hoạch Doanh thu / Sản lượng | D8: =IF(B3="EN","Sales team","Phòng kinh doanh") -> Phòng kinh doanh | E8: =IF(B3="EN","Acct.","Kế toán") -> Kế toán | F8: 15 | G8: =F8+$G$7 -> 45930
B9: 3 | C9: Kế hoạch giá cả nguyên vật liệu | D9: =IF(B2="EN","Supply chain","Chuỗi cung ứng") -> Chuỗi cung ứng | E9: =E8 -> Kế toán | F9: 15 | G9: =F9+$G$7 -> 45930
B10: =B9+1 -> 4 | C10: Kế hoạch chi phí vận chuyển, cước xuất khẩu,... | D10: =IF(B3="EN","Supply chain","Chuổi cung ứng") -> Chuổi cung ứng | E10: =E9 -> Kế toán | F10: 15 | G10: =F10+$G$7 -> 45930
B11: =B10+1 -> 5 | C11: Kế hoạch sản xuất | D11: =IF(B3="EN","Production","Bộ phận sản xuất") -> Bộ phận sản xuất | E11: =E10 -> Kế toán | F11: 20 | G11: =F11+$G$7 -> 45935
B12: =B11+1 -> 6 | C12: Kế hoạch biến phí sản xuất | D12: =E12 -> Kế toán | E12: =E11 -> Kế toán | F12: 20 | G12: =F12+$G$7 -> 45935
B13: =B12+1 -> 7 | C13: Kế hoạch nhân sự (số lượng nhân sự, quỹ lương, chi phí đào tạo,...) | D13: =IF(B3="EN","HR","Phòng nhân sự") -> Phòng nhân sự | E13: =E12 -> Kế toán | F13: 30 | G13: =F13+$G$7 -> 45945
B14: =B13+1 -> 8 | C14: Ngân sách đầu tư | D14: =E7 -> Tất cả | E14: =E13 -> Kế toán | F14: 30 | G14: =F14+$G$7 -> 45945
B15: =B14+1 -> 9 | C15: Ngân sách chi phí sản xuất (không bao gồm lương) | D15: =D11 -> Bộ phận sản xuất | E15: =E14 -> Kế toán | F15: 30 | G15: =F15+$G$7 -> 45945
B16: =B15+1 -> 10 | C16: Ngân sách chi phí bán hàng & chí phí quản lý (không bao gồm lương) | D16: =D14 -> Tất cả | E16: =E15 -> Kế toán | F16: 30 | G16: =F16+$G$7 -> 45945
B17: =B16+1 -> 11 | C17: Tổng hợp kết quả ngân sách mỗi công ty | D17: Kế toán quản trị | E17: KTT/GĐTC | F17: 45 | G17: =F17+$G$7 -> 45960
B18: 12 | C18: Trình bày kết quả ngân sách của mỗi công ty đến TGĐ (Bottom up) | D18: KTT/GĐTC | E18: TGĐ | F18: 50 | G18: =F18+$G$7 -> 45965
B19: 13 | C19: Trình bày kết quả ngân sách của mỗi công ty đến TGĐ (Top down) | D19: KTT/GĐTC | E19: TGĐ | F19: 55 | G19: =F19+$G$7 -> 45970
B20: 14 | C20: Trình bày kết quả ngân sách của mỗi công ty đến TGĐ (Chính thức) | D20: KTT/GĐTC | E20: TGĐ | F20: 62 | G20: =F20+$G$7 -> 45977
B21: 15 | C21: Hợp nhất ngân sách cho toàn bộ DT Group | D21: KTQT holding | E21: GĐTC holding | F21: 70 | G21: =F21+$G$7 -> 45985
B22: 16 | C22: Trình bày kết quả ngân sách hợp nhất cho toàn bộ DT Group | D22: GĐTC holding | E22: TGĐ | F22: 75 | G22: =F22+$G$7 -> 45990

Sheet Thongtin
B2: STT | C2: Nội dung | D2: Nguồn cung cấp dữ liệu | E2: Nguồn thông tin liên quan | F2: Thời gian cần dữ liệu | H2: STT | I2: Màu sheet | J2: Thông tin
B3: 1 | C3: Ban hành Nhóm-Loại NVL Trạm thu mua | D3: GĐĐH Trạm - DTR | E3: 1. BGĐ DTR 2. Phòng cung ứng DTR | F3: 45940 | H3: 1 | J3: Kết quả kinh doanh tổng hợp
B4: 2 | C4: Ban hành Sản lượng Trạm thu mua | D4: GĐĐH Trạm - DTR | E4: 1. BGĐ DTR 2. Phòng cung ứng DTR | F4: 45940 | H4: 2 | J4: Kết quả kinh doanh PET và HD
B5: 3 | C5: Ban hành đơn giá MUA từng loại NVL | D5: GĐĐH Trạm - DTR | E5: 1. Phòng cung ứng DTR đề xuất KH năm 2026 (Dữ liệu theo từng tháng) 2. KTT các trạm cung cấp đơn giá bình quân thực tế mua theo từng tháng ( Dữ liệu năm 2023-2024-2025) 3. Đơn giá BGĐ-DTR duyệt mua trong năm 2025 (Dữ liệu theo từng tháng) | F5: 45940 | H5: 3 | J5: Kết quả kinh doanh PET và HD
B6: 4 | C6: Ban hành đơn giá BÁN từng loại thành phẩm | D6: GĐĐH Trạm - DTR | E6: 1. BGĐ DTR 2. Phòng cung ứng DTR | F6: 45940 | H6: 4 | J6: Ban hành Định mức về Công suất MMTB - Định mức về CP phục vụ sản xuất - Định biên Nhân sự
B7: 5 | C7: Kế hoạch đầu tư CAPEX tại Trạm => Ảnh hưởng đến Sản phẩm và TCKT Trạm cung cấp đến DTR | D7: GĐĐH Trạm - DTR | E7: 1. BGĐ DTR 2. Phòng kỹ thuật DTR 3. Phòng mua hàng DTR | F7: 45940 | H7: 5 | J7: Ban hành sản lượng - đơn giá - Cơ cấu về: NVL - Thành phẩm - Hao hụt - Bán hàng
H8: 6 | J8: Nhóm Chi phí:CP Sản xuất - CP Bán hàng - CP Quản lý (Công thức từ: Định mức - Lương - PB_TSCD - PB_CPTT - nhóm NVL - Phát sinh trực tiếp)
H9: 7 | J9: Cập nhật TSCĐ - CPTT năm trước chuyển sang và Capex 2026
H10: 8 | I10: … | J10: Thông tin khác

Sheet KH hanh dong
A3: KẾ HOẠCH KINH DOANH 2026
A4: Nguồn yêu cầu: GĐTC-DTR
A5: STT | B5: Nhóm công việc | C5: Kế hoạch hành động | D5: Người thực hiện | E5: Thời gian hoàn thành tính toán và xác lập mục tiêu 2026 | F5: Hiện trạng / vướng mắt / giải pháp (tại thời điểm tháng 10/2025) | G5: Mục tiêu 2026 (rolling hàng tháng) | U5: KHNS 2026 | V5: Thực hiện 2025 | W5: Tăng/giảm vs KHNS 2026
G6: Đánh giá KQ đạt được (cập nhật đến thời điểm báo cáo) | H6: Mục tiêu T1 | I6: Mục tiêu T2 | J6: Mục tiêu T3 | K6: Mục tiêu T4 | L6: Mục tiêu T5 | M6: Mục tiêu T6 | N6: Mục tiêu T7 | O6: Mục tiêu T8 | P6: Mục tiêu T9 | Q6: Mục tiêu T10 | R6: Mục tiêu T11 | S6: Mục tiêu T12 | T6: Dự báo KQ 2026 | W6: Theo số tiền phát sinh | X6: Theo mức độ hoạt động | Y6: %
A7: A | B7: HOẠT ĐỘNG MUA HÀNG
A8: 1 | B8: Đáp ứng sản lượng mua cho Trạm | C8: Lập mục tiêu sản lượng mua để Trạm đạt hòa vốn và có lãi.
C9: Xây dựng các trạm vệ tinh để tăng lượng chai về Trạm.
C10: Phát triển thêm các NCC liên kết ở tỉnh.
C11: Đàm phán tăng sản lượng mua từ các NCC đang giao dịch.
A12: 2 | B12: Cải thiện dịch vụ khách hàng | C12: Cải thiện thời gian nhận hàng
C13: Thanh toán trong ngày và cuối tuần
A14: B | B14: HOẠT ĐỘNG BÁN HÀNG
A15: 1 | B15: Giá bán về DTR | C15: Áp dụng cơ cấu giá mới từ Tháng 9/2025
A16: 2 | B16: Kiểm soát tồn kho thành phẩm | C16: Lập KH giao hàng về DTR hàng ngày, ngày cuối tháng không để tồn kho và xuất hóa đơn 100%
A17: 3 | B17: Chi phí thuê xe vận chuyển | C17: - Đàm phán giảm giá, đề nghị NCC sử dụng phương tiện vận chuyển hiệu quả. - Tìm NCC mới cạnh tranh.
A18: C | B18: HOẠT ĐỘNG CẢI TIẾN CHI PHÍ
A19: I | B19: Chi phí nguyên vật liệu
A20: 1 | B20: Kiểm soát lượng mua, giá mua | C20: - Lập mục tiêu tồn kho tối thiểu 10 ngày sản xuất và phối hợp P.Cung ứng lập KH mua hàng theo tuần. - Kiểm soát giá mua tương ứng với từng mức chất lượng chai.
A21: 2 | B21: Kiểm soát chất lượng NVL, hao hụt | C21: Kiểm soát chất lượng chai (tỷ lệ chai nguyên liệu - Chai xá/xô tuyển, thành phần chai sau phân loại, tỷ lệ tạp chất).
A22: 3 | B22: Kiểm soát định mức vật tư sản xuất (hóa chất, dây đai, vật tư kỹ thuật …) | C22: - Thống kê và thực hiện cải tiến tiêu hao. - Mua tập trung tại P.Mua hàng DTR.
A23: 4 | B23: Xử lý phế liệu, phó sản thu hồi | C23: Phân loại phế liệu thành 2 nhóm: - Nhóm hàng hóa (nhãn, bao jumbo, kim loại,…): tìm đơn vị thu mua giá cao - Nhóm rác thải công nghiệp (bùn, hỗn hợp tạp chất): thuê thu gom
A24: II | B24: Chi phí nhân công
A25: 1 | B25: Định mức NCTT | C25: - Kiểm soát định mức NCTT theo chuyền/công đoạn. - Thực hiện tiêu chuẩn hóa/tự động hóa MMTB để giảm nhân công, tăng năng suất. - Tăng số lượng lao động thời vụ. - Tính toán phương án trả lương/ thưởng theo sản lượng.
A26: 2 | B26: Năng suất lao động | C26: - Lập mục tiêu tăng thời gian sản xuất từ 8 giờ/ngày -> 12 giờ -> 16 giờ -> 24 giờ.
A27: III | B27: Chi phí sản xuất chung
A28: 1 | B28: Chi phí điện | C28: - Phối hợp kỹ thuật bảo trì MMTB đảm bảo hoạt động liên tục -> tăng hiệu quả sử dụng điện và tăng năng suất lao động.
A29: 2 | B29: Chi phí xe nâng | C29: - Chuyển dần xe nâng dầu từ DTR về các Trạm (các xe của trạm sửa chữa nhiều sẽ thanh lý)
A30: 3 | B30: Chi phí khấu hao TSCĐ, CCDC, chi phí phân bổ khác | C30: - Thống kê, đánh giá lại hiệu quả sử dụng tất cả TS. - Tách chi phí khấu hao/phân bổ không phục vụ trực tiếp hoạt động để đánh giá hiệu quả KD thực của trạm.
A31: 4 | B31: Chi phí thuê xưởng | C31: - Tìm vị trí và đề xuất phương án di dời nhà máy để giảm tiền thu, tăng hiệu quả thu mua.
A32: IV | B32: Chi phí quản lý
A33: 1 | B33: Chi phí lương (gồm gián tiếp SX) | C33: Soát xét định biên và kế hoạch tuyển dụng, lập mục tiêu giảm định biên đến cuối 2026
A34: 2 | B34: Chi phí theo mục phí (ngoài chi phí lương) | C34: - Lập danh mục chi phí dịch vụ thuê/mua trả tiền định kỳ (nhóm dịch vụ/phòng ban quản lý, tên NCC, hợp đồng mới nhất, tiền trả định kỳ tháng/quý/năm, thời hạn công nợ) -> đàm phán từng NC giảm giá và tìm NCC mới cạnh tranh - XD định mức chi phí cho các khoản mục có thể xác lập định mức - Phân tích chi phí, nguyên nhân tăng/giảm và giải pháp cải tiến.
A35: V | B35: Mục tiêu lợi nhuận
A36: 1 | B36: Lợi nhuận kế hoạch đến cuối năm 2026 | C36: Sau khi đánh giá, xác lập các mục tiêu bên trên, tính toán lợi nhuận kế hoạch đến cuối năm 2026

Sheet KDKD DAY DAI
B3: MỤC TIÊU KẾT QUẢ KINH DOANH NĂM 2026 | S3: ĐVT: Triệu đồng
B4: STT | C4: Mục phí | D4: Thực tế năm 2023 | E4: Thực tế năm 2024 | F4: KQKD 2025 | G4: T1 | H4: T2 | I4: T3 | J4: T4 | K4: T5 | L4: T6 | M4: T7 | N4: T8 | O4: T9 | P4: T10 | Q4: T11 | R4: T12 | S4: KH 2026 | U4: Kiểm tra lại các sheet chi phí
B5: 1 | C5: SẢN LƯỢNG BÁN (TẤN) | D5: =D6+D7+D8 -> 0 | E5: =E6+E7+E8 -> 0 | F5: =F6+F7+F8 -> 0 | G5: =G6+G7+G8 -> 0 | H5: =H6+H7+H8 -> 0 | I5: =I6+I7+I8 -> 0 | J5: =J6+J7+J8 -> 0 | K5: =K6+K7+K8 -> 0 | ... R5: =R6+R7+R8 -> 0 | S5: =SUM(G5:R5) -> 0
B6: 1.1 | C6: Dây Đai PET | G6: ='KH DAY DAI'!E23 -> 0 | H6: ='KH DAY DAI'!F23 -> 0 | I6: ='KH DAY DAI'!G23 -> 0 | J6: ='KH DAY DAI'!H23 -> 0 | K6: ='KH DAY DAI'!I23 -> 0 | L6: ='KH DAY DAI'!J23 -> 0 | M6: ='KH DAY DAI'!K23 -> 0 | N6: ='KH DAY DAI'!L23 -> 0 | ... R6: ='KH DAY DAI'!P23 -> 0 | S6: =SUM(G6:R6) -> 0
B7: 1.2 | S7: =SUM(G7:R7) -> 0
B8: 1.3 | S8: =SUM(G8:R8) -> 0
B9: 2 | C9: DOANH THU | D9: =D10+D11+D12+D13 -> 0 | E9: =E10+E11+E12+E13 -> 0 | F9: =F10+F11+F12+F13 -> 0 | G9: =G10+G11+G12+G13 -> 0 | H9: =H10+H11+H12+H13 -> 0 | I9: =I10+I11+I12+I13 -> 0 | J9: =J10+J11+J12+J13 -> 0 | K9: =K10+K11+K12+K13 -> 0 | ... R9: =R10+R11+R12+R13 -> 0 | S9: =SUM(G9:R9) -> 0
B10: 2.1 | C10: Dây Đai PET | G10: ='KH DAY DAI'!E24 -> 0 | H10: ='KH DAY DAI'!F24 -> 0 | I10: ='KH DAY DAI'!G24 -> 0 | J10: ='KH DAY DAI'!H24 -> 0 | K10: ='KH DAY DAI'!I24 -> 0 | L10: ='KH DAY DAI'!J24 -> 0 | M10: ='KH DAY DAI'!K24 -> 0 | N10: ='KH DAY DAI'!L24 -> 0 | ... R10: ='KH DAY DAI'!P24 -> 0 | S10: =SUM(G10:R10) -> 0
B11: 2.2
B12: 2.3
B13: 2.4 | C13: Khác | S13: =SUM(G13:R13) -> 0
B14: 3 | C14: BIẾN PHÍ | D14: =D15+D23 -> 0 | E14: =E15+E23 -> 0 | G14: =G15+G23 -> 0 | H14: =H15+H23 -> 0 | I14: =I15+I23 -> 0 | J14: =J15+J23 -> 0 | K14: =K15+K23 -> 0 | L14: =L15+L23 -> 0 | M14: =M15+M23 -> 0 | N14: =N15+N23 -> 0 | ... R14: =R15+R23 -> 0 | S14: =SUM(G14:R14) -> 0
B15: 3.1 | C15: BIẾN PHÍ SẢN XUẤT | D15: =D16+D20+D21+D22 -> 0 | E15: =E16+E20+E21+E22 -> 0 | G15: =G16+G20+G21+G22 -> 0 | H15: =H16+H20+H21+H22 -> 0 | I15: =I16+I20+I21+I22 -> 0 | J15: =J16+J20+J21+J22 -> 0 | K15: =K16+K20+K21+K22 -> 0 | L15: =L16+L20+L21+L22 -> 0 | M15: =M16+M20+M21+M22 -> 0 | N15: =N16+N20+N21+N22 -> 0 | ... R15: =R16+R20+R21+R22 -> 0 | S15: =SUM(G15:R15) -> 0
B16: 3.1.1 | C16: Nguyên vật liệu chính (nhựa, gồm hao hụt) | G16: =SUM('KH DAY DAI'!E25:E26,'KH DAY DAI'!E33) -> 0 | H16: =SUM('KH DAY DAI'!F25:F26,'KH DAY DAI'!F33) -> 0 | I16: =SUM('KH DAY DAI'!G25:G26,'KH DAY DAI'!G33) -> 0 | J16: =SUM('KH DAY DAI'!H25:H26,'KH DAY DAI'!H33) -> 0 | K16: =SUM('KH DAY DAI'!I25:I26,'KH DAY DAI'!I33) -> 0 | L16: =SUM('KH DAY DAI'!J25:J26,'KH DAY DAI'!J33) -> 0 | M16: =SUM('KH DAY DAI'!K25:K26,'KH DAY DAI'!K33) -> 0 | N16: =SUM('KH DAY DAI'!L25:L26,'KH DAY DAI'!L33) -> 0 | ... R16: =SUM('KH DAY DAI'!P25:P26,'KH DAY DAI'!P33) -> 0 | S16: =SUM(G16:R16) -> 0
B17: 3.1.2 | C17: Trong đó: i/ Hao hụt CĐ phân loại chai | G17: =SUM('KH DAY DAI'!E26,'KH DAY DAI'!E33) -> 0 | H17: =SUM('KH DAY DAI'!F26,'KH DAY DAI'!F33) -> 0 | I17: =SUM('KH DAY DAI'!G26,'KH DAY DAI'!G33) -> 0 | J17: =SUM('KH DAY DAI'!H26,'KH DAY DAI'!H33) -> 0 | K17: =SUM('KH DAY DAI'!I26,'KH DAY DAI'!I33) -> 0 | L17: =SUM('KH DAY DAI'!J26,'KH DAY DAI'!J33) -> 0 | M17: =SUM('KH DAY DAI'!K26,'KH DAY DAI'!K33) -> 0 | N17: =SUM('KH DAY DAI'!L26,'KH DAY DAI'!L33) -> 0 | ... R17: =SUM('KH DAY DAI'!P26,'KH DAY DAI'!P33) -> 0 | S17: =SUM(G17:R17) -> 0
C18: ii/ Hao hụt CĐ băm vảy | S18: =SUM(G18:R18) -> 0
B19: 3.1.3 | C19: % chi phí nguyên liệu/doanh thu | D19: =IFERROR(D16/$F$9,0) -> 0 | E19: =IFERROR(E16/$F$9,0) -> 0 | F19: =IFERROR(F16/$F$9,0) -> 0 | G19: =G16/G9 -> #DIV/0! | H19: =H16/H9 -> #DIV/0! | I19: =I16/I9 -> #DIV/0! | J19: =J16/J9 -> #DIV/0! | K19: =K16/K9 -> #DIV/0! | L19: =L16/L9 -> #DIV/0! | M19: =M16/M9 -> #DIV/0! | N19: =N16/N9 -> #DIV/0! | ... S19: =S16/S9 -> #DIV/0!
B20: 3.1.4 | C20: Nguyên vật liệu phụ | G20: ='KH DAY DAI'!E27 -> 0 | H20: ='KH DAY DAI'!F27 -> 0 | I20: ='KH DAY DAI'!G27 -> 0 | J20: ='KH DAY DAI'!H27 -> 0 | K20: ='KH DAY DAI'!I27 -> 0 | L20: ='KH DAY DAI'!J27 -> 0 | M20: ='KH DAY DAI'!K27 -> 0 | N20: ='KH DAY DAI'!L27 -> 0 | ... R20: ='KH DAY DAI'!P27 -> 0 | S20: =SUM(G20:R20) -> 0
B21: 3.1.5 | C21: Điện sản xuất | G21: ='KH DAY DAI'!E28 -> 0 | H21: ='KH DAY DAI'!F28 -> 0 | I21: ='KH DAY DAI'!G28 -> 0 | J21: ='KH DAY DAI'!H28 -> 0 | K21: ='KH DAY DAI'!I28 -> 0 | L21: ='KH DAY DAI'!J28 -> 0 | M21: ='KH DAY DAI'!K28 -> 0 | N21: ='KH DAY DAI'!L28 -> 0 | ... R21: ='KH DAY DAI'!P28 -> 0 | S21: =SUM(G21:R21) -> 0
B22: 3.1.6 | C22: Nhân công trực tiếp | G22: ='KH DAY DAI'!E29 -> 0 | H22: ='KH DAY DAI'!F29 -> 0 | I22: ='KH DAY DAI'!G29 -> 0 | J22: ='KH DAY DAI'!H29 -> 0 | K22: ='KH DAY DAI'!I29 -> 0 | L22: ='KH DAY DAI'!J29 -> 0 | M22: ='KH DAY DAI'!K29 -> 0 | N22: ='KH DAY DAI'!L29 -> 0 | ... R22: ='KH DAY DAI'!P29 -> 0 | S22: =SUM(G22:R22) -> 0
B23: 3.2 | C23: BIẾN PHÍ BÁN HÀNG | D23: =D24 -> 0 | E23: =E24 -> 0 | F23: =F24 -> 0 | G23: =G24 -> 0 | H23: =H24 -> 0 | I23: =I24 -> 0 | J23: =J24 -> 0 | K23: =K24 -> 0 | ... R23: =R24 -> 0 | S23: =SUM(G23:R23) -> 0
C24: Chi phí vận chuyển | G24: ='KH DAY DAI'!E36 -> 0 | H24: ='KH DAY DAI'!F36 -> 0 | I24: ='KH DAY DAI'!G36 -> 0 | J24: ='KH DAY DAI'!H36 -> 0 | K24: ='KH DAY DAI'!I36 -> 0 | L24: ='KH DAY DAI'!J36 -> 0 | M24: ='KH DAY DAI'!K36 -> 0 | N24: ='KH DAY DAI'!L36 -> 0 | ... R24: ='KH DAY DAI'!P36 -> 0 | S24: =SUM(G24:R24) -> 0
B25: 4 | C25: LÃI SAU BIẾN PHÍ | D25: =D9-D14 -> 0 | E25: =E9-E14 -> 0 | F25: =F9-F14 -> 0 | G25: =G9-G14 -> 0 | H25: =H9-H14 -> 0 | I25: =I9-I14 -> 0 | J25: =J9-J14 -> 0 | K25: =K9-K14 -> 0 | ... R25: =R9-R14 -> 0 | S25: =SUM(G25:R25) -> 0
B26: 4.1 | C26: % lãi biến phí/doanh thu | D26: =IFERROR(D23/$F$9,0) -> 0 | E26: =IFERROR(E23/$F$9,0) -> 0 | F26: =IFERROR(F23/$F$9,0) -> 0 | G26: =G25/G9 -> #DIV/0! | H26: =H25/H9 -> #DIV/0! | I26: =I25/I9 -> #DIV/0! | J26: =J25/J9 -> #DIV/0! | K26: =K25/K9 -> #DIV/0! | L26: =L25/L9 -> #DIV/0! | M26: =M25/M9 -> #DIV/0! | N26: =N25/N9 -> #DIV/0! | ... S26: =S25/S9 -> #DIV/0!
B27: 5 | C27: CHI PHÍ SẢN XUẤT CHUNG | D27: =D28+D29+D30 -> 0 | E27: =E28+E29+E30 -> 0 | F27: =F28+F29+F30 -> 0 | G27: =G28+G29+G30 -> 0 | H27: =H28+H29+H30 -> 0 | I27: =I28+I29+I30 -> 0 | J27: =J28+J29+J30 -> 0 | K27: =K28+K29+K30 -> 0 | ... R27: =R28+R29+R30 -> 0 | S27: =SUM(G27:R27) -> 0
B28: 5.1 | C28: Lương gián tiếp Sản xuất | G28: ='KH DAY DAI'!E31 -> 0 | H28: ='KH DAY DAI'!F31 -> 0 | I28: ='KH DAY DAI'!G31 -> 0 | J28: ='KH DAY DAI'!H31 -> 0 | K28: ='KH DAY DAI'!I31 -> 0 | L28: ='KH DAY DAI'!J31 -> 0 | M28: ='KH DAY DAI'!K31 -> 0 | N28: ='KH DAY DAI'!L31 -> 0 | ... R28: ='KH DAY DAI'!P31 -> 0 | S28: =SUM(G28:R28) -> 0
B29: 5.2 | C29: Chi phí thuê xưởng | S29: =SUM(G29:R29) -> 0
B30: 5.3 | C30: Chi phí sản xuất (Ngoài lương, BOM, thuê xưởng, khấu hao) | G30: =SUM('KH DAY DAI'!E30) -> 0 | H30: =SUM('KH DAY DAI'!F30) -> 0 | I30: =SUM('KH DAY DAI'!G30) -> 0 | J30: =SUM('KH DAY DAI'!H30) -> 0 | K30: =SUM('KH DAY DAI'!I30) -> 0 | L30: =SUM('KH DAY DAI'!J30) -> 0 | M30: =SUM('KH DAY DAI'!K30) -> 0 | N30: =SUM('KH DAY DAI'!L30) -> 0 | ... R30: =SUM('KH DAY DAI'!P30) -> 0 | S30: =SUM(G30:R30) -> 0
B31: 6 | C31: CHI PHÍ KHẤU HAO, CCDC | G31: ='KH DAY DAI'!E32 -> 0 | H31: ='KH DAY DAI'!F32 -> 0 | I31: ='KH DAY DAI'!G32 -> 0 | J31: ='KH DAY DAI'!H32 -> 0 | K31: ='KH DAY DAI'!I32 -> 0 | L31: ='KH DAY DAI'!J32 -> 0 | M31: ='KH DAY DAI'!K32 -> 0 | N31: ='KH DAY DAI'!L32 -> 0 | ... R31: ='KH DAY DAI'!P32 -> 0 | S31: =SUM(G31:R31) -> 0
B32: 7 | C32: LỢI NHUẬN GỘP | D32: =D25-D27-D31 -> 0 | E32: =E25-E27-E31 -> 0 | F32: =F25-F27-F31 -> 0 | G32: =G25-G27-G31 -> 0 | H32: =H25-H27-H31 -> 0 | I32: =I25-I27-I31 -> 0 | J32: =J25-J27-J31 -> 0 | K32: =K25-K27-K31 -> 0 | ... R32: =R25-R27-R31 -> 0 | S32: =SUM(G32:R32) -> 0
B33: 7.1 | C33: % lãi gộp/doanh thu | D33: =IFERROR(D30/$F$9,0) -> 0 | E33: =IFERROR(E30/$F$9,0) -> 0 | F33: =IFERROR(F30/$F$9,0) -> 0 | G33: =G32/G9 -> #DIV/0! | H33: =H32/H9 -> #DIV/0! | I33: =I32/I9 -> #DIV/0! | J33: =J32/J9 -> #DIV/0! | K33: =K32/K9 -> #DIV/0! | L33: =L32/L9 -> #DIV/0! | M33: =M32/M9 -> #DIV/0! | N33: =N32/N9 -> #DIV/0! | ... S33: =S32/S9 -> #DIV/0!
B34: 8 | C34: CHI PHÍ BÁN HÀNG & MKT & R&D | D34: =D35+D36+D37 -> 0 | E34: =E35+E36+E37 -> 0 | F34: =F35+F36+F37 -> 0 | G34: =G35+G36+G37 -> 0 | H34: =H35+H36+H37 -> 0 | I34: =I35+I36+I37 -> 0 | J34: =J35+J36+J37 -> 0 | K34: =K35+K36+K37 -> 0 | ... R34: =R35+R36+R37 -> 0 | S34: =SUM(G34:R34) -> 0
B35: 8.1 | C35: Lương | S35: =SUM(G35:R35) -> 0
B36: 8.2 | C36: Chi phí bán hàng (ngoài lương, khấu hao) | G36: =SUM('KH DAY DAI'!E34:E35) -> 0 | H36: =SUM('KH DAY DAI'!F34:F35) -> 0 | I36: =SUM('KH DAY DAI'!G34:G35) -> 0 | J36: =SUM('KH DAY DAI'!H34:H35) -> 0 | K36: =SUM('KH DAY DAI'!I34:I35) -> 0 | L36: =SUM('KH DAY DAI'!J34:J35) -> 0 | M36: =SUM('KH DAY DAI'!K34:K35) -> 0 | N36: =SUM('KH DAY DAI'!L34:L35) -> 0 | ... R36: =SUM('KH DAY DAI'!P34:P35) -> 0 | S36: =SUM(G36:R36) -> 0
B37: 8.3 | C37: Khấu hao tài sản | S37: =SUM(G37:R37) -> 0
B38: 9 | C38: CHI PHÍ QUẢN LÝ | D38: =D39+D40+D41 -> 0 | E38: =E39+E40+E41 -> 0 | F38: =F39+F40+F41 -> 0 | G38: =G39+G40+G41 -> 0 | H38: =H39+H40+H41 -> 0 | I38: =I39+I40+I41 -> 0 | J38: =J39+J40+J41 -> 0 | K38: =K39+K40+K41 -> 0 | ... R38: =R39+R40+R41 -> 0 | S38: =SUM(G38:R38) -> 0
B39: 9.1 | C39: Lương | S39: =SUM(G39:R39) -> 0
B40: 9.2 | C40: Chi phí quản lý (ngoài lương, khấu hao) | S40: =SUM(G40:R40) -> 0
B41: 9.3 | C41: Khấu hao tài sản | S41: =SUM(G41:R41) -> 0
B42: 10 | C42: DOANH THU/CHI PHÍ KHÁC | S42: =SUM(G42:R42) -> 0 | U42: <= Nhập số liệu
...

Sheet KH DAY DAI
B2: 1. Dây đai
B4: STT | C4: Nội dung | D4: Tỷ lệ | E4: 1 | F4: =+E4+1 -> 2 | G4: =+F4+1 -> 3 | H4: =+G4+1 -> 4 | I4: =+H4+1 -> 5 | J4: =+I4+1 -> 6 | K4: =+J4+1 -> 7 | L4: =+K4+1 -> 8 | M4: =+L4+1 -> 9 | ... P4: =+O4+1 -> 12
B5: 1 | C5: Sản lượng sản xuất (tấn) | E5: =300*16*30/10^3 -> 144 | F5: =300*16*30/10^3 -> 144 | G5: =300*16*30/10^3 -> 144 | H5: =300*16*30/10^3 -> 144 | I5: =300*16*30/10^3 -> 144 | J5: =300*16*30/10^3 -> 144 | K5: =300*16*30/10^3 -> 144 | L5: =300*16*30/10^3 -> 144 | ... P5: =300*16*30/10^3 -> 144 | Q5: =400 -> 400
B6: 2 | C6: Giá bán | E6: 19000 | F6: 19000 | G6: 19000 | H6: 19000 | I6: 19000 | J6: 19000 | K6: 19000 | L6: 19000 | M6: 19000 | N6: 19000 | O6: 19000 | P6: 19000
B7: 3 | C7: Giá vốn (bao gồm CP hoa hồng) | E7: =SUM(E8,E12:E21) -> 17207.846 | F7: =SUM(F8,F12:F21) -> 17207.846 | G7: =SUM(G8,G12:G21) -> 17207.846 | H7: =SUM(H8,H12:H21) -> 17207.846 | I7: =SUM(I8,I12:I21) -> 17207.846 | J7: =SUM(J8,J12:J21) -> 17207.846 | K7: =SUM(K8,K12:K21) -> 17207.846 | L7: =SUM(L8,L12:L21) -> 17207.846 | ... P7: =SUM(P8,P12:P21) -> 17207.846
B8: 3.1 | C8: Chi phí nguyên vật liệu | E8: =+SUM(E9:E11) -> 8840 | F8: =+SUM(F9:F11) -> 8840 | G8: =+SUM(G9:G11) -> 8840 | H8: =+SUM(H9:H11) -> 8840 | I8: =+SUM(I9:I11) -> 8840 | J8: =+SUM(J9:J11) -> 8840 | K8: =+SUM(K9:K11) -> 8840 | L8: =+SUM(L9:L11) -> 8840 | ... P8: =+SUM(P9:P11) -> 8840
C9: Phó Sản PET GC Dây Đai | D9: 0.5 | E9: =8000*$D9 -> 4000 | F9: =8000*$D9 -> 4000 | G9: =8000*$D9 -> 4000 | H9: =8000*$D9 -> 4000 | I9: =8000*$D9 -> 4000 | J9: =8000*$D9 -> 4000 | K9: =8000*$D9 -> 4000 | L9: =8000*$D9 -> 4000 | ... P9: =8000*$D9 -> 4000
C10: Phó Sản PET Đầu Keo | D10: 0.35 | E10: 2800 | F10: 2800 | G10: 2800 | H10: 2800 | I10: 2800 | J10: 2800 | K10: 2800 | L10: 2800 | M10: 2800 | N10: 2800 | O10: 2800 | P10: 2800
C11: Vảy PET B4_A3 | D11: 0.15 | E11: 2040 | F11: 2040 | G11: 2040 | H11: 2040 | I11: 2040 | J11: 2040 | K11: 2040 | L11: 2040 | M11: 2040 | N11: 2040 | O11: 2040 | P11: 2040
B12: 3.2 | C12: Phó sản, hao hụt | E12: 365.39084 | F12: 365.39084 | G12: 365.39084 | H12: 365.39084 | I12: 365.39084 | J12: 365.39084 | K12: 365.39084 | L12: 365.39084 | M12: 365.39084 | N12: 365.39084 | O12: 365.39084 | P12: 365.39084
B13: 3.3 | C13: Hóa chất rửa vảy | E13: 36.24378 | F13: 36.24378 | G13: 36.24378 | H13: 36.24378 | I13: 36.24378 | J13: 36.24378 | K13: 36.24378 | L13: 36.24378 | M13: 36.24378 | N13: 36.24378 | O13: 36.24378 | P13: 36.24378
B14: 3.4 | C14: Điện, nước | E14: 212.12234 | F14: 212.12234 | G14: 212.12234 | H14: 212.12234 | I14: 212.12234 | J14: 212.12234 | K14: 212.12234 | L14: 212.12234 | M14: 212.12234 | N14: 212.12234 | O14: 212.12234 | P14: 212.12234
B15: 3.5 | C15: Nhân công trực tiếp | E15: 240.68287 | F15: 240.68287 | G15: 240.68287 | H15: 240.68287 | I15: 240.68287 | J15: 240.68287 | K15: 240.68287 | L15: 240.68287 | M15: 240.68287 | N15: 240.68287 | O15: 240.68287 | P15: 240.68287 | Q15: =48000*2 -> 96000 | R15: =Q15/Q5 -> 240
B16: 3.6 | C16: Vật tư phân xưởng | E16: 58.638979 | F16: 58.638979 | G16: 58.638979 | H16: 58.638979 | I16: 58.638979 | J16: 58.638979 | K16: 58.638979 | L16: 58.638979 | M16: 58.638979 | N16: 58.638979 | O16: 58.638979 | P16: 58.638979
B17: 3.7 | C17: Lương gián tiếp sx | E17: 217.51578 | F17: 217.51578 | G17: 217.51578 | H17: 217.51578 | I17: 217.51578 | J17: 217.51578 | K17: 217.51578 | L17: 217.51578 | M17: 217.51578 | N17: 217.51578 | O17: 217.51578 | P17: 217.51578
B18: 3.8 | C18: Khấu hao | E18: 421.56543 | F18: 421.56543 | G18: 421.56543 | H18: 421.56543 | I18: 421.56543 | J18: 421.56543 | K18: 421.56543 | L18: 421.56543 | M18: 421.56543 | N18: 421.56543 | O18: 421.56543 | P18: 421.56543 | Q18: =6200000000/12/12 -> 43055556 | R18: =Q18/E5 -> 298996.91
C19: Tỷ lệ hao hụt nguyên liệu gia công | D19: 0.04 | E19: =+SUM(E9:E18)*$D19 -> 415.6864 | F19: =+SUM(F9:F18)*$D19 -> 415.6864 | G19: =+SUM(G9:G18)*$D19 -> 415.6864 | H19: =+SUM(H9:H18)*$D19 -> 415.6864 | I19: =+SUM(I9:I18)*$D19 -> 415.6864 | J19: =+SUM(J9:J18)*$D19 -> 415.6864 | K19: =+SUM(K9:K18)*$D19 -> 415.6864 | L19: =+SUM(L9:L18)*$D19 -> 415.6864 | ... P19: =+SUM(P9:P18)*$D19 -> 415.6864
C20: Chi phí gia công | E20: 5000 | F20: 5000 | G20: 5000 | H20: 5000 | I20: 5000 | J20: 5000 | K20: 5000 | L20: 5000 | M20: 5000 | N20: 5000 | O20: 5000 | P20: 5000
C21: Chi phí hoa hồng | D21: =E21/E$6 -> 0.073684211 | E21: =(E6-5000)*10% -> 1400 | F21: =(F6-5000)*10% -> 1400 | G21: =(G6-5000)*10% -> 1400 | H21: =(H6-5000)*10% -> 1400 | I21: =(I6-5000)*10% -> 1400 | J21: =(J6-5000)*10% -> 1400 | K21: =(K6-5000)*10% -> 1400 | L21: =(L6-5000)*10% -> 1400 | ... P21: =(P6-5000)*10% -> 1400
C23: Thành Phẩm Bán
C24: Doanh thu
C25: CP NVL
C26: Hao hụt
C27: Hóa chất
C28: Điện, nước
C29: Nhân công trực tiếp
C30: Vật tư phân xưởng
C31: Lương gián tiếp sx
C32: Khấu hao
C33: Tỷ lệ hao hụt nguyên liệu gia công
C34: Chi phí gia công
... C42: Vảy B4_A3
C43: Phó Sản PET Đầu Keo | D43: 0.15
C44: HH 4%

Sheet Cong suat
B3: CÔNG SUẤT
B4: I - CÔNG SUẤT CHUYỀN LỰA CHAI - CHAI XÁ TRÒN | E4: SX Chai B1.1 | F4: Loại B2.2, B4, B5, B6.2 | H4: Loại kim loại, chai còn nhãn
B5: STT | C5: Công đoạn sản xuất | D5: Cấp liệu | E5: Lồng tách tạp chất | F5: Lựa phân loại chai | G5: Tách nhãn | H5: Lựa phân loại chai sau tách nhãn | I5: Ép kiện | J5: Xử lý phó sản, nắp, cổ chai | K5: Công suất thành phẩm cả chuyền
B6: 1 | C6: Năng suất THIẾT KẾ (Kg NVL đầu vào / giờ) | D6: 1500 | E6: 1500 | F6: 1500 | G6: 1.100-1.500 | H6: 1100 | I6: 1400 | K6: =D6*(100%-$D$14) -> 1335
B7: 2 | C7: Năng suất ĐỊNH MỨC (Kg NVL đầu vào / giờ) | D7: 1400 | E7: 1200 | F7: 1200 | G7: =D7*95% -> 1330 | H7: =D7*90% -> 1260 | I7: 1300 | K7: =E15 -> 1246
B8: 3 | C8: Định mức nhân công (Số NV / Ca8) | D8: 2 | E8: 2 | F8: =4+1 -> 5 | G8: 1 | H8: =5 -> 5 | I8: =1 -> 1 | J8: 2 | K8: =SUM(D8:J8) -> 18
C9: Diễn giải
B11: STT | C11: Chỉ tiêu định mức | D11: ĐVT | E11: ĐM 1 giờ | F11: ĐM 1 Ca8 | G11: ĐM 1 Ca12 | H11: ĐM 2 Ca8 | I11: ĐM 2 Ca12
B12: 1 | C12: Tổng nhân sự: | D12: Người | E12: =K8 -> 18 | F12: =$E12 -> 18 | G12: =$F12*1.5 -> 27 | H12: =$F12*2 -> 36 | I12: =$G12*2 -> 54
B13: 2 | C13: Định mức NVL đầu vào: | D13: kg/giờ | E13: =D7 -> 1400 | F13: =$E13*8 -> 11200 | G13: =$F13*1.5 -> 16800 | H13: =$F13*2 -> 22400 | I13: =$G13*2 -> 33600
B14: 3 | C14: Hao hụt: | D14: ='2.Hao hut & % chai '!$N$8 -> 0.11 | E14: =E13*$D$14 -> 154 | F14: =$E14*8 -> 1232 | G14: =$E14*12 -> 1848 | H14: =$F14*2 -> 2464 | I14: =$G14*2 -> 3696
B15: 4 | C15: Định mức thành phẩm: | D15: kg/giờ | E15: =E13-E14 -> 1246 | F15: =$E15*8 -> 9968 | G15: =$F15*1.5 -> 14952 | H15: =$F15*2 -> 19936 | I15: =$G15*2 -> 29904
B16: 5 | C16: Định mức thành phẩm/người: | D16: kg/giờ/người | E16: =E15/K8 -> 69.222222 | F16: =$E16*8 -> 553.77778 | G16: =$F16*1.5 -> 830.66667 | H16: =$F16*2 -> 1107.5556 | I16: =$G16*2 -> 1661.3333
B18: II - CÔNG SUẤT CHUYỀN LỰA CHAI - CHAI ÉP KIỆN
B19: STT | C19: Công đoạn sản xuất | D19: Cấp liệu | E19: Phá kiện (thủ công bằng tay) | F19: Lựa phân loại chai | G19: Tách nhãn | H19: Lựa phân loại chai sau tách nhãn | I19: Ép kiện | J19: Xử lý phó sản, nắp, cổ chai | K19: Công suất thành phẩm cả chuyền
B20: 1 | C20: Năng suất THIẾT KẾ (Kg NVL đầu vào / giờ) | D20: 1500 | F20: 1500 | G20: 1.100-1.500 | H20: 1100 | I20: 1400 | K20: =D20*(100%-$D$14) -> 1335
B21: 2 | C21: Năng suất ĐỊNH MỨC (Kg NVL đầu vào / giờ) | D21: 1400 | E21: =D21 -> 1400 | F21: =E21 -> 1400 | G21: =F21 -> 1400 | H21: =G21 -> 1400 | I21: 1300 | K21: =E29 -> 1218
B22: 3 | C22: Định mức nhân công (Số NV / Ca8) | D22: 2 | E22: 2 | F22: =3+1+1 -> 5 | G22: 1 | H22: 6 | I22: =1+1 -> 2 | J22: 2 | K22: =SUM(D22:J22) -> 20
C23: Diễn giải
B25: STT | C25: Chỉ tiêu định mức | D25: ĐVT | E25: ĐM 1 giờ | F25: ĐM 1 Ca8 | G25: ĐM 1 Ca12 | H25: ĐM 2 Ca8 | I25: ĐM 2 Ca12
B26: 1 | C26: Tổng nhân sự: | D26: Người | E26: =K22 -> 20 | F26: =$E26 -> 20 | G26: =$F26*1.5 -> 30 | H26: =$F26*2 -> 40 | I26: =$G26*2 -> 60
B27: 2 | C27: Định mức NVL đầu vào: | D27: kg/giờ | E27: =G21 -> 1400 | F27: =$E27*8 -> 11200 | G27: =$F27*1.5 -> 16800 | H27: =$F27*2 -> 22400 | I27: =$G27*2 -> 33600
B28: 3 | C28: Hao hụt: | D28: ='2.Hao hut & % chai '!$N$14 -> 0.13 | E28: =E27*$D$28 -> 182 | F28: =$E28*8 -> 1456 | G28: =$F28*1.5 -> 2184 | H28: =$F28*2 -> 2912 | I28: =$G28*2 -> 4368
B29: 4 | C29: Định mức thành phẩm: | D29: kg/giờ | E29: =E27-E28 -> 1218 | F29: =$E29*8 -> 9744 | G29: =$F29*1.5 -> 14616 | H29: =$F29*2 -> 19488 | I29: =$G29*2 -> 29232
B30: 5 | C30: Định mức thành phẩm/người: | D30: kg/giờ/người | E30: =E29/K22 -> 60.9 | F30: =$E30*8 -> 487.2 | G30: =$F30*1.5 -> 730.8 | H30: =$F30*2 -> 974.4 | I30: =$G30*2 -> 1461.6
B32: III - CÔNG SUẤT CHUYỀN LỰA CHAI - CHAI TUYỂN XÔ
B33: STT | C33: Công đoạn sản xuất | D33: Cấp liệu | E33: Lồng tách tạp chất | F33: Lựa phân loại chai | G33: Tách nhãn | H33: Lựa phân loại chai sau tách nhãn | I33: Ép kiện | J33: Xử lý phó sản, nắp, cổ chai | K33: Công suất thành phẩm cả chuyền
B34: 1 | C34: Năng suất THIẾT KẾ (Kg NVL đầu vào / giờ) | D34: 2000 | E34: 2000 | F34: 1500 | G34: 1.000-1.500 | H34: 1000 | I34: 1400 | K34: 1300
B35: 2 | C35: Năng suất ĐỊNH MỨC (Kg NVL đầu vào / giờ) | D35: 2000 | E35: 2000 | F35: 1500 | G35: 1000 | H35: 900 | I35: 1300 | K35: =E43 -> 1926
B36: 3 | C36: Định mức nhân công (Số NV / Ca8) | D36: 2 | F36: 2 | G36: 1 | H36: 2 | I36: 2 | J36: 2 | K36: =SUM(D36:J36) -> 11
C37: Diễn giải
B39: STT | C39: Chỉ tiêu định mức | D39: ĐVT | E39: ĐM 1 giờ | F39: ĐM 1 Ca8 | G39: ĐM 1 Ca12 | H39: ĐM 2 Ca8 | I39: ĐM 2 Ca12
B40: 1 | C40: Tổng nhân sự: | D40: Người | E40: =K36 -> 11 | F40: =$E40 -> 11 | G40: =$F40*1.5 -> 16.5 | H40: =$F40*2 -> 22 | I40: =$G40*2 -> 33
B41: 2 | C41: Định mức NVL đầu vào: | D41: kg/giờ | E41: =$E$35 -> 2000 | F41: =$E41*8 -> 16000 | G41: =$F41*1.5 -> 24000 | H41: =$F41*2 -> 32000 | I41: =$G41*2 -> 48000
B42: 3 | C42: Hao hụt: | D42: ='2.Hao hut & % chai '!$G$20 -> 0.037 | E42: =E41*$D$42 -> 74 | F42: =$E42*8 -> 592 | G42: =$E42*12 -> 888 | H42: =$F42*2 -> 1184 | I42: =$G42*2 -> 1776
B43: 4 | C43: Định mức thành phẩm: | D43: kg/giờ | E43: =E41-E42 -> 1926 | F43: =$E43*8 -> 15408 | G43: =$F43*1.5 -> 23112 | H43: =$F43*2 -> 30816 | I43: =$G43*2 -> 46224
B44: 5 | C44: Định mức thành phẩm/người: | D44: kg/giờ/người | E44: =E43/K36 -> 175.09091 | F44: =$E44*8 -> 1400.7273 | G44: =$F44*1.5 -> 2101.0909 | H44: =$F44*2 -> 2801.4545 | I44: =$G44*2 -> 4202.1818
B46: VI - CÔNG SUẤT MÁY VÀ NĂNG SUẤT LAO ĐỘNG MỤC TIÊU
B47: 1 | C47: CHUYỀN LỰA CHAI - CHAI XÁ TRÒN | E47: Định mức | F47: T1 | G47: T2 | H47: T3 | I47: T4 | J47: T5 | K47: T6 | L47: T7 | M47: T8 | N47: T9 | O47: T10 | P47: T11 | Q47: T12 | R47: Mục tiêu 2026
B48: a | C48: Số nhân sự/ chuyền/ ca | D48: Người | E48: =E12 -> 18 | F48: =E48 -> 18 | G48: =F48 -> 18 | H48: =G48 -> 18 | I48: =H48 -> 18 | J48: =E48 -> 18 | K48: =J48 -> 18 | L48: =K48 -> 18 | M48: =L48 -> 18 | N48: =M48 -> 18 | O48: =N48 -> 18 | P48: =O48 -> 18 | Q48: =P48 -> 18
...

Sheet Dinh muc
B3: ĐỊNH MỨC CHI PHÍ
B4: I - ĐỊNH MỨC TIÊU HAO VẬT TƯ - PHÂN LOẠI CHAI PET
B5: STT | C5: Mục phí | D5: ĐVT | E5: Định mức | F5: Đơn giá | G5: Chi phí/1kg thành phẩm | H5: Diễn giải
C6: Công suất lựa chai | E6: =('Cong suat'!E29+'Cong suat'!E15)/2 -> 1232
B7: 1 | C7: Chi phí nhân công trực tiếp (giờ công lao động) | E7: =E8+E9 -> 128
B8: a | C8: LĐ định biên | D8: Giờ công/ca 8 | E8: =7*8 -> 56 | G8: =E8*F8/E6 -> 0
B9: b | C9: LĐ thời vụ | D9: Giờ công/ca 8 | E9: =9*8 -> 72 | F9: =260000/8 -> 32500 | G9: =E9*F9/E6 -> 1899.3506
B10: c | C10: Tiền ăn giữa Ca | D10: Đồng/người/ngày công | E10: =E7/8 -> 16 | F10: =25000 -> 25000 | G10: =(E10*F10)/($E$6*8) -> 40.584416
B11: 2 | C11: Điện sản xuất | D11: Kw/1chuyền/1giờ hoạt động | E11: 40 | F11: =ROUND(2100*1.05,-1) -> 2210 | G11: =E11*F11/E6 -> 71.753247
B12: 3 | C12: Dao tách nhãn chai PET | D12: Tấn/Bộ | E12: =1700000 -> 1700000 | F12: 165000000 | G12: =F12/(E12*87%) -> 111.56187 | H12: Anh Quân chốt định mức băm: 1500 tấn chai PET-B0
B13: 4 | C13: Dây đai | D13: Kg/tấn | E13: =1.1*50% -> 0.55 | F13: 51000 | G13: =E13*F13/(1000*87%)+1 -> 33.241379 | H13: Chuyển Băm 80%, CP dây đai tái sử dụng lại được 2 lần
B14: 5 | C14: Bao jumbo
B15: 6 | C15: Hóa chất
B16: 7 | C16: Chi phí xử lý nhãn chai PET | D16: Kg | E16: 1 | F16: 300 | G16: =(6.5%*1000)*F16/870 -> 22.413793
B17: 8 | C17: Dầu xe nâng | D17: Lít/giờ hoạt động | E17: =2.5*85% -> 2.125 | F17: 18000 | G17: =E17*F17/1100 -> 34.772727 | H17: Bình quân 1 h: 2.5 lít, hiệu suất sử dụng: 85%
B18: 9 | C18: Chi phí vận chuyển | D18: Chuyến/9 tấn | E18: 1 | F18: 3200000 | G18: =F18/9000 -> 355.55556
B20: II - ĐỊNH MỨC TIÊU HAO VẬT TƯ - BĂM VẢY PET - CHUYỀN FS (B6.2)
B21: STT | C21: Mục phí | D21: ĐVT | E21: ĐM 1 giờ | F21: Đơn giá | G21: Chi phí/1kg thành phẩm | H21: Diễn giải
C22: Công suất băm PET | E22: ='Cong suat'!E82 -> 630
B23: 1 | C23: Chi phí nhân công trực tiếp | E23: =SUM(E24:E25) -> 24
B24: a | C24: LĐ định biên | D24: Giờ công/ca 8 | E24: =3*8 -> 24
B25: b | C25: LĐ thời vụ | D25: Giờ công/ca 8
B26: c | C26: Tiền ăn giữa Ca | D26: Đồng/người/ngày công | E26: =E23/8 -> 3 | F26: =25000 -> 25000 | G26: =(E26*F26)/($E$22*8) -> 14.880952
B27: 2 | C27: Điện sản xuất | D27: Kw/h | E27: 70 | F27: =ROUND(2100*1.05,-1) -> 2210 | G27: =E27*F27/$E$22 -> 245.55556
B28: 3 | C28: Dao băm vảy PET | D28: Tấn/Bộ | E28: 200000 | F28: 44000000 | G28: =F28/(E28*90%) -> 244.44444 | H28: Công suất thiết kế: 200 tấn
B29: 4 | C29: Dây đai
B30: 5 | C30: Bao jumbo | D30: Cái/Kg | E30: 350 | F30: 75000 | G30: =F30/(E30*2*0.9) -> 119.04762 | H30: 1 cái sử dụng được 2 lần
B31: 6 | C31: Hóa chất
B32: 7 | C32: Chi phí xử lý bùn, nước thải | G32: =SUM(G33:G35) -> 269.52381 | H32: Xử lý: nhãn, bùn, nước thải, hóa chất xử lý hồ XLNT
B33: 7.1 | C33: Chi phí nước sản xuất | D33: m3/h | E33: 3 | F33: 11500 | G33: =E33*F33/$E$22 -> 54.761905
C34: Chi phí xử lý nước thải | D34: m3/h | E34: =E33*80% -> 2.4 | F34: 9500 | G34: =E34*F34/$E$22 -> 36.190476
C35: Chi phí xử lý bùn | E35: ='Cong suat'!D90*5% -> 75 | F35: 1500 | G35: =E35*F35/$E$22 -> 178.57143
B36: 8 | C36: Dầu xe nâng | E36: =2.5*60% -> 1.5 | F36: 18000 | G36: =E36*F36/1100 -> 24.545455 | H36: Bình quân 1 h: 2.5 lít, hiệu suất sử dụng: 60%
B37: 9 | C37: Chi phí vận chuyển | D37: Chuyến | E37: 10000 | F37: 3200000 | G37: =F37/E37 -> 320
B39: III - ĐỊNH MỨC TIÊU HAO VẬT TƯ - BĂM VẢY PET Tu chuyen HD
B40: STT | C40: Mục phí | D40: ĐVT | E40: Định mức | F40: Đơn giá | G40: Chi phí/1kg thành phẩm | H40: Diễn giải
C41: Công suất băm HD | E41: ='Cong suat'!K90 -> 1410
B42: 1 | C42: Chi phí nhân công trực tiếp | E42: 3 | F42: 50320
B43: a | C43: LĐ định biên | D43: h | E43: =3*8 -> 24 | F43: 50320 | G43: =(E43*F43)/($E$41*8) -> 107.06383
B44: b | C44: LĐ thời vụ | D44: h
...

Sheet Dinh muc (2)
B3: ĐỊNH MỨC CHI PHÍ
B4: I - ĐỊNH MỨC TIÊU HAO VẬT TƯ - PHÂN LOẠI CHAI PET
B5: STT | C5: Mục phí | D5: ĐVT | E5: Định mức | F5: Đơn giá | G5: Chi phí/1kg thành phẩm | H5: Diễn giải
C6: Công suất lựa chai | E6: =('Cong suat'!E29+'Cong suat'!E15)/2 -> 1232
B7: 1 | C7: Chi phí nhân công trực tiếp (giờ công lao động) | E7: =E8+E9 -> 16 | F7: =(E8*F8+E9*F9)/E7 -> 18281.25 | G7: =G8+G9 -> 237.41883
B8: a | C8: LĐ định biên | D8: Giờ công/ca 8 | E8: 7 | G8: =E8*F8/E6 -> 0
B9: b | C9: LĐ thời vụ | D9: Giờ công/ca 8 | E9: 9 | F9: =260000/8 -> 32500 | G9: =E9*F9/E6 -> 237.41883
B10: c | C10: Tiền ăn giữa Ca | D10: Đồng/người/ngày công | E10: =E7 -> 16 | F10: =25000/8 -> 3125 | G10: =E10*F10/$E$6 -> 40.584416
B11: 2 | C11: Điện sản xuất | D11: Kw/1chuyền/1giờ hoạt động | E11: 40 | F11: =ROUND(2100*1.05,-1) -> 2210 | G11: =E11*F11/E6 -> 71.753247
B12: 3 | C12: Dao tách nhãn chai PET | D12: Tấn/Bộ | E12: =1/1700000*(('Cong suat'!$E$13+'Cong suat'!$E$21)/2) -> 0.00082352941 | F12: 165000000 | G12: =E12*F12/$E$6 -> 110.29412 | H12: Anh Quân chốt định mức băm: 1500 tấn chai PET-B0 | I12: Tăng Dm dao tách nhãn 1500 -> 1700
B13: 4 | C13: Dây đai | E13: =0.3*50% -> 0.15 | F13: 51000 | G13: =E13*F13/230 -> 33.26087 | H13: Chuyển Băm 80%, CP dây đai tái sử dụng lại được 2 lần
B14: 5 | C14: Bao jumbo
B15: 6 | C15: Hóa chất
B16: 7 | C16: Chi phí xử lý nhãn chai PET | D16: Kg | E16: =SUM('Cong suat'!E13,'Cong suat'!E27)/2*6.5% -> 91 | F16: 300 | G16: =E16*F16/$E$6 -> 22.159091
B17: 8 | C17: Dầu xe nâng | D17: Lít/giờ hoạt động | E17: =2.5*85% -> 2.125 | F17: 18000 | G17: =E17*F17/1100 -> 34.772727 | H17: Bình quân 1 h: 2.5 lít, hiệu suất sử dụng: 85%
B18: 9 | C18: Chi phí vận chuyển | D18: Chuyến/9 tấn | E18: 1 | F18: 3200000 | G18: =F18/9000 -> 355.55556
B20: II - ĐỊNH MỨC TIÊU HAO VẬT TƯ - BĂM VẢY PET
B21: STT | C21: Mục phí | D21: ĐVT | E21: ĐM 1 giờ | F21: Đơn giá | G21: Chi phí/1kg thành phẩm | H21: Diễn giải
C22: Công suất băm PET | E22: ='Cong suat'!$E$98 -> 1410
B23: 1 | C23: Chi phí nhân công trực tiếp
B24: a | C24: LĐ định biên | D24: Giờ công/ca 8 | E24: 3
B25: b | C25: LĐ thời vụ | D25: Giờ công/ca 8
B26: c | C26: Tiền ăn giữa Ca | D26: Đồng/người | E26: =E23 -> 0 | F26: =25000/8 -> 3125 | G26: =E26*F26/$E$22 -> 0
B27: 2 | C27: Điện sản xuất | D27: Kw/1chuyền/1giờ hoạt động | E27: 70 | F27: =ROUND(2100*1.05,-1) -> 2210 | G27: =E27*F27/$E$22 -> 109.71631
B28: 3 | C28: Dao băm vảy PET | E28: =1/200000*'Cong suat'!$E$96 -> 0.0075 | F28: 44000000 | G28: =E28*F28/$E$22 -> 234.04255 | H28: Công suất thiết kế: 200 tấn
B29: 4 | C29: Dây đai
B30: 5 | C30: Bao jumbo | E30: =E22/350*50% -> 2.0142857 | F30: 71000 | G30: =E30*F30/$E$22 -> 101.42857
B31: 6 | C31: Hóa chất
B32: 7 | C32: Chi phí xử lý bùn, nước thải | G32: =SUM(G33:G35) -> 120.42553 | H32: Xử lý: nhãn, bùn, nước thải, hóa chất xử lý hồ XLNT
B33: 7.1 | C33: Chi phí nước sản xuất | E33: 3 | F33: 11500 | G33: =E33*F33/$E$22 -> 24.468085
C34: Chi phí xử lý nước thải | E34: =E33*80% -> 2.4 | F34: 9500 | G34: =E34*F34/$E$22 -> 16.170213
C35: Chi phí xử lý bùn | E35: ='Cong suat'!D90*5% -> 75 | F35: 1500 | G35: =E35*F35/$E$22 -> 79.787234
B36: 8 | C36: Dầu xe nâng | E36: =2.5*60% -> 1.5 | F36: 18000 | G36: =E36*F36/1100 -> 24.545455 | H36: Bình quân 1 h: 2.5 lít, hiệu suất sử dụng: 60%
B37: 9 | C37: Chi phí vận chuyển | D37: Chuyến | E37: 10000 | F37: 3200000 | G37: =F37/E37 -> 320
B39: III - ĐỊNH MỨC TIÊU HAO VẬT TƯ - BĂM VẢY PET Tu chuyen HD
B40: STT | C40: Mục phí | D40: ĐVT | E40: Định mức | F40: Đơn giá | G40: Chi phí/1kg thành phẩm | H40: Diễn giải
C41: Công suất băm HD | E41: ='Cong suat'!K90 -> 1410
B42: 1 | C42: Chi phí nhân công trực tiếp | E42: 3 | F42: 50320
B43: a | C43: LĐ định biên | E43: 3 | F43: 50320 | G43: =E43*F43/$E$41 -> 107.06383
B44: b | C44: LĐ thời vụ
...

Sheet Dinh bien_HCNS
B1: #VALUE!
B3: I - ĐINH BIÊN NHÂN SỰ - PET | R3: ĐVT: người
B4: STT | C4: Phòng ban | D4: Tài khoản | E4: KQKD 2025 | F4: T1 | G4: T2 | H4: T3 | I4: T4 | J4: T5 | K4: T6 | L4: T7 | M4: T8 | N4: T9 | O4: T10 | P4: T11 | Q4: T12 | R4: KH 2026
B5: 1 | C5: Ban giám đốc | D5: 642 | E5: =E6+E7 -> 2 | F5: =SUM(F6:F7) -> 2 | G5: =SUM(G6:G7) -> 2 | H5: =SUM(H6:H7) -> 2 | I5: =SUM(I6:I7) -> 2 | J5: =SUM(J6:J7) -> 2 | K5: =SUM(K6:K7) -> 2 | L5: =SUM(L6:L7) -> 2 | M5: =SUM(M6:M7) -> 2 | ... Q5: =SUM(Q6:Q7) -> 2 | R5: =R6+R7 -> 2
B6: 1.1 | C6: Giám đốc Trạm | E6: 1 | F6: 1 | G6: 1 | H6: 1 | I6: 1 | J6: 1 | K6: 1 | L6: 1 | M6: 1 | N6: 1 | O6: 1 | P6: 1 | Q6: 1 | R6: =Q6 -> 1
B7: 1.2 | C7: Trưởng trạm thu mua | E7: 1 | F7: 1 | G7: 1 | H7: 1 | I7: 1 | J7: 1 | K7: 1 | L7: 1 | M7: 1 | N7: 1 | O7: 1 | P7: 1 | Q7: 1 | R7: =Q7 -> 1
B8: 2 | C8: Phòng Hành chánh nhân sự | D8: 642 | E8: =E9+E11+E12+E13+E14+E15 -> 2 | F8: =SUM(F9:F15) -> 2 | G8: =SUM(G9:G15) -> 2 | H8: =SUM(H9:H15) -> 2 | I8: =SUM(I9:I15) -> 2 | J8: =SUM(J9:J15) -> 2 | K8: =SUM(K9:K15) -> 2 | L8: =SUM(L9:L15) -> 2 | M8: =SUM(M9:M15) -> 2 | ... R8: =SUM(R9:R15) -> 2
B9: 2.1 | C9: Trưởng phòng nhân sự | E9: 1 | F9: 1 | G9: 1 | H9: 1 | I9: 1 | J9: 1 | K9: 1 | L9: 1 | M9: 1 | N9: 1 | O9: 1 | P9: 1 | Q9: 1 | R9: =Q9 -> 1
B10: 2.1 | C10: Nhân viên hành chính | R10: =Q10 -> 0
B11: 2.2 | C11: Nhân viên nhân sự | R11: =Q11 -> 0
B12: 2.3 | C12: Tuyển dụng | R12: =Q12 -> 0
B13: 2.4 | C13: Nhân viên tạp vụ | E13: 1 | F13: 1 | G13: 1 | H13: 1 | I13: 1 | J13: 1 | K13: 1 | L13: 1 | M13: 1 | N13: 1 | O13: 1 | P13: 1 | Q13: 1 | R13: =Q13 -> 1
B14: 2.5 | C14: Bảo vệ | R14: =Q14 -> 0
B15: 2.6 | C15: Nhân viên chăm sóc cây xanh | R15: =Q15 -> 0
B16: 3 | C16: Phòng Kế toán | D16: 642 | E16: =SUM(E17:E20) -> 3 | F16: =SUM(F17:F20) -> 3 | G16: =SUM(G17:G20) -> 3 | H16: =SUM(H17:H20) -> 3 | I16: =SUM(I17:I20) -> 3 | J16: =SUM(J17:J20) -> 3 | K16: =SUM(K17:K20) -> 3 | L16: =SUM(L17:L20) -> 3 | ... R16: =SUM(R17:R20) -> 3
B17: 3.1 | C17: Kế toán trưởng | E17: 1 | F17: 1 | G17: 1 | H17: 1 | I17: 1 | J17: 1 | K17: 1 | L17: 1 | M17: 1 | N17: 1 | O17: 1 | P17: 1 | Q17: 1 | R17: =Q17 -> 1
B18: 3.2 | C18: Kế toán tổng hợp | E18: 1 | F18: 1 | G18: 1 | H18: 1 | I18: 1 | J18: 1 | K18: 1 | L18: 1 | M18: 1 | N18: 1 | O18: 1 | P18: 1 | Q18: 1 | R18: =Q18 -> 1
B19: 3.3 | C19: Kế toán kho | R19: =Q19 -> 0
B20: 3.4 | C20: Kế toán viên | E20: 1 | F20: 1 | G20: 1 | H20: 1 | I20: 1 | J20: 1 | K20: 1 | L20: 1 | M20: 1 | N20: 1 | O20: 1 | P20: 1 | Q20: 1 | R20: =Q20 -> 1
B21: 4 | C21: Phòng Mua hàng | D21: 642 | E21: =E22 -> 1 | F21: =F22 -> 1 | G21: =G22 -> 1 | H21: =H22 -> 1 | I21: =I22 -> 1 | J21: =J22 -> 1 | K21: =K22 -> 1 | L21: =L22 -> 1 | ... R21: =R22 -> 1
B22: 4.1 | C22: Nhân viên mua hàng | E22: 1 | F22: 1 | G22: 1 | H22: 1 | I22: 1 | J22: 1 | K22: 1 | L22: 1 | M22: 1 | N22: 1 | O22: 1 | P22: 1 | Q22: 1 | R22: =Q22 -> 1
B23: 5 | C23: Ban dự án XDCB | D23: 642 | E23: =E24 -> 0 | F23: =F24 -> 0 | G23: =G24 -> 0 | H23: =H24 -> 0 | I23: =I24 -> 0 | J23: =J24 -> 0 | K23: =K24 -> 0 | L23: =L24 -> 0 | ... Q23: =Q24 -> 0
B24: 5.1 | C24: Nhân viên
B25: 6 | C25: Phòng Quản Trị Hệ Thống | D25: 642 | E25: =E26 -> 0 | F25: =F26 -> 0 | G25: =G26 -> 0 | H25: =H26 -> 0 | I25: =I26 -> 0 | J25: =J26 -> 0 | K25: =K26 -> 0 | L25: =L26 -> 0 | ... Q25: =Q26 -> 0
B26: 6.1 | C26: Nhân viên quản trị hệ thống
B27: 7 | C27: Phòng 5S & an toàn | D27: 642 | E27: =SUM(E28:E30) -> 5 | F27: =SUM(F28:F30) -> 5 | G27: =SUM(G28:G30) -> 5 | H27: =SUM(H28:H30) -> 5 | I27: =SUM(I28:I30) -> 5 | J27: =SUM(J28:J30) -> 5 | K27: =SUM(K28:K30) -> 5 | L27: =SUM(L28:L30) -> 5 | ... R27: =SUM(R28:R30) -> 5
B28: 7.1 | C28: Nhân viên 5S & an toàn | E28: 1 | F28: 1 | G28: 1 | H28: 1 | I28: 1 | J28: 1 | K28: 1 | L28: 1 | M28: 1 | N28: 1 | O28: 1 | P28: 1 | Q28: 1 | R28: =Q28 -> 1
B29: 7.2 | C29: Nhân viên XLNT | E29: 3 | F29: 3 | G29: 3 | H29: 3 | I29: 3 | J29: 3 | K29: 3 | L29: 3 | M29: 3 | N29: 3 | O29: 3 | P29: 3 | Q29: 3 | R29: 3
B30: 7.3 | C30: Lao động thuê ngoài: 5S 2 xưởng | E30: 1 | F30: 1 | G30: 1 | H30: 1 | I30: 1 | J30: 1 | K30: 1 | L30: 1 | M30: 1 | N30: 1 | O30: 1 | P30: 1 | Q30: 1 | R30: 1
B31: 8 | C31: Phòng Cung ứng | D31: 642 | E31: =E32 -> 0 | F31: =F32 -> 0 | G31: =G32 -> 0 | H31: =H32 -> 0 | I31: =I32 -> 0 | J31: =J32 -> 0 | K31: =K32 -> 0 | L31: =L32 -> 0 | ... Q31: =Q32 -> 0 | R31: =Q31 -> 0
B32: 8.1 | C32: Nhân viên | R32: =Q32 -> 0
B33: 9 | C33: Phòng mua XNK | D33: 642 | E33: =E34 -> 0 | F33: =F34 -> 0 | G33: =G34 -> 0 | H33: =H34 -> 0 | I33: =I34 -> 0 | J33: =J34 -> 0 | K33: =K34 -> 0 | L33: =L34 -> 0 | ... Q33: =Q34 -> 0 | R33: =Q33 -> 0
B34: 9.1 | C34: Nhân viên mua hàng | R34: =Q34 -> 0
B35: 10 | C35: Tư Vấn Dịch Vụ | D35: 642 | E35: =E36 -> 0 | F35: =F36 -> 0 | G35: =G36 -> 0 | H35: =H36 -> 0 | I35: =I36 -> 0 | J35: =J36 -> 0 | K35: =K36 -> 0 | L35: =L36 -> 0 | ... Q35: =Q36 -> 0 | R35: =Q35 -> 0
B36: 10.1 | C36: Nhân viên | R36: =Q36 -> 0
B37: 11 | C37: Phòng Nghiên Cứu & Phát Triển | D37: 627 | E37: =E38 -> 0 | F37: =F38 -> 0 | G37: =G38 -> 0 | H37: =H38 -> 0 | I37: =I38 -> 0 | J37: =J38 -> 0 | K37: =K38 -> 0 | L37: =L38 -> 0 | ... Q37: =Q38 -> 0 | R37: =Q37 -> 0
B38: 11.1 | C38: Nhân viên | R38: =Q38 -> 0
B39: 12 | C39: Phòng Kiểm soát chất lượng | D39: 627 | E39: =E41+E42 -> 2 | F39: =SUM(F40:F42) -> 2 | G39: =SUM(G40:G42) -> 2 | H39: =SUM(H40:H42) -> 2 | I39: =SUM(I40:I42) -> 2 | J39: =SUM(J40:J42) -> 2 | K39: =SUM(K40:K42) -> 2 | L39: =SUM(L40:L42) -> 2 | M39: =SUM(M40:M42) -> 2 | ... R39: =SUM(R40:R42) -> 2
B40: 12.1 | C40: Tổ trưởng Kiểm soát chất lượng
B41: 12.2 | C41: Kiểm soát NVL | E41: 1 | F41: 1 | G41: 1 | H41: 1 | I41: 1 | J41: 1 | K41: 1 | L41: 1 | M41: 1 | N41: 1 | O41: 1 | P41: 1 | Q41: 1 | R41: 1
...

Sheet LUONG
B3: BẢNG LƯƠNG TỪ HCNS - SẢN XUẤT PET | F3: 1 | G3: 2 | H3: 3 | I3: 4 | J3: 5 | K3: 6 | L3: 7 | M3: 8 | N3: 9 | O3: 10 | P3: 11 | Q3: 12
B4: Phòng ban | C4: Mã tài khoản (Mã Chi phí_L4) | D4: Tên tài khoản (Cost elements 2) | E4: Chi Phí_L5 (Cost Group 2) | F4: T1 | G4: T2 | H4: T3 | I4: T4 | J4: T5 | K4: T6 | L4: T7 | M4: T8 | N4: T9 | O4: T10 | P4: T11 | Q4: T12 | R4: Mục tiêu 2026
B5: Ban giám đốc | D5: Số lượng nhân sự | F5: ='Dinh bien_HCNS'!F5 -> 2 | G5: ='Dinh bien_HCNS'!G5 -> 2 | H5: ='Dinh bien_HCNS'!H5 -> 2 | I5: ='Dinh bien_HCNS'!I5 -> 2 | J5: ='Dinh bien_HCNS'!J5 -> 2 | K5: ='Dinh bien_HCNS'!K5 -> 2 | L5: ='Dinh bien_HCNS'!L5 -> 2 | M5: ='Dinh bien_HCNS'!M5 -> 2 | ... Q5: ='Dinh bien_HCNS'!Q5 -> 2 | R5: 2
B6: Ban giám đốc | D6: ADM_Lương Khối Quản Lý | F6: =SUM(F8:F16) -> 122904333 | G6: =SUM(G8:G16) -> 124845948 | H6: =SUM(H8:H16) -> 117254102 | I6: =SUM(I8:I16) -> 125250948 | J6: =SUM(J8:J16) -> 120476718 | K6: =SUM(K8:K16) -> 125250948 | L6: =SUM(L8:L16) -> 122585333 | M6: =SUM(M8:M16) -> 122585333 | ... R6: =SUM(R8:R16) -> 1474398610
B7: Ban giám đốc | D7: Chi phí lương TB/1 Người | F7: =IFERROR(SUM(F8:F15)/F5,0) -> 61452166 | G7: =IFERROR(SUM(G8:G15)/G5,0) -> 62422974 | H7: =IFERROR(SUM(H8:H15)/H5,0) -> 58627051 | I7: =IFERROR(SUM(I8:I15)/I5,0) -> 62625474 | J7: =IFERROR(SUM(J8:J15)/J5,0) -> 60238359 | K7: =IFERROR(SUM(K8:K15)/K5,0) -> 62625474 | L7: =IFERROR(SUM(L8:L15)/L5,0) -> 61292666 | M7: =IFERROR(SUM(M8:M15)/M5,0) -> 61292666 | ... Q7: =IFERROR(SUM(Q8:Q15)/Q5,0) -> 61292666
B8: Ban giám đốc | C8: 6421002604 | D8: Chi phí lương chính - Gián tiếp | E8: Salary and Wages - Direct | F8: 87200000 | G8: 89784615 | H8: 82030769 | I8: 89784615 | J8: 84615385 | K8: 89784615 | L8: 87200000 | M8: 87200000 | N8: 89784615 | O8: 84615385 | P8: 89784615 | Q8: 87200000 | R8: =SUM(F8:Q8) -> 1048984614
B9: Ban giám đốc | C9: 6421002605 | D9: Chi phí lương T13, phép năm - Gián tiếp | E9: Salary and Wages - Support | F9: 6903333 | G9: 6903333 | H9: 6903333 | I9: 6903333 | J9: 6903333 | K9: 6903333 | L9: 6903333 | M9: 6903333 | N9: 6903333 | O9: 6903333 | P9: 6903333 | Q9: 6903333 | R9: =SUM(F9:Q9) -> 82839996
B10: Ban giám đốc | C10: 6421002802 | D10: Chi phí khen thưởng - Gián tiếp | E10: Employee Welfare | F10: 1500000 | G10: 1100000 | H10: 1100000 | I10: 1100000 | J10: 1900000 | K10: 1100000 | L10: 1100000 | M10: 1100000 | N10: 1500000 | O10: 1100000 | P10: 1100000 | Q10: 1100000 | R10: =SUM(F10:Q10) -> 14800000
B11: Ban giám đốc | C11: 6421002806 | D11: Thưởng danh hiệu | E11: Salary and Wages - Support | F11: 9374000 | G11: 9374000 | H11: 9374000 | I11: 9374000 | J11: 9374000 | K11: 9374000 | L11: 9374000 | M11: 9374000 | N11: 9374000 | O11: 9374000 | P11: 9374000 | Q11: 9374000 | R11: =SUM(F11:Q11) -> 112488000
B12: Ban giám đốc | C12: 6421007202 | D12: Chi phí khen thưởng, bồi dưỡng khác | E12: Employee Welfare | F12: 0 | G12: 0 | H12: 0 | I12: 0 | J12: 0 | K12: 0 | L12: 0 | M12: 0 | N12: 0 | O12: 0 | P12: 0 | Q12: 0 | R12: =SUM(F12:Q12) -> 0
B13: Ban giám đốc | C13: 6421003202 | D13: Tiền ăn giữa ca - Gián tiếp | E13: Employee Welfare | F13: 2025000 | G13: 1782000 | H13: 1944000 | I13: 2187000 | J13: 1782000 | K13: 2187000 | L13: 2106000 | M13: 2106000 | N13: 2025000 | O13: 2025000 | P13: 2187000 | Q13: 2106000 | R13: =SUM(F13:Q13) -> 24462000
B14: Ban giám đốc | C14: 6421002603 | D14: Phụ cấp ca đêm - Gián tiếp | E14: Salary and Wages - Support | F14: 0 | G14: 0 | H14: 0 | I14: 0 | J14: 0 | K14: 0 | L14: 0 | M14: 0 | N14: 0 | O14: 0 | P14: 0 | Q14: 0 | R14: =SUM(F14:Q14) -> 0
B15: Ban giám đốc | C15: 6421003401 | D15: BHXH, BHYT, KPCĐ, BHTN - Gián tiếp | E15: Employee Welfare | F15: 15902000 | G15: 15902000 | H15: 15902000 | I15: 15902000 | J15: 15902000 | K15: 15902000 | L15: 15902000 | M15: 15902000 | N15: 15902000 | O15: 15902000 | P15: 15902000 | Q15: 15902000 | R15: =SUM(F15:Q15) -> 190824000
B16: Ban giám đốc | C16: 6421002703 | D16: Chi phí lương ngoài giờ - Gián tiếp | E16: Salary and Wages - Support | F16: 0 | G16: 0 | H16: 0 | I16: 0 | J16: 0 | K16: 0 | L16: 0 | M16: 0 | N16: 0 | O16: 0 | P16: 0 | Q16: 0 | R16: =SUM(F16:Q16) -> 0
B17: Phòng Hành chánh nhân sự | D17: Số lượng nhân sự | F17: ='Dinh bien_HCNS'!F8 -> 2 | G17: ='Dinh bien_HCNS'!G8 -> 2 | H17: ='Dinh bien_HCNS'!H8 -> 2 | I17: ='Dinh bien_HCNS'!I8 -> 2 | J17: ='Dinh bien_HCNS'!J8 -> 2 | K17: ='Dinh bien_HCNS'!K8 -> 2 | L17: ='Dinh bien_HCNS'!L8 -> 2 | M17: ='Dinh bien_HCNS'!M8 -> 2 | ... Q17: ='Dinh bien_HCNS'!Q8 -> 2 | R17: =Q17 -> 2
B18: Phòng Hành chánh nhân sự | D18: ADM_Lương Khối Quản Lý | F18: =SUM(F20:F28) -> 36609307 | G18: =SUM(G20:G28) -> 36976461 | H18: =SUM(H20:H28) -> 34282999 | I18: =SUM(I20:I28) -> 37256461 | J18: =SUM(J20:J28) -> 35906153 | K18: =SUM(K20:K28) -> 37256461 | L18: =SUM(L20:L28) -> 36265307 | M18: =SUM(M20:M28) -> 36265307 | ... R18: =SUM(R20:R28) -> 437158838
B19: Phòng Hành chánh nhân sự | D19: Chi phí lương TB/1 Người | F19: =IFERROR(SUM(F20:F27)/F17,0) -> 18304654 | G19: =IFERROR(SUM(G20:G27)/G17,0) -> 18488230 | H19: =IFERROR(SUM(H20:H27)/H17,0) -> 17141500 | I19: =IFERROR(SUM(I20:I27)/I17,0) -> 18628230 | J19: =IFERROR(SUM(J20:J27)/J17,0) -> 17953076 | K19: =IFERROR(SUM(K20:K27)/K17,0) -> 18628230 | L19: =IFERROR(SUM(L20:L27)/L17,0) -> 18132654 | M19: =IFERROR(SUM(M20:M27)/M17,0) -> 18132654 | ... Q19: =IFERROR(SUM(Q20:Q27)/Q17,0) -> 18132654
B20: Phòng Hành chánh nhân sự | C20: 6421002604 | D20: Chi phí lương chính - Gián tiếp | E20: Salary and Wages - Direct | F20: 24314000 | G20: 25249154 | H20: 22443692 | I20: 25249154 | J20: 23378846 | K20: 25249154 | L20: 24314000 | M20: 24314000 | N20: 25249154 | O20: 23378846 | P20: 25249154 | Q20: 24314000 | R20: =SUM(F20:Q20) -> 292703154
B21: Phòng Hành chánh nhân sự | C21: 6421002605 | D21: Chi phí lương T13, phép năm - Gián tiếp | E21: Salary and Wages - Support | F21: 1924859 | G21: 1924859 | H21: 1924859 | I21: 1924859 | J21: 1924859 | K21: 1924859 | L21: 1924859 | M21: 1924859 | N21: 1924859 | O21: 1924859 | P21: 1924859 | Q21: 1924859 | R21: =SUM(F21:Q21) -> 23098308
B22: Phòng Hành chánh nhân sự | C22: 6421002802 | D22: Chi phí khen thưởng - Gián tiếp | E22: Employee Welfare | F22: 1150000 | G22: 750000 | H22: 750000 | I22: 750000 | J22: 1550000 | K22: 750000 | L22: 750000 | M22: 750000 | N22: 1150000 | O22: 750000 | P22: 750000 | Q22: 750000 | R22: =SUM(F22:Q22) -> 10600000
B23: Phòng Hành chánh nhân sự | C23: 6421002806 | D23: Thưởng danh hiệu | E23: Salary and Wages - Support | F23: 2007924 | G23: 2007924 | H23: 2007924 | I23: 2007924 | J23: 2007924 | K23: 2007924 | L23: 2007924 | M23: 2007924 | N23: 2007924 | O23: 2007924 | P23: 2007924 | Q23: 2007924 | R23: =SUM(F23:Q23) -> 24095088
B24: Phòng Hành chánh nhân sự | C24: 6421007202 | D24: Chi phí khen thưởng, bồi dưỡng khác | E24: Employee Welfare | F24: 98734 | G24: 98734 | H24: 98734 | I24: 98734 | J24: 98734 | K24: 98734 | L24: 98734 | M24: 98734 | N24: 98734 | O24: 98734 | P24: 98734 | Q24: 98734 | R24: =SUM(F24:Q24) -> 1184808
B25: Phòng Hành chánh nhân sự | C25: 6421003202 | D25: Tiền ăn giữa ca - Gián tiếp | E25: Employee Welfare | F25: 1400000 | G25: 1232000 | H25: 1344000 | I25: 1512000 | J25: 1232000 | K25: 1512000 | L25: 1456000 | M25: 1456000 | N25: 1400000 | O25: 1400000 | P25: 1512000 | Q25: 1456000 | R25: =SUM(F25:Q25) -> 16912000
B26: Phòng Hành chánh nhân sự | C26: 6421002603 | D26: Phụ cấp ca đêm - Gián tiếp | E26: Salary and Wages - Support | F26: 0 | G26: 0 | H26: 0 | I26: 0 | J26: 0 | K26: 0 | L26: 0 | M26: 0 | N26: 0 | O26: 0 | P26: 0 | Q26: 0 | R26: =SUM(F26:Q26) -> 0
B27: Phòng Hành chánh nhân sự | C27: 6421003401 | D27: BHXH, BHYT, KPCĐ, BHTN - Gián tiếp | E27: Employee Welfare | F27: 5713790 | G27: 5713790 | H27: 5713790 | I27: 5713790 | J27: 5713790 | K27: 5713790 | L27: 5713790 | M27: 5713790 | N27: 5713790 | O27: 5713790 | P27: 5713790 | Q27: 5713790 | R27: =SUM(F27:Q27) -> 68565480
B28: Phòng Hành chánh nhân sự | C28: 6421002703 | D28: Chi phí lương ngoài giờ - Gián tiếp | E28: Salary and Wages - Support | F28: 0 | G28: 0 | H28: 0 | I28: 0 | J28: 0 | K28: 0 | L28: 0 | M28: 0 | N28: 0 | O28: 0 | P28: 0 | Q28: 0 | R28: =SUM(F28:Q28) -> 0
B29: Phòng Kế toán | D29: Số lượng nhân sự | F29: 3 | G29: ='Dinh bien_HCNS'!F16 -> 3 | H29: ='Dinh bien_HCNS'!G16 -> 3 | I29: ='Dinh bien_HCNS'!H16 -> 3 | J29: ='Dinh bien_HCNS'!I16 -> 3 | K29: ='Dinh bien_HCNS'!J16 -> 3 | L29: ='Dinh bien_HCNS'!K16 -> 3 | M29: ='Dinh bien_HCNS'!L16 -> 3 | N29: ='Dinh bien_HCNS'!M16 -> 3 | ... Q29: ='Dinh bien_HCNS'!P16 -> 3 | R29: =Q29 -> 3
B30: Phòng Kế toán | D30: ADM_Lương Khối Quản Lý | F30: =SUM(F32:F40) -> 72145573 | G30: =SUM(G32:G40) -> 73172343 | H30: =SUM(H32:H40) -> 67704034 | I30: =SUM(I32:I40) -> 73592343 | J30: =SUM(J32:J40) -> 70614803 | K30: =SUM(K32:K40) -> 73592343 | L30: =SUM(L32:L40) -> 71629573 | M30: =SUM(M32:M40) -> 71629573 | ... R30: =SUM(R32:R40) -> 862993647
B31: Phòng Kế toán | D31: Chi phí lương TB/1 Người | F31: =IFERROR(SUM(F32:F39)/F29,0) -> 24048524 | G31: =IFERROR(SUM(G32:G39)/G29,0) -> 24390781 | H31: =IFERROR(SUM(H32:H39)/H29,0) -> 22568011 | I31: =IFERROR(SUM(I32:I39)/I29,0) -> 24530781 | J31: =IFERROR(SUM(J32:J39)/J29,0) -> 23538268 | K31: =IFERROR(SUM(K32:K39)/K29,0) -> 24530781 | L31: =IFERROR(SUM(L32:L39)/L29,0) -> 23876524 | M31: =IFERROR(SUM(M32:M39)/M29,0) -> 23876524 | ... Q31: =IFERROR(SUM(Q32:Q39)/Q29,0) -> 23876524
B32: Phòng Kế toán | C32: 6421002604 | D32: Chi phí lương chính - Gián tiếp | E32: Salary and Wages - Direct | F32: 48848000 | G32: 50726770 | H32: 45090461 | I32: 50726770 | J32: 46969230 | K32: 50726770 | L32: 48848000 | M32: 48848000 | N32: 50726770 | O32: 46969230 | P32: 50726770 | Q32: 48848000 | R32: =SUM(F32:Q32) -> 588054771
B33: Phòng Kế toán | C33: 6421002605 | D33: Chi phí lương T13, phép năm - Gián tiếp | E33: Salary and Wages - Support | F33: 3867133 | G33: 3867133 | H33: 3867133 | I33: 3867133 | J33: 3867133 | K33: 3867133 | L33: 3867133 | M33: 3867133 | N33: 3867133 | O33: 3867133 | P33: 3867133 | Q33: 3867133 | R33: =SUM(F33:Q33) -> 46405596
B34: Phòng Kế toán | C34: 6421002802 | D34: Chi phí khen thưởng - Gián tiếp | E34: Employee Welfare | F34: 600000 | G34: 0 | H34: 0 | I34: 0 | J34: 1200000 | K34: 0 | L34: 0 | M34: 0 | N34: 600000 | O34: 0 | P34: 0 | Q34: 0 | R34: =SUM(F34:Q34) -> 2400000
B35: Phòng Kế toán | C35: 6421002806 | D35: Thưởng danh hiệu | E35: Salary and Wages - Support | F35: 5251160 | G35: 5251160 | H35: 5251160 | I35: 5251160 | J35: 5251160 | K35: 5251160 | L35: 5251160 | M35: 5251160 | N35: 5251160 | O35: 5251160 | P35: 5251160 | Q35: 5251160 | R35: =SUM(F35:Q35) -> 63013920
B36: Phòng Kế toán | C36: 6421007202 | D36: Chi phí khen thưởng, bồi dưỡng khác | E36: Employee Welfare | F36: 0 | G36: 0 | H36: 0 | I36: 0 | J36: 0 | K36: 0 | L36: 0 | M36: 0 | N36: 0 | O36: 0 | P36: 0 | Q36: 0 | R36: =SUM(F36:Q36) -> 0
B37: Phòng Kế toán | C37: 6421003202 | D37: Tiền ăn giữa ca - Gián tiếp | E37: Employee Welfare | F37: 2100000 | G37: 1848000 | H37: 2016000 | I37: 2268000 | J37: 1848000 | K37: 2268000 | L37: 2184000 | M37: 2184000 | N37: 2100000 | O37: 2100000 | P37: 2268000 | Q37: 2184000 | R37: =SUM(F37:Q37) -> 25368000
B38: Phòng Kế toán | C38: 6421002603 | D38: Phụ cấp ca đêm - Gián tiếp | E38: Salary and Wages - Support | F38: 0 | G38: 0 | H38: 0 | I38: 0 | J38: 0 | K38: 0 | L38: 0 | M38: 0 | N38: 0 | O38: 0 | P38: 0 | Q38: 0 | R38: =SUM(F38:Q38) -> 0
B39: Phòng Kế toán | C39: 6421003401 | D39: BHXH, BHYT, KPCĐ, BHTN - Gián tiếp | E39: Employee Welfare | F39: 11479280 | G39: 11479280 | H39: 11479280 | I39: 11479280 | J39: 11479280 | K39: 11479280 | L39: 11479280 | M39: 11479280 | N39: 11479280 | O39: 11479280 | P39: 11479280 | Q39: 11479280 | R39: =SUM(F39:Q39) -> 137751360
B40: Phòng Kế toán | C40: 6421002703 | D40: Chi phí lương ngoài giờ - Gián tiếp | E40: Salary and Wages - Support | F40: 0 | G40: 0 | H40: 0 | I40: 0 | J40: 0 | K40: 0 | L40: 0 | M40: 0 | N40: 0 | O40: 0 | P40: 0 | Q40: 0 | R40: =SUM(F40:Q40) -> 0
B41: Phòng Mua hàng | D41: Số lượng nhân sự | F41: 1 | G41: ='Dinh bien_HCNS'!F21 -> 1 | H41: ='Dinh bien_HCNS'!G21 -> 1 | I41: ='Dinh bien_HCNS'!H21 -> 1 | J41: ='Dinh bien_HCNS'!I21 -> 1 | K41: ='Dinh bien_HCNS'!J21 -> 1 | L41: ='Dinh bien_HCNS'!K21 -> 1 | M41: ='Dinh bien_HCNS'!L21 -> 1 | N41: ='Dinh bien_HCNS'!M21 -> 1 | ... Q41: ='Dinh bien_HCNS'!P21 -> 1 | R41: 1
B42: Phòng Mua hàng | D42: ADM_Lương Khối Quản Lý | F42: =SUM(F44:F52) -> 15462700 | G42: =SUM(G44:G52) -> 15545623 | H42: =SUM(H44:H52) -> 14500854 | I42: =SUM(I44:I52) -> 15685623 | J42: =SUM(J44:J52) -> 15211777 | K42: =SUM(K44:K52) -> 15685623 | L42: =SUM(L44:L52) -> 15290700 | M42: =SUM(M44:M52) -> 15290700 | ... R42: =SUM(R44:R52) -> 184375323
...

Sheet GB
A6: STT | B6: Thành phẩm (chai sau phân loại) | C6: ĐVT | D6: T1 | E6: T2 | F6: T3 | G6: T4 | H6: T5 | I6: T6 | J6: T7 | K6: T8 | L6: T9 | M6: T10 | N6: T11 | O6: T12 | P6: Giả định giá bán KHNS ngày 07/01/2026 | Q6: Giả định giá bán chốt ngày 19/01/26 | R6: Chênh lệch | S6: Ghi chú | T6: T1 | U6: T2 | V6: T3 | W6: T4 | X6: T5 | Y6: T6 | Z6: T7 | AA6: T8 | AB6: T9 | AC6: T10 | AD6: T11 | AE6: T12 | AF6: KQKD 2025 | AG6: Chốt
A7: 1 | B7: Chai PET B1 | C7: Đồng/kg | D7: ='4.Doanh thu'!F26 -> 15000 | E7: ='4.Doanh thu'!G26 -> 15000 | F7: ='4.Doanh thu'!H26 -> 15000 | G7: ='4.Doanh thu'!I26 -> 15000 | H7: ='4.Doanh thu'!J26 -> 15000 | I7: ='4.Doanh thu'!K26 -> 15000 | J7: ='4.Doanh thu'!L26 -> 15000 | K7: ='4.Doanh thu'!M26 -> 15000 | ... O7: ='4.Doanh thu'!Q26 -> 15000 | P7: =AVERAGE(D7:O7) -> 15000 | Q7: 16500 | R7: =Q7-P7 -> 1500 | T7: ='4.Doanh thu'!T26 -> 17866.084 | U7: ='4.Doanh thu'!U26 -> 18501.01 | V7: ='4.Doanh thu'!V26 -> 18423.973 | W7: ='4.Doanh thu'!W26 -> 19181.215 | X7: ='4.Doanh thu'!X26 -> 19067.207 | Y7: ='4.Doanh thu'!Y26 -> 19078.717 | Z7: ='4.Doanh thu'!Z26 -> 0 | AA7: ='4.Doanh thu'!AA26 -> 0 | ... AF7: ='4.Doanh thu'!AF26 -> 18817.739
A8: 2 | B8: Chai PET B1 Không Phân Loại | C8: Đồng/kg | D8: ='4.Doanh thu'!F27 -> 15000 | E8: ='4.Doanh thu'!G27 -> 15000 | F8: ='4.Doanh thu'!H27 -> 15000 | G8: ='4.Doanh thu'!I27 -> 15000 | H8: ='4.Doanh thu'!J27 -> 15000 | I8: ='4.Doanh thu'!K27 -> 15000 | J8: ='4.Doanh thu'!L27 -> 15000 | K8: ='4.Doanh thu'!M27 -> 15000 | ... O8: ='4.Doanh thu'!Q27 -> 15000 | P8: =AVERAGE(D8:O8) -> 15000 | Q8: 16500 | R8: =Q8-P8 -> 1500 | T8: ='4.Doanh thu'!T27 -> 0 | U8: ='4.Doanh thu'!U27 -> 0 | V8: ='4.Doanh thu'!V27 -> 0 | W8: ='4.Doanh thu'!W27 -> 0 | X8: ='4.Doanh thu'!X27 -> 0 | Y8: ='4.Doanh thu'!Y27 -> 19180.665 | Z8: ='4.Doanh thu'!Z27 -> 19335.797 | AA8: ='4.Doanh thu'!AA27 -> 19225.39 | ... AF8: ='4.Doanh thu'!AF27 -> 17305.86
A9: 3 | B9: Chai PET B2.2 | C9: Đồng/kg | D9: ='4.Doanh thu'!F30 -> 13500 | E9: ='4.Doanh thu'!G30 -> 13500 | F9: ='4.Doanh thu'!H30 -> 13500 | G9: ='4.Doanh thu'!I30 -> 13500 | H9: ='4.Doanh thu'!J30 -> 13500 | I9: ='4.Doanh thu'!K30 -> 13500 | J9: ='4.Doanh thu'!L30 -> 13500 | K9: ='4.Doanh thu'!M30 -> 13500 | ... O9: ='4.Doanh thu'!Q30 -> 13500 | P9: =AVERAGE(D9:O9) -> 13500 | Q9: 15000 | R9: =Q9-P9 -> 1500 | T9: ='4.Doanh thu'!T30 -> 15739.156 | U9: ='4.Doanh thu'!U30 -> 17522 | V9: ='4.Doanh thu'!V30 -> 17637.022 | W9: ='4.Doanh thu'!W30 -> 18745.521 | X9: ='4.Doanh thu'!X30 -> 18633.722 | Y9: ='4.Doanh thu'!Y30 -> 18892.799 | Z9: ='4.Doanh thu'!Z30 -> 5861.324 | AA9: ='4.Doanh thu'!AA30 -> 0 | ... AF9: ='4.Doanh thu'!AF30 -> 14569.13
