Workbook
Name \T: #REF!
Name \T: #REF!
Name \T: #REF!
Name \T: #REF!
Name \T: #REF!
Name \T: #REF!
Name \T: #REF!
Name __dao1: #REF!
Name __dao2: #REF!
Name __dap2: #REF!
Name __day1: #REF!
Name __day2: #REF!
Name __dbu1: #REF!
Name __dbu2: #REF!
Name __doi3: #REF!
Name __E99999: #REF!
Name __Jan02: #REF!
Name __lap1: #REF!
Name __lap2: #REF!
Name __vc1: #REF!
Name __vc2: #REF!
Name __vc3: #REF!
Name _01_01_99: #REF!
Name _01_02_99: #REF!
Name _01_03_99: #REF!
Name _01_04_99: #REF!
Name _01_05_99: #REF!
Name _01_06_99: #REF!
Name _01_07_99: #REF!
Name _01_08_1999: #REF!
Name _1CAP002: #REF!
Name _2STREO7: #REF!
Name _4GOIC01: #REF!
Name _4OSLCTT: #REF!
Name _6BNTTTH: #REF!
Name _6DCTTBO: #REF!
Name _6DD24TT: #REF!
Name _6FCOTBU: #REF!
Name _6LATUBU: #REF!
Name _6SDTT24: #REF!
Name _6TBUDTT: #REF!
Name _6TDDDTT: #REF!
Name _6TLTTTH: #REF!
Name _6TUBUTT: #REF!
Name _6UCLVIS: #REF!
Name _7DNCABC: #REF!
Name _7HDCTBU: #REF!
Name _7PKTUBU: #REF!
Name _7TBHT20: #REF!
Name _7TBHT30: #REF!
Name _7TDCABC: #REF!
Name _dao1: #REF!
Name _dao2: #REF!
Name _dap2: #REF!
Name _day1: #REF!
Name _day2: #REF!
Name _dbu1: #REF!
Name _dbu2: #REF!
Name _doi3: #REF!
Name _E99999: #REF!

Sheet PET-tháng

Sheet PET_tuan

Sheet Ma trận PET
D3: MA TRẬN GIÁ BÁN rPET | AL3: 2023 | AX3: 2024 | BJ3: 2025 | EA3: 2023 | EE3: 07.02 | EF3: 14.02 | EG3: 21.02 | EH3: 28.02 | EI3: 7.03 | EJ3: 14.03 | EK3: 21.03 | EL3: 28.03 | EM3: 4.04 | EN3: 11.04 | EO3: 18.04 | EP3: 25.04 | EQ3: 2.05 | ER3: 9.05 | ES3: 16.05 | ET3: 23.05 | EU3: 30.05 | EV3: 6.06 | EW3: 13.06 | EX3: 20.06 | FZ3: 2024 | HX3: 2025
F4: Tỷ giá | I4: 23147 | J4: 23135 | K4: 23142 | L4: 23194 | M4: 23204 | N4: 23160 | O4: 23141 | P4: 23161 | Q4: 23161 | R4: 23123 | S4: 23156 | T4: 23126 | U4: 23180 | V4: 23108 | W4: =V4 -> 23108 | X4: =W4 -> 23108 | Y4: =X4 -> 23108 | Z4: 23150 | AA4: 23150 | AB4: 23150 | AC4: 23150 | AD4: 23500 | AE4: 23500 | AF4: 23500 | AG4: 23500 | AH4: 23500 | AI4: 23500 | AJ4: 24600 | AK4: 24000 | AL4: 24000 | AM4: 24000 | AN4: 24000 | AO4: 24000 | AP4: 24000 | AQ4: 24000 | AR4: 24000 | AS4: 24000 | AT4: 24000 | AU4: 24000 | AV4: 24000 | AW4: 24000 | AX4: 24000 | AY4: 24000 | AZ4: 24000 | BA4: 24000 | BB4: 24000 | BC4: 24000 | BD4: 24000 | BE4: 24000 | BF4: 24000 | BG4: 24000 | BH4: 24000 | BI4: 24000 | CX4: 23150 | CY4: 23150 | CZ4: 23150 | DA4: 23150 | DB4: 23150 | DC4: 23150 | DD4: 23150 | DE4: 23150 | DF4: 23150 | DG4: 23150 | DH4: 23150 | DI4: 23150 | DJ4: 23500 | DK4: 23500 | DL4: 23500 | DM4: 23500 | DN4: 23500 | DO4: 23500 | DP4: 23500 | DQ4: 23500 | DR4: 24600 | DS4: 24600 | DT4: 24600 | DU4: 24600 | DV4: 24600 | DW4: 24000 | DX4: 24000 | DY4: 24000 | DZ4: 24000 | EA4: 24000 | EB4: 24000 | EC4: 24000 | ED4: 24000 | EE4: 24000 | EF4: 24000 | EG4: 24000 | EH4: 24000 | EI4: 24000 | EJ4: 24000 | EK4: 24000 | EL4: 24000 | EM4: 24000 | EN4: 24000 | EO4: 24000 | EP4: 24000 | EQ4: 24000 | ER4: 24000 | ES4: 24000 | ET4: 24000 | EU4: 24000 | EV4: 24000 | EW4: 24000 | EX4: 24000 | EY4: 24000 | EZ4: 24000 | FA4: 24000 | FB4: 24000 | FC4: 24000 | FD4: 24000 | FE4: 24000 | FF4: 24000 | FG4: 24000 | FH4: 24000 | FI4: 24000 | FJ4: 24000 | FK4: 24000 | FL4: 24000 | FM4: 24000 | FN4: 24000 | FO4: 24000 | FP4: 24000 | FQ4: 24000 | FR4: 24000 | FS4: 24000 | FT4: 24000 | FU4: 24000 | FV4: 24000 | FW4: 24000 | FX4: 24000 | FY4: 24000 | FZ4: 24000 | GA4: 24000 | GB4: 24000 | GC4: 24000 | GD4: 24000 | GE4: 24000 | GF4: 24000 | GG4: 24000 | GH4: 24000 | GI4: 24000 | GJ4: 24000 | GK4: 24000 | GL4: 24000 | GM4: 24000 | GN4: 24000 | JW4: 2026
A5: Stt | B5: Mã SAP | C5: Tên hàng hóa SAP | D5: Mã SP | E5: Tên sản phẩm | F5: Diễn giải | G5: Đơn vị tính | H5: Diễn giải | I5: T1.21 | J5: T2.21 | K5: T3.21 | L5: T4.21 | M5: T5.21 | N5: T6.21 | O5: T7.21 | P5: T8.21 | Q5: T9.21 | R5: T10.21 | S5: T11.21 | T5: T12.21 | U5: 1 | V5: 2 | W5: 3 | X5: 4 | Y5: 5 | Z5: 6 | AA5: 7 | AB5: 8 | AC5: Hiện tại 23/8 | AD5: 9 | AE5: 10 | AF5: 4/10 | AG5: 11/10 | AH5: 18/10 | AI5: 25/10 | AJ5: 11 | AK5: 12 | AL5: T1/23 | AM5: 2 | AN5: 3 | AO5: 4 | AP5: 5 | AQ5: 6 | AR5: 7 | AS5: 8 | AT5: 9 | AU5: 10 | AV5: 11 | AW5: 12 | AX5: T1.24 | AY5: 2 | AZ5: 3 | BA5: 4 | BB5: 5 | BC5: 6 | BD5: 7 | BE5: 8 | BF5: 9 | BG5: 10 | BH5: 11 | BI5: 12 | BJ5: T1.25 | BK5: 2 | BL5: 3 | BM5: 4 | BN5: 5 | BO5: 6 | BP5: 7 | BQ5: 8 | BR5: 9 | BS5: 10 | BT5: 11 | BU5: 12 | BV5: T1.26 | BX5: Mã SP | BY5: Tên sản phẩm | BZ5: Diễn giải | CA5: 1 | CB5: =+CA5+1 -> 2 | CC5: =+CB5+1 -> 3 | CD5: =+CC5+1 -> 4 | CE5: =+CD5+1 -> 5 | CF5: =+CE5+1 -> 6 | CG5: =+CF5+1 -> 7 | CH5: =+CG5+1 -> 8 | CI5: =+CH5+1 -> 9 | ... CW5: =+CV5+1 -> 23 | CX5: 24 | CY5: 25 | CZ5: 26 | DA5: 27 | DB5: 28 | DC5: 29 | DD5: 30 | DE5: 31 | DF5: 32 | DG5: 33 | DH5: 34 | DI5: 35 | DJ5: 36 | DK5: 37 | DL5: 38 | DM5: 39 | DN5: 40 | DO5: 41 | DP5: 42 | DQ5: 43 | DR5: 44 | DS5: 45 | DT5: 46 | DU5: 47 | DV5: 48 | DW5: 49 | DX5: 50 | DY5: 51 | DZ5: 52 | EA5: 1 | EB5: 2 | EC5: 3 | ED5: 5 | EE5: 6 | EF5: 7 | EG5: 8 | EH5: 9 | EI5: 10 | EJ5: 11 | EK5: 12 | EL5: 13 | EM5: 14 | EN5: 15 | EO5: 16 | EP5: 17 | EQ5: 18 | ER5: 19 | ES5: 20 | ET5: 21 | EU5: 22 | EV5: 23 | EW5: 24 | EX5: 25 | EY5: 26 | EZ5: 27 | FA5: 28 | FB5: 29 | FC5: 30 | FD5: 31 | FE5: 32 | FF5: 33 | FG5: 34 | FH5: 35 | FI5: 36 | FJ5: 37 | FK5: 38 | FL5: 39 | FM5: 40 | FN5: 41 | FO5: 42 | FP5: 43 | FQ5: 44 | FR5: 45 | FS5: 46 | FT5: 47 | FU5: 48 | FV5: 49 | FW5: 50 | FX5: 51 | FY5: 52 | FZ5: 1/24 | GA5: 02 | GB5: 03 | GC5: 04 | GD5: 05 | GE5: 08 | GF5: 09 | GG5: 10 | GH5: 11 | GI5: 12 | GJ5: 13 | GK5: 14 | GL5: 15 | GM5: 16 | GN5: 17 | GO5: 18 | GP5: 19 | GQ5: 20 | GR5: 21 | GS5: 22 | GT5: 23 | GU5: 24 | GV5: 25 | GW5: 26 | GX5: 27 | GY5: 28 | GZ5: 29 | HA5: 30 | HB5: 31 | HC5: 32 | HD5: 33 | HE5: 34 | HF5: 35 | HG5: 36 | HH5: 37 | HI5: 38 | HJ5: 39 | HK5: 40 | HL5: 41 | HM5: 42 | HN5: 43 | HO5: 44 | HP5: 45 | HQ5: 46 | HR5: 47 | HS5: 48 | HT5: 49 | HU5: 50 | HV5: 51 | HW5: 52 | HX5: 01 | HY5: 02 | HZ5: 03 | IA5: 04 | IB5: 06 | IC5: 07 | ID5: 08 | IE5: 09 | IF5: 10 | IG5: 11 | IH5: 12 | II5: 13 | IJ5: 14 | IK5: 15 | IL5: 16 | IM5: 17 | IN5: 18 | IO5: 19 | IP5: 20 | IQ5: 21 | IR5: 22 | IS5: 23 | IT5: 24 | IU5: 25 | IV5: 26 | IW5: 27 | IX5: 28 | IY5: 29 | IZ5: 30 | JA5: 31 | JB5: 32 | JC5: 33 | JD5: 34 | JE5: 35 | JF5: 36 | JG5: 37 | JH5: 38 | JI5: 39 | JJ5: 40 | JK5: 41 | JL5: 42 | JM5: 43 | JN5: 44 | JO5: 45 | JP5: 46 | JQ5: 47 | JR5: 48 | JS5: 49 | JT5: 50 | JU5: 51 | JV5: 52 | JW5: 01 | JX5: 02 | JY5: 03 | JZ5: 04 | KA5: 05
A6: 5 | B6: 110000329 | C6: Hạt rPET WSS01 | D6: WSS01G | E6: WSS01 - Hạt rPET (IV 0.78) | F6: DTR | G6: $ /tấn | H6: DTR | I6: =I7-20 -> 1230 | J6: =J7-20 -> 1230 | K6: =K7-20 -> 1230 | L6: =L7-20 -> 1230 | M6: =M7-20 -> 1230 | N6: =N7-20 -> 1230 | O6: =O7-20 -> 1250 | P6: =P7-20 -> 1250 | ... V6: =V7-20 -> 1300 | W6: 1450 | X6: 1550 | Y6: 1550 | Z6: 1550 | AA6: 1550 | AB6: 1480 | AC6: 1480 | AD6: =#REF!/AD4*1000 -> #REF! | AE6: =#REF!/AE4*1000 -> #REF! | AF6: =#REF!/AF4*1000 -> #REF! | AG6: =#REF!/AG4*1000 -> #REF! | AH6: =#REF!/AH4*1000 -> #REF! | AI6: =#REF!/AI4*1000 -> #REF! | AJ6: =#REF!/AJ4*1000 -> #REF! | AK6: 1330 | AL6: =+SUM(EA6:ED6)/4 -> 1330 | AM6: =+SUM(EE6:EH6)/4 -> 1330 | AN6: =+SUM(EI6:EK6)/COUNT(EI6:EK6) -> 1380 | AO6: =+SUM(EM6:EP6)/COUNT(EM6:EP6) -> 1380 | AP6: =+SUM(EQ6:EU6)/COUNT(EQ6:EU6) -> 1380 | AQ6: =+SUM(EV6:EY6)/COUNT(EV6:EY6) -> 1325 | AR6: =+SUM(EZ6:FC6)/COUNT(EZ6:FC6) -> 1275 | AS6: =FD6 -> 1250 | AT6: 1250 | AU6: 1250 | AV6: 1250 | AW6: 1250 | AX6: 1250 | AY6: 1250 | AZ6: 1250 | BA6: 1250 | BB6: 1300 | BC6: 1300 | BD6: 1300 | BE6: 1300 | BF6: 1310 | BG6: 1325 | BH6: 1325 | BI6: =1325-50 -> 1275 | BJ6: =1325-50-45 -> 1230 | BK6: =1325-50-45 -> 1230 | BL6: =1325-50-45 -> 1230 | BM6: =1325-50-45+20 -> 1250 | BN6: =1325-50-45+20 -> 1250 | BO6: =1325-50-45+20 -> 1250 | BP6: =1325-50-45+20 -> 1250 | BQ6: =1325-50-45+20-30 -> 1220 | BR6: =1325-50-45+20-30 -> 1220 | BS6: =1325-50-45+20-30-10 -> 1210 | BT6: =1325-50-45+20-30-10-10 -> 1200 | BU6: =1325-50-45+20-30-10-10 -> 1200 | BV6: =1325-50-45+20-30-10-10-40 -> 1160 | BX6: WSS01/G | BY6: WSS01 - Hạt rPET (IV 0.78) | BZ6: DTR | CX6: 1550 | CY6: 1550 | CZ6: 1550 | DA6: 1550 | DB6: 1550 | DC6: 1550 | DD6: 1550 | DE6: 1480 | DF6: 1480 | DG6: 1480 | DH6: 1480 | DI6: 1480 | DJ6: 1410 | DK6: 1410 | DL6: 1410 | DM6: 1410 | DN6: =#REF!/DN4*1000 -> #REF! | DO6: =#REF!/DO4*1000 -> #REF! | DP6: =#REF!/DP4*1000 -> #REF! | DQ6: =#REF!/DQ4*1000 -> #REF! | DR6: 1380 | DS6: 1380 | DT6: 1380 | DU6: 1380 | DV6: 1380 | DW6: 1380 | DX6: 1380 | DY6: 1330 | DZ6: 1330 | EA6: 1330 | EB6: 1330 | EC6: 1330 | ED6: 1330 | EE6: 1330 | EF6: 1330 | EG6: 1330 | EH6: 1330 | EI6: 1380 | EJ6: 1380 | EK6: 1380 | EL6: 1380 | EM6: 1380 | EN6: 1380 | EO6: 1380 | EP6: 1380 | EQ6: 1380 | ER6: 1380 | ES6: 1380 | ET6: 1380 | EU6: 1380 | EV6: 1350 | EW6: 1350 | EX6: 1300 | EY6: 1300 | EZ6: 1300 | FA6: 1300 | FB6: 1250 | FC6: 1250 | FD6: 1250 | FE6: 1250 | FF6: 1250 | FG6: 1250 | FH6: 1250 | FI6: 1250 | FJ6: 1250 | FK6: 1250 | FL6: 1250 | FM6: 1250 | FN6: 1250 | FO6: 1250 | FP6: 1250 | FQ6: 1250 | FR6: 1250 | FS6: 1250 | FT6: 1250 | FU6: 1250 | FV6: 1250 | FW6: 1250 | FX6: 1250 | FY6: 1250 | FZ6: 1250 | GA6: 1250 | GB6: 1250 | GC6: 1250 | GD6: 1250 | GE6: 1250 | GF6: 1250 | GG6: 1250 | GH6: 1250 | GI6: 1250 | GJ6: 1250 | GK6: 1250 | GL6: 1250 | GM6: 1250 | GN6: 1250 | GO6: 1300 | GP6: 1300 | GQ6: 1300 | GR6: 1300 | GS6: 1300 | GT6: 1300 | GU6: 1300 | GV6: 1300 | GW6: 1300 | GX6: 1300 | GY6: 1300 | GZ6: 1300 | HA6: 1300 | HB6: 1300 | HC6: 1300 | HD6: 1300 | HE6: 1300 | HF6: 1300 | HG6: 1310 | HH6: 1310 | HI6: 1310 | HJ6: 1310 | HK6: 1325 | HL6: 1325 | HM6: 1325 | HN6: 1325 | HO6: 1325 | HP6: 1325 | HQ6: 1325 | HR6: 1325 | HS6: 1325 | HT6: =1325-50 -> 1275 | HU6: =HT6 -> 1275 | HV6: =HU6 -> 1275 | HW6: =HV6 -> 1275 | HX6: 1230 | HY6: =HX6 -> 1230 | HZ6: =HY6 -> 1230 | IA6: =HZ6 -> 1230 | IB6: =IA6 -> 1230 | IC6: =IB6 -> 1230 | ID6: =IC6 -> 1230 | IE6: =ID6 -> 1230 | IF6: =IE6 -> 1230 | ... II6: =IH6 -> 1230 | IJ6: =II6+20 -> 1250 | IK6: =IJ6 -> 1250 | IL6: =IK6 -> 1250 | IM6: =IL6 -> 1250 | IN6: =IM6 -> 1250 | IO6: =IN6 -> 1250 | IP6: =IO6 -> 1250 | IQ6: =IP6 -> 1250 | IR6: =IQ6 -> 1250 | IS6: 1223.0835 | IT6: 1225.2286 | IU6: 1219.8595 | IV6: 1219.0531 | IW6: 1215.2889 | IX6: 1228.3131 | IY6: 1216.0902 | IZ6: 1220.5682 | JA6: 1216.9073 | JB6: 1204.4734 | JC6: 1187.6814 | JD6: 1220 | JE6: =JD6 -> 1220 | JF6: =JE6 -> 1220 | JG6: =JF6 -> 1220 | JH6: =JG6 -> 1220 | JI6: =JH6 -> 1220 | JJ6: 1210 | JK6: =JJ6 -> 1210 | JL6: =JK6 -> 1210 | JM6: =JL6 -> 1210 | JN6: 1210 | JO6: 1200 | JP6: 1200 | JQ6: 1200 | JR6: 1200 | JS6: 1200 | JT6: 1200 | JU6: 1200 | JV6: 1200 | JW6: 1160 | JX6: 1160 | JY6: 1160 | JZ6: 1160 | KA6: 1160
A7: 6 | B7: 110000329 | C7: Hạt rPET WSS01 | D7: WSS01/G | E7: WSS01 - Hạt rPET (IV 0.78) | F7: DTR-Giá WSS01 FOB-HCM (IV: 0,78+/- 0.02) | G7: $ /tấn | H7: DTR | I7: 1250 | J7: 1250 | K7: 1250 | L7: 1250 | M7: 1250 | N7: 1250 | O7: 1270 | P7: 1270 | Q7: 1270 | R7: 1270 | S7: 1320 | T7: 1320 | U7: 1320 | V7: 1320 | W7: =W6+20 -> 1470 | X7: =X6+20 -> 1570 | Y7: =Y6+20 -> 1570 | Z7: =Z6+20 -> 1570 | AA7: =AA6+20 -> 1570 | AB7: 1500 | AC7: =AC6+20 -> 1500 | AD7: =AD6+20 -> #REF! | AE7: =AE6+20 -> #REF! | AF7: =AF6+20 -> #REF! | AG7: =AG6+20 -> #REF! | AH7: =AH6+20 -> #REF! | AI7: =AI6+20 -> #REF! | AJ7: =AJ6+20 -> #REF! | AK7: =AK6+20 -> 1350 | AL7: =+SUM(EA7:ED7)/4 -> 1330 | AM7: =+SUM(EB7:EE7)/4 -> 1330 | AN7: =+SUM(EI7:EK7)/COUNT(EI7:EK7) -> 1380 | AO7: =+SUM(EM7:EP7)/COUNT(EM7:EP7) -> 1380 | AP7: =+SUM(EQ7:EU7)/COUNT(EQ7:EU7) -> 1380 | AQ7: =+SUM(EV7:EY7)/COUNT(EV7:EY7) -> 1325 | AR7: =+SUM(EZ7:FC7)/COUNT(EZ7:FC7) -> 1275 | AS7: =+SUM(FD7:FH7)/COUNT(FD7:FH7) -> 1250 | AT7: =FI7 -> 1250 | AU7: =FJ7 -> 1250 | AV7: =FK7 -> 1250 | AW7: =FL7 -> 1250 | AX7: =FM7 -> 1250 | AY7: =FN7 -> 1250 | AZ7: =FO7 -> 1250 | BA7: =FP7 -> 1250 | BB7: 1300 | BC7: 1300 | BD7: 1300 | BE7: 1300 | BF7: 1300 | BG7: 1300 | BH7: 1300 | BI7: 1300 | BJ7: 1300 | BK7: 1300 | BL7: 1300 | BM7: 1300 | BN7: 1300 | BO7: 1300 | BP7: 1300 | BQ7: 1300 | BR7: 1300 | BS7: 1300 | BT7: 1300 | BU7: 1300 | BV7: 1300 | BX7: giá EXW | BY7: WSS01 - Hạt rPET (IV 0.78) | BZ7: DTR | CX7: =CX6+20 -> 1570 | CY7: =CY6+20 -> 1570 | CZ7: =CZ6+20 -> 1570 | DA7: =DA6+20 -> 1570 | DB7: =DB6+20 -> 1570 | DC7: =DC6+20 -> 1570 | DD7: =DD6+20 -> 1570 | DE7: =DE6+20 -> 1500 | ... DQ7: =DQ6+20 -> #REF! | DR7: 1400 | DS7: 1400 | DT7: 1400 | DU7: 1400 | DV7: 1400 | DW7: 1400 | DX7: 1400 | DY7: 1350 | DZ7: 1350 | EA7: =EA6 -> 1330 | EB7: =EB6 -> 1330 | EC7: =EC6 -> 1330 | ED7: =ED6 -> 1330 | EE7: =EE6 -> 1330 | EF7: =EF6 -> 1330 | EG7: =EG6 -> 1330 | EH7: =EH6 -> 1330 | ... FX7: =FX6 -> 1250 | FY7: 1250 | FZ7: 1250 | GA7: 1250 | GB7: 1250 | GC7: 1250 | GD7: 1250 | GE7: 1250 | GF7: 1250 | GG7: 1250 | GH7: 1250 | GI7: 1250 | GJ7: 1250 | GK7: 1250 | GL7: 1250 | GM7: 1250 | GN7: 1250 | GO7: 1250 | GP7: 1250 | GQ7: 1250 | GR7: 1250 | GS7: 1250 | GT7: 1250 | GU7: 1250 | GV7: 1250 | GW7: 1250
A8: 7 | B8: 110000330 | C8: Hạt rPET SS01 | D8: ISS01/G | E8: SS01 - Hạt rPET (IV 0.82) | F8: DTR-Giá ISS01 FOB-HCM (IV: 0,82+/- 0.02) | G8: $ /tấn | H8: ISS01 (IV: 0,82+/- 0.02) | I8: =I7+30 -> 1280 | J8: =J7+30 -> 1280 | K8: =K7+30 -> 1280 | L8: =L7+30 -> 1280 | M8: =M7+30 -> 1280 | N8: =N7+30 -> 1280 | O8: =O7+30 -> 1300 | P8: =P7+30 -> 1300 | ... S8: =S7+30 -> 1350 | T8: =T7+50 -> 1370 | U8: =U7+50 -> 1370 | V8: =V7+50 -> 1370 | W8: =W7+100 -> 1570 | X8: =X7+100 -> 1670 | Y8: =Y7+100 -> 1670 | Z8: =Z7+80 -> 1650 | AA8: =AA7+80 -> 1650 | AB8: 1530 | AC8: 1530 | AD8: =#REF!/AD4*1000+20 -> #REF! | AE8: =#REF!/AE4*1000+20 -> #REF! | AF8: =#REF!/AF4*1000+20 -> #REF! | AG8: =#REF!/AG4*1000+20 -> #REF! | AH8: =#REF!/AH4*1000+20 -> #REF! | AI8: =#REF!/AI4*1000+20 -> #REF! | AJ8: =#REF!/AJ4*1000+20 -> #REF! | AK8: =#REF!/AK4*1000+20 -> #REF! | AL8: =#REF!/AL4*1000+20 -> #REF! | AM8: =+SUM(EE8:EH8)/4 -> 1397.5 | AN8: =+SUM(EI8:EK8)/COUNT(EI8:EK8) -> 1410 | AO8: =+SUM(EM8:EP8)/COUNT(EM8:EP8) -> 1410 | AP8: =+SUM(EQ8:EU8)/COUNT(EQ8:EU8) -> 1410 | AQ8: =+SUM(EV8:EY8)/COUNT(EV8:EY8) -> 1355 | AR8: =+SUM(EZ8:FC8)/COUNT(EZ8:FC8) -> 1305 | AS8: =+SUM(FD8:FH8)/COUNT(FD8:FH8) -> 1280 | AT8: =FI8 -> 1280 | AU8: =FJ8 -> 1280 | AV8: =FK8 -> 1280 | AW8: =FL8 -> 1280 | AX8: =FM8 -> 1280 | AY8: =FN8 -> 1280 | AZ8: =FO8 -> 1280 | BA8: =FP8 -> 1280 | ... BV8: =GK8 -> 1280 | BX8: ISS01/G | BY8: SS01 - Hạt rPET (IV 0.82) | BZ8: ISS01 (IV: 0,82+/- 0.02) | CX8: 1650 | CY8: 1650 | CZ8: 1650 | DA8: 1650 | DB8: 1650 | DC8: 1650 | DD8: 1650 | DE8: 1530 | DF8: 1530 | DG8: 1530 | DH8: 1530 | DI8: 1530 | DJ8: 1460 | DK8: 1460 | DL8: 1460 | DM8: 1460 | DN8: =#REF!/DN4*1000+20 -> #REF! | DO8: =#REF!/DO4*1000+20 -> #REF! | DP8: =#REF!/DP4*1000+20 -> #REF! | DQ8: =#REF!/DQ4*1000+20 -> #REF! | DR8: 1410 | DS8: 1410 | DT8: 1410 | DU8: 1410 | DV8: 1410 | DW8: 1410 | DX8: 1410 | DY8: 1410 | DZ8: 1410 | EA8: 1410 | EB8: 1410 | EC8: 1410 | ED8: 1410 | EE8: 1410 | EF8: 1410 | EG8: 1410 | EH8: =+EH7+30 -> 1360 | EI8: =+EI7+30 -> 1410 | EJ8: =+EJ7+30 -> 1410 | EK8: =+EK7+30 -> 1410 | EL8: =+EL7+30 -> 1410 | EM8: =+EM7+30 -> 1410 | EN8: =+EN7+30 -> 1410 | EO8: =+EO7+30 -> 1410 | ... GW8: =+GW7+30 -> 1280
D9: ẩn | F9: DTR-Giá FOB rPET ISS01 | G9: đồng /kg | H9: DTR-Giá FOB rPET ISS01 | V9: =V8*23108/1000 -> 31657.96 | W9: =W8*23108/1000 -> 36279.56 | X9: =X8*23108/1000 -> 38590.36 | Y9: =Y8*23108/1000 -> 38590.36 | Z9: =Z8*Z4/1000 -> 38197.5 | AC9: =AC8*AC4/1000 -> 35419.5 | AD9: =AD8*AD4/1000 -> #REF! | AE9: =AE8*AE4/1000 -> #REF! | AF9: =AF8*AF4/1000 -> #REF! | AG9: =AG8*AG4/1000 -> #REF! | AH9: =AH8*AH4/1000 -> #REF! | AI9: =AI8*AI4/1000 -> #REF! | AJ9: =AJ8*AJ4/1000 -> #REF! | ... AM9: =AM8*AM4/1000 -> 33540 | BX9: ẩn | BZ9: DTR-Giá FOB rPET ISS01 | DN9: =DN8*DN4/1000 -> #REF! | DO9: =DO8*DO4/1000 -> #REF! | DP9: =DP8*DP4/1000 -> #REF! | DQ9: =DQ8*DQ4/1000 -> #REF! | DR9: 33135 | EX9: =+#REF!+30 -> #REF!
A11: 9 | D11: ICIS | E11: ICIS giá rPET ($ /tấn) | F11: ICIS FOB ĐNA - Giá trung bình | G11: $ /tấn | H11: ICIS | P11: 1300 | Q11: 1300 | R11: 1350 | S11: 1350 | T11: 1350 | U11: 1350 | V11: 1500 | W11: 1525 | X11: 1525 | Y11: 1550 | Z11: 1627 | AA11: 1585 | AB11: 1574 | AC11: 1485 | AD11: 1444 | AE11: 1425 | AF11: 1425 | AG11: 1425 | AH11: 1425 | AI11: =(1350+1500)/2 -> 1425 | AJ11: 1425 | AK11: 1330 | AL11: =+SUM(EA11:ED11)/4 -> 1287.5 | AM11: =+SUM(EE11:EH11)/4 -> 1313.75 | AN11: =+SUM(EI11:EK11)/COUNT(EI11:EK11) -> 1440 | AO11: =+SUM(EM11:EP11)/COUNT(EM11:EP11) -> 1440 | AP11: =+SUM(EQ11:EU11)/COUNT(EQ11:EU11) -> 1433 | AQ11: =+SUM(EV11:EY11)/COUNT(EV11:EY11) -> 1337.5 | AR11: =+SUM(EZ11:FC11)/COUNT(EZ11:FC11) -> 1317.5 | AS11: =+SUM(FD11:FH11)/COUNT(FD11:FH11) -> 1274 | AT11: =+SUM(FI11:FL11)/COUNT(FI11:FL11) -> 1288.75 | AU11: =+SUM(FM11:FP11)/COUNT(FM11:FP11) -> 1288.125 | AV11: =+SUM(FQ11:FT11)/COUNT(FQ11:FT11) -> 1300 | AW11: =+SUM(FU11:FY11)/COUNT(FU11:FY11) -> 1300 | AX11: =+SUM(FZ11:GC11)/COUNT(FZ11:GC11) -> 1312.5 | AY11: =+SUM(GD11:GF11)/COUNT(GD11:GF11) -> 1325 | AZ11: =+SUM(GG11:GJ11)/COUNT(GG11:GJ11) -> 1320 | BA11: =+SUM(GK11:GN11)/COUNT(GK11:GN11) -> 1323.75 | BB11: =+SUM(GO11:GS11)/COUNT(GO11:GS11) -> 1346.6 | BC11: =+SUM(GT11:GW11)/COUNT(GT11:GW11) -> 1365 | BD11: =+SUM(GX11:HA11)/COUNT(GX11:HA11) -> 1365 | BE11: =+SUM(HB11:HF11)/COUNT(HB11:HF11) -> 1404 | BF11: =+SUM(HG11:HJ11)/COUNT(HG11:HJ11) -> 1427.5 | BG11: =+SUM(HK11:HN11)/COUNT(HK11:HN11) -> 1440 | BH11: =+SUM(HO11:HS11)/COUNT(HO11:HS11) -> 1440 | BI11: =+SUM(HT11:HW11)/COUNT(HT11:HW11) -> 1421.25 | BJ11: =+SUM(HX11:IA11)/COUNT(HX11:IA11) -> 1368.75 | BK11: =+SUM(IB11:IE11)/COUNT(IB11:IE11) -> 1350 | BL11: =+SUM(IF11:II11)/COUNT(IF11:II11) -> 1360 | BM11: =+SUM(IJ11:IM11)/COUNT(IJ11:IM11) -> 1360 | BN11: =+SUM(IN11:IR11)/COUNT(IN11:IR11) -> 1360 | BO11: =+SUM(IS11:IV11)/COUNT(IS11:IV11) -> 1360 | BP11: =+SUM(IW11:JA11)/COUNT(IW11:JA11) -> 1324 | BQ11: =+SUM(JB11:JE11)/COUNT(JB11:JE11) -> 1295 | BR11: =+SUM(JF11:JI11)/COUNT(JF11:JI11) -> 1275 | BS11: =+SUM(JJ11:JN11)/COUNT(JJ11:JN11) -> 1248 | BT11: =+SUM(JO11:JR11)/COUNT(JO11:JR11) -> 1243.75 | BU11: =+SUM(JS11:JV11)/COUNT(JS11:JV11) -> 1193.75 | BV11: 1150 | BX11: ICIS | BY11: ICIS giá rPET ($ /tấn) | BZ11: ICIS | CX11: =+(1550+1670)/2 -> 1610 | CY11: =+(1550+1700)/2 -> 1625 | CZ11: =+(1550+1650)/2 -> 1600 | DA11: =+(1550+1620)/2 -> 1585 | DB11: =+(1550+1650)/2 -> 1600 | DC11: =+(1550+1650)/2 -> 1600 | DD11: =+(1550+1650)/2 -> 1600 | DE11: =+(1550+1680)/2 -> 1615 | DF11: =+(1550+1680)/2 -> 1615 | DG11: =+(1550+1620)/2 -> 1585 | DH11: =+(1550+1620)/2 -> 1585 | DI11: =+(1450+1520)/2 -> 1485 | DJ11: =+(1350+1550)/2 -> 1450 | DK11: =+(1350+1550)/2 -> 1450 | DL11: =+(1350+1550)/2 -> 1450 | DM11: =+(1350+1550)/2 -> 1450 | DN11: 1425 | DO11: 1425 | DP11: 1425 | DQ11: =(1350+1500)/2 -> 1425 | DR11: 1350 | DS11: 1350 | DT11: =+(1250+1450)/2 -> 1350 | DU11: =+(1250+1450)/2 -> 1350 | DV11: =+(1250+1450)/2 -> 1350 | DW11: =+(1250+1450)/2 -> 1350 | DX11: =+(1250+1450)/2 -> 1350 | DY11: =+(1250+1350)/2 -> 1300 | DZ11: =+(1250+1350)/2 -> 1300 | EA11: =+(1250+1350)/2 -> 1300 | EB11: =+(1250+1350)/2 -> 1300 | EC11: =+(1250+1300)/2 -> 1275 | ED11: =+(1250+1300)/2 -> 1275 | EE11: =+(1250+1300)/2 -> 1275 | EF11: =+(1250+1300)/2 -> 1275 | EG11: =+(1280+1350)/2 -> 1315 | EH11: =+(1350+1430)/2 -> 1390 | EI11: =+(1350+1530)/2 -> 1440 | EJ11: =+(1350+1530)/2 -> 1440 | EK11: =+(1350+1530)/2 -> 1440 | EL11: =+(1350+1530)/2 -> 1440 | EM11: =+(1350+1530)/2 -> 1440 | EN11: =+(1350+1530)/2 -> 1440 | EO11: =+(1350+1530)/2 -> 1440 | EP11: =+(1350+1530)/2 -> 1440 | ... ET11: =+(1350+1530)/2 -> 1440 | EU11: =+(1350+1460)/2 -> 1405 | EV11: =+(1350+1400)/2 -> 1375 | EW11: =+(1300+1350)/2 -> 1325 | EX11: =+(1300+1350)/2 -> 1325 | EY11: =+(1300+1350)/2 -> 1325 | EZ11: =+(1300+1350)/2 -> 1325 | FA11: =+(1300+1350)/2 -> 1325 | FB11: =+(1270+1350)/2 -> 1310 | FC11: =+(1270+1350)/2 -> 1310 | FD11: =+(1200+1300)/2 -> 1250 | FE11: =+(1200+1320)/2 -> 1260 | FF11: =+(1200+1320)/2 -> 1260 | FG11: =+(1250+1350)/2 -> 1300 | FH11: =+(1250+1350)/2 -> 1300 | FI11: =+(1250+1330)/2 -> 1290 | FJ11: =+(1250+1330)/2 -> 1290 | FK11: =+(1250+1330)/2 -> 1290 | FL11: 1285 | FM11: 1285 | FN11: 1287.5 | FO11: 1280 | FP11: 1300 | FQ11: 1300 | FR11: 1300 | FS11: 1300 | FT11: 1300 | FU11: 1300 | FV11: 1300 | FW11: 1300 | FX11: 1300 | FY11: 1300 | FZ11: 1300 | GA11: 1300 | GB11: 1325 | GC11: 1325 | GD11: 1325 | GE11: 1325 | GF11: 1325 | GG11: 1325 | GH11: 1325 | GI11: 1315 | GJ11: 1315 | GK11: 1325 | GL11: 1325 | GM11: 1325 | GN11: 1320 | GO11: 1333 | GP11: 1350 | GQ11: 1350 | GR11: 1350 | GS11: 1350 | GT11: 1365 | GU11: 1365 | GV11: 1365 | GW11: 1365 | GX11: 1365 | GY11: 1365 | GZ11: 1365 | HA11: 1365 | HB11: 1400 | HC11: 1400 | HD11: 1400 | HE11: 1410 | HF11: 1410 | HG11: 1430 | HH11: 1430 | HI11: 1425 | HJ11: 1425 | HK11: 1440 | HL11: 1440 | HM11: 1440 | HN11: 1440 | HO11: 1440 | HP11: 1440 | HQ11: 1440 | HR11: 1440 | HS11: 1440 | HT11: 1430 | HU11: 1430 | HV11: 1425 | HW11: 1400 | HX11: 1400 | HY11: 1375 | HZ11: 1350 | IA11: 1350 | IB11: 1350 | IC11: 1350 | ID11: 1350 | IE11: 1350 | IF11: 1360 | IG11: 1360 | IH11: 1360 | II11: 1360 | IJ11: 1360 | IK11: 1360 | IL11: 1360 | IM11: 1360 | IN11: 1360 | IO11: 1360 | IP11: 1360 | IQ11: 1360 | IR11: 1360 | IS11: 1360 | IT11: 1360 | IU11: 1360 | IV11: 1360 | IW11: 1360 | IX11: 1360 | IY11: 1300 | IZ11: 1300 | JA11: 1300 | JB11: 1300 | JC11: 1300 | JD11: 1290 | JE11: 1290 | JF11: 1290 | JG11: 1290 | JH11: 1260 | JI11: 1260 | JJ11: 1240 | JK11: 1250 | JL11: 1250 | JM11: 1250 | JN11: 1250 | JO11: 1250 | JP11: 1250 | JQ11: 1250 | JR11: 1225 | JS11: 1225 | JT11: 1200 | JU11: 1200 | JV11: 1150
A12: 9 | D12: ICIS | E12: ICIS giá rPET ($ /tấn) | F12: ICIS FOB ĐNA - Giá Cao | G12: $ /tấn | H12: ICIS FOB ĐNA - Giá Cao | P12: 1400 | Q12: 1500 | R12: 1500 | S12: 1500 | T12: 1500 | U12: 1500 | V12: 1650 | W12: 1650 | X12: 1650 | Y12: 1650 | Z12: 1800 | AA12: 1700 | AB12: 1610 | AC12: 1520 | AD12: 1538 | AE12: 1550 | AF12: 1500 | AG12: 1500 | AH12: 1500 | AI12: 1500 | AJ12: 1500 | AK12: 1410 | AL12: =+SUM(EA12:ED12)/4 -> 1325 | AM12: =+SUM(EE12:EH12)/4 -> 1345 | AN12: =+SUM(EI12:EK12)/COUNT(EI12:EK12) -> 1530 | AO12: =+SUM(EM12:EP12)/COUNT(EM12:EP12) -> 1530 | AP12: =+SUM(EQ12:EU12)/COUNT(EQ12:EU12) -> 1516 | AQ12: =+SUM(EV12:EY12)/COUNT(EV12:EY12) -> 1362.5 | AR12: =+SUM(EZ12:FC12)/COUNT(EZ12:FC12) -> 1350 | AS12: =+SUM(FD12:FH12)/COUNT(FD12:FH12) -> 1328 | AT12: =+SUM(FI12:FL12)/COUNT(FI12:FL12) -> 1327.5 | AU12: =+SUM(FM12:FP12)/COUNT(FM12:FP12) -> 1326.25 | AV12: =+SUM(FQ12:FT12)/COUNT(FQ12:FT12) -> 1350 | AW12: =+SUM(FU12:FY12)/COUNT(FU12:FY12) -> 1350 | AX12: =+SUM(FZ12:GC12)/COUNT(FZ12:GC12) -> 1375 | AY12: =+SUM(GD12:GF12)/COUNT(GD12:GF12) -> 1400 | AZ12: =+SUM(GG12:GJ12)/COUNT(GG12:GJ12) -> 1390 | BA12: =+SUM(GK12:GN12)/COUNT(GK12:GN12) -> 1397.5 | BB12: =+SUM(GO12:GS12)/COUNT(GO12:GS12) -> 1399.2 | BC12: =+SUM(GT12:GW12)/COUNT(GT12:GW12) -> 1455 | BD12: =+SUM(GX12:HA12)/COUNT(GX12:HA12) -> 1455 | BE12: =+SUM(HB12:HF12)/COUNT(HB12:HF12) -> 1504 | BF12: =+SUM(HG12:HJ12)/COUNT(HG12:HJ12) -> 1550 | BG12: =+SUM(HK12:HN12)/COUNT(HK12:HN12) -> 1580 | BH12: =+SUM(HO12:HS12)/COUNT(HO12:HS12) -> 1580 | BI12: =+SUM(HT12:HW12)/COUNT(HT12:HW12) -> 1555 | BJ12: =+SUM(HX12:IA12)/COUNT(HX12:IA12) -> 1512.5 | BK12: =+SUM(IB12:IE12)/COUNT(IB12:IE12) -> 1500 | BL12: =+SUM(IF12:II12)/COUNT(IF12:II12) -> 1500 | BM12: =+SUM(IJ12:IM12)/COUNT(IJ12:IM12) -> 1500 | BN12: =+SUM(IN12:IR12)/COUNT(IN12:IR12) -> 1500 | BO12: =+SUM(IS12:IV12)/COUNT(IS12:IV12) -> 1500 | BP12: =+SUM(IW12:JA12)/COUNT(IW12:JA12) -> 1440 | BQ12: =+SUM(JB12:JE12)/COUNT(JB12:JE12) -> 1390 | BR12: =+SUM(JF12:JI12)/COUNT(JF12:JI12) -> 1350 | BS12: =+SUM(JJ12:JN12)/COUNT(JJ12:JN12) -> 1344 | BT12: =+SUM(JO12:JR12)/COUNT(JO12:JR12) -> 1350 | BU12: =+SUM(JS12:JV12)/COUNT(JS12:JV12) -> 1300 | BV12: 1250 | BX12: ICIS | BY12: ICIS giá rPET ($ /tấn) | BZ12: ICIS FOB ĐNA - Giá Cao | CX12: 1670 | CY12: 1700 | CZ12: 1650 | DA12: 1620 | DB12: 1650 | DC12: 1650 | DD12: 1650 | DE12: 1680 | DF12: 1680 | DG12: 1620 | DH12: 1620 | DI12: 1520 | DJ12: 1550 | DK12: 1550 | DL12: 1550 | DM12: 1550 | DN12: 1500 | DO12: 1500 | DP12: 1500 | DQ12: 1500 | DR12: 1450 | DS12: 1450 | DT12: 1450 | DU12: 1450 | DV12: 1450 | DW12: 1450 | DX12: 1450 | DY12: 1350 | DZ12: 1350 | EA12: 1350 | EB12: 1350 | EC12: 1300 | ED12: 1300 | EE12: 1300 | EF12: 1300 | EG12: 1350 | EH12: 1430 | EI12: 1530 | EJ12: 1530 | EK12: 1530 | EL12: 1530 | EM12: 1530 | EN12: 1530 | EO12: 1530 | EP12: 1530 | EQ12: 1530 | ER12: 1530 | ES12: 1530 | ET12: 1530 | EU12: 1460 | EV12: 1400 | EW12: 1350 | EX12: 1350 | EY12: 1350 | EZ12: 1350 | FA12: 1350 | FB12: 1350 | FC12: 1350 | FD12: 1300 | FE12: 1320 | FF12: 1320 | FG12: 1350 | FH12: 1350 | FI12: 1330 | FJ12: 1330 | FK12: 1330 | FL12: 1320 | FM12: 1320 | FN12: 1325 | FO12: 1310 | FP12: 1350 | FQ12: 1350 | FR12: 1350 | FS12: 1350 | FT12: 1350 | FU12: 1350 | FV12: 1350 | FW12: 1350 | FX12: 1350 | FY12: 1350 | FZ12: 1350 | GA12: 1350 | GB12: 1400 | GC12: 1400 | GD12: 1400 | GE12: 1400 | GF12: 1400 | GG12: 1400 | GH12: 1400 | GI12: 1380 | GJ12: 1380 | GK12: 1400 | GL12: 1400 | GM12: 1400 | GN12: 1390 | GO12: 1396 | GP12: 1400 | GQ12: 1400 | GR12: 1400 | GS12: 1400 | GT12: 1455 | GU12: 1455 | GV12: 1455 | GW12: 1455 | GX12: 1455 | GY12: 1455 | GZ12: 1455 | HA12: 1455 | HB12: 1500 | HC12: 1500 | HD12: 1500 | HE12: 1510 | HF12: 1510 | HG12: 1550 | HH12: 1550 | HI12: 1550 | HJ12: 1550 | HK12: 1580 | HL12: 1580 | HM12: 1580 | HN12: 1580 | HO12: 1580 | HP12: 1580 | HQ12: 1580 | HR12: 1580 | HS12: 1580 | HT12: 1560 | HU12: 1560 | HV12: 1550 | HW12: 1550 | HX12: 1550 | HY12: 1500 | HZ12: 1500 | IA12: 1500 | IB12: 1500 | IC12: 1500 | ID12: 1500 | IE12: 1500 | IF12: 1500 | IG12: 1500 | IH12: 1500 | II12: 1500 | IJ12: 1500 | IK12: 1500 | IL12: 1500 | IM12: 1500 | IN12: 1500 | IO12: 1500 | IP12: 1500 | IQ12: 1500 | IR12: 1500 | IS12: 1500 | IT12: 1500 | IU12: 1500 | IV12: 1500 | IW12: 1500 | IX12: 1500 | IY12: 1400 | IZ12: 1400 | JA12: 1400 | JB12: 1400 | JC12: 1400 | JD12: 1380 | JE12: 1380 | JF12: 1380 | JG12: 1380 | JH12: 1320 | JI12: 1320 | JJ12: 1320 | JK12: 1350 | JL12: 1350 | JM12: 1350 | JN12: 1350 | JO12: 1350 | JP12: 1350 | JQ12: 1350 | JR12: 1350 | JS12: 1350 | JT12: 1300 | JU12: 1300 | JV12: 1250
D13: Anh 12 | F13: FENC_FOB TAIWAN BÁN CHO UNILEVER | G13: $ /tấn | H13: FENC_BÁN CHO UNILEVER | R13: 1290 | S13: 1290 | T13: 1290 | U13: 1205 | V13: 1205 | W13: 1542 | X13: 1542 | Y13: 1542 | Z13: 1755 | AA13: 1755 | AB13: 1755 | AC13: 1755 | AD13: 1755 | AE13: 1718 | AF13: 1718 | AG13: 1718 | AH13: 1718 | AI13: 1718 | AJ13: 1718 | AK13: 1718 | AL13: =+SUM(EA13:ED13)/4 -> 1640.75 | AM13: =+SUM(EE13:EH13)/4 -> 1615 | AN13: =+SUM(EI13:EK13)/COUNT(EI13:EK13) -> 1615 | BO13: =+SUM(IS13:IV13)/COUNT(IS13:IV13) -> #DIV/0! | BP13: =+SUM(IW13:JA13)/COUNT(IW13:JA13) -> #DIV/0! | BQ13: =+SUM(JB13:JE13)/COUNT(JB13:JE13) -> #DIV/0! | BR13: =+SUM(JF13:JI13)/COUNT(JF13:JI13) -> #DIV/0! | BS13: =+SUM(JJ13:JN13)/COUNT(JJ13:JN13) -> #DIV/0! | BT13: =+SUM(JO13:JR13)/COUNT(JO13:JR13) -> #DIV/0! | BU13: =+SUM(JS13:JV13)/COUNT(JS13:JV13) -> #DIV/0! | BV13: =+SUM(JT13:JW13)/COUNT(JT13:JW13) -> #DIV/0! | BX13: Anh 12 | BZ13: FENC_BÁN CHO UNILEVER | CX13: 1755 | CY13: 1755 | CZ13: 1755 | DA13: 1755 | DB13: 1755 | DC13: 1755 | DD13: 1755 | DE13: 1755 | DF13: 1755 | DG13: 1755 | DH13: 1755 | DI13: 1718 | DJ13: 1718 | DK13: 1718 | DL13: 1718 | DM13: 1718 | DN13: 1718 | DO13: 1718 | DP13: 1718 | DQ13: 1718 | DR13: 1718 | DS13: 1718 | DT13: 1718 | DU13: 1718 | DV13: 1718 | DW13: 1718 | DX13: 1718 | DY13: 1718 | DZ13: 1718 | EA13: 1718 | EB13: 1615 | EC13: 1615 | ED13: 1615 | EE13: 1615 | EF13: 1615 | EG13: 1615 | EH13: 1615 | EI13: 1615 | EJ13: 1615 | EK13: 1615 | EL13: 1615
D14: Anh 12 | F14: RESIN | G14: $ /tấn | H14: RESIN | S14: 1190 | T14: 1150 | U14: 1165 | V14: 1272.5 | W14: 1346 | X14: 1297.5 | Y14: 1316.6667 | Z14: 1390 | AA14: 1220 | AB14: 1270 | AC14: 1190 | AD14: 1190 | AE14: 1130 | AF14: 1100 | AG14: 1100 | AH14: 1070 | AI14: 1040 | AJ14: 1040 | AK14: =+SUM(DW14:DZ14)/4 -> 977.5 | AL14: =+SUM(EA14:ED14)/4 -> 1000 | AM14: =+SUM(EE14:EH14)/4 -> 1045 | AN14: =+SUM(EI14:EK14)/COUNT(EI14:EK14) -> 1020 | AO14: =+SUM(EM14:EP14)/COUNT(EM14:EP14) -> 1055 | AP14: =+SUM(EQ14:EU14)/COUNT(EQ14:EU14) -> 974 | AQ14: =+SUM(EV14:EY14)/COUNT(EV14:EY14) -> 895 | AR14: =+SUM(EZ14:FC14)/COUNT(EZ14:FC14) -> 903 | AS14: =+SUM(FD14:FH14)/COUNT(FD14:FH14) -> 918 | AT14: =+SUM(FI14:FL14)/COUNT(FI14:FL14) -> 930 | AU14: =+SUM(FM14:FP14)/COUNT(FM14:FP14) -> 922.5 | AV14: =+SUM(FQ14:FT14)/COUNT(FQ14:FT14) -> 900 | AW14: =+SUM(FU14:FY14)/COUNT(FU14:FY14) -> 900 | AX14: =+SUM(FZ14:GC14)/COUNT(FZ14:GC14) -> 930 | AY14: =+SUM(GD14:GF14)/COUNT(GD14:GF14) -> 943.33333 | AZ14: =+SUM(GG14:GJ14)/COUNT(GG14:GJ14) -> 940 | BA14: =+SUM(GK14:GN14)/COUNT(GK14:GN14) -> 940 | BB14: =+SUM(GO14:GS14)/COUNT(GO14:GS14) -> 942 | BC14: =+SUM(GT14:GW14)/COUNT(GT14:GW14) -> 950 | BD14: =+SUM(GX14:HA14)/COUNT(GX14:HA14) -> 947.5 | BE14: =+SUM(HB14:HF14)/COUNT(HB14:HF14) -> 930 | BF14: =+SUM(HG14:HJ14)/COUNT(HG14:HJ14) -> 880 | BG14: =+SUM(HK14:HN14)/COUNT(HK14:HN14) -> 862.5 | BH14: =+SUM(HO14:HS14)/COUNT(HO14:HS14) -> 852 | BI14: =+SUM(HT14:HW14)/COUNT(HT14:HW14) -> 830 | BJ14: =+SUM(HX14:IA14)/COUNT(HX14:IA14) -> 827.5 | BK14: =+SUM(IB14:IE14)/COUNT(IB14:IE14) -> 840 | BL14: =+SUM(IF14:II14)/COUNT(IF14:II14) -> 822.5 | BM14: =+SUM(IJ14:IM14)/COUNT(IJ14:IM14) -> 765 | BN14: =+SUM(IN14:IR14)/COUNT(IN14:IR14) -> 782 | BO14: =+SUM(IS14:IV14)/COUNT(IS14:IV14) -> 807.5 | BP14: =+SUM(IW14:JA14)/COUNT(IW14:JA14) -> 802 | BQ14: =+SUM(JB14:JE14)/COUNT(JB14:JE14) -> 795 | BR14: =+SUM(JF14:JI14)/COUNT(JF14:JI14) -> 782.5 | BS14: =+SUM(JJ14:JN14)/COUNT(JJ14:JN14) -> 772 | BT14: =+SUM(JO14:JR14)/COUNT(JO14:JR14) -> 770 | BU14: =+SUM(JS14:JV14)/COUNT(JS14:JV14) -> 772.5 | BV14: 795 | BX14: Anh 12 | BZ14: RESIN | CX14: =+(1400+1430)/2 -> 1415 | CY14: =+(1380+1410)/2 -> 1395 | CZ14: =+(1360+1390)/2 -> 1375 | DA14: =+(1320+1350)/2 -> 1335 | DB14: =+(1230+1270)/2 -> 1250 | DC14: =+(1210+1250)/2 -> 1230 | DD14: =+(1200+1240)/2 -> 1220 | DE14: =+(1230+1270)/2 -> 1250 | DF14: =+(1230+1270)/2 -> 1250 | DG14: =+(1200+1240)/2 -> 1220 | DH14: =+(1170+1210)/2 -> 1190 | DI14: =+(1140+1180)/2 -> 1160 | DJ14: =+(1140+1180)/2 -> 1160 | DK14: =+(1140+1180)/2 -> 1160 | DL14: =+(1110+1150)/2 -> 1130 | DM14: =+(1110+1150)/2 -> 1130 | DN14: 1100 | DO14: 1100 | DP14: 1070 | DQ14: 1040 | DR14: 995 | DS14: 980 | DT14: =+(960+1000)/2 -> 980 | DU14: =+(960+1000)/2 -> 980 | DV14: =+(940+1000)/2 -> 970 | DW14: =+(940+1000)/2 -> 970 | DX14: =+(940+1000)/2 -> 970 | DY14: =+(960+1000)/2 -> 980 | DZ14: =+(970+1010)/2 -> 990 | EA14: 970 | EB14: 980 | EC14: 990 | ED14: 1060 | EE14: 1070 | EF14: 1070 | EG14: 1020 | EH14: 1020 | EI14: 1020 | EJ14: 1020 | EK14: 1020 | EL14: 1020 | EM14: 1050 | EN14: 1070 | EO14: 1050 | EP14: 1050 | EQ14: 1020 | ER14: 1000 | ES14: 980 | ET14: 960 | EU14: 910 | EV14: 910 | EW14: 890 | EX14: 890 | EY14: 890 | EZ14: 890 | FA14: 882 | FB14: 920 | FC14: 920 | FD14: 940 | FE14: 920 | FF14: 910 | FG14: 910 | FH14: 910 | FI14: 910 | FJ14: 930 | FK14: 940 | FL14: 940 | FM14: 940 | FN14: 930 | FO14: 920 | FP14: 900 | FQ14: 900 | FR14: 900 | FS14: 900 | FT14: 900 | FU14: 900 | FV14: 900 | FW14: 900 | FX14: 900 | FY14: 900 | FZ14: 900 | GA14: 940 | GB14: 940 | GC14: 940 | GD14: 950 | GE14: 940 | GF14: 940 | GG14: 940 | GH14: 940 | GI14: 940 | GJ14: 940 | GK14: 940 | GL14: 940 | GM14: 940 | GN14: 940 | GO14: 940 | GP14: 940 | GQ14: 940 | GR14: 940 | GS14: 950 | GT14: 950 | GU14: 950 | GV14: 950 | GW14: 950 | GX14: 950 | GY14: 950 | GZ14: 950 | HA14: 940 | HB14: 940 | HC14: 940 | HD14: 940 | HE14: 930 | HF14: 900 | HG14: 900 | HH14: 890 | HI14: 870 | HJ14: 860 | HK14: 860 | HL14: 860 | HM14: 870 | HN14: 860 | HO14: 860 | HP14: 860 | HQ14: 860 | HR14: 840 | HS14: 840 | HT14: 840 | HU14: 830 | HV14: 830 | HW14: 820 | HX14: 820 | HY14: 820 | HZ14: 820 | IA14: 850 | IB14: 840 | IC14: 840 | ID14: 840 | IE14: 840 | IF14: 840 | IG14: 830 | IH14: 810 | II14: 810 | IJ14: 800 | IK14: 750 | IL14: 750 | IM14: 760 | IN14: 760 | IO14: 760 | IP14: 800 | IQ14: 800 | IR14: 790 | IS14: 800 | IT14: 790 | IU14: 820 | IV14: 820 | IW14: 820 | IX14: 820 | IY14: 790 | IZ14: 790 | JA14: 790 | JB14: 800 | JC14: 790 | JD14: 790 | JE14: 800 | JF14: 790 | JG14: 780 | JH14: 780 | JI14: 780 | JJ14: 780 | JK14: 780 | JL14: 770 | JM14: 760 | JN14: 770 | JO14: 770 | JP14: 770 | JQ14: 770 | JR14: 770 | JS14: 770 | JT14: 770 | JU14: 770 | JV14: 780 | JW14: 795
F15: ICIS Thị trường Mỹ (FOB) | H15: x | BZ15: ICIS Bờ Tây Mỹ (FOB) | DE15: 2502.24 | DF15: 2502.24 | DG15: 2502.24 | DH15: 2259.74 | DI15: 2259.74 | DJ15: 2259.74 | DK15: 1918.02 | DL15: 1918.02 | DM15: 1918.02 | DN15: 1587.33 | DO15: 1587.33 | DP15: 1587.33 | DQ15: 1587.33 | DR15: 1587.33 | DS15: 1587.33 | DT15: 1587.33 | DU15: 1587.33 | DV15: 1477.1 | DW15: 1477.1 | DX15: 1477.1 | DY15: 1477.1 | DZ15: 1477.1 | EA15: 1543.23 | EB15: 1543.234 | EC15: 1543.234 | ED15: 1543.234 | EE15: 1543.234 | EF15: 1543.234 | EG15: 1543.234 | EH15: 1543.234 | EI15: 1543.234 | EJ15: 1543.234 | EK15: 1543.234 | EL15: 1543.234 | EM15: 1543.234 | EN15: 1543.234 | EO15: 1543.234 | EP15: 1543.234 | EQ15: 1543.234 | ER15: 1543.234 | ES15: 1543.234 | ET15: 1521.188 | EU15: 1521.188 | EV15: 1521.188 | EW15: 1521.188 | EX15: 1521.188 | EY15: 1521.188 | EZ15: 1521.188 | FA15: 1521.188 | FB15: 1521.188 | FC15: 1521.188 | FD15: 1521.188 | FE15: 1521.188 | FF15: 1521.188 | FG15: 1521.188 | FH15: 1521.188 | FI15: 1521.188 | FJ15: 1521.188 | FK15: 1521.188 | FL15: 1521.188 | FM15: 1521.188 | FN15: 1521.188 | FO15: 1521.188 | FP15: 1521.188 | FQ15: 1521.188 | FR15: 1521.188 | FS15: 1521.188 | FT15: 1521.188 | FU15: 1521.188 | FV15: 1521.188 | FW15: 1521.188 | FX15: 1521.188 | FY15: 1521.188 | FZ15: 1521.188 | GA15: 1521.188 | GB15: 1521.188 | GC15: 1521.188 | GD15: 1521.188 | GE15: 1521.188 | GF15: 1521.188 | GG15: 1521.188 | GH15: 1521.188 | GI15: 1521.188 | GJ15: 1521.188 | GK15: 1521.188 | GL15: 1521.188 | GM15: 1521.188 | GN15: 1521.188
F16: Giá keo dự báo | H16: Giá keo dự báo | U16: =U14 -> 1165 | V16: =V14 -> 1272.5 | W16: =W14 -> 1346 | X16: =X14 -> 1297.5 | Y16: =Y14 -> 1316.6667 | Z16: =Z14 -> 1390 | AA16: =AA14 -> 1220 | AB16: =AB14 -> 1270 | ... BV16: =BV14 -> 795 | BZ16: Giá tới nhà máy Plascene | DL16: =DL15+222 -> 2140.02 | DM16: =DM15-222 -> 1696.02 | DN16: =DN15-222 -> 1365.33 | DO16: =DO15-222 -> 1365.33 | DP16: =DP15-222 -> 1365.33 | DQ16: =DQ15-222 -> 1365.33 | DR16: =DR15-222 -> 1365.33 | DS16: =DS15-222 -> 1365.33 | DT16: =DT15-222 -> 1365.33 | ... KA16: =KA15-222 -> -222
H17: TTCP | X17: =X14 -> 1297.5 | Y17: =Y14 -> 1316.6667 | Z17: =Z14 -> 1390 | AA17: =AA14 -> 1220 | AB17: =AB14 -> 1270 | AC17: =AC14 -> 1190 | AD17: =AD14 -> 1190 | AE17: =AE14 -> 1130 | ... BV17: =BV14 -> 795 | BZ17: TTCP | DN17: =DN14 -> 1100 | DO17: =DO14 -> 1100 | DP17: =DP14 -> 1070 | DQ17: =DQ14 -> 1040 | DR17: =DR14 -> 995 | DS17: =DS14 -> 980 | DT17: =DT14 -> 980 | DU17: =DU14 -> 980 | ... KA17: =KA14 -> 0
H18: CL | X18: =X7-X17 -> 272.5 | Y18: =Y7-Y17 -> 253.33333 | Z18: =Z7-Z17 -> 180 | AA18: =AA7-AA17 -> 350 | AB18: =AB7-AB17 -> 230 | AC18: =AC7-AC17 -> 310 | AD18: =AD7-AD17 -> #REF! | AE18: =AE7-AE17 -> #REF! | ... AK18: =AK7-AK17 -> 372.5 | AL18: =AL6-AL17 -> 330 | AM18: =AM6-AM17 -> 285 | AN18: =AN6-AN17 -> 360 | AO18: =AO6-AO17 -> 325 | AP18: =AP6-AP17 -> 406 | AQ18: =AQ6-AQ17 -> 430 | AR18: =AR6-AR17 -> 372 | AS18: =AS6-AS17 -> 332 | ... BV18: =BV6-BV17 -> 365 | BZ18: CL | DN18: =+DN7-DN17 -> #REF! | DO18: =+DO7-DO17 -> #REF! | DP18: =+DP7-DP17 -> #REF! | DQ18: =+DQ7-DQ17 -> #REF! | DR18: =+DR7-DR17 -> 405 | DS18: =+DS7-DS17 -> 420 | DT18: =+DT7-DT17 -> 420 | DU18: =+DU7-DU17 -> 420 | ... FY18: =+FY7-FY17 -> 350 | FZ18: =+FZ6-FZ17 -> 350 | GA18: =+GA6-GA17 -> 310 | GB18: =+GB6-GB17 -> 310 | GC18: =+GC6-GC17 -> 310 | GD18: =+GD6-GD17 -> 300 | GE18: =+GE6-GE17 -> 310 | GF18: =+GF6-GF17 -> 310 | GG18: =+GG6-GG17 -> 310 | ... KA18: =+KA6-KA17 -> 1160
H19: % | X19: =X18/X17 -> 0.21001927 | Y19: =Y18/Y17 -> 0.19240506 | Z19: =Z18/Z17 -> 0.1294964 | AA19: =AA18/AA17 -> 0.28688525 | AB19: =AB18/AB17 -> 0.18110236 | AC19: =AC18/AC17 -> 0.2605042 | AD19: =AD18/AD17 -> #REF! | AE19: =AE18/AE17 -> #REF! | ... BV19: =BV18/BV17 -> 0.4591195 | BZ19: % | DN19: =+DN18/DN17 -> #REF! | DO19: =+DO18/DO17 -> #REF! | DP19: =+DP18/DP17 -> #REF! | DQ19: =+DQ18/DQ17 -> #REF! | DR19: =+DR18/DR17 -> 0.40703518 | DS19: =+DS18/DS17 -> 0.42857143 | DT19: =+DT18/DT17 -> 0.42857143 | DU19: =+DU18/DU17 -> 0.42857143 | ... KA19: =+KA18/KA17 -> #DIV/0!
H20: Điểm hòa vốn | X20: 1225 | Y20: 1225 | Z20: 1225 | AA20: 1225 | AB20: 1225 | AC20: 1225 | AD20: 1225 | AE20: 1225 | AF20: 1225 | AG20: 1225 | AH20: 1225 | AI20: 1225 | AJ20: 1225 | AK20: 1225 | AL20: 1225 | AM20: 1225 | AN20: 1225 | AO20: 1225 | AP20: 1225 | AQ20: 1185 | AR20: 1133 | AS20: 1133 | AT20: 1151 | AU20: 1175 | AV20: 1200 | AW20: 1143 | AX20: 1162 | AY20: 1175 | AZ20: 1200 | BA20: 1230 | BB20: 1260 | BC20: 1250 | BD20: 1174 | BE20: 1131 | BF20: 1154.4175 | BG20: 1161.0769 | BH20: 1179.9226 | BI20: 1183.4455 | BJ20: 1181 | BK20: 1185.2425 | BL20: 1190.7839 | BM20: 1188.899 | BN20: 1208.4564 | BO20: 1167.8122 | BP20: 1185.3194 | BQ20: 1163.1487 | BR20: 1186.2628 | BS20: 1128 | BT20: 1070.5116 | BU20: 1092.8991 | BV20: 1096.8837 | BZ20: Giá keo dự báo | DN20: =DN14 -> 1100 | DO20: =DO14 -> 1100 | DP20: =DP14 -> 1070 | DQ20: =DQ14 -> 1040 | DR20: =DR14 -> 995 | DS20: =DS14 -> 980 | DT20: =DT14 -> 980 | DU20: =DU14 -> 980 | ... KA20: =KA14 -> 0
H21: Điểm hòa vốn ( có phí hỗ trợ) | BZ21: Điểm hòa vốn | DP21: 1303 | DQ21: 1303 | DR21: 1225 | DS21: 1225 | DT21: 1225 | DU21: 1225 | DV21: 1225 | DW21: 1225 | DX21: 1225 | DY21: 1225 | DZ21: 1225 | EA21: 1225 | EB21: 1225 | EC21: 1225 | ED21: 1225 | EE21: 1225 | EF21: 1225 | EG21: 1225 | EH21: 1225 | EI21: 1225 | EJ21: 1225 | EK21: 1225 | EL21: 1225 | EM21: 1225 | EN21: 1225 | EO21: 1225 | EP21: 1225 | EQ21: 1225 | ER21: 1225 | ES21: 1225 | ET21: 1225 | EU21: 1225 | EV21: 1225 | EW21: 1185 | EX21: 1185 | EY21: 1185 | EZ21: 1185 | FA21: 1133 | FB21: 1133 | FC21: 1133 | FD21: 1133 | FE21: 1133 | FF21: 1133 | FG21: 1133 | FH21: 1151 | FI21: 1151 | FJ21: 1151 | FK21: 1175 | FL21: 1175 | FM21: 1175 | FN21: 1175 | FO21: 1175 | FP21: 1175 | FQ21: 1200 | FR21: 1200 | FS21: 1200 | FT21: 1200 | FU21: 1143 | FV21: 1143 | FW21: 1143 | FX21: 1143 | FY21: 1143 | FZ21: 1162 | GA21: 1162 | GB21: 1162 | GC21: 1162 | GD21: 1175 | GE21: 1175 | GF21: 1175 | GG21: 1200 | GH21: 1200 | GI21: 1200 | GJ21: 1200 | GK21: 1230 | GL21: 1230 | GM21: 1230 | GN21: 1230 | GO21: 1260 | GP21: 1260 | GQ21: 1260 | GR21: 1260 | GS21: 1260 | GT21: 1250 | GU21: 1250 | GV21: 1250 | GW21: 1250 | GX21: 1174 | GY21: 1174 | GZ21: 1174 | HA21: 1174 | HB21: 1131 | HC21: 1131 | HD21: 1131 | HE21: 1131 | HF21: 1131 | HG21: 1154.4175 | HH21: 1154.4175 | HI21: 1154.4175 | HJ21: 1154.4175 | HK21: 1161.0769 | HL21: 1161.0769 | HM21: 1161.0769 | HN21: 1161.0769 | HO21: 1179.9226 | HP21: 1179.9226 | HQ21: 1179.9226 | HR21: 1179.9226 | HS21: 1179.9226 | HT21: 1183.4455 | HU21: 1183.4455 | HV21: 1183.4455 | HW21: 1183.4455 | HX21: 1181 | HY21: 1181 | HZ21: 1181 | IA21: 1181 | IB21: 1185.2425 | IC21: 1185.2425 | ID21: 1185.2425 | IE21: 1185.2425 | IF21: 1190.7839 | IG21: 1190.7839 | IH21: 1190.7839 | II21: 1190.7839 | IJ21: 1188.899 | IK21: 1188.899 | IL21: 1188.899 | IM21: 1188.899 | IN21: 1208.4564 | IO21: 1208.4564 | IP21: 1208.4564 | IQ21: 1208.4564 | IR21: 1208.4564 | IS21: 1167.8122 | IT21: 1167.8122 | IU21: 1167.8122 | IV21: 1167.8122 | IW21: 1185.3194 | IX21: 1185.3194 | IY21: 1185.3194 | IZ21: 1185.3194 | JA21: 1185.3194 | JB21: 1163.1487 | JC21: 1163.1487 | JD21: 1163.1487 | JE21: 1163.1487 | JF21: 1186.2628 | JG21: 1186.2628 | JH21: 1186.2628 | JI21: 1186.2628 | JJ21: 1149.7077 | JK21: 1149.7077 | JL21: 1149.7077 | JM21: 1149.7077 | JN21: 1149.7077 | JO21: 1070.5116 | JP21: 1070.5116 | JQ21: 1070.5116 | JR21: 1070.5116 | JS21: 1092.8991 | JT21: 1092.8991 | JU21: 1092.8991 | JV21: 1092.8991 | JW21: 1096.8837 | JX21: 1096.8837 | JY21: 1096.8837 | JZ21: 1096.8837 | KA21: 1096.8837
BZ22: Điểm hòa vốn có 25% rewash | EA22: =EA21+35 -> 1260 | EB22: =EB21+35 -> 1260 | EC22: =EC21+35 -> 1260 | ED22: =ED21+35 -> 1260 | EE22: =EE21+35 -> 1260 | EF22: =EF21+35 -> 1260 | EG22: =EG21+35 -> 1260 | EH22: =EH21+35 -> 1260 | ... FU22: =FU21+35 -> 1178 | FV22: =FV21+20 -> 1163 | FW22: =FW21+20 -> 1163 | FX22: =FX21+20 -> 1163 | FY22: =FY21+20 -> 1163 | FZ22: =FZ21+20 -> 1182 | GA22: =GA21+20 -> 1182 | GB22: =GB21+20 -> 1182 | GC22: =GC21+20 -> 1182 | ... GN22: =GN21+20 -> 1250
H23: Giá bán đối thủ Intco | AS23: 1220 | AT23: 1220 | AU23: 1220 | BZ23: Điểm hòa vốn (có phí hỗ trợ) | EA23: =EA21+34 -> 1259 | EB23: =EB21+34 -> 1259 | EC23: =EC21+34 -> 1259 | ED23: =ED21+34 -> 1259 | EE23: =EE21+34 -> 1259 | EF23: =EF21+34 -> 1259 | EG23: =EG21+34 -> 1259 | EH23: =EH21+34 -> 1259 | ... FG23: =FG21+34 -> 1167 | FH23: 1182 | FI23: 1182 | FJ23: 1182 | FK23: 1182 | FL23: 1182 | FM23: 1234 | FN23: 1234 | FO23: 1234 | FP23: 1234 | FQ23: 1234 | FR23: 1234 | FS23: 1234 | FT23: 1234 | FU23: 1234 | FV23: 1234 | FW23: 1234 | FX23: 1234 | FY23: 1234 | FZ23: 1234 | GA23: 1234 | GB23: 1234 | GC23: 1234 | GD23: 1234 | GE23: 1234 | GF23: 1234 | GG23: 1234 | GH23: 1234 | GI23: 1234 | GJ23: 1234 | GK23: 1234 | GL23: 1234 | GM23: 1234 | GN23: 1234
H24: Giá bán Unilever | X24: 1360 | Y24: 1360 | Z24: 1360 | AA24: 1550 | AB24: 1550 | AC24: 1550 | AD24: 1550 | AE24: 1534 | AF24: 1534 | AG24: 1534 | AH24: 1534 | AI24: 1534 | AJ24: 1534 | AK24: 1534 | AL24: 1445 | AM24: 1445 | AN24: 1445 | AO24: 1500 | AP24: 1500 | AQ24: 1500 | AR24: 1450 | AS24: 1450 | AT24: 1450 | AU24: 1350 | AV24: 1350 | AW24: 1350 | AX24: 1320 | AY24: 1320 | AZ24: 1320 | BA24: 1320 | BB24: 1320 | BC24: 1320 | BD24: 1300 | BE24: 1300 | BF24: 1300 | BG24: 1300 | BH24: 1300 | BI24: 1300 | BJ24: 1300 | BK24: 1300 | BL24: 1250 | BM24: 1250 | BN24: 1250 | BO24: 1250 | BP24: 1280 | BQ24: 1280 | BR24: 1280 | BS24: 1280 | BT24: 1280 | BU24: 1280 | BV24: 1250 | BZ24: Giá bán đối thủ Intco | FA24: 1200 | FD24: 1200 | FE24: 1200 | FF24: 1200 | FG24: 1200 | FH24: 1200 | FI24: 1200 | FJ24: 1200 | FK24: 1200 | FL24: 1200 | FM24: 1200 | FN24: 1200 | FO24: 1200 | FP24: 1100 | FQ24: 1100 | FR24: 1100 | FS24: 1100 | FT24: 1100 | FU24: 1100 | FV24: 1100 | FW24: 1100 | FX24: 1100 | FY24: 1100 | FZ24: 1100 | GA24: 1100 | GB24: 1100 | GC24: 1100 | GD24: 1100 | GE24: 1100 | GF24: 1100 | GG24: 1100 | GH24: 1100 | GI24: 1100 | GJ24: 1100 | GK24: 1100 | GL24: 1100 | GM24: 1100 | GN24: 1100 | GO24: 1100 | GP24: 1100 | GQ24: 1100 | GR24: 1100 | GS24: 1100 | GT24: 1100 | GU24: 1100 | GV24: 1100 | GW24: 1100 | GX24: 1100 | GY24: 1100 | GZ24: 1100 | HA24: 1100
BZ25: Unilever | EA25: 1445 | EB25: 1445 | EC25: 1445 | ED25: 1445 | EE25: 1445 | EF25: 1445 | EG25: 1445 | EH25: 1445 | EI25: 1445 | EJ25: 1445 | EK25: 1445 | EL25: 1445 | EM25: 1500 | EN25: 1500 | EO25: 1500 | EP25: 1500 | EQ25: 1500 | ER25: 1500 | ES25: 1500 | ET25: 1500 | EU25: 1500 | EV25: 1500 | EW25: 1500 | EX25: 1500 | EY25: 1500 | EZ25: 1500 | FA25: 1450 | FB25: 1450 | FC25: 1450 | FD25: 1450 | FE25: 1450 | FF25: 1450 | FG25: 1450 | FH25: 1450 | FI25: 1450 | FJ25: 1450 | FK25: 1450 | FL25: 1450 | FM25: 1350 | FN25: 1350 | FO25: 1350 | FP25: 1350 | FQ25: 1350 | FR25: 1350 | FS25: 1350 | FT25: 1350 | FU25: 1350 | FV25: 1350 | FW25: 1350 | FX25: 1350 | FY25: 1350 | FZ25: 1320 | GA25: 1320 | GB25: 1320 | GC25: 1320 | GD25: 1320 | GE25: 1320 | GF25: 1320 | GG25: 1320 | GH25: 1320 | GI25: 1320 | GJ25: 1320 | GK25: 1320 | GL25: 1320 | GM25: 1320 | GN25: 1320 | GO25: 1320 | GP25: 1320 | GQ25: 1320 | GR25: 1320 | GS25: 1320 | GT25: 1320 | GU25: 1320 | GV25: 1320 | GW25: 1320 | GX25: 1300 | GY25: 1300 | GZ25: 1300 | HA25: 1300 | HB25: 1300 | HC25: 1300 | HD25: 1300 | HE25: 1300 | HF25: 1300 | HG25: 1300 | HH25: 1300 | HI25: 1300 | HJ25: 1300 | HK25: 1300 | HL25: 1300 | HM25: 1300 | HN25: 1300 | HO25: 1300 | HP25: 1300 | HQ25: 1300 | HR25: 1300 | HS25: 1300 | HT25: 1300 | HU25: 1300 | HV25: 1300 | HW25: 1300 | HX25: 1300 | HY25: 1300 | HZ25: 1300 | IA25: 1300 | IB25: 1300 | IC25: 1300 | ID25: 1300 | IE25: 1300 | IF25: 1250 | IG25: 1250 | IH25: 1250 | II25: 1250 | IJ25: 1250 | IK25: 1250 | IL25: 1250 | IM25: 1250 | IN25: 1250 | IO25: 1250 | IP25: 1250 | IQ25: 1250 | IR25: 1250 | IS25: 1250 | IT25: 1250 | IU25: 1250 | IV25: 1250 | IW25: 1280 | IX25: 1280 | IY25: 1280 | IZ25: 1280 | JA25: 1280 | JB25: 1280 | JC25: 1280 | JD25: 1280 | JE25: 1280 | JF25: 1280 | JG25: 1280 | JH25: 1280 | JI25: 1280 | JJ25: 1280 | JK25: 1280 | JL25: 1280 | JM25: 1280 | JN25: 1280 | JO25: 1280 | JP25: 1280 | JQ25: 1280 | JR25: 1280 | JS25: 1280 | JT25: 1280 | JU25: 1280 | JV25: 1280 | JW25: 1250 | JX25: 1250 | JY25: 1250 | JZ25: 1250 | KA25: 1250

Sheet PET Fiber_tháng

Sheet PET Fiber_tuan 

Sheet Ma trận PET- Fiber
D3: MA TRẬN GIÁ BÁN rPET | F3: MA TRẬN GIÁ BÁN rPET | AP3: 2023 | BG3: 2024
F4: Tỷ giá | I4: 24000 | J4: 24000 | K4: 24000 | L4: 24000 | AP4: 24000 | AQ4: 24000 | AR4: 24000 | AS4: 24000 | AT4: 24000 | AU4: 24000 | AV4: 24000 | AW4: 24000 | AX4: 24000 | AY4: 24000 | AZ4: 24000 | BA4: 24000 | BB4: 24000 | BC4: 24000 | BD4: 24000 | BE4: 24000 | BF4: 24000 | BG4: 24000 | BH4: 24000 | BI4: 24000 | BJ4: 24000 | DE4: 2025 | FD4: 2026
A5: Stt | B5: Mã SAP | C5: Tên hàng hóa SAP | D5: Mã SP | E5: Tên sản phẩm | F5: Diễn giải | G5: Đơn vị tính | H5: Diễn giải | I5: 9 | J5: 10 | K5: 11 | L5: 12 | M5: T1.24 | N5: 2 | O5: 3 | P5: 4 | Q5: 5 | R5: 6 | S5: 7 | T5: 8 | U5: 9 | V5: 10 | W5: 11 | X5: 12 | Y5: T1.25 | Z5: 2 | AA5: 3 | AB5: 4 | AC5: 5 | AD5: 6 | AE5: 7 | AF5: 8 | AG5: 9 | AH5: 10 | AI5: 11 | AJ5: 12 | AK5: T1.26 | AM5: Mã SP | AN5: Tên sản phẩm | AO5: Diễn giải | AP5: 36 | AQ5: 37 | AR5: 38 | AS5: 39 | AT5: 40 | AU5: 41 | AV5: 42 | AW5: 43 | AX5: 44 | AY5: 45 | AZ5: 46 | BA5: 47 | BB5: 48 | BC5: 49 | BD5: 50 | BE5: 51 | BF5: 52 | BG5: 1/24 | BH5: 02 | BI5: 03 | BJ5: 04 | BK5: 05 | BL5: 08 | BM5: 09 | BN5: 10 | BO5: 11 | BP5: 12 | BQ5: 13 | BR5: 14 | BS5: 15 | BT5: 16 | BU5: 17 | BV5: 18 | BW5: 19 | BX5: 20 | BY5: 21 | BZ5: 22 | CA5: 23 | CB5: 24 | CC5: 25 | CD5: 26 | CE5: 27 | CF5: 28 | CG5: 29 | CH5: 30 | CI5: 31 | CJ5: 32 | CK5: 33 | CL5: 34 | CM5: 35 | CN5: 36 | CO5: 37 | CP5: 38 | CQ5: 39 | CR5: 40 | CS5: 41 | CT5: 42 | CU5: 43 | CV5: 44 | CW5: 45 | CX5: 46 | CY5: 47 | CZ5: 48 | DA5: 49 | DB5: 50 | DC5: 51 | DD5: 52 | DE5: 01 | DF5: 02 | DG5: 03 | DH5: 04 | DI5: 06 | DJ5: 07 | DK5: 08 | DL5: 09 | DM5: 10 | DN5: 11 | DO5: 12 | DP5: 13 | DQ5: 14 | DR5: 15 | DS5: 16 | DT5: 17 | DU5: 18 | DV5: 19 | DW5: 20 | DX5: 21 | DY5: 22 | DZ5: 23 | EA5: 24 | EB5: 25 | EC5: 26 | ED5: 27 | EE5: 28 | EF5: 29 | EG5: 30 | EH5: 31 | EI5: 32 | EJ5: 33 | EK5: 34 | EL5: 35 | EM5: 36 | EN5: 37 | EO5: 38 | EP5: 39 | EQ5: 40 | ER5: 41 | ES5: 42 | ET5: 43 | EU5: 44 | EV5: 45 | EW5: 46 | EX5: 47 | EY5: 48 | EZ5: 49 | FA5: 50 | FB5: 51 | FC5: 52 | FD5: 01 | FE5: 02 | FF5: 03 | FG5: 04 | FH5: 05
H6: DTR-Food grade | J6: ='Ma trận PET'!AU6 -> 1250 | K6: ='Ma trận PET'!AV6 -> 1250 | L6: ='Ma trận PET'!AW6 -> 1250 | M6: ='Ma trận PET'!AX6 -> 1250 | N6: ='Ma trận PET'!AY6 -> 1250 | O6: ='Ma trận PET'!AZ6 -> 1250 | P6: ='Ma trận PET'!BA6 -> 1250 | Q6: ='Ma trận PET'!BB6 -> 1300 | ... U6: ='Ma trận PET'!BF6 -> 1310 | V6: =U6+15 -> 1325 | W6: =V6 -> 1325 | X6: =W6-50 -> 1275 | Y6: =X6-45 -> 1230 | Z6: =Y6 -> 1230 | AA6: =Z6 -> 1230 | AB6: =AA6+20 -> 1250 | AC6: =AB6 -> 1250 | AD6: =AC6 -> 1250 | AE6: =AD6 -> 1250 | AF6: =AE6-20-10 -> 1220 | AG6: =AF6 -> 1220 | AH6: 1210 | AI6: 1200 | AJ6: 1200 | AK6: 1160 | AO6: DTR-Food grade | AP6: ='Ma trận PET'!FI6 -> 1250 | AQ6: ='Ma trận PET'!FJ6 -> 1250 | AR6: ='Ma trận PET'!FK6 -> 1250 | AS6: ='Ma trận PET'!FL6 -> 1250 | AT6: ='Ma trận PET'!FM6 -> 1250 | AU6: ='Ma trận PET'!FN6 -> 1250 | AV6: ='Ma trận PET'!FO6 -> 1250 | AW6: ='Ma trận PET'!FP6 -> 1250 | ... BK6: ='Ma trận PET'!GD6 -> 1250 | BL6: 1250 | BM6: 1250 | BN6: 1250 | BO6: 1250 | BP6: 1250 | BQ6: 1250 | BR6: 1250 | BS6: 1250 | BT6: 1250 | BU6: 1250 | BV6: 1300 | BW6: 1300 | BX6: 1300 | BY6: 1300 | BZ6: 1300 | CA6: 1300 | CB6: 1300 | CC6: 1300 | CD6: 1300 | CE6: 1300 | CF6: 1300 | CG6: 1300 | CH6: 1300 | CI6: 1300 | CJ6: 1300 | CK6: 1300 | CL6: 1300 | CM6: 1300 | CN6: 1310 | CO6: 1310 | CP6: 1310 | CQ6: 1310 | CR6: 1325 | CS6: 1325 | CT6: 1325 | CU6: 1325 | CV6: 1325 | CW6: 1325 | CX6: 1325 | CY6: 1325 | CZ6: 1325 | DA6: =1325-50 -> 1275 | DB6: =1325-50 -> 1275 | DC6: =1325-50 -> 1275 | DD6: =1325-50 -> 1275 | DE6: =1325-50-45 -> 1230 | DF6: =1325-50-45 -> 1230 | DG6: =1325-50-45 -> 1230 | DH6: =1325-50-45 -> 1230 | DI6: =1325-50-45 -> 1230 | DJ6: =1325-50-45 -> 1230 | DK6: =1325-50-45 -> 1230 | DL6: =1325-50-45 -> 1230 | ... DP6: =1325-50-45 -> 1230 | DQ6: =1325-50-45+20 -> 1250 | DR6: =1325-50-45+20 -> 1250 | DS6: =1325-50-45+20 -> 1250 | DT6: =1325-50-45+20 -> 1250 | DU6: =1325-50-45+20 -> 1250 | DV6: =1325-50-45+20 -> 1250 | DW6: =1325-50-45+20 -> 1250 | DX6: =1325-50-45+20 -> 1250 | ... EH6: =1325-50-45+20 -> 1250 | EI6: =1325-50-45+20-20-10 -> 1220 | EJ6: =1325-50-45+20-20-10 -> 1220 | EK6: =1325-50-45+20-20-10 -> 1220 | EL6: =1325-50-45+20-20-10 -> 1220 | EM6: =1325-50-45+20-20-10 -> 1220 | EN6: =1325-50-45+20-20-10 -> 1220 | EO6: =1325-50-45+20-20-10 -> 1220 | EP6: =1325-50-45+20-20-10 -> 1220 | EQ6: =1325-50-45+20-20-10-10 -> 1210 | ER6: =1325-50-45+20-20-10-10 -> 1210 | ES6: =1325-50-45+20-20-10-10 -> 1210 | ET6: =1325-50-45+20-20-10-10 -> 1210 | EU6: =1325-50-45+20-20-10-10 -> 1210 | EV6: =1325-50-45+20-20-10-10-10 -> 1200 | EW6: =1325-50-45+20-20-10-10-10 -> 1200 | EX6: =1325-50-45+20-20-10-10-10 -> 1200 | EY6: =1325-50-45+20-20-10-10-10 -> 1200 | EZ6: =1325-50-45+20-20-10-10-10 -> 1200 | FA6: =1325-50-45+20-20-10-10-10 -> 1200 | FB6: =1325-50-45+20-20-10-10-10 -> 1200 | FC6: =1325-50-45+20-20-10-10-10 -> 1200 | FD6: =1325-50-45+20-20-10-10-10-40 -> 1160 | FE6: =1325-50-45+20-20-10-10-10-40 -> 1160 | FF6: =1325-50-45+20-20-10-10-10-40 -> 1160 | FG6: =1325-50-45+20-20-10-10-10-40 -> 1160 | FH6: =1325-50-45+20-20-10-10-10-40 -> 1160
A7: 5 | B7: 110000329 | C7: Hạt rPET WSS01 | E7: WSS01 - Hạt rPET (IV 0.78) | F7: Giá DTR | G7: $ /tấn | H7: DTR | I7: 1050 | J7: 1050 | K7: 1050 | L7: 1050 | M7: 1050 | N7: 1050 | O7: 1050 | P7: 1050 | Q7: 1100 | R7: 1100 | S7: 1100 | T7: 1100 | U7: 1100 | V7: 1100 | W7: 1100 | X7: 1100 | Y7: 1100 | Z7: 1100 | AA7: 1100 | AB7: 1120 | AC7: 1120 | AD7: 1120 | AE7: =+AE6-130 -> 1120 | AF7: =+AF6-130 -> 1090 | AG7: =+AG6-130 -> 1090 | AH7: =+AH6-130 -> 1080 | AI7: =+AI6-130 -> 1070 | AJ7: =+AJ6-130 -> 1070 | AK7: =+AK6-130 -> 1030 | AN7: WSS01 - Hạt rPET (IV 0.78) | AO7: DTR | AP7: 1050 | AQ7: 1050 | AR7: 1050 | AS7: 1050 | AT7: 1050 | AU7: 1050 | AV7: 1050 | AW7: 1050 | AX7: 1050 | AY7: 1050 | AZ7: 1050 | BA7: 1050 | BB7: 1050 | BC7: 1050 | BD7: 1050 | BE7: 1050 | BF7: 1050 | BG7: 1050 | BH7: 1050 | BI7: 1050 | BJ7: 1050 | BK7: 1050 | BL7: 1050 | BM7: 1050 | BN7: 1050 | BO7: 1050 | BP7: 1050 | BQ7: 1050 | BR7: 1050 | BS7: 1050 | BT7: 1050 | BU7: 1050 | BV7: 1100 | BW7: 1100 | BX7: 1100 | BY7: 1100 | BZ7: 1100 | CA7: 1100 | CB7: 1100 | CC7: 1100 | CD7: 1100 | CE7: 1100 | CF7: 1100 | CG7: 1100 | CH7: 1100 | CI7: 1100 | CJ7: 1100 | CK7: 1100 | CL7: 1100 | CM7: 1100 | CN7: 1100 | CO7: 1100 | CP7: 1100 | CQ7: 1100 | CR7: 1100 | CS7: 1100 | CT7: 1100 | CU7: 1100 | CV7: 1100 | CW7: 1100 | CX7: 1100 | CY7: 1100 | CZ7: 1100 | DA7: 1100 | DB7: 1100 | DC7: 1100 | DD7: 1100 | DE7: 1100 | DF7: 1100 | DG7: 1100 | DH7: 1100 | DI7: 1100 | DJ7: 1100 | DK7: 1100 | DL7: 1100 | DM7: 1100 | DN7: 1100 | DO7: 1100 | DP7: 1100 | DQ7: 1120 | DR7: 1120 | DS7: 1120 | DT7: 1120 | DU7: 1120 | DV7: 1120 | DW7: 1120 | DX7: 1120 | DY7: 1120 | DZ7: 1120 | EA7: 1120 | EB7: 1120 | EC7: 1120 | ED7: 1120 | EE7: 1120 | EF7: 1120 | EG7: 1120 | EH7: 1120 | EI7: =+EI6-130 -> 1090 | EJ7: =+EJ6-130 -> 1090 | EK7: =+EK6-130 -> 1090 | EL7: =+EL6-130 -> 1090 | EM7: =+EM6-130 -> 1090 | EN7: =+EN6-130 -> 1090 | EO7: =+EO6-130 -> 1090 | EP7: =+EP6-130 -> 1090 | ... FH7: =+FH6-130 -> 1030
A8: 9 | D8: ICIS | E8: ICIS giá rPET ($ /tấn) | F8: ICIS FOB ĐNA - Giá trung bình | G8: $ /tấn | H8: ICIS | I8: =SUM(AP8:AS8)/COUNT(AP8:AS8) -> 802.75 | J8: =SUM(AT8:AW8)/COUNT(AT8:AW8) -> 801 | K8: =SUM(AX8:BA8)/COUNT(AX8:BA8) -> 821.5 | L8: =SUM(BB8:BE8)/COUNT(BB8:BE8) -> 821.5 | M8: =SUM(BG8:BJ8)/COUNT(BG8:BJ8) -> 804.25 | N8: =SUM(BK8:BM8)/COUNT(BK8:BM8) -> 787 | O8: =SUM(BN8:BQ8)/COUNT(BN8:BQ8) -> 815.875 | P8: =SUM(BR8:BU8)/COUNT(BR8:BU8) -> 831.875 | Q8: =SUM(BV8:BZ8)/COUNT(BV8:BZ8) -> 894.5 | R8: =SUM(CA8:CD8)/COUNT(CA8:CD8) -> 978.5 | S8: =SUM(CE8:CH8)/COUNT(CE8:CH8) -> 978.5 | T8: =SUM(CI8:CM8)/COUNT(CI8:CM8) -> 980.5 | U8: =SUM(CN8:CQ8)/COUNT(CN8:CQ8) -> 996 | V8: =SUM(CR8:CU8)/COUNT(CR8:CU8) -> 1018.5 | W8: =SUM(CV8:CZ8)/COUNT(CV8:CZ8) -> 999.7 | X8: =SUM(DA8:DD8)/COUNT(DA8:DD8) -> 956.5 | Y8: =SUM(DE8:DH8)/COUNT(DE8:DH8) -> 911.5 | Z8: =SUM(DI8:DL8)/COUNT(DI8:DL8) -> 911.5 | AA8: =SUM(DM8:DP8)/COUNT(DM8:DP8) -> 919.25 | AB8: =SUM(DQ8:DT8)/COUNT(DQ8:DT8) -> 933.125 | AC8: =SUM(DU8:DY8)/COUNT(DU8:DY8) -> 944.7 | AD8: =SUM(DZ8:EC8)/COUNT(DZ8:EC8) -> 954.5 | AE8: =SUM(ED8:EH8)/COUNT(ED8:EH8) -> 918 | AF8: =SUM(EI8:EL8)/COUNT(EI8:EL8) -> 868.375 | AG8: =SUM(EM8:EP8)/COUNT(EM8:EP8) -> 803.5 | AH8: =SUM(EQ8:EU8)/COUNT(EQ8:EU8) -> 794.125 | AI8: =SUM(EV8:EY8)/COUNT(EV8:EY8) -> #DIV/0! | AJ8: =SUM(EW8:EZ8)/COUNT(EW8:EZ8) -> #DIV/0! | AK8: =SUM(EX8:FA8)/COUNT(EX8:FA8) -> #DIV/0! | AM8: ICIS | AN8: ICIS giá rPET ($ /tấn) | AO8: ICIS | AP8: 802.5 | AQ8: 802.5 | AR8: 802.5 | AS8: 803.5 | AT8: 801 | AU8: 801 | AV8: 801 | AW8: 801 | AX8: 821.5 | AY8: 821.5 | AZ8: 821.5 | BA8: 821.5 | BB8: 821.5 | BC8: 821.5 | BD8: 821.5 | BE8: 821.5 | BF8: 821.5 | BG8: 821.5 | BH8: 821.5 | BI8: 787 | BJ8: 787 | BK8: 787 | BL8: 787 | BM8: 787 | BN8: 788.5 | BO8: 825 | BP8: 825 | BQ8: 825 | BR8: 825 | BS8: 825 | BT8: 825 | BU8: 852.5 | BV8: 873.5 | BW8: 873.5 | BX8: 873.5 | BY8: 873.5 | BZ8: 978.5 | CA8: 978.5 | CB8: 978.5 | CC8: 978.5 | CD8: 978.5 | CE8: 978.5 | CF8: 978.5 | CG8: 978.5 | CH8: 978.5 | CI8: 978.5 | CJ8: 978.5 | CK8: 978.5 | CL8: 978.5 | CM8: 988.5 | CN8: 988.5 | CO8: 988.5 | CP8: 988.5 | CQ8: 1018.5 | CR8: 1018.5 | CS8: 1018.5 | CT8: 1018.5 | CU8: 1018.5 | CV8: 1018.5 | CW8: 1018.5 | CX8: 1018.5 | CY8: 971.5 | CZ8: 971.5 | DA8: 971.5 | DB8: 971.5 | DC8: 971.5 | DD8: 911.5 | DE8: 911.5 | DF8: 911.5 | DG8: 911.5 | DH8: 911.5 | DI8: 911.5 | DJ8: 911.5 | DK8: 911.5 | DL8: 911.5 | DM8: 911.5 | DN8: 911.5 | DO8: 911.5 | DP8: 942.5 | DQ8: 942.5 | DR8: 930 | DS8: 930 | DT8: 930 | DU8: 930 | DV8: 930 | DW8: 954.5 | DX8: 954.5 | DY8: 954.5 | DZ8: 954.5 | EA8: 954.5 | EB8: 954.5 | EC8: 954.5 | ED8: 954.5 | EE8: 954.5 | EF8: 910 | EG8: 885.5 | EH8: 885.5 | EI8: 875.5 | EJ8: 875.5 | EK8: 875.5 | EL8: 847 | EM8: 807 | EN8: 807 | EO8: 800 | EP8: 800 | EQ8: 800 | ER8: 800 | ES8: 800 | ET8: 776.5
D9: Anh 12 | F9: RESIN | G9: $ /tấn | H9: RESIN | I9: =SUM(AP9:AS9)/COUNT(AP9:AS9) -> 935 | J9: =SUM(AT9:AW9)/COUNT(AT9:AW9) -> 922.5 | K9: =SUM(AX9:AZ9)/COUNT(AX9:AZ9) -> 900 | L9: =SUM(BB9:BE9)/COUNT(BB9:BE9) -> 900 | M9: =SUM(BG9:BJ9)/COUNT(BG9:BJ9) -> 930 | N9: =SUM(BK9:BM9)/COUNT(BK9:BM9) -> 943.33333 | O9: =SUM(BN9:BQ9)/COUNT(BN9:BQ9) -> 940 | P9: =SUM(BR9:BU9)/COUNT(BR9:BU9) -> 940 | Q9: =SUM(BV9:BZ9)/COUNT(BV9:BZ9) -> 942 | R9: =SUM(CA9:CD9)/COUNT(CA9:CD9) -> 950 | S9: =SUM(CE9:CH9)/COUNT(CE9:CH9) -> 947.5 | T9: =SUM(CI9:CM9)/COUNT(CI9:CM9) -> 930 | U9: =SUM(CN9:CQ9)/COUNT(CN9:CQ9) -> 880 | V9: =SUM(CR9:CU9)/COUNT(CR9:CU9) -> 860 | W9: =SUM(CV9:CZ9)/COUNT(CV9:CZ9) -> 852 | X9: =SUM(DA9:DD9)/COUNT(DA9:DD9) -> 830 | Y9: =SUM(DE9:DH9)/COUNT(DE9:DH9) -> 827.5 | Z9: =SUM(DI9:DL9)/COUNT(DI9:DL9) -> 840 | AA9: =SUM(DM9:DP9)/COUNT(DM9:DP9) -> 822.5 | AB9: =SUM(DQ9:DT9)/COUNT(DQ9:DT9) -> 765 | AC9: =SUM(DU9:DY9)/COUNT(DU9:DY9) -> 782 | AD9: =SUM(DZ9:EC9)/COUNT(DZ9:EC9) -> 807.5 | AE9: =SUM(ED9:EH9)/COUNT(ED9:EH9) -> 802 | AF9: =SUM(EI9:EL9)/COUNT(EI9:EL9) -> 795 | AG9: =SUM(EM9:EP9)/COUNT(EM9:EP9) -> 782.5 | AH9: =SUM(EQ9:EU9)/COUNT(EQ9:EU9) -> 772 | AI9: =SUM(EV9:EY9)/COUNT(EV9:EY9) -> 770 | AJ9: =SUM(EZ9:FC9)/COUNT(EZ9:FC9) -> 772.5 | AK9: 795 | AM9: Anh 12 | AO9: RESIN | AP9: 930 | AQ9: 930 | AR9: 940 | AS9: 940 | AT9: 940 | AU9: 930 | AV9: 920 | AW9: 900 | AX9: 900 | AY9: 900 | AZ9: 900 | BA9: 900 | BB9: 900 | BC9: 900 | BD9: 900 | BE9: 900 | BF9: 900 | BG9: 900 | BH9: 940 | BI9: 940 | BJ9: 940 | BK9: 950 | BL9: 940 | BM9: 940 | BN9: 940 | BO9: 940 | BP9: 940 | BQ9: 940 | BR9: 940 | BS9: 940 | BT9: 940 | BU9: 940 | BV9: 940 | BW9: 940 | BX9: 940 | BY9: 940 | BZ9: 950 | CA9: 950 | CB9: 950 | CC9: 950 | CD9: 950 | CE9: 950 | CF9: 950 | CG9: 950 | CH9: 940 | CI9: 940 | CJ9: 940 | CK9: 940 | CL9: 930 | CM9: 900 | CN9: 900 | CO9: 890 | CP9: 870 | CQ9: 860 | CR9: 860 | CS9: 860 | CT9: 860 | CU9: 860 | CV9: 860 | CW9: 860 | CX9: 860 | CY9: 840 | CZ9: 840 | DA9: 840 | DB9: 830 | DC9: 830 | DD9: 820 | DE9: 820 | DF9: 820 | DG9: 820 | DH9: 850 | DI9: 840 | DJ9: 840 | DK9: 840 | DL9: 840 | DM9: 840 | DN9: 830 | DO9: 810 | DP9: 810 | DQ9: 800 | DR9: 750 | DS9: 750 | DT9: 760 | DU9: 760 | DV9: 760 | DW9: 800 | DX9: 800 | DY9: 790 | DZ9: 800 | EA9: 790 | EB9: 820 | EC9: 820 | ED9: 820 | EE9: 820 | EF9: 790 | EG9: 790 | EH9: 790 | EI9: 800 | EJ9: 790 | EK9: 790 | EL9: 800 | EM9: 790 | EN9: 780 | EO9: 780 | EP9: 780 | EQ9: 780 | ER9: 780 | ES9: 770 | ET9: 760 | EU9: 770 | EV9: 770 | EW9: 770 | EX9: 770 | EY9: 770 | EZ9: 770 | FA9: 770 | FB9: 770 | FC9: 780 | FD9: 795
H10: TTCP | I10: =I9 -> 935 | J10: =J9 -> 922.5 | K10: =K9 -> 900 | L10: =L9 -> 900 | M10: =M9 -> 930 | N10: =N9 -> 943.33333 | O10: =O9 -> 940 | P10: =P9 -> 940 | ... AK10: =AK9 -> 795 | AO10: TTCP | AP10: =AP9 -> 930 | AQ10: =AQ9 -> 930 | AR10: =AR9 -> 940 | AS10: =AS9 -> 940 | AT10: =AT9 -> 940 | AU10: =AU9 -> 930 | AV10: =AV9 -> 920 | AW10: =AW9 -> 900 | ... FH10: =FH9 -> 0
H11: CL | I11: =#REF!-I10 -> #REF! | J11: =J7-J9 -> 127.5 | K11: =K7-K9 -> 150 | L11: =L7-L9 -> 150 | M11: =M7-M9 -> 120 | N11: =N7-N9 -> 106.66667 | O11: =O7-O9 -> 110 | P11: =P7-P9 -> 110 | Q11: =Q7-Q9 -> 158 | ... AK11: =AK7-AK9 -> 235 | AO11: CL | AP11: =AP7-AP9 -> 120 | AQ11: =AQ7-AQ9 -> 120 | AR11: =AR7-AR9 -> 110 | AS11: =AS7-AS9 -> 110 | AT11: =AT7-AT9 -> 110 | AU11: =AU7-AU9 -> 120 | AV11: =AV7-AV9 -> 130 | AW11: =AW7-AW9 -> 150 | ... FH11: =FH7-FH9 -> 1030
H12: % | I12: =I11/I10 -> #REF! | J12: =J11/J10 -> 0.13821138 | K12: =K11/K10 -> 0.16666667 | L12: =L11/L10 -> 0.16666667 | M12: =M11/M10 -> 0.12903226 | N12: =N11/N10 -> 0.1130742 | O12: =O11/O10 -> 0.11702128 | P12: =P11/P10 -> 0.11702128 | ... AK12: =AK11/AK10 -> 0.29559748 | AO12: % | AP12: =+AP11/AP10 -> 0.12903226 | AQ12: =+AQ11/AQ10 -> 0.12903226 | AR12: =+AR11/AR10 -> 0.11702128 | AS12: =+AS11/AS10 -> 0.11702128 | AT12: =+AT11/AT10 -> 0.11702128 | AU12: =+AU11/AU10 -> 0.12903226 | AV12: =+AV11/AV10 -> 0.14130435 | AW12: =+AW11/AW10 -> 0.16666667 | ... FH12: =+FH11/FH10 -> #DIV/0!
