Workbook

Sheet theo anh Hoang
A1: Doanh thu theo từng loại chai
A2: Thành phẩm | B2: Năm 2023 | C2: Năm 2024 | D2: Năm 2025 | E2: Năm 2026
A3: Chai PET B1 | B3: =58896385050/1000000000 -> 58.896385 | C3: =45896670200/1000000000 -> 45.89667 | D3: =63630724917/1000000000 -> 63.630725 | E3: =56760000000/1000000000 -> 56.76
A4: Chai PET B2.2 | B4: =5760087865/1000000000 -> 5.7600879 | C4: =8502651000/1000000000 -> 8.502651 | D4: =9343579281/1000000000 -> 9.3435793 | E4: =10962000000/1000000000 -> 10.962
A5: Chai PET B4 | B5: =862376983/1000000000 -> 0.86237698 | C5: =1121063000/1000000000 -> 1.121063 | D5: =1722617331/1000000000 -> 1.7226173 | E5: =1440000000/1000000000 -> 1.44
A6: Chai PET B5 | B6: =1654320500/1000000000 -> 1.6543205 | C6: =1690342600/1000000000 -> 1.6903426 | D6: =2267014358/1000000000 -> 2.2670144 | E6: =1920000000/1000000000 -> 1.92
A7: Chai PET B6.2 | B7: =9041825897/1000000000 -> 9.0418259 | C7: =14790109500/1000000000 -> 14.790109 | D7: =23937332576/1000000000 -> 23.937333 | E7: =25920000000/1000000000 -> 25.92
A8: Cổ Chai PET | E8: =648000000/1000000000 -> 0.648
A9: Nắp HD ép các màu | B9: =2700668974/1000000000 -> 2.700669 | C9: =2522267785/1000000000 -> 2.5222678 | D9: =1462403060/1000000000 -> 1.4624031 | E9: =1944000000/1000000000 -> 1.944
A22: Sản lượng theo từng loại chai
A23: Thành phẩm | B23: Năm 2023 | C23: Năm 2024 | D23: Năm 2025 | E23: Năm 2026
A24: Chai PET B1 | B24: =3652358.5/1000 -> 3652.3585 | C24: =2688190/1000 -> 2688.19 | D24: =(3712198+17000)/1000 -> 3729.198 | E24: =3784000/1000 -> 3784
A25: Chai PET B2.2 | B25: =565953/1000 -> 565.953 | C25: =635827/1000 -> 635.827 | D25: =579402/1000 -> 579.402 | E25: =812000/1000 -> 812
A26: Chai PET B4 | B26: =86157/1000 -> 86.157 | C26: =85204/1000 -> 85.204 | D26: =107868/1000 -> 107.868 | E26: =120000/1000 -> 120
A27: Chai PET B5 | B27: =151214/1000 -> 151.214 | C27: =127968/1000 -> 127.968 | D27: =142369/1000 -> 142.369 | E27: =160000/1000 -> 160
A28: Chai PET B6.2 | B28: =981342/1000 -> 981.342 | C28: =1162969/1000 -> 1162.969 | D28: =1468557/1000 -> 1468.557 | E28: =1920000/1000 -> 1920
A29: Cổ Chai PET | E29: =80000/1000 -> 80
A30: Nắp HD ép các màu | B30: =215746/1000 -> 215.746 | C30: =194860.4/1000 -> 194.8604 | D30: =131456/1000 -> 131.456 | E30: =240000/1000 -> 240
A44: Doanh thu bình quân đầu người/ năm
A45: Danh mục nhân sự | B45: Năm 2023 | C45: Năm 2024 | D45: Năm 2025 | E45: Năm 2026
A46: Công ty | B46: =SUM(B3:B9)/56 -> 1.4092083 | C46: =SUM(C3:C9)/49 -> 1.5208797 | D46: =SUM(D3:D9)/53 -> 1.93139 | E46: =SUM(E3:E9)/54 -> 1.8443333
A63: Sản lượng bình quân đầu người/ năm
A64: Danh mục nhân sự | B64: Năm 2023 | C64: Năm 2024 | D64: Năm 2025 | E64: Năm 2026
A65: Công ty | B65: =SUM(B24:B30)/56 -> 100.94233 | C65: =SUM(C24:C30)/49 -> 99.898335 | D65: =SUM(D24:D30)/53 -> 116.20472 | E65: =SUM(E24:E30)/55 -> 129.38182

Sheet kt tu lam
A1: Doanh thu theo từng nhóm
A2: Nhóm sản phẩm | B2: Năm 2023 | C2: Năm 2024 | D2: Năm 2025 | E2: Năm 2026
A3: Nhóm PET | B3: =SUM('theo anh Hoang'!B3:B9) -> 78.915665 | C3: =SUM('theo anh Hoang'!C3:C9) -> 74.523104 | D3: =SUM('theo anh Hoang'!D3:D9) -> 102.36367 | E3: =SUM('theo anh Hoang'!E3:E9) -> 99.594
A22: Sản lượng theo từng nhóm
A23: Thành phẩm | B23: Năm 2023 | C23: Năm 2024 | D23: Năm 2025 | E23: Năm 2026
A24: Nhóm PET | B24: =SUM('theo anh Hoang'!B24:B30) -> 5652.7705 | C24: =SUM('theo anh Hoang'!C24:C30) -> 4895.0184 | D24: =SUM('theo anh Hoang'!D24:D30) -> 6158.85 | E24: =SUM('theo anh Hoang'!E24:E30) -> 7116
A44: Doanh thu bình quân đầu người/ năm
A45: Danh mục nhân sự | B45: Năm 2023 | C45: Năm 2024 | D45: Năm 2025 | E45: Năm 2026
A46: Công ty | B46: =SUM(B3:B9)/56 -> 1.4092083 | C46: =SUM(C3:C9)/49 -> 1.5208797 | D46: =SUM(D3:D9)/53 -> 1.93139 | E46: =SUM(E3:E9)/54 -> 1.8443333
A63: Sản lượng bình quân đầu người/ năm
A64: Danh mục nhân sự | B64: Năm 2023 | C64: Năm 2024 | D64: Năm 2025 | E64: Năm 2026
A65: Công ty | B65: =SUM(B24:B30)/56 -> 100.94233 | C65: =SUM(C24:C30)/49 -> 99.898335 | D65: =SUM(D24:D30)/53 -> 116.20472 | E65: =SUM(E24:E30)/54 -> 131.77778
A81: Doanh thu- Ebitda- LNST
A82: Danh mục | B82: Năm 2023 | C82: Năm 2024 | D82: Năm 2025 | E82: Năm 2026
A83: Doanh thu | B83: =B3 -> 78.915665 | C83: =C3 -> 74.523104 | D83: =D3 -> 102.36367 | E83: =E3 -> 99.594
A84: EBITDA | B84: =612830166/1000000000 -> 0.61283017 | C84: =-889112824/1000000000 -> -0.88911282 | D84: =6256778116/1000000000 -> 6.2567781 | E84: =3163000000/1000000000 -> 3.163
A85: LNST | B85: =-423578104/1000000000 -> -0.4235781 | C85: =-2284911122/1000000000 -> -2.2849111 | D85: =4197280868/1000000000 -> 4.1972809 | E85: =1802000000/1000000000 -> 1.802
A86: %EBITDA | B86: =B84/B83 -> 0.0077656339 | C86: =C84/C83 -> -0.0119307 | D86: =D84/D83 -> 0.061123033 | E86: =E84/E83 -> 0.031758941
A87: %LNST | B87: =B85/B83 -> -0.0053674781 | C87: =C85/C83 -> -0.030660439 | D87: =D85/D83 -> 0.041003618 | E87: =E85/E83 -> 0.018093459
A100: Doanh thu hòa vốn bình quân hàng tháng
A101: Danh mục | B101: Năm 2023 | C101: Năm 2024 | D101: Năm 2025 | E101: Năm 2026
A102: Doanh thu bình quân hàng tháng hòa vốn | B102: =(89627979381.8616/1000000000)/12 -> 7.4689983 | C102: =(120891154072.022/1000000000)/12 -> 10.074263 | D102: =(72125000000/1000000000)/12 -> 6.0104167 | E102: =(85061000000/1000000000)/12 -> 7.0884167
A103: Doanh thu bình quân hàng tháng thực hiện | B103: =(78915665269/1000000000)/12 -> 6.5763054 | C103: =(74523104085/1000000000)/12 -> 6.2102587 | D103: =(102263015418/1000000000)/12 -> 8.521918 | E103: =(99594000000/1000000000)/12 -> 8.2995
A116: Sản lượng thành phẩm hòa vốn bình quân hàng tháng
A117: Danh mục | B117: Năm 2023 | C117: Năm 2024 | D117: Năm 2025 | E117: Năm 2026
A118: Sản lượng thành phẩm bình quân hòa vốn (tháng) | B118: =6420099.17926167/1000/12 -> 535.00826 | C118: =7940684.04484096/1000/12 -> 661.72367 | D118: =5005000/1000/12 -> 417.08333 | E118: =6951072.2890632/1000/12 -> 579.25602
A119: Sản lượng thành phẩm bình quân thực hiện (tháng) | B119: =5652739/1000/12 -> 471.06158 | C119: =4894558/1000/12 -> 407.87983 | D119: =6159980/1000/12 -> 513.33167 | E119: =7116000/1000/12 -> 593
A134: Sản lượng NVL hòa vốn bình quân hàng tháng
A135: Danh mục | B135: Năm 2023 | C135: Năm 2024 | D135: Năm 2025 | E135: Năm 2026
A136: Sản lượng NVL bình quân hòa vốn (tháng) | B136: =6834600.3868238/1000/12 -> 569.55003 | C136: =8662919.11386164/1000/12 -> 721.90993 | D136: =6085582.79776948/1000/12 -> 507.1319 | E136: =7719165.77700468/1000/12 -> 643.26381
A137: Sản lượng NVL bình quân thực hiện (tháng) | B137: =5228509.8/1000/12 -> 435.70915 | C137: =5012893.7/1000/12 -> 417.74114 | D137: =6661533/1000/12 -> 555.12775 | E137: =8000000/1000/12 -> 666.66667
A147: 1000000000
A148: Định phí chi tiết từng chi phí
A149: Danh mục | B149: Năm 2023 | C149: Năm 2024 | D149: Năm 2025 | E149: Năm 2026
A150: CPSXC - Lương | B150: =320091240.5/A147 -> 0.32009124 | C150: =222231447/A147 -> 0.22223145 | D150: =1005626325/A147 -> 1.0056263 | E150: =2067000000/A147 -> 2.067
A151: CPSXC - Khác | B151: =1774066555/A147 -> 1.7740666 | C151: =2162965329/A147 -> 2.1629653 | D151: =3169468120.46972/A147 -> 3.1694681 | E151: =2886000000/A147 -> 2.886
A152: CPSXC - Khấu hao | B152: =1036408270/A147 -> 1.0364083 | C152: =1382050356/A147 -> 1.3820504 | D152: =2081537892/A147 -> 2.0815379 | E152: =1297000000/A147 -> 1.297
A153: CPQL - Lương | B153: =1191465336/A147 -> 1.1914653 | C153: =1437283377/A147 -> 1.4372834 | D153: =3207755890.78887/A147 -> 3.2077559 | E153: =3321000000/A147 -> 3.321
A154: CPQL - Khác | B154: =222951436/A147 -> 0.22295144 | C154: =585003451/A147 -> 0.58500345 | D154: =593457043/A147 -> 0.59345704 | E154: =726967216.426381/A147 -> 0.72696722
A155: CPQL - Khấu hao | C155: =13747942/A147 -> 0.013747942 | D155: =89858022.7272727/A147 -> 0.089858023 | E155: =64000000/A147 -> 0.064
...

Sheet Sheet1
A1: STT | B1: Tên khoản mục phí | C1: Chi phí | G1: Tăng giảm năm 2026 so với năm 2025
C2: Năm 2023 | D2: Năm 2024 | E2: Năm 2025 | F2: Năm 2026 | G2: Số tiền | H2: %
A4: 1 | B4: Chi Phí Công Tác | C4: 0 | D4: 10550000 | E4: 5900000 | F4: 6300000 | G4: =F4-E4 -> 400000 | H4: =G4/E4 -> 0.06779661
A5: 2 | B5: Chi Phí Đào Tạo | C5: 0 | D5: 0 | E5: 23650000 | F5: 20100000 | G5: =F5-E5 -> -3550000 | H5: =G5/E5 -> -0.15010571
A6: 3 | B6: Chi phí xăng dầu, nước, điện quản lý | C6: 6976562 | D6: 8473005 | E6: 10904569 | F6: 11253651 | G6: =F6-E6 -> 349082.15 | H6: =G6/E6 -> 0.032012467
A7: 4 | B7: Chi phí sửa chữa, bảo trì | C7: 561901641 | D7: 449578674 | E7: 1.0881455e+09 | F7: 1.4889435e+09 | G7: =F7-E7 -> 4.00798e+08 | H7: =G7/E7 -> 0.36833125
A8: 5 | B8: Công cụ dụng cụ | C8: 170666630 | D8: 134877650 | E8: 238330592 | F8: 3.0571565e+08 | G8: =F8-E8 -> 67385060 | H8: =G8/E8 -> 0.28273777
A9: 6 | B9: Chi phí in ấn, vật tư, VPP | C9: 22406346 | D9: 27191462 | E9: 65794076 | F9: 66000000 | G9: =F9-E9 -> 205924 | H9: =G9/E9 -> 0.0031298259
A10: 7 | B10: Chi phí kiểm định, mua mẫu | C10: 0 | D10: 0 | E10: 6600000 | F10: 19500000 | G10: =F10-E10 -> 12900000 | H10: =G10/E10 -> 1.9545455
A11: 8 | B11: Chi phí thuê nhà, văn phòng, Xưởng, kho, | C11: 1118310000 | D11: 1557000000 | E11: 1800000000 | F11: 1800000000 | G11: =F11-E11 -> 0 | H11: =G11/E11 -> 0
A12: 9 | B12: Chi phí internet, điện thoại, bưu phẩm | C12: 7127167 | D12: 10161366 | E12: 25174117 | F12: 34170991 | G12: =F12-E12 -> 8996874.2 | H12: =G12/E12 -> 0.35738589
A13: 10 | B13: Chi phí công chứng, sao y, thuế khác | C13: 3000000 | D13: 3000000 | E13: 3000000 | F13: 3000000 | G13: =F13-E13 -> 0 | H13: =G13/E13 -> 0
A14: 11 | B14: Chi phí bảo hiểm | C14: 18498603 | D14: 14672614 | E14: 15367540 | F14: 19028011 | G14: =F14-E14 -> 3660471.5 | H14: =G14/E14 -> 0.23819503
A15: 12 | B15: Chi phí dịch vụ, tư vấn | C15: 4645479 | D15: 370448392 | E15: 245925815 | F15: 247350371 | G15: =F15-E15 -> 1424556 | H15: =G15/E15 -> 0.0057926249
... A22: 19 | B22: Chi phí khác | C22: 41247379 | D22: 55808788 | E22: 124496297 | F22: 1.2526233e+08 | G22: =F22-E22 -> 766033.8 | H22: =G22/E22 -> 0.0061530649
B23: Tổng cộng
I24: 1000000
A25: STT | B25: Tên khoản mục phí | C25: Chi phí | G25: Tăng giảm năm 2026 so với năm 2025
C26: Năm 2023 | D26: Năm 2024 | E26: Năm 2025 | F26: Năm 2026 | G26: Số tiền | H26: % | I26: Đvt: Triệu vnđ
A27: 1 | B27: Chi phí thuê nhà, văn phòng, Xưởng, kho, | C27: =C11/$I$24 -> 1118.31 | D27: =D11/$I$24 -> 1557 | E27: =E11/$I$24 -> 1800 | F27: =F11/$I$24 -> 1800 | G27: =F27-E27 -> 0 | H27: =G27/E27 -> 0
A28: 2 | B28: Chi phí sửa chữa, bảo trì | C28: =C7/$I$24 -> 561.90164 | D28: =D7/$I$24 -> 449.57867 | E28: =E7/$I$24 -> 1088.1455 | F28: =F7/$I$24 -> 1488.9435 | G28: =F28-E28 -> 400.798 | H28: =G28/E28 -> 0.36833125
A29: 3 | B29: Công cụ dụng cụ | C29: =C8/$I$24 -> 170.66663 | D29: =D8/$I$24 -> 134.87765 | E29: =E8/$I$24 -> 238.33059 | F29: =F8/$I$24 -> 305.71565 | G29: =F29-E29 -> 67.38506 | H29: =G29/E29 -> 0.28273777
A30: 4 | B30: Chi phí dịch vụ, tư vấn | C30: =C15/$I$24 -> 4.645479 | D30: =D15/$I$24 -> 370.44839 | E30: =E15/$I$24 -> 245.92582 | F30: =F15/$I$24 -> 247.35037 | G30: =F30-E30 -> 1.424556 | H30: =G30/E30 -> 0.0057926249
A31: 5 | B31: Chi phí khác | C31: =C22/$I$24 -> 41.247379 | D31: =D22/$I$24 -> 55.808788 | E31: =E22/$I$24 -> 124.4963 | F31: =F22/$I$24 -> 125.26233 | G31: =F31-E31 -> 0.7660338 | H31: =G31/E31 -> 0.0061530649
A32: 6 | B32: Chi phí in ấn, vật tư, VPP | C32: =C9/$I$24 -> 22.406346 | D32: =D9/$I$24 -> 27.191462 | E32: =E9/$I$24 -> 65.794076 | F32: =F9/$I$24 -> 66 | G32: =F32-E32 -> 0.205924 | H32: =G32/E32 -> 0.0031298259
A33: 7 | B33: Dự Phòng nợ khó đòi | C33: =C19/$I$24 -> 0 | D33: =D19/$I$24 -> 0 | E33: =E19/$I$24 -> 0 | F33: =F19/$I$24 -> 77.807693 | G33: =F33-E33 -> 77.807693 | H33: 1
A34: 8 | B34: Chi phí bảo trì IT | C34: =C20/$I$24 -> 33.097524 | D34: =D20/$I$24 -> 56.004545 | E34: =E20/$I$24 -> 24.366593 | F34: =F20/$I$24 -> 57.064944 | G34: =F34-E34 -> 32.698351 | H34: =G34/E34 -> 1.3419336
A35: 9 | B35: Chi phí internet, điện thoại, bưu phẩm | C35: =C12/$I$24 -> 7.127167 | D35: =D12/$I$24 -> 10.161366 | E35: =E12/$I$24 -> 25.174117 | F35: =F12/$I$24 -> 34.170991 | G35: =F35-E35 -> 8.9968742 | H35: =G35/E35 -> 0.35738589
A36: 10 | B36: Chi phí dịch vụ môi trường | C36: =C21/$I$24 -> 0 | D36: =D21/$I$24 -> 0 | E36: =E21/$I$24 -> 43.2 | F36: =F21/$I$24 -> 31.78 | G36: =F36-E36 -> -11.42 | H36: =G36/E36 -> -0.26435185
A37: 11 | B37: Chi phí tiếp khách | C37: =C17/$I$24 -> 3.5 | D37: =D17/$I$24 -> 43.1 | E37: =E17/$I$24 -> 34.569998 | F37: =F17/$I$24 -> 32 | G37: =F37-E37 -> -2.569998 | H37: =G37/E37 -> -0.074341861
A38: 12 | B38: Chi Phí Đào Tạo | C38: =C5/$I$24 -> 0 | D38: =D5/$I$24 -> 0 | E38: =E5/$I$24 -> 23.65 | F38: =F5/$I$24 -> 20.1 | G38: =F38-E38 -> -3.55 | H38: =G38/E38 -> -0.15010571
A39: 13 | B39: Chi phí kiểm định, mua mẫu | C39: =C10/$I$24 -> 0 | D39: =D10/$I$24 -> 0 | E39: =E10/$I$24 -> 6.6 | F39: =F10/$I$24 -> 19.5 | G39: =F39-E39 -> 12.9 | H39: =G39/E39 -> 1.9545455
A40: 14 | B40: Chi phí bảo hiểm | C40: =C14/$I$24 -> 18.498603 | D40: =D14/$I$24 -> 14.672614 | E40: =E14/$I$24 -> 15.367539 | F40: =F14/$I$24 -> 19.028011 | G40: =F40-E40 -> 3.6604715 | H40: =G40/E40 -> 0.23819503
A41: 15 | B41: Chi phí xăng dầu, nước, điện quản lý | C41: =C6/$I$24 -> 6.976562 | D41: =D6/$I$24 -> 8.473005 | E41: =E6/$I$24 -> 10.904569 | F41: =F6/$I$24 -> 11.253651 | G41: =F41-E41 -> 0.34908215 | H41: =G41/E41 -> 0.032012467
A42: 16 | B42: Chi Phí Công Tác | C42: =C4/$I$24 -> 0 | D42: =D4/$I$24 -> 10.55 | E42: =E4/$I$24 -> 5.9 | F42: =F4/$I$24 -> 6.3 | G42: =F42-E42 -> 0.4 | H42: =G42/E42 -> 0.06779661
A43: 17 | B43: Chi phí ngân hàng | C43: =C18/$I$24 -> 3.092931 | D43: =D18/$I$24 -> 3.833195 | E43: =E18/$I$24 -> 3.793691 | F43: =F18/$I$24 -> 5.46 | G43: =F43-E43 -> 1.666309 | H43: =G43/E43 -> 0.43923161
A44: 18 | B44: Chi phí công chứng, sao y, thuế khác | C44: =C13/$I$24 -> 3 | D44: =D13/$I$24 -> 3 | E44: =E13/$I$24 -> 3 | F44: =F13/$I$24 -> 3 | G44: =F44-E44 -> 0 | H44: =G44/E44 -> 0
A45: 19 | B45: Chi phí ủng hộ, hỗ trợ, tài trợ | C45: =C16/$I$24 -> 1.5 | D45: =D16/$I$24 -> 0 | E45: =E16/$I$24 -> 2 | F45: =F16/$I$24 -> 0 | G45: =F45-E45 -> -2 | H45: =G45/E45 -> -1
B46: Tổng cộng | C46: =SUM(C27:C45) -> 1995.9703 | D46: =SUM(D27:D45) -> 2744.6997 | E46: =SUM(E27:E45) -> 3761.2188 | F46: =SUM(F27:F45) -> 4350.7371 | G46: =SUM(G27:G45) -> 589.51835 | H46: =G46/E46 -> 0.15673599
A49: STT | B49: Tên phòng ban | C49: Số lượng nhân sự (headcount) | G49: Tăng giảm năm 2026 so với năm 2025
...

Sheet Sheet2
A1: Chỉ tiêu | B1: Đvt | C1: Năm 2023 | D1: Năm 2024 | E1: Năm 2025 | F1: Năm 2026 | G1: Tăng/giảm | J1: Các chỉ tiêu | K1: Năm 2023 | L1: Năm 2024 | M1: Năm 2025 | N1: Năm 2026 | P1: Các chỉ tiêu | Q1: Năm 2023 | R1: Năm 2024 | S1: Năm 2025 | T1: Năm 2026 | V1: STT | W1: Các chỉ số tài chính | X1: Đvt | Y1: Năm 2023 | Z1: Năm 2024 | AA1: Năm 2025 | AB1: Năm 2026 | AD1: STT | AE1: Các chỉ tiêu | AF1: Đvt | AG1: Năm 2023 | AH1: Năm 2024 | AI1: Năm 2025 | AJ1: Năm 2026 | AK1: Tăng/Giảm
A2: Sản lượng bán | B2: Tấn | C2: =5652770.5/1000 -> 5652.7705 | D2: =4895018.4/1000 -> 4895.0184 | E2: =6159980/1000 -> 6159.98 | F2: =7116000/1000 -> 7116 | G2: =F2-E2 -> 956.02 | H2: =G2/E2 -> 0.15519856 | J2: TÀI SẢN NGẮN HẠN | K2: =SUM(K3:K6) -> 1.1226207e+10 | L2: =SUM(L3:L6) -> 1.1878997e+10 | M2: =SUM(M3:M6) -> 1.522929e+10 | N2: =SUM(N3:N6) -> 1.6795377e+10 | P2: Lợi nhuận sau thuế | Q2: -423578104 | R2: -2284911122 | S2: 9.7069113e+08 | T2: 2.9797899e+08 | V2: 1 | W2: Khả năng thanh toán hiện hành | X2: Lần | Y2: 3.4038597 | Z2: 1.6670929 | AA2: 1.5437926 | AB2: 1.7731481 | AD2: 1 | AE2: Sản lượng bán | AF2: Tấn | AG2: =C2 -> 5652.7705 | AH2: =D2 -> 4895.0184 | AI2: =E2 -> 6159.98 | AJ2: =F2 -> 7116 | AK2: =G2 -> 956.02 | AL2: =H2 -> 0.15519856
A3: Doanh thu thuần | B3: Tỷ vnđ | C3: 78915665269 | D3: 74523104085 | E3: 102263015418 | F3: 99594000000 | G3: =F3-E3 -> -2669015418 | H3: =G3/E3 -> -0.026099518 | J3: Tiền mặt & tương đương tiền | K3: 2116625281 | L3: 6003863340 | M3: 2740054809 | N3: =4267622366.77954+3456789000 -> 7.7244114e+09 | P3: Khấu hao | Q3: 1036408270 | R3: 1395798298 | S3: 1.9983578e+09 | T3: 1.1038002e+09 | V3: 2 | W3: Khả năng thanh toán nhanh | X3: Lần | Y3: 2.0078037 | Z3: 1.4449992 | AA3: 1.2740721 | AB3: 1.3401653 | AD3: 2 | AE3: Doanh thu thuần | AF3: Triệu vnđ | AG3: =C24 -> 78915.665 | AH3: =D24 -> 74523.104 | AI3: =E24 -> 102263.02 | AJ3: =F24 -> 99594 | AK3: =G24 -> -2669.0154 | AL3: =H24 -> -0.026099518
A4: Chi phí vận chuyển | B4: Tỷ vnđ | C4: 1458505034 | D4: 1294051828 | E4: 1386300000 | F4: 1.3862338e+09 | G4: =F4-E4 -> -66233.766 | H4: =G4/E4 -> -4.7777369e-05 | J4: Các khoản phải thu ngắn hạn | K4: 3904917434 | L4: 1638974810 | M4: 8273620186 | N4: 2.4042569e+09 | P4: Vốn lưu động thuần | Q4: =SUM(Q5:Q10) -> 7.6209757e+08 | R4: =SUM(R5:R10) -> 7061942551 | S4: =SUM(S5:S10) -> -6.7346014e+08 | T4: =SUM(T5:T10) -> -1.6892832e+09 | V4: 3 | W4: Nợ vay / EBITDA | X4: Lần | Y4: 0 | Z4: 0 | AA4: 0 | AB4: 0 | AD4: 3 | AE4: Lãi biến phí | AF4: Triệu vnđ | AG4: =C27 -> 5267.8094 | AH4: =D27 -> 6047.5174 | AI4: =E27 -> 20299.479 | AJ4: =F27 -> 18207.766 | AK4: =G27 -> -2091.7126 | AL4: =H27 -> -0.10304268
A5: Biến phí hàng bán | B5: Tỷ vnđ | C5: =73234417604-760053715-285013031 -> 72189350858 | D5: =69651631026-2470096185 -> 67181534841 | E5: 80577236536 | F5: 80000000000 | G5: =F5-E5 -> -577236536 | H5: =G5/E5 -> -0.0071637669 | J5: Hàng tồn kho | K5: 4.6043066e+09 | L5: 1.5825455e+09 | M5: 2.7401084e+09 | N5: =3012895143.03881+1000200000 -> 4.0130951e+09 | P5: Tăng (giảm) các khoản phải thu | Q5: -286669116 | R5: 2369966381 | S5: -4.6650888e+08 | T5: -2.7600334e+08 | V5: 4 | W5: Chi phí lãi vay / EBITDA | X5: % | Y5: 0 | Z5: 0 | AA5: 0 | AB5: 0 | AE5: Lãi biến phí / Tấn | AF5: Triệu đồng/Tấn | AG5: =AG4/AG2 -> 0.93189868 | AH5: =AH4/AH2 -> 1.2354432 | AI5: =AI4/AI2 -> 3.2953806 | AJ5: =AJ4/AJ2 -> 2.558708 | AK5: =AJ5-AI5 -> -0.73667263 | AL5: =AK5/AI5 -> -0.22354705
A6: Lãi biến phí | B6: Tỷ vnđ | C6: =C3-C4-C5 -> 5267809377 | D6: =D3-D4-D5 -> 6047517416 | E6: =E3-E4-E5 -> 20299478882 | F6: =F3-F4-F5 -> 1.8207766e+10 | G6: =F6-E6 -> -2.0917126e+09 | H6: =G6/E6 -> -0.10304268 | J6: Tài sản ngắn hạn khác | K6: 600357978 | L6: 2653613452 | M6: 1475506166 | N6: 2653613452 | P6: Tăng (giảm) hàng tồn kho | Q6: -2.0896683e+09 | R6: 3.0217611e+09 | S6: -3.9060982e+08 | T6: -1.0397398e+09 | V6: 5 | W6: Nợ vay / Doanh thu | X6: % | Y6: 0 | Z6: 0 | AA6: 0 | AB6: 0 | AE6: Lãi biến phí / Doanh thu (%) | AG6: =C7 -> 0.066752391 | AH6: =D7 -> 0.081149564 | AI6: =E7 -> 0.19850264 | AJ6: =F7 -> 0.18281991
A7: % Lãi biến phí / Doanh thu | C7: =C6/C3 -> 0.066752391 | D7: =D6/D3 -> 0.081149564 | E7: =E6/E3 -> 0.19850264 | F7: =F6/F3 -> 0.18281991 | J7: TÀI SẢN DÀI HẠN | K7: =SUM(K8:K10) -> 5030307875 | L7: =SUM(L8:L10) -> 5920101245 | M7: 7145209425 | N7: =SUM(N8:N10) -> 7.3807522e+09 | P7: Tăng (giảm) các khoản phải trả | Q7: 947342800 | R7: 235864858 | S7: 1.8997795e+08 | T7: -3.5708963e+08 | V7: 6 | W7: Nợ vay / Vốn chủ sở hữu | X7: Lần | Y7: 0 | Z7: 0 | AA7: 0 | AB7: 0 | AD7: 4 | AE7: Đầu tư | AF7: Triệu vnđ | AG7: =1186489000/1000000 -> 1186.489 | AH7: =2225328414/1000000 -> 2225.3284 | AI7: =3744325672/1000000 -> 3744.3257 | AK7: =AJ7-AI7 -> -3744.3257 | AL7: =AK7/AI7 -> -1
A8: Chi phí sản xuất | B8: Tỷ vnđ | C8: 3.6247735e+09 | D8: 4829197048 | E8: =7197593137+3012676807 -> 10210269944 | F8: 10816000000 | G8: =F8-E8 -> 605730056 | H8: =G8/E8 -> 0.059325567 | J8: Tài sản cố định | K8: 4820029021 | L8: 5649559137 | M8: 5818128147 | N8: =6291726870.92703+218960190+599523033 -> 7.1102101e+09 | P8: Tăng (giảm) trả trước người bán | Q8: 2265189997 | R8: -19023757 | S8: -6319385.6 | T8: -16450446 | V8: 7 | W8: Tổng nợ / Tổng tài sản | X8: Lần | Y8: =K36/K35 -> 0.20287753 | Z8: =L36/L35 -> 0.40033353 | AA8: =M36/M35 -> 0.37107299 | AB8: =N36/N35 -> 0.28782376 | AE8: % Đầu tư / Doanh thu | AG8: =AG7/AG3 -> 0.015034898 | AH8: =AH7/AH3 -> 0.02986092 | AI8: =AI7/AI3 -> 0.036614661 | AJ8: =AJ7/AJ3 -> 0
A9: % Chi phí SX / Doanh thu | C9: =C8/C3 -> 0.045932243 | D9: =D8/D3 -> 0.064801341 | E9: =E8/E3 -> 0.099843232 | F9: =F8/F3 -> 0.10860092 | J9: Chi phí dở dang dài hạn | P9: Các khoản phải thu khác | Q9: 77386213 | R9: -2138255474 | S9: 0 | T9: 0 | V9: 8 | W9: LNST / Vốn chủ sở hữu (ROE) | X9: % | Y9: =C40/K45 -> -0.050670248 | Z9: =D40/L45 -> -0.15662412 | AA9: =E40/M45 -> 0.28034196 | AB9: =F40/N45 -> 0.12010867 | AD9: 5 | AE9: Chi phí hoạt động (ngoại trừ lương) | AF9: Triệu vnđ | AG9: =Sheet1!C46 -> 1995.9703 | AH9: =Sheet1!D46 -> 2744.6997 | AI9: =Sheet1!E46 -> 3761.2188 | AJ9: =Sheet1!F46 -> 4350.7371 | AK9: =AJ9-AI9 -> 589.51835 | AL9: =AK9/AI9 -> 0.15673599
A10: Chi phí bán hàng | B10: Tỷ vnđ | C10: 0 | D10: 0 | E10: 0 | F10: 0 | G10: 0 | J10: Tài sản dài hạn khác | K10: 210278854 | L10: 270542108 | M10: 396258186 | N10: 270542108 | P10: Các khoản phải trả khác | Q10: -1.5148401e+08 | R10: 3.5916295e+09 | S10: 0 | T10: 0 | V10: 9 | W10: LNST / Tài sản (ROA) | X10: % | Y10: =C40/K35 -> -0.046753791 | Z10: =D40/L35 -> -0.13199331 | AA10: =E40/M35 -> 0.19610115 | AB10: =F40/N35 -> 0.074521031 | AE10: % Chi phí hoạt động / Doanh thu | AG10: =AG9/AG3 -> 0.025292447 | AH10: =AH9/AH3 -> 0.036830185 | AI10: =AI9/AI3 -> 0.036779854 | AJ10: =AJ9/AJ3 -> 0.043684731
A11: % Chi phí bán hàng / Doanh thu | C11: 0 | D11: 0 | E11: 0 | F11: 0 | G11: 0 | H11: 0 | J11: TỔNG TÀI SẢN | K11: =K2+K7 -> 1.6256515e+10 | L11: =L2+L7 -> 1.7799098e+10 | M11: =M2+M7 -> 2.2374499e+10 | N11: =N2+N7 -> 2.4176129e+10 | P11: Dòng tiền thuần từ hoạt động kinh doanh | Q11: =Q2+Q3+Q4 -> 1.3749277e+09 | R11: =R2+R3+R4 -> 6172829727 | S11: =S2+S3+S4 -> 2.2955888e+09 | T11: =T2+T3+T4 -> -2.8750407e+08 | V11: 10 | W11: Tỷ suất EBITDA | X11: % | Y11: =C35/C24 -> 0.0036051845 | Z11: =D35/D24 -> -0.011765007 | AA11: =E35/E24 -> 0.061183196 | AB11: =F35/F24 -> 0.031115611 | AD11: 6 | AE11: Chi phí nhân sự | AF11: Triệu vnđ | AG11: =Sheet1!C84 -> 7231.8426 | AH11: =Sheet1!D84 -> 6263.1073 | AI11: =Sheet1!E84 -> 9283.4298 | AJ11: =Sheet1!F84 -> 10311.525 | AK11: =AJ11-AI11 -> 1028.0953 | AL11: =AK11/AI11 -> 0.1107452
A12: Chi phí quản lý | B12: Tỷ vnđ | C12: 1.3781674e+09 | D12: 2036034770 | E12: 4197280868 | F12: 4.2928381e+09 | G12: =F12-E12 -> 95557215 | H12: =G12/E12 -> 0.022766457 | J12: NỢ PHẢI TRẢ | K12: =K13+K17 -> 3.2980816e+09 | L12: =L13+L17 -> 7.125576e+09 | M12: =M13+M17 -> 7957168842 | N12: =N13+N17 -> 7957168842 | P12: Tiền chi mua sắm TSCĐ | Q12: -1121281000 | R12: -2225328414 | S12: -3744325672 | V12: 11 | W12: Tỷ suất lợi nhuận gộp | X12: % | Y12: 0.011039653 | Z12: -0.0025472087 | AA12: 0.046784536 | AB12: 0.052034323 | AE12: Chi phí nhân sự / Doanh thu (%) | AG12: =AG11/AG3 -> 0.09164014 | AH12: =AH11/AH3 -> 0.084042492 | AI12: =AI11/AI3 -> 0.090779934 | AJ12: =AJ11/AJ3 -> 0.1035356
A13: % Chi phí quản lý / Doanh thu | C13: =C12/C3 -> 0.017463801 | D13: =D12/D3 -> 0.027320853 | E13: =E12/E3 -> 0.041043977 | F13: =F12/F3 -> 0.043103381 | J13: Nợ ngắn hạn | K13: =SUM(K14:K16) -> 3.2980816e+09 | L13: =SUM(L14:L16) -> 7.125576e+09 | M13: 7957168842 | N13: 7957168842 | V13: 12 | W13: Tỷ suất lợi nhuận sau thuế | X13: % | Y13: =C41 -> -0.0096312147 | Z13: =D41 -> -0.031525281 | AA13: =E41 -> 0.041120726 | AB13: =F41 -> 0.018089745 | AE13: Doanh thu bình quân đầu người | AF13: Triệu vnđ | AG13: =AG3/Sheet1!C60 -> 1409.2083 | AH13: =AH3/Sheet1!D60 -> 1520.8797 | AI13: =AI3/Sheet1!E60 -> 1929.4909 | AJ13: =AJ3/Sheet1!F60 -> 1844.3333 | AK13: =AJ13-AI13 -> -85.157524 | AL13: =AK13/AI13 -> -0.044134712
A14: EBITDA | B14: Tỷ vnđ | C14: =C19+C17+C16 -> 2.8450553e+08 | D14: =D19+D17+D16 -> -876764853 | E14: =E19+E17+E16 -> 6256778116 | F14: =F19+F17+F16 -> 3.0989282e+09 | G14: =F14-E14 -> -3.15785e+09 | H14: =G14/E14 -> -0.50470864 | J14: Phải trả thương mại | K14: 533825855 | L14: 769690713 | M14: 586652262 | N14: 6.0257903e+08 | P14: Đầu tư dài hạn khác | Q14: -93200080 | R14: -60263254 | V14: 13 | W14: Chi phí bán hàng & quản lý / Doanh thu | X14: % | Y14: =(C31+C33)/C24 -> 0.017463801 | Z14: =(D31+D33)/D24 -> 0.027320853 | AA14: =(E31+E33)/E24 -> 0.041043977 | AB14: =(F31+F33)/F24 -> 0.043103381 | AE14: Sản lượng bán bình quân đầu người | AF14: Tấn | AG14: =AG2/Sheet1!C60 -> 100.94233 | AH14: =AH2/Sheet1!D60 -> 99.898335 | AI14: =AI2/Sheet1!E60 -> 116.22604 | AJ14: =AJ2/Sheet1!F60 -> 131.77778 | AK14: =AJ14-AI14 -> 15.55174 | AL14: =AK14/AI14 -> 0.13380599
A15: % EBITDA / Doanh thu | C15: =C14/C3 -> 0.0036051845 | D15: =D14/D3 -> -0.011765007 | E15: =E14/E3 -> 0.061183196 | F15: =F14/F3 -> 0.031115611 | G15: =G14/G3 -> 1.1831516 | J15: Vay ngắn hạn | P15: Dòng tiền từ hoạt động đầu tư | Q15: =SUM(Q12:Q14) -> -1214481080 | R15: =SUM(R12:R14) -> -2285591668 | S15: =SUM(S12:S14) -> -3744325672 | T15: =SUM(T12:T14) -> 0 | V15: 14 | W15: Chi phí khấu hao / Doanh thu | X15: % | Y15: =C38/C24 -> 0.013236399 | Z15: =D38/D24 -> 0.019760274 | AA15: =E38/E24 -> 0.02006247 | AB15: =F38/F24 -> 0.013025866 | AD15: 7 | AE15: Chi phí sản xuất | AF15: Triệu vnđ | AG15: =C29 -> 3624.7735 | AH15: =D29 -> 4829.197 | AI15: =E29 -> 10210.27 | AJ15: =F29 -> 10816 | AK15: =AJ15-AI15 -> 605.73006 | AL15: =AK15/AI15 -> 0.059325567
A16: Chi phí tài chính | B16: Tỷ vnđ | C16: 0 | D16: 0 | E16: 0 | F16: 0 | G16: =F16-E16 -> 0 | H16: =IFERROR(G16/E16,0) -> 0 | J16: Nợ ngắn hạn khác | K16: 2.7642558e+09 | L16: 6.3558852e+09 | M16: 7370516580 | N16: 6.3558852e+09 | P16: Vay ngắn hạn ngân hàng | Q16: -2000000000 | V16: 15 | W16: Số ngày vốn lưu động | X16: Ngày | Y16: 11.31979 | Z16: 11.31979 | AA16: 11.123889 | AB16: 12.687794 | AE16: Chi phí sản xuất / Tấn | AF16: Triệu đồng/Tấn | AG16: =AG15/AG2 -> 0.6412384 | AH16: =AH15/AH2 -> 0.9865534 | AI16: =AI15/AI2 -> 1.6575167 | AJ16: =AJ15/AJ2 -> 1.519955 | AK16: =AJ16-AI16 -> -0.13756171 | AL16: =AK16/AI16 -> -0.082992649
A17: Chi phí khấu hao | B17: Tỷ vnđ | C17: 1.0445592e+09 | D17: 1472596978 | E17: 2051648676 | F17: 1.2972981e+09 | G17: =F17-E17 -> -7.5435058e+08 | H17: =G17/E17 -> -0.36768019 | J17: Nợ dài hạn | P17: Vay dài hạn ngân hàng | V17: 16 | W17: Ngày nợ phải thu bình quân (DSO) | X17: Ngày | Y17: 7.3385818 | Z17: 7.3385818 | AA17: 7.3385818 | AB17: 7 | AE17: Chi phí sản xuất / Doanh thu (%) | AG17: =AG15/AG3 -> 0.045932243 | AH17: =AH15/AH3 -> 0.064801341 | AI17: =AI15/AI3 -> 0.099843232 | AJ17: =AJ15/AJ3 -> 0.10860092
A18: Doanh thu/chi phí khác | B18: Tỷ vnđ | C18: 19637130 | D18: -59050451 | E18: 364850046 | G18: =F18-E18 -> -364850046 | H18: =G18/E18 -> -1 | J18: Vay dài hạn | P18: Cổ tức trả cho chủ sở hữu | V18: 17 | W18: Ngày nợ phải trả bình quân (DPO) | X18: Ngày | Y18: 3.7602208 | Z18: 3.7602208 | AA18: 3.7602208 | AB18: 4 | AD18: 8 | AE18: EBITDA | AF18: Triệu vnđ | AG18: =C35 -> 284.50553 | AH18: =D35 -> -876.76485 | AI18: =E35 -> 6256.7781 | AJ18: =F35 -> 3098.9282 | AK18: =AJ18-AI18 -> -3157.85 | AL18: =AK18/AI18 -> -0.50470864
A19: Lợi nhuận sau thuế | B19: Tỷ vnđ | C19: =C6-C8-C10-C12-C16-C17+C18 -> -7.6005371e+08 | D19: =D6-D8-D10-D12-D16-D17+D18 -> -2349361831 | E19: =E6-E8-E10-E12-E16-E17+E18 -> 4205129440 | F19: =F6-F8-F10-F12-F16-F17+F18 -> 1.8016301e+09 | G19: =F19-E19 -> -2.4034994e+09 | H19: =G19/E19 -> -0.57156371 | J19: Nợ dài hạn khác | P19: Chi cho vay hoặc thu hồi cho vay | V19: 18 | W19: Ngày tồn kho bình quân (DIO) | X19: Ngày | Y19: 7.7313139 | Z19: 7.7313139 | AA19: 7.7313139 | AB19: 10 | AE19: % EBITDA / Doanh thu | AG19: =AG18/AG3 -> 0.0036051845 | AH19: =AH18/AH3 -> -0.011765007 | AI19: =AI18/AI3 -> 0.061183196 | AJ19: =AJ18/AJ3 -> 0.031115611
A20: % LNST / Doanh thu | C20: =C19/C3 -> -0.0096312147 | D20: =D19/D3 -> -0.031525281 | E20: =E19/E3 -> 0.041120726 | F20: =F19/F3 -> 0.018089745 | G20: =G19/G3 -> 0.90051911 | J20: VỐN CHỦ SỠ HỮU | K20: =SUM(K21:K22) -> 12958433537 | L20: =SUM(L21:L22) -> 10673522415 | M20: =SUM(M21:M22) -> 14417330139 | N20: =SUM(N21:N22) -> 16218960190 | P20: Dòng tiền từ hoạt động tài chính | Q20: =SUM(Q16:Q19) -> -2000000000 | R20: =SUM(R16:R19) -> 0 | S20: =SUM(S16:S19) -> 0 | T20: =SUM(T16:T19) -> 0 | V20: 19 | W20: Doanh thu / TSCĐ | X20: Lần | Y20: =C24/K32 -> 16.372446 | Z20: =D24/L32 -> 13.190959 | AA20: =E24/M32 -> 17.576618 | AB20: =F24/N32 -> 14.007181 | AD20: 9 | AE20: Chi phí khấu hao | AF20: Triệu vnđ | AG20: =C38 -> 1044.5592 | AH20: =D38 -> 1472.597 | AI20: =E38 -> 2051.6487 | AJ20: =F38 -> 1297.2981 | AK20: =AJ20-AI20 -> -754.35058 | AL20: =AK20/AI20 -> -0.36768019
I21: 1000000 | J21: Vốn đầu tư của chủ sở hữu | K21: 15000000000 | L21: 15000000000 | M21: 15000000000 | N21: 15000000000 | P21: Tiền tồn đầu năm | Q21: 3956178628 | R21: 2.1166253e+09 | S21: 6003863340 | T21: 4.5551264e+09 | V21: 20 | W21: Doanh thu / Tổng tài sản | X21: Lần | Y21: =C24/K35 -> 4.8544023 | Z21: =D24/L35 -> 4.1869033 | AA21: =E24/M35 -> 4.7689126 | AB21: =F24/N35 -> 4.1195181 | AE21: % Chi phí khấu hao / Doanh thu | AG21: =AG20/AG3 -> 0.013236399 | AH21: =AH20/AH3 -> 0.019760274 | AI21: =AI20/AI3 -> 0.02006247 | AJ21: =AJ20/AJ3 -> 0.013025866
A22: Chỉ tiêu | B22: Đvt | C22: Năm 2023 | D22: Năm 2024 | E22: Năm 2025 | F22: Năm 2026 | G22: Tăng/giảm | I22: Đvt: Tỷ vnđ | J22: Lợi nhuận sau thuế | K22: -2041566463 | L22: -4326477585 | M22: -582669861 | N22: 1218960190 | R22: =R11+R15+R20+R21 -> 6003863340 | S22: =S11+S15+S20+S21 -> 4.5551264e+09 | T22: =T11+T15+T20+T21 -> 4.2676224e+09 | AD22: 10 | AE22: Lợi nhuận sau thuế | AF22: Triệu vnđ | AG22: =C40 -> -760.05371 | AH22: =D40 -> -2349.3618 | AI22: =E40 -> 4205.1294 | AJ22: =F40 -> 1801.6301 | AK22: =AJ22-AI22 -> -2403.4994 | AL22: =AK22/AI22 -> -0.57156371
A23: Sản lượng bán | B23: Tấn | C23: =5652770.5/1000 -> 5652.7705 | D23: =4895018.4/1000 -> 4895.0184 | E23: =6159980/1000 -> 6159.98 | F23: =7116000/1000 -> 7116 | G23: =F23-E23 -> 956.02 | H23: =G23/E23 -> 0.15519856 | J23: TỔNG NGUỒN VỐN | K23: =K12+K20 -> 1.6256515e+10 | L23: =L12+L20 -> 1.7799098e+10 | M23: =M12+M20 -> 22374498981 | N23: =N12+N20 -> 24176129032 | AE23: % Lợi nhuận sau thuế / Doanh thu | AG23: =AG22/AG3 -> -0.0096312147 | AH23: =AH22/AH3 -> -0.031525281 | AI23: =AI22/AI3 -> 0.041120726 | AJ23: =AJ22/AJ3 -> 0.018089745 | AK23: =AK22/AK3 -> 0.90051911
A24: Doanh thu thuần | B24: Triệu vnđ | C24: =C3/$I$21 -> 78915.665 | D24: =D3/$I$21 -> 74523.104 | E24: =E3/$I$21 -> 102263.02 | F24: =F3/$I$21 -> 99594 | G24: =G3/$I$21 -> -2669.0154 | H24: =G24/E24 -> -0.026099518 | N24: =N23-N11 -> -0.20481873 | O24: 1000000 | P24: Các chỉ tiêu | Q24: Năm 2023 | R24: Năm 2024 | S24: Năm 2025 | T24: Năm 2026 | U24: 1000000
A25: Chi phí vận chuyển | B25: Triệu vnđ | C25: =C4/$I$21 -> 1458.505 | D25: =D4/$I$21 -> 1294.0518 | E25: =E4/$I$21 -> 1386.3 | F25: =F4/$I$21 -> 1386.2338 | G25: =G4/$I$21 -> -0.066233766 | H25: =G25/E25 -> -4.7777369e-05 | J25: Các chỉ tiêu | K25: Năm 2023 | L25: Năm 2024 | M25: Năm 2025 | N25: Năm 2026 | P25: Lợi nhuận sau thuế | Q25: =Q2/$U$24 -> -423.5781 | R25: =R2/$U$24 -> -2284.9111 | S25: =S2/$U$24 -> 970.69113 | T25: =T2/$U$24 -> 297.97899
A26: Biến phí hàng bán | B26: Triệu vnđ | C26: =C5/$I$21 -> 72189.351 | D26: =D5/$I$21 -> 67181.535 | E26: =E5/$I$21 -> 80577.237 | F26: =F5/$I$21 -> 80000 | G26: =G5/$I$21 -> -577.23654 | H26: =G26/E26 -> -0.0071637669 | J26: TÀI SẢN NGẮN HẠN | K26: =SUM(K27:K30) -> 11226.207 | L26: =SUM(L27:L30) -> 11878.997 | M26: =SUM(M27:M30) -> 15229.29 | N26: =SUM(N27:N30) -> 16795.377 | P26: Khấu hao | Q26: =Q3/$U$24 -> 1036.4083 | R26: =R3/$U$24 -> 1395.7983 | S26: =S3/$U$24 -> 1998.3578 | T26: =T3/$U$24 -> 1103.8002
A27: Lãi biến phí | B27: Triệu vnđ | C27: =C24-C25-C26 -> 5267.8094 | D27: =D24-D25-D26 -> 6047.5174 | E27: =E24-E25-E26 -> 20299.479 | F27: =F24-F25-F26 -> 18207.766 | G27: =F27-E27 -> -2091.7126 | H27: =G27/E27 -> -0.10304268 | J27: Tiền mặt & tương đương tiền | K27: =K3/$O$24 -> 2116.6253 | L27: =L3/$O$24 -> 6003.8633 | M27: =M3/$O$24 -> 2740.0548 | N27: =N3/$O$24 -> 7724.4114 | P27: Vốn lưu động thuần | Q27: =Q4/$U$24 -> 762.09757 | R27: =R4/$U$24 -> 7061.9426 | S27: =S4/$U$24 -> -673.46014 | T27: =T4/$U$24 -> -1689.2832
A28: % Lãi biến phí / Doanh thu | C28: =C27/C24 -> 0.066752391 | D28: =D27/D24 -> 0.081149564 | E28: =E27/E24 -> 0.19850264 | F28: =F27/F24 -> 0.18281991 | J28: Các khoản phải thu ngắn hạn | K28: =K4/$O$24 -> 3904.9174 | L28: =L4/$O$24 -> 1638.9748 | M28: =M4/$O$24 -> 8273.6202 | N28: =N4/$O$24 -> 2404.2569 | P28: Tăng (giảm) các khoản phải thu | Q28: =Q5/$U$24 -> -286.66912 | R28: =R5/$U$24 -> 2369.9664 | S28: =S5/$U$24 -> -466.50888 | T28: =T5/$U$24 -> -276.00334
A29: Chi phí sản xuất | B29: Triệu vnđ | C29: =C8/$I$21 -> 3624.7735 | D29: =D8/$I$21 -> 4829.197 | E29: =E8/$I$21 -> 10210.27 | F29: =F8/$I$21 -> 10816 | G29: =G8/$I$21 -> 605.73006 | H29: =G29/E29 -> 0.059325567 | J29: Hàng tồn kho | K29: =K5/$O$24 -> 4604.3066 | L29: =L5/$O$24 -> 1582.5455 | M29: =M5/$O$24 -> 2740.1084 | N29: =N5/$O$24 -> 4013.0951 | P29: Tăng (giảm) hàng tồn kho | Q29: =Q6/$U$24 -> -2089.6683 | R29: =R6/$U$24 -> 3021.7611 | S29: =S6/$U$24 -> -390.60982 | T29: =T6/$U$24 -> -1039.7398
A30: % Chi phí SX / Doanh thu | C30: =C29/C24 -> 0.045932243 | D30: =D29/D24 -> 0.064801341 | E30: =E29/E24 -> 0.099843232 | F30: =F29/F24 -> 0.10860092 | G30: =G29/G24 -> -0.22694888 | J30: Tài sản ngắn hạn khác | K30: =K6/$O$24 -> 600.35798 | L30: =L6/$O$24 -> 2653.6135 | M30: =M6/$O$24 -> 1475.5062 | N30: =N6/$O$24 -> 2653.6135 | P30: Tăng (giảm) các khoản phải trả | Q30: =Q7/$U$24 -> 947.3428 | R30: =R7/$U$24 -> 235.86486 | S30: =S7/$U$24 -> 189.97795 | T30: =T7/$U$24 -> -357.08963
A31: Chi phí bán hàng | B31: Triệu vnđ | C31: 0 | D31: 0 | E31: 0 | F31: 0 | G31: 0 | J31: TÀI SẢN DÀI HẠN | K31: =SUM(K32:K34) -> 5030.3079 | L31: =SUM(L32:L34) -> 5920.1012 | M31: =SUM(M32:M34) -> 6214.3863 | N31: =SUM(N32:N34) -> 7380.7522 | P31: Tăng (giảm) trả trước người bán | Q31: =Q8/$U$24 -> 2265.19 | R31: =R8/$U$24 -> -19.023757 | S31: =S8/$U$24 -> -6.3193856 | T31: =T8/$U$24 -> -16.450446
A32: % Chi phí bán hàng / Doanh thu | C32: 0 | D32: 0 | E32: 0 | F32: 0 | G32: 0 | H32: 0 | J32: Tài sản cố định | K32: =K8/$O$24 -> 4820.029 | L32: =L8/$O$24 -> 5649.5591 | M32: =M8/$O$24 -> 5818.1281 | N32: =N8/$O$24 -> 7110.2101 | P32: Các khoản phải thu khác | Q32: =Q9/$U$24 -> 77.386213 | R32: =R9/$U$24 -> -2138.2555 | S32: =S9/$U$24 -> 0 | T32: =T9/$U$24 -> 0
A33: Chi phí quản lý | B33: Triệu vnđ | C33: =C12/$I$21 -> 1378.1674 | D33: =D12/$I$21 -> 2036.0348 | E33: =E12/$I$21 -> 4197.2809 | F33: =F12/$I$21 -> 4292.8381 | G33: =G12/$I$21 -> 95.557215 | H33: =G33/E33 -> 0.022766457 | J33: Chi phí dở dang dài hạn | K33: =K9/$O$24 -> 0 | L33: =L9/$O$24 -> 0 | M33: =M9/$O$24 -> 0 | N33: =N9/$O$24 -> 0 | P33: Các khoản phải trả khác | Q33: =Q10/$U$24 -> -151.48401 | R33: =R10/$U$24 -> 3591.6295 | S33: =S10/$U$24 -> 0 | T33: =T10/$U$24 -> 0
A34: % Chi phí quản lý / Doanh thu | C34: =C33/C24 -> 0.017463801 | D34: =D33/D24 -> 0.027320853 | E34: =E33/E24 -> 0.041043977 | F34: =F33/F24 -> 0.043103381 | G34: =G33/G24 -> -0.035802422 | J34: Tài sản dài hạn khác | K34: =K10/$O$24 -> 210.27885 | L34: =L10/$O$24 -> 270.54211 | M34: =M10/$O$24 -> 396.25819 | N34: =N10/$O$24 -> 270.54211 | P34: Dòng tiền thuần từ hoạt động kinh doanh | Q34: =Q11/$U$24 -> 1374.9277 | R34: =R11/$U$24 -> 6172.8297 | S34: =S11/$U$24 -> 2295.5888 | T34: =T11/$U$24 -> -287.50407
A35: EBITDA | B35: Triệu vnđ | C35: =C14/$I$21 -> 284.50553 | D35: =D14/$I$21 -> -876.76485 | E35: =E14/$I$21 -> 6256.7781 | F35: =F14/$I$21 -> 3098.9282 | G35: =G14/$I$21 -> -3157.85 | H35: =G35/E35 -> -0.50470864 | J35: TỔNG TÀI SẢN | K35: =K26+K31 -> 16256.515 | L35: =L26+L31 -> 17799.098 | M35: =M26+M31 -> 21443.676 | N35: =N26+N31 -> 24176.129 | P35: Tiền chi mua sắm TSCĐ | Q35: =Q12/$U$24 -> -1121.281 | R35: =R12/$U$24 -> -2225.3284 | S35: =S12/$U$24 -> -3744.3257 | T35: =T12/$U$24 -> 0
A36: % EBITDA / Doanh thu | C36: =C35/C24 -> 0.0036051845 | D36: =D35/D24 -> -0.011765007 | E36: =E35/E24 -> 0.061183196 | F36: =F35/F24 -> 0.031115611 | G36: =G35/G24 -> 1.1831516 | J36: NỢ PHẢI TRẢ | K36: =K37+K41 -> 3298.0816 | L36: =L37+L41 -> 7125.576 | M36: =M37+M41 -> 7957.1688 | N36: =N37+N41 -> 6958.4643 | P36: Đầu tư ngắn hạn khác | Q36: =Q13/$U$24 -> 0 | R36: =R13/$U$24 -> 0 | S36: =S13/$U$24 -> 0 | T36: =T13/$U$24 -> 0
A37: Chi phí tài chính | B37: Triệu vnđ | C37: 0 | D37: 0 | E37: 0 | F37: 0 | G37: =F37-E37 -> 0 | H37: =IFERROR(G37/E37,0) -> 0 | J37: Nợ ngắn hạn | K37: =SUM(K38:K40) -> 3298.0816 | L37: =SUM(L38:L40) -> 7125.576 | M37: =SUM(M38:M40) -> 7957.1688 | N37: =SUM(N38:N40) -> 6958.4643 | P37: Đầu tư dài hạn khác | Q37: =Q14/$U$24 -> -93.20008 | R37: =R14/$U$24 -> -60.263254 | S37: =S14/$U$24 -> 0 | T37: =T14/$U$24 -> 0
A38: Chi phí khấu hao | B38: Triệu vnđ | C38: =C17/$I$21 -> 1044.5592 | D38: =D17/$I$21 -> 1472.597 | E38: =E17/$I$21 -> 2051.6487 | F38: =F17/$I$21 -> 1297.2981 | G38: =G17/$I$21 -> -754.35058 | H38: =G38/E38 -> -0.36768019 | J38: Phải trả thương mại | K38: =K14/$O$24 -> 533.82586 | L38: =L14/$O$24 -> 769.69071 | M38: =M14/$O$24 -> 586.65226 | N38: =N14/$O$24 -> 602.57903 | P38: Dòng tiền từ hoạt động đầu tư | Q38: =Q15/$U$24 -> -1214.4811 | R38: =R15/$U$24 -> -2285.5917 | S38: =S15/$U$24 -> -3744.3257 | T38: =T15/$U$24 -> 0
A39: Doanh thu/chi phí khác | B39: Triệu vnđ | C39: =C18/$I$21 -> 19.63713 | D39: =D18/$I$21 -> -59.050451 | E39: =E18/$I$21 -> 364.85005 | F39: =F18/$I$21 -> 0 | G39: =G18/$I$21 -> -364.85005 | H39: =G39/E39 -> -1 | J39: Vay ngắn hạn | K39: =K15/$O$24 -> 0 | L39: =L15/$O$24 -> 0 | M39: =M15/$O$24 -> 0 | N39: =N15/$O$24 -> 0 | P39: Vay ngắn hạn ngân hàng | Q39: =Q16/$U$24 -> -2000 | R39: =R16/$U$24 -> 0 | S39: =S16/$U$24 -> 0 | T39: =T16/$U$24 -> 0
A40: Lợi nhuận sau thuế | B40: Triệu vnđ | C40: =C27-C29-C31-C33-C37-C38+C39 -> -760.05371 | D40: =D27-D29-D31-D33-D37-D38+D39 -> -2349.3618 | E40: =E27-E29-E31-E33-E37-E38+E39 -> 4205.1294 | F40: =F27-F29-F31-F33-F37-F38+F39 -> 1801.6301 | G40: =F40-E40 -> -2403.4994 | H40: =G40/E40 -> -0.57156371 | J40: Nợ ngắn hạn khác | K40: =K16/$O$24 -> 2764.2558 | L40: =L16/$O$24 -> 6355.8852 | M40: =M16/$O$24 -> 7370.5166 | N40: =N16/$O$24 -> 6355.8852 | P40: Vay dài hạn ngân hàng | Q40: =Q17/$U$24 -> 0 | R40: =R17/$U$24 -> 0 | S40: =S17/$U$24 -> 0 | T40: =T17/$U$24 -> 0
...

Sheet Sheet3
A1: Đvt: Triệu vnđ
