Workbook

Sheet >Slide

Sheet Slide 1
D1: (đã trừ cp hoa hồng) | E1: (đã trừ cp hoa hồng)
B2: Doanh thu hàng tháng | C2: Doanh thu LK | D2: LN hàng tháng | E2: LN LK | G2: Cp hoa hồng | H2: Cp hoa hồng LK
B3: tr.đ | C3: tr.đ | D3: tr.đ | E3: tr.đ | G3: tr.đ | H3: tr.đ
A4: 1 | B4: =SUMIFS('Điều chỉnh'!$G$10:$BE$10,'Điều chỉnh'!$G$1:$BE$1,'Slide 1'!$A4,'Điều chỉnh'!$G$4:$BE$4,"Sau đ/c") -> 0 | C4: =SUM(B$4:B4) -> 0 | D4: =SUMIFS('Điều chỉnh'!$G$15:$BE$15,'Điều chỉnh'!$G$1:$BE$1,'Slide 1'!$A4,'Điều chỉnh'!$G$4:$BE$4,"Sau đ/c") -> 0 | E4: =SUM(D$4:D4) -> 0 | G4: =SUMIFS('Điều chỉnh'!$G$14:$BE$14,'Điều chỉnh'!$G$1:$BE$1,'Slide 1'!$A4,'Điều chỉnh'!$G$4:$BE$4,"Sau đ/c") -> 0 | H4: =SUM(G$4:G4) -> 0
A5: 2 | B5: =SUMIFS('Điều chỉnh'!$G$10:$BE$10,'Điều chỉnh'!$G$1:$BE$1,'Slide 1'!$A5,'Điều chỉnh'!$G$4:$BE$4,"Sau đ/c") -> 7465.5 | C5: =SUM(B$4:B5) -> 7465.5 | D5: =SUMIFS('Điều chỉnh'!$G$15:$BE$15,'Điều chỉnh'!$G$1:$BE$1,'Slide 1'!$A5,'Điều chỉnh'!$G$4:$BE$4,"Sau đ/c") -> 810.58177 | E5: =SUM(D$4:D5) -> 810.58177 | G5: =SUMIFS('Điều chỉnh'!$G$14:$BE$14,'Điều chỉnh'!$G$1:$BE$1,'Slide 1'!$A5,'Điều chỉnh'!$G$4:$BE$4,"Sau đ/c") -> 553.55 | H5: =SUM(G$4:G5) -> 553.55 | J5: 0
A6: 3 | B6: =SUMIFS('Điều chỉnh'!$G$10:$BE$10,'Điều chỉnh'!$G$1:$BE$1,'Slide 1'!$A6,'Điều chỉnh'!$G$4:$BE$4,"Sau đ/c") -> 2755 | C6: =SUM(B$4:B6) -> 10220.5 | D6: =SUMIFS('Điều chỉnh'!$G$15:$BE$15,'Điều chỉnh'!$G$1:$BE$1,'Slide 1'!$A6,'Điều chỉnh'!$G$4:$BE$4,"Sau đ/c") -> 421.15388 | E6: =SUM(D$4:D6) -> 1231.7356 | G6: =SUMIFS('Điều chỉnh'!$G$14:$BE$14,'Điều chỉnh'!$G$1:$BE$1,'Slide 1'!$A6,'Điều chỉnh'!$G$4:$BE$4,"Sau đ/c") -> 205.5 | H6: =SUM(G$4:G6) -> 759.05 | J6: 0
A7: 4 | B7: =SUMIFS('Điều chỉnh'!$G$10:$BE$10,'Điều chỉnh'!$G$1:$BE$1,'Slide 1'!$A7,'Điều chỉnh'!$G$4:$BE$4,"Sau đ/c") -> 2242.5 | C7: =SUM(B$4:B7) -> 12463 | D7: =SUMIFS('Điều chỉnh'!$G$15:$BE$15,'Điều chỉnh'!$G$1:$BE$1,'Slide 1'!$A7,'Điều chỉnh'!$G$4:$BE$4,"Sau đ/c") -> 197.16733 | E7: =SUM(D$4:D7) -> 1428.903 | G7: =SUMIFS('Điều chỉnh'!$G$14:$BE$14,'Điều chỉnh'!$G$1:$BE$1,'Slide 1'!$A7,'Điều chỉnh'!$G$4:$BE$4,"Sau đ/c") -> 164.25 | H7: =SUM(G$4:G7) -> 923.3 | J7: 0
A8: 5 | B8: =SUMIFS('Điều chỉnh'!$G$10:$BE$10,'Điều chỉnh'!$G$1:$BE$1,'Slide 1'!$A8,'Điều chỉnh'!$G$4:$BE$4,"Sau đ/c") -> 1360 | C8: =SUM(B$4:B8) -> 13823 | D8: =SUMIFS('Điều chỉnh'!$G$15:$BE$15,'Điều chỉnh'!$G$1:$BE$1,'Slide 1'!$A8,'Điều chỉnh'!$G$4:$BE$4,"Sau đ/c") -> -87.625129 | E8: =SUM(D$4:D8) -> 1341.2778 | G8: =SUMIFS('Điều chỉnh'!$G$14:$BE$14,'Điều chỉnh'!$G$1:$BE$1,'Slide 1'!$A8,'Điều chỉnh'!$G$4:$BE$4,"Sau đ/c") -> 96 | H8: =SUM(G$4:G8) -> 1019.3 | J8: 0
A9: 6 | B9: =SUMIFS('Điều chỉnh'!$G$10:$BE$10,'Điều chỉnh'!$G$1:$BE$1,'Slide 1'!$A9,'Điều chỉnh'!$G$4:$BE$4,"Sau đ/c") -> 1780 | C9: =SUM(B$4:B9) -> 15603 | D9: =SUMIFS('Điều chỉnh'!$G$15:$BE$15,'Điều chỉnh'!$G$1:$BE$1,'Slide 1'!$A9,'Điều chỉnh'!$G$4:$BE$4,"Sau đ/c") -> 97.09175 | E9: =SUM(D$4:D9) -> 1438.3696 | G9: =SUMIFS('Điều chỉnh'!$G$14:$BE$14,'Điều chỉnh'!$G$1:$BE$1,'Slide 1'!$A9,'Điều chỉnh'!$G$4:$BE$4,"Sau đ/c") -> 128 | H9: =SUM(G$4:G9) -> 1147.3 | J9: 0
A10: 7 | B10: =SUMIFS('Điều chỉnh'!$G$10:$BE$10,'Điều chỉnh'!$G$1:$BE$1,'Slide 1'!$A10,'Điều chỉnh'!$G$4:$BE$4,"Sau đ/c") -> 340 | C10: =SUM(B$4:B10) -> 15943 | D10: =SUMIFS('Điều chỉnh'!$G$15:$BE$15,'Điều chỉnh'!$G$1:$BE$1,'Slide 1'!$A10,'Điều chỉnh'!$G$4:$BE$4,"Sau đ/c") -> -19.77894 | E10: =SUM(D$4:D10) -> 1418.5907 | G10: =SUMIFS('Điều chỉnh'!$G$14:$BE$14,'Điều chỉnh'!$G$1:$BE$1,'Slide 1'!$A10,'Điều chỉnh'!$G$4:$BE$4,"Sau đ/c") -> 24 | H10: =SUM(G$4:G10) -> 1171.3 | J10: 32.319144
A11: 8 | B11: =SUMIFS('Điều chỉnh'!$G$10:$BE$10,'Điều chỉnh'!$G$1:$BE$1,'Slide 1'!$A11,'Điều chỉnh'!$G$4:$BE$4,"Sau đ/c") -> 1456 | C11: =SUM(B$4:B11) -> 17399 | D11: =SUMIFS('Điều chỉnh'!$G$15:$BE$15,'Điều chỉnh'!$G$1:$BE$1,'Slide 1'!$A11,'Điều chỉnh'!$G$4:$BE$4,"Sau đ/c") -> 185.52896 | E11: =SUM(D$4:D11) -> 1604.1196 | G11: =SUMIFS('Điều chỉnh'!$G$14:$BE$14,'Điều chỉnh'!$G$1:$BE$1,'Slide 1'!$A11,'Điều chỉnh'!$G$4:$BE$4,"Sau đ/c") -> 105.6 | H11: =SUM(G$4:G11) -> 1276.9 | J11: 0
A12: 9 | B12: =SUMIFS('Điều chỉnh'!$G$10:$BE$10,'Điều chỉnh'!$G$1:$BE$1,'Slide 1'!$A12,'Điều chỉnh'!$G$4:$BE$4,"Sau đ/c") -> 4056.5 | C12: =SUM(B$4:B12) -> 21455.5 | D12: =SUMIFS('Điều chỉnh'!$G$15:$BE$15,'Điều chỉnh'!$G$1:$BE$1,'Slide 1'!$A12,'Điều chỉnh'!$G$4:$BE$4,"Sau đ/c") -> 99.271437 | E12: =SUM(D$4:D12) -> 1703.391 | G12: =SUMIFS('Điều chỉnh'!$G$14:$BE$14,'Điều chỉnh'!$G$1:$BE$1,'Slide 1'!$A12,'Điều chỉnh'!$G$4:$BE$4,"Sau đ/c") -> 295.65 | H12: =SUM(G$4:G12) -> 1572.55 | J12: 0
A13: 10 | B13: =SUMIFS('Điều chỉnh'!$G$10:$BE$10,'Điều chỉnh'!$G$1:$BE$1,'Slide 1'!$A13,'Điều chỉnh'!$G$4:$BE$4,"Sau đ/c") -> 2456 | C13: =SUM(B$4:B13) -> 23911.5 | D13: =SUMIFS('Điều chỉnh'!$G$15:$BE$15,'Điều chỉnh'!$G$1:$BE$1,'Slide 1'!$A13,'Điều chỉnh'!$G$4:$BE$4,"Sau đ/c") -> 73.634926 | E13: =SUM(D$4:D13) -> 1777.026 | G13: =SUMIFS('Điều chỉnh'!$G$14:$BE$14,'Điều chỉnh'!$G$1:$BE$1,'Slide 1'!$A13,'Điều chỉnh'!$G$4:$BE$4,"Sau đ/c") -> 176.6 | H13: =SUM(G$4:G13) -> 1749.15 | J13: 0
A14: 11 | B14: =SUMIFS('Điều chỉnh'!$G$10:$BE$10,'Điều chỉnh'!$G$1:$BE$1,'Slide 1'!$A14,'Điều chỉnh'!$G$4:$BE$4,"Sau đ/c") -> 2869 | C14: =SUM(B$4:B14) -> 26780.5 | D14: =SUMIFS('Điều chỉnh'!$G$15:$BE$15,'Điều chỉnh'!$G$1:$BE$1,'Slide 1'!$A14,'Điều chỉnh'!$G$4:$BE$4,"Sau đ/c") -> 168.24299 | E14: =SUM(D$4:D14) -> 1945.269 | G14: =SUMIFS('Điều chỉnh'!$G$14:$BE$14,'Điều chỉnh'!$G$1:$BE$1,'Slide 1'!$A14,'Điều chỉnh'!$G$4:$BE$4,"Sau đ/c") -> 206.9 | H14: =SUM(G$4:G14) -> 1956.05 | J14: 0
A15: 12 | B15: =SUMIFS('Điều chỉnh'!$G$10:$BE$10,'Điều chỉnh'!$G$1:$BE$1,'Slide 1'!$A15,'Điều chỉnh'!$G$4:$BE$4,"Sau đ/c") -> 1785 | C15: =SUM(B$4:B15) -> 28565.5 | D15: =SUMIFS('Điều chỉnh'!$G$15:$BE$15,'Điều chỉnh'!$G$1:$BE$1,'Slide 1'!$A15,'Điều chỉnh'!$G$4:$BE$4,"Sau đ/c") -> -248.50507 | E15: =SUM(D$4:D15) -> 1696.7639 | G15: =SUMIFS('Điều chỉnh'!$G$14:$BE$14,'Điều chỉnh'!$G$1:$BE$1,'Slide 1'!$A15,'Điều chỉnh'!$G$4:$BE$4,"Sau đ/c") -> 128.5 | H15: =SUM(G$4:G15) -> 2084.55 | J15: -248.50507

Sheet Slide 2
B2: SL bán hàng | C2: SL bán hàng LK
B3: tấn | C3: tấn
A4: 1 | B4: =SUMIFS('Điều chỉnh'!$G$6:$BE$6,'Điều chỉnh'!$G$1:$BE$1,'Slide 1'!$A4,'Điều chỉnh'!$G$4:$BE$4,"Sau đ/c") -> 0 | C4: =SUM(B$4:B4) -> 0
A5: 2 | B5: =SUMIFS('Điều chỉnh'!$G$6:$BE$6,'Điều chỉnh'!$G$1:$BE$1,'Slide 1'!$A5,'Điều chỉnh'!$G$4:$BE$4,"Sau đ/c") -> 386 | C5: =SUM(B$4:B5) -> 386
A6: 3 | B6: =SUMIFS('Điều chỉnh'!$G$6:$BE$6,'Điều chỉnh'!$G$1:$BE$1,'Slide 1'!$A6,'Điều chỉnh'!$G$4:$BE$4,"Sau đ/c") -> 140 | C6: =SUM(B$4:B6) -> 526
A7: 4 | B7: =SUMIFS('Điều chỉnh'!$G$6:$BE$6,'Điều chỉnh'!$G$1:$BE$1,'Slide 1'!$A7,'Điều chỉnh'!$G$4:$BE$4,"Sau đ/c") -> 120 | C7: =SUM(B$4:B7) -> 646
A8: 5 | B8: =SUMIFS('Điều chỉnh'!$G$6:$BE$6,'Điều chỉnh'!$G$1:$BE$1,'Slide 1'!$A8,'Điều chỉnh'!$G$4:$BE$4,"Sau đ/c") -> 80 | C8: =SUM(B$4:B8) -> 726
A9: 6 | B9: =SUMIFS('Điều chỉnh'!$G$6:$BE$6,'Điều chỉnh'!$G$1:$BE$1,'Slide 1'!$A9,'Điều chỉnh'!$G$4:$BE$4,"Sau đ/c") -> 100 | C9: =SUM(B$4:B9) -> 826
A10: 7 | B10: =SUMIFS('Điều chỉnh'!$G$6:$BE$6,'Điều chỉnh'!$G$1:$BE$1,'Slide 1'!$A10,'Điều chỉnh'!$G$4:$BE$4,"Sau đ/c") -> 20 | C10: =SUM(B$4:B10) -> 846
A11: 8 | B11: =SUMIFS('Điều chỉnh'!$G$6:$BE$6,'Điều chỉnh'!$G$1:$BE$1,'Slide 1'!$A11,'Điều chỉnh'!$G$4:$BE$4,"Sau đ/c") -> 80 | C11: =SUM(B$4:B11) -> 926
A12: 9 | B12: =SUMIFS('Điều chỉnh'!$G$6:$BE$6,'Điều chỉnh'!$G$1:$BE$1,'Slide 1'!$A12,'Điều chỉnh'!$G$4:$BE$4,"Sau đ/c") -> 220 | C12: =SUM(B$4:B12) -> 1146
A13: 10 | B13: =SUMIFS('Điều chỉnh'!$G$6:$BE$6,'Điều chỉnh'!$G$1:$BE$1,'Slide 1'!$A13,'Điều chỉnh'!$G$4:$BE$4,"Sau đ/c") -> 138 | C13: =SUM(B$4:B13) -> 1284
A14: 11 | B14: =SUMIFS('Điều chỉnh'!$G$6:$BE$6,'Điều chỉnh'!$G$1:$BE$1,'Slide 1'!$A14,'Điều chỉnh'!$G$4:$BE$4,"Sau đ/c") -> 160 | C14: =SUM(B$4:B14) -> 1444
A15: 12 | B15: =SUMIFS('Điều chỉnh'!$G$6:$BE$6,'Điều chỉnh'!$G$1:$BE$1,'Slide 1'!$A15,'Điều chỉnh'!$G$4:$BE$4,"Sau đ/c") -> 100 | C15: =SUM(B$4:B15) -> 1544

Sheet Slide 3
B2: Đvt: tấn
B3: STT | C3: Mã -SAP | D3: Tên hàng | E3: 1 | F3: 2 | G3: 3 | H3: 4 | I3: 5 | J3: 6 | K3: 7 | L3: 8 | M3: 9 | N3: 10 | O3: 11 | P3: 12 | Q3: Tổng
B4: 1 | C4: 160012429 | D4: Đầu Keo PET Sau Băm | E4: {=-SUMPRODUCT('Bán hàng-Break-down BOM'!$D$6:$AA$15*('Bán hàng-Break-down BOM'!$D$3:$AA$3=E$3)*('Bán hàng-Break-down BOM'!$B$6:$B$15=$C4))/10^3} -> 0 | F4: {=-SUMPRODUCT('Bán hàng-Break-down BOM'!$D$6:$AA$15*('Bán hàng-Break-down BOM'!$D$3:$AA$3=F$3)*('Bán hàng-Break-down BOM'!$B$6:$B$15=$C4))/10^3} -> 101.33477 | G4: {=-SUMPRODUCT('Bán hàng-Break-down BOM'!$D$6:$AA$15*('Bán hàng-Break-down BOM'!$D$3:$AA$3=G$3)*('Bán hàng-Break-down BOM'!$B$6:$B$15=$C4))/10^3} -> 32.518983 | H4: {=-SUMPRODUCT('Bán hàng-Break-down BOM'!$D$6:$AA$15*('Bán hàng-Break-down BOM'!$D$3:$AA$3=H$3)*('Bán hàng-Break-down BOM'!$B$6:$B$15=$C4))/10^3} -> 34.597628 | I4: {=-SUMPRODUCT('Bán hàng-Break-down BOM'!$D$6:$AA$15*('Bán hàng-Break-down BOM'!$D$3:$AA$3=I$3)*('Bán hàng-Break-down BOM'!$B$6:$B$15=$C4))/10^3} -> 34.484032 | J4: {=-SUMPRODUCT('Bán hàng-Break-down BOM'!$D$6:$AA$15*('Bán hàng-Break-down BOM'!$D$3:$AA$3=J$3)*('Bán hàng-Break-down BOM'!$B$6:$B$15=$C4))/10^3} -> 56.542726 | K4: {=-SUMPRODUCT('Bán hàng-Break-down BOM'!$D$6:$AA$15*('Bán hàng-Break-down BOM'!$D$3:$AA$3=K$3)*('Bán hàng-Break-down BOM'!$B$6:$B$15=$C4))/10^3} -> 9.6723529 | L4: {=-SUMPRODUCT('Bán hàng-Break-down BOM'!$D$6:$AA$15*('Bán hàng-Break-down BOM'!$D$3:$AA$3=L$3)*('Bán hàng-Break-down BOM'!$B$6:$B$15=$C4))/10^3} -> 44.18369 | ... P4: {=-SUMPRODUCT('Bán hàng-Break-down BOM'!$D$6:$AA$15*('Bán hàng-Break-down BOM'!$D$3:$AA$3=P$3)*('Bán hàng-Break-down BOM'!$B$6:$B$15=$C4))/10^3} -> 16.221904 | Q4: =SUM(E4:P4) -> 544.10462
B5: 2 | C5: 160012269 | D5: Phó Sản PET Zigzag Quay đầu | E5: {=-SUMPRODUCT('Bán hàng-Break-down BOM'!$D$6:$AA$15*('Bán hàng-Break-down BOM'!$D$3:$AA$3=E$3)*('Bán hàng-Break-down BOM'!$B$6:$B$15=$C5))/10^3} -> 0 | F5: {=-SUMPRODUCT('Bán hàng-Break-down BOM'!$D$6:$AA$15*('Bán hàng-Break-down BOM'!$D$3:$AA$3=F$3)*('Bán hàng-Break-down BOM'!$B$6:$B$15=$C5))/10^3} -> 0 | G5: {=-SUMPRODUCT('Bán hàng-Break-down BOM'!$D$6:$AA$15*('Bán hàng-Break-down BOM'!$D$3:$AA$3=G$3)*('Bán hàng-Break-down BOM'!$B$6:$B$15=$C5))/10^3} -> 0 | H5: {=-SUMPRODUCT('Bán hàng-Break-down BOM'!$D$6:$AA$15*('Bán hàng-Break-down BOM'!$D$3:$AA$3=H$3)*('Bán hàng-Break-down BOM'!$B$6:$B$15=$C5))/10^3} -> 0 | I5: {=-SUMPRODUCT('Bán hàng-Break-down BOM'!$D$6:$AA$15*('Bán hàng-Break-down BOM'!$D$3:$AA$3=I$3)*('Bán hàng-Break-down BOM'!$B$6:$B$15=$C5))/10^3} -> 0 | J5: {=-SUMPRODUCT('Bán hàng-Break-down BOM'!$D$6:$AA$15*('Bán hàng-Break-down BOM'!$D$3:$AA$3=J$3)*('Bán hàng-Break-down BOM'!$B$6:$B$15=$C5))/10^3} -> 0 | K5: {=-SUMPRODUCT('Bán hàng-Break-down BOM'!$D$6:$AA$15*('Bán hàng-Break-down BOM'!$D$3:$AA$3=K$3)*('Bán hàng-Break-down BOM'!$B$6:$B$15=$C5))/10^3} -> 0 | L5: {=-SUMPRODUCT('Bán hàng-Break-down BOM'!$D$6:$AA$15*('Bán hàng-Break-down BOM'!$D$3:$AA$3=L$3)*('Bán hàng-Break-down BOM'!$B$6:$B$15=$C5))/10^3} -> 2.955e-05 | ... P5: {=-SUMPRODUCT('Bán hàng-Break-down BOM'!$D$6:$AA$15*('Bán hàng-Break-down BOM'!$D$3:$AA$3=P$3)*('Bán hàng-Break-down BOM'!$B$6:$B$15=$C5))/10^3} -> 0 | Q5: =SUM(E5:P5) -> 0.00029
B6: 3 | C6: 160012268 | D6: Phó Sản PET Tomra Cổng 2 | E6: {=-SUMPRODUCT('Bán hàng-Break-down BOM'!$D$6:$AA$15*('Bán hàng-Break-down BOM'!$D$3:$AA$3=E$3)*('Bán hàng-Break-down BOM'!$B$6:$B$15=$C6))/10^3} -> 0 | F6: {=-SUMPRODUCT('Bán hàng-Break-down BOM'!$D$6:$AA$15*('Bán hàng-Break-down BOM'!$D$3:$AA$3=F$3)*('Bán hàng-Break-down BOM'!$B$6:$B$15=$C6))/10^3} -> 0 | G6: {=-SUMPRODUCT('Bán hàng-Break-down BOM'!$D$6:$AA$15*('Bán hàng-Break-down BOM'!$D$3:$AA$3=G$3)*('Bán hàng-Break-down BOM'!$B$6:$B$15=$C6))/10^3} -> 0 | H6: {=-SUMPRODUCT('Bán hàng-Break-down BOM'!$D$6:$AA$15*('Bán hàng-Break-down BOM'!$D$3:$AA$3=H$3)*('Bán hàng-Break-down BOM'!$B$6:$B$15=$C6))/10^3} -> 0 | I6: {=-SUMPRODUCT('Bán hàng-Break-down BOM'!$D$6:$AA$15*('Bán hàng-Break-down BOM'!$D$3:$AA$3=I$3)*('Bán hàng-Break-down BOM'!$B$6:$B$15=$C6))/10^3} -> 0 | J6: {=-SUMPRODUCT('Bán hàng-Break-down BOM'!$D$6:$AA$15*('Bán hàng-Break-down BOM'!$D$3:$AA$3=J$3)*('Bán hàng-Break-down BOM'!$B$6:$B$15=$C6))/10^3} -> 0 | K6: {=-SUMPRODUCT('Bán hàng-Break-down BOM'!$D$6:$AA$15*('Bán hàng-Break-down BOM'!$D$3:$AA$3=K$3)*('Bán hàng-Break-down BOM'!$B$6:$B$15=$C6))/10^3} -> 0 | L6: {=-SUMPRODUCT('Bán hàng-Break-down BOM'!$D$6:$AA$15*('Bán hàng-Break-down BOM'!$D$3:$AA$3=L$3)*('Bán hàng-Break-down BOM'!$B$6:$B$15=$C6))/10^3} -> 2.955e-05 | ... P6: {=-SUMPRODUCT('Bán hàng-Break-down BOM'!$D$6:$AA$15*('Bán hàng-Break-down BOM'!$D$3:$AA$3=P$3)*('Bán hàng-Break-down BOM'!$B$6:$B$15=$C6))/10^3} -> 0 | Q6: =SUM(E6:P6) -> 0.00029
B7: 4 | C7: 160012396 | D7: Vảy PET B4_A3 | E7: {=-SUMPRODUCT('Bán hàng-Break-down BOM'!$D$6:$AA$15*('Bán hàng-Break-down BOM'!$D$3:$AA$3=E$3)*('Bán hàng-Break-down BOM'!$B$6:$B$15=$C7))/10^3} -> 0 | F7: {=-SUMPRODUCT('Bán hàng-Break-down BOM'!$D$6:$AA$15*('Bán hàng-Break-down BOM'!$D$3:$AA$3=F$3)*('Bán hàng-Break-down BOM'!$B$6:$B$15=$C7))/10^3} -> 43.35162 | G7: {=-SUMPRODUCT('Bán hàng-Break-down BOM'!$D$6:$AA$15*('Bán hàng-Break-down BOM'!$D$3:$AA$3=G$3)*('Bán hàng-Break-down BOM'!$B$6:$B$15=$C7))/10^3} -> 9.7531435 | H7: {=-SUMPRODUCT('Bán hàng-Break-down BOM'!$D$6:$AA$15*('Bán hàng-Break-down BOM'!$D$3:$AA$3=H$3)*('Bán hàng-Break-down BOM'!$B$6:$B$15=$C7))/10^3} -> 8.5544932 | I7: {=-SUMPRODUCT('Bán hàng-Break-down BOM'!$D$6:$AA$15*('Bán hàng-Break-down BOM'!$D$3:$AA$3=I$3)*('Bán hàng-Break-down BOM'!$B$6:$B$15=$C7))/10^3} -> 6.5134549 | J7: {=-SUMPRODUCT('Bán hàng-Break-down BOM'!$D$6:$AA$15*('Bán hàng-Break-down BOM'!$D$3:$AA$3=J$3)*('Bán hàng-Break-down BOM'!$B$6:$B$15=$C7))/10^3} -> 14.111316 | K7: {=-SUMPRODUCT('Bán hàng-Break-down BOM'!$D$6:$AA$15*('Bán hàng-Break-down BOM'!$D$3:$AA$3=K$3)*('Bán hàng-Break-down BOM'!$B$6:$B$15=$C7))/10^3} -> 3.9090196 | L7: {=-SUMPRODUCT('Bán hàng-Break-down BOM'!$D$6:$AA$15*('Bán hàng-Break-down BOM'!$D$3:$AA$3=L$3)*('Bán hàng-Break-down BOM'!$B$6:$B$15=$C7))/10^3} -> 6.5425681 | ... P7: {=-SUMPRODUCT('Bán hàng-Break-down BOM'!$D$6:$AA$15*('Bán hàng-Break-down BOM'!$D$3:$AA$3=P$3)*('Bán hàng-Break-down BOM'!$B$6:$B$15=$C7))/10^3} -> 15.148101 | Q7: =SUM(E7:P7) -> 177.89135
B8: 5 | C8: 160012801 | D8: Vảy PET GC Dây Đai | E8: {=-SUMPRODUCT('Bán hàng-Break-down BOM'!$D$6:$AA$15*('Bán hàng-Break-down BOM'!$D$3:$AA$3=E$3)*('Bán hàng-Break-down BOM'!$B$6:$B$15=$C8))/10^3} -> 0 | F8: {=-SUMPRODUCT('Bán hàng-Break-down BOM'!$D$6:$AA$15*('Bán hàng-Break-down BOM'!$D$3:$AA$3=F$3)*('Bán hàng-Break-down BOM'!$B$6:$B$15=$C8))/10^3} -> 251.62409 | G8: {=-SUMPRODUCT('Bán hàng-Break-down BOM'!$D$6:$AA$15*('Bán hàng-Break-down BOM'!$D$3:$AA$3=G$3)*('Bán hàng-Break-down BOM'!$B$6:$B$15=$C8))/10^3} -> 102.95372 | H8: {=-SUMPRODUCT('Bán hàng-Break-down BOM'!$D$6:$AA$15*('Bán hàng-Break-down BOM'!$D$3:$AA$3=H$3)*('Bán hàng-Break-down BOM'!$B$6:$B$15=$C8))/10^3} -> 81.647879 | I8: {=-SUMPRODUCT('Bán hàng-Break-down BOM'!$D$6:$AA$15*('Bán hàng-Break-down BOM'!$D$3:$AA$3=I$3)*('Bán hàng-Break-down BOM'!$B$6:$B$15=$C8))/10^3} -> 41.188461 | J8: {=-SUMPRODUCT('Bán hàng-Break-down BOM'!$D$6:$AA$15*('Bán hàng-Break-down BOM'!$D$3:$AA$3=J$3)*('Bán hàng-Break-down BOM'!$B$6:$B$15=$C8))/10^3} -> 31.378426 | K8: {=-SUMPRODUCT('Bán hàng-Break-down BOM'!$D$6:$AA$15*('Bán hàng-Break-down BOM'!$D$3:$AA$3=K$3)*('Bán hàng-Break-down BOM'!$B$6:$B$15=$C8))/10^3} -> 7.2180392 | L8: {=-SUMPRODUCT('Bán hàng-Break-down BOM'!$D$6:$AA$15*('Bán hàng-Break-down BOM'!$D$3:$AA$3=L$3)*('Bán hàng-Break-down BOM'!$B$6:$B$15=$C8))/10^3} -> 32.913106 | ... P8: {=-SUMPRODUCT('Bán hàng-Break-down BOM'!$D$6:$AA$15*('Bán hàng-Break-down BOM'!$D$3:$AA$3=P$3)*('Bán hàng-Break-down BOM'!$B$6:$B$15=$C8))/10^3} -> 72.629995 | Q8: =SUM(E8:P8) -> 879.59736
B9: 6 | C9: 160012397 | D9: Vảy PET B4_A3.RN | E9: {=-SUMPRODUCT('Bán hàng-Break-down BOM'!$D$6:$AA$15*('Bán hàng-Break-down BOM'!$D$3:$AA$3=E$3)*('Bán hàng-Break-down BOM'!$B$6:$B$15=$C9))/10^3} -> 0 | F9: {=-SUMPRODUCT('Bán hàng-Break-down BOM'!$D$6:$AA$15*('Bán hàng-Break-down BOM'!$D$3:$AA$3=F$3)*('Bán hàng-Break-down BOM'!$B$6:$B$15=$C9))/10^3} -> 0 | G9: {=-SUMPRODUCT('Bán hàng-Break-down BOM'!$D$6:$AA$15*('Bán hàng-Break-down BOM'!$D$3:$AA$3=G$3)*('Bán hàng-Break-down BOM'!$B$6:$B$15=$C9))/10^3} -> 0 | H9: {=-SUMPRODUCT('Bán hàng-Break-down BOM'!$D$6:$AA$15*('Bán hàng-Break-down BOM'!$D$3:$AA$3=H$3)*('Bán hàng-Break-down BOM'!$B$6:$B$15=$C9))/10^3} -> 0 | I9: {=-SUMPRODUCT('Bán hàng-Break-down BOM'!$D$6:$AA$15*('Bán hàng-Break-down BOM'!$D$3:$AA$3=I$3)*('Bán hàng-Break-down BOM'!$B$6:$B$15=$C9))/10^3} -> 0 | J9: {=-SUMPRODUCT('Bán hàng-Break-down BOM'!$D$6:$AA$15*('Bán hàng-Break-down BOM'!$D$3:$AA$3=J$3)*('Bán hàng-Break-down BOM'!$B$6:$B$15=$C9))/10^3} -> 0 | K9: {=-SUMPRODUCT('Bán hàng-Break-down BOM'!$D$6:$AA$15*('Bán hàng-Break-down BOM'!$D$3:$AA$3=K$3)*('Bán hàng-Break-down BOM'!$B$6:$B$15=$C9))/10^3} -> 0 | L9: {=-SUMPRODUCT('Bán hàng-Break-down BOM'!$D$6:$AA$15*('Bán hàng-Break-down BOM'!$D$3:$AA$3=L$3)*('Bán hàng-Break-down BOM'!$B$6:$B$15=$C9))/10^3} -> 0 | ... P9: {=-SUMPRODUCT('Bán hàng-Break-down BOM'!$D$6:$AA$15*('Bán hàng-Break-down BOM'!$D$3:$AA$3=P$3)*('Bán hàng-Break-down BOM'!$B$6:$B$15=$C9))/10^3} -> 0 | Q9: =SUM(E9:P9) -> 0
B10: 7 | C10: 160012607 | D10: Phó Sản PET Zigzag Sau Lựa | E10: {=-SUMPRODUCT('Bán hàng-Break-down BOM'!$D$6:$AA$15*('Bán hàng-Break-down BOM'!$D$3:$AA$3=E$3)*('Bán hàng-Break-down BOM'!$B$6:$B$15=$C10))/10^3} -> 0 | F10: {=-SUMPRODUCT('Bán hàng-Break-down BOM'!$D$6:$AA$15*('Bán hàng-Break-down BOM'!$D$3:$AA$3=F$3)*('Bán hàng-Break-down BOM'!$B$6:$B$15=$C10))/10^3} -> 0 | G10: {=-SUMPRODUCT('Bán hàng-Break-down BOM'!$D$6:$AA$15*('Bán hàng-Break-down BOM'!$D$3:$AA$3=G$3)*('Bán hàng-Break-down BOM'!$B$6:$B$15=$C10))/10^3} -> 0 | H10: {=-SUMPRODUCT('Bán hàng-Break-down BOM'!$D$6:$AA$15*('Bán hàng-Break-down BOM'!$D$3:$AA$3=H$3)*('Bán hàng-Break-down BOM'!$B$6:$B$15=$C10))/10^3} -> 0 | I10: {=-SUMPRODUCT('Bán hàng-Break-down BOM'!$D$6:$AA$15*('Bán hàng-Break-down BOM'!$D$3:$AA$3=I$3)*('Bán hàng-Break-down BOM'!$B$6:$B$15=$C10))/10^3} -> 0 | J10: {=-SUMPRODUCT('Bán hàng-Break-down BOM'!$D$6:$AA$15*('Bán hàng-Break-down BOM'!$D$3:$AA$3=J$3)*('Bán hàng-Break-down BOM'!$B$6:$B$15=$C10))/10^3} -> 0 | K10: {=-SUMPRODUCT('Bán hàng-Break-down BOM'!$D$6:$AA$15*('Bán hàng-Break-down BOM'!$D$3:$AA$3=K$3)*('Bán hàng-Break-down BOM'!$B$6:$B$15=$C10))/10^3} -> 0 | L10: {=-SUMPRODUCT('Bán hàng-Break-down BOM'!$D$6:$AA$15*('Bán hàng-Break-down BOM'!$D$3:$AA$3=L$3)*('Bán hàng-Break-down BOM'!$B$6:$B$15=$C10))/10^3} -> 0 | ... P10: {=-SUMPRODUCT('Bán hàng-Break-down BOM'!$D$6:$AA$15*('Bán hàng-Break-down BOM'!$D$3:$AA$3=P$3)*('Bán hàng-Break-down BOM'!$B$6:$B$15=$C10))/10^3} -> 0 | Q10: =SUM(E10:P10) -> 0
B11: 8 | C11: 160012395 | D11: Vảy PET B4_A2 | E11: {=-SUMPRODUCT('Bán hàng-Break-down BOM'!$D$6:$AA$15*('Bán hàng-Break-down BOM'!$D$3:$AA$3=E$3)*('Bán hàng-Break-down BOM'!$B$6:$B$15=$C11))/10^3} -> 0 | F11: {=-SUMPRODUCT('Bán hàng-Break-down BOM'!$D$6:$AA$15*('Bán hàng-Break-down BOM'!$D$3:$AA$3=F$3)*('Bán hàng-Break-down BOM'!$B$6:$B$15=$C11))/10^3} -> 1.9209573 | G11: {=-SUMPRODUCT('Bán hàng-Break-down BOM'!$D$6:$AA$15*('Bán hàng-Break-down BOM'!$D$3:$AA$3=G$3)*('Bán hàng-Break-down BOM'!$B$6:$B$15=$C11))/10^3} -> 0 | H11: {=-SUMPRODUCT('Bán hàng-Break-down BOM'!$D$6:$AA$15*('Bán hàng-Break-down BOM'!$D$3:$AA$3=H$3)*('Bán hàng-Break-down BOM'!$B$6:$B$15=$C11))/10^3} -> 0 | I11: {=-SUMPRODUCT('Bán hàng-Break-down BOM'!$D$6:$AA$15*('Bán hàng-Break-down BOM'!$D$3:$AA$3=I$3)*('Bán hàng-Break-down BOM'!$B$6:$B$15=$C11))/10^3} -> 0.33926486 | J11: {=-SUMPRODUCT('Bán hàng-Break-down BOM'!$D$6:$AA$15*('Bán hàng-Break-down BOM'!$D$3:$AA$3=J$3)*('Bán hàng-Break-down BOM'!$B$6:$B$15=$C11))/10^3} -> 0.65773514 | K11: {=-SUMPRODUCT('Bán hàng-Break-down BOM'!$D$6:$AA$15*('Bán hàng-Break-down BOM'!$D$3:$AA$3=K$3)*('Bán hàng-Break-down BOM'!$B$6:$B$15=$C11))/10^3} -> 0 | L11: {=-SUMPRODUCT('Bán hàng-Break-down BOM'!$D$6:$AA$15*('Bán hàng-Break-down BOM'!$D$3:$AA$3=L$3)*('Bán hàng-Break-down BOM'!$B$6:$B$15=$C11))/10^3} -> 0 | ... P11: {=-SUMPRODUCT('Bán hàng-Break-down BOM'!$D$6:$AA$15*('Bán hàng-Break-down BOM'!$D$3:$AA$3=P$3)*('Bán hàng-Break-down BOM'!$B$6:$B$15=$C11))/10^3} -> 0 | Q11: =SUM(E11:P11) -> 2.9179573
B12: 9 | C12: 160012394 | D12: Vảy PET B4_A1 | E12: {=-SUMPRODUCT('Bán hàng-Break-down BOM'!$D$6:$AA$15*('Bán hàng-Break-down BOM'!$D$3:$AA$3=E$3)*('Bán hàng-Break-down BOM'!$B$6:$B$15=$C12))/10^3} -> 0 | F12: {=-SUMPRODUCT('Bán hàng-Break-down BOM'!$D$6:$AA$15*('Bán hàng-Break-down BOM'!$D$3:$AA$3=F$3)*('Bán hàng-Break-down BOM'!$B$6:$B$15=$C12))/10^3} -> 0 | G12: {=-SUMPRODUCT('Bán hàng-Break-down BOM'!$D$6:$AA$15*('Bán hàng-Break-down BOM'!$D$3:$AA$3=G$3)*('Bán hàng-Break-down BOM'!$B$6:$B$15=$C12))/10^3} -> 0 | H12: {=-SUMPRODUCT('Bán hàng-Break-down BOM'!$D$6:$AA$15*('Bán hàng-Break-down BOM'!$D$3:$AA$3=H$3)*('Bán hàng-Break-down BOM'!$B$6:$B$15=$C12))/10^3} -> 0 | I12: {=-SUMPRODUCT('Bán hàng-Break-down BOM'!$D$6:$AA$15*('Bán hàng-Break-down BOM'!$D$3:$AA$3=I$3)*('Bán hàng-Break-down BOM'!$B$6:$B$15=$C12))/10^3} -> 0.67478657 | J12: {=-SUMPRODUCT('Bán hàng-Break-down BOM'!$D$6:$AA$15*('Bán hàng-Break-down BOM'!$D$3:$AA$3=J$3)*('Bán hàng-Break-down BOM'!$B$6:$B$15=$C12))/10^3} -> 1.3082134 | K12: {=-SUMPRODUCT('Bán hàng-Break-down BOM'!$D$6:$AA$15*('Bán hàng-Break-down BOM'!$D$3:$AA$3=K$3)*('Bán hàng-Break-down BOM'!$B$6:$B$15=$C12))/10^3} -> 0 | L12: {=-SUMPRODUCT('Bán hàng-Break-down BOM'!$D$6:$AA$15*('Bán hàng-Break-down BOM'!$D$3:$AA$3=L$3)*('Bán hàng-Break-down BOM'!$B$6:$B$15=$C12))/10^3} -> 0 | ... P12: {=-SUMPRODUCT('Bán hàng-Break-down BOM'!$D$6:$AA$15*('Bán hàng-Break-down BOM'!$D$3:$AA$3=P$3)*('Bán hàng-Break-down BOM'!$B$6:$B$15=$C12))/10^3} -> 0 | Q12: =SUM(E12:P12) -> 1.983
B13: 10 | C13: 160012787 | D13: Phó Sản PP Trắng Sữa Bụi | E13: {=-SUMPRODUCT('Bán hàng-Break-down BOM'!$D$6:$AA$15*('Bán hàng-Break-down BOM'!$D$3:$AA$3=E$3)*('Bán hàng-Break-down BOM'!$B$6:$B$15=$C13))/10^3} -> 0 | F13: {=-SUMPRODUCT('Bán hàng-Break-down BOM'!$D$6:$AA$15*('Bán hàng-Break-down BOM'!$D$3:$AA$3=F$3)*('Bán hàng-Break-down BOM'!$B$6:$B$15=$C13))/10^3} -> 0.13337852 | G13: {=-SUMPRODUCT('Bán hàng-Break-down BOM'!$D$6:$AA$15*('Bán hàng-Break-down BOM'!$D$3:$AA$3=G$3)*('Bán hàng-Break-down BOM'!$B$6:$B$15=$C13))/10^3} -> 0 | H13: {=-SUMPRODUCT('Bán hàng-Break-down BOM'!$D$6:$AA$15*('Bán hàng-Break-down BOM'!$D$3:$AA$3=H$3)*('Bán hàng-Break-down BOM'!$B$6:$B$15=$C13))/10^3} -> 0 | I13: {=-SUMPRODUCT('Bán hàng-Break-down BOM'!$D$6:$AA$15*('Bán hàng-Break-down BOM'!$D$3:$AA$3=I$3)*('Bán hàng-Break-down BOM'!$B$6:$B$15=$C13))/10^3} -> 0 | J13: {=-SUMPRODUCT('Bán hàng-Break-down BOM'!$D$6:$AA$15*('Bán hàng-Break-down BOM'!$D$3:$AA$3=J$3)*('Bán hàng-Break-down BOM'!$B$6:$B$15=$C13))/10^3} -> 0 | K13: {=-SUMPRODUCT('Bán hàng-Break-down BOM'!$D$6:$AA$15*('Bán hàng-Break-down BOM'!$D$3:$AA$3=K$3)*('Bán hàng-Break-down BOM'!$B$6:$B$15=$C13))/10^3} -> 0 | L13: {=-SUMPRODUCT('Bán hàng-Break-down BOM'!$D$6:$AA$15*('Bán hàng-Break-down BOM'!$D$3:$AA$3=L$3)*('Bán hàng-Break-down BOM'!$B$6:$B$15=$C13))/10^3} -> 0 | ... P13: {=-SUMPRODUCT('Bán hàng-Break-down BOM'!$D$6:$AA$15*('Bán hàng-Break-down BOM'!$D$3:$AA$3=P$3)*('Bán hàng-Break-down BOM'!$B$6:$B$15=$C13))/10^3} -> 0 | Q13: =SUM(E13:P13) -> 0.13337852
B14: TỔNG | E14: =SUM(E4:E13) -> 0 | F14: =SUM(F4:F13) -> 398.36482 | G14: =SUM(G4:G13) -> 145.22584 | H14: =SUM(H4:H13) -> 124.8 | I14: =SUM(I4:I13) -> 83.2 | J14: =SUM(J4:J13) -> 103.99842 | K14: =SUM(K4:K13) -> 20.799412 | L14: =SUM(L4:L13) -> 83.639423 | ... Q14: =SUM(Q4:Q13) -> 1606.6282
Q15: =Q14+SUM('Bán hàng-Break-down BOM'!AB6:AB15)/10^3 -> 0

Sheet GB
A1: 110000428 | B1: Dây đai PET
B3: I. DOANH THU EXW
B5: CHỈ TIÊU | C5: Ghi chú | D5: Sản lượng | E5: Đơn giá | F5: Giá trị
D6: (tấn) | E6: (đ/kg) | F6: (tr.đ)
B7: Doanh thu | C7: [1] | D7: 826 | E7: 18889.831 | F7: =D7*E7/10^3 -> 15603
B8: CP bán hàng trực tiếp | C8: [2] = [2.1]+[2.2] | E8: =SUM(E9:E10) -> 6388.9831 | F8: =SUM(F9:F10) -> 5277.3
B9: Chi phí gia công | C9: [2.1] | D9: =D7 -> 826 | E9: 5000 | F9: =D9*E9/10^3 -> 4130
B10: Chi phí hoa hồng | C10: [2.2] | D10: =D9 -> 826 | E10: =(E7-E9)*10% -> 1388.9831 | F10: =D10*E10/10^3 -> 1147.3
B11: Doanh thu EXW | C11: [3]=[2]-[1] | D11: =D7 -> 826 | E11: =E7-E8 -> 12500.847 | F11: =D11*E11/10^3 -> 10325.7
B13: II. TÍNH TOÁN ĐƠN GIÁ
B15: CƠ CẤU NGUYÊN LIỆU | C15: Ghi chú | D15: Sản lượng (*) | E15: Đơn giá (**) | F15: Giá trị | H15: Đơn giá đề xuất | I15: Doanh thu | K15: Đơn giá theo SAP | L15: Giá trị
D16: (tấn) | E16: (đ/kg) | F16: (tr.đ) | H16: (đ/kg) | I16: (tr.đ) | K16: (đ/kg) | L16: (tr.đ)
A17: 160012394 | B17: Vảy PET B4_A1 | C17: [1] | D17: 1.983 | E17: =K17 -> 28951.971 | F17: =D17*E17/10^3 -> 57.411758 | H17: =$F$11*F17/$F$22/D17*10^3 -> 33719.055 | I17: =D17*H17/10^3 -> 66.864887 | K17: 28951.971 | L17: =D17*K17/10^3 -> 57.411758
A18: 160012395 | B18: Vảy PET B4_A2 | C18: [2] | D18: 2.9179573 | E18: =K18 -> 22614 | F18: =D18*E18/10^3 -> 65.986686 | H18: =$F$11*F18/$F$22/D18*10^3 -> 26337.506 | I18: =D18*H18/10^3 -> 76.851718 | K18: 22614 | L18: =D18*K18/10^3 -> 65.986686
A19: 160012396 | B19: Vảy PET B4_A3 | C19: [3] | D19: 82.284027 | E19: =K19 -> 22400.569 | F19: =D19*E19/10^3 -> 1843.209 | H19: =$F$11*F19/$F$22/D19*10^3 -> 26088.933 | I19: =D19*H19/10^3 -> 2146.7025 | K19: 22400.569 | L19: =D19*K19/10^3 -> 1843.209
A20: 160012429 | B20: Đầu Keo PET Sau Băm | C20: [4] | D20: 259.47814 | E20: 8935 | F20: =D20*E20/10^3 -> 2318.4372 | H20: =$F$11*F20/$F$22/D20*10^3 -> 10406.192 | I20: =D20*H20/10^3 -> 2700.1793 | K20: 23598.367 | L20: =D20*K20/10^3 -> 6123.2606
A21: 160012801 | B21: Vảy PET GC Dây Đai | C21: [5] | D21: 508.79257 | E21: =K21 -> 9003.3611 | F21: =D21*E21/10^3 -> 4580.8432 | H21: =$F$11*F21/$F$22/D21*10^3 -> 10485.809 | I21: =D21*H21/10^3 -> 5335.1016 | K21: =9040.32171775628-36.9606335562544 -> 9003.3611 | L21: =D21*K21/10^3 -> 4580.8432
B22: Tổng | C22: [6]=[1]+[2]+[3]+[4]+[5] | D22: =SUM(D17:D21) -> 855.4557 | E22: =IFERROR(F22/D22*10^3,0) -> 10363.936 | F22: =SUM(F17:F21) -> 8865.8879 | I22: =SUM(I17:I21) -> 10325.7 | K22: =IFERROR(L22/D22*10^3,0) -> 14811.651 | L22: =SUM(L17:L21) -> 12670.711
B24: (*): Sản lượng cấu thành 750 tấn bán trong 6 tháng đầu năm 2025
B25: (**): Đơn giá đã điều chỉnh theo giá thị trường cho phó sản (đầu keo PET)
B31: Đầu Keo PET Sau Băm | C31: 23598.367
B32: Vảy PET B4_A1 | C32: 28951.971
B33: Vảy PET B4_A2 | C33: 22614
B34: Vảy PET B4_A3 | C34: 22400.569
B35: Vảy PET GC Dây Đai | C35: 9040.3217

Sheet GB-v2
A1: 110000428 | C1: Dây đai PET
E3: TH1: HIỆN TRẠNG 6 THÁNG ĐẦU NĂM 2025 | J3: TH2: BÁN PHÓ SẢN NHƯNG VẪN ĐẢM BẢO LỢI NHUẬN
C5: CHỈ TIÊU | E5: Ghi chú | F5: Sản lượng | G5: Đơn giá | H5: Giá trị
F6: (tấn) | G6: (đ/kg) | H6: (tr.đ)
C7: Doanh thu | E7: [1] | F7: 826 | G7: 18889.831 | H7: =F7*G7/10^3 -> 15603
C8: CP bán hàng trực tiếp | E8: [2] = [2.1]+[2.2] | G8: =SUM(G9:G10) -> 6388.9831 | H8: =SUM(H9:H10) -> 5277.3
C9: Chi phí gia công | E9: [2.1] | F9: =F7 -> 826 | G9: 5000 | H9: =F9*G9/10^3 -> 4130
C10: Chi phí hoa hồng | E10: [2.2] | F10: =F9 -> 826 | G10: =(G7-G9)*10% -> 1388.9831 | H10: =F10*G10/10^3 -> 1147.3
C11: Doanh thu EXW | E11: [3]=[2]-[1] | F11: =F7 -> 826 | G11: =G7-G8 -> 12500.847 | H11: =F11*G11/10^3 -> 10325.7
C15: CƠ CẤU NGUYÊN LIỆU | E15: Ghi chú | F15: Sản lượng (*) | G15: Đơn giá theo SAP | H15: Giá trị | J15: Đơn giá đề xuất | K15: Doanh thu | Q15: Đơn giá (**) | R15: Giá trị
F16: (tấn) | G16: (đ/kg) | H16: (tr.đ) | J16: (đ/kg) | K16: (tr.đ) | Q16: (đ/kg) | R16: (tr.đ)
A17: 160012394 | C17: Vảy PET B4_A1 | E17: [1] | F17: 1.983 | G17: 28951.971 | H17: =F17*G17/10^3 -> 57.411758 | J17: =$H$11*R17/$R$22/F17*10^3 -> 33719.055 | K17: =F17*J17/10^3 -> 66.864887 | Q17: =G17 -> 28951.971 | R17: =F17*Q17/10^3 -> 57.411758
A18: 160012395 | C18: Vảy PET B4_A2 | E18: [2] | F18: 2.9179573 | G18: 22614 | H18: =F18*G18/10^3 -> 65.986686 | J18: =$H$11*R18/$R$22/F18*10^3 -> 26337.506 | K18: =F18*J18/10^3 -> 76.851718 | Q18: =G18 -> 22614 | R18: =F18*Q18/10^3 -> 65.986686
A19: 160012396 | C19: Vảy PET B4_A3 | E19: [3] | F19: 82.284027 | G19: 22400.569 | H19: =F19*G19/10^3 -> 1843.209 | J19: =$H$11*R19/$R$22/F19*10^3 -> 26088.933 | K19: =F19*J19/10^3 -> 2146.7025 | Q19: =G19 -> 22400.569 | R19: =F19*Q19/10^3 -> 1843.209
A20: 160012429 | C20: Đầu Keo PET Sau Băm | E20: [4] | F20: 259.47814 | G20: 23598.367 | H20: =F20*G20/10^3 -> 6123.2606 | J20: =$H$11*R20/$R$22/F20*10^3 -> 10406.192 | K20: =F20*J20/10^3 -> 2700.1793 | Q20: 8935 | R20: =F20*Q20/10^3 -> 2318.4372
A21: 160012801 | C21: Vảy PET GC Dây Đai | E21: [5] | F21: 508.79257 | G21: =9040.32171775628-36.9606335562544 -> 9003.3611 | H21: =F21*G21/10^3 -> 4580.8432 | J21: =$H$11*R21/$R$22/F21*10^3 -> 10485.809 | K21: =F21*J21/10^3 -> 5335.1016 | Q21: =G21 -> 9003.3611 | R21: =F21*Q21/10^3 -> 4580.8432
C22: Tổng | E22: [6]=[1]+[2]+[3]+[4]+[5] | F22: =SUM(F17:F21) -> 855.4557 | G22: =IFERROR(H22/F22*10^3,0) -> 14811.651 | H22: =SUM(H17:H21) -> 12670.711 | K22: =SUM(K17:K21) -> 10325.7 | Q22: =IFERROR(R22/F22*10^3,0) -> 10363.936 | R22: =SUM(R17:R21) -> 8865.8879
Q24: (**): Đơn giá đã điều chỉnh theo giá thị trường cho phó sản (đầu keo PET)
C25: Lãi gộp sổ sách SAP | E25: [7] = [3]-[6] | H25: =H11-H22 -> -2345.0113 | K25: =K22-H22 -> -2345.0113
C31: Ghi chú:
C32: (*): Sản lượng cấu thành 750 tấn bán trong 6 tháng đầu năm 2025
C33: Ở cả 2 trường hợp: nếu định giá nguyên liệu theo giá thị trường (đầu keo PET) thì lợi nhuận mang lại là 1.4 tỷ

Sheet >Working

Sheet Điều chỉnh
G1: 1 | H1: =G1 -> 1 | I1: =H1 -> 1 | K1: 2 | L1: =K1 -> 2 | M1: =L1 -> 2 | O1: 3 | P1: =O1 -> 3 | Q1: =P1 -> 3 | S1: 4 | T1: =S1 -> 4 | U1: =T1 -> 4 | W1: 5 | X1: =W1 -> 5 | Y1: =X1 -> 5 | AA1: 6 | AB1: =AA1 -> 6 | AC1: =AB1 -> 6 | AE1: 7 | AF1: =AE1 -> 7 | AG1: =AF1 -> 7 | AI1: 8 | AJ1: =AI1 -> 8 | AK1: =AJ1 -> 8 | AM1: 9 | AN1: =AM1 -> 9 | AO1: =AN1 -> 9 | AQ1: 10 | AR1: =AQ1 -> 10 | AS1: =AR1 -> 10 | AU1: 11 | AV1: =AU1 -> 11 | AW1: =AV1 -> 11 | AY1: 12 | AZ1: =AY1 -> 12 | BA1: =AZ1 -> 12 | BC1: =BC14/BC6*10^3 -> 1350.0972 | BE1: =BE12/BE6*10^3 -> 2449.0375
D3: DÂY ĐAI PET | E3: Đvt | G3: ="Tháng "&TEXT(G$1,"00") -> Tháng 01 | K3: ="Tháng "&TEXT(K$1,"00") -> Tháng 02 | O3: ="Tháng "&TEXT(O$1,"00") -> Tháng 03 | S3: ="Tháng "&TEXT(S$1,"00") -> Tháng 04 | W3: ="Tháng "&TEXT(W$1,"00") -> Tháng 05 | AA3: ="Tháng "&TEXT(AA$1,"00") -> Tháng 06 | AE3: ="Tháng "&TEXT(AE$1,"00") -> Tháng 07 | AI3: ="Tháng "&TEXT(AI$1,"00") -> Tháng 08 | AM3: ="Tháng "&TEXT(AM$1,"00") -> Tháng 09 | AQ3: ="Tháng "&TEXT(AQ$1,"00") -> Tháng 10 | AU3: ="Tháng "&TEXT(AU$1,"00") -> Tháng 11 | AY3: ="Tháng "&TEXT(AY$1,"00") -> Tháng 12 | BC3: TỔNG
G4: Trước đ/c | H4: Điều chỉnh | I4: Sau đ/c | K4: Trước đ/c | L4: Điều chỉnh | M4: Sau đ/c | O4: Trước đ/c | P4: Điều chỉnh | Q4: Sau đ/c | S4: Trước đ/c | T4: Điều chỉnh | U4: Sau đ/c | W4: Trước đ/c | X4: Điều chỉnh | Y4: Sau đ/c | AA4: Trước đ/c | AB4: Điều chỉnh | AC4: Sau đ/c | AE4: Trước đ/c | AF4: Điều chỉnh | AG4: Sau đ/c | AI4: Trước đ/c | AJ4: Điều chỉnh | AK4: Sau đ/c | AM4: Trước đ/c | AN4: Điều chỉnh | AO4: Sau đ/c | AQ4: Trước đ/c | AR4: Điều chỉnh | AS4: Sau đ/c | AU4: Trước đ/c | AV4: Điều chỉnh | AW4: Sau đ/c | AY4: Trước đ/c | AZ4: Điều chỉnh | BA4: Sau đ/c | BC4: Trước đ/c | BD4: Điều chỉnh | BE4: Sau đ/c
D6: Số lượng | E6: tấn | I6: =G6+H6 -> 0 | K6: 386 | M6: =K6+L6 -> 386 | O6: 140 | Q6: =O6+P6 -> 140 | S6: 120 | U6: =S6+T6 -> 120 | W6: 80 | Y6: =W6+X6 -> 80 | AA6: 100 | AC6: =AA6+AB6 -> 100 | AE6: 20 | AG6: =AE6+AF6 -> 20 | AI6: 80 | AK6: =AI6+AJ6 -> 80 | AM6: 220 | AO6: 220 | AQ6: 138 | AS6: =AQ6+AR6 -> 138 | AU6: 160 | AW6: =AU6+AV6 -> 160 | AY6: 100 | BA6: =AY6+AZ6 -> 100 | BC6: =SUMIFS($G6:$BA6,$G$4:$BA$4,BC$4) -> 1544 | BE6: =SUMIFS($G6:$BA6,$G$4:$BA$4,BE$4) -> 1544
D7: Giá bán | E7: đ/kg | I7: =G7+H7 -> 0 | K7: 19340.674 | M7: =K7+L7 -> 19340.674 | O7: 19678.571 | Q7: =O7+P7 -> 19678.571 | S7: 18687.5 | U7: =S7+T7 -> 18687.5 | W7: 17000 | Y7: =W7+X7 -> 17000 | AA7: 17800 | AC7: =AA7+AB7 -> 17800 | AE7: 17000 | AG7: =AE7+AF7 -> 17000 | AI7: 18200 | AK7: =AI7+AJ7 -> 18200 | AM7: 18438.636 | AO7: =AM7+AN7 -> 18438.636 | AQ7: 17797.101 | AS7: =AQ7+AR7 -> 17797.101 | AU7: 17931.25 | AW7: =AU7+AV7 -> 17931.25 | AY7: 17850 | BA7: =AY7+AZ7 -> 17850 | BC7: =IFERROR(SUMIFS($G10:$BA10,$G$4:$BA$4,BC$4)/BC$6*10^3,0) -> 18500.972 | BE7: =BC7+BD7 -> 18500.972
D8: GVĐV | E8: đ/kg | I8: =G8+H8 -> 0 | K8: 19523.461 | L8: =IFERROR(SUMIFS(L$21:L$33,$B$21:$B$33,"X")/K6*10^3,0) -> -3716.808 | M8: =K8+L8 -> 15806.653 | O8: 18725.828 | P8: =IFERROR(SUMIFS(P$21:P$33,$B$21:$B$33,"X")/O6*10^3,0) -> -3523.3555 | Q8: =O8+P8 -> 15202.472 | S8: 20034.899 | T8: =IFERROR(SUMIFS(T$21:T$33,$B$21:$B$33,"X")/S6*10^3,0) -> -4359.2098 | U8: =S8+T8 -> 15675.689 | W8: 23286.81 | X8: =IFERROR(SUMIFS(X$21:X$33,$B$21:$B$33,"X")/W6*10^3,0) -> -6391.4961 | Y8: =W8+X8 -> 16895.314 | AA8: 23759.066 | AB8: =IFERROR(SUMIFS(AB$21:AB$33,$B$21:$B$33,"X")/AA6*10^3,0) -> -8209.9838 | AC8: =AA8+AB8 -> 15549.082 | AE8: 23733.496 | AF8: =IFERROR(SUMIFS(AF$21:AF$33,$B$21:$B$33,"X")/AE6*10^3,0) -> -6944.5494 | AG8: =AE8+AF8 -> 16788.947 | AI8: 22508.845 | AJ8: =IFERROR(SUMIFS(AJ$21:AJ$33,$B$21:$B$33,"X")/AI6*10^3,0) -> -7947.9565 | AK8: =AI8+AJ8 -> 14560.888 | AM8: 22904.606 | AN8: =IFERROR(SUMIFS(AN$21:AN$33,$B$21:$B$33,"X")/AM6*10^3,0) -> -6261.0675 | AO8: =AM8+AN8 -> 16643.539 | AQ8: 22108.052 | AR8: =IFERROR(SUMIFS(AR$21:AR$33,$B$21:$B$33,"X")/AQ6*10^3,0) -> -6124.2474 | AS8: =AQ8+AR8 -> 15983.805 | AU8: 20611.435 | AV8: =IFERROR(SUMIFS(AV$21:AV$33,$B$21:$B$33,"X")/AU6*10^3,0) -> -5024.8291 | AW8: =AU8+AV8 -> 15586.606 | AY8: 21246.659 | AZ8: =IFERROR(SUMIFS(AZ$21:AZ$33,$B$21:$B$33,"X")/AY6*10^3,0) -> -2196.608 | BA8: =AY8+AZ8 -> 19050.051 | BC8: =IFERROR(SUMIFS($G11:$BA11,$G$4:$BA$4,BC$4)/BC6*10^3,0) -> 21106.547 | BD8: =IFERROR(SUMIFS(BD$21:BD$33,$B$21:$B$33,"X")/BC6*10^3,0) -> -5054.6133 | BE8: =BC8+BD8 -> 16051.934
D10: Doanh thu | E10: tr.đ | G10: =G6*G7/10^3 -> 0 | H10: =I10-G10 -> 0 | I10: =I6*I7/10^3 -> 0 | K10: =K6*K7/10^3 -> 7465.5 | L10: =M10-K10 -> 0 | M10: =M6*M7/10^3 -> 7465.5 | O10: =O6*O7/10^3 -> 2755 | P10: =Q10-O10 -> 0 | Q10: =Q6*Q7/10^3 -> 2755 | S10: =S6*S7/10^3 -> 2242.5 | T10: =U10-S10 -> 0 | U10: =U6*U7/10^3 -> 2242.5 | W10: =W6*W7/10^3 -> 1360 | X10: =Y10-W10 -> 0 | Y10: =Y6*Y7/10^3 -> 1360 | AA10: =AA6*AA7/10^3 -> 1780 | AB10: =AC10-AA10 -> 0 | AC10: =AC6*AC7/10^3 -> 1780 | AE10: =AE6*AE7/10^3 -> 340 | AF10: =AG10-AE10 -> 0 | AG10: =AG6*AG7/10^3 -> 340 | AI10: =AI6*AI7/10^3 -> 1456 | AJ10: =AK10-AI10 -> 0 | AK10: =AK6*AK7/10^3 -> 1456 | AM10: =AM6*AM7/10^3 -> 4056.5 | AN10: =AO10-AM10 -> 0 | AO10: =AO6*AO7/10^3 -> 4056.5 | AQ10: =AQ6*AQ7/10^3 -> 2456 | AR10: =AS10-AQ10 -> 0 | AS10: =AS6*AS7/10^3 -> 2456 | AU10: =AU6*AU7/10^3 -> 2869 | AV10: =AW10-AU10 -> 0 | AW10: =AW6*AW7/10^3 -> 2869 | AY10: =AY6*AY7/10^3 -> 1785 | AZ10: =BA10-AY10 -> 0 | BA10: =BA6*BA7/10^3 -> 1785 | BC10: =BC6*BC7/10^3 -> 28565.5 | BD10: =BE10-BC10 -> 0 | BE10: =BE6*BE7/10^3 -> 28565.5
D11: GVHB | E11: tr.đ | G11: =G8*G6/10^3 -> 0 | H11: =I11-G11 -> 0 | I11: =I8*I6/10^3 -> 0 | K11: =K8*K6/10^3 -> 7536.0561 | L11: =M11-K11 -> -1434.6879 | M11: =M8*M6/10^3 -> 6101.3682 | O11: =O8*O6/10^3 -> 2621.6159 | P11: =Q11-O11 -> -493.26977 | Q11: =Q8*Q6/10^3 -> 2128.3461 | S11: =S8*S6/10^3 -> 2404.1878 | T11: =U11-S11 -> -523.10517 | U11: =U8*U6/10^3 -> 1881.0827 | W11: =W8*W6/10^3 -> 1862.9448 | X11: =Y11-W11 -> -511.31969 | Y11: =Y8*Y6/10^3 -> 1351.6251 | AA11: =AA8*AA6/10^3 -> 2375.9066 | AB11: =AC11-AA11 -> -820.99838 | AC11: =AC8*AC6/10^3 -> 1554.9082 | AE11: =AE8*AE6/10^3 -> 474.66993 | AF11: =AG11-AE11 -> -138.89099 | AG11: =AG8*AG6/10^3 -> 335.77894 | AI11: =AI8*AI6/10^3 -> 1800.7076 | AJ11: =AK11-AI11 -> -635.83652 | AK11: =AK8*AK6/10^3 -> 1164.871 | AM11: =AM8*AM6/10^3 -> 5039.0134 | AN11: =AO11-AM11 -> -1377.4348 | AO11: =AO8*AO6/10^3 -> 3661.5786 | AQ11: =AQ8*AQ6/10^3 -> 3050.9112 | AR11: =AS11-AQ11 -> -845.14614 | AS11: =AS8*AS6/10^3 -> 2205.7651 | AU11: =AU8*AU6/10^3 -> 3297.8297 | AV11: =AW11-AU11 -> -803.97265 | AW11: =AW8*AW6/10^3 -> 2493.857 | AY11: =AY8*AY6/10^3 -> 2124.6659 | AZ11: =BA11-AY11 -> -219.6608 | BA11: =BA8*BA6/10^3 -> 1905.0051 | BC11: =BC8*BC6/10^3 -> 32588.509 | BD11: =BE11-BC11 -> -7804.3229 | BE11: =BE8*BE6/10^3 -> 24784.186
D12: Lãi gộp | E12: tr.đ | G12: =G10-G11 -> 0 | H12: =I12-G12 -> 0 | I12: =I10-I11 -> 0 | K12: =K10-K11 -> -70.556136 | L12: =M12-K12 -> 1434.6879 | M12: =M10-M11 -> 1364.1318 | O12: =O10-O11 -> 133.3841 | P12: =Q12-O12 -> 493.26977 | Q12: =Q10-Q11 -> 626.65388 | S12: =S10-S11 -> -161.68784 | T12: =U12-S12 -> 523.10517 | U12: =U10-U11 -> 361.41733 | W12: =W10-W11 -> -502.94482 | X12: =Y12-W12 -> 511.31969 | Y12: =Y10-Y11 -> 8.374871 | AA12: =AA10-AA11 -> -595.90663 | AB12: =AC12-AA12 -> 820.99838 | AC12: =AC10-AC11 -> 225.09175 | AE12: =AE10-AE11 -> -134.66993 | AF12: =AG12-AE12 -> 138.89099 | AG12: =AG10-AG11 -> 4.2210597 | AI12: =AI10-AI11 -> -344.70757 | AJ12: =AK12-AI12 -> 635.83652 | AK12: =AK10-AK11 -> 291.12896 | AM12: =AM10-AM11 -> -982.51341 | AN12: =AO12-AM12 -> 1377.4348 | AO12: =AO10-AO11 -> 394.92144 | AQ12: =AQ10-AQ11 -> -594.91121 | AR12: =AS12-AQ12 -> 845.14614 | AS12: =AS10-AS11 -> 250.23493 | AU12: =AU10-AU11 -> -428.82966 | AV12: =AW12-AU12 -> 803.97265 | AW12: =AW10-AW11 -> 375.14299 | AY12: =AY10-AY11 -> -339.66588 | AZ12: =BA12-AY12 -> 219.6608 | BA12: =BA10-BA11 -> -120.00507 | BC12: =BC10-BC11 -> -4023.009 | BD12: =BE12-BC12 -> 7804.3229 | BE12: =BE10-BE11 -> 3781.3139
D13: %LG | G13: =IFERROR(G12/G$10,0) -> 0 | I13: =IFERROR(I12/I$10,0) -> 0 | K13: =IFERROR(K12/K$10,0) -> -0.0094509592 | M13: =IFERROR(M12/M$10,0) -> 0.18272477 | O13: =IFERROR(O12/O$10,0) -> 0.048415282 | Q13: =IFERROR(Q12/Q$10,0) -> 0.22746057 | S13: =IFERROR(S12/S$10,0) -> -0.072101603 | U13: =IFERROR(U12/U$10,0) -> 0.16116715 | W13: =IFERROR(W12/W$10,0) -> -0.36981236 | Y13: =IFERROR(Y12/Y$10,0) -> 0.0061579934 | AA13: =IFERROR(AA12/AA$10,0) -> -0.334779 | AC13: =IFERROR(AC12/AC$10,0) -> 0.12645604 | AE13: =IFERROR(AE12/AE$10,0) -> -0.39608803 | AG13: =IFERROR(AG12/AG$10,0) -> 0.012414882 | AI13: =IFERROR(AI12/AI$10,0) -> -0.2367497 | AK13: =IFERROR(AK12/AK$10,0) -> 0.19995121 | AM13: =IFERROR(AM12/AM$10,0) -> -0.24220718 | AO13: =IFERROR(AO12/AO$10,0) -> 0.097355217 | AQ13: =IFERROR(AQ12/AQ$10,0) -> -0.24222769 | AS13: =IFERROR(AS12/AS$10,0) -> 0.10188718 | AU13: =IFERROR(AU12/AU$10,0) -> -0.14947008 | AW13: =IFERROR(AW12/AW$10,0) -> 0.1307574 | AY13: =IFERROR(AY12/AY$10,0) -> -0.19028901 | BA13: =IFERROR(BA12/BA$10,0) -> -0.067229731 | BC13: =IFERROR(BC12/BC$10,0) -> -0.14083454 | BE13: =IFERROR(BE12/BE$10,0) -> 0.13237345
D14: Chi phí hoa hồng | E14: tr.đ | I14: =G14+H14 -> 0 | K14: =(K7-5000)*K6*10%/10^3 -> 553.55 | M14: =K14+L14 -> 553.55 | O14: =(O7-5000)*O6*10%/10^3 -> 205.5 | Q14: =O14+P14 -> 205.5 | S14: =(S7-5000)*S6*10%/10^3 -> 164.25 | U14: =S14+T14 -> 164.25 | W14: =(W7-5000)*W6*10%/10^3 -> 96 | Y14: =W14+X14 -> 96 | AA14: =(AA7-5000)*AA6*10%/10^3 -> 128 | AC14: =AA14+AB14 -> 128 | AE14: 24 | AG14: =AE14+AF14 -> 24 | AI14: 105.6 | AK14: =AI14+AJ14 -> 105.6 | AM14: =(AM7-5000)*10%*AM6/10^3 -> 295.65 | AO14: =AM14+AN14 -> 295.65 | AQ14: =(AQ7-5000)*10%*AQ6/10^3 -> 176.6 | AS14: =AQ14+AR14 -> 176.6 | AU14: =(AU7-5000)*10%*AU6/10^3 -> 206.9 | AW14: =AU14+AV14 -> 206.9 | AY14: =(AY7-5000)*10%*AY6/10^3 -> 128.5 | BA14: =AY14+AZ14 -> 128.5 | BC14: =SUMIFS($G14:$BA14,$G$4:$BA$4,BC$4) -> 2084.55 | BE14: =BC14+BD14 -> 2084.55
D15: Lãi gộp sau Cp hoa hồng | E15: tr.đ | G15: =G12-G14 -> 0 | I15: =I12-I14 -> 0 | K15: =K12-K14 -> -624.10614 | M15: =M12-M14 -> 810.58177 | O15: =O12-O14 -> -72.115897 | Q15: =Q12-Q14 -> 421.15388 | S15: =S12-S14 -> -325.93784 | U15: =U12-U14 -> 197.16733 | W15: =W12-W14 -> -598.94482 | Y15: =Y12-Y14 -> -87.625129 | AA15: =AA12-AA14 -> -723.90663 | AC15: =AC12-AC14 -> 97.09175 | AE15: =AE12-AE14 -> -158.66993 | AG15: =AG12-AG14 -> -19.77894 | AI15: =AI12-AI14 -> -450.30757 | AK15: =AK12-AK14 -> 185.52896 | AM15: =AM12-AM14 -> -1278.1634 | AO15: =AO12-AO14 -> 99.271437 | AQ15: =AQ12-AQ14 -> -771.51121 | AS15: =AS12-AS14 -> 73.634926 | AU15: =AU12-AU14 -> -635.72966 | AW15: =AW12-AW14 -> 168.24299 | AY15: =AY12-AY14 -> -468.16588 | BA15: =BA12-BA14 -> -248.50507 | BC15: =BC12-BC14 -> -6107.559 | BE15: =BE12-BE14 -> 1696.7639
D16: %LG-sau hoa hồng | G16: =IFERROR(G15/G$10,0) -> 0 | I16: =IFERROR(I15/I$10,0) -> 0 | K16: =IFERROR(K15/K$10,0) -> -0.083598706 | M16: =IFERROR(M15/M$10,0) -> 0.10857702 | O16: =IFERROR(O15/O$10,0) -> -0.026176369 | Q16: =IFERROR(Q15/Q$10,0) -> 0.15286892 | S16: =IFERROR(S15/S$10,0) -> -0.14534575 | U16: =IFERROR(U15/U$10,0) -> 0.087923 | W16: =IFERROR(W15/W$10,0) -> -0.4404006 | Y16: =IFERROR(Y15/Y$10,0) -> -0.064430242 | AA16: =IFERROR(AA15/AA$10,0) -> -0.40668912 | AC16: =IFERROR(AC15/AC$10,0) -> 0.054545927 | AE16: =IFERROR(AE15/AE$10,0) -> -0.46667626 | AG16: =IFERROR(AG15/AG$10,0) -> -0.058173354 | AI16: =IFERROR(AI15/AI$10,0) -> -0.30927718 | AK16: =IFERROR(AK15/AK$10,0) -> 0.12742373 | AM16: =IFERROR(AM15/AM$10,0) -> -0.3150902 | AO16: =IFERROR(AO15/AO$10,0) -> 0.024472189 | AQ16: =IFERROR(AQ15/AQ$10,0) -> -0.31413323 | AS16: =IFERROR(AS15/AS$10,0) -> 0.029981647 | AU16: =IFERROR(AU15/AU$10,0) -> -0.2215858 | AW16: =IFERROR(AW15/AW$10,0) -> 0.058641682 | AY16: =IFERROR(AY15/AY$10,0) -> -0.2622778 | BA16: =IFERROR(BA15/BA$10,0) -> -0.13921853 | BC16: =IFERROR(BC15/BC$10,0) -> -0.21380893 | BE16: =IFERROR(BE15/BE$10,0) -> 0.059399061
D19: ĐIỀU CHỈNH NVL BOM
A21: Phó sản PET làm dây đai | B21: X | C21: 160012269 | D21: Phó Sản PET Zigzag Quay đầu | E21: tr.đ | G21: =G22*G23/10^3 -> 0 | H21: =I21-G21 -> 0 | I21: =I22*I23/10^3 -> 0 | K21: =K22*K23/10^3 -> 0 | L21: =M21-K21 -> 0 | M21: =M22*M23/10^3 -> 0 | O21: =O22*O23/10^3 -> 0 | P21: =Q21-O21 -> 0 | Q21: =Q22*Q23/10^3 -> 0 | S21: =S22*S23/10^3 -> 0 | T21: =U21-S21 -> 0 | U21: =U22*U23/10^3 -> 0 | W21: =W22*W23/10^3 -> 0 | X21: =Y21-W21 -> 0 | Y21: =Y22*Y23/10^3 -> 0 | AA21: =AA22*AA23/10^3 -> 0 | AB21: =AC21-AA21 -> 0 | AC21: =AC22*AC23/10^3 -> 0 | AE21: =AE22*AE23/10^3 -> 0 | AF21: =AG21-AE21 -> 0 | AG21: =AG22*AG23/10^3 -> 0 | AI21: =AI22*AI23/10^3 -> 0.00056711432 | AJ21: =AK21-AI21 -> -0.00033071432 | AK21: =AK22*AK23/10^3 -> 0.0002364 | AM21: =AM22*AM23/10^3 -> 0.0049984746 | AN21: =AO21-AM21 -> -0.0029148746 | AO21: =AO22*AO23/10^3 -> 0.0020836 | AQ21: =AQ22*AQ23/10^3 -> 0 | AR21: =AS21-AQ21 -> 0 | AS21: =AS22*AS23/10^3 -> 0 | AU21: =AU22*AU23/10^3 -> 0 | AV21: =AW21-AU21 -> 0 | AW21: =AW22*AW23/10^3 -> 0 | AY21: =AY22*AY23/10^3 -> 0 | AZ21: =BA21-AY21 -> 0 | BA21: =BA22*BA23/10^3 -> 0 | BC21: =BC22*BC23/10^3 -> 0.0055655889 | BD21: =BE21-BC21 -> -0.0032455889 | BE21: =SUMIFS($G21:$BA21,$G$4:$BA$4,BE$4) -> 0.00232
B22: =C21 -> 160012269 | D22: Sản lượng | E22: tấn | G22: {=-SUMPRODUCT('Bán hàng-Break-down BOM'!$D$6:$AA$15*('Bán hàng-Break-down BOM'!$B$6:$B$15=$B22)*('Bán hàng-Break-down BOM'!$D$3:$AA$3=G$1))/10^3} -> 0 | I22: =G22+H22 -> 0 | K22: {=-SUMPRODUCT('Bán hàng-Break-down BOM'!$D$6:$AA$15*('Bán hàng-Break-down BOM'!$B$6:$B$15=$B22)*('Bán hàng-Break-down BOM'!$D$3:$AA$3=K$1))/10^3} -> 0 | M22: =K22+L22 -> 0 | O22: {=-SUMPRODUCT('Bán hàng-Break-down BOM'!$D$6:$AA$15*('Bán hàng-Break-down BOM'!$B$6:$B$15=$B22)*('Bán hàng-Break-down BOM'!$D$3:$AA$3=O$1))/10^3} -> 0 | Q22: =O22+P22 -> 0 | S22: {=-SUMPRODUCT('Bán hàng-Break-down BOM'!$D$6:$AA$15*('Bán hàng-Break-down BOM'!$B$6:$B$15=$B22)*('Bán hàng-Break-down BOM'!$D$3:$AA$3=S$1))/10^3} -> 0 | U22: =S22+T22 -> 0 | W22: {=-SUMPRODUCT('Bán hàng-Break-down BOM'!$D$6:$AA$15*('Bán hàng-Break-down BOM'!$B$6:$B$15=$B22)*('Bán hàng-Break-down BOM'!$D$3:$AA$3=W$1))/10^3} -> 0 | Y22: =W22+X22 -> 0 | AA22: {=-SUMPRODUCT('Bán hàng-Break-down BOM'!$D$6:$AA$15*('Bán hàng-Break-down BOM'!$B$6:$B$15=$B22)*('Bán hàng-Break-down BOM'!$D$3:$AA$3=AA$1))/10^3} -> 0 | AC22: =AA22+AB22 -> 0 | AE22: {=-SUMPRODUCT('Bán hàng-Break-down BOM'!$D$6:$AA$15*('Bán hàng-Break-down BOM'!$B$6:$B$15=$B22)*('Bán hàng-Break-down BOM'!$D$3:$AA$3=AE$1))/10^3} -> 0 | AG22: =AE22+AF22 -> 0 | AI22: {=-SUMPRODUCT('Bán hàng-Break-down BOM'!$D$6:$AA$15*('Bán hàng-Break-down BOM'!$B$6:$B$15=$B22)*('Bán hàng-Break-down BOM'!$D$3:$AA$3=AI$1))/10^3} -> 2.955e-05 | AK22: =AI22+AJ22 -> 2.955e-05 | AM22: {=-SUMPRODUCT('Bán hàng-Break-down BOM'!$D$6:$AA$15*('Bán hàng-Break-down BOM'!$B$6:$B$15=$B22)*('Bán hàng-Break-down BOM'!$D$3:$AA$3=AM$1))/10^3} -> 0.00026045 | AO22: =AM22+AN22 -> 0.00026045 | AQ22: {=-SUMPRODUCT('Bán hàng-Break-down BOM'!$D$6:$AA$15*('Bán hàng-Break-down BOM'!$B$6:$B$15=$B22)*('Bán hàng-Break-down BOM'!$D$3:$AA$3=AQ$1))/10^3} -> 0 | AS22: =AQ22+AR22 -> 0 | AU22: {=-SUMPRODUCT('Bán hàng-Break-down BOM'!$D$6:$AA$15*('Bán hàng-Break-down BOM'!$B$6:$B$15=$B22)*('Bán hàng-Break-down BOM'!$D$3:$AA$3=AU$1))/10^3} -> 0 | AW22: =AU22+AV22 -> 0 | AY22: {=-SUMPRODUCT('Bán hàng-Break-down BOM'!$D$6:$AA$15*('Bán hàng-Break-down BOM'!$B$6:$B$15=$B22)*('Bán hàng-Break-down BOM'!$D$3:$AA$3=AY$1))/10^3} -> 0 | BA22: =AY22+AZ22 -> 0 | BC22: =SUMIFS($G22:$BA22,$G$4:$BA$4,BC$4) -> 0.00029 | BE22: =BC22+BD22 -> 0.00029
B23: =B22 -> 160012269 | D23: ĐG | E23: đ/kg | G23: {=IFERROR(SUMPRODUCT('Bán hàng-Break-down BOM'!$D$30:$AA$39*('Bán hàng-Break-down BOM'!$B$30:$B$39=$B23)*('Bán hàng-Break-down BOM'!$D$3:$AA$3=G$1))/G22/10^3,0)} -> 0 | H23: =INDEX(MD!$G$3:$G$8,MATCH('Điều chỉnh'!$B23,MD!$A$3:$A$8,0))-G23 -> 8000 | I23: =G23+H23 -> 8000 | K23: {=IFERROR(SUMPRODUCT('Bán hàng-Break-down BOM'!$D$30:$AA$39*('Bán hàng-Break-down BOM'!$B$30:$B$39=$B23)*('Bán hàng-Break-down BOM'!$D$3:$AA$3=K$1))/K22/10^3,0)} -> 0 | L23: =INDEX(MD!$G$3:$G$8,MATCH('Điều chỉnh'!$B23,MD!$A$3:$A$8,0))-K23 -> 8000 | M23: =K23+L23 -> 8000 | O23: {=IFERROR(SUMPRODUCT('Bán hàng-Break-down BOM'!$D$30:$AA$39*('Bán hàng-Break-down BOM'!$B$30:$B$39=$B23)*('Bán hàng-Break-down BOM'!$D$3:$AA$3=O$1))/O22/10^3,0)} -> 0 | P23: =INDEX(MD!$G$3:$G$8,MATCH('Điều chỉnh'!$B23,MD!$A$3:$A$8,0))-O23 -> 8000 | Q23: =O23+P23 -> 8000 | S23: {=IFERROR(SUMPRODUCT('Bán hàng-Break-down BOM'!$D$30:$AA$39*('Bán hàng-Break-down BOM'!$B$30:$B$39=$B23)*('Bán hàng-Break-down BOM'!$D$3:$AA$3=S$1))/S22/10^3,0)} -> 0 | T23: =INDEX(MD!$G$3:$G$8,MATCH('Điều chỉnh'!$B23,MD!$A$3:$A$8,0))-S23 -> 8000 | U23: =S23+T23 -> 8000 | W23: {=IFERROR(SUMPRODUCT('Bán hàng-Break-down BOM'!$D$30:$AA$39*('Bán hàng-Break-down BOM'!$B$30:$B$39=$B23)*('Bán hàng-Break-down BOM'!$D$3:$AA$3=W$1))/W22/10^3,0)} -> 0 | X23: =INDEX(MD!$G$3:$G$8,MATCH('Điều chỉnh'!$B23,MD!$A$3:$A$8,0))-W23 -> 8000 | Y23: =W23+X23 -> 8000 | AA23: {=IFERROR(SUMPRODUCT('Bán hàng-Break-down BOM'!$D$30:$AA$39*('Bán hàng-Break-down BOM'!$B$30:$B$39=$B23)*('Bán hàng-Break-down BOM'!$D$3:$AA$3=AA$1))/AA22/10^3,0)} -> 0 | AB23: =INDEX(MD!$G$3:$G$8,MATCH('Điều chỉnh'!$B23,MD!$A$3:$A$8,0))-AA23 -> 8000 | AC23: =AA23+AB23 -> 8000 | AE23: {=IFERROR(SUMPRODUCT('Bán hàng-Break-down BOM'!$D$30:$AA$39*('Bán hàng-Break-down BOM'!$B$30:$B$39=$B23)*('Bán hàng-Break-down BOM'!$D$3:$AA$3=AE$1))/AE22/10^3,0)} -> 0 | AF23: =INDEX(MD!$G$3:$G$8,MATCH('Điều chỉnh'!$B23,MD!$A$3:$A$8,0))-AE23 -> 8000 | AG23: =AE23+AF23 -> 8000 | AI23: {=IFERROR(SUMPRODUCT('Bán hàng-Break-down BOM'!$D$30:$AA$39*('Bán hàng-Break-down BOM'!$B$30:$B$39=$B23)*('Bán hàng-Break-down BOM'!$D$3:$AA$3=AI$1))/AI22/10^3,0)} -> 19191.686 | AJ23: =INDEX(MD!$G$3:$G$8,MATCH('Điều chỉnh'!$B23,MD!$A$3:$A$8,0))-AI23 -> -11191.686 | AK23: =AI23+AJ23 -> 8000 | AM23: {=IFERROR(SUMPRODUCT('Bán hàng-Break-down BOM'!$D$30:$AA$39*('Bán hàng-Break-down BOM'!$B$30:$B$39=$B23)*('Bán hàng-Break-down BOM'!$D$3:$AA$3=AM$1))/AM22/10^3,0)} -> 19191.686 | AN23: =INDEX(MD!$G$3:$G$8,MATCH('Điều chỉnh'!$B23,MD!$A$3:$A$8,0))-AM23 -> -11191.686 | AO23: =AM23+AN23 -> 8000 | AQ23: {=IFERROR(SUMPRODUCT('Bán hàng-Break-down BOM'!$D$30:$AA$39*('Bán hàng-Break-down BOM'!$B$30:$B$39=$B23)*('Bán hàng-Break-down BOM'!$D$3:$AA$3=AQ$1))/AQ22/10^3,0)} -> 0 | AR23: =INDEX(MD!$G$3:$G$8,MATCH('Điều chỉnh'!$B23,MD!$A$3:$A$8,0))-AQ23 -> 8000 | AS23: =AQ23+AR23 -> 8000 | AU23: =INDEX(MD!$F$3:$F$8,MATCH('Điều chỉnh'!$B23,MD!$A$3:$A$8,0)) -> 19192 | AV23: =INDEX(MD!$G$3:$G$8,MATCH('Điều chỉnh'!$B23,MD!$A$3:$A$8,0))-AU23 -> -11192 | AW23: =AU23+AV23 -> 8000 | AY23: =INDEX(MD!$F$3:$F$8,MATCH('Điều chỉnh'!$B23,MD!$A$3:$A$8,0)) -> 19192 | AZ23: =INDEX(MD!$G$3:$G$8,MATCH('Điều chỉnh'!$B23,MD!$A$3:$A$8,0))-AY23 -> -11192 | BA23: =AY23+AZ23 -> 8000 | BC23: =IFERROR(SUMIFS($G21:$BA21,$G$4:$BA$4,BC$4)/BC22,0)*10^3 -> 19191.686 | BD23: =IFERROR(SUMIFS($G21:$BA21,$G$4:$BA$4,BE$4)/BE22*10^3-BC23,0) -> -11191.686 | BE23: =BC23+BD23 -> 8000
A24: Đầu Keo PET | B24: X | C24: 160012429 | D24: Đầu Keo PET Sau Băm | E24: tr.đ | G24: =G25*G26/10^3 -> 0 | H24: =I24-G24 -> 0 | I24: =I25*I26/10^3 -> 0 | K24: =K25*K26/10^3 -> 2340.1141 | L24: =M24-K24 -> -1434.6879 | M24: =M25*M26/10^3 -> 905.42621 | O24: =O25*O26/10^3 -> 783.82689 | P24: =Q24-O24 -> -493.26977 | Q24: =Q25*Q26/10^3 -> 290.55711 | S24: =S25*S26/10^3 -> 832.23498 | T24: =U24-S24 -> -523.10517 | U24: =U25*U26/10^3 -> 309.12981 | W24: =W25*W26/10^3 -> 819.43452 | X24: =Y24-W24 -> -511.31969 | Y24: =Y25*Y26/10^3 -> 308.11483 | AA24: =AA25*AA26/10^3 -> 1326.2076 | AB24: =AC24-AA24 -> -820.99838 | AC24: =AC25*AC26/10^3 -> 505.20926 | AE24: =AE25*AE26/10^3 -> 225.31346 | AF24: =AG24-AE24 -> -138.89099 | AG24: =AG25*AG26/10^3 -> 86.422474 | AI24: =AI25*AI26/10^3 -> 1027.149 | AJ24: =AK24-AI24 -> -632.36775 | AK24: =AK25*AK26/10^3 -> 394.78127 | AM24: =AM25*AM26/10^3 -> 2198.4293 | AN24: =AO24-AM24 -> -1346.8615 | AO24: =AO25*AO26/10^3 -> 851.56773 | AQ24: =AQ25*AQ26/10^3 -> 1380.0699 | AR24: =AS24-AQ24 -> -845.14614 | AS24: =AS25*AS26/10^3 -> 534.92374 | AU24: =AU25*AU26/10^3 -> 1334.4723 | AV24: =AW24-AU24 -> -803.97265 | AW24: =AW25*AW26/10^3 -> 530.49964 | AY24: =AY25*AY26/10^3 -> 364.60352 | AZ24: =BA24-AY24 -> -219.6608 | BA24: =BA25*BA26/10^3 -> 144.94271 | BC24: =BC25*BC26/10^3 -> 12631.856 | BD24: =BE24-BC24 -> -7770.2808 | BE24: =SUMIFS($G24:$BA24,$G$4:$BA$4,BE$4) -> 4861.5748
B25: =C24 -> 160012429 | D25: Sản lượng | E25: tấn | G25: {=-SUMPRODUCT('Bán hàng-Break-down BOM'!$D$6:$AA$15*('Bán hàng-Break-down BOM'!$B$6:$B$15=$B25)*('Bán hàng-Break-down BOM'!$D$3:$AA$3=G$1))/10^3} -> 0 | I25: =G25+H25 -> 0 | K25: {=-SUMPRODUCT('Bán hàng-Break-down BOM'!$D$6:$AA$15*('Bán hàng-Break-down BOM'!$B$6:$B$15=$B25)*('Bán hàng-Break-down BOM'!$D$3:$AA$3=K$1))/10^3} -> 101.33477 | M25: =K25+L25 -> 101.33477 | O25: {=-SUMPRODUCT('Bán hàng-Break-down BOM'!$D$6:$AA$15*('Bán hàng-Break-down BOM'!$B$6:$B$15=$B25)*('Bán hàng-Break-down BOM'!$D$3:$AA$3=O$1))/10^3} -> 32.518983 | Q25: =O25+P25 -> 32.518983 | S25: {=-SUMPRODUCT('Bán hàng-Break-down BOM'!$D$6:$AA$15*('Bán hàng-Break-down BOM'!$B$6:$B$15=$B25)*('Bán hàng-Break-down BOM'!$D$3:$AA$3=S$1))/10^3} -> 34.597628 | U25: =S25+T25 -> 34.597628 | W25: {=-SUMPRODUCT('Bán hàng-Break-down BOM'!$D$6:$AA$15*('Bán hàng-Break-down BOM'!$B$6:$B$15=$B25)*('Bán hàng-Break-down BOM'!$D$3:$AA$3=W$1))/10^3} -> 34.484032 | Y25: =W25+X25 -> 34.484032 | AA25: {=-SUMPRODUCT('Bán hàng-Break-down BOM'!$D$6:$AA$15*('Bán hàng-Break-down BOM'!$B$6:$B$15=$B25)*('Bán hàng-Break-down BOM'!$D$3:$AA$3=AA$1))/10^3} -> 56.542726 | AC25: =AA25+AB25 -> 56.542726 | AE25: {=-SUMPRODUCT('Bán hàng-Break-down BOM'!$D$6:$AA$15*('Bán hàng-Break-down BOM'!$B$6:$B$15=$B25)*('Bán hàng-Break-down BOM'!$D$3:$AA$3=AE$1))/10^3} -> 9.6723529 | AG25: =AE25+AF25 -> 9.6723529 | AI25: {=-SUMPRODUCT('Bán hàng-Break-down BOM'!$D$6:$AA$15*('Bán hàng-Break-down BOM'!$B$6:$B$15=$B25)*('Bán hàng-Break-down BOM'!$D$3:$AA$3=AI$1))/10^3} -> 44.18369 | AK25: =AI25+AJ25 -> 44.18369 | AM25: {=-SUMPRODUCT('Bán hàng-Break-down BOM'!$D$6:$AA$15*('Bán hàng-Break-down BOM'!$B$6:$B$15=$B25)*('Bán hàng-Break-down BOM'!$D$3:$AA$3=AM$1))/10^3} -> 95.306965 | AO25: =AM25+AN25 -> 95.306965 | AQ25: {=-SUMPRODUCT('Bán hàng-Break-down BOM'!$D$6:$AA$15*('Bán hàng-Break-down BOM'!$B$6:$B$15=$B25)*('Bán hàng-Break-down BOM'!$D$3:$AA$3=AQ$1))/10^3} -> 59.868354 | AS25: =AQ25+AR25 -> 59.868354 | AU25: {=-SUMPRODUCT('Bán hàng-Break-down BOM'!$D$6:$AA$15*('Bán hàng-Break-down BOM'!$B$6:$B$15=$B25)*('Bán hàng-Break-down BOM'!$D$3:$AA$3=AU$1))/10^3} -> 59.373211 | AW25: =AU25+AV25 -> 59.373211 | AY25: {=-SUMPRODUCT('Bán hàng-Break-down BOM'!$D$6:$AA$15*('Bán hàng-Break-down BOM'!$B$6:$B$15=$B25)*('Bán hàng-Break-down BOM'!$D$3:$AA$3=AY$1))/10^3} -> 16.221904 | BA25: =AY25+AZ25 -> 16.221904 | BC25: =SUMIFS($G25:$BA25,$G$4:$BA$4,BC$4) -> 544.10462 | BE25: =BC25+BD25 -> 544.10462
B26: =B25 -> 160012429 | D26: ĐG | E26: đ/kg | G26: {=IFERROR(SUMPRODUCT('Bán hàng-Break-down BOM'!$D$30:$AA$39*('Bán hàng-Break-down BOM'!$B$30:$B$39=$B26)*('Bán hàng-Break-down BOM'!$D$3:$AA$3=G$1))/G25/10^3,0)} -> 0 | H26: =INDEX(MD!$G$3:$G$8,MATCH('Điều chỉnh'!$B26,MD!$A$3:$A$8,0))-G26 -> 8935 | I26: =G26+H26 -> 8935 | K26: {=IFERROR(SUMPRODUCT('Bán hàng-Break-down BOM'!$D$30:$AA$39*('Bán hàng-Break-down BOM'!$B$30:$B$39=$B26)*('Bán hàng-Break-down BOM'!$D$3:$AA$3=K$1))/K25/10^3,0)} -> 23092.903 | L26: =INDEX(MD!$G$3:$G$8,MATCH('Điều chỉnh'!$B26,MD!$A$3:$A$8,0))-K26 -> -14157.903 | M26: =K26+L26 -> 8935 | O26: {=IFERROR(SUMPRODUCT('Bán hàng-Break-down BOM'!$D$30:$AA$39*('Bán hàng-Break-down BOM'!$B$30:$B$39=$B26)*('Bán hàng-Break-down BOM'!$D$3:$AA$3=O$1))/O25/10^3,0)} -> 24103.672 | P26: =INDEX(MD!$G$3:$G$8,MATCH('Điều chỉnh'!$B26,MD!$A$3:$A$8,0))-O26 -> -15168.672 | Q26: =O26+P26 -> 8935 | S26: {=IFERROR(SUMPRODUCT('Bán hàng-Break-down BOM'!$D$30:$AA$39*('Bán hàng-Break-down BOM'!$B$30:$B$39=$B26)*('Bán hàng-Break-down BOM'!$D$3:$AA$3=S$1))/S25/10^3,0)} -> 24054.683 | T26: =INDEX(MD!$G$3:$G$8,MATCH('Điều chỉnh'!$B26,MD!$A$3:$A$8,0))-S26 -> -15119.683 | U26: =S26+T26 -> 8935 | W26: {=IFERROR(SUMPRODUCT('Bán hàng-Break-down BOM'!$D$30:$AA$39*('Bán hàng-Break-down BOM'!$B$30:$B$39=$B26)*('Bán hàng-Break-down BOM'!$D$3:$AA$3=W$1))/W25/10^3,0)} -> 23762.723 | X26: =INDEX(MD!$G$3:$G$8,MATCH('Điều chỉnh'!$B26,MD!$A$3:$A$8,0))-W26 -> -14827.723 | Y26: =W26+X26 -> 8935 | AA26: {=IFERROR(SUMPRODUCT('Bán hàng-Break-down BOM'!$D$30:$AA$39*('Bán hàng-Break-down BOM'!$B$30:$B$39=$B26)*('Bán hàng-Break-down BOM'!$D$3:$AA$3=AA$1))/AA25/10^3,0)} -> 23454.964 | AB26: =INDEX(MD!$G$3:$G$8,MATCH('Điều chỉnh'!$B26,MD!$A$3:$A$8,0))-AA26 -> -14519.964 | AC26: =AA26+AB26 -> 8935 | AE26: {=IFERROR(SUMPRODUCT('Bán hàng-Break-down BOM'!$D$30:$AA$39*('Bán hàng-Break-down BOM'!$B$30:$B$39=$B26)*('Bán hàng-Break-down BOM'!$D$3:$AA$3=AE$1))/AE25/10^3,0)} -> 23294.587 | AF26: =INDEX(MD!$G$3:$G$8,MATCH('Điều chỉnh'!$B26,MD!$A$3:$A$8,0))-AE26 -> -14359.587 | AG26: =AE26+AF26 -> 8935 | AI26: {=IFERROR(SUMPRODUCT('Bán hàng-Break-down BOM'!$D$30:$AA$39*('Bán hàng-Break-down BOM'!$B$30:$B$39=$B26)*('Bán hàng-Break-down BOM'!$D$3:$AA$3=AI$1))/AI25/10^3,0)} -> 23247.244 | AJ26: =INDEX(MD!$G$3:$G$8,MATCH('Điều chỉnh'!$B26,MD!$A$3:$A$8,0))-AI26 -> -14312.244 | AK26: =AI26+AJ26 -> 8935 | AM26: {=IFERROR(SUMPRODUCT('Bán hàng-Break-down BOM'!$D$30:$AA$39*('Bán hàng-Break-down BOM'!$B$30:$B$39=$B26)*('Bán hàng-Break-down BOM'!$D$3:$AA$3=AM$1))/AM25/10^3,0)} -> 23066.827 | AN26: =INDEX(MD!$G$3:$G$8,MATCH('Điều chỉnh'!$B26,MD!$A$3:$A$8,0))-AM26 -> -14131.827 | AO26: =AM26+AN26 -> 8935 | AQ26: {=IFERROR(SUMPRODUCT('Bán hàng-Break-down BOM'!$D$30:$AA$39*('Bán hàng-Break-down BOM'!$B$30:$B$39=$B26)*('Bán hàng-Break-down BOM'!$D$3:$AA$3=AQ$1))/AQ25/10^3,0)} -> 23051.742 | AR26: =INDEX(MD!$G$3:$G$8,MATCH('Điều chỉnh'!$B26,MD!$A$3:$A$8,0))-AQ26 -> -14116.742 | AS26: =AQ26+AR26 -> 8935 | AU26: =INDEX(MD!$F$3:$F$8,MATCH('Điều chỉnh'!$B26,MD!$A$3:$A$8,0)) -> 22476 | AV26: =INDEX(MD!$G$3:$G$8,MATCH('Điều chỉnh'!$B26,MD!$A$3:$A$8,0))-AU26 -> -13541 | AW26: =AU26+AV26 -> 8935 | AY26: =INDEX(MD!$F$3:$F$8,MATCH('Điều chỉnh'!$B26,MD!$A$3:$A$8,0)) -> 22476 | AZ26: =INDEX(MD!$G$3:$G$8,MATCH('Điều chỉnh'!$B26,MD!$A$3:$A$8,0))-AY26 -> -13541 | BA26: =AY26+AZ26 -> 8935 | BC26: =IFERROR(SUMIFS($G24:$BA24,$G$4:$BA$4,BC$4)/BC25,0)*10^3 -> 23215.858 | BD26: =IFERROR(SUMIFS($G24:$BA24,$G$4:$BA$4,BE$4)/BE25*10^3-BC26,0) -> -14280.858 | BE26: =BC26+BD26 -> 8935
A27: Phó sản PET làm dây đai | B27: X | C27: 160012607 | D27: Phó Sản PET Zigzag Sau Lựa | E27: tr.đ | G27: =G28*G29/10^3 -> 0 | H27: =I27-G27 -> 0 | I27: =I28*I29/10^3 -> 0 | K27: =K28*K29/10^3 -> 0 | L27: =M27-K27 -> 0 | M27: =M28*M29/10^3 -> 0 | O27: =O28*O29/10^3 -> 0 | P27: =Q27-O27 -> 0 | Q27: =Q28*Q29/10^3 -> 0 | S27: =S28*S29/10^3 -> 0 | T27: =U27-S27 -> 0 | U27: =U28*U29/10^3 -> 0 | W27: =W28*W29/10^3 -> 0 | X27: =Y27-W27 -> 0 | Y27: =Y28*Y29/10^3 -> 0 | AA27: =AA28*AA29/10^3 -> 0 | AB27: =AC27-AA27 -> 0 | AC27: =AC28*AC29/10^3 -> 0 | AE27: =AE28*AE29/10^3 -> 0 | AF27: =AG27-AE27 -> 0 | AG27: =AG28*AG29/10^3 -> 0 | AI27: =AI28*AI29/10^3 -> 0 | AJ27: =AK27-AI27 -> 0 | AK27: =AK28*AK29/10^3 -> 0 | AM27: =AM28*AM29/10^3 -> 0 | AN27: =AO27-AM27 -> 0 | AO27: =AO28*AO29/10^3 -> 0 | AQ27: =AQ28*AQ29/10^3 -> 0 | AR27: =AS27-AQ27 -> 0 | AS27: =AS28*AS29/10^3 -> 0 | AU27: =AU28*AU29/10^3 -> 0 | AV27: =AW27-AU27 -> 0 | AW27: =AW28*AW29/10^3 -> 0 | AY27: =AY28*AY29/10^3 -> 0 | AZ27: =BA27-AY27 -> 0 | BA27: =BA28*BA29/10^3 -> 0 | BC27: =BC28*BC29/10^3 -> 0 | BD27: =BE27-BC27 -> 0 | BE27: =SUMIFS($G27:$BA27,$G$4:$BA$4,BE$4) -> 0
B28: =C27 -> 160012607 | D28: Sản lượng | E28: tấn | G28: {=-SUMPRODUCT('Bán hàng-Break-down BOM'!$D$6:$AA$15*('Bán hàng-Break-down BOM'!$B$6:$B$15=$B28)*('Bán hàng-Break-down BOM'!$D$3:$AA$3=G$1))/10^3} -> 0 | I28: =G28+H28 -> 0 | K28: {=-SUMPRODUCT('Bán hàng-Break-down BOM'!$D$6:$AA$15*('Bán hàng-Break-down BOM'!$B$6:$B$15=$B28)*('Bán hàng-Break-down BOM'!$D$3:$AA$3=K$1))/10^3} -> 0 | M28: =K28+L28 -> 0 | O28: {=-SUMPRODUCT('Bán hàng-Break-down BOM'!$D$6:$AA$15*('Bán hàng-Break-down BOM'!$B$6:$B$15=$B28)*('Bán hàng-Break-down BOM'!$D$3:$AA$3=O$1))/10^3} -> 0 | Q28: =O28+P28 -> 0 | S28: {=-SUMPRODUCT('Bán hàng-Break-down BOM'!$D$6:$AA$15*('Bán hàng-Break-down BOM'!$B$6:$B$15=$B28)*('Bán hàng-Break-down BOM'!$D$3:$AA$3=S$1))/10^3} -> 0 | U28: =S28+T28 -> 0 | W28: {=-SUMPRODUCT('Bán hàng-Break-down BOM'!$D$6:$AA$15*('Bán hàng-Break-down BOM'!$B$6:$B$15=$B28)*('Bán hàng-Break-down BOM'!$D$3:$AA$3=W$1))/10^3} -> 0 | Y28: =W28+X28 -> 0 | AA28: {=-SUMPRODUCT('Bán hàng-Break-down BOM'!$D$6:$AA$15*('Bán hàng-Break-down BOM'!$B$6:$B$15=$B28)*('Bán hàng-Break-down BOM'!$D$3:$AA$3=AA$1))/10^3} -> 0 | AC28: =AA28+AB28 -> 0 | AE28: {=-SUMPRODUCT('Bán hàng-Break-down BOM'!$D$6:$AA$15*('Bán hàng-Break-down BOM'!$B$6:$B$15=$B28)*('Bán hàng-Break-down BOM'!$D$3:$AA$3=AE$1))/10^3} -> 0 | AG28: =AE28+AF28 -> 0 | AI28: {=-SUMPRODUCT('Bán hàng-Break-down BOM'!$D$6:$AA$15*('Bán hàng-Break-down BOM'!$B$6:$B$15=$B28)*('Bán hàng-Break-down BOM'!$D$3:$AA$3=AI$1))/10^3} -> 0 | AK28: =AI28+AJ28 -> 0 | AM28: {=-SUMPRODUCT('Bán hàng-Break-down BOM'!$D$6:$AA$15*('Bán hàng-Break-down BOM'!$B$6:$B$15=$B28)*('Bán hàng-Break-down BOM'!$D$3:$AA$3=AM$1))/10^3} -> 0 | AO28: =AM28+AN28 -> 0 | AQ28: {=-SUMPRODUCT('Bán hàng-Break-down BOM'!$D$6:$AA$15*('Bán hàng-Break-down BOM'!$B$6:$B$15=$B28)*('Bán hàng-Break-down BOM'!$D$3:$AA$3=AQ$1))/10^3} -> 0 | AS28: =AQ28+AR28 -> 0 | AU28: {=-SUMPRODUCT('Bán hàng-Break-down BOM'!$D$6:$AA$15*('Bán hàng-Break-down BOM'!$B$6:$B$15=$B28)*('Bán hàng-Break-down BOM'!$D$3:$AA$3=AU$1))/10^3} -> 0 | AW28: =AU28+AV28 -> 0 | AY28: {=-SUMPRODUCT('Bán hàng-Break-down BOM'!$D$6:$AA$15*('Bán hàng-Break-down BOM'!$B$6:$B$15=$B28)*('Bán hàng-Break-down BOM'!$D$3:$AA$3=AY$1))/10^3} -> 0 | BA28: =AY28+AZ28 -> 0 | BC28: =SUMIFS($G28:$BA28,$G$4:$BA$4,BC$4) -> 0 | BE28: =BC28+BD28 -> 0
