Workbook
Name _1: #REF!
Name _1: #REF!
Name _2: #REF!
Name _2: #REF!
Name _3: #REF!
Name _3: #REF!
Name _4: #REF!
Name _4: #REF!
Name _5: #REF!
Name _5: #REF!
Name a: #REF!
Name a: #REF!
Name Accounts: #REF!
Name Accounts: #REF!
Name Activity_Reports: #REF!
Name Activity_Reports: #REF!
Name ADM: #REF!
Name ADM: #REF!
Name Application: #REF!
Name B: #REF!
Name B: #REF!
Name back: #REF!
Name back: #REF!
Name Calendar: #REF!
Name Calendar: #REF!
Name Catalogue_xls: #REF!
Name Catalogue_xls: #REF!
Name CompanyCode: [10]CompanyCode!$A$2:$A$5
Name Contractingdiv: #REF!
Name Contractingdiv: #REF!
Name corporate_affairs: #REF!
Name corporate_affairs: #REF!
Name CTY: '[11]0.CTY'!$D$1:$D$65536
Name Data_Values: '[15]Single Measure Analysis'!$B$29:$M$30
Name DATA13: '[16]2.1Raw material_details'!#REF!
Name DATA13: '[16]2.1Raw material_details'!#REF!
Name DATA14: '[16]2.1Raw material_details'!#REF!
Name DATA14: '[16]2.1Raw material_details'!#REF!
Name DATA15: '[16]2.1Raw material_details'!#REF!
Name DATA15: '[16]2.1Raw material_details'!#REF!
Name DATA16: '[16]2.1Raw material_details'!#REF!
Name DATA16: '[16]2.1Raw material_details'!#REF!
Name DATA17: '[16]2.1Raw material_details'!#REF!
Name DATA17: '[16]2.1Raw material_details'!#REF!
Name DATA18: '[16]2.1Raw material_details'!#REF!
Name DATA18: '[16]2.1Raw material_details'!#REF!
Name DATA19: '[16]2.1Raw material_details'!#REF!
Name DATA19: '[16]2.1Raw material_details'!#REF!
Name DATA20: '[16]2.1Raw material_details'!#REF!
Name DATA20: '[16]2.1Raw material_details'!#REF!
Name DATA21: '[16]2.1Raw material_details'!#REF!
Name DATA21: '[16]2.1Raw material_details'!#REF!
Name DATA22: '[16]2.1Raw material_details'!#REF!
Name DATA22: '[16]2.1Raw material_details'!#REF!
Name DATA23: '[16]2.1Raw material_details'!#REF!
Name DATA23: '[16]2.1Raw material_details'!#REF!
Name DATA24: '[16]2.1Raw material_details'!#REF!
Name DATA24: '[16]2.1Raw material_details'!#REF!
Name DATA25: '[16]2.1Raw material_details'!#REF!
Name DATA25: '[16]2.1Raw material_details'!#REF!

Sheet Timeline & PIC
B1: DUY TAN GROUP
B2: =IF(B3="EN","Schedule Annual Plan 2025","Lịch lập NGÂN SÁCH năm 2026") -> Lịch lập NGÂN SÁCH năm 2026 | D2: =IF(B3="EN","Start:","Bắt đầu:") -> Bắt đầu: | E2: 45915
B3: VN | D3: =IF(B3="EN","Finish:","Kết thúc:") -> Kết thúc: | E3: =G22 -> 45990 | G3: =E3-E2 -> 75
D4: =IF(B3="en","SENDER","Đơn vị gửi") -> Đơn vị gửi | E4: =IF(B3="EN","RECEIVER","Đơn vị nhận") -> Đơn vị nhận | G4: Deadline | H4: THÁNG 09 | AM4: THÁNG 10 | BR4: THÁNG 11
B5: No. | C5: =IF(B3="EN","PROCESS","TRÌNH TỰ THỰC HIỆN") -> TRÌNH TỰ THỰC HIỆN | F5: Thời gian | H5: 1 | I5: 2 | J5: 3 | K5: 4 | L5: 5 | M5: 6 | N5: 7 | O5: 8 | P5: 9 | Q5: 10 | R5: 11 | S5: 12 | T5: 13 | U5: 14 | V5: 15 | W5: 16 | X5: 17 | Y5: 18 | Z5: 19 | AA5: 20 | AB5: 21 | AC5: 22 | AD5: 23 | AE5: 24 | AF5: 25 | AG5: 26 | AH5: 27 | AI5: 28 | AJ5: 29 | AK5: 30 | AL5: 31 | AM5: 1 | AN5: 2 | AO5: 3 | AP5: 4 | AQ5: 5 | AR5: 6 | AS5: 7 | AT5: 8 | AU5: 9 | AV5: 10 | AW5: 11 | AX5: 12 | AY5: 13 | AZ5: 14 | BA5: 15 | BB5: 16 | BC5: 17 | BD5: 18 | BE5: 19 | BF5: 20 | BG5: 21 | BH5: 22 | BI5: 23 | BJ5: 24 | BK5: 25 | BL5: 26 | BM5: 27 | BN5: 28 | BO5: 29 | BP5: 30 | BQ5: 31 | BR5: 1 | BS5: =BR5+1 -> 2 | BT5: =BS5+1 -> 3 | BU5: =BT5+1 -> 4 | BV5: =BU5+1 -> 5 | BW5: =BV5+1 -> 6 | BX5: =BW5+1 -> 7 | BY5: =BX5+1 -> 8 | BZ5: =BY5+1 -> 9 | ... CT5: =CS5+1 -> 29 | CU5: 30
F6: (Ngày) | H6: M | I6: T | J6: W | K6: TH | L6: F | M6: Sa | N6: Su | O6: M | P6: T | Q6: W | R6: TH | S6: F | T6: Sa | U6: Su | V6: M | W6: T | X6: W | Y6: TH | Z6: F | AA6: Sa | AB6: Su | AC6: M | AD6: T | AE6: W | AF6: TH | AG6: F | AH6: Sa | AI6: Su | AJ6: M | AK6: T | AL6: W | AM6: TH | AN6: F | AO6: Sa | AP6: Su | AQ6: M | AR6: T | AS6: W | AT6: TH | AU6: F | AV6: Sa | AW6: Su | AX6: M | AY6: T | AZ6: W | BA6: TH | BB6: F | BC6: Sa | BD6: Su | BE6: M | BF6: T | BG6: W | BH6: TH | BI6: F | BJ6: Sa | BK6: Su | BL6: M | BM6: T | BN6: W | BO6: TH | BP6: F | BQ6: Sa | BR6: Su | BS6: M | BT6: T | BU6: W | BV6: TH | BW6: F | BX6: Sa | BY6: Su | BZ6: M | CA6: T | CB6: W | CC6: TH | CD6: F | CE6: Sa | CF6: Su | CG6: M | CH6: T | CI6: W | CJ6: TH | CK6: F | CL6: Sa | CM6: Su | CN6: M | CO6: T | CP6: W | CQ6: TH | CR6: F | CS6: Sa | CT6: Su | CU6: M
B7: 1 | C7: Khởi động | D7: GĐTC holding | E7: =IF(B3="EN","All","Tất cả") -> Tất cả | G7: =E2 -> 45915
B8: 2 | C8: Kế hoạch Doanh thu / Sản lượng | D8: =IF(B3="EN","Sales team","Phòng kinh doanh") -> Phòng kinh doanh | E8: =IF(B3="EN","Acct.","Kế toán") -> Kế toán | F8: 15 | G8: =F8+$G$7 -> 45930
B9: 3 | C9: Kế hoạch giá cả nguyên vật liệu | D9: =IF(B2="EN","Supply chain","Chuỗi cung ứng") -> Chuỗi cung ứng | E9: =E8 -> Kế toán | F9: 15 | G9: =F9+$G$7 -> 45930
B10: =B9+1 -> 4 | C10: Kế hoạch chi phí vận chuyển, cước xuất khẩu,... | D10: =IF(B3="EN","Supply chain","Chuổi cung ứng") -> Chuổi cung ứng | E10: =E9 -> Kế toán | F10: 15 | G10: =F10+$G$7 -> 45930
B11: =B10+1 -> 5 | C11: Kế hoạch sản xuất | D11: =IF(B3="EN","Production","Bộ phận sản xuất") -> Bộ phận sản xuất | E11: =E10 -> Kế toán | F11: 20 | G11: =F11+$G$7 -> 45935
B12: =B11+1 -> 6 | C12: Kế hoạch biến phí sản xuất | D12: =E12 -> Kế toán | E12: =E11 -> Kế toán | F12: 20 | G12: =F12+$G$7 -> 45935
B13: =B12+1 -> 7 | C13: Kế hoạch nhân sự (số lượng nhân sự, quỹ lương, chi phí đào tạo,...) | D13: =IF(B3="EN","HR","Phòng nhân sự") -> Phòng nhân sự | E13: =E12 -> Kế toán | F13: 30 | G13: =F13+$G$7 -> 45945
B14: =B13+1 -> 8 | C14: Ngân sách đầu tư | D14: =E7 -> Tất cả | E14: =E13 -> Kế toán | F14: 30 | G14: =F14+$G$7 -> 45945
B15: =B14+1 -> 9 | C15: Ngân sách chi phí sản xuất (không bao gồm lương) | D15: =D11 -> Bộ phận sản xuất | E15: =E14 -> Kế toán | F15: 30 | G15: =F15+$G$7 -> 45945
B16: =B15+1 -> 10 | C16: Ngân sách chi phí bán hàng & chí phí quản lý (không bao gồm lương) | D16: =D14 -> Tất cả | E16: =E15 -> Kế toán | F16: 30 | G16: =F16+$G$7 -> 45945
B17: =B16+1 -> 11 | C17: Tổng hợp kết quả ngân sách mỗi công ty | D17: Kế toán quản trị | E17: KTT/GĐTC | F17: 45 | G17: =F17+$G$7 -> 45960
B18: 12 | C18: Trình bày kết quả ngân sách của mỗi công ty đến TGĐ (Bottom up) | D18: KTT/GĐTC | E18: TGĐ | F18: 50 | G18: =F18+$G$7 -> 45965
B19: 13 | C19: Trình bày kết quả ngân sách của mỗi công ty đến TGĐ (Top down) | D19: KTT/GĐTC | E19: TGĐ | F19: 55 | G19: =F19+$G$7 -> 45970
B20: 14 | C20: Trình bày kết quả ngân sách của mỗi công ty đến TGĐ (Chính thức) | D20: KTT/GĐTC | E20: TGĐ | F20: 62 | G20: =F20+$G$7 -> 45977
B21: 15 | C21: Hợp nhất ngân sách cho toàn bộ DT Group | D21: KTQT holding | E21: GĐTC holding | F21: 70 | G21: =F21+$G$7 -> 45985
B22: 16 | C22: Trình bày kết quả ngân sách hợp nhất cho toàn bộ DT Group | D22: GĐTC holding | E22: TGĐ | F22: 75 | G22: =F22+$G$7 -> 45990

Sheet Thongtin
B2: STT | C2: Nội dung | D2: Nguồn cung cấp dữ liệu | E2: Nguồn thông tin liên quan | F2: Thời gian cần dữ liệu | H2: STT | I2: Màu sheet | J2: Thông tin
B3: 1 | C3: Ban hành Nhóm-Loại NVL Trạm thu mua | D3: GĐĐH Trạm - DTR | E3: 1. BGĐ DTR 2. Phòng cung ứng DTR | F3: 45940 | H3: 1 | J3: Kết quả kinh doanh tổng hợp
B4: 2 | C4: Ban hành Sản lượng Trạm thu mua | D4: GĐĐH Trạm - DTR | E4: 1. BGĐ DTR 2. Phòng cung ứng DTR | F4: 45940 | H4: 2 | J4: Kết quả kinh doanh PET và HD
B5: 3 | C5: Ban hành đơn giá MUA từng loại NVL | D5: GĐĐH Trạm - DTR | E5: 1. Phòng cung ứng DTR đề xuất KH năm 2026 (Dữ liệu theo từng tháng) 2. KTT các trạm cung cấp đơn giá bình quân thực tế mua theo từng tháng ( Dữ liệu năm 2023-2024-2025) 3. Đơn giá BGĐ-DTR duyệt mua trong năm 2025 (Dữ liệu theo từng tháng) | F5: 45940 | H5: 3 | J5: Kết quả kinh doanh PET và HD
B6: 4 | C6: Ban hành đơn giá BÁN từng loại thành phẩm | D6: GĐĐH Trạm - DTR | E6: 1. BGĐ DTR 2. Phòng cung ứng DTR | F6: 45940 | H6: 4 | J6: Ban hành Định mức về Công suất MMTB - Định mức về CP phục vụ sản xuất - Định biên Nhân sự
B7: 5 | C7: Kế hoạch đầu tư CAPEX tại Trạm => Ảnh hưởng đến Sản phẩm và TCKT Trạm cung cấp đến DTR | D7: GĐĐH Trạm - DTR | E7: 1. BGĐ DTR 2. Phòng kỹ thuật DTR 3. Phòng mua hàng DTR | F7: 45940 | H7: 5 | J7: Ban hành sản lượng - đơn giá - Cơ cấu về: NVL - Thành phẩm - Hao hụt - Bán hàng
H8: 6 | J8: Nhóm Chi phí:CP Sản xuất - CP Bán hàng - CP Quản lý (Công thức từ: Định mức - Lương - PB_TSCD - PB_CPTT - nhóm NVL - Phát sinh trực tiếp)
H9: 7 | J9: Cập nhật TSCĐ - CPTT năm trước chuyển sang và Capex 2026
H10: 8 | I10: … | J10: Thông tin khác

Sheet KH hanh dong
A3: KẾ HOẠCH KINH DOANH 2026
A4: Nguồn yêu cầu: GĐTC-DTR
A5: STT | B5: Nhóm công việc | C5: Kế hoạch hành động | D5: Người thực hiện | E5: Thời gian hoàn thành tính toán và xác lập mục tiêu 2026 | F5: Hiện trạng / vướng mắt / giải pháp (tại thời điểm tháng 10/2025) | G5: Mục tiêu 2026 (rolling hàng tháng) | U5: KHNS 2026 | V5: Thực hiện 2025 | W5: Tăng/giảm vs KHNS 2026
G6: Đánh giá KQ đạt được (cập nhật đến thời điểm báo cáo) | H6: Mục tiêu T1 | I6: Mục tiêu T2 | J6: Mục tiêu T3 | K6: Mục tiêu T4 | L6: Mục tiêu T5 | M6: Mục tiêu T6 | N6: Mục tiêu T7 | O6: Mục tiêu T8 | P6: Mục tiêu T9 | Q6: Mục tiêu T10 | R6: Mục tiêu T11 | S6: Mục tiêu T12 | T6: Dự báo KQ 2026 | W6: Theo số tiền phát sinh | X6: Theo mức độ hoạt động | Y6: %
A7: A | B7: HOẠT ĐỘNG MUA HÀNG
A8: 1 | B8: Đáp ứng sản lượng mua cho Trạm | C8: Lập mục tiêu sản lượng mua để Trạm đạt hòa vốn và có lãi.
C9: Xây dựng các trạm vệ tinh để tăng lượng chai về Trạm.
C10: Phát triển thêm các NCC liên kết ở tỉnh.
C11: Đàm phán tăng sản lượng mua từ các NCC đang giao dịch.
A12: 2 | B12: Cải thiện dịch vụ khách hàng | C12: Cải thiện thời gian nhận hàng
C13: Thanh toán trong ngày và cuối tuần
A14: B | B14: HOẠT ĐỘNG BÁN HÀNG
A15: 1 | B15: Giá bán về DTR | C15: Áp dụng cơ cấu giá mới từ Tháng 9/2025
A16: 2 | B16: Kiểm soát tồn kho thành phẩm | C16: Lập KH giao hàng về DTR hàng ngày, ngày cuối tháng không để tồn kho và xuất hóa đơn 100%
A17: 3 | B17: Chi phí thuê xe vận chuyển | C17: - Đàm phán giảm giá, đề nghị NCC sử dụng phương tiện vận chuyển hiệu quả. - Tìm NCC mới cạnh tranh.
A18: C | B18: HOẠT ĐỘNG CẢI TIẾN CHI PHÍ
A19: I | B19: Chi phí nguyên vật liệu
A20: 1 | B20: Kiểm soát lượng mua, giá mua | C20: - Lập mục tiêu tồn kho tối thiểu 10 ngày sản xuất và phối hợp P.Cung ứng lập KH mua hàng theo tuần. - Kiểm soát giá mua tương ứng với từng mức chất lượng chai.
A21: 2 | B21: Kiểm soát chất lượng NVL, hao hụt | C21: Kiểm soát chất lượng chai (tỷ lệ chai nguyên liệu - Chai xá/xô tuyển, thành phần chai sau phân loại, tỷ lệ tạp chất).
A22: 3 | B22: Kiểm soát định mức vật tư sản xuất (hóa chất, dây đai, vật tư kỹ thuật …) | C22: - Thống kê và thực hiện cải tiến tiêu hao. - Mua tập trung tại P.Mua hàng DTR.
A23: 4 | B23: Xử lý phế liệu, phó sản thu hồi | C23: Phân loại phế liệu thành 2 nhóm: - Nhóm hàng hóa (nhãn, bao jumbo, kim loại,…): tìm đơn vị thu mua giá cao - Nhóm rác thải công nghiệp (bùn, hỗn hợp tạp chất): thuê thu gom
A24: II | B24: Chi phí nhân công
A25: 1 | B25: Định mức NCTT | C25: - Kiểm soát định mức NCTT theo chuyền/công đoạn. - Thực hiện tiêu chuẩn hóa/tự động hóa MMTB để giảm nhân công, tăng năng suất. - Tăng số lượng lao động thời vụ. - Tính toán phương án trả lương/ thưởng theo sản lượng.
A26: 2 | B26: Năng suất lao động | C26: - Lập mục tiêu tăng thời gian sản xuất từ 8 giờ/ngày -> 12 giờ -> 16 giờ -> 24 giờ.
A27: III | B27: Chi phí sản xuất chung
A28: 1 | B28: Chi phí điện | C28: - Phối hợp kỹ thuật bảo trì MMTB đảm bảo hoạt động liên tục -> tăng hiệu quả sử dụng điện và tăng năng suất lao động.
A29: 2 | B29: Chi phí xe nâng | C29: - Chuyển dần xe nâng dầu từ DTR về các Trạm (các xe của trạm sửa chữa nhiều sẽ thanh lý)
A30: 3 | B30: Chi phí khấu hao TSCĐ, CCDC, chi phí phân bổ khác | C30: - Thống kê, đánh giá lại hiệu quả sử dụng tất cả TS. - Tách chi phí khấu hao/phân bổ không phục vụ trực tiếp hoạt động để đánh giá hiệu quả KD thực của trạm.
A31: 4 | B31: Chi phí thuê xưởng | C31: - Tìm vị trí và đề xuất phương án di dời nhà máy để giảm tiền thu, tăng hiệu quả thu mua.
A32: IV | B32: Chi phí quản lý
A33: 1 | B33: Chi phí lương (gồm gián tiếp SX) | C33: Soát xét định biên và kế hoạch tuyển dụng, lập mục tiêu giảm định biên đến cuối 2026
A34: 2 | B34: Chi phí theo mục phí (ngoài chi phí lương) | C34: - Lập danh mục chi phí dịch vụ thuê/mua trả tiền định kỳ (nhóm dịch vụ/phòng ban quản lý, tên NCC, hợp đồng mới nhất, tiền trả định kỳ tháng/quý/năm, thời hạn công nợ) -> đàm phán từng NC giảm giá và tìm NCC mới cạnh tranh - XD định mức chi phí cho các khoản mục có thể xác lập định mức - Phân tích chi phí, nguyên nhân tăng/giảm và giải pháp cải tiến.
A35: V | B35: Mục tiêu lợi nhuận
A36: 1 | B36: Lợi nhuận kế hoạch đến cuối năm 2026 | C36: Sau khi đánh giá, xác lập các mục tiêu bên trên, tính toán lợi nhuận kế hoạch đến cuối năm 2026

Sheet KQKD Tong hop
E1: =E29+E33+E40 -> 22617107745 | R1: =R29+R33+R40 -> 2.3161896e+10
R2: =SUM(R24,R30,R41) -> 1.6873505e+10
B3: MỤC TIÊU KẾT QUẢ KINH DOANH NĂM 2026 | F3: =F17/F5 -> 13307.439 | G3: =G17/G5 -> 13277.288 | H3: =H17/H5 -> 13317.825 | I3: =I17/I5 -> 13140.123 | J3: =J17/J5 -> 13150.499 | K3: =K17/K5 -> 13155.331 | L3: =L17/L5 -> 13178.937 | M3: =M17/M5 -> 13179.046 | N3: =N17/N5 -> 13117.508 | O3: ='1.NVL Chai'!Q16*11000 -> 14300000000 | P3: ='1.NVL Chai'!R16*11000 -> 14300000000 | Q3: ='1.NVL Chai'!S16*11000 -> 14300000000 | R3: ĐVT: Triệu đồng
B4: STT | C4: Mục phí | D4: Thực tế năm 2024 | E4: KQKD 2025 | F4: T1 | G4: T2 | H4: T3 | I4: T4 | J4: T5 | K4: T6 | L4: T7 | M4: T8 | N4: T9 | O4: T10 | P4: T11 | Q4: T12 | R4: KH 2026
B5: 1 | C5: SẢN LƯỢNG BÁN (TẤN) | D5: ='KQKD PET'!E5 -> 0 | E5: ='KQKD PET'!F5+'KQKD HD'!F5 -> 9805731 | F5: =F6+F7+F8 -> 760725 | G5: =G6+G7+G8 -> 591675 | H5: =H6+H7+H8 -> 845250 | I5: =I6+I7+I8 -> 1055250 | J5: =J6+J7+J8 -> 1055250 | K5: =K6+K7+K8 -> 1055250 | L5: =L6+L7+L8 -> 1055250 | M5: =M6+M7+M8 -> 1055250 | ... Q5: =Q6+Q7+Q8 -> 1057212 | R5: =SUM(F5:Q5) -> 11700786
B6: 1.1 | C6: Chai PET | D6: ='KQKD PET'!E6 -> 0 | E6: ='KQKD PET'!F6 -> 7883386 | F6: ='KQKD PET'!G6+'KQKD HD'!G6 -> 519750 | G6: ='KQKD PET'!H6+'KQKD HD'!H6 -> 404250 | H6: ='KQKD PET'!I6+'KQKD HD'!I6 -> 577500 | I6: ='KQKD PET'!J6+'KQKD HD'!J6 -> 720000 | J6: ='KQKD PET'!K6+'KQKD HD'!K6 -> 720000 | K6: ='KQKD PET'!L6+'KQKD HD'!L6 -> 720000 | L6: ='KQKD PET'!M6+'KQKD HD'!M6 -> 720000 | M6: ='KQKD PET'!N6+'KQKD HD'!N6 -> 720000 | ... Q6: ='KQKD PET'!R6+'KQKD HD'!R6 -> 78000 | R6: =SUM(F6:Q6) -> 6055500
B7: 1.2 | C7: Vảy PET | D7: ='KQKD PET'!E7 -> 0 | E7: ='KQKD PET'!F7 -> 1688932 | F7: ='KQKD PET'!G7+'KQKD HD'!G7 -> 240975 | G7: ='KQKD PET'!H7+'KQKD HD'!H7 -> 187425 | H7: ='KQKD PET'!I7+'KQKD HD'!I7 -> 267750 | I7: ='KQKD PET'!J7+'KQKD HD'!J7 -> 335250 | J7: ='KQKD PET'!K7+'KQKD HD'!K7 -> 335250 | K7: ='KQKD PET'!L7+'KQKD HD'!L7 -> 335250 | L7: ='KQKD PET'!M7+'KQKD HD'!M7 -> 335250 | M7: ='KQKD PET'!N7+'KQKD HD'!N7 -> 335250 | ... Q7: ='KQKD PET'!R7+'KQKD HD'!R7 -> 979212 | R7: =SUM(F7:Q7) -> 5645286
B8: 1.3 | C8: Vảy HD | D8: ='KQKD PET'!E8 -> 0 | E8: ='KQKD HD'!F5 -> 233413 | F8: ='KQKD PET'!G8+'KQKD HD'!G8 -> 0 | G8: ='KQKD PET'!H8+'KQKD HD'!H8 -> 0 | H8: ='KQKD PET'!I8+'KQKD HD'!I8 -> 0 | I8: ='KQKD PET'!J8+'KQKD HD'!J8 -> 0 | J8: ='KQKD PET'!K8+'KQKD HD'!K8 -> 0 | K8: ='KQKD PET'!L8+'KQKD HD'!L8 -> 0 | L8: ='KQKD PET'!M8+'KQKD HD'!M8 -> 0 | M8: ='KQKD PET'!N8+'KQKD HD'!N8 -> 0 | ... Q8: ='KQKD PET'!R8+'KQKD HD'!R8 -> 0 | R8: =SUM(F8:Q8) -> 0
B9: 1.4 | C9: Dây Đai PET | F9: ='KDKD DAY DAI'!G6 -> 0 | G9: ='KDKD DAY DAI'!H6 -> 0 | H9: ='KDKD DAY DAI'!I6 -> 0 | I9: ='KDKD DAY DAI'!J6 -> 0 | J9: ='KDKD DAY DAI'!K6 -> 0 | K9: ='KDKD DAY DAI'!L6 -> 0 | L9: ='KDKD DAY DAI'!M6 -> 0 | M9: ='KDKD DAY DAI'!N6 -> 0 | ... Q9: ='KDKD DAY DAI'!R6 -> 0 | R9: =SUM(F9:Q9) -> 0
B10: 2 | C10: DOANH THU | D10: ='KQKD PET'!E9 -> 64684339330 | E10: ='KQKD PET'!F9+'KQKD HD'!F9+126341842 -> 173927684403 | F10: =SUM(F11:F14) -> 11515218750 | G10: =SUM(G11:G14) -> 8956281250 | H10: =SUM(H11:H14) -> 12794687500 | I10: =SUM(I11:I14) -> 15974312500 | J10: =SUM(J11:J14) -> 15974312500 | K10: =SUM(K11:K14) -> 15974312500 | L10: =SUM(L11:L14) -> 15974312500 | M10: =SUM(M11:M14) -> 15974312500 | ... Q10: =SUM(Q11:Q14) -> 17334395000 | R10: =SUM(F10:Q10) -> 181115247500
B11: 2.1 | C11: Chai PET | D11: ='KQKD PET'!E10 -> 64684339330 | E11: ='KQKD PET'!F10+'KQKD HD'!F10+126341842 -> 140227158729 | F11: ='KQKD PET'!G10+'KQKD HD'!G10 -> 7626150000 | G11: ='KQKD PET'!H10+'KQKD HD'!H10 -> 5931450000 | H11: ='KQKD PET'!I10+'KQKD HD'!I10 -> 8473500000 | I11: ='KQKD PET'!J10+'KQKD HD'!J10 -> 10563750000 | J11: ='KQKD PET'!K10+'KQKD HD'!K10 -> 10563750000 | K11: ='KQKD PET'!L10+'KQKD HD'!L10 -> 10563750000 | L11: ='KQKD PET'!M10+'KQKD HD'!M10 -> 10563750000 | M11: ='KQKD PET'!N10+'KQKD HD'!N10 -> 10563750000 | ... Q11: ='KQKD PET'!R10+'KQKD HD'!R10 -> 924300000 | R11: =SUM(F11:Q11) -> 88186500000
B12: 2.2 | C12: Vảy PET | D12: ='KQKD PET'!E11 -> 0 | E12: ='KQKD PET'!F11+'KQKD HD'!F11 -> 30731028704 | F12: ='KQKD PET'!G11+'KQKD HD'!G11 -> 3889068750 | G12: ='KQKD PET'!H11+'KQKD HD'!H11 -> 3024831250 | H12: ='KQKD PET'!I11+'KQKD HD'!I11 -> 4321187500 | I12: ='KQKD PET'!J11+'KQKD HD'!J11 -> 5410562500 | J12: ='KQKD PET'!K11+'KQKD HD'!K11 -> 5410562500 | K12: ='KQKD PET'!L11+'KQKD HD'!L11 -> 5410562500 | L12: ='KQKD PET'!M11+'KQKD HD'!M11 -> 5410562500 | ... Q12: ='KQKD PET'!R11+'KQKD HD'!R11 -> 16410095000 | R12: =SUM(F12:Q12) -> 92928747500
B13: 2.3 | C13: Vảy HD | D13: ='KQKD PET'!E12 -> 0 | E13: ='KQKD PET'!F12+'KQKD HD'!F12 -> 2969496970 | F13: ='KQKD PET'!G12+'KQKD HD'!G12 -> 0 | G13: ='KQKD PET'!H12+'KQKD HD'!H12 -> 0 | H13: ='KQKD PET'!I12+'KQKD HD'!I12 -> 0 | I13: ='KQKD PET'!J12+'KQKD HD'!J12 -> 0 | J13: ='KQKD PET'!K12+'KQKD HD'!K12 -> 0 | K13: ='KQKD PET'!L12+'KQKD HD'!L12 -> 0 | L13: ='KQKD PET'!M12+'KQKD HD'!M12 -> 0 | ... Q13: ='KQKD PET'!R12+'KQKD HD'!R12 -> 0 | R13: =SUM(F13:Q13) -> 0
B14: 2.4 | C14: Dây Đai PET | F14: ='KDKD DAY DAI'!G10 -> 0 | G14: ='KDKD DAY DAI'!H10 -> 0 | H14: ='KDKD DAY DAI'!I10 -> 0 | I14: ='KDKD DAY DAI'!J10 -> 0 | J14: ='KDKD DAY DAI'!K10 -> 0 | K14: ='KDKD DAY DAI'!L10 -> 0 | L14: ='KDKD DAY DAI'!M10 -> 0 | M14: ='KDKD DAY DAI'!N10 -> 0 | ... Q14: ='KDKD DAY DAI'!R10 -> 0 | R14: =SUM(F14:Q14) -> 0
B15: 2.4 | C15: Khác | D15: ='KQKD PET'!E13 -> 0 | E15: ='KQKD PET'!F13+'KQKD HD'!F13 -> 0 | F15: ='KQKD PET'!G13+'KQKD HD'!G13 -> 0 | G15: ='KQKD PET'!H13+'KQKD HD'!H13 -> 0 | H15: ='KQKD PET'!I13+'KQKD HD'!I13 -> 0 | I15: ='KQKD PET'!J13+'KQKD HD'!J13 -> 0 | J15: ='KQKD PET'!K13+'KQKD HD'!K13 -> 0 | K15: ='KQKD PET'!L13+'KQKD HD'!L13 -> 0 | L15: ='KQKD PET'!M13+'KQKD HD'!M13 -> 0 | ... Q15: ='KQKD PET'!R13+'KQKD HD'!R13 -> 0 | R15: =SUM(F15:Q15) -> 0
B16: 3 | C16: BIẾN PHÍ | D16: ='KQKD PET'!E14 -> 0 | E16: ='KQKD PET'!F14+'KQKD HD'!F14 -> 1.5804639e+11 | F16: =F17+F25 -> 1.0382402e+10 | G16: =G17+G25 -> 8.057362e+09 | H16: =H17+H25 -> 1.1544781e+10 | I16: =I17+I25 -> 1.4225483e+10 | J16: =J17+J25 -> 1.4236432e+10 | K16: =K17+K25 -> 1.4241531e+10 | L16: =L17+L25 -> 1.4266442e+10 | M16: =M17+M25 -> 1.4266557e+10 | ... Q16: =Q17+Q25 -> 1.5196076e+10 | R16: =SUM(F16:Q16) -> 1.6103167e+11
B17: 3.1 | C17: BIẾN PHÍ SẢN XUẤT | D17: ='KQKD PET'!E15 -> 0 | E17: ='KQKD PET'!F15+'KQKD HD'!F15 -> 1.5491849e+11 | F17: =F18+F22+F23+F24 -> 1.0123301e+10 | G17: =G18+G22+G23+G24 -> 7.8558393e+09 | H17: =H18+H22+H23+H24 -> 1.1256891e+10 | I17: =I18+I22+I23+I24 -> 1.3866114e+10 | J17: =J18+J22+J23+J24 -> 1.3877064e+10 | K17: =K18+K22+K23+K24 -> 1.3882163e+10 | L17: =L18+L22+L23+L24 -> 1.3907073e+10 | M17: =M18+M22+M23+M24 -> 1.3907188e+10 | ... Q17: =Q18+Q22+Q23+Q24 -> 1.4866419e+10 | R17: =SUM(F17:Q17) -> 1.5713797e+11
B18: 3.1.1 | C18: Nguyên vật liệu chính (nhựa, gồm hao hụt) | D18: ='KQKD PET'!E16 -> 0 | E18: ='KQKD PET'!F16+'KQKD HD'!F16 -> 1.4456918e+11 | F18: ='KQKD PET'!G16+'KQKD HD'!G16+'KDKD DAY DAI'!G16 -> 9000000000 | G18: ='KQKD PET'!H16+'KQKD HD'!H16+'KDKD DAY DAI'!H16 -> 7000000000 | H18: ='KQKD PET'!I16+'KQKD HD'!I16+'KDKD DAY DAI'!I16 -> 10000000000 | I18: ='KQKD PET'!J16+'KQKD HD'!J16+'KDKD DAY DAI'!J16 -> 12500000000 | J18: ='KQKD PET'!K16+'KQKD HD'!K16+'KDKD DAY DAI'!K16 -> 12500000000 | K18: ='KQKD PET'!L16+'KQKD HD'!L16+'KDKD DAY DAI'!L16 -> 12500000000 | L18: ='KQKD PET'!M16+'KQKD HD'!M16+'KDKD DAY DAI'!M16 -> 12500000000 | M18: ='KQKD PET'!N16+'KQKD HD'!N16+'KDKD DAY DAI'!N16 -> 12500000000 | ... Q18: ='KQKD PET'!R16+'KQKD HD'!R16+'KDKD DAY DAI'!R16 -> 13000000000 | R18: =SUM(F18:Q18) -> 140000000000
B19: 3.1.2 | C19: Trong đó: i/ Hao hụt CĐ phân loại chai | D19: ='KQKD PET'!E17 -> 0 | E19: ='KQKD PET'!F17 -> 1.3748236e+10 | F19: ='KQKD PET'!G17+'KQKD HD'!G17 -> 1125000000 | G19: ='KQKD PET'!H17+'KQKD HD'!H17 -> 875000000 | H19: ='KQKD PET'!I17+'KQKD HD'!I17 -> 1250000000 | I19: ='KQKD PET'!J17+'KQKD HD'!J17 -> 1575000000 | J19: ='KQKD PET'!K17+'KQKD HD'!K17 -> 1575000000 | K19: ='KQKD PET'!L17+'KQKD HD'!L17 -> 1575000000 | L19: ='KQKD PET'!M17+'KQKD HD'!M17 -> 1575000000 | M19: ='KQKD PET'!N17+'KQKD HD'!N17 -> 1575000000 | ... Q19: ='KQKD PET'!R17+'KQKD HD'!R17 -> 1638000000 | R19: =SUM(F19:Q19) -> 17614000000
C20: ii/ Hao hụt CĐ băm vảy | D20: ='KQKD PET'!E18 -> 0 | E20: ='KQKD PET'!F18 -> 1.715399e+09 | F20: ='KQKD PET'!G18+'KQKD HD'!G18 -> 267750000 | G20: ='KQKD PET'!H18+'KQKD HD'!H18 -> 208250000 | H20: ='KQKD PET'!I18+'KQKD HD'!I18 -> 297500000 | I20: ='KQKD PET'!J18+'KQKD HD'!J18 -> 372500000 | J20: ='KQKD PET'!K18+'KQKD HD'!K18 -> 372500000 | K20: ='KQKD PET'!L18+'KQKD HD'!L18 -> 372500000 | L20: ='KQKD PET'!M18+'KQKD HD'!M18 -> 372500000 | M20: ='KQKD PET'!N18+'KQKD HD'!N18 -> 372500000 | ... Q20: ='KQKD PET'!R18+'KQKD HD'!R18 -> 1192360000 | R20: =SUM(F20:Q20) -> 6585580000
B21: 3.1.3 | C21: % chi phí nguyên liệu/doanh thu | D21: ='KQKD PET'!E19 -> 0 | E21: =E18/E10 -> 0.83120281 | F21: =F18/F10 -> 0.78157438 | G21: =G18/G10 -> 0.78157438 | H21: =H18/H10 -> 0.78157438 | I21: =I18/I10 -> 0.78250629 | J21: =J18/J10 -> 0.78250629 | K21: =K18/K10 -> 0.78250629 | L21: =L18/L10 -> 0.78250629 | ... R21: =R18/R10 -> 0.77298848
B22: 3.1.4 | C22: Vật tư tiêu hao(dao băm, dao tách nhãn, bùn, nhãn, dao jumbo, dây đai) | D22: ='KQKD PET'!E20 -> 0 | E22: ='KQKD PET'!F20+'KQKD HD'!F20 -> 2.7789895e+09 | F22: ='KQKD PET'!G20+'KQKD HD'!G20+'KDKD DAY DAI'!G20 -> 3.0802692e+08 | G22: ='KQKD PET'!H20+'KQKD HD'!H20+'KDKD DAY DAI'!H20 -> 2.3889538e+08 | H22: ='KQKD PET'!I20+'KQKD HD'!I20+'KDKD DAY DAI'!I20 -> 3.3811419e+08 | I22: ='KQKD PET'!J20+'KQKD HD'!J20+'KDKD DAY DAI'!J20 -> 4.2242376e+08 | J22: ='KQKD PET'!K20+'KQKD HD'!K20+'KDKD DAY DAI'!K20 -> 4.2112376e+08 | K22: ='KQKD PET'!L20+'KQKD HD'!L20+'KDKD DAY DAI'!L20 -> 4.2078209e+08 | L22: ='KQKD PET'!M20+'KQKD HD'!M20+'KDKD DAY DAI'!M20 -> 4.2015876e+08 | M22: ='KQKD PET'!N20+'KQKD HD'!N20+'KDKD DAY DAI'!N20 -> 4.2027376e+08 | ... Q22: ='KQKD PET'!R20+'KQKD HD'!R20+'KDKD DAY DAI'!R20 -> 6.7023156e+08 | R22: =SUM(F22:Q22) -> 5.4218121e+09
B23: 3.1.5 | C23: Điện sản xuất | D23: ='KQKD PET'!E21 -> 0 | E23: ='KQKD PET'!F21+'KQKD HD'!F21 -> 1409501660 | F23: ='KQKD PET'!G21+'KQKD HD'!G21+'KDKD DAY DAI'!G21 -> 1.1567843e+08 | G23: ='KQKD PET'!H21+'KQKD HD'!H21+'KDKD DAY DAI'!H21 -> 89972114 | H23: ='KQKD PET'!I21+'KQKD HD'!I21+'KDKD DAY DAI'!I21 -> 1.2853159e+08 | I23: ='KQKD PET'!J21+'KQKD HD'!J21+'KDKD DAY DAI'!J21 -> 1.6071292e+08 | J23: ='KQKD PET'!K21+'KQKD HD'!K21+'KDKD DAY DAI'!K21 -> 1.6071292e+08 | K23: ='KQKD PET'!L21+'KQKD HD'!L21+'KDKD DAY DAI'!L21 -> 1.6071292e+08 | L23: ='KQKD PET'!M21+'KQKD HD'!M21+'KDKD DAY DAI'!M21 -> 1.6071292e+08 | M23: ='KQKD PET'!N21+'KQKD HD'!N21+'KDKD DAY DAI'!N21 -> 1.6071292e+08 | ... Q23: ='KQKD PET'!R21+'KQKD HD'!R21+'KDKD DAY DAI'!R21 -> 3.4009604e+08 | R23: =SUM(F23:Q23) -> 2.3187478e+09
B24: 3.1.6 | C24: Nhân công trực tiếp | D24: ='KQKD PET'!E22 -> 0 | E24: ='KQKD PET'!F22+'KQKD HD'!F22 -> 6160821040 | F24: ='KQKD PET'!G22+'KQKD HD'!G22+'KDKD DAY DAI'!G22 -> 6.995961e+08 | G24: ='KQKD PET'!H22+'KQKD HD'!H22+'KDKD DAY DAI'!H22 -> 5.2697176e+08 | H24: ='KQKD PET'!I22+'KQKD HD'!I22+'KDKD DAY DAI'!I22 -> 7.902456e+08 | I24: ='KQKD PET'!J22+'KQKD HD'!J22+'KDKD DAY DAI'!J22 -> 7.8297773e+08 | J24: ='KQKD PET'!K22+'KQKD HD'!K22+'KDKD DAY DAI'!K22 -> 7.9522688e+08 | K24: ='KQKD PET'!L22+'KQKD HD'!L22+'KDKD DAY DAI'!L22 -> 8.0066773e+08 | L24: ='KQKD PET'!M22+'KQKD HD'!M22+'KDKD DAY DAI'!M22 -> 826201238 | M24: ='KQKD PET'!N22+'KQKD HD'!N22+'KDKD DAY DAI'!N22 -> 826201238 | ... Q24: ='KQKD PET'!R22+'KQKD HD'!R22+'KDKD DAY DAI'!R22 -> 8.5609124e+08 | R24: =SUM(F24:Q24) -> 9.3974111e+09 | S24: 9050781100
B25: 3.2 | C25: BIẾN PHÍ BÁN HÀNG | D25: ='KQKD PET'!E23 -> 0 | E25: ='KQKD PET'!F23+'KQKD HD'!F23 -> 3127900000 | F25: =F26 -> 259100625 | G25: =G26 -> 2.0152271e+08 | H25: =H26 -> 2.8788958e+08 | I25: =I26 -> 359368750 | J25: =J26 -> 359368750 | K25: =K26 -> 359368750 | L25: =L26 -> 359368750 | M25: =M26 -> 359368750 | ... Q25: =Q26 -> 3.2965703e+08 | R25: =SUM(F25:Q25) -> 3.8936965e+09 | S25: =S24-R24 -> -3.4663001e+08
C26: Chi phí vận chuyển | D26: ='KQKD PET'!E24 -> 0 | E26: ='KQKD PET'!F24+'KQKD HD'!F24 -> 3127900000 | F26: ='KQKD PET'!G24+'KQKD HD'!G24+'KDKD DAY DAI'!G24 -> 259100625 | G26: ='KQKD PET'!H24+'KQKD HD'!H24+'KDKD DAY DAI'!H24 -> 2.0152271e+08 | H26: ='KQKD PET'!I24+'KQKD HD'!I24+'KDKD DAY DAI'!I24 -> 2.8788958e+08 | I26: ='KQKD PET'!J24+'KQKD HD'!J24+'KDKD DAY DAI'!J24 -> 359368750 | J26: ='KQKD PET'!K24+'KQKD HD'!K24+'KDKD DAY DAI'!K24 -> 359368750 | K26: ='KQKD PET'!L24+'KQKD HD'!L24+'KDKD DAY DAI'!L24 -> 359368750 | L26: ='KQKD PET'!M24+'KQKD HD'!M24+'KDKD DAY DAI'!M24 -> 359368750 | M26: ='KQKD PET'!N24+'KQKD HD'!N24+'KDKD DAY DAI'!N24 -> 359368750 | ... Q26: ='KQKD PET'!R24+'KQKD HD'!R24+'KDKD DAY DAI'!R24 -> 3.2965703e+08 | R26: =SUM(F26:Q26) -> 3.8936965e+09
B27: 4 | C27: LÃI SAU BIẾN PHÍ | D27: ='KQKD PET'!E25 -> 64684339330 | E27: ='KQKD PET'!F25+'KQKD HD'!F25+126341842 -> 1.5881292e+10 | F27: =F10-F16 -> 1.1328167e+09 | G27: =G10-G16 -> 8.9891929e+08 | H27: =H10-H16 -> 1.2499065e+09 | I27: =I10-I16 -> 1.7488293e+09 | J27: =J10-J16 -> 1.7378802e+09 | K27: =K10-K16 -> 1.732781e+09 | L27: =L10-L16 -> 1.7078708e+09 | M27: =M10-M16 -> 1.7077558e+09 | ... Q27: =Q10-Q16 -> 2.1383191e+09 | R27: =SUM(F27:Q27) -> 2.008358e+10 | S27: =(R29+R33+R40)/R28 -> 2.0887573e+11 | T27: =S27/T10 -> #DIV/0!
B28: 4.1 | C28: % lãi biến phí/doanh thu | D28: ='KQKD PET'!E26 -> 0 | E28: =E27/E10 -> 0.091309744 | F28: =F27/F10 -> 0.09837561 | G28: =G27/G10 -> 0.10036747 | H28: =H27/H10 -> 0.097689493 | I28: =I27/I10 -> 0.1094776 | J28: =J27/J10 -> 0.10879217 | K28: =K27/K10 -> 0.10847296 | L28: =L27/L10 -> 0.10691357 | ... R28: =R27/R10 -> 0.1108884 | S28: =S27/12 -> 1.7406311e+10 | T28: =T27/0.85 -> #DIV/0!
B29: 5 | C29: CHI PHÍ SẢN XUẤT CHUNG | D29: ='KQKD PET'!E27 -> 0 | E29: ='KQKD PET'!F27+'KQKD HD'!F27 -> 11547786451 | F29: =F30+F31+F32 -> 9.8327029e+08 | G29: =G30+G31+G32 -> 9.7009247e+08 | H29: =H30+H31+H32 -> 9.4610202e+08 | I29: =I30+I31+I32 -> 9.8519882e+08 | J29: =J30+J31+J32 -> 9.9516998e+08 | K29: =K30+K31+K32 -> 1.0293843e+09 | L29: =L30+L31+L32 -> 1.031294e+09 | M29: =M30+M31+M32 -> 1.0384301e+09 | ... Q29: =Q30+Q31+Q32 -> 1.120583e+09 | R29: =SUM(F29:Q29) -> 1.2401078e+10 | S29: =R29+R33 -> 1.695734e+10 | T29: =T28/12 -> #DIV/0!
B30: 5.1 | C30: Lương gián tiếp Sản xuất | D30: ='KQKD PET'!E28 -> 0 | E30: ='KQKD PET'!F28+'KQKD HD'!F28 -> 3749845944 | F30: ='KQKD PET'!G28+'KQKD HD'!G28+'KDKD DAY DAI'!G28 -> 2.9691432e+08 | G30: ='KQKD PET'!H28+'KQKD HD'!H28+'KDKD DAY DAI'!H28 -> 2.9460366e+08 | H30: ='KQKD PET'!I28+'KQKD HD'!I28+'KDKD DAY DAI'!I28 -> 2.8225475e+08 | I30: ='KQKD PET'!J28+'KQKD HD'!J28+'KDKD DAY DAI'!J28 -> 3.0506017e+08 | J30: ='KQKD PET'!K28+'KQKD HD'!K28+'KDKD DAY DAI'!K28 -> 2.8977549e+08 | K30: ='KQKD PET'!L28+'KQKD HD'!L28+'KDKD DAY DAI'!L28 -> 3.0532267e+08 | L30: ='KQKD PET'!M28+'KQKD HD'!M28+'KDKD DAY DAI'!M28 -> 2.9807777e+08 | M30: ='KQKD PET'!N28+'KQKD HD'!N28+'KDKD DAY DAI'!N28 -> 2.9807777e+08 | ... Q30: ='KQKD PET'!R28+'KQKD HD'!R28+'KDKD DAY DAI'!R28 -> 2.9807777e+08 | R30: =SUM(F30:Q30) -> 3.5686231e+09
B31: 5.2 | C31: Chi phí thuê xưởng | D31: ='KQKD PET'!E29 -> 0 | E31: ='KQKD PET'!F29+'KQKD HD'!F29 -> 5585152224 | F31: ='KQKD PET'!G29+'KQKD HD'!G29 -> 461679352 | G31: ='KQKD PET'!H29+'KQKD HD'!H29 -> 461679352 | H31: ='KQKD PET'!I29+'KQKD HD'!I29 -> 461679352 | I31: ='KQKD PET'!J29+'KQKD HD'!J29 -> 461679352 | J31: ='KQKD PET'!K29+'KQKD HD'!K29 -> 461679352 | K31: ='KQKD PET'!L29+'KQKD HD'!L29 -> 461679352 | L31: ='KQKD PET'!M29+'KQKD HD'!M29 -> 461679352 | ... Q31: ='KQKD PET'!R29+'KQKD HD'!R29 -> 461679352 | R31: =SUM(F31:Q31) -> 5540152224
B32: 5.3 | C32: Chi phí sản xuất (Ngoài lương, BOM, thuê xưởng, khấu hao) | D32: ='KQKD PET'!E30 -> 0 | E32: ='KQKD PET'!F30+'KQKD HD'!F30 -> 2212788283 | F32: ='KQKD PET'!G30+'KQKD HD'!G30+'KDKD DAY DAI'!G30 -> 2.2467662e+08 | G32: ='KQKD PET'!H30+'KQKD HD'!H30+'KDKD DAY DAI'!H30 -> 2.1380946e+08 | H32: ='KQKD PET'!I30+'KQKD HD'!I30+'KDKD DAY DAI'!I30 -> 2.0216791e+08 | I32: ='KQKD PET'!J30+'KQKD HD'!J30+'KDKD DAY DAI'!J30 -> 2.184593e+08 | J32: ='KQKD PET'!K30+'KQKD HD'!K30+'KDKD DAY DAI'!K30 -> 2.4371514e+08 | K32: ='KQKD PET'!L30+'KQKD HD'!L30+'KDKD DAY DAI'!L30 -> 2.6238226e+08 | L32: ='KQKD PET'!M30+'KQKD HD'!M30+'KDKD DAY DAI'!M30 -> 2.7153692e+08 | M32: ='KQKD PET'!N30+'KQKD HD'!N30+'KDKD DAY DAI'!N30 -> 2.7867294e+08 | ... Q32: ='KQKD PET'!R30+'KQKD HD'!R30+'KDKD DAY DAI'!R30 -> 3.6082585e+08 | R32: =SUM(F32:Q32) -> 3.2923026e+09
B33: 6 | C33: CHI PHÍ KHẤU HAO, CCDC | D33: ='KQKD PET'!E31 -> 0 | E33: ='KQKD PET'!F31+'KQKD HD'!F31 -> 7149747131 | F33: ='KQKD PET'!G31+'KQKD HD'!G31 -> 3.7748461e+08 | G33: ='KQKD PET'!H31+'KQKD HD'!H31 -> 3.7748461e+08 | H33: ='KQKD PET'!I31+'KQKD HD'!I31 -> 3.7492098e+08 | I33: ='KQKD PET'!J31+'KQKD HD'!J31 -> 3.7492098e+08 | J33: ='KQKD PET'!K31+'KQKD HD'!K31 -> 3.7492098e+08 | K33: ='KQKD PET'!L31+'KQKD HD'!L31 -> 3.7492098e+08 | L33: ='KQKD PET'!M31+'KQKD HD'!M31 -> 3.7492098e+08 | ... Q33: ='KQKD PET'!R31+'KQKD HD'!R31 -> 3.9228209e+08 | R33: =SUM(F33:Q33) -> 4.5562623e+09
B34: 7 | C34: LỢI NHUẬN GỘP | D34: ='KQKD PET'!E32 -> 64684339330 | E34: ='KQKD PET'!F32+'KQKD HD'!F32+126341842 -> -2.8162412e+09 | F34: =F27-F29-F33 -> -2.2793823e+08 | G34: =G27-G29-G33 -> -4.486578e+08 | H34: =H27-H29-H33 -> -71116452 | I34: =I27-I29-I33 -> 3.8870955e+08 | J34: =J27-J29-J33 -> 3.6778923e+08 | K34: =K27-K29-K33 -> 3.2847575e+08 | L34: =L27-L29-L33 -> 3.0165582e+08 | M34: =M27-M29-M33 -> 2.944048e+08 | ... Q34: =Q27-Q29-Q33 -> 6.2545408e+08 | R34: =SUM(F34:Q34) -> 3.1262398e+09
B35: 7.1 | C35: % lãi gộp/doanh thu | D35: ='KQKD PET'!E33 -> 0 | E35: =E34/E10 -> -0.016192024 | F35: =F34/F10 -> -0.01979452 | G35: =G34/G10 -> -0.050094206 | H35: =H34/H10 -> -0.0055582798 | I35: =I34/I10 -> 0.024333413 | J35: =J34/J10 -> 0.023023791 | K35: =K34/K10 -> 0.020562747 | L35: =L34/L10 -> 0.018883806 | ... R35: =R34/R10 -> 0.017261053
B36: 8 | C36: CHI PHÍ BÁN HÀNG & MKT & R&D | D36: ='KQKD PET'!E34 -> 0 | E36: ='KQKD PET'!F34+'KQKD HD'!F34 -> 0 | F36: =F37+F38+F39 -> 0 | G36: =G37+G38+G39 -> 0 | H36: =H37+H38+H39 -> 0 | I36: =I37+I38+I39 -> 0 | J36: =J37+J38+J39 -> 0 | K36: =K37+K38+K39 -> 0 | L36: =L37+L38+L39 -> 0 | M36: =M37+M38+M39 -> 0 | ... Q36: =Q37+Q38+Q39 -> 0 | R36: =SUM(F36:Q36) -> 0
B37: 8.1 | C37: Lương | D37: ='KQKD PET'!E35 -> 0 | E37: ='KQKD PET'!F35+'KQKD HD'!F35 -> 0 | F37: ='KQKD PET'!G35+'KQKD HD'!G35+'KDKD DAY DAI'!G35 -> 0 | G37: ='KQKD PET'!H35+'KQKD HD'!H35+'KDKD DAY DAI'!H35 -> 0 | H37: ='KQKD PET'!I35+'KQKD HD'!I35+'KDKD DAY DAI'!I35 -> 0 | I37: ='KQKD PET'!J35+'KQKD HD'!J35+'KDKD DAY DAI'!J35 -> 0 | J37: ='KQKD PET'!K35+'KQKD HD'!K35+'KDKD DAY DAI'!K35 -> 0 | K37: ='KQKD PET'!L35+'KQKD HD'!L35+'KDKD DAY DAI'!L35 -> 0 | L37: ='KQKD PET'!M35+'KQKD HD'!M35+'KDKD DAY DAI'!M35 -> 0 | M37: ='KQKD PET'!N35+'KQKD HD'!N35+'KDKD DAY DAI'!N35 -> 0 | ... Q37: ='KQKD PET'!R35+'KQKD HD'!R35+'KDKD DAY DAI'!R35 -> 0 | R37: =SUM(F37:Q37) -> 0
B38: 8.2 | C38: Chi phí bán hàng (ngoài lương, khấu hao) | D38: ='KQKD PET'!E36 -> 0 | E38: ='KQKD PET'!F36+'KQKD HD'!F36 -> 0 | F38: ='KQKD PET'!G36+'KQKD HD'!G36+'KDKD DAY DAI'!G36 -> 0 | G38: ='KQKD PET'!H36+'KQKD HD'!H36+'KDKD DAY DAI'!H36 -> 0 | H38: ='KQKD PET'!I36+'KQKD HD'!I36+'KDKD DAY DAI'!I36 -> 0 | I38: ='KQKD PET'!J36+'KQKD HD'!J36+'KDKD DAY DAI'!J36 -> 0 | J38: ='KQKD PET'!K36+'KQKD HD'!K36+'KDKD DAY DAI'!K36 -> 0 | K38: ='KQKD PET'!L36+'KQKD HD'!L36+'KDKD DAY DAI'!L36 -> 0 | L38: ='KQKD PET'!M36+'KQKD HD'!M36+'KDKD DAY DAI'!M36 -> 0 | M38: ='KQKD PET'!N36+'KQKD HD'!N36+'KDKD DAY DAI'!N36 -> 0 | ... Q38: ='KQKD PET'!R36+'KQKD HD'!R36+'KDKD DAY DAI'!R36 -> 0 | R38: =SUM(F38:Q38) -> 0
B39: 83 | C39: Khấu hao tài sản | D39: ='KQKD PET'!E37 -> 0 | E39: ='KQKD PET'!F37+'KQKD HD'!F37 -> 0 | F39: ='KQKD PET'!G37+'KQKD HD'!G37+'KDKD DAY DAI'!G37 -> 0 | G39: ='KQKD PET'!H37+'KQKD HD'!H37+'KDKD DAY DAI'!H37 -> 0 | H39: ='KQKD PET'!I37+'KQKD HD'!I37+'KDKD DAY DAI'!I37 -> 0 | I39: ='KQKD PET'!J37+'KQKD HD'!J37+'KDKD DAY DAI'!J37 -> 0 | J39: ='KQKD PET'!K37+'KQKD HD'!K37+'KDKD DAY DAI'!K37 -> 0 | K39: ='KQKD PET'!L37+'KQKD HD'!L37+'KDKD DAY DAI'!L37 -> 0 | L39: ='KQKD PET'!M37+'KQKD HD'!M37+'KDKD DAY DAI'!M37 -> 0 | M39: ='KQKD PET'!N37+'KQKD HD'!N37+'KDKD DAY DAI'!N37 -> 0 | ... Q39: ='KQKD PET'!R37+'KQKD HD'!R37+'KDKD DAY DAI'!R37 -> 0 | R39: =SUM(F39:Q39) -> 0
B40: 9 | C40: CHI PHÍ QUẢN LÝ | D40: ='KQKD PET'!E38 -> 0 | E40: ='KQKD PET'!F38+'KQKD HD'!F38 -> 3919574163 | F40: =F41+F42+F43 -> 5.5148923e+08 | G40: =G41+G42+G43 -> 4.8534478e+08 | H40: =H41+H42+H43 -> 5.1455941e+08 | I40: =I41+I42+I43 -> 5.1939125e+08 | J40: =J41+J42+J43 -> 5.0091629e+08 | K40: =K41+K42+K43 -> 6.637032e+08 | L40: =L41+L42+L43 -> 4.8847633e+08 | M40: =M41+M42+M43 -> 5.1885133e+08 | ... Q40: =Q41+Q42+Q43 -> 4.9062235e+08 | R40: =SUM(F40:Q40) -> 6.2045555e+09 | S40: 6.2045555e+09
...

Sheet KQKD PET
H2: 0.153846 | I2: 0.076923 | J2: 0.961538 | K2: 0.153846 | L2: 0.961538 | O2: 0.038462 | P2: 0.038462 | Q2: 0.961538
B3: MỤC TIÊU KẾT QUẢ KINH DOANH NĂM 2026 | G3: ='1.NVL Chai'!H16 -> 900000 | H3: ='1.NVL Chai'!I16 -> 700000 | I3: ='1.NVL Chai'!J16 -> 1000000 | J3: ='1.NVL Chai'!K16 -> 1250000 | K3: ='1.NVL Chai'!L16 -> 1250000 | L3: ='1.NVL Chai'!M16 -> 1250000 | M3: ='1.NVL Chai'!N16 -> 1250000 | N3: ='1.NVL Chai'!O16 -> 1250000 | ... R3: ='1.NVL Chai'!S16 -> 1300000 | S3: ĐVT: Triệu đồng
B4: STT | C4: Mục phí | D4: Thực tế năm 2023 | E4: Thực tế năm 2024 | F4: KQKD 2025 | G4: T1 | H4: T2 | I4: T3 | J4: T4 | K4: T5 | L4: T6 | M4: T7 | N4: T8 | O4: T9 | P4: T10 | Q4: T11 | R4: T12 | S4: KH 2026 | U4: Kiểm tra lại các sheet chi phí
B5: 1 | C5: SẢN LƯỢNG BÁN (TẤN) | D5: =D6+D7+D8 -> 0 | E5: =E6+E7+E8 -> 0 | F5: =F6+F7+F8 -> 9572318 | G5: =G6+G7+G8 -> 760725 | H5: =H6+H7+H8 -> 591675 | I5: =I6+I7+I8 -> 845250 | J5: =J6+J7+J8 -> 1055250 | K5: =K6+K7+K8 -> 1055250 | ... R5: =R6+R7+R8 -> 426660 | S5: =SUM(G5:R5) -> 9809130
B6: 1.1 | C6: Chai PET | F6: ='4.Doanh thu'!AF22 -> 7883386 | G6: ='4.Doanh thu'!F22 -> 519750 | H6: ='4.Doanh thu'!G22 -> 404250 | I6: ='4.Doanh thu'!H22 -> 577500 | J6: ='4.Doanh thu'!I22 -> 720000 | K6: ='4.Doanh thu'!J22 -> 720000 | L6: ='4.Doanh thu'!K22 -> 720000 | M6: ='4.Doanh thu'!L22 -> 720000 | N6: ='4.Doanh thu'!M22 -> 720000 | ... R6: ='4.Doanh thu'!Q22 -> 78000 | S6: =SUM(G6:R6) -> 6055500
B7: 1.2 | C7: Vảy PET | F7: ='4.Doanh thu'!AF80 -> 1688932 | G7: ='4.Doanh thu'!F80 -> 240975 | H7: ='4.Doanh thu'!G80 -> 187425 | I7: ='4.Doanh thu'!H80 -> 267750 | J7: ='4.Doanh thu'!I80 -> 335250 | K7: ='4.Doanh thu'!J80 -> 335250 | L7: ='4.Doanh thu'!K80 -> 335250 | M7: ='4.Doanh thu'!L80 -> 335250 | N7: ='4.Doanh thu'!M80 -> 335250 | ... R7: ='4.Doanh thu'!Q80 -> 348660 | S7: =SUM(G7:R7) -> 3753630
B8: 1.3 | C8: Vảy HD | S8: =SUM(G8:R8) -> 0
B9: 2 | C9: DOANH THU | D9: =D10+D11+D12+D13 -> 0 | E9: =E10+E11+E12+E13 -> 64684339330 | F9: =F10+F11+F12+F13 -> 170831845591 | G9: =G10+G11+G12+G13 -> 11515218750 | H9: =H10+H11+H12+H13 -> 8956281250 | I9: =I10+I11+I12+I13 -> 12794687500 | J9: =J10+J11+J12+J13 -> 15974312500 | K9: =K10+K11+K12+K13 -> 15974312500 | ... R9: =R10+R11+R12+R13 -> 6551285000 | S9: =SUM(G9:R9) -> 148765917500
B10: 2.1 | C10: Chai PET | E10: =64684339330 -> 64684339330 | F10: ='4.Doanh thu'!AF60 -> 140100816887 | G10: ='4.Doanh thu'!F60 -> 7626150000 | H10: ='4.Doanh thu'!G60 -> 5931450000 | I10: ='4.Doanh thu'!H60 -> 8473500000 | J10: ='4.Doanh thu'!I60 -> 10563750000 | K10: ='4.Doanh thu'!J60 -> 10563750000 | L10: ='4.Doanh thu'!K60 -> 10563750000 | M10: ='4.Doanh thu'!L60 -> 10563750000 | N10: ='4.Doanh thu'!M60 -> 10563750000 | ... R10: ='4.Doanh thu'!Q60 -> 924300000 | S10: =SUM(G10:R10) -> 88186500000
B11: 2.2 | C11: Vảy PET | F11: ='4.Doanh thu'!AF138 -> 30731028704 | G11: ='4.Doanh thu'!F138 -> 3889068750 | H11: ='4.Doanh thu'!G138 -> 3024831250 | I11: ='4.Doanh thu'!H138 -> 4321187500 | J11: ='4.Doanh thu'!I138 -> 5410562500 | K11: ='4.Doanh thu'!J138 -> 5410562500 | L11: ='4.Doanh thu'!K138 -> 5410562500 | M11: ='4.Doanh thu'!L138 -> 5410562500 | N11: ='4.Doanh thu'!M138 -> 5410562500 | ... R11: ='4.Doanh thu'!Q138 -> 5626985000 | S11: =SUM(G11:R11) -> 60579417500
B12: 2.3 | C12: Vảy HD | S12: =SUM(G12:R12) -> 0
B13: 2.4 | C13: Khác | S13: =SUM(G13:R13) -> 0
B14: 3 | C14: BIẾN PHÍ | D14: =D15+D23 -> 0 | E14: =E15+E23 -> 0 | F14: =F15+F23 -> 1.5431149e+11 | G14: =G15+G23 -> 1.0382402e+10 | H14: =H15+H23 -> 8.057362e+09 | I14: =I15+I23 -> 1.1544781e+10 | J14: =J15+J23 -> 1.4225483e+10 | K14: =K15+K23 -> 1.4236432e+10 | ... R14: =R15+R23 -> 7.778246e+09 | S14: =SUM(G14:R14) -> 1.3877818e+11
B15: 3.1 | C15: BIẾN PHÍ SẢN XUẤT | D15: =D16+D20+D21+D22 -> 0 | E15: =E16+E20+E21+E22 -> 0 | F15: =F16+F20+F21+F22 -> 1.5121452e+11 | G15: =G16+G20+G21+G22 -> 1.0123301e+10 | H15: =H16+H20+H21+H22 -> 7.8558393e+09 | I15: =I16+I20+I21+I22 -> 1.1256891e+10 | J15: =J16+J20+J21+J22 -> 1.3866114e+10 | K15: =K16+K20+K21+K22 -> 1.3877064e+10 | ... R15: =R16+R20+R21+R22 -> 7.6430092e+09 | S15: =SUM(G15:R15) -> 1.3546774e+11
B16: 3.1.1 | C16: Nguyên vật liệu chính (nhựa, gồm hao hụt) | F16: 1.4101136e+11 | G16: ='1.NVL Chai'!H42-'KQKD HD'!G16 -> 9000000000 | H16: ='1.NVL Chai'!I42-'KQKD HD'!H16 -> 7000000000 | I16: ='1.NVL Chai'!J42-'KQKD HD'!I16 -> 10000000000 | J16: ='1.NVL Chai'!K42-'KQKD HD'!J16 -> 12500000000 | K16: ='1.NVL Chai'!L42-'KQKD HD'!K16 -> 12500000000 | L16: ='1.NVL Chai'!M42-'KQKD HD'!L16 -> 12500000000 | M16: ='1.NVL Chai'!N42-'KQKD HD'!M16 -> 12500000000 | N16: ='1.NVL Chai'!O42-'KQKD HD'!N16 -> 12500000000 | ... R16: ='1.NVL Chai'!S42-'KQKD HD'!R16 -> 6292000000 | S16: =SUM(G16:R16) -> 119876000000
B17: 3.1.2 | C17: Trong đó: i/ Hao hụt CĐ phân loại chai | F17: 1.3748236e+10 | G17: =SUM('3.Thanh pham'!F$211:F$213)*'1.NVL Chai'!H$34 -> 1125000000 | H17: =SUM('3.Thanh pham'!G$211:G$213)*'1.NVL Chai'!I$34 -> 875000000 | I17: =SUM('3.Thanh pham'!H$211:H$213)*'1.NVL Chai'!J$34 -> 1250000000 | J17: =SUM('3.Thanh pham'!I$211:I$213)*'1.NVL Chai'!K$34 -> 1575000000 | K17: =SUM('3.Thanh pham'!J$211:J$213)*'1.NVL Chai'!L$34 -> 1575000000 | L17: =SUM('3.Thanh pham'!K$211:K$213)*'1.NVL Chai'!M$34 -> 1575000000 | M17: =SUM('3.Thanh pham'!L$211:L$213)*'1.NVL Chai'!N$34 -> 1575000000 | N17: =SUM('3.Thanh pham'!M$211:M$213)*'1.NVL Chai'!O$34 -> 1575000000 | ... R17: =SUM('3.Thanh pham'!Q$211:Q$213)*'1.NVL Chai'!S$34 -> 1638000000 | S17: =SUM(G17:R17) -> 17614000000
C18: ii/ Hao hụt CĐ băm vảy | F18: 1.715399e+09 | G18: =('3.Thanh pham'!F$214*'1.NVL Chai'!H$34) -> 267750000 | H18: =('3.Thanh pham'!G$214*'1.NVL Chai'!I$34) -> 208250000 | I18: =('3.Thanh pham'!H$214*'1.NVL Chai'!J$34) -> 297500000 | J18: =('3.Thanh pham'!I$214*'1.NVL Chai'!K$34) -> 372500000 | K18: =('3.Thanh pham'!J$214*'1.NVL Chai'!L$34) -> 372500000 | L18: =('3.Thanh pham'!K$214*'1.NVL Chai'!M$34) -> 372500000 | M18: =('3.Thanh pham'!L$214*'1.NVL Chai'!N$34) -> 372500000 | N18: =('3.Thanh pham'!M$214*'1.NVL Chai'!O$34) -> 372500000 | ... R18: =('3.Thanh pham'!Q$214*'1.NVL Chai'!S$34) -> 789880000 | S18: =SUM(G18:R18) -> 5378140000
B19: 3.1.3 | C19: % chi phí nguyên liệu/doanh thu | D19: =IFERROR(D16/$F$9,0) -> 0 | E19: =IFERROR(E16/$F$9,0) -> 0 | F19: =IFERROR(F16/$F$9,0) -> 0.82543955 | G19: =G16/G9 -> 0.78157438 | H19: =H16/H9 -> 0.78157438 | I19: =I16/I9 -> 0.78157438 | J19: =J16/J9 -> 0.78250629 | K19: =K16/K9 -> 0.78250629 | L19: =L16/L9 -> 0.78250629 | M19: =M16/M9 -> 0.78250629 | N19: =N16/N9 -> 0.78250629 | ... S19: =S16/S9 -> 0.80580285
B20: 3.1.4 | C20: Nguyên vật liệu phụ | F20: =SUM(CPSX!AK19:AK25) -> 2.7789895e+09 | G20: =SUM(CPSX!K19:K25) -> 3.0802692e+08 | H20: =SUM(CPSX!L19:L25) -> 2.3889538e+08 | I20: =SUM(CPSX!M19:M25) -> 3.3811419e+08 | J20: =SUM(CPSX!N19:N25) -> 4.2242376e+08 | K20: =SUM(CPSX!O19:O25) -> 4.2112376e+08 | L20: =SUM(CPSX!P19:P25) -> 4.2078209e+08 | M20: =SUM(CPSX!Q19:Q25) -> 4.2015876e+08 | N20: =SUM(CPSX!R19:R25) -> 4.2027376e+08 | ... R20: =SUM(CPSX!V19:V25) -> 3.9947829e+08 | S20: =SUM(G20:R20) -> 4.6095523e+09
B21: 3.1.5 | C21: Điện sản xuất | F21: =CPSX!$AK$18 -> 1323352660 | G21: =CPSX!K$18 -> 1.1567843e+08 | H21: =CPSX!L$18 -> 89972114 | I21: =CPSX!M$18 -> 1.2853159e+08 | J21: =CPSX!N$18 -> 1.6071292e+08 | K21: =CPSX!O$18 -> 1.6071292e+08 | L21: =CPSX!P$18 -> 1.6071292e+08 | M21: =CPSX!Q$18 -> 1.6071292e+08 | N21: =CPSX!R$18 -> 1.6071292e+08 | ... R21: =CPSX!V$18 -> 1.6714144e+08 | S21: =SUM(G21:R21) -> 1.799884e+09
B22: 3.1.6 | C22: Nhân công trực tiếp | F22: =SUM(CPSX!AK6:AK16) -> 6100821040 | G22: =SUM(CPSX!K6:K16) -> 6.995961e+08 | H22: =SUM(CPSX!L6:L16) -> 5.2697176e+08 | I22: =SUM(CPSX!M6:M16) -> 7.902456e+08 | J22: =SUM(CPSX!N6:N16) -> 7.8297773e+08 | K22: =SUM(CPSX!O6:O16) -> 7.9522688e+08 | L22: =SUM(CPSX!P6:P16) -> 8.0066773e+08 | M22: =SUM(CPSX!Q6:Q16) -> 826201238 | N22: =SUM(CPSX!R6:R16) -> 826201238 | ... R22: =SUM(CPSX!V6:V16) -> 7.8438943e+08 | S22: =SUM(G22:R22) -> 9.1823057e+09
B23: 3.2 | C23: BIẾN PHÍ BÁN HÀNG | D23: =D24 -> 0 | E23: =E24 -> 0 | F23: =F24 -> 3.0969688e+09 | G23: =G24 -> 259100625 | H23: =H24 -> 2.0152271e+08 | I23: =I24 -> 2.8788958e+08 | J23: =J24 -> 359368750 | K23: =K24 -> 359368750 | ... R23: =R24 -> 1.3523683e+08 | S23: =SUM(G23:R23) -> 3.3104359e+09
C24: Chi phí vận chuyển | F24: =CPBH!AK8 -> 3.0969688e+09 | G24: =SUM(CPBH!K5:K6) -> 259100625 | H24: =SUM(CPBH!L5:L6) -> 2.0152271e+08 | I24: =SUM(CPBH!M5:M6) -> 2.8788958e+08 | J24: =SUM(CPBH!N5:N6) -> 359368750 | K24: =SUM(CPBH!O5:O6) -> 359368750 | L24: =SUM(CPBH!P5:P6) -> 359368750 | M24: =SUM(CPBH!Q5:Q6) -> 359368750 | N24: =SUM(CPBH!R5:R6) -> 359368750 | ... R24: =SUM(CPBH!V5:V6) -> 1.3523683e+08 | S24: =SUM(G24:R24) -> 3.3104359e+09
B25: 4 | C25: LÃI SAU BIẾN PHÍ | D25: =D9-D14 -> 0 | E25: =E9-E14 -> 64684339330 | F25: =F9-F14 -> 1.6520352e+10 | G25: =G9-G14 -> 1.1328167e+09 | H25: =H9-H14 -> 8.9891929e+08 | I25: =I9-I14 -> 1.2499065e+09 | J25: =J9-J14 -> 1.7488293e+09 | K25: =K9-K14 -> 1.7378802e+09 | ... R25: =R9-R14 -> -1.226961e+09 | S25: =SUM(G25:R25) -> 9.9877397e+09
B26: 4.1 | C26: % lãi biến phí/doanh thu | D26: =IFERROR(D23/$F$9,0) -> 0 | E26: =IFERROR(E23/$F$9,0) -> 0 | F26: =IFERROR(F23/$F$9,0) -> 0.018128756 | G26: =G25/G9 -> 0.09837561 | H26: =H25/H9 -> 0.10036747 | I26: =I25/I9 -> 0.097689493 | J26: =J25/J9 -> 0.1094776 | K26: =K25/K9 -> 0.10879217 | L26: =L25/L9 -> 0.10847296 | M26: =M25/M9 -> 0.10691357 | N26: =N25/N9 -> 0.10690637 | ... S26: =S25/S9 -> 0.067137284
B27: 5 | C27: CHI PHÍ SẢN XUẤT CHUNG | D27: =D28+D29+D30 -> 0 | E27: =E28+E29+E30 -> 0 | F27: =F28+F29+F30 -> 8620348627 | G27: =G28+G29+G30 -> 7.5243062e+08 | H27: =H28+H29+H30 -> 7.3925279e+08 | I27: =I28+I29+I30 -> 7.1526234e+08 | J27: =J28+J29+J30 -> 7.5435915e+08 | K27: =K28+K29+K30 -> 7.6433031e+08 | ... R27: =R28+R29+R30 -> 8.7431489e+08 | S27: =SUM(G27:R27) -> 9.5847166e+09
B28: 5.1 | C28: Lương gián tiếp Sản xuất | F28: =SUM(CPSX!AK72:AK82) -> 3749845944 | G28: =SUM(CPSX!K$72:K$83) -> 2.9691432e+08 | H28: =SUM(CPSX!L$72:L$83) -> 2.9460366e+08 | I28: =SUM(CPSX!M$72:M$83) -> 2.8225475e+08 | J28: =SUM(CPSX!N$72:N$83) -> 3.0506017e+08 | K28: =SUM(CPSX!O$72:O$83) -> 2.8977549e+08 | L28: =SUM(CPSX!P$72:P$83) -> 3.0532267e+08 | M28: =SUM(CPSX!Q$72:Q$83) -> 2.9807777e+08 | N28: =SUM(CPSX!R$72:R$83) -> 2.9807777e+08 | ... R28: =SUM(CPSX!V$72:V$83) -> 2.9807777e+08 | S28: =SUM(G28:R28) -> 3.5686231e+09
B29: 5.2 | C29: Chi phí thuê xưởng | F29: =CPSX!AK88 -> 2815076112 | G29: =CPSX!K$88 -> 230839676 | H29: =CPSX!L$88 -> 230839676 | I29: =CPSX!M$88 -> 230839676 | J29: =CPSX!N$88 -> 230839676 | K29: =CPSX!O$88 -> 230839676 | L29: =CPSX!P$88 -> 230839676 | M29: =CPSX!Q$88 -> 230839676 | N29: =CPSX!R$88 -> 230839676 | ... R29: =CPSX!V$88 -> 230839676 | S29: =SUM(G29:R29) -> 2770076112
B30: 5.3 | C30: Chi phí sản xuất (Ngoài lương, BOM, thuê xưởng, khấu hao) | F30: =SUM(CPSX!AK16:AK17,CPSX!$AK$71)-'KQKD PET'!F28-'KQKD PET'!F29-'KQKD PET'!F31 -> 2055426571 | G30: =SUM(CPSX!K$71)-'KQKD PET'!G28-'KQKD PET'!G29-'KQKD PET'!G31 -> 2.2467662e+08 | H30: =SUM(CPSX!L$71)-'KQKD PET'!H28-'KQKD PET'!H29-'KQKD PET'!H31 -> 2.1380946e+08 | I30: =SUM(CPSX!M$71)-'KQKD PET'!I28-'KQKD PET'!I29-'KQKD PET'!I31 -> 2.0216791e+08 | J30: =SUM(CPSX!N$71)-'KQKD PET'!J28-'KQKD PET'!J29-'KQKD PET'!J31 -> 2.184593e+08 | K30: =SUM(CPSX!O$71)-'KQKD PET'!K28-'KQKD PET'!K29-'KQKD PET'!K31 -> 2.4371514e+08 | L30: =SUM(CPSX!P$71)-'KQKD PET'!L28-'KQKD PET'!L29-'KQKD PET'!L31 -> 2.6238226e+08 | M30: =SUM(CPSX!Q$71)-'KQKD PET'!M28-'KQKD PET'!M29-'KQKD PET'!M31 -> 2.7153692e+08 | N30: =SUM(CPSX!R$71)-'KQKD PET'!N28-'KQKD PET'!N29-'KQKD PET'!N31 -> 2.7867294e+08 | ... R30: =SUM(CPSX!V$71)-'KQKD PET'!R28-'KQKD PET'!R29-'KQKD PET'!R31 -> 3.4539745e+08 | S30: =SUM(G30:R30) -> 3.2460174e+09
B31: 6 | C31: CHI PHÍ KHẤU HAO, CCDC | F31: =CPSX!AK99 -> 3687386699 | G31: =CPSX!K$99 -> 1.4379769e+08 | H31: =CPSX!L$99 -> 1.4379769e+08 | I31: =CPSX!M$99 -> 1.4123406e+08 | J31: =CPSX!N$99 -> 1.4123406e+08 | K31: =CPSX!O$99 -> 1.4123406e+08 | L31: =CPSX!P$99 -> 1.4123406e+08 | M31: =CPSX!Q$99 -> 1.4123406e+08 | N31: =CPSX!R$99 -> 1.4123406e+08 | ... R31: =CPSX!V$99 -> 1.4123406e+08 | S31: =SUM(G31:R31) -> 1.699936e+09
B32: 7 | C32: LỢI NHUẬN GỘP | D32: =D25-D27-D31 -> 0 | E32: =E25-E27-E31 -> 64684339330 | F32: =F25-F27-F31 -> 4.2126165e+09 | G32: =G25-G27-G31 -> 2.3658836e+08 | H32: =H25-H27-H31 -> 15868797 | I32: =I25-I27-I31 -> 3.9341014e+08 | J32: =J25-J27-J31 -> 8.5323614e+08 | K32: =K25-K27-K31 -> 8.3231583e+08 | ... R32: =R25-R27-R31 -> -2.2425099e+09 | S32: =SUM(G32:R32) -> -1.2969129e+09
B33: 7.1 | C33: % lãi gộp/doanh thu | D33: =IFERROR(D30/$F$9,0) -> 0 | E33: =IFERROR(E30/$F$9,0) -> 0 | F33: =IFERROR(F30/$F$9,0) -> 0.01203187 | G33: =G32/G9 -> 0.020545712 | H33: =H32/H9 -> 0.0017718065 | I33: =I32/I9 -> 0.030747929 | J33: =J32/J9 -> 0.053413012 | K33: =K32/K9 -> 0.05210339 | L33: =L32/L9 -> 0.049642346 | M33: =M32/M9 -> 0.047963405 | N33: =N32/N9 -> 0.047509487 | ... S33: =S32/S9 -> -0.0087178094
B34: 8 | C34: CHI PHÍ BÁN HÀNG & MKT & R&D | D34: =D35+D36+D37 -> 0 | E34: =E35+E36+E37 -> 0 | F34: =F35+F36+F37 -> 0 | G34: =G35+G36+G37 -> 0 | H34: =H35+H36+H37 -> 0 | I34: =I35+I36+I37 -> 0 | J34: =J35+J36+J37 -> 0 | K34: =K35+K36+K37 -> 0 | ... R34: =R35+R36+R37 -> 0 | S34: =SUM(G34:R34) -> 0
B35: 8.1 | C35: Lương | S35: =SUM(G35:R35) -> 0
B36: 8.2 | C36: Chi phí bán hàng (ngoài lương, khấu hao) | S36: =SUM(G36:R36) -> 0
B37: 8.3 | C37: Khấu hao tài sản | S37: =SUM(G37:R37) -> 0
B38: 9 | C38: CHI PHÍ QUẢN LÝ | D38: =D39+D40+D41 -> 0 | E38: =E39+E40+E41 -> 0 | F38: =F39+F40+F41 -> 3919574163 | G38: =G39+G40+G41 -> 5.5148923e+08 | H38: =H39+H40+H41 -> 4.8534478e+08 | I38: =I39+I40+I41 -> 5.1455941e+08 | J38: =J39+J40+J41 -> 5.1939125e+08 | K38: =K39+K40+K41 -> 5.0091629e+08 | ... R38: =R39+R40+R41 -> 4.9062235e+08 | S38: =SUM(G38:R38) -> 6.2045555e+09
B39: 9.1 | C39: Lương | F39: =SUM(CPQL!AK5:AK14) -> 2289784061 | G39: =SUM(CPQL!K5:K14) -> 3.2479914e+08 | H39: =SUM(CPQL!L5:L14) -> 3.2569102e+08 | I39: =SUM(CPQL!M5:M14) -> 3.0965466e+08 | J39: =SUM(CPQL!N5:N14) -> 3.3272325e+08 | K39: =SUM(CPQL!O5:O14) -> 3.1993578e+08 | L39: =SUM(CPQL!P5:P14) -> 3.3302825e+08 | M39: =SUM(CPQL!Q5:Q14) -> 3.2580138e+08 | N39: =SUM(CPQL!R5:R14) -> 3.2580138e+08 | ... R39: =SUM(CPQL!V5:V14) -> 3.2549638e+08 | S39: =SUM(G39:R39) -> 3.9074709e+09
B40: 9.2 | C40: Chi phí quản lý (ngoài lương, khấu hao) | F40: =CPQL!AK65-'KQKD PET'!F39-'KQKD PET'!F41 -> 1543688629 | G40: =CPQL!K65-G39-G41 -> 2.2404662e+08 | H40: =CPQL!L65-H39-H41 -> 1.5701029e+08 | I40: =CPQL!M65-I39-I41 -> 2.0226129e+08 | J40: =CPQL!N65-J39-J41 -> 1.8402454e+08 | K40: =CPQL!O65-K39-K41 -> 1.7833704e+08 | L40: =CPQL!P65-L39-L41 -> 3.2803148e+08 | M40: =CPQL!Q65-M39-M41 -> 1.6003148e+08 | N40: =CPQL!R65-N39-N41 -> 1.9040648e+08 | ... R40: =CPQL!V65-R39-R41 -> 1.624825e+08 | S40: =SUM(G40:R40) -> 2.265363e+09
B41: 9.3 | C41: Khấu hao tài sản | F41: =CPQL!AK61 -> 86101473 | G41: =CPQL!K61 -> 2643466 | H41: =CPQL!L61 -> 2643466 | I41: =CPQL!M61 -> 2643466 | J41: =CPQL!N61 -> 2643466 | K41: =CPQL!O61 -> 2643466 | L41: =CPQL!P61 -> 2643466 | M41: =CPQL!Q61 -> 2643466 | N41: =CPQL!R61 -> 2643466 | ... R41: =CPQL!V61 -> 2643466 | S41: =SUM(G41:R41) -> 31721592
...

Sheet KDKD DAY DAI
B3: MỤC TIÊU KẾT QUẢ KINH DOANH NĂM 2026 | S3: ĐVT: Triệu đồng
B4: STT | C4: Mục phí | D4: Thực tế năm 2023 | E4: Thực tế năm 2024 | F4: KQKD 2025 | G4: T1 | H4: T2 | I4: T3 | J4: T4 | K4: T5 | L4: T6 | M4: T7 | N4: T8 | O4: T9 | P4: T10 | Q4: T11 | R4: T12 | S4: KH 2026 | U4: Kiểm tra lại các sheet chi phí
B5: 1 | C5: SẢN LƯỢNG BÁN (TẤN) | D5: =D6+D7+D8 -> 0 | E5: =E6+E7+E8 -> 0 | F5: =F6+F7+F8 -> 0 | G5: =G6+G7+G8 -> 0 | H5: =H6+H7+H8 -> 0 | I5: =I6+I7+I8 -> 0 | J5: =J6+J7+J8 -> 0 | K5: =K6+K7+K8 -> 0 | ... R5: =R6+R7+R8 -> 0 | S5: =SUM(G5:R5) -> 0
B6: 1.1 | C6: Dây Đai PET | G6: ='KH DAY DAI'!E23 -> 0 | H6: ='KH DAY DAI'!F23 -> 0 | I6: ='KH DAY DAI'!G23 -> 0 | J6: ='KH DAY DAI'!H23 -> 0 | K6: ='KH DAY DAI'!I23 -> 0 | L6: ='KH DAY DAI'!J23 -> 0 | M6: ='KH DAY DAI'!K23 -> 0 | N6: ='KH DAY DAI'!L23 -> 0 | ... R6: ='KH DAY DAI'!P23 -> 0 | S6: =SUM(G6:R6) -> 0
B7: 1.2 | S7: =SUM(G7:R7) -> 0
B8: 1.3 | S8: =SUM(G8:R8) -> 0
B9: 2 | C9: DOANH THU | D9: =D10+D11+D12+D13 -> 0 | E9: =E10+E11+E12+E13 -> 0 | F9: =F10+F11+F12+F13 -> 0 | G9: =G10+G11+G12+G13 -> 0 | H9: =H10+H11+H12+H13 -> 0 | I9: =I10+I11+I12+I13 -> 0 | J9: =J10+J11+J12+J13 -> 0 | K9: =K10+K11+K12+K13 -> 0 | ... R9: =R10+R11+R12+R13 -> 0 | S9: =SUM(G9:R9) -> 0
B10: 2.1 | C10: Dây Đai PET | G10: ='KH DAY DAI'!E24 -> 0 | H10: ='KH DAY DAI'!F24 -> 0 | I10: ='KH DAY DAI'!G24 -> 0 | J10: ='KH DAY DAI'!H24 -> 0 | K10: ='KH DAY DAI'!I24 -> 0 | L10: ='KH DAY DAI'!J24 -> 0 | M10: ='KH DAY DAI'!K24 -> 0 | N10: ='KH DAY DAI'!L24 -> 0 | ... R10: ='KH DAY DAI'!P24 -> 0 | S10: =SUM(G10:R10) -> 0
B11: 2.2
B12: 2.3
B13: 2.4 | C13: Khác | S13: =SUM(G13:R13) -> 0
B14: 3 | C14: BIẾN PHÍ | D14: =D15+D23 -> 0 | E14: =E15+E23 -> 0 | G14: =G15+G23 -> 0 | H14: =H15+H23 -> 0 | I14: =I15+I23 -> 0 | J14: =J15+J23 -> 0 | K14: =K15+K23 -> 0 | L14: =L15+L23 -> 0 | M14: =M15+M23 -> 0 | N14: =N15+N23 -> 0 | ... R14: =R15+R23 -> 0 | S14: =SUM(G14:R14) -> 0
B15: 3.1 | C15: BIẾN PHÍ SẢN XUẤT | D15: =D16+D20+D21+D22 -> 0 | E15: =E16+E20+E21+E22 -> 0 | G15: =G16+G20+G21+G22 -> 0 | H15: =H16+H20+H21+H22 -> 0 | I15: =I16+I20+I21+I22 -> 0 | J15: =J16+J20+J21+J22 -> 0 | K15: =K16+K20+K21+K22 -> 0 | L15: =L16+L20+L21+L22 -> 0 | M15: =M16+M20+M21+M22 -> 0 | N15: =N16+N20+N21+N22 -> 0 | ... R15: =R16+R20+R21+R22 -> 0 | S15: =SUM(G15:R15) -> 0
B16: 3.1.1 | C16: Nguyên vật liệu chính (nhựa, gồm hao hụt) | G16: =SUM('KH DAY DAI'!E25:E26,'KH DAY DAI'!E33) -> 0 | H16: =SUM('KH DAY DAI'!F25:F26,'KH DAY DAI'!F33) -> 0 | I16: =SUM('KH DAY DAI'!G25:G26,'KH DAY DAI'!G33) -> 0 | J16: =SUM('KH DAY DAI'!H25:H26,'KH DAY DAI'!H33) -> 0 | K16: =SUM('KH DAY DAI'!I25:I26,'KH DAY DAI'!I33) -> 0 | L16: =SUM('KH DAY DAI'!J25:J26,'KH DAY DAI'!J33) -> 0 | M16: =SUM('KH DAY DAI'!K25:K26,'KH DAY DAI'!K33) -> 0 | N16: =SUM('KH DAY DAI'!L25:L26,'KH DAY DAI'!L33) -> 0 | ... R16: =SUM('KH DAY DAI'!P25:P26,'KH DAY DAI'!P33) -> 0 | S16: =SUM(G16:R16) -> 0
B17: 3.1.2 | C17: Trong đó: i/ Hao hụt CĐ phân loại chai | G17: =SUM('KH DAY DAI'!E26,'KH DAY DAI'!E33) -> 0 | H17: =SUM('KH DAY DAI'!F26,'KH DAY DAI'!F33) -> 0 | I17: =SUM('KH DAY DAI'!G26,'KH DAY DAI'!G33) -> 0 | J17: =SUM('KH DAY DAI'!H26,'KH DAY DAI'!H33) -> 0 | K17: =SUM('KH DAY DAI'!I26,'KH DAY DAI'!I33) -> 0 | L17: =SUM('KH DAY DAI'!J26,'KH DAY DAI'!J33) -> 0 | M17: =SUM('KH DAY DAI'!K26,'KH DAY DAI'!K33) -> 0 | N17: =SUM('KH DAY DAI'!L26,'KH DAY DAI'!L33) -> 0 | ... R17: =SUM('KH DAY DAI'!P26,'KH DAY DAI'!P33) -> 0 | S17: =SUM(G17:R17) -> 0
C18: ii/ Hao hụt CĐ băm vảy | S18: =SUM(G18:R18) -> 0
B19: 3.1.3 | C19: % chi phí nguyên liệu/doanh thu | D19: =IFERROR(D16/$F$9,0) -> 0 | E19: =IFERROR(E16/$F$9,0) -> 0 | F19: =IFERROR(F16/$F$9,0) -> 0 | G19: =G16/G9 -> #DIV/0! | H19: =H16/H9 -> #DIV/0! | I19: =I16/I9 -> #DIV/0! | J19: =J16/J9 -> #DIV/0! | K19: =K16/K9 -> #DIV/0! | L19: =L16/L9 -> #DIV/0! | M19: =M16/M9 -> #DIV/0! | N19: =N16/N9 -> #DIV/0! | ... S19: =S16/S9 -> #DIV/0!
B20: 3.1.4 | C20: Nguyên vật liệu phụ | G20: ='KH DAY DAI'!E27 -> 0 | H20: ='KH DAY DAI'!F27 -> 0 | I20: ='KH DAY DAI'!G27 -> 0 | J20: ='KH DAY DAI'!H27 -> 0 | K20: ='KH DAY DAI'!I27 -> 0 | L20: ='KH DAY DAI'!J27 -> 0 | M20: ='KH DAY DAI'!K27 -> 0 | N20: ='KH DAY DAI'!L27 -> 0 | ... R20: ='KH DAY DAI'!P27 -> 0 | S20: =SUM(G20:R20) -> 0
B21: 3.1.5 | C21: Điện sản xuất | G21: ='KH DAY DAI'!E28 -> 0 | H21: ='KH DAY DAI'!F28 -> 0 | I21: ='KH DAY DAI'!G28 -> 0 | J21: ='KH DAY DAI'!H28 -> 0 | K21: ='KH DAY DAI'!I28 -> 0 | L21: ='KH DAY DAI'!J28 -> 0 | M21: ='KH DAY DAI'!K28 -> 0 | N21: ='KH DAY DAI'!L28 -> 0 | ... R21: ='KH DAY DAI'!P28 -> 0 | S21: =SUM(G21:R21) -> 0
B22: 3.1.6 | C22: Nhân công trực tiếp | G22: ='KH DAY DAI'!E29 -> 0 | H22: ='KH DAY DAI'!F29 -> 0 | I22: ='KH DAY DAI'!G29 -> 0 | J22: ='KH DAY DAI'!H29 -> 0 | K22: ='KH DAY DAI'!I29 -> 0 | L22: ='KH DAY DAI'!J29 -> 0 | M22: ='KH DAY DAI'!K29 -> 0 | N22: ='KH DAY DAI'!L29 -> 0 | ... R22: ='KH DAY DAI'!P29 -> 0 | S22: =SUM(G22:R22) -> 0
B23: 3.2 | C23: BIẾN PHÍ BÁN HÀNG | D23: =D24 -> 0 | E23: =E24 -> 0 | F23: =F24 -> 0 | G23: =G24 -> 0 | H23: =H24 -> 0 | I23: =I24 -> 0 | J23: =J24 -> 0 | K23: =K24 -> 0 | ... R23: =R24 -> 0 | S23: =SUM(G23:R23) -> 0
C24: Chi phí vận chuyển | G24: ='KH DAY DAI'!E36 -> 0 | H24: ='KH DAY DAI'!F36 -> 0 | I24: ='KH DAY DAI'!G36 -> 0 | J24: ='KH DAY DAI'!H36 -> 0 | K24: ='KH DAY DAI'!I36 -> 0 | L24: ='KH DAY DAI'!J36 -> 0 | M24: ='KH DAY DAI'!K36 -> 0 | N24: ='KH DAY DAI'!L36 -> 0 | ... R24: ='KH DAY DAI'!P36 -> 0 | S24: =SUM(G24:R24) -> 0
B25: 4 | C25: LÃI SAU BIẾN PHÍ | D25: =D9-D14 -> 0 | E25: =E9-E14 -> 0 | F25: =F9-F14 -> 0 | G25: =G9-G14 -> 0 | H25: =H9-H14 -> 0 | I25: =I9-I14 -> 0 | J25: =J9-J14 -> 0 | K25: =K9-K14 -> 0 | ... R25: =R9-R14 -> 0 | S25: =SUM(G25:R25) -> 0
B26: 4.1 | C26: % lãi biến phí/doanh thu | D26: =IFERROR(D23/$F$9,0) -> 0 | E26: =IFERROR(E23/$F$9,0) -> 0 | F26: =IFERROR(F23/$F$9,0) -> 0 | G26: =G25/G9 -> #DIV/0! | H26: =H25/H9 -> #DIV/0! | I26: =I25/I9 -> #DIV/0! | J26: =J25/J9 -> #DIV/0! | K26: =K25/K9 -> #DIV/0! | L26: =L25/L9 -> #DIV/0! | M26: =M25/M9 -> #DIV/0! | N26: =N25/N9 -> #DIV/0! | ... S26: =S25/S9 -> #DIV/0!
B27: 5 | C27: CHI PHÍ SẢN XUẤT CHUNG | D27: =D28+D29+D30 -> 0 | E27: =E28+E29+E30 -> 0 | F27: =F28+F29+F30 -> 0 | G27: =G28+G29+G30 -> 0 | H27: =H28+H29+H30 -> 0 | I27: =I28+I29+I30 -> 0 | J27: =J28+J29+J30 -> 0 | K27: =K28+K29+K30 -> 0 | ... R27: =R28+R29+R30 -> 0 | S27: =SUM(G27:R27) -> 0
B28: 5.1 | C28: Lương gián tiếp Sản xuất | G28: ='KH DAY DAI'!E31 -> 0 | H28: ='KH DAY DAI'!F31 -> 0 | I28: ='KH DAY DAI'!G31 -> 0 | J28: ='KH DAY DAI'!H31 -> 0 | K28: ='KH DAY DAI'!I31 -> 0 | L28: ='KH DAY DAI'!J31 -> 0 | M28: ='KH DAY DAI'!K31 -> 0 | N28: ='KH DAY DAI'!L31 -> 0 | ... R28: ='KH DAY DAI'!P31 -> 0 | S28: =SUM(G28:R28) -> 0
B29: 5.2 | C29: Chi phí thuê xưởng | S29: =SUM(G29:R29) -> 0
B30: 5.3 | C30: Chi phí sản xuất (Ngoài lương, BOM, thuê xưởng, khấu hao) | G30: =SUM('KH DAY DAI'!E30) -> 0 | H30: =SUM('KH DAY DAI'!F30) -> 0 | I30: =SUM('KH DAY DAI'!G30) -> 0 | J30: =SUM('KH DAY DAI'!H30) -> 0 | K30: =SUM('KH DAY DAI'!I30) -> 0 | L30: =SUM('KH DAY DAI'!J30) -> 0 | M30: =SUM('KH DAY DAI'!K30) -> 0 | N30: =SUM('KH DAY DAI'!L30) -> 0 | ... R30: =SUM('KH DAY DAI'!P30) -> 0 | S30: =SUM(G30:R30) -> 0
B31: 6 | C31: CHI PHÍ KHẤU HAO, CCDC | G31: ='KH DAY DAI'!E32 -> 0 | H31: ='KH DAY DAI'!F32 -> 0 | I31: ='KH DAY DAI'!G32 -> 0 | J31: ='KH DAY DAI'!H32 -> 0 | K31: ='KH DAY DAI'!I32 -> 0 | L31: ='KH DAY DAI'!J32 -> 0 | M31: ='KH DAY DAI'!K32 -> 0 | N31: ='KH DAY DAI'!L32 -> 0 | ... R31: ='KH DAY DAI'!P32 -> 0 | S31: =SUM(G31:R31) -> 0
B32: 7 | C32: LỢI NHUẬN GỘP | D32: =D25-D27-D31 -> 0 | E32: =E25-E27-E31 -> 0 | F32: =F25-F27-F31 -> 0 | G32: =G25-G27-G31 -> 0 | H32: =H25-H27-H31 -> 0 | I32: =I25-I27-I31 -> 0 | J32: =J25-J27-J31 -> 0 | K32: =K25-K27-K31 -> 0 | ... R32: =R25-R27-R31 -> 0 | S32: =SUM(G32:R32) -> 0
B33: 7.1 | C33: % lãi gộp/doanh thu | D33: =IFERROR(D30/$F$9,0) -> 0 | E33: =IFERROR(E30/$F$9,0) -> 0 | F33: =IFERROR(F30/$F$9,0) -> 0 | G33: =G32/G9 -> #DIV/0! | H33: =H32/H9 -> #DIV/0! | I33: =I32/I9 -> #DIV/0! | J33: =J32/J9 -> #DIV/0! | K33: =K32/K9 -> #DIV/0! | L33: =L32/L9 -> #DIV/0! | M33: =M32/M9 -> #DIV/0! | N33: =N32/N9 -> #DIV/0! | ... S33: =S32/S9 -> #DIV/0!
B34: 8 | C34: CHI PHÍ BÁN HÀNG & MKT & R&D | D34: =D35+D36+D37 -> 0 | E34: =E35+E36+E37 -> 0 | F34: =F35+F36+F37 -> 0 | G34: =G35+G36+G37 -> 0 | H34: =H35+H36+H37 -> 0 | I34: =I35+I36+I37 -> 0 | J34: =J35+J36+J37 -> 0 | K34: =K35+K36+K37 -> 0 | ... R34: =R35+R36+R37 -> 0 | S34: =SUM(G34:R34) -> 0
B35: 8.1 | C35: Lương | S35: =SUM(G35:R35) -> 0
B36: 8.2 | C36: Chi phí bán hàng (ngoài lương, khấu hao) | G36: =SUM('KH DAY DAI'!E34:E35) -> 0 | H36: =SUM('KH DAY DAI'!F34:F35) -> 0 | I36: =SUM('KH DAY DAI'!G34:G35) -> 0 | J36: =SUM('KH DAY DAI'!H34:H35) -> 0 | K36: =SUM('KH DAY DAI'!I34:I35) -> 0 | L36: =SUM('KH DAY DAI'!J34:J35) -> 0 | M36: =SUM('KH DAY DAI'!K34:K35) -> 0 | N36: =SUM('KH DAY DAI'!L34:L35) -> 0 | ... R36: =SUM('KH DAY DAI'!P34:P35) -> 0 | S36: =SUM(G36:R36) -> 0
B37: 8.3 | C37: Khấu hao tài sản | S37: =SUM(G37:R37) -> 0
B38: 9 | C38: CHI PHÍ QUẢN LÝ | D38: =D39+D40+D41 -> 0 | E38: =E39+E40+E41 -> 0 | F38: =F39+F40+F41 -> 0 | G38: =G39+G40+G41 -> 0 | H38: =H39+H40+H41 -> 0 | I38: =I39+I40+I41 -> 0 | J38: =J39+J40+J41 -> 0 | K38: =K39+K40+K41 -> 0 | ... R38: =R39+R40+R41 -> 0 | S38: =SUM(G38:R38) -> 0
B39: 9.1 | C39: Lương | S39: =SUM(G39:R39) -> 0
B40: 9.2 | C40: Chi phí quản lý (ngoài lương, khấu hao) | S40: =SUM(G40:R40) -> 0
B41: 9.3 | C41: Khấu hao tài sản | S41: =SUM(G41:R41) -> 0
B42: 10 | C42: DOANH THU/CHI PHÍ KHÁC | S42: =SUM(G42:R42) -> 0 | U42: <= Nhập số liệu
...

Sheet KH DAY DAI
B2: 1. Dây đai
B4: STT | C4: Nội dung | D4: Tỷ lệ | E4: 1 | F4: =+E4+1 -> 2 | G4: =+F4+1 -> 3 | H4: =+G4+1 -> 4 | I4: =+H4+1 -> 5 | J4: =+I4+1 -> 6 | K4: =+J4+1 -> 7 | L4: =+K4+1 -> 8 | M4: =+L4+1 -> 9 | ... P4: =+O4+1 -> 12
B5: 1 | C5: Sản lượng sản xuất (tấn) | E5: =300*16*30/10^3 -> 144 | F5: =300*16*30/10^3 -> 144 | G5: =300*16*30/10^3 -> 144 | H5: =300*16*30/10^3 -> 144 | I5: =300*16*30/10^3 -> 144 | J5: =300*16*30/10^3 -> 144 | K5: =300*16*30/10^3 -> 144 | L5: =300*16*30/10^3 -> 144 | ... P5: =300*16*30/10^3 -> 144 | Q5: =400 -> 400
B6: 2 | C6: Giá bán | E6: 19000 | F6: 19000 | G6: 19000 | H6: 19000 | I6: 19000 | J6: 19000 | K6: 19000 | L6: 19000 | M6: 19000 | N6: 19000 | O6: 19000 | P6: 19000
B7: 3 | C7: Giá vốn (bao gồm CP hoa hồng) | E7: =SUM(E8,E12:E21) -> 17207.846 | F7: =SUM(F8,F12:F21) -> 17207.846 | G7: =SUM(G8,G12:G21) -> 17207.846 | H7: =SUM(H8,H12:H21) -> 17207.846 | I7: =SUM(I8,I12:I21) -> 17207.846 | J7: =SUM(J8,J12:J21) -> 17207.846 | K7: =SUM(K8,K12:K21) -> 17207.846 | L7: =SUM(L8,L12:L21) -> 17207.846 | ... P7: =SUM(P8,P12:P21) -> 17207.846
B8: 3.1 | C8: Chi phí nguyên vật liệu | E8: =+SUM(E9:E11) -> 8840 | F8: =+SUM(F9:F11) -> 8840 | G8: =+SUM(G9:G11) -> 8840 | H8: =+SUM(H9:H11) -> 8840 | I8: =+SUM(I9:I11) -> 8840 | J8: =+SUM(J9:J11) -> 8840 | K8: =+SUM(K9:K11) -> 8840 | L8: =+SUM(L9:L11) -> 8840 | ... P8: =+SUM(P9:P11) -> 8840
