Workbook

Sheet SO SÁNH
B1: GROUP TÁI CHẾ
B2: VND
A3: Index PL | B3: PHẦN II-KẾT QUẢ HOẠT ĐỘNG KINH DOANH | D3: 3 TRẠM | U3: HỢP NHẤT
D4: Version Mới | E4: Đồng Lâm | F4: Khánh Nga | G4: Đại Lộc | H4: Version Cũ | I4: Đồng Lâm | J4: Khánh Nga | K4: Đại Lộc | L4: +/- | M4: +/- Đồng Lâm | N4: +/- Khánh Nga | O4: +/- Đại Lộc | P4: %+/- | Q4: %+/- Đồng Lâm | R4: %+/- Khánh Nga | S4: %+/- Đại Lộc | U4: Version Mới | V4: Version Cũ | W4: +/- | X4: %+/-
A5: 1 | B5: Sản lượng (tấn) | D5: =SUM(D6:D8) -> 30121.928 | E5: =SUM(E6:E8) -> 11305.142 | F5: =SUM(F6:F8) -> 7116 | G5: =SUM(G6:G8) -> 11700.786 | H5: =SUM(H6:H8) -> 29233.917 | I5: =SUM(I6:I8) -> 11696.882 | J5: =SUM(J6:J8) -> 7116 | K5: =SUM(K6:K8) -> 10421.035 | L5: =D5-H5 -> 888.01073 | M5: =E5-I5 -> -391.74027 | N5: =F5-J5 -> 0 | O5: =G5-K5 -> 1279.751 | P5: =IFERROR(L5/H5,0) -> 0.030376043 | Q5: =IFERROR(M5/I5,0) -> -0.033490999 | R5: =IFERROR(N5/J5,0) -> 0 | S5: =IFERROR(O5/K5,0) -> 0.1228046 | U5: =SUM(U6:U8) -> 55000 | V5: =SUM(V6:V8) -> 55000 | W5: =U5-V5 -> 0 | X5: =IFERROR(W5/V5,0) -> 0
A6: SL-BN | B6: Bán ngoài | D6: =SUM(E6:G6) -> 0 | E6: ='Consol PL-DTRG'!CG6 -> 0 | F6: ='Consol PL-DTRG'!CU6 -> 0 | G6: ='Consol PL-DTRG'!DI6 -> 0 | H6: =SUM(I6:K6) -> 0 | I6: ='Consol PL-DTRG-Cũ'!CG6 -> 0 | J6: ='Consol PL-DTRG-Cũ'!CU6 -> 0 | K6: ='Consol PL-DTRG-Cũ'!DI6 -> 0 | L6: =D6-H6 -> 0 | M6: =E6-I6 -> 0 | N6: =F6-J6 -> 0 | O6: =G6-K6 -> 0 | P6: =IFERROR(L6/H6,0) -> 0 | Q6: =IFERROR(M6/I6,0) -> 0 | R6: =IFERROR(N6/J6,0) -> 0 | S6: =IFERROR(O6/K6,0) -> 0 | U6: ='Consol PL-DTRG'!O6 -> 55000 | V6: ='Consol PL-DTRG-Cũ'!O6 -> 55000 | W6: =U6-V6 -> 0 | X6: =IFERROR(W6/V6,0) -> 0
A7: SL-MC | B7: Mẹ-Con | D7: =SUM(E7:G7) -> 30121.928 | E7: ='Consol PL-DTRG'!CG7 -> 11305.142 | F7: ='Consol PL-DTRG'!CU7 -> 7116 | G7: ='Consol PL-DTRG'!DI7 -> 11700.786 | H7: =SUM(I7:K7) -> 29233.917 | I7: ='Consol PL-DTRG-Cũ'!CG7 -> 11696.882 | J7: ='Consol PL-DTRG-Cũ'!CU7 -> 7116 | K7: ='Consol PL-DTRG-Cũ'!DI7 -> 10421.035 | L7: =D7-H7 -> 888.01073 | M7: =E7-I7 -> -391.74027 | N7: =F7-J7 -> 0 | O7: =G7-K7 -> 1279.751 | P7: =IFERROR(L7/H7,0) -> 0.030376043 | Q7: =IFERROR(M7/I7,0) -> -0.033490999 | R7: =IFERROR(N7/J7,0) -> 0 | S7: =IFERROR(O7/K7,0) -> 0.1228046 | U7: ='Consol PL-DTRG'!O7 -> 0 | V7: ='Consol PL-DTRG-Cũ'!O7 -> 0 | W7: =U7-V7 -> 0 | X7: =IFERROR(W7/V7,0) -> 0
A8: SL-CC | B8: Con-Con | D8: =SUM(E8:G8) -> 0 | E8: ='Consol PL-DTRG'!CG8 -> 0 | F8: ='Consol PL-DTRG'!CU8 -> 0 | G8: ='Consol PL-DTRG'!DI8 -> 0 | H8: =SUM(I8:K8) -> 0 | I8: ='Consol PL-DTRG-Cũ'!CG8 -> 0 | J8: ='Consol PL-DTRG-Cũ'!CU8 -> 0 | K8: ='Consol PL-DTRG-Cũ'!DI8 -> 0 | L8: =D8-H8 -> 0 | M8: =E8-I8 -> 0 | N8: =F8-J8 -> 0 | O8: =G8-K8 -> 0 | P8: =IFERROR(L8/H8,0) -> 0 | Q8: =IFERROR(M8/I8,0) -> 0 | R8: =IFERROR(N8/J8,0) -> 0 | S8: =IFERROR(O8/K8,0) -> 0 | U8: ='Consol PL-DTRG'!O8 -> 0 | V8: ='Consol PL-DTRG-Cũ'!O8 -> 0 | W8: =U8-V8 -> 0 | X8: =IFERROR(W8/V8,0) -> 0
A9: 2 | B9: 1.Doanh thu bán hàng và cung cấp dịch vụ | D9: =SUM(D10:D12) -> 458198101250 | E9: =SUM(E10:E12) -> 177488853750 | F9: =SUM(F10:F12) -> 99594000000 | G9: =SUM(G10:G12) -> 181115247500 | H9: =SUM(H10:H12) -> 441436738250 | I9: =SUM(I10:I12) -> 182794810750 | J9: =SUM(J10:J12) -> 99594000000 | K9: =SUM(K10:K12) -> 159047927500 | L9: =D9-H9 -> 16761363000 | M9: =E9-I9 -> -5305957000 | N9: =F9-J9 -> 0 | O9: =G9-K9 -> 22067320000 | P9: =IFERROR(L9/H9,0) -> 0.037970023 | Q9: =IFERROR(M9/I9,0) -> -0.029026847 | R9: =IFERROR(N9/J9,0) -> 0 | S9: =IFERROR(O9/K9,0) -> 0.13874635 | U9: =SUM(U10:U12) -> 1.6787476e+12 | V9: =SUM(V10:V12) -> 1.6787476e+12 | W9: =U9-V9 -> 0 | X9: =IFERROR(W9/V9,0) -> 0
A10: 511-BN | B10: Bán ngoài | D10: =SUM(E10:G10) -> 0 | E10: ='Consol PL-DTRG'!CG10 -> 0 | F10: ='Consol PL-DTRG'!CU10 -> 0 | G10: ='Consol PL-DTRG'!DI10 -> 0 | H10: =SUM(I10:K10) -> 0 | I10: ='Consol PL-DTRG-Cũ'!CG10 -> 0 | J10: ='Consol PL-DTRG-Cũ'!CU10 -> 0 | K10: ='Consol PL-DTRG-Cũ'!DI10 -> 0 | L10: =D10-H10 -> 0 | M10: =E10-I10 -> 0 | N10: =F10-J10 -> 0 | O10: =G10-K10 -> 0 | P10: =IFERROR(L10/H10,0) -> 0 | Q10: =IFERROR(M10/I10,0) -> 0 | R10: =IFERROR(N10/J10,0) -> 0 | S10: =IFERROR(O10/K10,0) -> 0 | U10: ='Consol PL-DTRG'!O10 -> 1.6787476e+12 | V10: ='Consol PL-DTRG-Cũ'!O10 -> 1.6787476e+12 | W10: =U10-V10 -> 0 | X10: =IFERROR(W10/V10,0) -> 0
A11: 511-MC | B11: Mẹ-Con | D11: =SUM(E11:G11) -> 458198101250 | E11: ='Consol PL-DTRG'!CG11 -> 177488853750 | F11: ='Consol PL-DTRG'!CU11 -> 99594000000 | G11: ='Consol PL-DTRG'!DI11 -> 181115247500 | H11: =SUM(I11:K11) -> 441436738250 | I11: ='Consol PL-DTRG-Cũ'!CG11 -> 182794810750 | J11: ='Consol PL-DTRG-Cũ'!CU11 -> 99594000000 | K11: ='Consol PL-DTRG-Cũ'!DI11 -> 159047927500 | L11: =D11-H11 -> 16761363000 | M11: =E11-I11 -> -5305957000 | N11: =F11-J11 -> 0 | O11: =G11-K11 -> 22067320000 | P11: =IFERROR(L11/H11,0) -> 0.037970023 | Q11: =IFERROR(M11/I11,0) -> -0.029026847 | R11: =IFERROR(N11/J11,0) -> 0 | S11: =IFERROR(O11/K11,0) -> 0.13874635 | U11: ='Consol PL-DTRG'!O11 -> 0 | V11: ='Consol PL-DTRG-Cũ'!O11 -> 0 | W11: =U11-V11 -> 0 | X11: =IFERROR(W11/V11,0) -> 0
A12: 511-CC | B12: Con-Con | D12: =SUM(E12:G12) -> 0 | E12: ='Consol PL-DTRG'!CG12 -> 0 | F12: ='Consol PL-DTRG'!CU12 -> 0 | G12: ='Consol PL-DTRG'!DI12 -> 0 | H12: =SUM(I12:K12) -> 0 | I12: ='Consol PL-DTRG-Cũ'!CG12 -> 0 | J12: ='Consol PL-DTRG-Cũ'!CU12 -> 0 | K12: ='Consol PL-DTRG-Cũ'!DI12 -> 0 | L12: =D12-H12 -> 0 | M12: =E12-I12 -> 0 | N12: =F12-J12 -> 0 | O12: =G12-K12 -> 0 | P12: =IFERROR(L12/H12,0) -> 0 | Q12: =IFERROR(M12/I12,0) -> 0 | R12: =IFERROR(N12/J12,0) -> 0 | S12: =IFERROR(O12/K12,0) -> 0 | U12: ='Consol PL-DTRG'!O12 -> 0 | V12: ='Consol PL-DTRG-Cũ'!O12 -> 0 | W12: =U12-V12 -> 0 | X12: =IFERROR(W12/V12,0) -> 0
A13: 3 | B13: 2.Các khoản giảm trừ doanh thu | D13: =SUM(D14:D16) -> 0 | E13: =SUM(E14:E16) -> 0 | F13: =SUM(F14:F16) -> 0 | G13: =SUM(G14:G16) -> 0 | H13: =SUM(H14:H16) -> 0 | I13: =SUM(I14:I16) -> 0 | J13: =SUM(J14:J16) -> 0 | K13: =SUM(K14:K16) -> 0 | L13: =D13-H13 -> 0 | M13: =E13-I13 -> 0 | N13: =F13-J13 -> 0 | O13: =G13-K13 -> 0 | P13: =IFERROR(L13/H13,0) -> 0 | Q13: =IFERROR(M13/I13,0) -> 0 | R13: =IFERROR(N13/J13,0) -> 0 | S13: =IFERROR(O13/K13,0) -> 0 | U13: =SUM(U14:U16) -> 0 | V13: =SUM(V14:V16) -> 0 | W13: =U13-V13 -> 0 | X13: =IFERROR(W13/V13,0) -> 0
A14: 521-BN | B14: Bán ngoài | D14: =SUM(E14:G14) -> 0 | E14: ='Consol PL-DTRG'!CG14 -> 0 | F14: ='Consol PL-DTRG'!CU14 -> 0 | G14: ='Consol PL-DTRG'!DI14 -> 0 | H14: =SUM(I14:K14) -> 0 | I14: ='Consol PL-DTRG-Cũ'!CG14 -> 0 | J14: ='Consol PL-DTRG-Cũ'!CU14 -> 0 | K14: ='Consol PL-DTRG-Cũ'!DI14 -> 0 | L14: =D14-H14 -> 0 | M14: =E14-I14 -> 0 | N14: =F14-J14 -> 0 | O14: =G14-K14 -> 0 | P14: =IFERROR(L14/H14,0) -> 0 | Q14: =IFERROR(M14/I14,0) -> 0 | R14: =IFERROR(N14/J14,0) -> 0 | S14: =IFERROR(O14/K14,0) -> 0 | U14: ='Consol PL-DTRG'!O14 -> 0 | V14: ='Consol PL-DTRG-Cũ'!O14 -> 0 | W14: =U14-V14 -> 0 | X14: =IFERROR(W14/V14,0) -> 0
A15: 521-MC | B15: Mẹ-Con | D15: =SUM(E15:G15) -> 0 | E15: ='Consol PL-DTRG'!CG15 -> 0 | F15: ='Consol PL-DTRG'!CU15 -> 0 | G15: ='Consol PL-DTRG'!DI15 -> 0 | H15: =SUM(I15:K15) -> 0 | I15: ='Consol PL-DTRG-Cũ'!CG15 -> 0 | J15: ='Consol PL-DTRG-Cũ'!CU15 -> 0 | K15: ='Consol PL-DTRG-Cũ'!DI15 -> 0 | L15: =D15-H15 -> 0 | M15: =E15-I15 -> 0 | N15: =F15-J15 -> 0 | O15: =G15-K15 -> 0 | P15: =IFERROR(L15/H15,0) -> 0 | Q15: =IFERROR(M15/I15,0) -> 0 | R15: =IFERROR(N15/J15,0) -> 0 | S15: =IFERROR(O15/K15,0) -> 0 | U15: ='Consol PL-DTRG'!O15 -> 0 | V15: ='Consol PL-DTRG-Cũ'!O15 -> 0 | W15: =U15-V15 -> 0 | X15: =IFERROR(W15/V15,0) -> 0
A16: 521-CC | B16: Con-Con | D16: =SUM(E16:G16) -> 0 | E16: ='Consol PL-DTRG'!CG16 -> 0 | F16: ='Consol PL-DTRG'!CU16 -> 0 | G16: ='Consol PL-DTRG'!DI16 -> 0 | H16: =SUM(I16:K16) -> 0 | I16: ='Consol PL-DTRG-Cũ'!CG16 -> 0 | J16: ='Consol PL-DTRG-Cũ'!CU16 -> 0 | K16: ='Consol PL-DTRG-Cũ'!DI16 -> 0 | L16: =D16-H16 -> 0 | M16: =E16-I16 -> 0 | N16: =F16-J16 -> 0 | O16: =G16-K16 -> 0 | P16: =IFERROR(L16/H16,0) -> 0 | Q16: =IFERROR(M16/I16,0) -> 0 | R16: =IFERROR(N16/J16,0) -> 0 | S16: =IFERROR(O16/K16,0) -> 0 | U16: ='Consol PL-DTRG'!O16 -> 0 | V16: ='Consol PL-DTRG-Cũ'!O16 -> 0 | W16: =U16-V16 -> 0 | X16: =IFERROR(W16/V16,0) -> 0
A17: 4 | B17: 3.Doanh thu thuần về bán hàng và cung cấp dịch vụ | D17: =SUM(D18:D20) -> 458198101250 | E17: =SUM(E18:E20) -> 177488853750 | F17: =SUM(F18:F20) -> 99594000000 | G17: =SUM(G18:G20) -> 181115247500 | H17: =SUM(H18:H20) -> 441436738250 | I17: =SUM(I18:I20) -> 182794810750 | J17: =SUM(J18:J20) -> 99594000000 | K17: =SUM(K18:K20) -> 159047927500 | L17: =D17-H17 -> 16761363000 | M17: =E17-I17 -> -5305957000 | N17: =F17-J17 -> 0 | O17: =G17-K17 -> 22067320000 | P17: =IFERROR(L17/H17,0) -> 0.037970023 | Q17: =IFERROR(M17/I17,0) -> -0.029026847 | R17: =IFERROR(N17/J17,0) -> 0 | S17: =IFERROR(O17/K17,0) -> 0.13874635 | U17: =SUM(U18:U20) -> 1.6787476e+12 | V17: =SUM(V18:V20) -> 1.6787476e+12 | W17: =U17-V17 -> 0 | X17: =IFERROR(W17/V17,0) -> 0
A18: DTT-BN | B18: Bán ngoài | D18: =D10-D14 -> 0 | E18: =E10-E14 -> 0 | F18: =F10-F14 -> 0 | G18: =G10-G14 -> 0 | H18: =H10-H14 -> 0 | I18: =I10-I14 -> 0 | J18: =J10-J14 -> 0 | K18: =K10-K14 -> 0 | L18: =D18-H18 -> 0 | M18: =E18-I18 -> 0 | N18: =F18-J18 -> 0 | O18: =G18-K18 -> 0 | P18: =IFERROR(L18/H18,0) -> 0 | Q18: =IFERROR(M18/I18,0) -> 0 | R18: =IFERROR(N18/J18,0) -> 0 | S18: =IFERROR(O18/K18,0) -> 0 | U18: =U10-U14 -> 1.6787476e+12 | V18: =V10-V14 -> 1.6787476e+12 | W18: =U18-V18 -> 0 | X18: =IFERROR(W18/V18,0) -> 0
A19: DTT-MC | B19: Mẹ-Con | D19: =D11-D15 -> 458198101250 | E19: =E11-E15 -> 177488853750 | F19: =F11-F15 -> 99594000000 | G19: =G11-G15 -> 181115247500 | H19: =H11-H15 -> 441436738250 | I19: =I11-I15 -> 182794810750 | J19: =J11-J15 -> 99594000000 | K19: =K11-K15 -> 159047927500 | L19: =D19-H19 -> 16761363000 | M19: =E19-I19 -> -5305957000 | N19: =F19-J19 -> 0 | O19: =G19-K19 -> 22067320000 | P19: =IFERROR(L19/H19,0) -> 0.037970023 | Q19: =IFERROR(M19/I19,0) -> -0.029026847 | R19: =IFERROR(N19/J19,0) -> 0 | S19: =IFERROR(O19/K19,0) -> 0.13874635 | U19: =U11-U15 -> 0 | V19: =V11-V15 -> 0 | W19: =U19-V19 -> 0 | X19: =IFERROR(W19/V19,0) -> 0
A20: DTT-CC | B20: Con-Con | D20: =D12-D16 -> 0 | E20: =E12-E16 -> 0 | F20: =F12-F16 -> 0 | G20: =G12-G16 -> 0 | H20: =H12-H16 -> 0 | I20: =I12-I16 -> 0 | J20: =J12-J16 -> 0 | K20: =K12-K16 -> 0 | L20: =D20-H20 -> 0 | M20: =E20-I20 -> 0 | N20: =F20-J20 -> 0 | O20: =G20-K20 -> 0 | P20: =IFERROR(L20/H20,0) -> 0 | Q20: =IFERROR(M20/I20,0) -> 0 | R20: =IFERROR(N20/J20,0) -> 0 | S20: =IFERROR(O20/K20,0) -> 0 | U20: =U12-U16 -> 0 | V20: =V12-V16 -> 0 | W20: =U20-V20 -> 0 | X20: =IFERROR(W20/V20,0) -> 0
A21: 5 | B21: 4.Giá vốn hàng bán | D21: =SUM(D22:D24)-D25+D26 -> 4.3419899e+11 | E21: =SUM(E22:E24)-E25+E26 -> 1.6798997e+11 | F21: =SUM(F22:F24)-F25+F26 -> 9.2113709e+10 | G21: =SUM(G22:G24)-G25+G26 -> 1.7409531e+11 | H21: =SUM(H22:H24)-H25+H26 -> 4.3957128e+11 | I21: =SUM(I22:I24)-I25+I26 -> 1.8419241e+11 | J21: =SUM(J22:J24)-J25+J26 -> 9.4520064e+10 | K21: =SUM(K22:K24)-K25+K26 -> 1.6085881e+11 | L21: =D21-H21 -> -5.3722971e+09 | M21: =E21-I21 -> -1.6202441e+10 | N21: =F21-J21 -> -2.4063549e+09 | O21: =G21-K21 -> 1.3236499e+10 | P21: =IFERROR(L21/H21,0) -> -0.012221674 | Q21: =IFERROR(M21/I21,0) -> -0.08796476 | R21: =IFERROR(N21/J21,0) -> -0.025458668 | S21: =IFERROR(O21/K21,0) -> 0.082286439 | U21: =SUM(U22:U24)-U25+U26 -> 1.3991907e+12 | V21: =SUM(V22:V24)-V25+V26 -> 1.4141767e+12 | W21: =U21-V21 -> -1.4986055e+10 | X21: =IFERROR(W21/V21,0) -> -0.010597017
A22: 632-BN | B22: Bán ngoài | D22: =SUM(E22:G22) -> 0 | E22: ='Consol PL-DTRG'!CG22 -> 0 | F22: ='Consol PL-DTRG'!CU22 -> 0 | G22: ='Consol PL-DTRG'!DI22 -> 0 | H22: =SUM(I22:K22) -> 0 | I22: ='Consol PL-DTRG-Cũ'!CG22 -> 0 | J22: ='Consol PL-DTRG-Cũ'!CU22 -> 0 | K22: ='Consol PL-DTRG-Cũ'!DI22 -> 0 | L22: =D22-H22 -> 0 | M22: =E22-I22 -> 0 | N22: =F22-J22 -> 0 | O22: =G22-K22 -> 0 | P22: =IFERROR(L22/H22,0) -> 0 | Q22: =IFERROR(M22/I22,0) -> 0 | R22: =IFERROR(N22/J22,0) -> 0 | S22: =IFERROR(O22/K22,0) -> 0 | U22: ='Consol PL-DTRG'!O22 -> 1.4160422e+12 | V22: ='Consol PL-DTRG-Cũ'!O22 -> 1.4160422e+12 | W22: =U22-V22 -> 0 | X22: =IFERROR(W22/V22,0) -> 0
A23: 632-MC | B23: Mẹ-Con | D23: =SUM(E23:G23) -> 4.3419899e+11 | E23: ='Consol PL-DTRG'!CG23 -> 1.6798997e+11 | F23: ='Consol PL-DTRG'!CU23 -> 9.2113709e+10 | G23: ='Consol PL-DTRG'!DI23 -> 1.7409531e+11 | H23: =SUM(I23:K23) -> 4.3957128e+11 | I23: ='Consol PL-DTRG-Cũ'!CG23 -> 1.8419241e+11 | J23: ='Consol PL-DTRG-Cũ'!CU23 -> 9.4520064e+10 | K23: ='Consol PL-DTRG-Cũ'!DI23 -> 1.6085881e+11 | L23: =D23-H23 -> -5.3722971e+09 | M23: =E23-I23 -> -1.6202441e+10 | N23: =F23-J23 -> -2.4063549e+09 | O23: =G23-K23 -> 1.3236499e+10 | P23: =IFERROR(L23/H23,0) -> -0.012221674 | Q23: =IFERROR(M23/I23,0) -> -0.08796476 | R23: =IFERROR(N23/J23,0) -> -0.025458668 | S23: =IFERROR(O23/K23,0) -> 0.082286439 | U23: ='Consol PL-DTRG'!O23 -> -2.3999115e+10 | V23: ='Consol PL-DTRG-Cũ'!O23 -> -1.8654548e+09 | W23: =U23-V23 -> -2.213366e+10 | X23: =IFERROR(W23/V23,0) -> 11.865021
A24: 632-CC | B24: Con-Con | D24: =SUM(E24:G24) -> 0 | E24: ='Consol PL-DTRG'!CG24 -> 0 | F24: ='Consol PL-DTRG'!CU24 -> 0 | G24: ='Consol PL-DTRG'!DI24 -> 0 | H24: =SUM(I24:K24) -> 0 | I24: ='Consol PL-DTRG-Cũ'!CG24 -> 0 | J24: ='Consol PL-DTRG-Cũ'!CU24 -> 0 | K24: ='Consol PL-DTRG-Cũ'!DI24 -> 0 | L24: =D24-H24 -> 0 | M24: =E24-I24 -> 0 | N24: =F24-J24 -> 0 | O24: =G24-K24 -> 0 | P24: =IFERROR(L24/H24,0) -> 0 | Q24: =IFERROR(M24/I24,0) -> 0 | R24: =IFERROR(N24/J24,0) -> 0 | S24: =IFERROR(O24/K24,0) -> 0 | U24: ='Consol PL-DTRG'!O24 -> 0 | V24: ='Consol PL-DTRG-Cũ'!O24 -> 0 | W24: =U24-V24 -> 0 | X24: =IFERROR(W24/V24,0) -> 0
A25: URP-DK | B25: URP đầu kỳ | L25: =D25-H25 -> 0 | M25: =E25-I25 -> 0 | N25: =F25-J25 -> 0 | O25: =G25-K25 -> 0 | P25: =IFERROR(L25/H25,0) -> 0 | Q25: =IFERROR(M25/I25,0) -> 0 | R25: =IFERROR(N25/J25,0) -> 0 | S25: =IFERROR(O25/K25,0) -> 0 | U25: ='Consol PL-DTRG'!O25 -> 0 | V25: ='Consol PL-DTRG-Cũ'!O25 -> 0 | W25: =U25-V25 -> 0 | X25: =IFERROR(W25/V25,0) -> 0
A26: URP-CK | B26: URP cuối kỳ | L26: =D26-H26 -> 0 | M26: =E26-I26 -> 0 | N26: =F26-J26 -> 0 | O26: =G26-K26 -> 0 | P26: =IFERROR(L26/H26,0) -> 0 | Q26: =IFERROR(M26/I26,0) -> 0 | R26: =IFERROR(N26/J26,0) -> 0 | S26: =IFERROR(O26/K26,0) -> 0 | U26: ='Consol PL-DTRG'!O26 -> 7.147605e+09 | V26: ='Consol PL-DTRG-Cũ'!O26 -> 0 | W26: =U26-V26 -> 7.147605e+09 | X26: =IFERROR(W26/V26,0) -> 0
A27: 6 | B27: 5.Lợi nhuận gộp về bán hàng | D27: =SUM(D28:D30) -> 2.3999115e+10 | E27: =SUM(E28:E30) -> 9.4988874e+09 | F27: =SUM(F28:F30) -> 7.4802912e+09 | G27: =SUM(G28:G30) -> 7.0199363e+09 | H27: =SUM(H28:H30) -> 1.8654548e+09 | I27: =SUM(I28:I30) -> -1.3975966e+09 | J27: =SUM(J28:J30) -> 5.0739363e+09 | K27: =SUM(K28:K30) -> -1.8108849e+09 | L27: =D27-H27 -> 2.213366e+10 | M27: =E27-I27 -> 1.0896484e+10 | N27: =F27-J27 -> 2.4063549e+09 | O27: =G27-K27 -> 8.8308212e+09 | P27: =IFERROR(L27/H27,0) -> 11.865021 | Q27: =IFERROR(M27/I27,0) -> -7.7965872 | R27: =IFERROR(N27/J27,0) -> 0.474258 | S27: =IFERROR(O27/K27,0) -> -4.8765227 | U27: =SUM(U28:U30) -> 2.7955694e+11 | V27: =SUM(V28:V30) -> 2.6457089e+11 | W27: =U27-V27 -> 1.4986055e+10 | X27: =IFERROR(W27/V27,0) -> 0.056642873
A28: LG-BN | B28: Bán ngoài | D28: =D18-D22+D25-D26 -> 0 | E28: =E18-E22+E25-E26 -> 0 | F28: =F18-F22+F25-F26 -> 0 | G28: =G18-G22+G25-G26 -> 0 | H28: =H18-H22+H25-H26 -> 0 | I28: =I18-I22+I25-I26 -> 0 | J28: =J18-J22+J25-J26 -> 0 | K28: =K18-K22+K25-K26 -> 0 | L28: =D28-H28 -> 0 | M28: =E28-I28 -> 0 | N28: =F28-J28 -> 0 | O28: =G28-K28 -> 0 | P28: =IFERROR(L28/H28,0) -> 0 | Q28: =IFERROR(M28/I28,0) -> 0 | R28: =IFERROR(N28/J28,0) -> 0 | S28: =IFERROR(O28/K28,0) -> 0 | U28: =U18-U22+U25-U26 -> 2.5555783e+11 | V28: =V18-V22+V25-V26 -> 2.6270543e+11 | W28: =U28-V28 -> -7.147605e+09 | X28: =IFERROR(W28/V28,0) -> -0.027207679
A29: LG-MC | B29: Mẹ-Con | D29: =D19-D23 -> 2.3999115e+10 | E29: =E19-E23 -> 9.4988874e+09 | F29: =F19-F23 -> 7.4802912e+09 | G29: =G19-G23 -> 7.0199363e+09 | H29: =H19-H23 -> 1.8654548e+09 | I29: =I19-I23 -> -1.3975966e+09 | J29: =J19-J23 -> 5.0739363e+09 | K29: =K19-K23 -> -1.8108849e+09 | L29: =D29-H29 -> 2.213366e+10 | M29: =E29-I29 -> 1.0896484e+10 | N29: =F29-J29 -> 2.4063549e+09 | O29: =G29-K29 -> 8.8308212e+09 | P29: =IFERROR(L29/H29,0) -> 11.865021 | Q29: =IFERROR(M29/I29,0) -> -7.7965872 | R29: =IFERROR(N29/J29,0) -> 0.474258 | S29: =IFERROR(O29/K29,0) -> -4.8765227 | U29: =U19-U23 -> 2.3999115e+10 | V29: =V19-V23 -> 1.8654548e+09 | W29: =U29-V29 -> 2.213366e+10 | X29: =IFERROR(W29/V29,0) -> 11.865021
A30: LG-CC | B30: Con-Con | D30: =D20-D24 -> 0 | E30: =E20-E24 -> 0 | F30: =F20-F24 -> 0 | G30: =G20-G24 -> 0 | H30: =H20-H24 -> 0 | I30: =I20-I24 -> 0 | J30: =J20-J24 -> 0 | K30: =K20-K24 -> 0 | L30: =D30-H30 -> 0 | M30: =E30-I30 -> 0 | N30: =F30-J30 -> 0 | O30: =G30-K30 -> 0 | P30: =IFERROR(L30/H30,0) -> 0 | Q30: =IFERROR(M30/I30,0) -> 0 | R30: =IFERROR(N30/J30,0) -> 0 | S30: =IFERROR(O30/K30,0) -> 0 | U30: =U20-U24 -> 0 | V30: =V20-V24 -> 0 | W30: =U30-V30 -> 0 | X30: =IFERROR(W30/V30,0) -> 0
B31: %LG | D31: =IFERROR(D27/D17,0) -> 0.052377159 | E31: =IFERROR(E27/E17,0) -> 0.053518219 | F31: =IFERROR(F27/F17,0) -> 0.07510785 | G31: =IFERROR(G27/G17,0) -> 0.038759499 | H31: =IFERROR(H27/H17,0) -> 0.0042258712 | I31: =IFERROR(I27/I17,0) -> -0.0076457128 | J31: =IFERROR(J27/J17,0) -> 0.050946205 | K31: =IFERROR(K27/K17,0) -> -0.011385781 | L31: =D31-H31 -> 0.048151288 | U31: =IFERROR(U27/U17,0) -> 0.16652708 | V31: =IFERROR(V27/V17,0) -> 0.15760015 | W31: =U31-V31 -> 0.0089269256
A32: 7 | B32: 6.Lãi/lỗ của hoạt động bán, thanh lý bất động sản đầu tư | D32: =SUM(D33:D35) -> 0 | E32: =SUM(E33:E35) -> 0 | F32: =SUM(F33:F35) -> 0 | G32: =SUM(G33:G35) -> 0 | H32: =SUM(H33:H35) -> 0 | I32: =SUM(I33:I35) -> 0 | J32: =SUM(J33:J35) -> 0 | K32: =SUM(K33:K35) -> 0 | L32: =D32-H32 -> 0 | M32: =E32-I32 -> 0 | N32: =F32-J32 -> 0 | O32: =G32-K32 -> 0 | P32: =IFERROR(L32/H32,0) -> 0 | Q32: =IFERROR(M32/I32,0) -> 0 | R32: =IFERROR(N32/J32,0) -> 0 | S32: =IFERROR(O32/K32,0) -> 0 | U32: =SUM(U33:U35) -> 0 | V32: =SUM(V33:V35) -> 0 | W32: =U32-V32 -> 0 | X32: =IFERROR(W32/V32,0) -> 0
A33: TL-TSCĐ-BN | B33: Bán ngoài | D33: =SUM(E33:G33) -> 0 | E33: ='Consol PL-DTRG'!CG32 -> 0 | F33: ='Consol PL-DTRG'!CU32 -> 0 | G33: ='Consol PL-DTRG'!DI32 -> 0 | H33: =SUM(I33:K33) -> 0 | I33: ='Consol PL-DTRG-Cũ'!CG32 -> 0 | J33: ='Consol PL-DTRG-Cũ'!CU32 -> 0 | K33: ='Consol PL-DTRG-Cũ'!DI32 -> 0 | L33: =D33-H33 -> 0 | M33: =E33-I33 -> 0 | N33: =F33-J33 -> 0 | O33: =G33-K33 -> 0 | P33: =IFERROR(L33/H33,0) -> 0 | Q33: =IFERROR(M33/I33,0) -> 0 | R33: =IFERROR(N33/J33,0) -> 0 | S33: =IFERROR(O33/K33,0) -> 0 | U33: ='Consol PL-DTRG'!O32 -> 0 | V33: ='Consol PL-DTRG-Cũ'!O32 -> 0 | W33: =U33-V33 -> 0 | X33: =IFERROR(W33/V33,0) -> 0
A34: TL-TSCĐ-MC | B34: Mẹ-Con | D34: =SUM(E34:G34) -> 0 | E34: ='Consol PL-DTRG'!CG33 -> 0 | F34: ='Consol PL-DTRG'!CU33 -> 0 | G34: ='Consol PL-DTRG'!DI33 -> 0 | H34: =SUM(I34:K34) -> 0 | I34: ='Consol PL-DTRG-Cũ'!CG33 -> 0 | J34: ='Consol PL-DTRG-Cũ'!CU33 -> 0 | K34: ='Consol PL-DTRG-Cũ'!DI33 -> 0 | L34: =D34-H34 -> 0 | M34: =E34-I34 -> 0 | N34: =F34-J34 -> 0 | O34: =G34-K34 -> 0 | P34: =IFERROR(L34/H34,0) -> 0 | Q34: =IFERROR(M34/I34,0) -> 0 | R34: =IFERROR(N34/J34,0) -> 0 | S34: =IFERROR(O34/K34,0) -> 0 | U34: ='Consol PL-DTRG'!O33 -> 0 | V34: ='Consol PL-DTRG-Cũ'!O33 -> 0 | W34: =U34-V34 -> 0 | X34: =IFERROR(W34/V34,0) -> 0
A35: TL-TSCĐ-CC | B35: Con-Con | D35: =SUM(E35:G35) -> 0 | E35: ='Consol PL-DTRG'!CG34 -> 0 | F35: ='Consol PL-DTRG'!CU34 -> 0 | G35: ='Consol PL-DTRG'!DI34 -> 0 | H35: =SUM(I35:K35) -> 0 | I35: ='Consol PL-DTRG-Cũ'!CG34 -> 0 | J35: ='Consol PL-DTRG-Cũ'!CU34 -> 0 | K35: ='Consol PL-DTRG-Cũ'!DI34 -> 0 | L35: =D35-H35 -> 0 | M35: =E35-I35 -> 0 | N35: =F35-J35 -> 0 | O35: =G35-K35 -> 0 | P35: =IFERROR(L35/H35,0) -> 0 | Q35: =IFERROR(M35/I35,0) -> 0 | R35: =IFERROR(N35/J35,0) -> 0 | S35: =IFERROR(O35/K35,0) -> 0 | U35: ='Consol PL-DTRG'!O34 -> 0 | V35: ='Consol PL-DTRG-Cũ'!O34 -> 0 | W35: =U35-V35 -> 0 | X35: =IFERROR(W35/V35,0) -> 0
A36: 8 | B36: 7.Doanh thu hoạt động tài chính | D36: =SUM(E36:G36) -> 150720000 | E36: ='Consol PL-DTRG'!CG35 -> 150000000 | F36: ='Consol PL-DTRG'!CU35 -> 720000 | G36: ='Consol PL-DTRG'!DI35 -> 0 | H36: =SUM(I36:K36) -> 150000000 | I36: ='Consol PL-DTRG-Cũ'!CG35 -> 150000000 | J36: ='Consol PL-DTRG-Cũ'!CU35 -> 0 | K36: ='Consol PL-DTRG-Cũ'!DI35 -> 0 | L36: =D36-H36 -> 720000 | M36: =E36-I36 -> 0 | N36: =F36-J36 -> 720000 | O36: =G36-K36 -> 0 | P36: =IFERROR(L36/H36,0) -> 0.0048 | Q36: =IFERROR(M36/I36,0) -> 0 | R36: =IFERROR(N36/J36,0) -> 0 | S36: =IFERROR(O36/K36,0) -> 0 | U36: ='Consol PL-DTRG'!O35 -> 1.5078658e+08 | V36: ='Consol PL-DTRG-Cũ'!O35 -> 1.5006658e+08 | W36: =U36-V36 -> 720000 | X36: =IFERROR(W36/V36,0) -> 0.0047978705
A37: 9 | B37: 8.Chi phí tài chính | D37: =SUM(E37:G37) -> 0 | E37: ='Consol PL-DTRG'!CG36 -> 0 | F37: ='Consol PL-DTRG'!CU36 -> 0 | G37: ='Consol PL-DTRG'!DI36 -> 0 | H37: =SUM(I37:K37) -> 0 | I37: ='Consol PL-DTRG-Cũ'!CG36 -> 0 | J37: ='Consol PL-DTRG-Cũ'!CU36 -> 0 | K37: ='Consol PL-DTRG-Cũ'!DI36 -> 0 | L37: =D37-H37 -> 0 | M37: =E37-I37 -> 0 | N37: =F37-J37 -> 0 | O37: =G37-K37 -> 0 | P37: =IFERROR(L37/H37,0) -> 0 | Q37: =IFERROR(M37/I37,0) -> 0 | R37: =IFERROR(N37/J37,0) -> 0 | S37: =IFERROR(O37/K37,0) -> 0 | U37: ='Consol PL-DTRG'!O36 -> 3.4565904e+10 | V37: ='Consol PL-DTRG-Cũ'!O36 -> 3.4565904e+10 | W37: =U37-V37 -> 0 | X37: =IFERROR(W37/V37,0) -> 0
A38: 10 | B38: Trong đó: Chi phí lãi vay | D38: =SUM(E38:G38) -> 0 | E38: ='Consol PL-DTRG'!CG37 -> 0 | F38: ='Consol PL-DTRG'!CU37 -> 0 | G38: ='Consol PL-DTRG'!DI37 -> 0 | H38: =SUM(I38:K38) -> 0 | I38: ='Consol PL-DTRG-Cũ'!CG37 -> 0 | J38: ='Consol PL-DTRG-Cũ'!CU37 -> 0 | K38: ='Consol PL-DTRG-Cũ'!DI37 -> 0 | L38: =D38-H38 -> 0 | M38: =E38-I38 -> 0 | N38: =F38-J38 -> 0 | O38: =G38-K38 -> 0 | P38: =IFERROR(L38/H38,0) -> 0 | Q38: =IFERROR(M38/I38,0) -> 0 | R38: =IFERROR(N38/J38,0) -> 0 | S38: =IFERROR(O38/K38,0) -> 0 | U38: ='Consol PL-DTRG'!O37 -> 3.4565904e+10 | V38: ='Consol PL-DTRG-Cũ'!O37 -> 3.4565904e+10 | W38: =U38-V38 -> 0 | X38: =IFERROR(W38/V38,0) -> 0
A39: 11 | B39: 9.Chi phí bán hàng | D39: =SUM(E39:G39) -> 9.0794487e+09 | E39: ='Consol PL-DTRG'!CG38 -> 3799518440 | F39: ='Consol PL-DTRG'!CU38 -> 1.3862338e+09 | G39: ='Consol PL-DTRG'!DI38 -> 3.8936965e+09 | H39: =SUM(I39:K39) -> 8.8177031e+09 | I39: ='Consol PL-DTRG-Cũ'!CG38 -> 3840892528 | J39: ='Consol PL-DTRG-Cũ'!CU38 -> 1.5248571e+09 | K39: ='Consol PL-DTRG-Cũ'!DI38 -> 3.4519534e+09 | L39: =D39-H39 -> 2.6174563e+08 | M39: =E39-I39 -> -41374088 | N39: =F39-J39 -> -1.3862338e+08 | O39: =G39-K39 -> 4.4174309e+08 | P39: =IFERROR(L39/H39,0) -> 0.029684106 | Q39: =IFERROR(M39/I39,0) -> -0.010771998 | R39: =IFERROR(N39/J39,0) -> -0.090909091 | S39: =IFERROR(O39/K39,0) -> 0.12796902 | U39: ='Consol PL-DTRG'!O38 -> 6.5635224e+10 | V39: ='Consol PL-DTRG-Cũ'!O38 -> 6.5373478e+10 | W39: =U39-V39 -> 2.6174563e+08 | X39: =IFERROR(W39/V39,0) -> 0.0040038504
A40: 12 | B40: 10.Chi phí quản lý doanh nghiệp | D40: =SUM(E40:G40) -> 1.4847056e+10 | E40: ='Consol PL-DTRG'!CG39 -> 4.3496623e+09 | F40: ='Consol PL-DTRG'!CU39 -> 4.2928381e+09 | G40: ='Consol PL-DTRG'!DI39 -> 6.2045555e+09 | H40: =SUM(I40:K40) -> 1.6375558e+10 | I40: ='Consol PL-DTRG-Cũ'!CG39 -> 4.6875106e+09 | J40: ='Consol PL-DTRG-Cũ'!CU39 -> 5.4138202e+09 | K40: ='Consol PL-DTRG-Cũ'!DI39 -> 6.2742277e+09 | L40: =D40-H40 -> -1.5285027e+09 | M40: =E40-I40 -> -3.3784836e+08 | N40: =F40-J40 -> -1.1209821e+09 | O40: =G40-K40 -> -69672244 | P40: =IFERROR(L40/H40,0) -> -0.093340493 | Q40: =IFERROR(M40/I40,0) -> -0.072074155 | R40: =IFERROR(N40/J40,0) -> -0.20705935 | S40: =IFERROR(O40/K40,0) -> -0.011104513 | U40: ='Consol PL-DTRG'!O39 -> 1.1444546e+11 | V40: ='Consol PL-DTRG-Cũ'!O39 -> 1.1597396e+11 | W40: =U40-V40 -> -1.5285027e+09 | X40: =IFERROR(W40/V40,0) -> -0.013179706
...

Sheet Consol PL-DTRG
B1: GROUP TÁI CHẾ | C1: =C17-C21-C27 -> 0 | Q1: Phân bổ LG nội bộ | R1: 4
B2: VND
A3: Index PL | B3: PHẦN II-KẾT QUẢ HOẠT ĐỘNG KINH DOANH | C3: HỢP NHẤT | Q3: ĐIỀU CHỈNH | AE3: TỔNG | AS3: DTR | BG3: 3 TRẠM | BU3: ĐỒNG LÂM | CI3: KHÁNH NGA | CW3: ĐẠI LỘC | DK3: TÂN ĐẠI PHÁT | DY3: LƯU CÔNG THỨC
C4: 1 | D4: 2 | E4: 3 | F4: 4 | G4: 5 | H4: 6 | I4: 7 | J4: 8 | K4: 9 | L4: 10 | M4: 11 | N4: 12 | O4: TỔNG | Q4: 1 | R4: 2 | S4: 3 | T4: 4 | U4: 5 | V4: 6 | W4: 7 | X4: 8 | Y4: 9 | Z4: 10 | AA4: 11 | AB4: 12 | AC4: TỔNG | AE4: 1 | AF4: 2 | AG4: 3 | AH4: 4 | AI4: 5 | AJ4: 6 | AK4: 7 | AL4: 8 | AM4: 9 | AN4: 10 | AO4: 11 | AP4: 12 | AQ4: TỔNG | AS4: 1 | AT4: 2 | AU4: 3 | AV4: 4 | AW4: 5 | AX4: 6 | AY4: 7 | AZ4: 8 | BA4: 9 | BB4: 10 | BC4: 11 | BD4: 12 | BE4: TỔNG | BG4: 1 | BH4: 2 | BI4: 3 | BJ4: 4 | BK4: 5 | BL4: 6 | BM4: 7 | BN4: 8 | BO4: 9 | BP4: 10 | BQ4: 11 | BR4: 12 | BS4: TỔNG | BU4: 1 | BV4: 2 | BW4: 3 | BX4: 4 | BY4: 5 | BZ4: 6 | CA4: 7 | CB4: 8 | CC4: 9 | CD4: 10 | CE4: 11 | CF4: 12 | CG4: TỔNG | CI4: 1 | CJ4: 2 | CK4: 3 | CL4: 4 | CM4: 5 | CN4: 6 | CO4: 7 | CP4: 8 | CQ4: 9 | CR4: 10 | CS4: 11 | CT4: 12 | CU4: TỔNG | CW4: 1 | CX4: 2 | CY4: 3 | CZ4: 4 | DA4: 5 | DB4: 6 | DC4: 7 | DD4: 8 | DE4: 9 | DF4: 10 | DG4: 11 | DH4: 12 | DI4: TỔNG | DK4: 1 | DL4: 2 | DM4: 3 | DN4: 4 | DO4: 5 | DP4: 6 | DQ4: 7 | DR4: 8 | DS4: 9 | DT4: 10 | DU4: 11 | DV4: 12 | DW4: TỔNG | DY4: 1 | DZ4: 2 | EA4: 3 | EB4: 4 | EC4: 5 | ED4: 6 | EE4: 7 | EF4: 8 | EG4: 9 | EH4: 10 | EI4: 11 | EJ4: 12 | EK4: TỔNG
A5: 1 | B5: Sản lượng (tấn) | C5: =SUM(C6:C8) -> 4318.2229 | D5: =SUM(D6:D8) -> 4253.3146 | E5: =SUM(E6:E8) -> 4678.5574 | F5: =SUM(F6:F8) -> 4394.2315 | G5: =SUM(G6:G8) -> 4663.4364 | H5: =SUM(H6:H8) -> 4691.9522 | I5: =SUM(I6:I8) -> 4689.4225 | J5: =SUM(J6:J8) -> 4562.8495 | ... O5: =SUM(O6:O8) -> 55000 | Q5: =SUM(Q6:Q8) -> -1961.925 | R5: =SUM(R6:R8) -> -1392.45 | S5: =SUM(S6:S8) -> -2307.425 | T5: =SUM(T6:T8) -> -2662.248 | U5: =SUM(U6:U8) -> -2703.2625 | V5: =SUM(V6:V8) -> -2703.2625 | W5: =SUM(W6:W8) -> -2744.277 | X5: =SUM(X6:X8) -> -2745.044 | ... AC5: =SUM(AC6:AC8) -> -30121.928 | AE5: =SUM(AE6:AE8) -> 6280.1479 | AF5: =SUM(AF6:AF8) -> 5645.7646 | AG5: =SUM(AG6:AG8) -> 6985.9824 | AH5: =SUM(AH6:AH8) -> 7056.4795 | AI5: =SUM(AI6:AI8) -> 7366.6989 | AJ5: =SUM(AJ6:AJ8) -> 7395.2147 | AK5: =SUM(AK6:AK8) -> 7433.6995 | AL5: =SUM(AL6:AL8) -> 7307.8935 | ... AQ5: =SUM(AQ6:AQ8) -> 85121.928 | AS5: =SUM(AS6:AS8) -> 4318.2229 | AT5: =SUM(AT6:AT8) -> 4253.3146 | AU5: =SUM(AU6:AU8) -> 4678.5574 | AV5: =SUM(AV6:AV8) -> 4394.2315 | AW5: =SUM(AW6:AW8) -> 4663.4364 | AX5: =SUM(AX6:AX8) -> 4691.9522 | AY5: =SUM(AY6:AY8) -> 4689.4225 | AZ5: =SUM(AZ6:AZ8) -> 4562.8495 | ... BE5: =SUM(BE6:BE8) -> 55000 | BG5: =SUM(BG6:BG8) -> 1961.925 | BH5: =SUM(BH6:BH8) -> 1392.45 | BI5: =SUM(BI6:BI8) -> 2307.425 | BJ5: =SUM(BJ6:BJ8) -> 2662.248 | BK5: =SUM(BK6:BK8) -> 2703.2625 | BL5: =SUM(BL6:BL8) -> 2703.2625 | BM5: =SUM(BM6:BM8) -> 2744.277 | BN5: =SUM(BN6:BN8) -> 2745.044 | ... BS5: =SUM(BS6:BS8) -> 30121.928 | BU5: =SUM(BU6:BU8) -> 667.5 | BV5: =SUM(BV6:BV8) -> 400.5 | BW5: =SUM(BW6:BW8) -> 884 | BX5: =SUM(BX6:BX8) -> 984.348 | BY5: =SUM(BY6:BY8) -> 1025.3625 | BZ5: =SUM(BZ6:BZ8) -> 1025.3625 | CA5: =SUM(CA6:CA8) -> 1066.377 | CB5: =SUM(CB6:CB8) -> 1067.144 | ... CG5: =SUM(CG6:CG8) -> 11305.142 | CI5: =SUM(CI6:CI8) -> 533.7 | CJ5: =SUM(CJ6:CJ8) -> 400.275 | CK5: =SUM(CK6:CK8) -> 578.175 | CL5: =SUM(CL6:CL8) -> 622.65 | CM5: =SUM(CM6:CM8) -> 622.65 | CN5: =SUM(CN6:CN8) -> 622.65 | CO5: =SUM(CO6:CO8) -> 622.65 | CP5: =SUM(CP6:CP8) -> 622.65 | ... CU5: =SUM(CU6:CU8) -> 7116 | CW5: =SUM(CW6:CW8) -> 760.725 | CX5: =SUM(CX6:CX8) -> 591.675 | CY5: =SUM(CY6:CY8) -> 845.25 | CZ5: =SUM(CZ6:CZ8) -> 1055.25 | DA5: =SUM(DA6:DA8) -> 1055.25 | DB5: =SUM(DB6:DB8) -> 1055.25 | DC5: =SUM(DC6:DC8) -> 1055.25 | DD5: =SUM(DD6:DD8) -> 1055.25 | ... DI5: =SUM(DI6:DI8) -> 11700.786 | DK5: =SUM(DK6:DK8) -> 0 | DL5: =SUM(DL6:DL8) -> 0 | DM5: =SUM(DM6:DM8) -> 0 | DN5: =SUM(DN6:DN8) -> 0 | DO5: =SUM(DO6:DO8) -> 0 | DP5: =SUM(DP6:DP8) -> 0 | DQ5: =SUM(DQ6:DQ8) -> 0 | DR5: =SUM(DR6:DR8) -> 0 | ... DW5: =SUM(DW6:DW8) -> 0 | DY5: =SUM(DY6:DY8) -> 0 | DZ5: =SUM(DZ6:DZ8) -> 0 | EA5: =SUM(EA6:EA8) -> 0 | EB5: =SUM(EB6:EB8) -> 0 | EC5: =SUM(EC6:EC8) -> 0 | ED5: =SUM(ED6:ED8) -> 0 | EE5: =SUM(EE6:EE8) -> 0 | EF5: =SUM(EF6:EF8) -> 0 | ... EK5: =SUM(EK6:EK8) -> 0
A6: SL-BN | B6: Bán ngoài | C6: =Q6+AE6 -> 4318.2229 | D6: =R6+AF6 -> 4253.3146 | E6: =S6+AG6 -> 4678.5574 | F6: =T6+AH6 -> 4394.2315 | G6: =U6+AI6 -> 4663.4364 | H6: =V6+AJ6 -> 4691.9522 | I6: =W6+AK6 -> 4689.4225 | J6: =X6+AL6 -> 4562.8495 | ... N6: =AB6+AP6 -> 4784.5204 | O6: =SUM(C6:N6) -> 55000 | AC6: =SUM(Q6:AB6) -> 0 | AE6: =AS6+BU6+CI6+CW6+DK6 -> 4318.2229 | AF6: =AT6+BV6+CJ6+CX6+DL6 -> 4253.3146 | AG6: =AU6+BW6+CK6+CY6+DM6 -> 4678.5574 | AH6: =AV6+BX6+CL6+CZ6+DN6 -> 4394.2315 | AI6: =AW6+BY6+CM6+DA6+DO6 -> 4663.4364 | AJ6: =AX6+BZ6+CN6+DB6+DP6 -> 4691.9522 | AK6: =AY6+CA6+CO6+DC6+DQ6 -> 4689.4225 | AL6: =AZ6+CB6+CP6+DD6+DR6 -> 4562.8495 | ... AP6: =BD6+CF6+CT6+DH6+DV6 -> 4784.5204 | AQ6: =SUM(AE6:AP6) -> 55000 | AS6: ='PL-KH26-DTR'!BL4 -> 4318.2229 | AT6: 4253.3146 | AU6: 4678.5574 | AV6: 4394.2315 | AW6: 4663.4364 | AX6: 4691.9522 | AY6: 4689.4225 | AZ6: 4562.8495 | BA6: 4774.6231 | BB6: 4468.6263 | BC6: 4720.2431 | BD6: 4784.5204 | BE6: =SUM(AS6:BD6) -> 55000 | BG6: =BU6+CI6+CW6 -> 0 | BH6: =BV6+CJ6+CX6 -> 0 | BI6: =BW6+CK6+CY6 -> 0 | BJ6: =BX6+CL6+CZ6 -> 0 | BK6: =BY6+CM6+DA6 -> 0 | BL6: =BZ6+CN6+DB6 -> 0 | BM6: =CA6+CO6+DC6 -> 0 | BN6: =CB6+CP6+DD6 -> 0 | ... BR6: =CF6+CT6+DH6 -> 0 | BS6: =SUM(BG6:BR6) -> 0 | CG6: =SUM(BU6:CF6) -> 0 | CU6: =SUM(CI6:CT6) -> 0 | DI6: =SUM(CW6:DH6) -> 0 | DW6: =SUM(DK6:DV6) -> 0 | EK6: =SUM(DY6:EJ6) -> 0
A7: SL-MC | B7: Mẹ-Con | C7: =Q7+AE7 -> 0 | D7: =R7+AF7 -> 0 | E7: =S7+AG7 -> 0 | F7: =T7+AH7 -> 0 | G7: =U7+AI7 -> 0 | H7: =V7+AJ7 -> 0 | I7: =W7+AK7 -> 0 | J7: =X7+AL7 -> 0 | ... N7: =AB7+AP7 -> 0 | O7: =SUM(C7:N7) -> 0 | Q7: =-AE7 -> -1961.925 | R7: =-AF7 -> -1392.45 | S7: =-AG7 -> -2307.425 | T7: =-AH7 -> -2662.248 | U7: =-AI7 -> -2703.2625 | V7: =-AJ7 -> -2703.2625 | W7: =-AK7 -> -2744.277 | X7: =-AL7 -> -2745.044 | ... AB7: =-AP7 -> -2746.239 | AC7: =SUM(Q7:AB7) -> -30121.928 | AE7: =AS7+BU7+CI7+CW7+DK7 -> 1961.925 | AF7: =AT7+BV7+CJ7+CX7+DL7 -> 1392.45 | AG7: =AU7+BW7+CK7+CY7+DM7 -> 2307.425 | AH7: =AV7+BX7+CL7+CZ7+DN7 -> 2662.248 | AI7: =AW7+BY7+CM7+DA7+DO7 -> 2703.2625 | AJ7: =AX7+BZ7+CN7+DB7+DP7 -> 2703.2625 | AK7: =AY7+CA7+CO7+DC7+DQ7 -> 2744.277 | AL7: =AZ7+CB7+CP7+DD7+DR7 -> 2745.044 | ... AP7: =BD7+CF7+CT7+DH7+DV7 -> 2746.239 | AQ7: =SUM(AE7:AP7) -> 30121.928 | BE7: =SUM(AS7:BD7) -> 0 | BG7: =BU7+CI7+CW7 -> 1961.925 | BH7: =BV7+CJ7+CX7 -> 1392.45 | BI7: =BW7+CK7+CY7 -> 2307.425 | BJ7: =BX7+CL7+CZ7 -> 2662.248 | BK7: =BY7+CM7+DA7 -> 2703.2625 | BL7: =BZ7+CN7+DB7 -> 2703.2625 | BM7: =CA7+CO7+DC7 -> 2744.277 | BN7: =CB7+CP7+DD7 -> 2745.044 | ... BR7: =CF7+CT7+DH7 -> 2746.239 | BS7: =SUM(BG7:BR7) -> 30121.928 | BU7: ='PL-KH26-DongLam'!G6/10^3 -> 667.5 | BV7: ='PL-KH26-DongLam'!H6/10^3 -> 400.5 | BW7: ='PL-KH26-DongLam'!I6/10^3 -> 884 | BX7: ='PL-KH26-DongLam'!J6/10^3 -> 984.348 | BY7: ='PL-KH26-DongLam'!K6/10^3 -> 1025.3625 | BZ7: ='PL-KH26-DongLam'!L6/10^3 -> 1025.3625 | CA7: ='PL-KH26-DongLam'!M6/10^3 -> 1066.377 | CB7: ='PL-KH26-DongLam'!N6/10^3 -> 1067.144 | ... CF7: ='PL-KH26-DongLam'!R6/10^3 -> 1066.377 | CG7: =SUM(BU7:CF7) -> 11305.142 | CI7: ='PL-KH26-KhanhNga'!G5/10^3 -> 533.7 | CJ7: ='PL-KH26-KhanhNga'!H5/10^3 -> 400.275 | CK7: ='PL-KH26-KhanhNga'!I5/10^3 -> 578.175 | CL7: ='PL-KH26-KhanhNga'!J5/10^3 -> 622.65 | CM7: ='PL-KH26-KhanhNga'!K5/10^3 -> 622.65 | CN7: ='PL-KH26-KhanhNga'!L5/10^3 -> 622.65 | CO7: ='PL-KH26-KhanhNga'!M5/10^3 -> 622.65 | CP7: ='PL-KH26-KhanhNga'!N5/10^3 -> 622.65 | ... CT7: ='PL-KH26-KhanhNga'!R5/10^3 -> 622.65 | CU7: =SUM(CI7:CT7) -> 7116 | CW7: ='PL-KH26-DaiLoc'!F5/10^3 -> 760.725 | CX7: ='PL-KH26-DaiLoc'!G5/10^3 -> 591.675 | CY7: ='PL-KH26-DaiLoc'!H5/10^3 -> 845.25 | CZ7: ='PL-KH26-DaiLoc'!I5/10^3 -> 1055.25 | DA7: ='PL-KH26-DaiLoc'!J5/10^3 -> 1055.25 | DB7: ='PL-KH26-DaiLoc'!K5/10^3 -> 1055.25 | DC7: ='PL-KH26-DaiLoc'!L5/10^3 -> 1055.25 | DD7: ='PL-KH26-DaiLoc'!M5/10^3 -> 1055.25 | ... DH7: ='PL-KH26-DaiLoc'!Q5/10^3 -> 1057.212 | DI7: =SUM(CW7:DH7) -> 11700.786 | DW7: =SUM(DK7:DV7) -> 0 | EK7: =SUM(DY7:EJ7) -> 0
A8: SL-CC | B8: Con-Con | C8: =Q8+AE8 -> 0 | D8: =R8+AF8 -> 0 | E8: =S8+AG8 -> 0 | F8: =T8+AH8 -> 0 | G8: =U8+AI8 -> 0 | H8: =V8+AJ8 -> 0 | I8: =W8+AK8 -> 0 | J8: =X8+AL8 -> 0 | ... N8: =AB8+AP8 -> 0 | O8: =SUM(C8:N8) -> 0 | AC8: =SUM(Q8:AB8) -> 0 | AE8: =AS8+BU8+CI8+CW8+DK8 -> 0 | AF8: =AT8+BV8+CJ8+CX8+DL8 -> 0 | AG8: =AU8+BW8+CK8+CY8+DM8 -> 0 | AH8: =AV8+BX8+CL8+CZ8+DN8 -> 0 | AI8: =AW8+BY8+CM8+DA8+DO8 -> 0 | AJ8: =AX8+BZ8+CN8+DB8+DP8 -> 0 | AK8: =AY8+CA8+CO8+DC8+DQ8 -> 0 | AL8: =AZ8+CB8+CP8+DD8+DR8 -> 0 | ... AP8: =BD8+CF8+CT8+DH8+DV8 -> 0 | AQ8: =SUM(AE8:AP8) -> 0 | BE8: =SUM(AS8:BD8) -> 0 | BG8: =BU8+CI8+CW8 -> 0 | BH8: =BV8+CJ8+CX8 -> 0 | BI8: =BW8+CK8+CY8 -> 0 | BJ8: =BX8+CL8+CZ8 -> 0 | BK8: =BY8+CM8+DA8 -> 0 | BL8: =BZ8+CN8+DB8 -> 0 | BM8: =CA8+CO8+DC8 -> 0 | BN8: =CB8+CP8+DD8 -> 0 | ... BR8: =CF8+CT8+DH8 -> 0 | BS8: =SUM(BG8:BR8) -> 0 | CG8: =SUM(BU8:CF8) -> 0 | CU8: =SUM(CI8:CT8) -> 0 | DI8: =SUM(CW8:DH8) -> 0 | DW8: =SUM(DK8:DV8) -> 0 | EK8: =SUM(DY8:EJ8) -> 0
A9: 2 | B9: 1.Doanh thu bán hàng và cung cấp dịch vụ | C9: =SUM(C10:C12) -> 1.2950534e+11 | D9: =SUM(D10:D12) -> 1.2797444e+11 | E9: =SUM(E10:E12) -> 1.4159949e+11 | F9: =SUM(F10:F12) -> 1.3178227e+11 | G9: =SUM(G10:G12) -> 1.4024431e+11 | H9: =SUM(H10:H12) -> 1.414093e+11 | I9: =SUM(I10:I12) -> 1.4540406e+11 | J9: =SUM(J10:J12) -> 1.4127636e+11 | ... O9: =SUM(O10:O12) -> 1.6787476e+12 | Q9: =SUM(Q10:Q12) -> -28404956250 | R9: =SUM(R10:R12) -> -20210556250 | S9: =SUM(S10:S12) -> -33329800000 | T9: =SUM(T10:T12) -> -40468427500 | U9: =SUM(U10:U12) -> -41125912500 | V9: =SUM(V10:V12) -> -41125912500 | W9: =SUM(W10:W12) -> -41783397500 | X9: =SUM(X10:X12) -> -41806927500 | ... AC9: =SUM(AC10:AC12) -> -458198101250 | AE9: =SUM(AE10:AE12) -> 1.579103e+11 | AF9: =SUM(AF10:AF12) -> 1.48185e+11 | AG9: =SUM(AG10:AG12) -> 1.7492929e+11 | AH9: =SUM(AH10:AH12) -> 1.7225069e+11 | AI9: =SUM(AI10:AI12) -> 1.8137022e+11 | AJ9: =SUM(AJ10:AJ12) -> 1.8253521e+11 | AK9: =SUM(AK10:AK12) -> 1.8718745e+11 | AL9: =SUM(AL10:AL12) -> 1.8308329e+11 | ... AQ9: =SUM(AQ10:AQ12) -> 2.1369457e+12 | AS9: =SUM(AS10:AS12) -> 1.2950534e+11 | AT9: =SUM(AT10:AT12) -> 1.2797444e+11 | AU9: =SUM(AU10:AU12) -> 1.4159949e+11 | AV9: =SUM(AV10:AV12) -> 1.3178227e+11 | AW9: =SUM(AW10:AW12) -> 1.4024431e+11 | AX9: =SUM(AX10:AX12) -> 1.414093e+11 | AY9: =SUM(AY10:AY12) -> 1.4540406e+11 | AZ9: =SUM(AZ10:AZ12) -> 1.4127636e+11 | ... BE9: =SUM(BE10:BE12) -> 1.6787476e+12 | BG9: =SUM(BG10:BG12) -> 28404956250 | BH9: =SUM(BH10:BH12) -> 20210556250 | BI9: =SUM(BI10:BI12) -> 33329800000 | BJ9: =SUM(BJ10:BJ12) -> 40468427500 | BK9: =SUM(BK10:BK12) -> 41125912500 | BL9: =SUM(BL10:BL12) -> 41125912500 | BM9: =SUM(BM10:BM12) -> 41783397500 | BN9: =SUM(BN10:BN12) -> 41806927500 | ... BS9: =SUM(BS10:BS12) -> 458198101250 | BU9: =SUM(BU10:BU12) -> 9420187500 | BV9: =SUM(BV10:BV12) -> 5652112500 | BW9: =SUM(BW10:BW12) -> 12443100000 | BX9: =SUM(BX10:BX12) -> 15779640000 | BY9: =SUM(BY10:BY12) -> 16437125000 | BZ9: =SUM(BZ10:BZ12) -> 16437125000 | CA9: =SUM(CA10:CA12) -> 17094610000 | CB9: =SUM(CB10:CB12) -> 17118140000 | ... CG9: =SUM(CG10:CG12) -> 177488853750 | CI9: =SUM(CI10:CI12) -> 7469550000 | CJ9: =SUM(CJ10:CJ12) -> 5602162500 | CK9: =SUM(CK10:CK12) -> 8092012500 | CL9: =SUM(CL10:CL12) -> 8714475000 | CM9: =SUM(CM10:CM12) -> 8714475000 | CN9: =SUM(CN10:CN12) -> 8714475000 | CO9: =SUM(CO10:CO12) -> 8714475000 | CP9: =SUM(CP10:CP12) -> 8714475000 | ... CU9: =SUM(CU10:CU12) -> 99594000000 | CW9: =SUM(CW10:CW12) -> 11515218750 | CX9: =SUM(CX10:CX12) -> 8956281250 | CY9: =SUM(CY10:CY12) -> 12794687500 | CZ9: =SUM(CZ10:CZ12) -> 15974312500 | DA9: =SUM(DA10:DA12) -> 15974312500 | DB9: =SUM(DB10:DB12) -> 15974312500 | DC9: =SUM(DC10:DC12) -> 15974312500 | DD9: =SUM(DD10:DD12) -> 15974312500 | ... DI9: =SUM(DI10:DI12) -> 181115247500 | DK9: =SUM(DK10:DK12) -> 0 | DL9: =SUM(DL10:DL12) -> 0 | DM9: =SUM(DM10:DM12) -> 0 | DN9: =SUM(DN10:DN12) -> 0 | DO9: =SUM(DO10:DO12) -> 0 | DP9: =SUM(DP10:DP12) -> 0 | DQ9: =SUM(DQ10:DQ12) -> 0 | DR9: =SUM(DR10:DR12) -> 0 | ... DW9: =SUM(DW10:DW12) -> 0 | DY9: =SUM(DY10:DY12) -> 0 | DZ9: =SUM(DZ10:DZ12) -> 0 | EA9: =SUM(EA10:EA12) -> 0 | EB9: =SUM(EB10:EB12) -> 0 | EC9: =SUM(EC10:EC12) -> 0 | ED9: =SUM(ED10:ED12) -> 0 | EE9: =SUM(EE10:EE12) -> 0 | EF9: =SUM(EF10:EF12) -> 0 | ... EK9: =SUM(EK10:EK12) -> 0
A10: 511-BN | B10: Bán ngoài | C10: =Q10+AE10 -> 1.2950534e+11 | D10: =R10+AF10 -> 1.2797444e+11 | E10: =S10+AG10 -> 1.4159949e+11 | F10: =T10+AH10 -> 1.3178227e+11 | G10: =U10+AI10 -> 1.4024431e+11 | H10: =V10+AJ10 -> 1.414093e+11 | I10: =W10+AK10 -> 1.4540406e+11 | J10: =X10+AL10 -> 1.4127636e+11 | ... N10: =AB10+AP10 -> 1.4744201e+11 | O10: =SUM(C10:N10) -> 1.6787476e+12 | AC10: =SUM(Q10:AB10) -> 0 | AE10: =AS10+BU10+CI10+CW10+DK10 -> 1.2950534e+11 | AF10: =AT10+BV10+CJ10+CX10+DL10 -> 1.2797444e+11 | AG10: =AU10+BW10+CK10+CY10+DM10 -> 1.4159949e+11 | AH10: =AV10+BX10+CL10+CZ10+DN10 -> 1.3178227e+11 | AI10: =AW10+BY10+CM10+DA10+DO10 -> 1.4024431e+11 | AJ10: =AX10+BZ10+CN10+DB10+DP10 -> 1.414093e+11 | AK10: =AY10+CA10+CO10+DC10+DQ10 -> 1.4540406e+11 | AL10: =AZ10+CB10+CP10+DD10+DR10 -> 1.4127636e+11 | ... AP10: =BD10+CF10+CT10+DH10+DV10 -> 1.4744201e+11 | AQ10: =SUM(AE10:AP10) -> 1.6787476e+12 | AS10: ='PL-KH26-DTR'!BL5 -> 1.2950534e+11 | AT10: ='PL-KH26-DTR'!BM5 -> 1.2797444e+11 | AU10: ='PL-KH26-DTR'!BN5 -> 1.4159949e+11 | AV10: ='PL-KH26-DTR'!BO5 -> 1.3178227e+11 | AW10: ='PL-KH26-DTR'!BP5 -> 1.4024431e+11 | AX10: ='PL-KH26-DTR'!BQ5 -> 1.414093e+11 | AY10: ='PL-KH26-DTR'!BR5 -> 1.4540406e+11 | AZ10: ='PL-KH26-DTR'!BS5 -> 1.4127636e+11 | ... BD10: ='PL-KH26-DTR'!BW5 -> 1.4744201e+11 | BE10: =SUM(AS10:BD10) -> 1.6787476e+12 | BG10: =BU10+CI10+CW10 -> 0 | BH10: =BV10+CJ10+CX10 -> 0 | BI10: =BW10+CK10+CY10 -> 0 | BJ10: =BX10+CL10+CZ10 -> 0 | BK10: =BY10+CM10+DA10 -> 0 | BL10: =BZ10+CN10+DB10 -> 0 | BM10: =CA10+CO10+DC10 -> 0 | BN10: =CB10+CP10+DD10 -> 0 | ... BR10: =CF10+CT10+DH10 -> 0 | BS10: =SUM(BG10:BR10) -> 0 | CG10: =SUM(BU10:CF10) -> 0 | CU10: =SUM(CI10:CT10) -> 0 | DI10: =SUM(CW10:DH10) -> 0 | DW10: =SUM(DK10:DV10) -> 0 | EK10: =SUM(DY10:EJ10) -> 0
A11: 511-MC | B11: Mẹ-Con | C11: =Q11+AE11 -> 0 | D11: =R11+AF11 -> 0 | E11: =S11+AG11 -> 0 | F11: =T11+AH11 -> 0 | G11: =U11+AI11 -> 0 | H11: =V11+AJ11 -> 0 | I11: =W11+AK11 -> 0 | J11: =X11+AL11 -> 0 | ... N11: =AB11+AP11 -> 0 | O11: =SUM(C11:N11) -> 0 | Q11: =-AE11 -> -28404956250 | R11: =-AF11 -> -20210556250 | S11: =-AG11 -> -33329800000 | T11: =-AH11 -> -40468427500 | U11: =-AI11 -> -41125912500 | V11: =-AJ11 -> -41125912500 | W11: =-AK11 -> -41783397500 | X11: =-AL11 -> -41806927500 | ... AB11: =-AP11 -> -43143480000 | AC11: =SUM(Q11:AB11) -> -458198101250 | AE11: =AS11+BU11+CI11+CW11+DK11 -> 28404956250 | AF11: =AT11+BV11+CJ11+CX11+DL11 -> 20210556250 | AG11: =AU11+BW11+CK11+CY11+DM11 -> 33329800000 | AH11: =AV11+BX11+CL11+CZ11+DN11 -> 40468427500 | AI11: =AW11+BY11+CM11+DA11+DO11 -> 41125912500 | AJ11: =AX11+BZ11+CN11+DB11+DP11 -> 41125912500 | AK11: =AY11+CA11+CO11+DC11+DQ11 -> 41783397500 | AL11: =AZ11+CB11+CP11+DD11+DR11 -> 41806927500 | ... AP11: =BD11+CF11+CT11+DH11+DV11 -> 43143480000 | AQ11: =SUM(AE11:AP11) -> 458198101250 | BE11: =SUM(AS11:BD11) -> 0 | BG11: =BU11+CI11+CW11 -> 28404956250 | BH11: =BV11+CJ11+CX11 -> 20210556250 | BI11: =BW11+CK11+CY11 -> 33329800000 | BJ11: =BX11+CL11+CZ11 -> 40468427500 | BK11: =BY11+CM11+DA11 -> 41125912500 | BL11: =BZ11+CN11+DB11 -> 41125912500 | BM11: =CA11+CO11+DC11 -> 41783397500 | BN11: =CB11+CP11+DD11 -> 41806927500 | ... BR11: =CF11+CT11+DH11 -> 43143480000 | BS11: =SUM(BG11:BR11) -> 458198101250 | BU11: ='PL-KH26-DongLam'!G10 -> 9420187500 | BV11: ='PL-KH26-DongLam'!H10 -> 5652112500 | BW11: ='PL-KH26-DongLam'!I10 -> 12443100000 | BX11: ='PL-KH26-DongLam'!J10 -> 15779640000 | BY11: ='PL-KH26-DongLam'!K10 -> 16437125000 | BZ11: ='PL-KH26-DongLam'!L10 -> 16437125000 | CA11: ='PL-KH26-DongLam'!M10 -> 17094610000 | CB11: ='PL-KH26-DongLam'!N10 -> 17118140000 | ... CF11: ='PL-KH26-DongLam'!R10 -> 17094610000 | CG11: =SUM(BU11:CF11) -> 177488853750 | CI11: ='PL-KH26-KhanhNga'!G9 -> 7469550000 | CJ11: ='PL-KH26-KhanhNga'!H9 -> 5602162500 | CK11: ='PL-KH26-KhanhNga'!I9 -> 8092012500 | CL11: ='PL-KH26-KhanhNga'!J9 -> 8714475000 | CM11: ='PL-KH26-KhanhNga'!K9 -> 8714475000 | CN11: ='PL-KH26-KhanhNga'!L9 -> 8714475000 | CO11: ='PL-KH26-KhanhNga'!M9 -> 8714475000 | CP11: ='PL-KH26-KhanhNga'!N9 -> 8714475000 | ... CT11: ='PL-KH26-KhanhNga'!R9 -> 8714475000 | CU11: =SUM(CI11:CT11) -> 99594000000 | CW11: ='PL-KH26-DaiLoc'!F10 -> 11515218750 | CX11: ='PL-KH26-DaiLoc'!G10 -> 8956281250 | CY11: ='PL-KH26-DaiLoc'!H10 -> 12794687500 | CZ11: ='PL-KH26-DaiLoc'!I10 -> 15974312500 | DA11: ='PL-KH26-DaiLoc'!J10 -> 15974312500 | DB11: ='PL-KH26-DaiLoc'!K10 -> 15974312500 | DC11: ='PL-KH26-DaiLoc'!L10 -> 15974312500 | DD11: ='PL-KH26-DaiLoc'!M10 -> 15974312500 | ... DH11: ='PL-KH26-DaiLoc'!Q10 -> 17334395000 | DI11: =SUM(CW11:DH11) -> 181115247500 | DW11: =SUM(DK11:DV11) -> 0 | EK11: =SUM(DY11:EJ11) -> 0
A12: 511-CC | B12: Con-Con | C12: =Q12+AE12 -> 0 | D12: =R12+AF12 -> 0 | E12: =S12+AG12 -> 0 | F12: =T12+AH12 -> 0 | G12: =U12+AI12 -> 0 | H12: =V12+AJ12 -> 0 | I12: =W12+AK12 -> 0 | J12: =X12+AL12 -> 0 | ... N12: =AB12+AP12 -> 0 | O12: =SUM(C12:N12) -> 0 | AC12: =SUM(Q12:AB12) -> 0 | AE12: =AS12+BU12+CI12+CW12+DK12 -> 0 | AF12: =AT12+BV12+CJ12+CX12+DL12 -> 0 | AG12: =AU12+BW12+CK12+CY12+DM12 -> 0 | AH12: =AV12+BX12+CL12+CZ12+DN12 -> 0 | AI12: =AW12+BY12+CM12+DA12+DO12 -> 0 | AJ12: =AX12+BZ12+CN12+DB12+DP12 -> 0 | AK12: =AY12+CA12+CO12+DC12+DQ12 -> 0 | AL12: =AZ12+CB12+CP12+DD12+DR12 -> 0 | ... AP12: =BD12+CF12+CT12+DH12+DV12 -> 0 | AQ12: =SUM(AE12:AP12) -> 0 | BE12: =SUM(AS12:BD12) -> 0 | BG12: =BU12+CI12+CW12 -> 0 | BH12: =BV12+CJ12+CX12 -> 0 | BI12: =BW12+CK12+CY12 -> 0 | BJ12: =BX12+CL12+CZ12 -> 0 | BK12: =BY12+CM12+DA12 -> 0 | BL12: =BZ12+CN12+DB12 -> 0 | BM12: =CA12+CO12+DC12 -> 0 | BN12: =CB12+CP12+DD12 -> 0 | ... BR12: =CF12+CT12+DH12 -> 0 | BS12: =SUM(BG12:BR12) -> 0 | CG12: =SUM(BU12:CF12) -> 0 | CU12: =SUM(CI12:CT12) -> 0 | DI12: =SUM(CW12:DH12) -> 0 | DW12: =SUM(DK12:DV12) -> 0 | EK12: =SUM(DY12:EJ12) -> 0
A13: 3 | B13: 2.Các khoản giảm trừ doanh thu | C13: =SUM(C14:C16) -> 0 | D13: =SUM(D14:D16) -> 0 | E13: =SUM(E14:E16) -> 0 | F13: =SUM(F14:F16) -> 0 | G13: =SUM(G14:G16) -> 0 | H13: =SUM(H14:H16) -> 0 | I13: =SUM(I14:I16) -> 0 | J13: =SUM(J14:J16) -> 0 | ... O13: =SUM(O14:O16) -> 0 | Q13: =SUM(Q14:Q16) -> 0 | R13: =SUM(R14:R16) -> 0 | S13: =SUM(S14:S16) -> 0 | T13: =SUM(T14:T16) -> 0 | U13: =SUM(U14:U16) -> 0 | V13: =SUM(V14:V16) -> 0 | W13: =SUM(W14:W16) -> 0 | X13: =SUM(X14:X16) -> 0 | ... AC13: =SUM(AC14:AC16) -> 0 | AE13: =SUM(AE14:AE16) -> 0 | AF13: =SUM(AF14:AF16) -> 0 | AG13: =SUM(AG14:AG16) -> 0 | AH13: =SUM(AH14:AH16) -> 0 | AI13: =SUM(AI14:AI16) -> 0 | AJ13: =SUM(AJ14:AJ16) -> 0 | AK13: =SUM(AK14:AK16) -> 0 | AL13: =SUM(AL14:AL16) -> 0 | ... AQ13: =SUM(AQ14:AQ16) -> 0 | AS13: =SUM(AS14:AS16) -> 0 | AT13: =SUM(AT14:AT16) -> 0 | AU13: =SUM(AU14:AU16) -> 0 | AV13: =SUM(AV14:AV16) -> 0 | AW13: =SUM(AW14:AW16) -> 0 | AX13: =SUM(AX14:AX16) -> 0 | AY13: =SUM(AY14:AY16) -> 0 | AZ13: =SUM(AZ14:AZ16) -> 0 | ... BE13: =SUM(BE14:BE16) -> 0 | BG13: =SUM(BG14:BG16) -> 0 | BH13: =SUM(BH14:BH16) -> 0 | BI13: =SUM(BI14:BI16) -> 0 | BJ13: =SUM(BJ14:BJ16) -> 0 | BK13: =SUM(BK14:BK16) -> 0 | BL13: =SUM(BL14:BL16) -> 0 | BM13: =SUM(BM14:BM16) -> 0 | BN13: =SUM(BN14:BN16) -> 0 | ... BS13: =SUM(BS14:BS16) -> 0 | BU13: =SUM(BU14:BU16) -> 0 | BV13: =SUM(BV14:BV16) -> 0 | BW13: =SUM(BW14:BW16) -> 0 | BX13: =SUM(BX14:BX16) -> 0 | BY13: =SUM(BY14:BY16) -> 0 | BZ13: =SUM(BZ14:BZ16) -> 0 | CA13: =SUM(CA14:CA16) -> 0 | CB13: =SUM(CB14:CB16) -> 0 | ... CG13: =SUM(CG14:CG16) -> 0 | CI13: =SUM(CI14:CI16) -> 0 | CJ13: =SUM(CJ14:CJ16) -> 0 | CK13: =SUM(CK14:CK16) -> 0 | CL13: =SUM(CL14:CL16) -> 0 | CM13: =SUM(CM14:CM16) -> 0 | CN13: =SUM(CN14:CN16) -> 0 | CO13: =SUM(CO14:CO16) -> 0 | CP13: =SUM(CP14:CP16) -> 0 | ... CU13: =SUM(CU14:CU16) -> 0 | CW13: =SUM(CW14:CW16) -> 0 | CX13: =SUM(CX14:CX16) -> 0 | CY13: =SUM(CY14:CY16) -> 0 | CZ13: =SUM(CZ14:CZ16) -> 0 | DA13: =SUM(DA14:DA16) -> 0 | DB13: =SUM(DB14:DB16) -> 0 | DC13: =SUM(DC14:DC16) -> 0 | DD13: =SUM(DD14:DD16) -> 0 | ... DI13: =SUM(DI14:DI16) -> 0 | DK13: =SUM(DK14:DK16) -> 0 | DL13: =SUM(DL14:DL16) -> 0 | DM13: =SUM(DM14:DM16) -> 0 | DN13: =SUM(DN14:DN16) -> 0 | DO13: =SUM(DO14:DO16) -> 0 | DP13: =SUM(DP14:DP16) -> 0 | DQ13: =SUM(DQ14:DQ16) -> 0 | DR13: =SUM(DR14:DR16) -> 0 | ... DW13: =SUM(DW14:DW16) -> 0 | DY13: =SUM(DY14:DY16) -> 0 | DZ13: =SUM(DZ14:DZ16) -> 0 | EA13: =SUM(EA14:EA16) -> 0 | EB13: =SUM(EB14:EB16) -> 0 | EC13: =SUM(EC14:EC16) -> 0 | ED13: =SUM(ED14:ED16) -> 0 | EE13: =SUM(EE14:EE16) -> 0 | EF13: =SUM(EF14:EF16) -> 0 | ... EK13: =SUM(EK14:EK16) -> 0
A14: 521-BN | B14: Bán ngoài | C14: =Q14+AE14 -> 0 | D14: =R14+AF14 -> 0 | E14: =S14+AG14 -> 0 | F14: =T14+AH14 -> 0 | G14: =U14+AI14 -> 0 | H14: =V14+AJ14 -> 0 | I14: =W14+AK14 -> 0 | J14: =X14+AL14 -> 0 | ... N14: =AB14+AP14 -> 0 | O14: =SUM(C14:N14) -> 0 | AC14: =SUM(Q14:AB14) -> 0 | AE14: =AS14+BU14+CI14+CW14+DK14 -> 0 | AF14: =AT14+BV14+CJ14+CX14+DL14 -> 0 | AG14: =AU14+BW14+CK14+CY14+DM14 -> 0 | AH14: =AV14+BX14+CL14+CZ14+DN14 -> 0 | AI14: =AW14+BY14+CM14+DA14+DO14 -> 0 | AJ14: =AX14+BZ14+CN14+DB14+DP14 -> 0 | AK14: =AY14+CA14+CO14+DC14+DQ14 -> 0 | AL14: =AZ14+CB14+CP14+DD14+DR14 -> 0 | ... AP14: =BD14+CF14+CT14+DH14+DV14 -> 0 | AQ14: =SUM(AE14:AP14) -> 0 | BE14: =SUM(AS14:BD14) -> 0 | BG14: =BU14+CI14+CW14 -> 0 | BH14: =BV14+CJ14+CX14 -> 0 | BI14: =BW14+CK14+CY14 -> 0 | BJ14: =BX14+CL14+CZ14 -> 0 | BK14: =BY14+CM14+DA14 -> 0 | BL14: =BZ14+CN14+DB14 -> 0 | BM14: =CA14+CO14+DC14 -> 0 | BN14: =CB14+CP14+DD14 -> 0 | ... BR14: =CF14+CT14+DH14 -> 0 | BS14: =SUM(BG14:BR14) -> 0 | CG14: =SUM(BU14:CF14) -> 0 | CU14: =SUM(CI14:CT14) -> 0 | DI14: =SUM(CW14:DH14) -> 0 | DW14: =SUM(DK14:DV14) -> 0 | EK14: =SUM(DY14:EJ14) -> 0
A15: 521-MC | B15: Mẹ-Con | C15: =Q15+AE15 -> 0 | D15: =R15+AF15 -> 0 | E15: =S15+AG15 -> 0 | F15: =T15+AH15 -> 0 | G15: =U15+AI15 -> 0 | H15: =V15+AJ15 -> 0 | I15: =W15+AK15 -> 0 | J15: =X15+AL15 -> 0 | ... N15: =AB15+AP15 -> 0 | O15: =SUM(C15:N15) -> 0 | AC15: =SUM(Q15:AB15) -> 0 | AE15: =AS15+BU15+CI15+CW15+DK15 -> 0 | AF15: =AT15+BV15+CJ15+CX15+DL15 -> 0 | AG15: =AU15+BW15+CK15+CY15+DM15 -> 0 | AH15: =AV15+BX15+CL15+CZ15+DN15 -> 0 | AI15: =AW15+BY15+CM15+DA15+DO15 -> 0 | AJ15: =AX15+BZ15+CN15+DB15+DP15 -> 0 | AK15: =AY15+CA15+CO15+DC15+DQ15 -> 0 | AL15: =AZ15+CB15+CP15+DD15+DR15 -> 0 | ... AP15: =BD15+CF15+CT15+DH15+DV15 -> 0 | AQ15: =SUM(AE15:AP15) -> 0 | BE15: =SUM(AS15:BD15) -> 0 | BG15: =BU15+CI15+CW15 -> 0 | BH15: =BV15+CJ15+CX15 -> 0 | BI15: =BW15+CK15+CY15 -> 0 | BJ15: =BX15+CL15+CZ15 -> 0 | BK15: =BY15+CM15+DA15 -> 0 | BL15: =BZ15+CN15+DB15 -> 0 | BM15: =CA15+CO15+DC15 -> 0 | BN15: =CB15+CP15+DD15 -> 0 | ... BR15: =CF15+CT15+DH15 -> 0 | BS15: =SUM(BG15:BR15) -> 0 | CG15: =SUM(BU15:CF15) -> 0 | CU15: =SUM(CI15:CT15) -> 0 | DI15: =SUM(CW15:DH15) -> 0 | DW15: =SUM(DK15:DV15) -> 0 | EK15: =SUM(DY15:EJ15) -> 0
A16: 521-CC | B16: Con-Con | C16: =Q16+AE16 -> 0 | D16: =R16+AF16 -> 0 | E16: =S16+AG16 -> 0 | F16: =T16+AH16 -> 0 | G16: =U16+AI16 -> 0 | H16: =V16+AJ16 -> 0 | I16: =W16+AK16 -> 0 | J16: =X16+AL16 -> 0 | ... N16: =AB16+AP16 -> 0 | O16: =SUM(C16:N16) -> 0 | AC16: =SUM(Q16:AB16) -> 0 | AE16: =AS16+BU16+CI16+CW16+DK16 -> 0 | AF16: =AT16+BV16+CJ16+CX16+DL16 -> 0 | AG16: =AU16+BW16+CK16+CY16+DM16 -> 0 | AH16: =AV16+BX16+CL16+CZ16+DN16 -> 0 | AI16: =AW16+BY16+CM16+DA16+DO16 -> 0 | AJ16: =AX16+BZ16+CN16+DB16+DP16 -> 0 | AK16: =AY16+CA16+CO16+DC16+DQ16 -> 0 | AL16: =AZ16+CB16+CP16+DD16+DR16 -> 0 | ... AP16: =BD16+CF16+CT16+DH16+DV16 -> 0 | AQ16: =SUM(AE16:AP16) -> 0 | BE16: =SUM(AS16:BD16) -> 0 | BG16: =BU16+CI16+CW16 -> 0 | BH16: =BV16+CJ16+CX16 -> 0 | BI16: =BW16+CK16+CY16 -> 0 | BJ16: =BX16+CL16+CZ16 -> 0 | BK16: =BY16+CM16+DA16 -> 0 | BL16: =BZ16+CN16+DB16 -> 0 | BM16: =CA16+CO16+DC16 -> 0 | BN16: =CB16+CP16+DD16 -> 0 | ... BR16: =CF16+CT16+DH16 -> 0 | BS16: =SUM(BG16:BR16) -> 0 | CG16: =SUM(BU16:CF16) -> 0 | CU16: =SUM(CI16:CT16) -> 0 | DI16: =SUM(CW16:DH16) -> 0 | DW16: =SUM(DK16:DV16) -> 0 | EK16: =SUM(DY16:EJ16) -> 0
A17: 4 | B17: 3.Doanh thu thuần về bán hàng và cung cấp dịch vụ | C17: =SUM(C18:C20) -> 1.2950534e+11 | D17: =SUM(D18:D20) -> 1.2797444e+11 | E17: =SUM(E18:E20) -> 1.4159949e+11 | F17: =SUM(F18:F20) -> 1.3178227e+11 | G17: =SUM(G18:G20) -> 1.4024431e+11 | H17: =SUM(H18:H20) -> 1.414093e+11 | I17: =SUM(I18:I20) -> 1.4540406e+11 | J17: =SUM(J18:J20) -> 1.4127636e+11 | ... O17: =SUM(O18:O20) -> 1.6787476e+12 | Q17: =SUM(Q18:Q20) -> -28404956250 | R17: =SUM(R18:R20) -> -20210556250 | S17: =SUM(S18:S20) -> -33329800000 | T17: =SUM(T18:T20) -> -40468427500 | U17: =SUM(U18:U20) -> -41125912500 | V17: =SUM(V18:V20) -> -41125912500 | W17: =SUM(W18:W20) -> -41783397500 | X17: =SUM(X18:X20) -> -41806927500 | ... AC17: =SUM(AC18:AC20) -> -458198101250 | AE17: =SUM(AE18:AE20) -> 1.579103e+11 | AF17: =SUM(AF18:AF20) -> 1.48185e+11 | AG17: =SUM(AG18:AG20) -> 1.7492929e+11 | AH17: =SUM(AH18:AH20) -> 1.7225069e+11 | AI17: =SUM(AI18:AI20) -> 1.8137022e+11 | AJ17: =SUM(AJ18:AJ20) -> 1.8253521e+11 | AK17: =SUM(AK18:AK20) -> 1.8718745e+11 | AL17: =SUM(AL18:AL20) -> 1.8308329e+11 | ... AQ17: =SUM(AQ18:AQ20) -> 2.1369457e+12 | AS17: =SUM(AS18:AS20) -> 1.2950534e+11 | AT17: =SUM(AT18:AT20) -> 1.2797444e+11 | AU17: =SUM(AU18:AU20) -> 1.4159949e+11 | AV17: =SUM(AV18:AV20) -> 1.3178227e+11 | AW17: =SUM(AW18:AW20) -> 1.4024431e+11 | AX17: =SUM(AX18:AX20) -> 1.414093e+11 | AY17: =SUM(AY18:AY20) -> 1.4540406e+11 | AZ17: =SUM(AZ18:AZ20) -> 1.4127636e+11 | ... BE17: =SUM(BE18:BE20) -> 1.6787476e+12 | BG17: =SUM(BG18:BG20) -> 28404956250 | BH17: =SUM(BH18:BH20) -> 20210556250 | BI17: =SUM(BI18:BI20) -> 33329800000 | BJ17: =SUM(BJ18:BJ20) -> 40468427500 | BK17: =SUM(BK18:BK20) -> 41125912500 | BL17: =SUM(BL18:BL20) -> 41125912500 | BM17: =SUM(BM18:BM20) -> 41783397500 | BN17: =SUM(BN18:BN20) -> 41806927500 | ... BS17: =SUM(BS18:BS20) -> 458198101250 | BU17: =SUM(BU18:BU20) -> 9420187500 | BV17: =SUM(BV18:BV20) -> 5652112500 | BW17: =SUM(BW18:BW20) -> 12443100000 | BX17: =SUM(BX18:BX20) -> 15779640000 | BY17: =SUM(BY18:BY20) -> 16437125000 | BZ17: =SUM(BZ18:BZ20) -> 16437125000 | CA17: =SUM(CA18:CA20) -> 17094610000 | CB17: =SUM(CB18:CB20) -> 17118140000 | ... CG17: =SUM(CG18:CG20) -> 177488853750 | CI17: =SUM(CI18:CI20) -> 7469550000 | CJ17: =SUM(CJ18:CJ20) -> 5602162500 | CK17: =SUM(CK18:CK20) -> 8092012500 | CL17: =SUM(CL18:CL20) -> 8714475000 | CM17: =SUM(CM18:CM20) -> 8714475000 | CN17: =SUM(CN18:CN20) -> 8714475000 | CO17: =SUM(CO18:CO20) -> 8714475000 | CP17: =SUM(CP18:CP20) -> 8714475000 | ... CU17: =SUM(CU18:CU20) -> 99594000000 | CW17: =SUM(CW18:CW20) -> 11515218750 | CX17: =SUM(CX18:CX20) -> 8956281250 | CY17: =SUM(CY18:CY20) -> 12794687500 | CZ17: =SUM(CZ18:CZ20) -> 15974312500 | DA17: =SUM(DA18:DA20) -> 15974312500 | DB17: =SUM(DB18:DB20) -> 15974312500 | DC17: =SUM(DC18:DC20) -> 15974312500 | DD17: =SUM(DD18:DD20) -> 15974312500 | ... DI17: =SUM(DI18:DI20) -> 181115247500 | DK17: =SUM(DK18:DK20) -> 0 | DL17: =SUM(DL18:DL20) -> 0 | DM17: =SUM(DM18:DM20) -> 0 | DN17: =SUM(DN18:DN20) -> 0 | DO17: =SUM(DO18:DO20) -> 0 | DP17: =SUM(DP18:DP20) -> 0 | DQ17: =SUM(DQ18:DQ20) -> 0 | DR17: =SUM(DR18:DR20) -> 0 | ... DW17: =SUM(DW18:DW20) -> 0 | DY17: =SUM(DY18:DY20) -> 0 | DZ17: =SUM(DZ18:DZ20) -> 0 | EA17: =SUM(EA18:EA20) -> 0 | EB17: =SUM(EB18:EB20) -> 0 | EC17: =SUM(EC18:EC20) -> 0 | ED17: =SUM(ED18:ED20) -> 0 | EE17: =SUM(EE18:EE20) -> 0 | EF17: =SUM(EF18:EF20) -> 0 | ... EK17: =SUM(EK18:EK20) -> 0
A18: DTT-BN | B18: Bán ngoài | C18: =C10-C14 -> 1.2950534e+11 | D18: =D10-D14 -> 1.2797444e+11 | E18: =E10-E14 -> 1.4159949e+11 | F18: =F10-F14 -> 1.3178227e+11 | G18: =G10-G14 -> 1.4024431e+11 | H18: =H10-H14 -> 1.414093e+11 | I18: =I10-I14 -> 1.4540406e+11 | J18: =J10-J14 -> 1.4127636e+11 | ... O18: =O10-O14 -> 1.6787476e+12 | Q18: =Q10-Q14 -> 0 | R18: =R10-R14 -> 0 | S18: =S10-S14 -> 0 | T18: =T10-T14 -> 0 | U18: =U10-U14 -> 0 | V18: =V10-V14 -> 0 | W18: =W10-W14 -> 0 | X18: =X10-X14 -> 0 | ... AC18: =AC10-AC14 -> 0 | AE18: =AE10-AE14 -> 1.2950534e+11 | AF18: =AF10-AF14 -> 1.2797444e+11 | AG18: =AG10-AG14 -> 1.4159949e+11 | AH18: =AH10-AH14 -> 1.3178227e+11 | AI18: =AI10-AI14 -> 1.4024431e+11 | AJ18: =AJ10-AJ14 -> 1.414093e+11 | AK18: =AK10-AK14 -> 1.4540406e+11 | AL18: =AL10-AL14 -> 1.4127636e+11 | ... AQ18: =AQ10-AQ14 -> 1.6787476e+12 | AS18: =AS10-AS14 -> 1.2950534e+11 | AT18: =AT10-AT14 -> 1.2797444e+11 | AU18: =AU10-AU14 -> 1.4159949e+11 | AV18: =AV10-AV14 -> 1.3178227e+11 | AW18: =AW10-AW14 -> 1.4024431e+11 | AX18: =AX10-AX14 -> 1.414093e+11 | AY18: =AY10-AY14 -> 1.4540406e+11 | AZ18: =AZ10-AZ14 -> 1.4127636e+11 | ... BE18: =BE10-BE14 -> 1.6787476e+12 | BG18: =BG10-BG14 -> 0 | BH18: =BH10-BH14 -> 0 | BI18: =BI10-BI14 -> 0 | BJ18: =BJ10-BJ14 -> 0 | BK18: =BK10-BK14 -> 0 | BL18: =BL10-BL14 -> 0 | BM18: =BM10-BM14 -> 0 | BN18: =BN10-BN14 -> 0 | ... BS18: =BS10-BS14 -> 0 | BU18: =BU10-BU14 -> 0 | BV18: =BV10-BV14 -> 0 | BW18: =BW10-BW14 -> 0 | BX18: =BX10-BX14 -> 0 | BY18: =BY10-BY14 -> 0 | BZ18: =BZ10-BZ14 -> 0 | CA18: =CA10-CA14 -> 0 | CB18: =CB10-CB14 -> 0 | ... CG18: =CG10-CG14 -> 0 | CI18: =CI10-CI14 -> 0 | CJ18: =CJ10-CJ14 -> 0 | CK18: =CK10-CK14 -> 0 | CL18: =CL10-CL14 -> 0 | CM18: =CM10-CM14 -> 0 | CN18: =CN10-CN14 -> 0 | CO18: =CO10-CO14 -> 0 | CP18: =CP10-CP14 -> 0 | ... CU18: =CU10-CU14 -> 0 | CW18: =CW10-CW14 -> 0 | CX18: =CX10-CX14 -> 0 | CY18: =CY10-CY14 -> 0 | CZ18: =CZ10-CZ14 -> 0 | DA18: =DA10-DA14 -> 0 | DB18: =DB10-DB14 -> 0 | DC18: =DC10-DC14 -> 0 | DD18: =DD10-DD14 -> 0 | ... DI18: =DI10-DI14 -> 0 | DK18: =DK10-DK14 -> 0 | DL18: =DL10-DL14 -> 0 | DM18: =DM10-DM14 -> 0 | DN18: =DN10-DN14 -> 0 | DO18: =DO10-DO14 -> 0 | DP18: =DP10-DP14 -> 0 | DQ18: =DQ10-DQ14 -> 0 | DR18: =DR10-DR14 -> 0 | ... DW18: =DW10-DW14 -> 0 | DY18: =DY10-DY14 -> 0 | DZ18: =DZ10-DZ14 -> 0 | EA18: =EA10-EA14 -> 0 | EB18: =EB10-EB14 -> 0 | EC18: =EC10-EC14 -> 0 | ED18: =ED10-ED14 -> 0 | EE18: =EE10-EE14 -> 0 | EF18: =EF10-EF14 -> 0 | ... EK18: =EK10-EK14 -> 0
A19: DTT-MC | B19: Mẹ-Con | C19: =C11-C15 -> 0 | D19: =D11-D15 -> 0 | E19: =E11-E15 -> 0 | F19: =F11-F15 -> 0 | G19: =G11-G15 -> 0 | H19: =H11-H15 -> 0 | I19: =I11-I15 -> 0 | J19: =J11-J15 -> 0 | ... O19: =O11-O15 -> 0 | Q19: =Q11-Q15 -> -28404956250 | R19: =R11-R15 -> -20210556250 | S19: =S11-S15 -> -33329800000 | T19: =T11-T15 -> -40468427500 | U19: =U11-U15 -> -41125912500 | V19: =V11-V15 -> -41125912500 | W19: =W11-W15 -> -41783397500 | X19: =X11-X15 -> -41806927500 | ... AC19: =AC11-AC15 -> -458198101250 | AE19: =AE11-AE15 -> 28404956250 | AF19: =AF11-AF15 -> 20210556250 | AG19: =AG11-AG15 -> 33329800000 | AH19: =AH11-AH15 -> 40468427500 | AI19: =AI11-AI15 -> 41125912500 | AJ19: =AJ11-AJ15 -> 41125912500 | AK19: =AK11-AK15 -> 41783397500 | AL19: =AL11-AL15 -> 41806927500 | ... AQ19: =AQ11-AQ15 -> 458198101250 | AS19: =AS11-AS15 -> 0 | AT19: =AT11-AT15 -> 0 | AU19: =AU11-AU15 -> 0 | AV19: =AV11-AV15 -> 0 | AW19: =AW11-AW15 -> 0 | AX19: =AX11-AX15 -> 0 | AY19: =AY11-AY15 -> 0 | AZ19: =AZ11-AZ15 -> 0 | ... BE19: =BE11-BE15 -> 0 | BG19: =BG11-BG15 -> 28404956250 | BH19: =BH11-BH15 -> 20210556250 | BI19: =BI11-BI15 -> 33329800000 | BJ19: =BJ11-BJ15 -> 40468427500 | BK19: =BK11-BK15 -> 41125912500 | BL19: =BL11-BL15 -> 41125912500 | BM19: =BM11-BM15 -> 41783397500 | BN19: =BN11-BN15 -> 41806927500 | ... BS19: =BS11-BS15 -> 458198101250 | BU19: =BU11-BU15 -> 9420187500 | BV19: =BV11-BV15 -> 5652112500 | BW19: =BW11-BW15 -> 12443100000 | BX19: =BX11-BX15 -> 15779640000 | BY19: =BY11-BY15 -> 16437125000 | BZ19: =BZ11-BZ15 -> 16437125000 | CA19: =CA11-CA15 -> 17094610000 | CB19: =CB11-CB15 -> 17118140000 | ... CG19: =CG11-CG15 -> 177488853750 | CI19: =CI11-CI15 -> 7469550000 | CJ19: =CJ11-CJ15 -> 5602162500 | CK19: =CK11-CK15 -> 8092012500 | CL19: =CL11-CL15 -> 8714475000 | CM19: =CM11-CM15 -> 8714475000 | CN19: =CN11-CN15 -> 8714475000 | CO19: =CO11-CO15 -> 8714475000 | CP19: =CP11-CP15 -> 8714475000 | ... CU19: =CU11-CU15 -> 99594000000 | CW19: =CW11-CW15 -> 11515218750 | CX19: =CX11-CX15 -> 8956281250 | CY19: =CY11-CY15 -> 12794687500 | CZ19: =CZ11-CZ15 -> 15974312500 | DA19: =DA11-DA15 -> 15974312500 | DB19: =DB11-DB15 -> 15974312500 | DC19: =DC11-DC15 -> 15974312500 | DD19: =DD11-DD15 -> 15974312500 | ... DI19: =DI11-DI15 -> 181115247500 | DK19: =DK11-DK15 -> 0 | DL19: =DL11-DL15 -> 0 | DM19: =DM11-DM15 -> 0 | DN19: =DN11-DN15 -> 0 | DO19: =DO11-DO15 -> 0 | DP19: =DP11-DP15 -> 0 | DQ19: =DQ11-DQ15 -> 0 | DR19: =DR11-DR15 -> 0 | ... DW19: =DW11-DW15 -> 0 | DY19: =DY11-DY15 -> 0 | DZ19: =DZ11-DZ15 -> 0 | EA19: =EA11-EA15 -> 0 | EB19: =EB11-EB15 -> 0 | EC19: =EC11-EC15 -> 0 | ED19: =ED11-ED15 -> 0 | EE19: =EE11-EE15 -> 0 | EF19: =EF11-EF15 -> 0 | ... EK19: =EK11-EK15 -> 0
A20: DTT-CC | B20: Con-Con | C20: =C12-C16 -> 0 | D20: =D12-D16 -> 0 | E20: =E12-E16 -> 0 | F20: =F12-F16 -> 0 | G20: =G12-G16 -> 0 | H20: =H12-H16 -> 0 | I20: =I12-I16 -> 0 | J20: =J12-J16 -> 0 | ... O20: =O12-O16 -> 0 | Q20: =Q12-Q16 -> 0 | R20: =R12-R16 -> 0 | S20: =S12-S16 -> 0 | T20: =T12-T16 -> 0 | U20: =U12-U16 -> 0 | V20: =V12-V16 -> 0 | W20: =W12-W16 -> 0 | X20: =X12-X16 -> 0 | ... AC20: =AC12-AC16 -> 0 | AE20: =AE12-AE16 -> 0 | AF20: =AF12-AF16 -> 0 | AG20: =AG12-AG16 -> 0 | AH20: =AH12-AH16 -> 0 | AI20: =AI12-AI16 -> 0 | AJ20: =AJ12-AJ16 -> 0 | AK20: =AK12-AK16 -> 0 | AL20: =AL12-AL16 -> 0 | ... AQ20: =AQ12-AQ16 -> 0 | AS20: =AS12-AS16 -> 0 | AT20: =AT12-AT16 -> 0 | AU20: =AU12-AU16 -> 0 | AV20: =AV12-AV16 -> 0 | AW20: =AW12-AW16 -> 0 | AX20: =AX12-AX16 -> 0 | AY20: =AY12-AY16 -> 0 | AZ20: =AZ12-AZ16 -> 0 | ... BE20: =BE12-BE16 -> 0 | BG20: =BG12-BG16 -> 0 | BH20: =BH12-BH16 -> 0 | BI20: =BI12-BI16 -> 0 | BJ20: =BJ12-BJ16 -> 0 | BK20: =BK12-BK16 -> 0 | BL20: =BL12-BL16 -> 0 | BM20: =BM12-BM16 -> 0 | BN20: =BN12-BN16 -> 0 | ... BS20: =BS12-BS16 -> 0 | BU20: =BU12-BU16 -> 0 | BV20: =BV12-BV16 -> 0 | BW20: =BW12-BW16 -> 0 | BX20: =BX12-BX16 -> 0 | BY20: =BY12-BY16 -> 0 | BZ20: =BZ12-BZ16 -> 0 | CA20: =CA12-CA16 -> 0 | CB20: =CB12-CB16 -> 0 | ... CG20: =CG12-CG16 -> 0 | CI20: =CI12-CI16 -> 0 | CJ20: =CJ12-CJ16 -> 0 | CK20: =CK12-CK16 -> 0 | CL20: =CL12-CL16 -> 0 | CM20: =CM12-CM16 -> 0 | CN20: =CN12-CN16 -> 0 | CO20: =CO12-CO16 -> 0 | CP20: =CP12-CP16 -> 0 | ... CU20: =CU12-CU16 -> 0 | CW20: =CW12-CW16 -> 0 | CX20: =CX12-CX16 -> 0 | CY20: =CY12-CY16 -> 0 | CZ20: =CZ12-CZ16 -> 0 | DA20: =DA12-DA16 -> 0 | DB20: =DB12-DB16 -> 0 | DC20: =DC12-DC16 -> 0 | DD20: =DD12-DD16 -> 0 | ... DI20: =DI12-DI16 -> 0 | DK20: =DK12-DK16 -> 0 | DL20: =DL12-DL16 -> 0 | DM20: =DM12-DM16 -> 0 | DN20: =DN12-DN16 -> 0 | DO20: =DO12-DO16 -> 0 | DP20: =DP12-DP16 -> 0 | DQ20: =DQ12-DQ16 -> 0 | DR20: =DR12-DR16 -> 0 | ... DW20: =DW12-DW16 -> 0 | DY20: =DY12-DY16 -> 0 | DZ20: =DZ12-DZ16 -> 0 | EA20: =EA12-EA16 -> 0 | EB20: =EB12-EB16 -> 0 | EC20: =EC12-EC16 -> 0 | ED20: =ED12-ED16 -> 0 | EE20: =EE12-EE16 -> 0 | EF20: =EF12-EF16 -> 0 | ... EK20: =EK12-EK16 -> 0
